<?xml version="1.0" ?>
<sdf version="1.6">
	<model name="VRpuppet">
		<link name="base">
			<self_collide>false</self_collide>
			<pose frame="">-0.0174920138254576 -0.003008807938494491 0.9286191847004409 0.0 -0.0 0.0</pose>
			<inertial>
				<pose frame="">0.0 0.0 0.0 0 0 0</pose>
				<mass>48.441191784456166</mass>
				<inertia>
					<ixx>52.32431576836706</ixx>
					<ixy>-0.005183475223456421</ixy>
					<ixz>0.8007340413128515</ixz>
					<iyy>52.31338853447885</iyy>
					<iyz>0.1383457895425122</iyz>
					<izz>12.862915869896792</izz>
				</inertia>
			</inertial>
			<collision name="base_collision">
				<geometry>
					<mesh>
						<uri>model://VRpuppet/meshes/CAD/base.stl</uri>
						<scale>0.001 0.001 0.001</scale>
					</mesh>
				</geometry>
			</collision>
			<visual name="base_visual">
				<geometry>
					<mesh>
						<uri>model://VRpuppet/meshes/CAD/base.stl</uri>
						<scale>0.001 0.001 0.001</scale>
					</mesh>
				</geometry>
			</visual>
		</link>
		<link name="motor3">
			<self_collide>false</self_collide>
			<pose frame="">-1.4838021873254814 -1.2342394028102621 0.01051655894117484 0.0 -0.0 0.0</pose>
			<inertial>
				<pose frame="">0.0 0.0 0.0 0 0 0</pose>
				<mass>0.5407289156586891</mass>
				<inertia>
					<ixx>0.8239519347007563</ixx>
					<ixy>-0.9902621278821997</ixy>
					<ixz>0.008437545456538848</ixz>
					<iyy>1.1908347538526611</iyy>
					<iyz>0.007018743074075354</iyz>
					<izz>2.0145909271886877</izz>
				</inertia>
			</inertial>
			<collision name="motor3_collision">
				<geometry>
					<mesh>
						<uri>model://VRpuppet/meshes/CAD/motor3.stl</uri>
						<scale>0.001 0.001 0.001</scale>
					</mesh>
				</geometry>
			</collision>
			<visual name="motor3_visual">
				<geometry>
					<mesh>
						<uri>model://VRpuppet/meshes/CAD/motor3.stl</uri>
						<scale>0.001 0.001 0.001</scale>
					</mesh>
				</geometry>
			</visual>
		</link>
		<link name="motor2">
			<self_collide>false</self_collide>
			<pose frame="">-1.485334311593426 1.2358101926090346 0.010485803664418522 0.0 -0.0 0.0</pose>
			<inertial>
				<pose frame="">0.0 0.0 0.0 0 0 0</pose>
				<mass>0.5915184316952449</mass>
				<inertia>
					<ixx>0.9036405133260113</ixx>
					<ixy>1.0857914520512877</ixy>
					<ixz>0.009213108679123352</ixz>
					<iyy>1.3053863599243112</iyy>
					<iyz>-0.007665084014776147</iyz>
					<izz>2.2088188733016993</izz>
				</inertia>
			</inertial>
			<collision name="motor2_collision">
				<geometry>
					<mesh>
						<uri>model://VRpuppet/meshes/CAD/motor2.stl</uri>
						<scale>0.001 0.001 0.001</scale>
					</mesh>
				</geometry>
			</collision>
			<visual name="motor2_visual">
				<geometry>
					<mesh>
						<uri>model://VRpuppet/meshes/CAD/motor2.stl</uri>
						<scale>0.001 0.001 0.001</scale>
					</mesh>
				</geometry>
			</visual>
		</link>
		<link name="motor0">
			<self_collide>false</self_collide>
			<pose frame="">1.4853343115934643 1.2358101926090335 0.01051419634034889 0.0 -0.0 0.0</pose>
			<inertial>
				<pose frame="">0.0 0.0 0.0 0 0 0</pose>
				<mass>0.5915184316951642</mass>
				<inertia>
					<ixx>0.9036408660165021</ixx>
					<ixy>-1.0857914520511684</ixy>
					<ixz>-0.009237546389943497</ixz>
					<iyy>1.305386712614818</iyy>
					<iyz>-0.007686010628829871</iyz>
					<izz>2.2088188733014675</izz>
				</inertia>
			</inertial>
			<collision name="motor0_collision">
				<geometry>
					<mesh>
						<uri>model://VRpuppet/meshes/CAD/motor0.stl</uri>
						<scale>0.001 0.001 0.001</scale>
					</mesh>
				</geometry>
			</collision>
			<visual name="motor0_visual">
				<geometry>
					<mesh>
						<uri>model://VRpuppet/meshes/CAD/motor0.stl</uri>
						<scale>0.001 0.001 0.001</scale>
					</mesh>
				</geometry>
			</visual>
		</link>
		<link name="motor4">
			<self_collide>false</self_collide>
			<pose frame="">-1.2358101829513672 1.485334301546107 0.01051419449950688 0.0 -0.0 0.0</pose>
			<inertial>
				<pose frame="">0.0 0.0 0.0 0 0 0</pose>
				<mass>0.5915182656349381</mass>
				<inertia>
					<ixx>1.3053863288187992</ixx>
					<ixy>1.085791131455688</ixy>
					<ixz>0.007686007040985962</ixz>
					<iyy>0.9036405981034654</iyy>
					<iyz>-0.009237542099685631</iyz>
					<izz>2.2088182216814296</izz>
				</inertia>
			</inertial>
			<collision name="motor4_collision">
				<geometry>
					<mesh>
						<uri>model://VRpuppet/meshes/CAD/motor4.stl</uri>
						<scale>0.001 0.001 0.001</scale>
					</mesh>
				</geometry>
			</collision>
			<visual name="motor4_visual">
				<geometry>
					<mesh>
						<uri>model://VRpuppet/meshes/CAD/motor4.stl</uri>
						<scale>0.001 0.001 0.001</scale>
					</mesh>
				</geometry>
			</visual>
		</link>
		<link name="motor5">
			<self_collide>false</self_collide>
			<pose frame="">1.2358101926090344 1.4853343115934126 0.010485803664418505 0.0 -0.0 0.0</pose>
			<inertial>
				<pose frame="">0.0 0.0 0.0 0 0 0</pose>
				<mass>0.5915184316952438</mass>
				<inertia>
					<ixx>1.3053863599242819</ixx>
					<ixy>-1.0857914520512741</ixy>
					<ixz>-0.007665084014776132</ixz>
					<iyy>0.9036405133260096</iyy>
					<iyz>-0.009213108679123314</iyz>
					<izz>2.2088188733016674</izz>
				</inertia>
			</inertial>
			<collision name="motor5_collision">
				<geometry>
					<mesh>
						<uri>model://VRpuppet/meshes/CAD/motor5.stl</uri>
						<scale>0.001 0.001 0.001</scale>
					</mesh>
				</geometry>
			</collision>
			<visual name="motor5_visual">
				<geometry>
					<mesh>
						<uri>model://VRpuppet/meshes/CAD/motor5.stl</uri>
						<scale>0.001 0.001 0.001</scale>
					</mesh>
				</geometry>
			</visual>
		</link>
		<link name="motor6">
			<self_collide>false</self_collide>
			<pose frame="">-1.2358101829513677 -1.4853343018224894 0.01048580550527066 0.0 -0.0 0.0</pose>
			<inertial>
				<pose frame="">0.0 0.0 0.0 0 0 0</pose>
				<mass>0.5915182656350185</mass>
				<inertia>
					<ixx>1.3053859761740971</ixx>
					<ixy>-1.0857911314557949</ixy>
					<ixz>0.007665083173063848</ixz>
					<iyy>0.9036402454588066</iyy>
					<iyz>0.009213107668262954</iyz>
					<izz>2.2088182216816317</izz>
				</inertia>
			</inertial>
			<collision name="motor6_collision">
				<geometry>
					<mesh>
						<uri>model://VRpuppet/meshes/CAD/motor6.stl</uri>
						<scale>0.001 0.001 0.001</scale>
					</mesh>
				</geometry>
			</collision>
			<visual name="motor6_visual">
				<geometry>
					<mesh>
						<uri>model://VRpuppet/meshes/CAD/motor6.stl</uri>
						<scale>0.001 0.001 0.001</scale>
					</mesh>
				</geometry>
			</visual>
		</link>
		<link name="motor7">
			<self_collide>false</self_collide>
			<pose frame="">1.2358101926090332 -1.48533431159348 0.010514196340348884 0.0 -0.0 0.0</pose>
			<inertial>
				<pose frame="">0.0 0.0 0.0 0 0 0</pose>
				<mass>0.5915184316951644</mass>
				<inertia>
					<ixx>1.305386712614845</ixx>
					<ixy>1.08579145205118</ixy>
					<ixz>-0.0076860106288298745</ixz>
					<iyy>0.9036408660165024</iyy>
					<iyz>0.009237546389943516</iyz>
					<izz>2.2088188733014955</izz>
				</inertia>
			</inertial>
			<collision name="motor7_collision">
				<geometry>
					<mesh>
						<uri>model://VRpuppet/meshes/CAD/motor7.stl</uri>
						<scale>0.001 0.001 0.001</scale>
					</mesh>
				</geometry>
			</collision>
			<visual name="motor7_visual">
				<geometry>
					<mesh>
						<uri>model://VRpuppet/meshes/CAD/motor7.stl</uri>
						<scale>0.001 0.001 0.001</scale>
					</mesh>
				</geometry>
			</visual>
		</link>
		<link name="motor1">
			<self_collide>false</self_collide>
			<pose frame="">1.4853343015460536 -1.2358101829513677 0.010485805505270663 0.0 -0.0 0.0</pose>
			<inertial>
				<pose frame="">0.0 0.0 0.0 0 0 0</pose>
				<mass>0.5915182656350185</mass>
				<inertia>
					<ixx>0.9036402454588068</ixx>
					<ixy>1.0857911314557955</ixy>
					<ixz>-0.009213107668262955</ixz>
					<iyy>1.3053859761740987</iyy>
					<iyz>0.007665083173063846</iyz>
					<izz>2.208818221681633</izz>
				</inertia>
			</inertial>
			<collision name="motor1_collision">
				<geometry>
					<mesh>
						<uri>model://VRpuppet/meshes/CAD/motor1.stl</uri>
						<scale>0.001 0.001 0.001</scale>
					</mesh>
				</geometry>
			</collision>
			<visual name="motor1_visual">
				<geometry>
					<mesh>
						<uri>model://VRpuppet/meshes/CAD/motor1.stl</uri>
						<scale>0.001 0.001 0.001</scale>
					</mesh>
				</geometry>
			</visual>
		</link>
		<link name="motor11">
			<self_collide>false</self_collide>
			<pose frame="">-1.4838021873254792 -1.234239402810263 1.010516558941175 0.0 -0.0 0.0</pose>
			<inertial>
				<pose frame="">0.0 0.0 0.0 0 0 0</pose>
				<mass>0.540728915658689</mass>
				<inertia>
					<ixx>1.3760540653848898</ixx>
					<ixy>-0.9902621278821995</ixy>
					<ixz>0.8107722932610368</ixz>
					<iyy>1.7429368845367943</iyy>
					<iyz>0.6744076770188961</iyz>
					<izz>2.0145909271886877</izz>
				</inertia>
			</inertial>
			<collision name="motor11_collision">
				<geometry>
					<mesh>
						<uri>model://VRpuppet/meshes/CAD/motor11.stl</uri>
						<scale>0.001 0.001 0.001</scale>
					</mesh>
				</geometry>
			</collision>
			<visual name="motor11_visual">
				<geometry>
					<mesh>
						<uri>model://VRpuppet/meshes/CAD/motor11.stl</uri>
						<scale>0.001 0.001 0.001</scale>
					</mesh>
				</geometry>
			</visual>
		</link>
		<link name="motor10">
			<self_collide>false</self_collide>
			<pose frame="">-1.483802186329325 1.2342394009707196 1.0104834407810215 0.0 -0.0 0.0</pose>
			<inertial>
				<pose frame="">0.0 0.0 0.0 0 0 0</pose>
				<mass>0.5407288092535038</mass>
				<inertia>
					<ixx>1.3760176002125752</ixx>
					<ixy>0.99026193086944</ixy>
					<ixz>0.8107460717445298</ixz>
					<iyy>1.7429003480577039</iyy>
					<iyz>-0.6743852245854303</iyz>
					<izz>2.0145905267549784</izz>
				</inertia>
			</inertial>
			<collision name="motor10_collision">
				<geometry>
					<mesh>
						<uri>model://VRpuppet/meshes/CAD/motor10.stl</uri>
						<scale>0.001 0.001 0.001</scale>
					</mesh>
				</geometry>
			</collision>
			<visual name="motor10_visual">
				<geometry>
					<mesh>
						<uri>model://VRpuppet/meshes/CAD/motor10.stl</uri>
						<scale>0.001 0.001 0.001</scale>
					</mesh>
				</geometry>
			</visual>
		</link>
		<link name="motor8">
			<self_collide>false</self_collide>
			<pose frame="">1.4838021863293247 1.2342394009707207 1.010516559218978 0.0 -0.0 0.0</pose>
			<inertial>
				<pose frame="">0.0 0.0 0.0 0 0 0</pose>
				<mass>0.5407288092534246</mass>
				<inertia>
					<ixx>1.3760537924693779</ixx>
					<ixy>-0.9902619308692957</ixy>
					<ixz>-0.8107721333955696</ixz>
					<iyy>1.7429365403144546</iyy>
					<iyz>-0.6744075434898156</iyz>
					<izz>2.014590526754685</izz>
				</inertia>
			</inertial>
			<collision name="motor8_collision">
				<geometry>
					<mesh>
						<uri>model://VRpuppet/meshes/CAD/motor8.stl</uri>
						<scale>0.001 0.001 0.001</scale>
					</mesh>
				</geometry>
			</collision>
			<visual name="motor8_visual">
				<geometry>
					<mesh>
						<uri>model://VRpuppet/meshes/CAD/motor8.stl</uri>
						<scale>0.001 0.001 0.001</scale>
					</mesh>
				</geometry>
			</visual>
		</link>
		<link name="motor12">
			<self_collide>false</self_collide>
			<pose frame="">-1.234239402810263 1.4838021873254785 1.010516558941175 0.0 -0.0 0.0</pose>
			<inertial>
				<pose frame="">0.0 0.0 0.0 0 0 0</pose>
				<mass>0.5407289156586891</mass>
				<inertia>
					<ixx>1.7429368845367943</ixx>
					<ixy>0.9902621278821994</ixy>
					<ixz>0.6744076770188963</ixz>
					<iyy>1.3760540653848898</iyy>
					<iyz>-0.810772293261037</iyz>
					<izz>2.0145909271886873</izz>
				</inertia>
			</inertial>
			<collision name="motor12_collision">
				<geometry>
					<mesh>
						<uri>model://VRpuppet/meshes/CAD/motor12.stl</uri>
						<scale>0.001 0.001 0.001</scale>
					</mesh>
				</geometry>
			</collision>
			<visual name="motor12_visual">
				<geometry>
					<mesh>
						<uri>model://VRpuppet/meshes/CAD/motor12.stl</uri>
						<scale>0.001 0.001 0.001</scale>
					</mesh>
				</geometry>
			</visual>
		</link>
		<link name="motor13">
			<self_collide>false</self_collide>
			<pose frame="">1.2342394009707198 1.4838021863293254 1.0104834407810217 0.0 -0.0 0.0</pose>
			<inertial>
				<pose frame="">0.0 0.0 0.0 0 0 0</pose>
				<mass>0.5407288092535051</mass>
				<inertia>
					<ixx>1.7429003480577074</ixx>
					<ixy>-0.9902619308694421</ixy>
					<ixz>-0.6743852245854316</ixz>
					<iyy>1.3760176002125781</iyy>
					<iyz>-0.8107460717445316</iyz>
					<izz>2.0145905267549824</izz>
				</inertia>
			</inertial>
			<collision name="motor13_collision">
				<geometry>
					<mesh>
						<uri>model://VRpuppet/meshes/CAD/motor13.stl</uri>
						<scale>0.001 0.001 0.001</scale>
					</mesh>
				</geometry>
			</collision>
			<visual name="motor13_visual">
				<geometry>
					<mesh>
						<uri>model://VRpuppet/meshes/CAD/motor13.stl</uri>
						<scale>0.001 0.001 0.001</scale>
					</mesh>
				</geometry>
			</visual>
		</link>
		<link name="motor14">
			<self_collide>false</self_collide>
			<pose frame="">-1.234239402810262 -1.4838021873254785 1.0104834410588253 0.0 -0.0 0.0</pose>
			<inertial>
				<pose frame="">0.0 0.0 0.0 0 0 0</pose>
				<mass>0.5407289156587678</mass>
				<inertia>
					<ixx>1.742900692880094</ixx>
					<ixy>-0.9902621278823432</ixy>
					<ixz>0.6743853584836851</ixz>
					<iyy>1.3760178737281379</iyy>
					<iyz>0.8107462320519715</iyz>
					<izz>2.0145909271889795</izz>
				</inertia>
			</inertial>
			<collision name="motor14_collision">
				<geometry>
					<mesh>
						<uri>model://VRpuppet/meshes/CAD/motor14.stl</uri>
						<scale>0.001 0.001 0.001</scale>
					</mesh>
				</geometry>
			</collision>
			<visual name="motor14_visual">
				<geometry>
					<mesh>
						<uri>model://VRpuppet/meshes/CAD/motor14.stl</uri>
						<scale>0.001 0.001 0.001</scale>
					</mesh>
				</geometry>
			</visual>
		</link>
		<link name="motor15">
			<self_collide>false</self_collide>
			<pose frame="">1.2342394009707207 -1.483802186329324 1.010516559218978 0.0 -0.0 0.0</pose>
			<inertial>
				<pose frame="">0.0 0.0 0.0 0 0 0</pose>
				<mass>0.5407288092534249</mass>
				<inertia>
					<ixx>1.7429365403144548</ixx>
					<ixy>0.9902619308692958</ixy>
					<ixz>-0.6744075434898158</ixz>
					<iyy>1.376053792469379</iyy>
					<iyz>0.81077213339557</iyz>
					<izz>2.0145905267546853</izz>
				</inertia>
			</inertial>
			<collision name="motor15_collision">
				<geometry>
					<mesh>
						<uri>model://VRpuppet/meshes/CAD/motor15.stl</uri>
						<scale>0.001 0.001 0.001</scale>
					</mesh>
				</geometry>
			</collision>
			<visual name="motor15_visual">
				<geometry>
					<mesh>
						<uri>model://VRpuppet/meshes/CAD/motor15.stl</uri>
						<scale>0.001 0.001 0.001</scale>
					</mesh>
				</geometry>
			</visual>
		</link>
		<link name="motor9">
			<self_collide>false</self_collide>
			<pose frame="">1.4853343018224885 -1.2358101829513672 1.0104858057327721 0.0 -0.0 0.0</pose>
			<inertial>
				<pose frame="">0.0 0.0 0.0 0 0 0</pose>
				<mass>0.5915182656350185</mass>
				<inertia>
					<ixx>1.5075636020635315</ixx>
					<ixy>1.085791131251597</ixy>
					<ixz>-0.8878154774061241</ixz>
					<iyy>1.909309332296448</iyy>
					<iyz>0.7386693790802477</iyz>
					<izz>2.2088182211992584</izz>
				</inertia>
			</inertial>
			<collision name="motor9_collision">
				<geometry>
					<mesh>
						<uri>model://VRpuppet/meshes/CAD/motor9.stl</uri>
						<scale>0.001 0.001 0.001</scale>
					</mesh>
				</geometry>
			</collision>
			<visual name="motor9_visual">
				<geometry>
					<mesh>
						<uri>model://VRpuppet/meshes/CAD/motor9.stl</uri>
						<scale>0.001 0.001 0.001</scale>
					</mesh>
				</geometry>
			</visual>
		</link>
		<link name="motor19">
			<self_collide>false</self_collide>
			<pose frame="">-1.483802187325481 -1.2342394028102615 2.010516558941175 0.0 -0.0 0.0</pose>
			<inertial>
				<pose frame="">0.0 0.0 0.0 0 0 0</pose>
				<mass>0.5407289156586891</mass>
				<inertia>
					<ixx>3.009614027386401</ixx>
					<ixy>-0.9902621278821997</ixy>
					<ixz>1.6131070410655353</ixz>
					<iyy>3.3764968465383065</iyy>
					<iyz>1.3417966109637172</iyz>
					<izz>2.0145909271886877</izz>
				</inertia>
			</inertial>
			<collision name="motor19_collision">
				<geometry>
					<mesh>
						<uri>model://VRpuppet/meshes/CAD/motor19.stl</uri>
						<scale>0.001 0.001 0.001</scale>
					</mesh>
				</geometry>
			</collision>
			<visual name="motor19_visual">
				<geometry>
					<mesh>
						<uri>model://VRpuppet/meshes/CAD/motor19.stl</uri>
						<scale>0.001 0.001 0.001</scale>
					</mesh>
				</geometry>
			</visual>
		</link>
		<link name="motor18">
			<self_collide>false</self_collide>
			<pose frame="">-1.483802186329323 1.2342394009707196 2.0104834407810213 0.0 -0.0 0.0</pose>
			<inertial>
				<pose frame="">0.0 0.0 0.0 0 0 0</pose>
				<mass>0.5407288092535049</mass>
				<inertia>
					<ixx>3.009541424873896</ixx>
					<ixy>0.9902619308694421</ixy>
					<ixz>1.6130806611261352</ixz>
					<iyy>3.3764241727190254</iyy>
					<iyz>-1.3417740262060884</iyz>
					<izz>2.0145905267549824</izz>
				</inertia>
			</inertial>
			<collision name="motor18_collision">
				<geometry>
					<mesh>
						<uri>model://VRpuppet/meshes/CAD/motor18.stl</uri>
						<scale>0.001 0.001 0.001</scale>
					</mesh>
				</geometry>
			</collision>
			<visual name="motor18_visual">
				<geometry>
					<mesh>
						<uri>model://VRpuppet/meshes/CAD/motor18.stl</uri>
						<scale>0.001 0.001 0.001</scale>
					</mesh>
				</geometry>
			</visual>
		</link>
		<link name="motor16">
			<self_collide>false</self_collide>
			<pose frame="">1.483802186329327 1.2342394009707198 2.010516559218978 0.0 -0.0 0.0</pose>
			<inertial>
				<pose frame="">0.0 0.0 0.0 0 0 0</pose>
				<mass>0.5407288092534246</mass>
				<inertia>
					<ixx>3.0096134333174938</ixx>
					<ixy>-0.9902619308692957</ixy>
					<ixz>-1.6131067227770544</ixz>
					<iyy>3.3764961811625707</iyy>
					<iyz>-1.3417963451103734</iyz>
					<izz>2.014590526754685</izz>
				</inertia>
			</inertial>
			<collision name="motor16_collision">
				<geometry>
					<mesh>
						<uri>model://VRpuppet/meshes/CAD/motor16.stl</uri>
						<scale>0.001 0.001 0.001</scale>
					</mesh>
				</geometry>
			</collision>
			<visual name="motor16_visual">
				<geometry>
					<mesh>
						<uri>model://VRpuppet/meshes/CAD/motor16.stl</uri>
						<scale>0.001 0.001 0.001</scale>
					</mesh>
				</geometry>
			</visual>
		</link>
		<link name="motor20">
			<self_collide>false</self_collide>
			<pose frame="">-1.2342394028102615 1.483802187325481 2.010516558941175 0.0 -0.0 0.0</pose>
			<inertial>
				<pose frame="">0.0 0.0 0.0 0 0 0</pose>
				<mass>0.540728915658689</mass>
				<inertia>
					<ixx>3.3764968465383056</ixx>
					<ixy>0.9902621278821991</ixy>
					<ixz>1.3417966109637167</ixz>
					<iyy>3.0096140273864003</iyy>
					<iyz>-1.613107041065535</iyz>
					<izz>2.0145909271886864</izz>
				</inertia>
			</inertial>
			<collision name="motor20_collision">
				<geometry>
					<mesh>
						<uri>model://VRpuppet/meshes/CAD/motor20.stl</uri>
						<scale>0.001 0.001 0.001</scale>
					</mesh>
				</geometry>
			</collision>
			<visual name="motor20_visual">
				<geometry>
					<mesh>
						<uri>model://VRpuppet/meshes/CAD/motor20.stl</uri>
						<scale>0.001 0.001 0.001</scale>
					</mesh>
				</geometry>
			</visual>
		</link>
		<link name="motor21">
			<self_collide>false</self_collide>
			<pose frame="">1.2342394009707203 1.483802186329324 2.0104834407810213 0.0 -0.0 0.0</pose>
			<inertial>
				<pose frame="">0.0 0.0 0.0 0 0 0</pose>
				<mass>0.540728809253504</mass>
				<inertia>
					<ixx>3.3764241727190205</ixx>
					<ixy>-0.9902619308694405</ixy>
					<ixz>-1.3417740262060864</ixz>
					<iyy>3.009541424873891</iyy>
					<iyz>-1.6130806611261326</iyz>
					<izz>2.0145905267549797</izz>
				</inertia>
			</inertial>
			<collision name="motor21_collision">
				<geometry>
					<mesh>
						<uri>model://VRpuppet/meshes/CAD/motor21.stl</uri>
						<scale>0.001 0.001 0.001</scale>
					</mesh>
				</geometry>
			</collision>
			<visual name="motor21_visual">
				<geometry>
					<mesh>
						<uri>model://VRpuppet/meshes/CAD/motor21.stl</uri>
						<scale>0.001 0.001 0.001</scale>
					</mesh>
				</geometry>
			</visual>
		</link>
		<link name="motor22">
			<self_collide>false</self_collide>
			<pose frame="">-1.2342394028102621 -1.4838021873254774 2.0104834410588244 0.0 -0.0 0.0</pose>
			<inertial>
				<pose frame="">0.0 0.0 0.0 0 0 0</pose>
				<mass>0.5407289156587689</mass>
				<inertia>
					<ixx>3.376424839288627</ixx>
					<ixy>-0.9902621278823452</ixy>
					<ixz>1.3417742924286062</ixz>
					<iyy>3.00954202013667</iyy>
					<iyz>1.6130809798565893</iyz>
					<izz>2.0145909271889835</izz>
				</inertia>
			</inertial>
			<collision name="motor22_collision">
				<geometry>
					<mesh>
						<uri>model://VRpuppet/meshes/CAD/motor22.stl</uri>
						<scale>0.001 0.001 0.001</scale>
					</mesh>
				</geometry>
			</collision>
			<visual name="motor22_visual">
				<geometry>
					<mesh>
						<uri>model://VRpuppet/meshes/CAD/motor22.stl</uri>
						<scale>0.001 0.001 0.001</scale>
					</mesh>
				</geometry>
			</visual>
		</link>
		<link name="motor23">
			<self_collide>false</self_collide>
			<pose frame="">1.2342394009707196 -1.4838021863293265 2.0105165592189773 0.0 -0.0 0.0</pose>
			<inertial>
				<pose frame="">0.0 0.0 0.0 0 0 0</pose>
				<mass>0.5407288092534249</mass>
				<inertia>
					<ixx>3.376496181162572</ixx>
					<ixy>0.9902619308692958</ixy>
					<ixz>-1.3417963451103738</ixz>
					<iyy>3.0096134333174955</iyy>
					<iyz>1.6131067227770552</iyz>
					<izz>2.0145905267546853</izz>
				</inertia>
			</inertial>
			<collision name="motor23_collision">
				<geometry>
					<mesh>
						<uri>model://VRpuppet/meshes/CAD/motor23.stl</uri>
						<scale>0.001 0.001 0.001</scale>
					</mesh>
				</geometry>
			</collision>
			<visual name="motor23_visual">
				<geometry>
					<mesh>
						<uri>model://VRpuppet/meshes/CAD/motor23.stl</uri>
						<scale>0.001 0.001 0.001</scale>
					</mesh>
				</geometry>
			</visual>
		</link>
		<link name="motor17">
			<self_collide>false</self_collide>
			<pose frame="">1.4838021873254774 -1.2342394028102615 2.0104834410588235 0.0 -0.0 0.0</pose>
			<inertial>
				<pose frame="">0.0 0.0 0.0 0 0 0</pose>
				<mass>0.5407289156587689</mass>
				<inertia>
					<ixx>3.0095420201366694</ixx>
					<ixy>0.9902621278823456</ixy>
					<ixz>-1.6130809798565902</ixz>
					<iyy>3.376424839288629</iyy>
					<iyz>1.341774292428606</iyz>
					<izz>2.014590927188985</izz>
				</inertia>
			</inertial>
			<collision name="motor17_collision">
				<geometry>
					<mesh>
						<uri>model://VRpuppet/meshes/CAD/motor17.stl</uri>
						<scale>0.001 0.001 0.001</scale>
					</mesh>
				</geometry>
			</collision>
			<visual name="motor17_visual">
				<geometry>
					<mesh>
						<uri>model://VRpuppet/meshes/CAD/motor17.stl</uri>
						<scale>0.001 0.001 0.001</scale>
					</mesh>
				</geometry>
			</visual>
		</link>
		<link name="neck_link1">
			<self_collide>false</self_collide>
			<pose frame="">-0.03021065211712152 -0.0021542615510272154 1.6100189040829915 0.0 -0.0 0.0</pose>
			<inertial>
				<pose frame="">0.0 0.0 0.0 0 0 0</pose>
				<mass>0.06979037783542182</mass>
				<inertia>
					<ixx>0.1809198577960802</ixx>
					<ixy>-4.5420726845470915e-06</ixy>
					<ixz>0.0033945845073235633</ixz>
					<iyy>0.1809832304363084</iyy>
					<iyz>0.00024206107360706254</iyz>
					<izz>7.566768967812972e-05</izz>
				</inertia>
			</inertial>
			<collision name="neck_link1_collision">
				<geometry>
					<mesh>
						<uri>model://VRpuppet/meshes/CAD/neck_link1.stl</uri>
						<scale>0.001 0.001 0.001</scale>
					</mesh>
				</geometry>
			</collision>
			<visual name="neck_link1_visual">
				<geometry>
					<mesh>
						<uri>model://VRpuppet/meshes/CAD/neck_link1.stl</uri>
						<scale>0.001 0.001 0.001</scale>
					</mesh>
				</geometry>
			</visual>
		</link>
		<link name="neck_link2">
			<self_collide>false</self_collide>
			<pose frame="">-0.03021065209880325 -0.002154261532699797 1.6100189040829913 0.0 -0.0 0.0</pose>
			<inertial>
				<pose frame="">0.0 0.0 0.0 0 0 0</pose>
				<mass>0.04678255602502142</mass>
				<inertia>
					<ixx>0.12127338974092727</ixx>
					<ixy>-3.0446857358908502e-06</ixy>
					<ixz>0.002275490471963592</ixz>
					<iyy>0.12131587029742415</iyy>
					<iyz>0.00016226070115084857</iyz>
					<izz>4.817621074330742e-05</izz>
				</inertia>
			</inertial>
			<collision name="neck_link2_collision">
				<geometry>
					<mesh>
						<uri>model://VRpuppet/meshes/CAD/neck_link2.stl</uri>
						<scale>0.001 0.001 0.001</scale>
					</mesh>
				</geometry>
			</collision>
			<visual name="neck_link2_visual">
				<geometry>
					<mesh>
						<uri>model://VRpuppet/meshes/CAD/neck_link2.stl</uri>
						<scale>0.001 0.001 0.001</scale>
					</mesh>
				</geometry>
			</visual>
		</link>
		<link name="hip_right_link1">
			<self_collide>false</self_collide>
			<pose frame="">-0.029627237871723052 -0.10423074516990154 0.8954841277672508 0.0 -0.0 0.0</pose>
			<inertial>
				<pose frame="">0.0 0.0 0.0 0 0 0</pose>
				<mass>0.06979037783542491</mass>
				<inertia>
					<ixx>0.05673418662490819</ixx>
					<ixy>-0.00021551750792364035</ixy>
					<ixz>0.001851589061240855</ixz>
					<iyy>0.05603724071845925</iyy>
					<iyz>0.006514022955402456</iyz>
					<izz>0.0008311134334503395</izz>
				</inertia>
			</inertial>
			<collision name="hip_right_link1_collision">
				<geometry>
					<mesh>
						<uri>model://VRpuppet/meshes/CAD/hip_right_link1.stl</uri>
						<scale>0.001 0.001 0.001</scale>
					</mesh>
				</geometry>
			</collision>
			<visual name="hip_right_link1_visual">
				<geometry>
					<mesh>
						<uri>model://VRpuppet/meshes/CAD/hip_right_link1.stl</uri>
						<scale>0.001 0.001 0.001</scale>
					</mesh>
				</geometry>
			</visual>
		</link>
		<link name="hip_right_link2">
			<self_collide>false</self_collide>
			<pose frame="">-0.02962723785340419 -0.10423074515157214 0.8954841277672522 0.0 -0.0 0.0</pose>
			<inertial>
				<pose frame="">0.0 0.0 0.0 0 0 0</pose>
				<mass>0.046782556025021425</mass>
				<inertia>
					<ixx>0.03802805851800515</ixx>
					<ixy>-0.0001444677646620478</ixy>
					<ixz>0.001241174953136438</ixz>
					<iyy>0.037560875047773584</iyy>
					<iyz>0.004366542398214626</iyz>
					<izz>0.00055457385345388</izz>
				</inertia>
			</inertial>
			<collision name="hip_right_link2_collision">
				<geometry>
					<mesh>
						<uri>model://VRpuppet/meshes/CAD/hip_right_link2.stl</uri>
						<scale>0.001 0.001 0.001</scale>
					</mesh>
				</geometry>
			</collision>
			<visual name="hip_right_link2_visual">
				<geometry>
					<mesh>
						<uri>model://VRpuppet/meshes/CAD/hip_right_link2.stl</uri>
						<scale>0.001 0.001 0.001</scale>
					</mesh>
				</geometry>
			</visual>
		</link>
		<link name="spine_link1">
			<self_collide>false</self_collide>
			<pose frame="">-0.020248705136213272 -0.0030258189785023776 1.0300189040829886 0.0 -0.0 0.0</pose>
			<inertial>
				<pose frame="">0.0 0.0 0.0 0 0 0</pose>
				<mass>0.06979037783542481</mass>
				<inertia>
					<ixx>0.07405561592494245</ixx>
					<ixy>-4.275980817533393e-06</ixy>
					<ixz>0.0014555864401827802</ixz>
					<iyy>0.07408359171050302</iyy>
					<iyz>0.00021751223329727313</iyz>
					<izz>4.090100550480463e-05</izz>
				</inertia>
			</inertial>
			<collision name="spine_link1_collision">
				<geometry>
					<mesh>
						<uri>model://VRpuppet/meshes/CAD/spine_link1.stl</uri>
						<scale>0.001 0.001 0.001</scale>
					</mesh>
				</geometry>
			</collision>
			<visual name="spine_link1_visual">
				<geometry>
					<mesh>
						<uri>model://VRpuppet/meshes/CAD/spine_link1.stl</uri>
						<scale>0.001 0.001 0.001</scale>
					</mesh>
				</geometry>
			</visual>
		</link>
		<link name="spine_link2">
			<self_collide>false</self_collide>
			<pose frame="">-0.02024870511789456 -0.0030258189601748637 1.03001890408299 0.0 -0.0 0.0</pose>
			<inertial>
				<pose frame="">0.0 0.0 0.0 0 0 0</pose>
				<mass>0.04678255602502141</mass>
				<inertia>
					<ixx>0.04963912528404723</ixx>
					<ixy>-2.8663164890332892e-06</ixy>
					<ixz>0.0009757226746369926</ixz>
					<iyy>0.049657878281148884</iyy>
					<iyz>0.00014580488735450097</iyz>
					<izz>2.4871073280215496e-05</izz>
				</inertia>
			</inertial>
			<collision name="spine_link2_collision">
				<geometry>
					<mesh>
						<uri>model://VRpuppet/meshes/CAD/spine_link2.stl</uri>
						<scale>0.001 0.001 0.001</scale>
					</mesh>
				</geometry>
			</collision>
			<visual name="spine_link2_visual">
				<geometry>
					<mesh>
						<uri>model://VRpuppet/meshes/CAD/spine_link2.stl</uri>
						<scale>0.001 0.001 0.001</scale>
					</mesh>
				</geometry>
			</visual>
		</link>
		<link name="ankle_right_link1">
			<self_collide>false</self_collide>
			<pose frame="">-0.03078585321162911 -0.1224096462262446 0.11146497559651632 0.0 -0.0 0.0</pose>
			<inertial>
				<pose frame="">0.0 0.0 0.0 0 0 0</pose>
				<mass>0.06979037783542485</mass>
				<inertia>
					<ixx>0.0019245011944293432</ixx>
					<ixy>-0.0002630040199617997</ixy>
					<ixz>0.0002394887786265198</ixz>
					<iyy>0.0009448988338829647</iyy>
					<iyz>0.0009522470098621112</iyz>
					<izz>0.0011235399170855089</izz>
				</inertia>
			</inertial>
			<collision name="ankle_right_link1_collision">
				<geometry>
					<mesh>
						<uri>model://VRpuppet/meshes/CAD/ankle_right_link1.stl</uri>
						<scale>0.001 0.001 0.001</scale>
					</mesh>
				</geometry>
			</collision>
			<visual name="ankle_right_link1_visual">
				<geometry>
					<mesh>
						<uri>model://VRpuppet/meshes/CAD/ankle_right_link1.stl</uri>
						<scale>0.001 0.001 0.001</scale>
					</mesh>
				</geometry>
			</visual>
		</link>
		<link name="ankle_right_link2">
			<self_collide>false</self_collide>
			<pose frame="">-0.03078585319331049 -0.12240964620791796 0.11146497559651661 0.0 -0.0 0.0</pose>
			<inertial>
				<pose frame="">0.0 0.0 0.0 0 0 0</pose>
				<mass>0.046782556025021446</mass>
				<inertia>
					<ixx>0.0012875040333462837</ixx>
					<ixy>-0.00017629937924279257</ixy>
					<ixz>0.00016053641697158822</ixz>
					<iyy>0.0006308475754659841</iyy>
					<iyz>0.0006383193566728547</iyz>
					<izz>0.0007505959810860087</izz>
				</inertia>
			</inertial>
			<collision name="ankle_right_link2_collision">
				<geometry>
					<mesh>
						<uri>model://VRpuppet/meshes/CAD/ankle_right_link2.stl</uri>
						<scale>0.001 0.001 0.001</scale>
					</mesh>
				</geometry>
			</collision>
			<visual name="ankle_right_link2_visual">
				<geometry>
					<mesh>
						<uri>model://VRpuppet/meshes/CAD/ankle_right_link2.stl</uri>
						<scale>0.001 0.001 0.001</scale>
					</mesh>
				</geometry>
			</visual>
		</link>
		<link name="knee_right_link1">
			<self_collide>false</self_collide>
			<pose frame="">-0.030063016585460987 -0.1092117186603625 0.46548412776725095 0.0 -0.0 0.0</pose>
			<inertial>
				<pose frame="">0.0 0.0 0.0 0 0 0</pose>
				<mass>0.0697903778354249</mass>
				<inertia>
					<ixx>0.015965914179044468</ixx>
					<ixy>-0.00022913812110194966</ixy>
					<ixz>0.0009766365711272257</ixz>
					<iyy>0.015196585914201251</iyy>
					<iyz>0.0035478860924073184</iyz>
					<izz>0.0009071265304925711</izz>
				</inertia>
			</inertial>
			<collision name="knee_right_link1_collision">
				<geometry>
					<mesh>
						<uri>model://VRpuppet/meshes/CAD/knee_right_link1.stl</uri>
						<scale>0.001 0.001 0.001</scale>
					</mesh>
				</geometry>
			</collision>
			<visual name="knee_right_link1_visual">
				<geometry>
					<mesh>
						<uri>model://VRpuppet/meshes/CAD/knee_right_link1.stl</uri>
						<scale>0.001 0.001 0.001</scale>
					</mesh>
				</geometry>
			</visual>
		</link>
		<link name="knee_right_link2">
			<self_collide>false</self_collide>
			<pose frame="">-0.03006301656714234 -0.10921171864203537 0.4654841277672518 0.0 -0.0 0.0</pose>
			<inertial>
				<pose frame="">0.0 0.0 0.0 0 0 0</pose>
				<mass>0.046782556025021425</mass>
				<inertia>
					<ixx>0.010699878776091546</ixx>
					<ixy>-0.00015359806483449144</ixy>
					<ixz>0.0006546684012049038</ixz>
					<iyy>0.010184175268552751</iyy>
					<iyz>0.0023782530630796664</iyz>
					<izz>0.0006055276823434818</izz>
				</inertia>
			</inertial>
			<collision name="knee_right_link2_collision">
				<geometry>
					<mesh>
						<uri>model://VRpuppet/meshes/CAD/knee_right_link2.stl</uri>
						<scale>0.001 0.001 0.001</scale>
					</mesh>
				</geometry>
			</collision>
			<visual name="knee_right_link2_visual">
				<geometry>
					<mesh>
						<uri>model://VRpuppet/meshes/CAD/knee_right_link2.stl</uri>
						<scale>0.001 0.001 0.001</scale>
					</mesh>
				</geometry>
			</visual>
		</link>
		<link name="wrist_right_link1">
			<self_collide>false</self_collide>
			<pose frame="">-0.09718306853267211 -0.2628091012134199 0.8690189040829772 0.0 -0.0 0.0</pose>
			<inertial>
				<pose frame="">0.0 0.0 0.0 0 0 0</pose>
				<mass>0.06979037783542315</mass>
				<inertia>
					<ixx>0.05753723714569883</ixx>
					<ixy>-0.0017824877678100535</ixy>
					<ixz>0.0058940712455224</ixz>
					<iyy>0.053376050432351635</iyy>
					<iyz>0.01593915061452127</iyz>
					<izz>0.005491111250237795</izz>
				</inertia>
			</inertial>
			<collision name="wrist_right_link1_collision">
				<geometry>
					<mesh>
						<uri>model://VRpuppet/meshes/CAD/wrist_right_link1.stl</uri>
						<scale>0.001 0.001 0.001</scale>
					</mesh>
				</geometry>
			</collision>
			<visual name="wrist_right_link1_visual">
				<geometry>
					<mesh>
						<uri>model://VRpuppet/meshes/CAD/wrist_right_link1.stl</uri>
						<scale>0.001 0.001 0.001</scale>
					</mesh>
				</geometry>
			</visual>
		</link>
		<link name="wrist_right_link2">
			<self_collide>false</self_collide>
			<pose frame="">-0.09718306851434588 -0.26280910119509565 0.8690189040829803 0.0 -0.0 0.0</pose>
			<inertial>
				<pose frame="">0.0 0.0 0.0 0 0 0</pose>
				<mass>0.046782556025034956</mass>
				<inertia>
					<ixx>0.038566367051744425</ixx>
					<ixy>-0.0011948543112435834</ixy>
					<ixz>0.003950970416830831</ixz>
					<iyy>0.03577700042892654</iyy>
					<iyz>0.010684484447436892</iyz>
					<izz>0.0036783083233753516</izz>
				</inertia>
			</inertial>
			<collision name="wrist_right_link2_collision">
				<geometry>
					<mesh>
						<uri>model://VRpuppet/meshes/CAD/wrist_right_link2.stl</uri>
						<scale>0.001 0.001 0.001</scale>
					</mesh>
				</geometry>
			</collision>
			<visual name="wrist_right_link2_visual">
				<geometry>
					<mesh>
						<uri>model://VRpuppet/meshes/CAD/wrist_right_link2.stl</uri>
						<scale>0.001 0.001 0.001</scale>
					</mesh>
				</geometry>
			</visual>
		</link>
		<link name="shoulder_left_link1">
			<self_collide>false</self_collide>
			<pose frame="">-0.04890500456828595 0.18574827576446715 1.4000189040829958 0.0 -0.0 0.0</pose>
			<inertial>
				<pose frame="">0.0 0.0 0.0 0 0 0</pose>
				<mass>0.0697903778354231</mass>
				<inertia>
					<ixx>0.13921241902852993</ixx>
					<ixy>0.0006339772072438079</ixy>
					<ixz>0.004778402767111253</ixz>
					<iyy>0.13697139957424642</iyy>
					<iyz>-0.01814906434902278</iyz>
					<izz>0.0025865019509990015</izz>
				</inertia>
			</inertial>
			<collision name="shoulder_left_link1_collision">
				<geometry>
					<mesh>
						<uri>model://VRpuppet/meshes/CAD/shoulder_left_link1.stl</uri>
						<scale>0.001 0.001 0.001</scale>
					</mesh>
				</geometry>
			</collision>
			<visual name="shoulder_left_link1_visual">
				<geometry>
					<mesh>
						<uri>model://VRpuppet/meshes/CAD/shoulder_left_link1.stl</uri>
						<scale>0.001 0.001 0.001</scale>
					</mesh>
				</geometry>
			</visual>
		</link>
		<link name="shoulder_left_link2">
			<self_collide>false</self_collide>
			<pose frame="">-0.04890500454995888 0.18574827578279574 1.4000189040829951 0.0 -0.0 0.0</pose>
			<inertial>
				<pose frame="">0.0 0.0 0.0 0 0 0</pose>
				<mass>0.04678255602503103</mass>
				<inertia>
					<ixx>0.0933156590150584</ixx>
					<ixy>0.0004249736873216092</ixy>
					<ixz>0.0032031048120405516</ixz>
					<iyy>0.09181343734134116</iyy>
					<iyz>-0.012165855038011845</iyz>
					<izz>0.0017312627358952296</izz>
				</inertia>
			</inertial>
			<collision name="shoulder_left_link2_collision">
				<geometry>
					<mesh>
						<uri>model://VRpuppet/meshes/CAD/shoulder_left_link2.stl</uri>
						<scale>0.001 0.001 0.001</scale>
					</mesh>
				</geometry>
			</collision>
			<visual name="shoulder_left_link2_visual">
				<geometry>
					<mesh>
						<uri>model://VRpuppet/meshes/CAD/shoulder_left_link2.stl</uri>
						<scale>0.001 0.001 0.001</scale>
					</mesh>
				</geometry>
			</visual>
		</link>
		<link name="elbow_right_link1">
			<self_collide>false</self_collide>
			<pose frame="">-0.11015279210520997 -0.216000594823536 1.1370189040829768 0.0 -0.0 0.0</pose>
			<inertial>
				<pose frame="">0.0 0.0 0.0 0 0 0</pose>
				<mass>0.06979037783542313</mass>
				<inertia>
					<ixx>0.0934936422088936</ixx>
					<ixy>-0.001660527248588653</ixy>
					<ixz>0.008740952190120837</ixz>
					<iyy>0.09108429556020144</iyy>
					<iyz>0.01714029064816496</iyz>
					<izz>0.004114616232233812</izz>
				</inertia>
			</inertial>
			<collision name="elbow_right_link1_collision">
				<geometry>
					<mesh>
						<uri>model://VRpuppet/meshes/CAD/elbow_right_link1.stl</uri>
						<scale>0.001 0.001 0.001</scale>
					</mesh>
				</geometry>
			</collision>
			<visual name="elbow_right_link1_visual">
				<geometry>
					<mesh>
						<uri>model://VRpuppet/meshes/CAD/elbow_right_link1.stl</uri>
						<scale>0.001 0.001 0.001</scale>
					</mesh>
				</geometry>
			</visual>
		</link>
		<link name="elbow_right_link2">
			<self_collide>false</self_collide>
			<pose frame="">-0.1101527920868839 -0.21600059480521178 1.1370189040829777 0.0 -0.0 0.0</pose>
			<inertial>
				<pose frame="">0.0 0.0 0.0 0 0 0</pose>
				<mass>0.046782556025034956</mass>
				<inertia>
					<ixx>0.06266900965815193</ixx>
					<ixy>-0.0011131005652651998</ixy>
					<ixz>0.005859318980085709</ixz>
					<iyy>0.061053953284201525</iyy>
					<iyz>0.01148964416493151</iyz>
					<izz>0.0027556029692682297</izz>
				</inertia>
			</inertial>
			<collision name="elbow_right_link2_collision">
				<geometry>
					<mesh>
						<uri>model://VRpuppet/meshes/CAD/elbow_right_link2.stl</uri>
						<scale>0.001 0.001 0.001</scale>
					</mesh>
				</geometry>
			</collision>
			<visual name="elbow_right_link2_visual">
				<geometry>
					<mesh>
						<uri>model://VRpuppet/meshes/CAD/elbow_right_link2.stl</uri>
						<scale>0.001 0.001 0.001</scale>
					</mesh>
				</geometry>
			</visual>
		</link>
		<link name="shoulder_right_link1">
			<self_collide>false</self_collide>
			<pose frame="">-0.080765500244921 -0.17841885621137163 1.4000189040829871 0.0 -0.0 0.0</pose>
			<inertial>
				<pose frame="">0.0 0.0 0.0 0 0 0</pose>
				<mass>0.06979037783542312</mass>
				<inertia>
					<ixx>0.13902613917927265</ixx>
					<ixy>-0.0010056854983776684</ixy>
					<ixz>0.00789142324521368</ixz>
					<iyy>0.1372597292073034</iyy>
					<iyz>0.01743292253525537</iyz>
					<izz>0.0026885517348020026</izz>
				</inertia>
			</inertial>
			<collision name="shoulder_right_link1_collision">
				<geometry>
					<mesh>
						<uri>model://VRpuppet/meshes/CAD/shoulder_right_link1.stl</uri>
						<scale>0.001 0.001 0.001</scale>
					</mesh>
				</geometry>
			</collision>
			<visual name="shoulder_right_link1_visual">
				<geometry>
					<mesh>
						<uri>model://VRpuppet/meshes/CAD/shoulder_right_link1.stl</uri>
						<scale>0.001 0.001 0.001</scale>
					</mesh>
				</geometry>
			</visual>
		</link>
		<link name="shoulder_right_link2">
			<self_collide>false</self_collide>
			<pose frame="">-0.08076550022659496 -0.1784188561930476 1.4000189040829887 0.0 -0.0 0.0</pose>
			<inertial>
				<pose frame="">0.0 0.0 0.0 0 0 0</pose>
				<mass>0.046782556025034935</mass>
				<inertia>
					<ixx>0.09319079011769002</ixx>
					<ixy>-0.0006741407571522098</ixy>
					<ixz>0.005289854582436727</ixz>
					<iyy>0.09200671322875241</iyy>
					<iyz>0.011685803980387287</iyz>
					<izz>0.0017996697259244625</izz>
				</inertia>
			</inertial>
			<collision name="shoulder_right_link2_collision">
				<geometry>
					<mesh>
						<uri>model://VRpuppet/meshes/CAD/shoulder_right_link2.stl</uri>
						<scale>0.001 0.001 0.001</scale>
					</mesh>
				</geometry>
			</collision>
			<visual name="shoulder_right_link2_visual">
				<geometry>
					<mesh>
						<uri>model://VRpuppet/meshes/CAD/shoulder_right_link2.stl</uri>
						<scale>0.001 0.001 0.001</scale>
					</mesh>
				</geometry>
			</visual>
		</link>
		<link name="knee_left_link1">
			<self_collide>false</self_collide>
			<pose frame="">-0.010990498880752285 0.10878815624979847 0.4654841277672509 0.0 -0.0 0.0</pose>
			<inertial>
				<pose frame="">0.0 0.0 0.0 0 0 0</pose>
				<mass>0.06979037783542481</mass>
				<inertia>
					<ixx>0.01595946997615608</ixx>
					<ixy>8.344389583585825e-05</ixy>
					<ixz>0.00035704078835077944</ixz>
					<iyy>0.015141940474037626</iyy>
					<iyz>-0.0035341261112977734</iyz>
					<izz>0.0008460368874405992</izz>
				</inertia>
			</inertial>
			<collision name="knee_left_link1_collision">
				<geometry>
					<mesh>
						<uri>model://VRpuppet/meshes/CAD/knee_left_link1.stl</uri>
						<scale>0.001 0.001 0.001</scale>
					</mesh>
				</geometry>
			</collision>
			<visual name="knee_left_link1_visual">
				<geometry>
					<mesh>
						<uri>model://VRpuppet/meshes/CAD/knee_left_link1.stl</uri>
						<scale>0.001 0.001 0.001</scale>
					</mesh>
				</geometry>
			</visual>
		</link>
		<link name="knee_left_link2">
			<self_collide>false</self_collide>
			<pose frame="">-0.010990498862418001 0.10878815626812387 0.4654841277672519 0.0 -0.0 0.0</pose>
			<inertial>
				<pose frame="">0.0 0.0 0.0 0 0 0</pose>
				<mass>0.046782556025046794</mass>
				<inertia>
					<ixx>0.010695559036529741</ixx>
					<ixy>5.593491319448228e-05</ixy>
					<ixz>0.0002393350082696423</ixz>
					<iyy>0.010147544812570268</iyy>
					<iyz>-0.0023690293412525084</iyz>
					<izz>0.0005645774867881984</izz>
				</inertia>
			</inertial>
			<collision name="knee_left_link2_collision">
				<geometry>
					<mesh>
						<uri>model://VRpuppet/meshes/CAD/knee_left_link2.stl</uri>
						<scale>0.001 0.001 0.001</scale>
					</mesh>
				</geometry>
			</collision>
			<visual name="knee_left_link2_visual">
				<geometry>
					<mesh>
						<uri>model://VRpuppet/meshes/CAD/knee_left_link2.stl</uri>
						<scale>0.001 0.001 0.001</scale>
					</mesh>
				</geometry>
			</visual>
		</link>
		<link name="elbow_left_link1">
			<self_collide>false</self_collide>
			<pose frame="">-0.0713198370087738 0.22786211299951023 1.1370189040829852 0.0 -0.0 0.0</pose>
			<inertial>
				<pose frame="">0.0 0.0 0.0 0 0 0</pose>
				<mass>0.06979037783542312</mass>
				<inertia>
					<ixx>0.0938610805625378</ixx>
					<ixy>0.001134169624769473</ixy>
					<ixz>0.005659441522875585</ixz>
					<iyy>0.09059247450039482</iyy>
					<iyz>-0.01808153744996574</iyz>
					<izz>0.00399023352606866</izz>
				</inertia>
			</inertial>
			<collision name="elbow_left_link1_collision">
				<geometry>
					<mesh>
						<uri>model://VRpuppet/meshes/CAD/elbow_left_link1.stl</uri>
						<scale>0.001 0.001 0.001</scale>
					</mesh>
				</geometry>
			</collision>
			<visual name="elbow_left_link1_visual">
				<geometry>
					<mesh>
						<uri>model://VRpuppet/meshes/CAD/elbow_left_link1.stl</uri>
						<scale>0.001 0.001 0.001</scale>
					</mesh>
				</geometry>
			</visual>
		</link>
		<link name="elbow_left_link2">
			<self_collide>false</self_collide>
			<pose frame="">-0.07131983699044678 0.22786211301783885 1.1370189040829841 0.0 -0.0 0.0</pose>
			<inertial>
				<pose frame="">0.0 0.0 0.0 0 0 0</pose>
				<mass>0.046782556025031015</mass>
				<inertia>
					<ixx>0.06291531446335553</ixx>
					<ixy>0.000760267470229521</ixy>
					<ixz>0.003793691168582457</ixz>
					<iyy>0.06072427107020524</iyy>
					<iyz>-0.01212058975858432</iyz>
					<izz>0.0026722255604843103</izz>
				</inertia>
			</inertial>
			<collision name="elbow_left_link2_collision">
				<geometry>
					<mesh>
						<uri>model://VRpuppet/meshes/CAD/elbow_left_link2.stl</uri>
						<scale>0.001 0.001 0.001</scale>
					</mesh>
				</geometry>
			</collision>
			<visual name="elbow_left_link2_visual">
				<geometry>
					<mesh>
						<uri>model://VRpuppet/meshes/CAD/elbow_left_link2.stl</uri>
						<scale>0.001 0.001 0.001</scale>
					</mesh>
				</geometry>
			</visual>
		</link>
		<link name="wrist_left_link1">
			<self_collide>false</self_collide>
			<pose frame="">-0.05041894084619907 0.2717073241359743 0.8690189040829854 0.0 -0.0 0.0</pose>
			<inertial>
				<pose frame="">0.0 0.0 0.0 0 0 0</pose>
				<mass>0.06979037783542305</mass>
				<inertia>
					<ixx>0.057869177372650134</ixx>
					<ixy>0.0009560720302020307</ixy>
					<ixz>0.0030578662925360538</ixz>
					<iyy>0.05289432380005012</iyy>
					<iyz>-0.016478820339463716</iyz>
					<izz>0.005341324844885649</izz>
				</inertia>
			</inertial>
			<collision name="wrist_left_link1_collision">
				<geometry>
					<mesh>
						<uri>model://VRpuppet/meshes/CAD/wrist_left_link1.stl</uri>
						<scale>0.001 0.001 0.001</scale>
					</mesh>
				</geometry>
			</collision>
			<visual name="wrist_left_link1_visual">
				<geometry>
					<mesh>
						<uri>model://VRpuppet/meshes/CAD/wrist_left_link1.stl</uri>
						<scale>0.001 0.001 0.001</scale>
					</mesh>
				</geometry>
			</visual>
		</link>
		<link name="wrist_left_link2">
			<self_collide>false</self_collide>
			<pose frame="">-0.05041894082787189 0.271707324154303 0.8690189040829869 0.0 -0.0 0.0</pose>
			<inertial>
				<pose frame="">0.0 0.0 0.0 0 0 0</pose>
				<mass>0.04678255602503101</mass>
				<inertia>
					<ixx>0.038788876412055716</ixx>
					<ixy>0.0006408833809314679</ixy>
					<ixz>0.0020497782865278114</ixz>
					<iyy>0.035454084808492985</iyy>
					<iyz>-0.011046241039521867</iyz>
					<izz>0.0035779020632579653</izz>
				</inertia>
			</inertial>
			<collision name="wrist_left_link2_collision">
				<geometry>
					<mesh>
						<uri>model://VRpuppet/meshes/CAD/wrist_left_link2.stl</uri>
						<scale>0.001 0.001 0.001</scale>
					</mesh>
				</geometry>
			</collision>
			<visual name="wrist_left_link2_visual">
				<geometry>
					<mesh>
						<uri>model://VRpuppet/meshes/CAD/wrist_left_link2.stl</uri>
						<scale>0.001 0.001 0.001</scale>
					</mesh>
				</geometry>
			</visual>
		</link>
		<link name="hip_left_link1">
			<self_collide>false</self_collide>
			<pose frame="">-0.011426277594490813 0.10380718275933769 0.8954841277672543 0.0 -0.0 0.0</pose>
			<inertial>
				<pose frame="">0.0 0.0 0.0 0 0 0</pose>
				<mass>0.06979037783542139</mass>
				<inertia>
					<ixx>0.05672803690295472</ixx>
					<ixy>8.278043898335915e-05</ixy>
					<ixz>0.0007140986512567287</ixz>
					<iyy>0.05598509241265113</iyy>
					<iyz>-0.006487551924604462</iyz>
					<izz>0.0007728154056936069</izz>
				</inertia>
			</inertial>
			<collision name="hip_left_link1_collision">
				<geometry>
					<mesh>
						<uri>model://VRpuppet/meshes/CAD/hip_left_link1.stl</uri>
						<scale>0.001 0.001 0.001</scale>
					</mesh>
				</geometry>
			</collision>
			<visual name="hip_left_link1_visual">
				<geometry>
					<mesh>
						<uri>model://VRpuppet/meshes/CAD/hip_left_link1.stl</uri>
						<scale>0.001 0.001 0.001</scale>
					</mesh>
				</geometry>
			</visual>
		</link>
		<link name="hip_left_link2">
			<self_collide>false</self_collide>
			<pose frame="">-0.011426277576156765 0.10380718277766483 0.8954841277672544 0.0 -0.0 0.0</pose>
			<inertial>
				<pose frame="">0.0 0.0 0.0 0 0 0</pose>
				<mass>0.046782556025046766</mass>
				<inertia>
					<ixx>0.0380239361777301</ixx>
					<ixy>5.549017843289629e-05</ixy>
					<ixz>0.0004786814621494824</ixz>
					<iyy>0.03752591849487873</iyy>
					<iyz>-0.004348798084279055</iyz>
					<izz>0.0005154949602429389</izz>
				</inertia>
			</inertial>
			<collision name="hip_left_link2_collision">
				<geometry>
					<mesh>
						<uri>model://VRpuppet/meshes/CAD/hip_left_link2.stl</uri>
						<scale>0.001 0.001 0.001</scale>
					</mesh>
				</geometry>
			</collision>
			<visual name="hip_left_link2_visual">
				<geometry>
					<mesh>
						<uri>model://VRpuppet/meshes/CAD/hip_left_link2.stl</uri>
						<scale>0.001 0.001 0.001</scale>
					</mesh>
				</geometry>
			</visual>
		</link>
		<link name="foot_left_link1">
			<self_collide>false</self_collide>
			<pose frame="">-0.009410557923568283 0.12191109690325765 0.11146497559651632 0.0 -0.0 0.0</pose>
			<inertial>
				<pose frame="">0.0 0.0 0.0 0 0 0</pose>
				<mass>0.06979037783542483</mass>
				<inertia>
					<ixx>0.0019160003117788468</ixx>
					<ixy>8.006711139542837e-05</ixy>
					<ixz>7.320644998262254e-05</ixz>
					<iyy>0.0008849342323485516</iyy>
					<iyz>-0.0009483687035625753</iyz>
					<izz>0.0010550744329006008</izz>
				</inertia>
			</inertial>
			<collision name="foot_left_link1_collision">
				<geometry>
					<mesh>
						<uri>model://VRpuppet/meshes/CAD/foot_left_link1.stl</uri>
						<scale>0.001 0.001 0.001</scale>
					</mesh>
				</geometry>
			</collision>
			<visual name="foot_left_link1_visual">
				<geometry>
					<mesh>
						<uri>model://VRpuppet/meshes/CAD/foot_left_link1.stl</uri>
						<scale>0.001 0.001 0.001</scale>
					</mesh>
				</geometry>
			</visual>
		</link>
		<link name="foot_left_link2">
			<self_collide>false</self_collide>
			<pose frame="">-0.00941055790523389 0.12191109692158363 0.11146497559651661 0.0 -0.0 0.0</pose>
			<inertial>
				<pose frame="">0.0 0.0 0.0 0 0 0</pose>
				<mass>0.0467825560250468</mass>
				<inertia>
					<ixx>0.0012818056405032102</ixx>
					<ixy>5.367135462023979e-05</ixy>
					<ixz>4.9072450203816196e-05</ixz>
					<iyy>0.0005906515281707711</iyy>
					<iyz>-0.0006357196133557313</iyz>
					<izz>0.0007047015409470922</izz>
				</inertia>
			</inertial>
			<collision name="foot_left_link2_collision">
				<geometry>
					<mesh>
						<uri>model://VRpuppet/meshes/CAD/foot_left_link2.stl</uri>
						<scale>0.001 0.001 0.001</scale>
					</mesh>
				</geometry>
			</collision>
			<visual name="foot_left_link2_visual">
				<geometry>
					<mesh>
						<uri>model://VRpuppet/meshes/CAD/foot_left_link2.stl</uri>
						<scale>0.001 0.001 0.001</scale>
					</mesh>
				</geometry>
			</visual>
		</link>
		<link name="lower_leg_right">
			<self_collide>false</self_collide>
			<pose frame="">-0.047648624323068864 -0.11249174998202205 0.3281763683960044 0.0 -0.0 0.0</pose>
			<inertial>
				<pose frame="">0.0 0.0 0.0 0 0 0</pose>
				<mass>27.22911787247933</mass>
				<inertia>
					<ixx>3.5579731242419097</ixx>
					<ixy>-0.14332021627451483</ixy>
					<ixz>0.41848033730353784</ixz>
					<iyy>3.285422931495319</iyy>
					<iyz>0.9974952828432662</iyz>
					<izz>0.45288695207992324</izz>
				</inertia>
			</inertial>
			<collision name="lower_leg_right_collision">
				<geometry>
					<mesh>
						<uri>model://VRpuppet/meshes/CAD/lower_leg_right.stl</uri>
						<scale>0.001 0.001 0.001</scale>
					</mesh>
				</geometry>
			</collision>
			<visual name="lower_leg_right_visual">
				<geometry>
					<mesh>
						<uri>model://VRpuppet/meshes/CAD/lower_leg_right.stl</uri>
						<scale>0.001 0.001 0.001</scale>
					</mesh>
				</geometry>
			</visual>
		</link>
		<link name="foot_right">
			<self_collide>false</self_collide>
			<pose frame="">-0.03078586813183749 -0.12240963132352976 0.11085911144948236 0.0 -0.0 0.0</pose>
			<inertial>
				<pose frame="">0.0 0.0 0.0 0 0 0</pose>
				<mass>0.2795712981996832</mass>
				<inertia>
					<ixx>0.007669426553180407</ixx>
					<ixy>-0.0010535607179814883</ixy>
					<ixz>0.0009541471208166398</ixz>
					<iyy>0.0037452666563460853</iyy>
					<iyz>0.0037938449303246287</iyz>
					<izz>0.004496457668169397</izz>
				</inertia>
			</inertial>
			<collision name="foot_right_collision">
				<geometry>
					<mesh>
						<uri>model://VRpuppet/meshes/CAD/foot_right.stl</uri>
						<scale>0.001 0.001 0.001</scale>
					</mesh>
				</geometry>
			</collision>
			<visual name="foot_right_visual">
				<geometry>
					<mesh>
						<uri>model://VRpuppet/meshes/CAD/foot_right.stl</uri>
						<scale>0.001 0.001 0.001</scale>
					</mesh>
				</geometry>
			</visual>
		</link>
		<link name="upper_leg_right">
			<self_collide>false</self_collide>
			<pose frame="">-0.022788154128297468 -0.10966463316694061 0.7423935581154243 0.0 -0.0 0.0</pose>
			<inertial>
				<pose frame="">0.0 0.0 0.0 0 0 0</pose>
				<mass>63.39184409768466</mass>
				<inertia>
					<ixx>36.739359452096586</ixx>
					<ixy>-0.1466100866013607</ixy>
					<ixz>1.102477805075895</ixz>
					<iyy>36.06288190042159</iyy>
					<iyz>5.166895198331794</iyz>
					<izz>0.9892013975403753</izz>
				</inertia>
			</inertial>
			<collision name="upper_leg_right_collision">
				<geometry>
					<mesh>
						<uri>model://VRpuppet/meshes/CAD/upper_leg_right.stl</uri>
						<scale>0.001 0.001 0.001</scale>
					</mesh>
				</geometry>
			</collision>
			<visual name="upper_leg_right_visual">
				<geometry>
					<mesh>
						<uri>model://VRpuppet/meshes/CAD/upper_leg_right.stl</uri>
						<scale>0.001 0.001 0.001</scale>
					</mesh>
				</geometry>
			</visual>
		</link>
		<link name="chest">
			<self_collide>false</self_collide>
			<pose frame="">-0.025065457998930337 -0.002741971531160698 1.3448247502839468 0.0 -0.0 0.0</pose>
			<inertial>
				<pose frame="">0.0 0.0 0.0 0 0 0</pose>
				<mass>2.0895139823533024</mass>
				<inertia>
					<ixx>3.9524457490421483</ixx>
					<ixy>-0.0006654909039640642</ixy>
					<ixz>0.07118692605918392</ixz>
					<iyy>3.9475673395760693</iyy>
					<iyz>0.007659817430062151</iyz>
					<izz>0.009024484509844916</izz>
				</inertia>
			</inertial>
			<collision name="chest_collision">
				<geometry>
					<mesh>
						<uri>model://VRpuppet/meshes/CAD/chest.stl</uri>
						<scale>0.001 0.001 0.001</scale>
					</mesh>
				</geometry>
			</collision>
			<visual name="chest_visual">
				<geometry>
					<mesh>
						<uri>model://VRpuppet/meshes/CAD/chest.stl</uri>
						<scale>0.001 0.001 0.001</scale>
					</mesh>
				</geometry>
			</visual>
		</link>
		<link name="upper_arm_right">
			<self_collide>false</self_collide>
			<pose frame="">-0.10587334673601348 -0.20946254793602326 1.1745803142509361 0.0 -0.0 0.0</pose>
			<inertial>
				<pose frame="">0.0 0.0 0.0 0 0 0</pose>
				<mass>0.11563807156317799</mass>
				<inertia>
					<ixx>0.16564830019102675</ixx>
					<ixy>-0.0025852498411248303</ixy>
					<ixz>0.014267436827144889</ixz>
					<iyy>0.16185014433988829</iyy>
					<iyz>0.02827128548919638</iyz>
					<izz>0.006439566613380333</izz>
				</inertia>
			</inertial>
			<collision name="upper_arm_right_collision">
				<geometry>
					<mesh>
						<uri>model://VRpuppet/meshes/CAD/upper_arm_right.stl</uri>
						<scale>0.001 0.001 0.001</scale>
					</mesh>
				</geometry>
			</collision>
			<visual name="upper_arm_right_visual">
				<geometry>
					<mesh>
						<uri>model://VRpuppet/meshes/CAD/upper_arm_right.stl</uri>
						<scale>0.001 0.001 0.001</scale>
					</mesh>
				</geometry>
			</visual>
		</link>
		<link name="lower_arm_right">
			<self_collide>false</self_collide>
			<pose frame="">-0.09895299495120308 -0.2549532998024565 0.9072944075039571 0.0 -0.0 0.0</pose>
			<inertial>
				<pose frame="">0.0 0.0 0.0 0 0 0</pose>
				<mass>0.11563807156317799</mass>
				<inertia>
					<ixx>0.1037952358192096</ixx>
					<ixy>-0.00290773074489254</ixy>
					<ixz>0.010427544319140373</ixz>
					<iyy>0.09736536466204024</iyy>
					<iyz>0.0265315029392369</iyz>
					<izz>0.00872149600005539</izz>
				</inertia>
			</inertial>
			<collision name="lower_arm_right_collision">
				<geometry>
					<mesh>
						<uri>model://VRpuppet/meshes/CAD/lower_arm_right.stl</uri>
						<scale>0.001 0.001 0.001</scale>
					</mesh>
				</geometry>
			</collision>
			<visual name="lower_arm_right_visual">
				<geometry>
					<mesh>
						<uri>model://VRpuppet/meshes/CAD/lower_arm_right.stl</uri>
						<scale>0.001 0.001 0.001</scale>
					</mesh>
				</geometry>
			</visual>
		</link>
		<link name="hand_right">
			<self_collide>false</self_collide>
			<pose frame="">-0.09628946516087629 -0.25259200879166605 0.8690191311784201 0.0 -0.0 0.0</pose>
			<inertial>
				<pose frame="">0.0 0.0 0.0 0 0 0</pose>
				<mass>0.01651527333909785</mass>
				<inertia>
					<ixx>0.013526669952126582</ixx>
					<ixy>-0.0004017221677441583</ixy>
					<ixz>0.0013819549252235511</ixz>
					<iyy>0.012625637080884393</iyy>
					<iyz>0.0036252228248703704</iyz>
					<izz>0.0012075580529869038</izz>
				</inertia>
			</inertial>
			<collision name="hand_right_collision">
				<geometry>
					<mesh>
						<uri>model://VRpuppet/meshes/CAD/hand_right.stl</uri>
						<scale>0.001 0.001 0.001</scale>
					</mesh>
				</geometry>
			</collision>
			<visual name="hand_right_visual">
				<geometry>
					<mesh>
						<uri>model://VRpuppet/meshes/CAD/hand_right.stl</uri>
						<scale>0.001 0.001 0.001</scale>
					</mesh>
				</geometry>
			</visual>
		</link>
		<link name="upper_arm_left">
			<self_collide>false</self_collide>
			<pose frame="">-0.0679964372833337 0.22301467194975302 1.1745803029018593 0.0 -0.0 0.0</pose>
			<inertial>
				<pose frame="">0.0 0.0 0.0 0 0 0</pose>
				<mass>0.11563810874472029</mass>
				<inertia>
					<ixx>0.166307413582168</ixx>
					<ixy>0.0017639251461552608</ixy>
					<ixz>0.009148892975354943</ixz>
					<iyy>0.16108329631059937</iyy>
					<iyz>-0.030173755987746763</iyz>
					<izz>0.006331735454186379</izz>
				</inertia>
			</inertial>
			<collision name="upper_arm_left_collision">
				<geometry>
					<mesh>
						<uri>model://VRpuppet/meshes/CAD/upper_arm_left.stl</uri>
						<scale>0.001 0.001 0.001</scale>
					</mesh>
				</geometry>
			</collision>
			<visual name="upper_arm_left_visual">
				<geometry>
					<mesh>
						<uri>model://VRpuppet/meshes/CAD/upper_arm_left.stl</uri>
						<scale>0.001 0.001 0.001</scale>
					</mesh>
				</geometry>
			</visual>
		</link>
		<link name="lower_arm_left">
			<self_collide>false</self_collide>
			<pose frame="">-0.053281833040679454 0.2666126106813735 0.9072943959252863 0.0 -0.0 0.0</pose>
			<inertial>
				<pose frame="">0.0 0.0 0.0 0 0 0</pose>
				<mass>0.11563810874472034</mass>
				<inertia>
					<ixx>0.10446759284304319</ixx>
					<ixy>0.0016332345481314349</ixy>
					<ixz>0.00566609346857091</ixz>
					<iyy>0.09656499331827892</iyy>
					<iyz>-0.02784611885307521</iyz>
					<izz>0.008593425228288779</izz>
				</inertia>
			</inertial>
			<collision name="lower_arm_left_collision">
				<geometry>
					<mesh>
						<uri>model://VRpuppet/meshes/CAD/lower_arm_left.stl</uri>
						<scale>0.001 0.001 0.001</scale>
					</mesh>
				</geometry>
			</collision>
			<visual name="lower_arm_left_visual">
				<geometry>
					<mesh>
						<uri>model://VRpuppet/meshes/CAD/lower_arm_left.stl</uri>
						<scale>0.001 0.001 0.001</scale>
					</mesh>
				</geometry>
			</visual>
		</link>
		<link name="hand_left">
			<self_collide>false</self_collide>
			<pose frame="">-0.04952478867695269 0.28192436854417696 0.8690191311784145 0.0 -0.0 0.0</pose>
			<inertial>
				<pose frame="">0.0 0.0 0.0 0 0 0</pose>
				<mass>0.016515273339097858</mass>
				<inertia>
					<ixx>0.013785606741828639</ixx>
					<ixy>0.00023055167682189333</ixy>
					<ixz>0.0007107841423446757</ixz>
					<iyy>0.012513020167321505</iyy>
					<iyz>-0.004046203520421022</iyz>
					<izz>0.0013538779291266824</izz>
				</inertia>
			</inertial>
			<collision name="hand_left_collision">
				<geometry>
					<mesh>
						<uri>model://VRpuppet/meshes/CAD/hand_left.stl</uri>
						<scale>0.001 0.001 0.001</scale>
					</mesh>
				</geometry>
			</collision>
			<visual name="hand_left_visual">
				<geometry>
					<mesh>
						<uri>model://VRpuppet/meshes/CAD/hand_left.stl</uri>
						<scale>0.001 0.001 0.001</scale>
					</mesh>
				</geometry>
			</visual>
		</link>
		<link name="upper_leg_left">
			<self_collide>false</self_collide>
			<pose frame="">-0.004277611892833151 0.10178374541647559 0.7422497734866815 0.0 -0.0 0.0</pose>
			<inertial>
				<pose frame="">0.0 0.0 0.0 0 0 0</pose>
				<mass>63.32645097326837</mass>
				<inertia>
					<ixx>36.57973518632728</ixx>
					<ixy>0.025531232026523833</ixy>
					<ixz>0.22952612911216297</ixz>
					<iyy>35.98267439802099</iyy>
					<iyz>-4.795008527943786</iyz>
					<izz>0.851120562398565</izz>
				</inertia>
			</inertial>
			<collision name="upper_leg_left_collision">
				<geometry>
					<mesh>
						<uri>model://VRpuppet/meshes/CAD/upper_leg_left.stl</uri>
						<scale>0.001 0.001 0.001</scale>
					</mesh>
				</geometry>
			</collision>
			<visual name="upper_leg_left_visual">
				<geometry>
					<mesh>
						<uri>model://VRpuppet/meshes/CAD/upper_leg_left.stl</uri>
						<scale>0.001 0.001 0.001</scale>
					</mesh>
				</geometry>
			</visual>
		</link>
		<link name="lower_leg_left">
			<self_collide>false</self_collide>
			<pose frame="">-0.027347758615848913 0.10915465331342636 0.31881332783644073 0.0 -0.0 0.0</pose>
			<inertial>
				<pose frame="">0.0 0.0 0.0 0 0 0</pose>
				<mass>28.43783650100289</mass>
				<inertia>
					<ixx>3.5664796438702537</ixx>
					<ixy>0.08401137312564953</ixy>
					<ixz>0.2477114654783178</ixz>
					<iyy>3.260810826061813</iyy>
					<iyz>-0.9790790917248035</iyz>
					<izz>0.4078059442215795</izz>
				</inertia>
			</inertial>
			<collision name="lower_leg_left_collision">
				<geometry>
					<mesh>
						<uri>model://VRpuppet/meshes/CAD/lower_leg_left.stl</uri>
						<scale>0.001 0.001 0.001</scale>
					</mesh>
				</geometry>
			</collision>
			<visual name="lower_leg_left_visual">
				<geometry>
					<mesh>
						<uri>model://VRpuppet/meshes/CAD/lower_leg_left.stl</uri>
						<scale>0.001 0.001 0.001</scale>
					</mesh>
				</geometry>
			</visual>
		</link>
		<link name="foot_left">
			<self_collide>false</self_collide>
			<pose frame="">-0.00991984754346 0.11608970196045425 0.10993444486070429 0.0 -0.0 0.0</pose>
			<inertial>
				<pose frame="">0.0 0.0 0.0 0 0 0</pose>
				<mass>0.2795712981996832</mass>
				<inertia>
					<ixx>0.007192350249843101</ixx>
					<ixy>0.0003219000689589345</ixy>
					<ixz>0.0003047762519740455</ixz>
					<iyy>0.0034515392248869194</iyy>
					<iyz>-0.0035691649816709616</iyz>
					<izz>0.003838201031576945</izz>
				</inertia>
			</inertial>
			<collision name="foot_left_collision">
				<geometry>
					<mesh>
						<uri>model://VRpuppet/meshes/CAD/foot_left.stl</uri>
						<scale>0.001 0.001 0.001</scale>
					</mesh>
				</geometry>
			</collision>
			<visual name="foot_left_visual">
				<geometry>
					<mesh>
						<uri>model://VRpuppet/meshes/CAD/foot_left.stl</uri>
						<scale>0.001 0.001 0.001</scale>
					</mesh>
				</geometry>
			</visual>
		</link>
		<link name="head">
			<self_collide>false</self_collide>
			<pose frame="">-0.017081207803059245 -0.003652589220768542 1.6542285628209408 0.0 -0.0 0.0</pose>
			<inertial>
				<pose frame="">0.0 0.0 0.0 0 0 0</pose>
				<mass>35.90620293890531</mass>
				<inertia>
					<ixx>98.4016398560236</ixx>
					<ixy>0.0024270841017597815</ixy>
					<ixz>1.0425153185535418</ixz>
					<iyy>98.46385951878611</iyy>
					<iyz>0.2143105314031048</iyz>
					<izz>0.1679277732426822</izz>
				</inertia>
			</inertial>
			<collision name="head_collision">
				<geometry>
					<mesh>
						<uri>model://VRpuppet/meshes/CAD/head.stl</uri>
						<scale>0.001 0.001 0.001</scale>
					</mesh>
				</geometry>
			</collision>
			<visual name="head_visual">
				<geometry>
					<mesh>
						<uri>model://VRpuppet/meshes/CAD/head.stl</uri>
						<scale>0.001 0.001 0.001</scale>
					</mesh>
				</geometry>
			</visual>
		</link>
		<link name="hip">
			<self_collide>false</self_collide>
			<pose frame="">-0.019764489805874665 -0.003383368150272576 0.9505141785492641 0.0 -0.0 0.0</pose>
			<inertial>
				<pose frame="">0.0 0.0 0.0 0 0 0</pose>
				<mass>43.179324708677235</mass>
				<inertia>
					<ixx>39.274963315326886</ixx>
					<ixy>-0.005378069050759215</ixy>
					<ixz>0.8064540894149136</ixz>
					<iyy>39.262031038387676</iyy>
					<iyz>0.13869185352231367</iyz>
					<izz>0.3012744013144662</izz>
				</inertia>
			</inertial>
			<collision name="hip_collision">
				<geometry>
					<mesh>
						<uri>model://VRpuppet/meshes/CAD/hip.stl</uri>
						<scale>0.001 0.001 0.001</scale>
					</mesh>
				</geometry>
			</collision>
			<visual name="hip_visual">
				<geometry>
					<mesh>
						<uri>model://VRpuppet/meshes/CAD/hip.stl</uri>
						<scale>0.001 0.001 0.001</scale>
					</mesh>
				</geometry>
			</visual>
		</link>
		<joint name="elbow_left_axis0" type="revolute">
			<parent>upper_arm_left</parent>
			<child>elbow_left_link1</child>
			<pose frame="">0.29209893263801606 -0.1369541779094035 -4.831690603168682e-15 0 0 0</pose>
			<axis>
				<xyz>-2.5304758288768916e-13 1.3505903520121705e-14 -1.0000000000000049</xyz>
				<limit>
					<lower>-3.141592653589793</lower>
					<upper>3.141592653589793</upper>
				</limit>
				<use_parent_model_frame>0</use_parent_model_frame>
			</axis>
		</joint>
		<joint name="elbow_left_axis2" type="revolute">
			<parent>elbow_left_link2</parent>
			<child>lower_arm_left</child>
			<pose frame="">0.2740609286699217 -0.17570467559126676 0.22972450815769407 0 0 0</pose>
			<axis>
				<xyz>0.9999999999999986 -8.879455281983226e-17 -2.507161145359759e-13</xyz>
				<limit>
					<lower>-3.141592653589793</lower>
					<upper>3.141592653589793</upper>
				</limit>
				<use_parent_model_frame>0</use_parent_model_frame>
			</axis>
		</joint>
		<joint name="ankle_right_axis1" type="revolute">
			<parent>elbow_left_link1</parent>
			<child>elbow_left_link2</child>
			<pose frame="">0.292098932619686 -0.13695417792773204 -3.268496584496461e-15 0 0 0</pose>
			<axis>
				<xyz>-7.156266817764895e-17 -1.0000000000000002 -1.4033259456818733e-14</xyz>
				<limit>
					<lower>-3.141592653589793</lower>
					<upper>3.141592653589793</upper>
				</limit>
				<use_parent_model_frame>0</use_parent_model_frame>
			</axis>
		</joint>
		<joint name="wrist_left_axis0" type="revolute">
			<parent>lower_arm_left</parent>
			<child>wrist_left_link1</child>
			<pose frame="">0.31669803647544087 -0.19779938904586433 -2.2737367544323206e-15 0 0 0</pose>
			<axis>
				<xyz>-2.530475828876854e-13 1.351978130792962e-14 -1.0000000000000049</xyz>
				<limit>
					<lower>-3.141592653589793</lower>
					<upper>3.141592653589793</upper>
				</limit>
				<use_parent_model_frame>0</use_parent_model_frame>
			</axis>
		</joint>
		<joint name="wrist_left_axis2" type="revolute">
			<parent>wrist_left_link2</parent>
			<child>hand_left</child>
			<pose frame="">0.31580388430619455 -0.208016433454067 -2.2709543102905629e-07 0 0 0</pose>
			<axis>
				<xyz>0.9999999999999986 -3.328340158902708e-17 -2.5071611453597603e-13</xyz>
				<limit>
					<lower>-3.141592653589793</lower>
					<upper>3.141592653589793</upper>
				</limit>
				<use_parent_model_frame>0</use_parent_model_frame>
			</axis>
		</joint>
		<joint name="wrist_left_axis1" type="revolute">
			<parent>wrist_left_link1</parent>
			<child>wrist_left_link2</child>
			<pose frame="">0.31669803645711064 -0.19779938906419278 -5.826450433232822e-15 0 0 0</pose>
			<axis>
				<xyz>-1.6051516946003177e-17 -1.0000000000000002 -1.4074892820242178e-14</xyz>
				<limit>
					<lower>-3.141592653589793</lower>
					<upper>3.141592653589793</upper>
				</limit>
				<use_parent_model_frame>0</use_parent_model_frame>
			</axis>
		</joint>
		<joint name="motor0" type="prismatic">
			<parent>base</parent>
			<child>motor0</child>
			<pose frame="">-0.00033431159346434923 -1.2358101926090335 -0.009514196340348889 0 0 0</pose>
			<axis>
				<xyz>0.0 -1.0 0.0</xyz>
				<limit>
					<lower>-1.4</lower>
					<upper>0.0</upper>
				</limit>
				<use_parent_model_frame>0</use_parent_model_frame>
			</axis>
		</joint>
		<joint name="motor1" type="prismatic">
			<parent>base</parent>
			<child>motor1</child>
			<pose frame="">-0.00033430154605355254 1.2358101829513677 -0.009485805505270662 0 0 0</pose>
			<axis>
				<xyz>0.0 -1.0 0.0</xyz>
				<limit>
					<lower>0.0</lower>
					<upper>1.4</upper>
				</limit>
				<use_parent_model_frame>0</use_parent_model_frame>
			</axis>
		</joint>
		<joint name="motor2" type="prismatic">
			<parent>base</parent>
			<child>motor2</child>
			<pose frame="">0.00033431159342597996 -1.2358101926090346 -0.009485803664418523 0 0 0</pose>
			<axis>
				<xyz>0.0 1.0 0.0</xyz>
				<limit>
					<lower>0.0</lower>
					<upper>1.4</upper>
				</limit>
				<use_parent_model_frame>0</use_parent_model_frame>
			</axis>
		</joint>
		<joint name="motor3" type="prismatic">
			<parent>base</parent>
			<child>motor3</child>
			<pose frame="">-0.0011978126745185592 1.2342394028102621 -0.00951655894117484 0 0 0</pose>
			<axis>
				<xyz>0.0 1.0 0.0</xyz>
				<limit>
					<lower>-1.4</lower>
					<upper>0.0</upper>
				</limit>
				<use_parent_model_frame>0</use_parent_model_frame>
			</axis>
		</joint>
		<joint name="motor4" type="prismatic">
			<parent>base</parent>
			<child>motor5</child>
			<pose frame="">-1.2358101926090344 -0.00033431159341290595 -0.009485803664418506 0 0 0</pose>
			<axis>
				<xyz>1.0 0.0 0.0</xyz>
				<limit>
					<lower>0.0</lower>
					<upper>1.4</upper>
				</limit>
				<use_parent_model_frame>0</use_parent_model_frame>
			</axis>
		</joint>
		<joint name="motor5" type="prismatic">
			<parent>base</parent>
			<child>motor4</child>
			<pose frame="">1.2358101829513672 -0.0003343015461072696 -0.00951419449950688 0 0 0</pose>
			<axis>
				<xyz>1.0 0.0 0.0</xyz>
				<limit>
					<lower>-1.4</lower>
					<upper>0.0</upper>
				</limit>
				<use_parent_model_frame>0</use_parent_model_frame>
			</axis>
		</joint>
		<joint name="motor6" type="prismatic">
			<parent>base</parent>
			<child>motor7</child>
			<pose frame="">-1.2358101926090332 0.0003343115934802654 -0.009514196340348885 0 0 0</pose>
			<axis>
				<xyz>-1.0 0.0 0.0</xyz>
				<limit>
					<lower>-1.4</lower>
					<upper>0.0</upper>
				</limit>
				<use_parent_model_frame>0</use_parent_model_frame>
			</axis>
		</joint>
		<joint name="motor7" type="prismatic">
			<parent>base</parent>
			<child>motor6</child>
			<pose frame="">1.2358101829513677 0.0003343018224896355 -0.00948580550527066 0 0 0</pose>
			<axis>
				<xyz>-1.0 0.0 0.0</xyz>
				<limit>
					<lower>0.0</lower>
					<upper>1.4</upper>
				</limit>
				<use_parent_model_frame>0</use_parent_model_frame>
			</axis>
		</joint>
		<joint name="knee_left_axis0" type="revolute">
			<parent>upper_leg_left</parent>
			<child>knee_left_link1</child>
			<pose frame="">0.1184067983891455 -0.08835796708463471 7.815970093361102e-16 0 0 0</pose>
			<axis>
				<xyz>0.9999999999999996 -4.1806835771034814e-16 -1.9598976533926194e-17</xyz>
				<limit>
					<lower>-3.141592653589793</lower>
					<upper>3.141592653589793</upper>
				</limit>
				<use_parent_model_frame>0</use_parent_model_frame>
			</axis>
		</joint>
		<joint name="knee_left_axis2" type="revolute">
			<parent>knee_left_link2</parent>
			<child>lower_leg_left</child>
			<pose frame="">0.1347640581242422 -0.08872446414826261 0.14667079993081106 0 0 0</pose>
			<axis>
				<xyz>-2.917023895426902e-17 -1.3767600013708988e-14 0.9999999999999997</xyz>
				<limit>
					<lower>-3.141592653589793</lower>
					<upper>3.141592653589793</upper>
				</limit>
				<use_parent_model_frame>0</use_parent_model_frame>
			</axis>
		</joint>
		<joint name="knee_left_axis1" type="revolute">
			<parent>knee_left_link1</parent>
			<child>knee_left_link2</child>
			<pose frame="">0.1184067983708119 -0.08835796710296011 -9.237055564881303e-16 0 0 0</pose>
			<axis>
				<xyz>-2.5153490401660483e-16 -0.9999999999999997 -1.3712088862477735e-14</xyz>
				<limit>
					<lower>-3.141592653589793</lower>
					<upper>3.141592653589793</upper>
				</limit>
				<use_parent_model_frame>0</use_parent_model_frame>
			</axis>
		</joint>
		<joint name="motor8" type="prismatic">
			<parent>base</parent>
			<child>motor8</child>
			<pose frame="">0.0011978136706753161 -1.2342394009707207 -0.00951655921897796 0 0 0</pose>
			<axis>
				<xyz>0.0 -1.0 0.0</xyz>
				<limit>
					<lower>-1.4</lower>
					<upper>0.0</upper>
				</limit>
				<use_parent_model_frame>0</use_parent_model_frame>
			</axis>
		</joint>
		<joint name="motor9" type="prismatic">
			<parent>base</parent>
			<child>motor9</child>
			<pose frame="">-0.0003343018224884986 1.2358101829513672 -0.00948580573277212 0 0 0</pose>
			<axis>
				<xyz>0.0 -1.0 0.0</xyz>
				<limit>
					<lower>0.0</lower>
					<upper>0.0</upper>
				</limit>
				<use_parent_model_frame>0</use_parent_model_frame>
			</axis>
		</joint>
		<joint name="motor10" type="prismatic">
			<parent>base</parent>
			<child>motor11</child>
			<pose frame="">-0.0011978126745208328 1.234239402810263 -0.009516558941175219 0 0 0</pose>
			<axis>
				<xyz>0.0 1.0 0.0</xyz>
				<limit>
					<lower>-1.4</lower>
					<upper>0.0</upper>
				</limit>
				<use_parent_model_frame>0</use_parent_model_frame>
			</axis>
		</joint>
		<joint name="motor11" type="prismatic">
			<parent>base</parent>
			<child>motor10</child>
			<pose frame="">-0.001197813670675032 -1.2342394009707196 -0.009483440781021528 0 0 0</pose>
			<axis>
				<xyz>0.0 1.0 0.0</xyz>
				<limit>
					<lower>0.0</lower>
					<upper>1.4</upper>
				</limit>
				<use_parent_model_frame>0</use_parent_model_frame>
			</axis>
		</joint>
		<joint name="motor12" type="prismatic">
			<parent>base</parent>
			<child>motor12</child>
			<pose frame="">1.234239402810263 0.001197812674521117 -0.009516558941175077 0 0 0</pose>
			<axis>
				<xyz>1.0 0.0 0.0</xyz>
				<limit>
					<lower>-1.4</lower>
					<upper>0.0</upper>
				</limit>
				<use_parent_model_frame>0</use_parent_model_frame>
			</axis>
		</joint>
		<joint name="motor13" type="prismatic">
			<parent>base</parent>
			<child>motor13</child>
			<pose frame="">-1.2342394009707198 0.0011978136706744635 -0.00948344078102167 0 0 0</pose>
			<axis>
				<xyz>1.0 0.0 0.0</xyz>
				<limit>
					<lower>0.0</lower>
					<upper>1.4</upper>
				</limit>
				<use_parent_model_frame>0</use_parent_model_frame>
			</axis>
		</joint>
		<joint name="motor14" type="prismatic">
			<parent>base</parent>
			<child>motor15</child>
			<pose frame="">-1.2342394009707207 -0.0011978136706756004 -0.00951655921897796 0 0 0</pose>
			<axis>
				<xyz>-1.0 0.0 0.0</xyz>
				<limit>
					<lower>-1.4</lower>
					<upper>0.0</upper>
				</limit>
				<use_parent_model_frame>0</use_parent_model_frame>
			</axis>
		</joint>
		<joint name="motor15" type="prismatic">
			<parent>base</parent>
			<child>motor14</child>
			<pose frame="">1.234239402810262 -0.001197812674521117 -0.009483441058825265 0 0 0</pose>
			<axis>
				<xyz>-1.0 0.0 0.0</xyz>
				<limit>
					<lower>0.0</lower>
					<upper>1.4</upper>
				</limit>
				<use_parent_model_frame>0</use_parent_model_frame>
			</axis>
		</joint>
		<joint name="motor16" type="prismatic">
			<parent>base</parent>
			<child>motor16</child>
			<pose frame="">0.0011978136706730425 -1.2342394009707198 -0.009516559218978102 0 0 0</pose>
			<axis>
				<xyz>0.0 -1.0 0.0</xyz>
				<limit>
					<lower>-1.4</lower>
					<upper>0.0</upper>
				</limit>
				<use_parent_model_frame>0</use_parent_model_frame>
			</axis>
		</joint>
		<joint name="motor17" type="prismatic">
			<parent>base</parent>
			<child>motor17</child>
			<pose frame="">0.0011978126745225382 1.2342394028102615 -0.009483441058823702 0 0 0</pose>
			<axis>
				<xyz>0.0 -1.0 0.0</xyz>
				<limit>
					<lower>0.0</lower>
					<upper>1.4</upper>
				</limit>
				<use_parent_model_frame>0</use_parent_model_frame>
			</axis>
		</joint>
		<joint name="motor18" type="prismatic">
			<parent>base</parent>
			<child>motor19</child>
			<pose frame="">-0.0011978126745191275 1.2342394028102615 -0.009516558941174936 0 0 0</pose>
			<axis>
				<xyz>0.0 1.0 0.0</xyz>
				<limit>
					<lower>-1.4</lower>
					<upper>0.0</upper>
				</limit>
				<use_parent_model_frame>0</use_parent_model_frame>
			</axis>
		</joint>
		<joint name="motor19" type="prismatic">
			<parent>base</parent>
			<child>motor18</child>
			<pose frame="">-0.0011978136706770216 -1.2342394009707196 -0.009483440781021103 0 0 0</pose>
			<axis>
				<xyz>0.0 1.0 0.0</xyz>
				<limit>
					<lower>0.0</lower>
					<upper>1.4</upper>
				</limit>
				<use_parent_model_frame>0</use_parent_model_frame>
			</axis>
		</joint>
		<joint name="motor20" type="prismatic">
			<parent>base</parent>
			<child>motor20</child>
			<pose frame="">1.2342394028102615 0.0011978126745188433 -0.009516558941174936 0 0 0</pose>
			<axis>
				<xyz>1.0 0.0 0.0</xyz>
				<limit>
					<lower>-1.4</lower>
					<upper>0.0</upper>
				</limit>
				<use_parent_model_frame>0</use_parent_model_frame>
			</axis>
		</joint>
		<joint name="motor21" type="prismatic">
			<parent>base</parent>
			<child>motor21</child>
			<pose frame="">-1.2342394009707203 0.0011978136706756004 -0.009483440781021386 0 0 0</pose>
			<axis>
				<xyz>1.0 0.0 0.0</xyz>
				<limit>
					<lower>0.0</lower>
					<upper>1.4</upper>
				</limit>
				<use_parent_model_frame>0</use_parent_model_frame>
			</axis>
		</joint>
		<joint name="motor22" type="prismatic">
			<parent>base</parent>
			<child>motor23</child>
			<pose frame="">-1.2342394009707196 -0.0011978136706733266 -0.009516559218977535 0 0 0</pose>
			<axis>
				<xyz>-1.0 0.0 0.0</xyz>
				<limit>
					<lower>-1.4</lower>
					<upper>0.0</upper>
				</limit>
				<use_parent_model_frame>0</use_parent_model_frame>
			</axis>
		</joint>
		<joint name="motor23" type="prismatic">
			<parent>base</parent>
			<child>motor22</child>
			<pose frame="">1.2342394028102621 -0.001197812674522254 -0.009483441058824553 0 0 0</pose>
			<axis>
				<xyz>-1.0 0.0 0.0</xyz>
				<limit>
					<lower>0.0</lower>
					<upper>1.4</upper>
				</limit>
				<use_parent_model_frame>0</use_parent_model_frame>
			</axis>
		</joint>
		<joint name="foot_right_axis0" type="revolute">
			<parent>lower_leg_right</parent>
			<child>ankle_right_link1</child>
			<pose frame="">-0.09384115112673463 0.14240964622624927 2.486899575160351e-15 0 0 0</pose>
			<axis>
				<xyz>1.0 -4.139818793615308e-31 -2.2204460492503032e-15</xyz>
				<limit>
					<lower>-3.141592653589793</lower>
					<upper>3.141592653589793</upper>
				</limit>
				<use_parent_model_frame>0</use_parent_model_frame>
			</axis>
		</joint>
		<joint name="foot_right_axis2" type="revolute">
			<parent>ankle_right_link2</parent>
			<child>foot_right</child>
			<pose frame="">-0.09384113620652583 0.14240963132353443 0.0006058641470340654 0 0 0</pose>
			<axis>
				<xyz>-7.143892735423172e-45 1.3745948823640208e-14 -0.9999999999999997</xyz>
				<limit>
					<lower>-3.141592653589793</lower>
					<upper>3.141592653589793</upper>
				</limit>
				<use_parent_model_frame>0</use_parent_model_frame>
			</axis>
		</joint>
		<joint name="foot_right_axis1" type="revolute">
			<parent>ankle_right_link1</parent>
			<child>ankle_right_link2</child>
			<pose frame="">-0.09384115114505283 0.14240964620792262 -3.019806626980426e-16 0 0 0</pose>
			<axis>
				<xyz>3.1133334864315536e-29 0.9999999999999997 1.371819324802458e-14</xyz>
				<limit>
					<lower>-3.141592653589793</lower>
					<upper>3.141592653589793</upper>
				</limit>
				<use_parent_model_frame>0</use_parent_model_frame>
			</axis>
		</joint>
		<joint name="knee_right_axis0" type="revolute">
			<parent>upper_leg_right</parent>
			<child>knee_right_link1</child>
			<pose frame="">-0.08135328292293315 0.12964190782552623 3.126388037344441e-15 0 0 0</pose>
			<axis>
				<xyz>0.9999999999999996 4.1806835771041026e-16 -2.234323837058117e-15</xyz>
				<limit>
					<lower>-3.141592653589793</lower>
					<upper>3.141592653589793</upper>
				</limit>
				<use_parent_model_frame>0</use_parent_model_frame>
			</axis>
		</joint>
		<joint name="knee_right_axis2" type="revolute">
			<parent>knee_right_link2</parent>
			<child>lower_leg_right</child>
			<pose frame="">-0.06376767518532442 0.1329219391471858 0.1373077593712474 0 0 0</pose>
			<axis>
				<xyz>-2.917023895426823e-17 1.3767600013708988e-14 -0.9999999999999997</xyz>
				<limit>
					<lower>-3.141592653589793</lower>
					<upper>3.141592653589793</upper>
				</limit>
				<use_parent_model_frame>0</use_parent_model_frame>
			</axis>
		</joint>
		<joint name="knee_right_axis1" type="revolute">
			<parent>knee_right_link1</parent>
			<child>knee_right_link2</child>
			<pose frame="">-0.08135328294125153 0.1296419078071991 -8.526512829121202e-16 0 0 0</pose>
			<axis>
				<xyz>-2.515349040166056e-16 0.9999999999999997 1.3712088862477733e-14</xyz>
				<limit>
					<lower>-3.141592653589793</lower>
					<upper>3.141592653589793</upper>
				</limit>
				<use_parent_model_frame>0</use_parent_model_frame>
			</axis>
		</joint>
		<joint name="hip_right_axis0" type="revolute">
			<parent>hip</parent>
			<child>hip_right_link1</child>
			<pose frame="">-0.07678906163666874 0.12466093433506573 3.552713678800501e-15 0 0 0</pose>
			<axis>
				<xyz>0.9999999999999997 4.250072516143169e-16 -2.234323837058116e-15</xyz>
				<limit>
					<lower>-3.141592653589793</lower>
					<upper>3.141592653589793</upper>
				</limit>
				<use_parent_model_frame>0</use_parent_model_frame>
			</axis>
		</joint>
		<joint name="hip_right_axis2" type="revolute">
			<parent>hip_right_link2</parent>
			<child>upper_leg_right</child>
			<pose frame="">-0.08362814538009128 0.13009482233210487 0.1530905696518275 0 0 0</pose>
			<axis>
				<xyz>-2.9170238954268427e-17 1.376760001370904e-14 -0.9999999999999999</xyz>
				<limit>
					<lower>-3.141592653589793</lower>
					<upper>3.141592653589793</upper>
				</limit>
				<use_parent_model_frame>0</use_parent_model_frame>
			</axis>
		</joint>
		<joint name="hip_right_axis1" type="revolute">
			<parent>hip_right_link1</parent>
			<child>hip_right_link2</child>
			<pose frame="">-0.07678906165498744 0.12466093431673639 -1.4210854715202005e-15 0 0 0</pose>
			<axis>
				<xyz>-2.5847379792051305e-16 0.9999999999999999 1.3739844438093417e-14</xyz>
				<limit>
					<lower>-3.141592653589793</lower>
					<upper>3.141592653589793</upper>
				</limit>
				<use_parent_model_frame>0</use_parent_model_frame>
			</axis>
		</joint>
		<joint name="spine_axis0" type="revolute">
			<parent>hip</parent>
			<child>spine_link1</child>
			<pose frame="">0.015469609506906344 0.02293375406860519 3.694822225952521e-15 0 0 0</pose>
			<axis>
				<xyz>1.000000000000005 6.73689136906368e-16 -2.1197893720368177e-15</xyz>
				<limit>
					<lower>-3.141592653589793</lower>
					<upper>3.141592653589793</upper>
				</limit>
				<use_parent_model_frame>0</use_parent_model_frame>
			</axis>
		</joint>
		<joint name="spine_axis2" type="revolute">
			<parent>spine_link2</parent>
			<child>chest</child>
			<pose frame="">0.020286362369624868 0.02264990662126358 -0.3148058462009567 0 0 0</pose>
			<axis>
				<xyz>2.1688924369416758e-16 1.391195659261643e-14 -0.9999999999999994</xyz>
				<limit>
					<lower>-3.141592653589793</lower>
					<upper>3.141592653589793</upper>
				</limit>
				<use_parent_model_frame>0</use_parent_model_frame>
			</axis>
		</joint>
		<joint name="spine_axis1" type="revolute">
			<parent>spine_link1</parent>
			<child>spine_link2</child>
			<pose frame="">0.015469609488587641 0.02293375405027774 -1.4210854715202005e-15 0 0 0</pose>
			<axis>
				<xyz>7.400103343713659e-18 1.0000000000000024 1.3884201017000807e-14</xyz>
				<limit>
					<lower>-3.141592653589793</lower>
					<upper>3.141592653589793</upper>
				</limit>
				<use_parent_model_frame>0</use_parent_model_frame>
			</axis>
		</joint>
		<joint name="shoulder_right_axis0" type="revolute">
			<parent>chest</parent>
			<child>shoulder_right_link1</child>
			<pose frame="">-0.10401359538438926 0.24332679130147522 3.694822225952521e-15 0 0 0</pose>
			<axis>
				<xyz>-2.4821811273056937e-13 -1.3346308960332139e-14 1.0000000000000049</xyz>
				<limit>
					<lower>-3.141592653589793</lower>
					<upper>3.141592653589793</upper>
				</limit>
				<use_parent_model_frame>0</use_parent_model_frame>
			</axis>
		</joint>
		<joint name="shoulder_right_axis2" type="revolute">
			<parent>shoulder_right_link2</parent>
			<child>upper_arm_right</child>
			<pose frame="">-0.07890574889329571 0.27437048302612693 0.22543858983205653 0 0 0</pose>
			<axis>
				<xyz>1.0 1.0267234056411354e-16 2.5071611453597593e-13</xyz>
				<limit>
					<lower>-3.141592653589793</lower>
					<upper>3.141592653589793</upper>
				</limit>
				<use_parent_model_frame>0</use_parent_model_frame>
			</axis>
		</joint>
		<joint name="shoulder_right_axis1" type="revolute">
			<parent>shoulder_right_link1</parent>
			<child>shoulder_right_link2</child>
			<pose frame="">-0.10401359540271048 0.2433267912831513 2.2737367544323206e-15 0 0 0</pose>
			<axis>
				<xyz>-8.544045600202932e-17 1.0000000000000024 1.4012442775107149e-14</xyz>
				<limit>
					<lower>-3.141592653589793</lower>
					<upper>3.141592653589793</upper>
				</limit>
				<use_parent_model_frame>0</use_parent_model_frame>
			</axis>
		</joint>
		<joint name="elbow_right_axis0" type="revolute">
			<parent>upper_arm_right</parent>
			<child>elbow_right_link1</child>
			<pose frame="">-0.11462630352403354 0.3069085299136428 3.4106051316484808e-15 0 0 0</pose>
			<axis>
				<xyz>-2.4821811273056937e-13 -1.333937006642791e-14 1.0000000000000049</xyz>
				<limit>
					<lower>-3.141592653589793</lower>
					<upper>3.141592653589793</upper>
				</limit>
				<use_parent_model_frame>0</use_parent_model_frame>
			</axis>
		</joint>
		<joint name="elbow_right_axis2" type="revolute">
			<parent>elbow_right_link2</parent>
			<child>lower_arm_right</child>
			<pose frame="">-0.12582610067803918 0.34586123489256326 0.22972449657902316 0 0 0</pose>
			<axis>
				<xyz>0.9999999999999986 8.879455281983322e-17 2.507161145359759e-13</xyz>
				<limit>
					<lower>-3.141592653589793</lower>
					<upper>3.141592653589793</upper>
				</limit>
				<use_parent_model_frame>0</use_parent_model_frame>
			</axis>
		</joint>
		<joint name="elbow_right_axis1" type="revolute">
			<parent>elbow_right_link1</parent>
			<child>elbow_right_link2</child>
			<pose frame="">-0.11462630354235528 0.3069085298953186 3.126388037344441e-15 0 0 0</pose>
			<axis>
				<xyz>-7.156266817764898e-17 1.0000000000000002 1.4033259456818555e-14</xyz>
				<limit>
					<lower>-3.141592653589793</lower>
					<upper>3.141592653589793</upper>
				</limit>
				<use_parent_model_frame>0</use_parent_model_frame>
			</axis>
		</joint>
		<joint name="wrist_right_axis0" type="revolute">
			<parent>lower_arm_right</parent>
			<child>wrist_right_link1</child>
			<pose frame="">-0.17309602709657046 0.33671703630353 6.536993168992922e-15 0 0 0</pose>
			<axis>
				<xyz>-2.4821811273056897e-13 -1.3353247854235726e-14 1.0000000000000049</xyz>
				<limit>
					<lower>-3.141592653589793</lower>
					<upper>3.141592653589793</upper>
				</limit>
				<use_parent_model_frame>0</use_parent_model_frame>
			</axis>
		</joint>
		<joint name="wrist_right_axis2" type="revolute">
			<parent>wrist_right_link2</parent>
			<child>hand_right</child>
			<pose frame="">-0.17398963046836557 0.32649994388177606 -2.2709543671339815e-07 0 0 0</pose>
			<axis>
				<xyz>0.9999999999999986 3.3283401589028054e-17 2.50716114535976e-13</xyz>
				<limit>
					<lower>-3.141592653589793</lower>
					<upper>3.141592653589793</upper>
				</limit>
				<use_parent_model_frame>0</use_parent_model_frame>
			</axis>
		</joint>
		<joint name="wrist_right_axis1" type="revolute">
			<parent>wrist_right_link1</parent>
			<child>wrist_right_link2</child>
			<pose frame="">-0.17309602711489283 0.3367170362852059 7.105427357601002e-16 0 0 0</pose>
			<axis>
				<xyz>-1.605151694600947e-17 1.0000000000000002 1.4074892820242e-14</xyz>
				<limit>
					<lower>-3.141592653589793</lower>
					<upper>3.141592653589793</upper>
				</limit>
				<use_parent_model_frame>0</use_parent_model_frame>
			</axis>
		</joint>
		<joint name="shoulder_left_axis0" type="revolute">
			<parent>chest</parent>
			<child>shoulder_left_link1</child>
			<pose frame="">0.22968410019759514 -0.12084034067436349 -3.126388037344441e-15 0 0 0</pose>
			<axis>
				<xyz>-2.530475828876892e-13 1.3512842414025933e-14 -1.0000000000000049</xyz>
				<limit>
					<lower>-3.141592653589793</lower>
					<upper>3.141592653589793</upper>
				</limit>
				<use_parent_model_frame>0</use_parent_model_frame>
			</axis>
		</joint>
		<joint name="shoulder_left_axis2" type="revolute">
			<parent>shoulder_left_link2</parent>
			<child>upper_arm_left</child>
			<pose frame="">0.2487755329126429 -0.15810673685964935 0.2254386011811333 0 0 0</pose>
			<axis>
				<xyz>1.0 -1.0267234056411258e-16 -2.5071611453597593e-13</xyz>
				<limit>
					<lower>-3.141592653589793</lower>
					<upper>3.141592653589793</upper>
				</limit>
				<use_parent_model_frame>0</use_parent_model_frame>
			</axis>
		</joint>
		<joint name="shoulder_left_axis1" type="revolute">
			<parent>shoulder_left_link1</parent>
			<child>shoulder_left_link2</child>
			<pose frame="">0.2296841001792643 -0.12084034069269206 -4.547473508864641e-15 0 0 0</pose>
			<axis>
				<xyz>-8.544045600203651e-17 -1.0000000000000024 -1.4012442775107327e-14</xyz>
				<limit>
					<lower>-3.141592653589793</lower>
					<upper>3.141592653589793</upper>
				</limit>
				<use_parent_model_frame>0</use_parent_model_frame>
			</axis>
		</joint>
		<joint name="foot_left_axis0" type="revolute">
			<parent>lower_leg_left</parent>
			<child>foot_left_link1</child>
			<pose frame="">0.1300375622619316 -0.10191109690325295 1.7763568394002505e-17 0 0 0</pose>
			<axis>
				<xyz>1.0 6.242653171537101e-29 -6.123233995736757e-17</xyz>
				<limit>
					<lower>-3.141592653589793</lower>
					<upper>3.141592653589793</upper>
				</limit>
				<use_parent_model_frame>0</use_parent_model_frame>
			</axis>
		</joint>
		<joint name="foot_left_axis2" type="revolute">
			<parent>foot_left_link2</parent>
			<child>foot_left</child>
			<pose frame="">0.13054685188182333 -0.09608970196044958 0.001530530735812139 0 0 0</pose>
			<axis>
				<xyz>-7.8886090522100445e-31 -1.3745948823640208e-14 0.9999999999999997</xyz>
				<limit>
					<lower>-3.141592653589793</lower>
					<upper>3.141592653589793</upper>
				</limit>
				<use_parent_model_frame>0</use_parent_model_frame>
			</axis>
		</joint>
		<joint name="foot_left_axis1" type="revolute">
			<parent>foot_left_link1</parent>
			<child>foot_left_link2</child>
			<pose frame="">0.13003756224359722 -0.10191109692157894 -3.019806626980426e-16 0 0 0</pose>
			<axis>
				<xyz>3.1707178730417e-29 -0.9999999999999997 -1.371819324802458e-14</xyz>
				<limit>
					<lower>-3.141592653589793</lower>
					<upper>3.141592653589793</upper>
				</limit>
				<use_parent_model_frame>0</use_parent_model_frame>
			</axis>
		</joint>
		<joint name="hip_left_axis0" type="revolute">
			<parent>hip</parent>
			<child>upper_leg_left</child>
			<pose frame="">0.10669391140122494 -0.08135355625131141 0.15323435428057294 0 0 0</pose>
			<axis>
				<xyz>0.9999999999999997 -4.250072516143159e-16 2.234323837058117e-15</xyz>
				<limit>
					<lower>-3.141592653589793</lower>
					<upper>3.141592653589793</upper>
				</limit>
				<use_parent_model_frame>0</use_parent_model_frame>
			</axis>
		</joint>
		<joint name="hip_leftt_axis2" type="revolute">
			<parent>hip_left_link2</parent>
			<child>upper_leg_left</child>
			<pose frame="">0.10669391140122507 -0.08135355625131141 0.15323435428057253 0 0 0</pose>
			<axis>
				<xyz>2.185554621569935e-15 1.3809233377132487e-14 -0.9999999999999999</xyz>
				<limit>
					<lower>-3.141592653589793</lower>
					<upper>3.141592653589793</upper>
				</limit>
				<use_parent_model_frame>0</use_parent_model_frame>
			</axis>
		</joint>
		<joint name="hip_left_axis1" type="revolute">
			<parent>hip_left_link1</parent>
			<child>hip_left_link2</child>
			<pose frame="">0.11384257708454854 -0.08337699361250066 0.0 0 0 0</pose>
			<axis>
				<xyz>5.91540705308149e-16 0.9999999999999999 1.3739844438093416e-14</xyz>
				<limit>
					<lower>-3.141592653589793</lower>
					<upper>3.141592653589793</upper>
				</limit>
				<use_parent_model_frame>0</use_parent_model_frame>
			</axis>
		</joint>
		<joint name="neck_axis0" type="revolute">
			<parent>chest</parent>
			<child>neck_link1</child>
			<pose frame="">0.025431556487813877 0.03206219664112121 3.126388037344441e-15 0 0 0</pose>
			<axis>
				<xyz>1.0000000000000049 6.736891369068284e-16 -2.1197893720368355e-15</xyz>
				<limit>
					<lower>-3.141592653589793</lower>
					<upper>3.141592653589793</upper>
				</limit>
				<use_parent_model_frame>0</use_parent_model_frame>
			</axis>
		</joint>
		<joint name="neck_axis2" type="revolute">
			<parent>neck_link2</parent>
			<child>head</child>
			<pose frame="">0.012302112173752931 0.03356052431086265 -0.0442096587379487 0 0 0</pose>
			<axis>
				<xyz>2.1688924369418631e-16 -1.0103029524088923e-14 -0.9999999999999996</xyz>
				<limit>
					<lower>-3.141592653589793</lower>
					<upper>3.141592653589793</upper>
				</limit>
				<use_parent_model_frame>0</use_parent_model_frame>
			</axis>
		</joint>
		<joint name="neck_axis1" type="revolute">
			<parent>neck_link1</parent>
			<child>neck_link2</child>
			<pose frame="">0.02543155646949562 0.03206219662279378 5.684341886080802e-16 0 0 0</pose>
			<axis>
				<xyz>7.400103344332076e-18 1.000000000000002 -1.0214051826551439e-14</xyz>
				<limit>
					<lower>-3.141592653589793</lower>
					<upper>3.141592653589793</upper>
				</limit>
				<use_parent_model_frame>0</use_parent_model_frame>
			</axis>
		</joint>
		<plugin filename="libcardsflow_gazebo_plugin.so" name="cardsflow_gazebo_plugin"/>
	</model>
</sdf>
