<?xml version="1.0" ?>
<sdf version="1.6">
	<model name="VRpuppet">
		<link name="base">
			<self_collide>false</self_collide>
			<pose frame="">0.0001901919426824477 0.5169540680491131 0.3596164678395443 0.0 -0.0 0.0</pose>
			<inertial>
				<pose frame="">0.0 0.0 0.0 0 0 0</pose>
				<mass>14.69473796695913</mass>
				<inertia>
					<ixx>10.684689333678833</ixx>
					<ixy>-0.0005083987852701654</ixy>
					<ixz>-0.0027654760315275894</ixz>
					<iyy>6.756408948551988</iyy>
					<iyz>-2.7324379280551483</iyz>
					<izz>7.9937684672241085</izz>
				</inertia>
			</inertial>
			<collision name="base_collision">
				<geometry>
					<mesh>
						<uri>model://VRpuppet/meshes/CAD/base.stl</uri>
						<scale>0.001 0.001 0.001</scale>
					</mesh>
				</geometry>
			</collision>
			<visual name="base_visual">
				<geometry>
					<mesh>
						<uri>model://VRpuppet/meshes/CAD/base.stl</uri>
						<scale>0.001 0.001 0.001</scale>
					</mesh>
				</geometry>
			</visual>
		</link>
		<link name="motor0">
			<self_collide>false</self_collide>
			<pose frame="">-0.015845447389059037 -0.002960060762676503 0.1070911341135532 0.0 -0.0 0.0</pose>
			<inertial>
				<pose frame="">0.0 0.0 0.0 0 0 0</pose>
				<mass>0.43629459845139135</mass>
				<inertia>
					<ixx>0.005704479485529596</ixx>
					<ixy>-5.39600982427005e-05</ixy>
					<ixz>0.0007647920148924098</ixz>
					<iyy>0.005867057501025582</iyy>
					<iyz>0.0001712835467593431</iyz>
					<izz>0.0005066875563435714</izz>
				</inertia>
			</inertial>
			<collision name="motor0_collision">
				<geometry>
					<mesh>
						<uri>model://VRpuppet/meshes/CAD/motor0.stl</uri>
						<scale>0.001 0.001 0.001</scale>
					</mesh>
				</geometry>
			</collision>
			<visual name="motor0_visual">
				<geometry>
					<mesh>
						<uri>model://VRpuppet/meshes/CAD/motor0.stl</uri>
						<scale>0.001 0.001 0.001</scale>
					</mesh>
				</geometry>
			</visual>
		</link>
		<link name="motor1">
			<self_collide>false</self_collide>
			<pose frame="">0.4422526020721498 0.24325954839310232 0.10691969518804309 0.0 -0.0 0.0</pose>
			<inertial>
				<pose frame="">0.0 0.0 0.0 0 0 0</pose>
				<mass>0.4363809929153096</mass>
				<inertia>
					<ixx>0.031580994814732866</ixx>
					<ixy>-0.0469546695916107</ixy>
					<ixz>-0.020650879709634893</ixz>
					<iyy>0.09102230859297562</iyy>
					<iyz>-0.011311485518812408</iyz>
					<izz>0.11156588382429838</izz>
				</inertia>
			</inertial>
			<collision name="motor1_collision">
				<geometry>
					<mesh>
						<uri>model://VRpuppet/meshes/CAD/motor1.stl</uri>
						<scale>0.001 0.001 0.001</scale>
					</mesh>
				</geometry>
			</collision>
			<visual name="motor1_visual">
				<geometry>
					<mesh>
						<uri>model://VRpuppet/meshes/CAD/motor1.stl</uri>
						<scale>0.001 0.001 0.001</scale>
					</mesh>
				</geometry>
			</visual>
		</link>
		<link name="motor2">
			<self_collide>false</self_collide>
			<pose frame="">0.45809694305981424 0.7630758369911415 0.10691980681415961 0.0 -0.0 0.0</pose>
			<inertial>
				<pose frame="">0.0 0.0 0.0 0 0 0</pose>
				<mass>0.43637989704911995</mass>
				<inertia>
					<ixx>0.2597974619033026</ixx>
					<ixy>-0.15250081840963697</ixy>
					<ixz>-0.0214152137391521</ixz>
					<iyy>0.09730520981059797</iyy>
					<iyz>-0.03559828955432776</iyz>
					<izz>0.3460652352058029</izz>
				</inertia>
			</inertial>
			<collision name="motor2_collision">
				<geometry>
					<mesh>
						<uri>model://VRpuppet/meshes/CAD/motor2.stl</uri>
						<scale>0.001 0.001 0.001</scale>
					</mesh>
				</geometry>
			</collision>
			<visual name="motor2_visual">
				<geometry>
					<mesh>
						<uri>model://VRpuppet/meshes/CAD/motor2.stl</uri>
						<scale>0.001 0.001 0.001</scale>
					</mesh>
				</geometry>
			</visual>
		</link>
		<link name="motor3">
			<self_collide>false</self_collide>
			<pose frame="">0.015845676319101058 1.0367364034033846 0.10709166412197565 0.0 -0.0 0.0</pose>
			<inertial>
				<pose frame="">0.0 0.0 0.0 0 0 0</pose>
				<mass>0.43628953344146976</mass>
				<inertia>
					<ixx>0.47463438076278264</ixx>
					<ixy>-0.007200764698140614</ixy>
					<ixz>-0.000764802695559814</ixz>
					<iyy>0.005867029647524154</iyy>
					<iyz>-0.048472385233820164</iyz>
					<izz>0.46943660945962284</izz>
				</inertia>
			</inertial>
			<collision name="motor3_collision">
				<geometry>
					<mesh>
						<uri>model://VRpuppet/meshes/CAD/motor3.stl</uri>
						<scale>0.001 0.001 0.001</scale>
					</mesh>
				</geometry>
			</collision>
			<visual name="motor3_visual">
				<geometry>
					<mesh>
						<uri>model://VRpuppet/meshes/CAD/motor3.stl</uri>
						<scale>0.001 0.001 0.001</scale>
					</mesh>
				</geometry>
			</visual>
		</link>
		<link name="motor4">
			<self_collide>false</self_collide>
			<pose frame="">-0.44225424449694933 0.7905171502081413 0.10692005111233298 0.0 -0.0 0.0</pose>
			<inertial>
				<pose frame="">0.0 0.0 0.0 0 0 0</pose>
				<mass>0.43633130265901054</mass>
				<inertia>
					<ixx>0.2784284732072221</ixx>
					<ixy>0.15253772988110678</ixy>
					<ixz>0.020648671430114215</ixz>
					<iyy>0.09101265308110286</iyy>
					<iyz>-0.03691809321595001</iyz>
					<izz>0.35840480753636467</izz>
				</inertia>
			</inertial>
			<collision name="motor4_collision">
				<geometry>
					<mesh>
						<uri>model://VRpuppet/meshes/CAD/motor4.stl</uri>
						<scale>0.001 0.001 0.001</scale>
					</mesh>
				</geometry>
			</collision>
			<visual name="motor4_visual">
				<geometry>
					<mesh>
						<uri>model://VRpuppet/meshes/CAD/motor4.stl</uri>
						<scale>0.001 0.001 0.001</scale>
					</mesh>
				</geometry>
			</visual>
		</link>
		<link name="motor5">
			<self_collide>false</self_collide>
			<pose frame="">-0.45809600274610035 0.27070016510579153 0.10691944897857551 0.0 -0.0 0.0</pose>
			<inertial>
				<pose frame="">0.0 0.0 0.0 0 0 0</pose>
				<mass>0.4363690901435038</mass>
				<inertia>
					<ixx>0.0376764492785796</ixx>
					<ixy>0.054153996184430724</ixy>
					<ixz>0.021414565216775008</ixz>
					<iyy>0.09730239860386165</iyy>
					<iyz>-0.012634919165036302</iyz>
					<izz>0.1239417279563606</izz>
				</inertia>
			</inertial>
			<collision name="motor5_collision">
				<geometry>
					<mesh>
						<uri>model://VRpuppet/meshes/CAD/motor5.stl</uri>
						<scale>0.001 0.001 0.001</scale>
					</mesh>
				</geometry>
			</collision>
			<visual name="motor5_visual">
				<geometry>
					<mesh>
						<uri>model://VRpuppet/meshes/CAD/motor5.stl</uri>
						<scale>0.001 0.001 0.001</scale>
					</mesh>
				</geometry>
			</visual>
		</link>
		<link name="box">
			<self_collide>false</self_collide>
			<pose frame="">3.6987060335515945e-05 0.5001199924802076 0.08822286690177963 0.0 -0.0 0.0</pose>
			<inertial>
				<pose frame="">0.0 0.0 0.0 0 0 0</pose>
				<mass>1.9759674075483924</mass>
				<inertia>
					<ixx>0.5140518745430102</ixx>
					<ixy>-3.3351428118892794e-05</ixy>
					<ixz>-9.755909896797407e-06</ixz>
					<iyy>0.019824299044768273</iyy>
					<iyz>-0.08719715331855628</iyz>
					<izz>0.49794885650845067</izz>
				</inertia>
			</inertial>
			<collision name="box_collision">
				<geometry>
					<mesh>
						<uri>model://VRpuppet/meshes/CAD/box.stl</uri>
						<scale>0.001 0.001 0.001</scale>
					</mesh>
				</geometry>
			</collision>
			<visual name="box_visual">
				<geometry>
					<mesh>
						<uri>model://VRpuppet/meshes/CAD/box.stl</uri>
						<scale>0.001 0.001 0.001</scale>
					</mesh>
				</geometry>
			</visual>
		</link>
		<joint name="motor0" type="prismatic">
			<parent>base</parent>
			<child>motor0</child>
			<pose frame="">0.015845447389059037 0.007460060762676544 -0.10705828552701745 0 0 0</pose>
			<axis>
				<xyz>-1.7516230804060213e-46 0.0 -1.0</xyz>
				<limit>
					<lower>-0.79</lower>
					<upper>0.0</upper>
				</limit>
				<use_parent_model_frame>0</use_parent_model_frame>
			</axis>
		</joint>
		<joint name="motor2" type="prismatic">
			<parent>base</parent>
			<child>motor2</child>
			<pose frame="">-0.014355765466881821 0.01000642801025549 -0.10688695822762215 0 0 0</pose>
			<axis>
				<xyz>-4.564032648851929e-15 6.759967440614182e-16 -1.0</xyz>
				<limit>
					<lower>-0.79</lower>
					<upper>0.0</upper>
				</limit>
				<use_parent_model_frame>0</use_parent_model_frame>
			</axis>
		</joint>
		<joint name="motor1" type="prismatic">
			<parent>base</parent>
			<child>motor1</child>
			<pose frame="">0.0014885755207797047 0.01743453994069629 -0.10688684660150653 0 0 0</pose>
			<axis>
				<xyz>-5.071147387613207e-16 1.4842458363327e-15 -1.0</xyz>
				<limit>
					<lower>-0.79</lower>
					<upper>0.0</upper>
				</limit>
				<use_parent_model_frame>0</use_parent_model_frame>
			</axis>
		</joint>
		<joint name="motor3" type="prismatic">
			<parent>base</parent>
			<child>motor3</child>
			<pose frame="">-0.015845676319095798 -0.007460050068185211 -0.10705881553544287 0 0 0</pose>
			<axis>
				<xyz>7.713980309253913e-16 -4.998218758884115e-15 -1.0</xyz>
				<limit>
					<lower>-0.79</lower>
					<upper>0.0</upper>
				</limit>
				<use_parent_model_frame>0</use_parent_model_frame>
			</axis>
		</joint>
		<joint name="motor5" type="prismatic">
			<parent>base</parent>
			<child>motor5</child>
			<pose frame="">0.014354825153172825 -0.01000607677198886 -0.10688660039203769 0 0 0</pose>
			<axis>
				<xyz>6.035394926270176e-16 1.9852835547407376e-15 -1.0</xyz>
				<limit>
					<lower>-0.79</lower>
					<upper>0.0</upper>
				</limit>
				<use_parent_model_frame>0</use_parent_model_frame>
			</axis>
		</joint>
		<joint name="motor4" type="prismatic">
			<parent>base</parent>
			<child>motor4</child>
			<pose frame="">-0.0014869330959756866 -0.017434885206740632 -0.10688720252579445 0 0 0</pose>
			<axis>
				<xyz>5.431855433643031e-15 1.5110596080747193e-15 -1.0</xyz>
				<limit>
					<lower>-0.79</lower>
					<upper>0.0</upper>
				</limit>
				<use_parent_model_frame>0</use_parent_model_frame>
			</axis>
		</joint>
		<plugin filename="libcardsflow_gazebo_plugin.so" name="cardsflow_gazebo_plugin"/>
	</model>
</sdf>
