<?xml version="1.0" ?>
<sdf version="1.6">
	<model name="VRpuppet">
		<link name="base">
			<self_collide>false</self_collide>
			<pose frame="">0.0 -1.4210854715202004e-16 0.05 0.0 -0.0 0.0</pose>
			<inertial>
				<pose frame="">0.0 0.0 0.0 0 0 0</pose>
				<mass>14.80571472744744</mass>
				<inertia>
					<ixx>6.761884261169531</ixx>
					<ixy>0.000888098241208643</ixy>
					<ixz>-0.0027842413122673953</ixz>
					<iyy>6.756418956494972</iyy>
					<iyz>-0.09025625769730981</iyz>
					<izz>4.070963414748864</izz>
				</inertia>
			</inertial>
			<collision name="base_collision">
				<geometry>
					<mesh>
						<uri>model://VRpuppet/meshes/CAD/base.stl</uri>
						<scale>0.001 0.001 0.001</scale>
					</mesh>
				</geometry>
			</collision>
			<visual name="base_visual">
				<geometry>
					<mesh>
						<uri>model://VRpuppet/meshes/CAD/base.stl</uri>
						<scale>0.001 0.001 0.001</scale>
					</mesh>
				</geometry>
			</visual>
		</link>
		<link name="box">
			<self_collide>false</self_collide>
			<pose frame="">0.0 -1.4210854715202004e-16 0.07400000000000001 0.0 -0.0 0.0</pose>
			<inertial>
				<pose frame="">0.0 0.0 0.0 0 0 0</pose>
				<mass>1.3308344620114287</mass>
				<inertia>
					<ixx>0.010171271450187725</ixx>
					<ixy>-3.145103290783754e-06</ixy>
					<ixz>-1.7207873115611552e-05</ixz>
					<iyy>0.010170584384841317</iyy>
					<iyz>2.130755890777051e-05</iyz>
					<izz>0.0020634373012541917</izz>
				</inertia>
			</inertial>
			<collision name="box_collision">
				<geometry>
					<mesh>
						<uri>model://VRpuppet/meshes/CAD/box.stl</uri>
						<scale>0.001 0.001 0.001</scale>
					</mesh>
				</geometry>
			</collision>
			<visual name="box_visual">
				<geometry>
					<mesh>
						<uri>model://VRpuppet/meshes/CAD/box.stl</uri>
						<scale>0.001 0.001 0.001</scale>
					</mesh>
				</geometry>
			</visual>
		</link>
		<link name="6dof_link4">
			<self_collide>false</self_collide>
			<pose frame="">0.04264321097415029 -6.0943105862397715e-05 3.703040005024979e-18 0.0 -0.0 0.0</pose>
			<inertial>
				<pose frame="">0.0 0.0 0.0 0 0 0</pose>
				<mass>0.029253556048299476</mass>
				<inertia>
					<ixx>4.2090251723419015e-07</ixx>
					<ixy>1.0370831206417925e-07</ixy>
					<ixz>-5.798374481226597e-21</ixz>
					<iyy>6.386641397225651e-05</iyy>
					<iyz>1.1075531602667452e-11</iyz>
					<izz>6.386578535831043e-05</izz>
				</inertia>
			</inertial>
			<collision name="6dof_link4_collision">
				<geometry>
					<mesh>
						<uri>model://VRpuppet/meshes/CAD/6dof_link4.stl</uri>
						<scale>0.001 0.001 0.001</scale>
					</mesh>
				</geometry>
			</collision>
			<visual name="6dof_link4_visual">
				<geometry>
					<mesh>
						<uri>model://VRpuppet/meshes/CAD/6dof_link4.stl</uri>
						<scale>0.001 0.001 0.001</scale>
					</mesh>
				</geometry>
			</visual>
		</link>
		<link name="6dof_link5">
			<self_collide>false</self_collide>
			<pose frame="">6.455931229707808e-05 0.04261989748204808 -1.8770577057560806e-08 0.0 -0.0 0.0</pose>
			<inertial>
				<pose frame="">0.0 0.0 0.0 0 0 0</pose>
				<mass>0.029267161202751038</mass>
				<inertia>
					<ixx>6.385311836563872e-05</ixx>
					<ixy>-1.0820097121352837e-07</ixy>
					<ixz>3.647628896237974e-12</ixz>
					<iyy>4.208289556490234e-07</iyy>
					<iyz>1.314568252966794e-10</iyz>
					<izz>6.385353905648622e-05</izz>
				</inertia>
			</inertial>
			<collision name="6dof_link5_collision">
				<geometry>
					<mesh>
						<uri>model://VRpuppet/meshes/CAD/6dof_link5.stl</uri>
						<scale>0.001 0.001 0.001</scale>
					</mesh>
				</geometry>
			</collision>
			<visual name="6dof_link5_visual">
				<geometry>
					<mesh>
						<uri>model://VRpuppet/meshes/CAD/6dof_link5.stl</uri>
						<scale>0.001 0.001 0.001</scale>
					</mesh>
				</geometry>
			</visual>
		</link>
		<link name="6dof_link1">
			<self_collide>false</self_collide>
			<pose frame="">0.0 0.0 0.0 0.0 -0.0 0.0</pose>
			<inertial>
				<pose frame="">0.0 0.0 0.0 0 0 0</pose>
				<mass>0.03806502884740436</mass>
				<inertia>
					<ixx>1.6786677721705307e-06</ixx>
					<ixy>2.168404344971009e-22</ixy>
					<ixz>-8.348356728138384e-22</ixz>
					<iyy>1.6786677721705311e-06</iyy>
					<iyz>-1.8431436932253577e-22</iyz>
					<izz>1.6786677721705307e-06</izz>
				</inertia>
			</inertial>
			<collision name="6dof_link1_collision">
				<geometry>
					<mesh>
						<uri>model://VRpuppet/meshes/CAD/6dof_link1.stl</uri>
						<scale>0.001 0.001 0.001</scale>
					</mesh>
				</geometry>
			</collision>
			<visual name="6dof_link1_visual">
				<geometry>
					<mesh>
						<uri>model://VRpuppet/meshes/CAD/6dof_link1.stl</uri>
						<scale>0.001 0.001 0.001</scale>
					</mesh>
				</geometry>
			</visual>
		</link>
		<link name="6dof_link2">
			<self_collide>false</self_collide>
			<pose frame="">0.0 0.0 0.0 0.0 -0.0 0.0</pose>
			<inertial>
				<pose frame="">0.0 0.0 0.0 0 0 0</pose>
				<mass>0.0029963725331776064</mass>
				<inertia>
					<ixx>2.42706175187388e-08</ixx>
					<ixy>8.851426536171658e-24</ixy>
					<ixz>-9.532305500492555e-24</ixz>
					<iyy>2.4270617518738303e-08</iyy>
					<iyz>-1.3552527156068806e-24</iyz>
					<izz>2.4270617518738147e-08</izz>
				</inertia>
			</inertial>
			<collision name="6dof_link2_collision">
				<geometry>
					<mesh>
						<uri>model://VRpuppet/meshes/CAD/6dof_link2.stl</uri>
						<scale>0.001 0.001 0.001</scale>
					</mesh>
				</geometry>
			</collision>
			<visual name="6dof_link2_visual">
				<geometry>
					<mesh>
						<uri>model://VRpuppet/meshes/CAD/6dof_link2.stl</uri>
						<scale>0.001 0.001 0.001</scale>
					</mesh>
				</geometry>
			</visual>
		</link>
		<link name="6dof_link3">
			<self_collide>false</self_collide>
			<pose frame="">2.3792895949006e-07 -2.890294149946432e-07 0.010729363507488397 0.0 -0.0 0.0</pose>
			<inertial>
				<pose frame="">0.0 0.0 0.0 0 0 0</pose>
				<mass>0.015709236754408062</mass>
				<inertia>
					<ixx>2.4494864177993604e-06</ixx>
					<ixy>3.9391391199366906e-12</ixy>
					<ixz>-7.480906938650857e-11</ixz>
					<iyy>2.4420629329931183e-06</iyy>
					<iyz>9.08467159514214e-11</iyz>
					<izz>2.606872971819379e-07</izz>
				</inertia>
			</inertial>
			<collision name="6dof_link3_collision">
				<geometry>
					<mesh>
						<uri>model://VRpuppet/meshes/CAD/6dof_link3.stl</uri>
						<scale>0.001 0.001 0.001</scale>
					</mesh>
				</geometry>
			</collision>
			<visual name="6dof_link3_visual">
				<geometry>
					<mesh>
						<uri>model://VRpuppet/meshes/CAD/6dof_link3.stl</uri>
						<scale>0.001 0.001 0.001</scale>
					</mesh>
				</geometry>
			</visual>
		</link>
		<link name="motor0">
			<self_collide>false</self_collide>
			<pose frame="">0.017867185993299676 -0.5047579009053257 0.10048473111942212 0.0 -0.0 0.0</pose>
			<inertial>
				<pose frame="">0.0 0.0 0.0 0 0 0</pose>
				<mass>0.3861179640455582</mass>
				<inertia>
					<ixx>0.10283601280606824</ixx>
					<ixy>0.0035221286505488637</ixy>
					<ixz>-0.0006600623768263094</ixz>
					<iyy>0.004633506332965584</iyy>
					<iyz>0.019545092464183293</iyz>
					<izz>0.09887428432986992</izz>
				</inertia>
			</inertial>
			<collision name="motor0_collision">
				<geometry>
					<mesh>
						<uri>model://VRpuppet/meshes/CAD/motor0.stl</uri>
						<scale>0.001 0.001 0.001</scale>
					</mesh>
				</geometry>
			</collision>
			<visual name="motor0_visual">
				<geometry>
					<mesh>
						<uri>model://VRpuppet/meshes/CAD/motor0.stl</uri>
						<scale>0.001 0.001 0.001</scale>
					</mesh>
				</geometry>
			</visual>
		</link>
		<link name="motor5">
			<self_collide>false</self_collide>
			<pose frame="">0.46070189988510457 -0.22845995840138034 0.10048519910305999 0.0 -0.0 0.0</pose>
			<inertial>
				<pose frame="">0.0 0.0 0.0 0 0 0</pose>
				<mass>0.3861018099744338</mass>
				<inertia>
					<ixx>0.024615357686220217</ixx>
					<ixy>0.04059655686840908</ixy>
					<ixz>-0.017823744854122272</ixz>
					<iyy>0.08645612152786952</iyy>
					<iyz>0.008872906276319445</iyz>
					<izz>0.10247649771273773</izz>
				</inertia>
			</inertial>
			<collision name="motor5_collision">
				<geometry>
					<mesh>
						<uri>model://VRpuppet/meshes/CAD/motor5.stl</uri>
						<scale>0.001 0.001 0.001</scale>
					</mesh>
				</geometry>
			</collision>
			<visual name="motor5_visual">
				<geometry>
					<mesh>
						<uri>model://VRpuppet/meshes/CAD/motor5.stl</uri>
						<scale>0.001 0.001 0.001</scale>
					</mesh>
				</geometry>
			</visual>
		</link>
		<link name="motor3">
			<self_collide>false</self_collide>
			<pose frame="">-0.017859087354013307 0.5385543344564675 0.10048496686668007 0.0 -0.0 0.0</pose>
			<inertial>
				<pose frame="">0.0 0.0 0.0 0 0 0</pose>
				<mass>0.3861130863842234</mass>
				<inertia>
					<ixx>0.11644918027576831</ixx>
					<ixy>0.0037535577155235218</ixy>
					<ixz>0.000659741079604325</ixz>
					<iyy>0.0046333649195279426</iyy>
					<iyz>-0.020856141465504473</iyz>
					<izz>0.11248736334729866</izz>
				</inertia>
			</inertial>
			<collision name="motor3_collision">
				<geometry>
					<mesh>
						<uri>model://VRpuppet/meshes/CAD/motor3.stl</uri>
						<scale>0.001 0.001 0.001</scale>
					</mesh>
				</geometry>
			</collision>
			<visual name="motor3_visual">
				<geometry>
					<mesh>
						<uri>model://VRpuppet/meshes/CAD/motor3.stl</uri>
						<scale>0.001 0.001 0.001</scale>
					</mesh>
				</geometry>
			</visual>
		</link>
		<link name="motor4">
			<self_collide>false</self_collide>
			<pose frame="">0.4503397648188681 0.28020425806665056 0.1004854208925892 0.0 -0.0 0.0</pose>
			<inertial>
				<pose frame="">0.0 0.0 0.0 0 0 0</pose>
				<mass>0.38609130739244313</mass>
				<inertia>
					<ixx>0.03484589418974067</ixx>
					<ixy>-0.04871822466707692</ixy>
					<ixz>-0.017454445381922548</ixz>
					<iyy>0.08273989102575226</iyy>
					<iyz>-0.010822744829140727</iyz>
					<izz>0.10899098008430244</izz>
				</inertia>
			</inertial>
			<collision name="motor4_collision">
				<geometry>
					<mesh>
						<uri>model://VRpuppet/meshes/CAD/motor4.stl</uri>
						<scale>0.001 0.001 0.001</scale>
					</mesh>
				</geometry>
			</collision>
			<visual name="motor4_visual">
				<geometry>
					<mesh>
						<uri>model://VRpuppet/meshes/CAD/motor4.stl</uri>
						<scale>0.001 0.001 0.001</scale>
					</mesh>
				</geometry>
			</visual>
		</link>
		<link name="motor2">
			<self_collide>false</self_collide>
			<pose frame="">-0.46069524092578584 0.26225626271267843 0.10048481097338613 0.0 -0.0 0.0</pose>
			<inertial>
				<pose frame="">0.0 0.0 0.0 0 0 0</pose>
				<mass>0.3861171003201705</mass>
				<inertia>
					<ixx>0.031019809322734945</ixx>
					<ixy>0.04660934156557589</ixy>
					<ixz>0.01782412346236659</ixz>
					<iyy>0.0864571377395829</iyy>
					<iyz>-0.010184481448800851</iyz>
					<izz>0.10888171287068213</izz>
				</inertia>
			</inertial>
			<collision name="motor2_collision">
				<geometry>
					<mesh>
						<uri>model://VRpuppet/meshes/CAD/motor2.stl</uri>
						<scale>0.001 0.001 0.001</scale>
					</mesh>
				</geometry>
			</collision>
			<visual name="motor2_visual">
				<geometry>
					<mesh>
						<uri>model://VRpuppet/meshes/CAD/motor2.stl</uri>
						<scale>0.001 0.001 0.001</scale>
					</mesh>
				</geometry>
			</visual>
		</link>
		<link name="motor1">
			<self_collide>false</self_collide>
			<pose frame="">-0.4428314546483174 -0.2593988381751871 0.10048550165548134 0.0 -0.0 0.0</pose>
			<inertial>
				<pose frame="">0.0 0.0 0.0 0 0 0</pose>
				<mass>0.3861247581086072</mass>
				<inertia>
					<ixx>0.030514002216031216</ixx>
					<ixy>-0.044352619661393825</ixy>
					<ixz>0.01716464387377868</ixz>
					<iyy>0.08015761355565745</iyy>
					<iyz>0.010016437618935883</iyz>
					<izz>0.10207610634401384</izz>
				</inertia>
			</inertial>
			<collision name="motor1_collision">
				<geometry>
					<mesh>
						<uri>model://VRpuppet/meshes/CAD/motor1.stl</uri>
						<scale>0.001 0.001 0.001</scale>
					</mesh>
				</geometry>
			</collision>
			<visual name="motor1_visual">
				<geometry>
					<mesh>
						<uri>model://VRpuppet/meshes/CAD/motor1.stl</uri>
						<scale>0.001 0.001 0.001</scale>
					</mesh>
				</geometry>
			</visual>
		</link>
		<joint name="6dof_axis3" type="prismatic">
			<parent>6dof_link3</parent>
			<child>6dof_link4</child>
			<pose frame="">-0.04264321097415029 6.0943105862397715e-05 -3.703040005024979e-18 0 0 0</pose>
			<axis>
				<xyz>-1.0 0.0 0.0</xyz>
				<limit>
					<lower>-1.0</lower>
					<upper>1.0</upper>
				</limit>
				<use_parent_model_frame>0</use_parent_model_frame>
			</axis>
		</joint>
		<joint name="6dof_axis4" type="prismatic">
			<parent>6dof_link4</parent>
			<child>6dof_link5</child>
			<pose frame="">-6.100828795643542e-05 -0.0426198974820481 1.8770577057562537e-08 0 0 0</pose>
			<axis>
				<xyz>-2.4477572411455534e-32 1.0 7.913917870025163e-22</xyz>
				<limit>
					<lower>-1.0</lower>
					<upper>1.0</upper>
				</limit>
				<use_parent_model_frame>0</use_parent_model_frame>
			</axis>
		</joint>
		<joint name="motor0" type="prismatic">
			<parent>base</parent>
			<child>motor0</child>
			<pose frame="">-0.02236363496895903 0.0047679702968050465 -0.10045188253288637 0 0 0</pose>
			<axis>
				<xyz>4.7557550391198343e-42 7.357506267547071e-22 -1.0</xyz>
				<limit>
					<lower>0.0</lower>
					<upper>0.0</upper>
				</limit>
				<use_parent_model_frame>0</use_parent_model_frame>
			</axis>
		</joint>
		<joint name="motor5" type="prismatic">
			<parent>base</parent>
			<child>motor5</child>
			<pose frame="">-0.015310056950804025 -0.01698299819037196 -0.10045235051652344 0 0 0</pose>
			<axis>
				<xyz>-5.071147387613207e-16 1.4842465720833278e-15 -1.0</xyz>
				<limit>
					<lower>0.0</lower>
					<upper>0.0</upper>
				</limit>
				<use_parent_model_frame>0</use_parent_model_frame>
			</axis>
		</joint>
		<joint name="motor4" type="prismatic">
			<parent>base</parent>
			<child>motor4</child>
			<pose frame="">-0.0004479218845654032 -0.008759037990804472 -0.10045257230605177 0 0 0</pose>
			<axis>
				<xyz>-4.564032648851929e-15 6.759974798120444e-16 -1.0</xyz>
				<limit>
					<lower>0.0</lower>
					<upper>0.0</upper>
				</limit>
				<use_parent_model_frame>0</use_parent_model_frame>
			</axis>
		</joint>
		<joint name="motor3" type="prismatic">
			<parent>base</parent>
			<child>motor3</child>
			<pose frame="">0.02236263837835921 -0.004767911729788636 -0.10045211828014732 0 0 0</pose>
			<axis>
				<xyz>7.713980309253913e-16 -4.998218023133488e-15 -1.0</xyz>
				<limit>
					<lower>0.0</lower>
					<upper>0.0</upper>
				</limit>
				<use_parent_model_frame>0</use_parent_model_frame>
			</axis>
		</joint>
		<joint name="motor2" type="prismatic">
			<parent>base</parent>
			<child>motor2</child>
			<pose frame="">0.015310500040171676 0.016983185997231302 -0.1004519623868476 0 0 0</pose>
			<axis>
				<xyz>5.431855433643031e-15 1.5110603438253467e-15 -1.0</xyz>
				<limit>
					<lower>0.0</lower>
					<upper>0.0</upper>
				</limit>
				<use_parent_model_frame>0</use_parent_model_frame>
			</axis>
		</joint>
		<joint name="motor1" type="prismatic">
			<parent>base</parent>
			<child>motor1</child>
			<pose frame="">-0.007053286237299474 0.02175011021749903 -0.10045265306894352 0 0 0</pose>
			<axis>
				<xyz>6.035394926270176e-16 1.9852842904913647e-15 -1.0</xyz>
				<limit>
					<lower>0.0</lower>
					<upper>0.0</upper>
				</limit>
				<use_parent_model_frame>0</use_parent_model_frame>
			</axis>
		</joint>
		<joint name="6dof_axis0" type="revolute">
			<parent>base</parent>
			<child>6dof_link1</child>
			<pose frame="">-1.1393157502461063e-18 -1.7089736253691594e-18 -5.696578751230531e-20 0 0 0</pose>
			<axis>
				<xyz>1.0 0.0 0.0</xyz>
				<limit>
					<lower>-3.141592653589793</lower>
					<upper>3.141592653589793</upper>
				</limit>
				<use_parent_model_frame>0</use_parent_model_frame>
			</axis>
		</joint>
		<joint name="6dof_axis1" type="revolute">
			<parent>6dof_link1</parent>
			<child>6dof_link2</child>
			<pose frame="">-3.6357506646816586e-19 2.7137868217667634e-19 3.6183824290223516e-19 0 0 0</pose>
			<axis>
				<xyz>0.0 1.0 0.0</xyz>
				<limit>
					<lower>-3.141592653589793</lower>
					<upper>3.141592653589793</upper>
				</limit>
				<use_parent_model_frame>0</use_parent_model_frame>
			</axis>
		</joint>
		<joint name="6dof_axis2" type="revolute">
			<parent>6dof_link2</parent>
			<child>6dof_link3</child>
			<pose frame="">-2.3792895949006e-07 2.890294149946432e-07 -0.010729363507488397 0 0 0</pose>
			<axis>
				<xyz>0.0 0.0 1.0</xyz>
				<limit>
					<lower>-3.141592653589793</lower>
					<upper>3.141592653589793</upper>
				</limit>
				<use_parent_model_frame>0</use_parent_model_frame>
			</axis>
		</joint>
		<plugin filename="libcardsflow_gazebo_plugin.so" name="cardsflow_gazebo_plugin"/>
	</model>
</sdf>
