<?xml version="1.0" ?>
<sdf version="1.6">
	<model name="VRpuppet">
		<link name="base">
			<self_collide>false</self_collide>
			<pose frame="">0.0 -1.4210854715202004e-16 0.05 0.0 -0.0 0.0</pose>
			<inertial>
				<pose frame="">0.0 0.0 0.0 0 0 0</pose>
				<mass>14.80571472744744</mass>
				<inertia>
					<ixx>6.761884261169531</ixx>
					<ixy>0.000888098241208643</ixy>
					<ixz>-0.0027842413122673953</ixz>
					<iyy>6.756418956494972</iyy>
					<iyz>-0.09025625769730981</iyz>
					<izz>4.070963414748864</izz>
				</inertia>
			</inertial>
			<collision name="base_collision">
				<geometry>
					<mesh>
						<uri>model://VRpuppet/meshes/CAD/base.stl</uri>
						<scale>0.001 0.001 0.001</scale>
					</mesh>
				</geometry>
			</collision>
			<visual name="base_visual">
				<geometry>
					<mesh>
						<uri>model://VRpuppet/meshes/CAD/base.stl</uri>
						<scale>0.001 0.001 0.001</scale>
					</mesh>
				</geometry>
			</visual>
		</link>
		<link name="box">
			<self_collide>false</self_collide>
			<pose frame="">0.0 -1.4210854715202004e-16 0.07400000000000001 0.0 -0.0 0.0</pose>
			<inertial>
				<pose frame="">0.0 0.0 0.0 0 0 0</pose>
				<mass>1.3599851753023426</mass>
				<inertia>
					<ixx>0.010235146953606238</ixx>
					<ixy>-3.1451062116997783e-06</ixy>
					<ixz>-1.7212513861258524e-05</ixz>
					<iyy>0.010234460750982537</iyy>
					<iyz>2.1295014088902833e-05</iyz>
					<izz>0.0020638574274181075</izz>
				</inertia>
			</inertial>
			<collision name="box_collision">
				<geometry>
					<mesh>
						<uri>model://VRpuppet/meshes/CAD/box.stl</uri>
						<scale>0.001 0.001 0.001</scale>
					</mesh>
				</geometry>
			</collision>
			<visual name="box_visual">
				<geometry>
					<mesh>
						<uri>model://VRpuppet/meshes/CAD/box.stl</uri>
						<scale>0.001 0.001 0.001</scale>
					</mesh>
				</geometry>
			</visual>
		</link>
		<link name="6dof_link4">
			<self_collide>false</self_collide>
			<pose frame="">0.04264321097415029 -6.0943105862397715e-05 3.703040005024979e-18 0.0 -0.0 0.0</pose>
			<inertial>
				<pose frame="">0.0 0.0 0.0 0 0 0</pose>
				<mass>0.029253556048299476</mass>
				<inertia>
					<ixx>4.2090251723419015e-07</ixx>
					<ixy>1.0370831206417925e-07</ixy>
					<ixz>-5.798374481226597e-21</ixz>
					<iyy>6.386641397225651e-05</iyy>
					<iyz>1.1075531602667452e-11</iyz>
					<izz>6.386578535831043e-05</izz>
				</inertia>
			</inertial>
			<collision name="6dof_link4_collision">
				<geometry>
					<mesh>
						<uri>model://VRpuppet/meshes/CAD/6dof_link4.stl</uri>
						<scale>0.001 0.001 0.001</scale>
					</mesh>
				</geometry>
			</collision>
			<visual name="6dof_link4_visual">
				<geometry>
					<mesh>
						<uri>model://VRpuppet/meshes/CAD/6dof_link4.stl</uri>
						<scale>0.001 0.001 0.001</scale>
					</mesh>
				</geometry>
			</visual>
		</link>
		<link name="6dof_link5">
			<self_collide>false</self_collide>
			<pose frame="">6.455931229707808e-05 0.04261989748204808 -1.8770577057560806e-08 0.0 -0.0 0.0</pose>
			<inertial>
				<pose frame="">0.0 0.0 0.0 0 0 0</pose>
				<mass>0.029267161202751038</mass>
				<inertia>
					<ixx>6.385311836563872e-05</ixx>
					<ixy>-1.0820097121352837e-07</ixy>
					<ixz>3.647628896237974e-12</ixz>
					<iyy>4.208289556490234e-07</iyy>
					<iyz>1.314568252966794e-10</iyz>
					<izz>6.385353905648622e-05</izz>
				</inertia>
			</inertial>
			<collision name="6dof_link5_collision">
				<geometry>
					<mesh>
						<uri>model://VRpuppet/meshes/CAD/6dof_link5.stl</uri>
						<scale>0.001 0.001 0.001</scale>
					</mesh>
				</geometry>
			</collision>
			<visual name="6dof_link5_visual">
				<geometry>
					<mesh>
						<uri>model://VRpuppet/meshes/CAD/6dof_link5.stl</uri>
						<scale>0.001 0.001 0.001</scale>
					</mesh>
				</geometry>
			</visual>
		</link>
		<link name="6dof_link1">
			<self_collide>false</self_collide>
			<pose frame="">0.0 0.0 0.0 0.0 -0.0 0.0</pose>
			<inertial>
				<pose frame="">0.0 0.0 0.0 0 0 0</pose>
				<mass>0.03806502884740436</mass>
				<inertia>
					<ixx>1.6786677721705307e-06</ixx>
					<ixy>2.168404344971009e-22</ixy>
					<ixz>-8.348356728138384e-22</ixz>
					<iyy>1.6786677721705311e-06</iyy>
					<iyz>-1.8431436932253577e-22</iyz>
					<izz>1.6786677721705307e-06</izz>
				</inertia>
			</inertial>
			<collision name="6dof_link1_collision">
				<geometry>
					<mesh>
						<uri>model://VRpuppet/meshes/CAD/6dof_link1.stl</uri>
						<scale>0.001 0.001 0.001</scale>
					</mesh>
				</geometry>
			</collision>
			<visual name="6dof_link1_visual">
				<geometry>
					<mesh>
						<uri>model://VRpuppet/meshes/CAD/6dof_link1.stl</uri>
						<scale>0.001 0.001 0.001</scale>
					</mesh>
				</geometry>
			</visual>
		</link>
		<link name="6dof_link2">
			<self_collide>false</self_collide>
			<pose frame="">0.0 0.0 0.0 0.0 -0.0 0.0</pose>
			<inertial>
				<pose frame="">0.0 0.0 0.0 0 0 0</pose>
				<mass>0.0029963725331776064</mass>
				<inertia>
					<ixx>2.42706175187388e-08</ixx>
					<ixy>8.851426536171658e-24</ixy>
					<ixz>-9.532305500492555e-24</ixz>
					<iyy>2.4270617518738303e-08</iyy>
					<iyz>-1.3552527156068806e-24</iyz>
					<izz>2.4270617518738147e-08</izz>
				</inertia>
			</inertial>
			<collision name="6dof_link2_collision">
				<geometry>
					<mesh>
						<uri>model://VRpuppet/meshes/CAD/6dof_link2.stl</uri>
						<scale>0.001 0.001 0.001</scale>
					</mesh>
				</geometry>
			</collision>
			<visual name="6dof_link2_visual">
				<geometry>
					<mesh>
						<uri>model://VRpuppet/meshes/CAD/6dof_link2.stl</uri>
						<scale>0.001 0.001 0.001</scale>
					</mesh>
				</geometry>
			</visual>
		</link>
		<link name="6dof_link3">
			<self_collide>false</self_collide>
			<pose frame="">2.3792895949006e-07 -2.890294149946432e-07 0.010729363507488397 0.0 -0.0 0.0</pose>
			<inertial>
				<pose frame="">0.0 0.0 0.0 0 0 0</pose>
				<mass>0.015709236754408062</mass>
				<inertia>
					<ixx>2.4494864177993604e-06</ixx>
					<ixy>3.9391391199366906e-12</ixy>
					<ixz>-7.480906938650857e-11</ixz>
					<iyy>2.4420629329931183e-06</iyy>
					<iyz>9.08467159514214e-11</iyz>
					<izz>2.606872971819379e-07</izz>
				</inertia>
			</inertial>
			<collision name="6dof_link3_collision">
				<geometry>
					<mesh>
						<uri>model://VRpuppet/meshes/CAD/6dof_link3.stl</uri>
						<scale>0.001 0.001 0.001</scale>
					</mesh>
				</geometry>
			</collision>
			<visual name="6dof_link3_visual">
				<geometry>
					<mesh>
						<uri>model://VRpuppet/meshes/CAD/6dof_link3.stl</uri>
						<scale>0.001 0.001 0.001</scale>
					</mesh>
				</geometry>
			</visual>
		</link>
		<link name="motor0">
			<self_collide>false</self_collide>
			<pose frame="">0.02285714176573923 -0.506038457476608 0.09933287503067394 0.0 -0.0 0.0</pose>
			<inertial>
				<pose frame="">0.0 0.0 0.0 0 0 0</pose>
				<mass>0.30550490373816114</mass>
				<inertia>
					<ixx>0.08158240948536945</ixx>
					<ixy>0.0035641837811466676</ixy>
					<ixz>-0.0006688831377434676</ixz>
					<iyy>0.003525413660856625</iyy>
					<iyz>0.015319756698910803</iyz>
					<izz>0.07869230225448481</izz>
				</inertia>
			</inertial>
			<collision name="motor0_collision">
				<geometry>
					<mesh>
						<uri>model://VRpuppet/meshes/CAD/motor0.stl</uri>
						<scale>0.001 0.001 0.001</scale>
					</mesh>
				</geometry>
			</collision>
			<visual name="motor0_visual">
				<geometry>
					<mesh>
						<uri>model://VRpuppet/meshes/CAD/motor0.stl</uri>
						<scale>0.001 0.001 0.001</scale>
					</mesh>
				</geometry>
			</visual>
		</link>
		<link name="motor5">
			<self_collide>false</self_collide>
			<pose frame="">0.46430581374507385 -0.22477874360990258 0.0993334056089418 0.0 -0.0 0.0</pose>
			<inertial>
				<pose frame="">0.0 0.0 0.0 0 0 0</pose>
				<mass>0.30548874966703765</mass>
				<inertia>
					<ixx>0.01877031276787272</ixx>
					<ixy>0.03186066774903848</ixy>
					<ixz>-0.014045198835378653</ixz>
					<iyy>0.06923768537046954</iyy>
					<iyz>0.00682398774592904</iyz>
					<izz>0.08159273055412432</izz>
				</inertia>
			</inertial>
			<collision name="motor5_collision">
				<geometry>
					<mesh>
						<uri>model://VRpuppet/meshes/CAD/motor5.stl</uri>
						<scale>0.001 0.001 0.001</scale>
					</mesh>
				</geometry>
			</collision>
			<visual name="motor5_visual">
				<geometry>
					<mesh>
						<uri>model://VRpuppet/meshes/CAD/motor5.stl</uri>
						<scale>0.001 0.001 0.001</scale>
					</mesh>
				</geometry>
			</visual>
		</link>
		<link name="motor3">
			<self_collide>false</self_collide>
			<pose frame="">-0.022848859824001068 0.53983489601909 0.0993331545944906 0.0 -0.0 0.0</pose>
			<inertial>
				<pose frame="">0.0 0.0 0.0 0 0 0</pose>
				<mass>0.30550002607682675</mass>
				<inertia>
					<ixx>0.09237958008811772</ixx>
					<ixy>0.0037987616117338362</ixy>
					<ixz>0.0006686218690217871</ixz>
					<iyy>0.003525271048401693</iyy>
					<iyz>-0.016345148306912454</iyz>
					<izz>0.08948938320593802</izz>
				</inertia>
			</inertial>
			<collision name="motor3_collision">
				<geometry>
					<mesh>
						<uri>model://VRpuppet/meshes/CAD/motor3.stl</uri>
						<scale>0.001 0.001 0.001</scale>
					</mesh>
				</geometry>
			</collision>
			<visual name="motor3_visual">
				<geometry>
					<mesh>
						<uri>model://VRpuppet/meshes/CAD/motor3.stl</uri>
						<scale>0.001 0.001 0.001</scale>
					</mesh>
				</geometry>
			</visual>
		</link>
		<link name="motor4">
			<self_collide>false</self_collide>
			<pose frame="">0.4489538072396617 0.2851658588399177 0.09933364632723844 0.0 -0.0 0.0</pose>
			<inertial>
				<pose frame="">0.0 0.0 0.0 0 0 0</pose>
				<mass>0.30547824708504573</mass>
				<inertia>
					<ixx>0.028229493059966804</ixx>
					<ixy>-0.03911778437003105</ixy>
					<ixz>-0.013603656492851206</ixz>
					<iyy>0.06489952890002364</iyy>
					<iyz>-0.008613297227676224</iyz>
					<izz>0.08671393074594681</izz>
				</inertia>
			</inertial>
			<collision name="motor4_collision">
				<geometry>
					<mesh>
						<uri>model://VRpuppet/meshes/CAD/motor4.stl</uri>
						<scale>0.001 0.001 0.001</scale>
					</mesh>
				</geometry>
			</collision>
			<visual name="motor4_visual">
				<geometry>
					<mesh>
						<uri>model://VRpuppet/meshes/CAD/motor4.stl</uri>
						<scale>0.001 0.001 0.001</scale>
					</mesh>
				</geometry>
			</visual>
		</link>
		<link name="motor2">
			<self_collide>false</self_collide>
			<pose frame="">-0.4642990913289874 0.2585751826079969 0.09933297271062784 0.0 -0.0 0.0</pose>
			<inertial>
				<pose frame="">0.0 0.0 0.0 0 0 0</pose>
				<mass>0.30550404001277265</mass>
				<inertia>
					<ixx>0.023761824626400196</ixx>
					<ixy>0.03665566493632551</ixy>
					<ixz>0.01404563747212196</ixz>
					<iyy>0.06923921346019207</iyy>
					<iyz>-0.00784990552507985</iyz>
					<izz>0.08658551781209088</izz>
				</inertia>
			</inertial>
			<collision name="motor2_collision">
				<geometry>
					<mesh>
						<uri>model://VRpuppet/meshes/CAD/motor2.stl</uri>
						<scale>0.001 0.001 0.001</scale>
					</mesh>
				</geometry>
			</collision>
			<visual name="motor2_visual">
				<geometry>
					<mesh>
						<uri>model://VRpuppet/meshes/CAD/motor2.stl</uri>
						<scale>0.001 0.001 0.001</scale>
					</mesh>
				</geometry>
			</visual>
		</link>
		<link name="motor1">
			<self_collide>false</self_collide>
			<pose frame="">-0.4414453300407218 -0.2643600780726651 0.09933387450912597 0.0 -0.0 0.0</pose>
			<inertial>
				<pose frame="">0.0 0.0 0.0 0 0 0</pose>
				<mass>0.3055116978012082</mass>
				<inertia>
					<ixx>0.024739576108863588</ixx>
					<ixy>-0.035661919926525947</ixy>
					<ixz>0.013377307108531364</ixz>
					<iyy>0.06286412972011794</iyy>
					<iyz>0.00798284908090229</iyz>
					<izz>0.08118791031845371</izz>
				</inertia>
			</inertial>
			<collision name="motor1_collision">
				<geometry>
					<mesh>
						<uri>model://VRpuppet/meshes/CAD/motor1.stl</uri>
						<scale>0.001 0.001 0.001</scale>
					</mesh>
				</geometry>
			</collision>
			<visual name="motor1_visual">
				<geometry>
					<mesh>
						<uri>model://VRpuppet/meshes/CAD/motor1.stl</uri>
						<scale>0.001 0.001 0.001</scale>
					</mesh>
				</geometry>
			</visual>
		</link>
		<joint name="6dof_axis3" type="prismatic">
			<parent>6dof_link3</parent>
			<child>6dof_link4</child>
			<pose frame="">-0.04264321097415029 6.0943105862397715e-05 -3.703040005024979e-18 0 0 0</pose>
			<axis>
				<xyz>-1.0 0.0 0.0</xyz>
				<limit>
					<lower>-1.0</lower>
					<upper>1.0</upper>
				</limit>
				<use_parent_model_frame>0</use_parent_model_frame>
			</axis>
		</joint>
		<joint name="6dof_axis4" type="prismatic">
			<parent>6dof_link4</parent>
			<child>6dof_link5</child>
			<pose frame="">-6.100828795643542e-05 -0.0426198974820481 1.8770577057562537e-08 0 0 0</pose>
			<axis>
				<xyz>-2.4477572411455534e-32 1.0 7.913917870025163e-22</xyz>
				<limit>
					<lower>-1.0</lower>
					<upper>1.0</upper>
				</limit>
				<use_parent_model_frame>0</use_parent_model_frame>
			</axis>
		</joint>
		<joint name="6dof_axis5" type="prismatic">
			<parent>6dof_link5</parent>
			<child>box</child>
			<pose frame="">3.5510243406426314e-06 1.0056394587544793e-05 -0.07399999683157192 0 0 0</pose>
			<axis>
				<xyz>0.0 -5.082197683525802e-21 1.0</xyz>
				<limit>
					<lower>-1.0</lower>
					<upper>1.0</upper>
				</limit>
				<use_parent_model_frame>0</use_parent_model_frame>
			</axis>
		</joint>
		<joint name="6dof_axis0" type="revolute">
			<parent>base</parent>
			<child>6dof_link1</child>
			<pose frame="">-1.1393157502461063e-18 -1.7089736253691594e-18 -5.696578751230531e-20 0 0 0</pose>
			<axis>
				<xyz>1.0 0.0 0.0</xyz>
				<limit>
					<lower>-3.141592653589793</lower>
					<upper>3.141592653589793</upper>
				</limit>
				<use_parent_model_frame>0</use_parent_model_frame>
			</axis>
		</joint>
		<joint name="6dof_axis1" type="revolute">
			<parent>6dof_link1</parent>
			<child>6dof_link2</child>
			<pose frame="">-3.6357506646816586e-19 2.7137868217667634e-19 3.6183824290223516e-19 0 0 0</pose>
			<axis>
				<xyz>0.0 1.0 0.0</xyz>
				<limit>
					<lower>-3.141592653589793</lower>
					<upper>3.141592653589793</upper>
				</limit>
				<use_parent_model_frame>0</use_parent_model_frame>
			</axis>
		</joint>
		<joint name="6dof_axis2" type="revolute">
			<parent>6dof_link2</parent>
			<child>6dof_link3</child>
			<pose frame="">-2.3792895949006e-07 2.890294149946432e-07 -0.010729363507488397 0 0 0</pose>
			<axis>
				<xyz>0.0 0.0 1.0</xyz>
				<limit>
					<lower>-3.141592653589793</lower>
					<upper>3.141592653589793</upper>
				</limit>
				<use_parent_model_frame>0</use_parent_model_frame>
			</axis>
		</joint>
		<joint name="motor0" type="prismatic">
			<parent>base</parent>
			<child>motor0</child>
			<pose frame="">-0.027353590741398585 0.006048526868087407 -0.09930002644413818 0 0 0</pose>
			<axis>
				<xyz>4.7557550391198343e-42 7.357506267547071e-22 -1.0</xyz>
				<limit>
					<lower>0.0</lower>
					<upper>0.0</upper>
				</limit>
				<use_parent_model_frame>0</use_parent_model_frame>
			</axis>
		</joint>
		<joint name="motor5" type="prismatic">
			<parent>base</parent>
			<child>motor5</child>
			<pose frame="">-0.018913970810773294 -0.020664212981849738 -0.09930055702240527 0 0 0</pose>
			<axis>
				<xyz>-5.071147387613207e-16 1.4842465720833278e-15 -1.0</xyz>
				<limit>
					<lower>0.0</lower>
					<upper>0.0</upper>
				</limit>
				<use_parent_model_frame>0</use_parent_model_frame>
			</axis>
		</joint>
		<joint name="motor4" type="prismatic">
			<parent>base</parent>
			<child>motor4</child>
			<pose frame="">0.0009380356946410018 -0.013720638764071608 -0.09930079774070101 0 0 0</pose>
			<axis>
				<xyz>-4.564032648851929e-15 6.759974798120444e-16 -1.0</xyz>
				<limit>
					<lower>0.0</lower>
					<upper>0.0</upper>
				</limit>
				<use_parent_model_frame>0</use_parent_model_frame>
			</axis>
		</joint>
		<joint name="motor3" type="prismatic">
			<parent>base</parent>
			<child>motor3</child>
			<pose frame="">0.02735241084834697 -0.006048473292411103 -0.09930030600795785 0 0 0</pose>
			<axis>
				<xyz>7.713980309253913e-16 -4.998218023133488e-15 -1.0</xyz>
				<limit>
					<lower>0.0</lower>
					<upper>0.0</upper>
				</limit>
				<use_parent_model_frame>0</use_parent_model_frame>
			</axis>
		</joint>
		<joint name="motor2" type="prismatic">
			<parent>base</parent>
			<child>motor2</child>
			<pose frame="">0.01891435044337321 0.020664266101912823 -0.09930012412408931 0 0 0</pose>
			<axis>
				<xyz>5.431855433643031e-15 1.5110603438253467e-15 -1.0</xyz>
				<limit>
					<lower>0.0</lower>
					<upper>0.0</upper>
				</limit>
				<use_parent_model_frame>0</use_parent_model_frame>
			</axis>
		</joint>
		<joint name="motor1" type="prismatic">
			<parent>base</parent>
			<child>motor1</child>
			<pose frame="">-0.008439410844895079 0.026711350114977002 -0.09930102592258815 0 0 0</pose>
			<axis>
				<xyz>6.035394926270176e-16 1.9852842904913647e-15 -1.0</xyz>
				<limit>
					<lower>0.0</lower>
					<upper>0.0</upper>
				</limit>
				<use_parent_model_frame>0</use_parent_model_frame>
			</axis>
		</joint>
		<plugin filename="libcardsflow_gazebo_plugin.so" name="cardsflow_gazebo_plugin"/>
	</model>
</sdf>
