<robot name="VRpuppet">
  <joint name="motor0" type="prismatic">
    <parent link="base" />
    <child link="motor0" />
    <origin rpy="0 0 0" xyz="1.485e+00 0.000e+00 1.000e-03" />
    <axis xyz="0 -1  0" />
    <limit effort="0.0" lower="-1.4" upper="0.0" velocity="0.0" />
  </joint>
  <joint name="motor1" type="prismatic">
    <parent link="base" />
    <child link="motor1" />
    <origin rpy="0 0 0" xyz="1.485e+00 0.000e+00 1.000e-03" />
    <axis xyz="0 -1  0" />
    <limit effort="0.0" lower="0.0" upper="1.4" velocity="0.0" />
  </joint>
  <joint name="motor2" type="prismatic">
    <parent link="base" />
    <child link="motor2" />
    <origin rpy="0 0 0" xyz="-1.485e+00  0.000e+00  1.000e-03" />
    <axis xyz="0 1 0" />
    <limit effort="0.0" lower="0.0" upper="1.4" velocity="0.0" />
  </joint>
  <joint name="motor3" type="prismatic">
    <parent link="base" />
    <child link="motor3" />
    <origin rpy="0 0 0" xyz="-1.485e+00  0.000e+00  1.000e-03" />
    <axis xyz="0 1 0" />
    <limit effort="0.0" lower="-1.4" upper="0.0" velocity="0.0" />
  </joint>
  <joint name="motor4" type="prismatic">
    <parent link="base" />
    <child link="motor5" />
    <origin rpy="0 0 0" xyz="0.000e+00 1.485e+00 1.000e-03" />
    <axis xyz="1 0 0" />
    <limit effort="0.0" lower="0.0" upper="1.4" velocity="0.0" />
  </joint>
  <joint name="motor5" type="prismatic">
    <parent link="base" />
    <child link="motor4" />
    <origin rpy="0 0 0" xyz="0.000e+00 1.485e+00 1.000e-03" />
    <axis xyz="1 0 0" />
    <limit effort="0.0" lower="-1.4" upper="0.0" velocity="0.0" />
  </joint>
  <joint name="motor6" type="prismatic">
    <parent link="base" />
    <child link="motor7" />
    <origin rpy="0 0 0" xyz="0.000e+00 -1.485e+00  1.000e-03" />
    <axis xyz="-1  0  0" />
    <limit effort="0.0" lower="-1.4" upper="0.0" velocity="0.0" />
  </joint>
  <joint name="motor7" type="prismatic">
    <parent link="base" />
    <child link="motor6" />
    <origin rpy="0 0 0" xyz="0.000e+00 -1.485e+00  1.000e-03" />
    <axis xyz="-1  0  0" />
    <limit effort="0.0" lower="0.0" upper="1.4" velocity="0.0" />
  </joint>
  <joint name="motor8" type="prismatic">
    <parent link="base" />
    <child link="motor8" />
    <origin rpy="0 0 0" xyz="1.485   0      1.00099" />
    <axis xyz="0 -1  0" />
    <limit effort="0.0" lower="-1.4" upper="0.0" velocity="0.0" />
  </joint>
  <joint name="motor9" type="prismatic">
    <parent link="base" />
    <child link="motor9" />
    <origin rpy="0 0 0" xyz="1.485   0      1.00099" />
    <axis xyz="0 -1  0" />
    <limit effort="0.0" lower="0.0" upper="0.0" velocity="0.0" />
  </joint>
  <joint name="motor10" type="prismatic">
    <parent link="base" />
    <child link="motor11" />
    <origin rpy="0 0 0" xyz="-1.485    0       1.00099" />
    <axis xyz="0 1 0" />
    <limit effort="0.0" lower="-1.4" upper="0.0" velocity="0.0" />
  </joint>
  <joint name="motor11" type="prismatic">
    <parent link="base" />
    <child link="motor10" />
    <origin rpy="0 0 0" xyz="-1.485    0       1.00099" />
    <axis xyz="0 1 0" />
    <limit effort="0.0" lower="0.0" upper="1.4" velocity="0.0" />
  </joint>
  <joint name="motor12" type="prismatic">
    <parent link="base" />
    <child link="motor12" />
    <origin rpy="0 0 0" xyz="0      1.485   1.00099" />
    <axis xyz="1 0 0" />
    <limit effort="0.0" lower="-1.4" upper="0.0" velocity="0.0" />
  </joint>
  <joint name="motor13" type="prismatic">
    <parent link="base" />
    <child link="motor13" />
    <origin rpy="0 0 0" xyz="0      1.485   1.00099" />
    <axis xyz="1 0 0" />
    <limit effort="0.0" lower="0.0" upper="1.4" velocity="0.0" />
  </joint>
  <joint name="motor14" type="prismatic">
    <parent link="base" />
    <child link="motor15" />
    <origin rpy="0 0 0" xyz="0      -1.485    1.00099" />
    <axis xyz="-1  0  0" />
    <limit effort="0.0" lower="-1.4" upper="0.0" velocity="0.0" />
  </joint>
  <joint name="motor15" type="prismatic">
    <parent link="base" />
    <child link="motor14" />
    <origin rpy="0 0 0" xyz="0      -1.485    1.00099" />
    <axis xyz="-1  0  0" />
    <limit effort="0.0" lower="0.0" upper="1.4" velocity="0.0" />
  </joint>
  <joint name="motor16" type="prismatic">
    <parent link="base" />
    <child link="motor16" />
    <origin rpy="0 0 0" xyz="1.485 0    2.001" />
    <axis xyz="0 -1  0" />
    <limit effort="0.0" lower="-1.4" upper="0.0" velocity="0.0" />
  </joint>
  <joint name="motor17" type="prismatic">
    <parent link="base" />
    <child link="motor17" />
    <origin rpy="0 0 0" xyz="1.485 0    2.001" />
    <axis xyz="0 -1  0" />
    <limit effort="0.0" lower="0.0" upper="1.4" velocity="0.0" />
  </joint>
  <joint name="motor18" type="prismatic">
    <parent link="base" />
    <child link="motor19" />
    <origin rpy="0 0 0" xyz="-1.485  0     2.001" />
    <axis xyz="0 1 0" />
    <limit effort="0.0" lower="-1.4" upper="0.0" velocity="0.0" />
  </joint>
  <joint name="motor19" type="prismatic">
    <parent link="base" />
    <child link="motor18" />
    <origin rpy="0 0 0" xyz="-1.485  0     2.001" />
    <axis xyz="0 1 0" />
    <limit effort="0.0" lower="0.0" upper="1.4" velocity="0.0" />
  </joint>
  <joint name="motor20" type="prismatic">
    <parent link="base" />
    <child link="motor20" />
    <origin rpy="0 0 0" xyz="0    1.485 2.001" />
    <axis xyz="1 0 0" />
    <limit effort="0.0" lower="-1.4" upper="0.0" velocity="0.0" />
  </joint>
  <joint name="motor21" type="prismatic">
    <parent link="base" />
    <child link="motor21" />
    <origin rpy="0 0 0" xyz="0    1.485 2.001" />
    <axis xyz="1 0 0" />
    <limit effort="0.0" lower="0.0" upper="1.4" velocity="0.0" />
  </joint>
  <joint name="motor22" type="prismatic">
    <parent link="base" />
    <child link="motor23" />
    <origin rpy="0 0 0" xyz="0    -1.485  2.001" />
    <axis xyz="-1  0  0" />
    <limit effort="0.0" lower="-1.4" upper="0.0" velocity="0.0" />
  </joint>
  <joint name="motor23" type="prismatic">
    <parent link="base" />
    <child link="motor22" />
    <origin rpy="0 0 0" xyz="0    -1.485  2.001" />
    <axis xyz="-1  0  0" />
    <limit effort="0.0" lower="0.0" upper="1.4" velocity="0.0" />
  </joint>
  <joint name="foot_right_axis0" type="revolute">
    <parent link="lower_leg_right" />
    <child link="ankle_right_link1" />
    <origin rpy="0 0 0" xyz="-0.00072 -0.01319 -0.35401" />
    <axis xyz="0.08715 0.99619 0" />
    <limit effort="0.0" lower="-3.14159265359" upper="3.14159265359" velocity="0.0" />
  </joint>
  <joint name="foot_right_axis2" type="revolute">
    <parent link="ankle_right_link2" />
    <child link="foot_right" />
    <origin rpy="0 0 0" xyz="0 0 0" />
    <axis xyz="0  0 -1" />
    <limit effort="0.0" lower="-3.14159265359" upper="3.14159265359" velocity="0.0" />
  </joint>
  <joint name="foot_right_axis1" type="revolute">
    <parent link="ankle_right_link1" />
    <child link="ankle_right_link2" />
    <origin rpy="0 0 0" xyz="0 0 0" />
    <axis xyz="-0.99619  0.08715  0" />
    <limit effort="0.0" lower="-3.14159265359" upper="3.14159265359" velocity="0.0" />
  </joint>
  <joint name="shoulder_right_axis0" type="revolute">
    <parent link="torso" />
    <child link="shoulder_right_link1" />
    <origin rpy="0 0 0" xyz="-0.06039 -0.17508  0.36978" />
    <axis xyz="0 0 1" />
    <limit effort="0.0" lower="-3.14159265359" upper="3.14159265359" velocity="0.0" />
  </joint>
  <joint name="shoulder_right_axis2" type="revolute">
    <parent link="shoulder_right_link2" />
    <child link="upper_arm_right" />
    <origin rpy="0 0 0" xyz="0 0 0" />
    <axis xyz="0.08715 0.99619 0" />
    <limit effort="0.0" lower="-3.14159265359" upper="3.14159265359" velocity="0.0" />
  </joint>
  <joint name="shoulder_right_axis1" type="revolute">
    <parent link="shoulder_right_link1" />
    <child link="shoulder_right_link2" />
    <origin rpy="0 0 0" xyz="0 0 0" />
    <axis xyz="-0.99619  0.08715  0" />
    <limit effort="0.0" lower="-3.14159265359" upper="3.14159265359" velocity="0.0" />
  </joint>
  <joint name="knee_right_axis0" type="revolute">
    <parent link="upper_leg_right" />
    <child link="knee_right_link1" />
    <origin rpy="0 0 0" xyz="-1.5000e-04 -6.5800e-03 -4.3161e-01" />
    <axis xyz="0.08715 0.99619 0" />
    <limit effort="0.0" lower="-3.14159265359" upper="3.14159265359" velocity="0.0" />
  </joint>
  <joint name="knee_right_axis2" type="revolute">
    <parent link="knee_right_link2" />
    <child link="lower_leg_right" />
    <origin rpy="0 0 0" xyz="0 0 0" />
    <axis xyz="0  0 -1" />
    <limit effort="0.0" lower="-3.14159265359" upper="3.14159265359" velocity="0.0" />
  </joint>
  <joint name="knee_right_axis1" type="revolute">
    <parent link="knee_right_link1" />
    <child link="knee_right_link2" />
    <origin rpy="0 0 0" xyz="0 0 0" />
    <axis xyz="-0.99619  0.08715  0" />
    <limit effort="0.0" lower="-3.14159265359" upper="3.14159265359" velocity="0.0" />
  </joint>
  <joint name="elbow_right_axis0" type="revolute">
    <parent link="upper_arm_right" />
    <child link="elbow_right_link1" />
    <origin rpy="0 0 0" xyz="-0.02938 -0.03758 -0.263" />
    <axis xyz="0 0 1" />
    <limit effort="0.0" lower="-3.14159265359" upper="3.14159265359" velocity="0.0" />
  </joint>
  <joint name="elbow_right_axis2" type="revolute">
    <parent link="elbow_right_link2" />
    <child link="lower_arm_right" />
    <origin rpy="0 0 0" xyz="0 0 0" />
    <axis xyz="0.08715 0.99619 0" />
    <limit effort="0.0" lower="-3.14159265359" upper="3.14159265359" velocity="0.0" />
  </joint>
  <joint name="elbow_right_axis1" type="revolute">
    <parent link="elbow_right_link1" />
    <child link="elbow_right_link2" />
    <origin rpy="0 0 0" xyz="0 0 0" />
    <axis xyz="-0.99619  0.08715  0" />
    <limit effort="0.0" lower="-3.14159265359" upper="3.14159265359" velocity="0.0" />
  </joint>
  <joint name="shoulder_left_axis0" type="revolute">
    <parent link="torso" />
    <child link="shoulder_left_link1" />
    <origin rpy="0 0 0" xyz="-0.02853  0.18908  0.36978" />
    <axis xyz="0  0 -1" />
    <limit effort="0.0" lower="-3.14159265359" upper="3.14159265359" velocity="0.0" />
  </joint>
  <joint name="shoulder_left_axis2" type="revolute">
    <parent link="shoulder_left_link2" />
    <child link="upper_arm_left" />
    <origin rpy="0 0 0" xyz="0 0 0" />
    <axis xyz="0.08715 0.99619 0" />
    <limit effort="0.0" lower="-3.14159265359" upper="3.14159265359" velocity="0.0" />
  </joint>
  <joint name="shoulder_left_axis1" type="revolute">
    <parent link="shoulder_left_link1" />
    <child link="shoulder_left_link2" />
    <origin rpy="0 0 0" xyz="0 0 0" />
    <axis xyz="0.99619 -0.08715  0" />
    <limit effort="0.0" lower="-3.14159265359" upper="3.14159265359" velocity="0.0" />
  </joint>
  <joint name="wrist_right_axis0" type="revolute">
    <parent link="lower_arm_right" />
    <child link="wrist_right_link1" />
    <origin rpy="0 0 0" xyz="0.01297 -0.0468  -0.268" />
    <axis xyz="0 0 1" />
    <limit effort="0.0" lower="-3.14159265359" upper="3.14159265359" velocity="0.0" />
  </joint>
  <joint name="wrist_right_axis2" type="revolute">
    <parent link="wrist_right_link2" />
    <child link="hand_right" />
    <origin rpy="0 0 0" xyz="0 0 0" />
    <axis xyz="0.08715 0.99619 0" />
    <limit effort="0.0" lower="-3.14159265359" upper="3.14159265359" velocity="0.0" />
  </joint>
  <joint name="wrist_right_axis1" type="revolute">
    <parent link="wrist_right_link1" />
    <child link="wrist_right_link2" />
    <origin rpy="0 0 0" xyz="0 0 0" />
    <axis xyz="-0.99619  0.08715  0" />
    <limit effort="0.0" lower="-3.14159265359" upper="3.14159265359" velocity="0.0" />
  </joint>
  <joint name="elbow_left_axis0" type="revolute">
    <parent link="upper_arm_left" />
    <child link="elbow_left_link1" />
    <origin rpy="0 0 0" xyz="-0.02241  0.04211 -0.263" />
    <axis xyz="0  0 -1" />
    <limit effort="0.0" lower="-3.14159265359" upper="3.14159265359" velocity="0.0" />
  </joint>
  <joint name="elbow_left_axis2" type="revolute">
    <parent link="elbow_left_link2" />
    <child link="lower_arm_left" />
    <origin rpy="0 0 0" xyz="0 0 0" />
    <axis xyz="0.08715 0.99619 0" />
    <limit effort="0.0" lower="-3.14159265359" upper="3.14159265359" velocity="0.0" />
  </joint>
  <joint name="ankle_right_axis1" type="revolute">
    <parent link="elbow_left_link1" />
    <child link="elbow_left_link2" />
    <origin rpy="0 0 0" xyz="0 0 0" />
    <axis xyz="0.99619 -0.08715  0" />
    <limit effort="0.0" lower="-3.14159265359" upper="3.14159265359" velocity="0.0" />
  </joint>
  <joint name="wrist_left_axis0" type="revolute">
    <parent link="lower_arm_left" />
    <child link="wrist_left_link1" />
    <origin rpy="0 0 0" xyz="0.0209   0.04384 -0.268" />
    <axis xyz="0  0 -1" />
    <limit effort="0.0" lower="-3.14159265359" upper="3.14159265359" velocity="0.0" />
  </joint>
  <joint name="wrist_left_axis2" type="revolute">
    <parent link="wrist_left_link2" />
    <child link="hand_left" />
    <origin rpy="0 0 0" xyz="0 0 0" />
    <axis xyz="0.08715 0.99619 0" />
    <limit effort="0.0" lower="-3.14159265359" upper="3.14159265359" velocity="0.0" />
  </joint>
  <joint name="wrist_left_axis1" type="revolute">
    <parent link="wrist_left_link1" />
    <child link="wrist_left_link2" />
    <origin rpy="0 0 0" xyz="0 0 0" />
    <axis xyz="0.99619 -0.08715  0" />
    <limit effort="0.0" lower="-3.14159265359" upper="3.14159265359" velocity="0.0" />
  </joint>
  <joint name="knee_left_axis0" type="revolute">
    <parent link="upper_leg_left" />
    <child link="knee_left_link1" />
    <origin rpy="0 0 0" xyz="0.00153  0.0127  -0.43161" />
    <axis xyz="0.08715 0.99619 0" />
    <limit effort="0.0" lower="-3.14159265359" upper="3.14159265359" velocity="0.0" />
  </joint>
  <joint name="knee_left_axis2" type="revolute">
    <parent link="knee_left_link2" />
    <child link="lower_leg_left" />
    <origin rpy="0 0 0" xyz="0 0 0" />
    <axis xyz="0 0 1" />
    <limit effort="0.0" lower="-3.14159265359" upper="3.14159265359" velocity="0.0" />
  </joint>
  <joint name="knee_left_axis1" type="revolute">
    <parent link="knee_left_link1" />
    <child link="knee_left_link2" />
    <origin rpy="0 0 0" xyz="0 0 0" />
    <axis xyz="0.99619 -0.08715  0" />
    <limit effort="0.0" lower="-3.14159265359" upper="3.14159265359" velocity="0.0" />
  </joint>
  <joint name="foot_left_axis0" type="revolute">
    <parent link="lower_leg_left" />
    <child link="foot_left_link1" />
    <origin rpy="0 0 0" xyz="0.00158  0.01312 -0.35401" />
    <axis xyz="0.08715 0.99619 0" />
    <limit effort="0.0" lower="-3.14159265359" upper="3.14159265359" velocity="0.0" />
  </joint>
  <joint name="foot_left_axis2" type="revolute">
    <parent link="foot_left_link2" />
    <child link="foot_left" />
    <origin rpy="0 0 0" xyz="0 0 0" />
    <axis xyz="0 0 1" />
    <limit effort="0.0" lower="-3.14159265359" upper="3.14159265359" velocity="0.0" />
  </joint>
  <joint name="foot_left_axis1" type="revolute">
    <parent link="foot_left_link1" />
    <child link="foot_left_link2" />
    <origin rpy="0 0 0" xyz="0 0 0" />
    <axis xyz="0.99619 -0.08715  0" />
    <limit effort="0.0" lower="-3.14159265359" upper="3.14159265359" velocity="0.0" />
  </joint>
  <joint name="neck_axis0" type="revolute">
    <parent link="torso" />
    <child link="neck_link1" />
    <origin rpy="0 0 0" xyz="-0.00984  0.00118  0.57978" />
    <axis xyz="0.08715 0.99619 0" />
    <limit effort="0.0" lower="-3.14159265359" upper="3.14159265359" velocity="0.0" />
  </joint>
  <joint name="neck_axis2" type="revolute">
    <parent link="neck_link2" />
    <child link="head" />
    <origin rpy="0 0 0" xyz="0 0 0" />
    <axis xyz="0  0 -1" />
    <limit effort="0.0" lower="-3.14159265359" upper="3.14159265359" velocity="0.0" />
  </joint>
  <joint name="neck_axis1" type="revolute">
    <parent link="neck_link1" />
    <child link="neck_link2" />
    <origin rpy="0 0 0" xyz="0 0 0" />
    <axis xyz="-0.99619  0.08715  0" />
    <limit effort="0.0" lower="-3.14159265359" upper="3.14159265359" velocity="0.0" />
  </joint>
  <joint name="hip_left_sphere_axis0" type="revolute">
    <parent link="base" />
    <child link="hip_left_sphere_link1" />
    <origin rpy="0 0 0" xyz="-0.01252  0.09608  0.89709" />
    <axis xyz="0.99619 -0.08715  0" />
    <limit effort="0.0" lower="-3.14159265359" upper="3.14159265359" velocity="0.0" />
  </joint>
  <joint name="hip_left_sphere_axis1" type="revolute">
    <parent link="hip_left_sphere_link1" />
    <child link="hip_left_sphere_link2" />
    <origin rpy="0 0 0" xyz="0 0 0" />
    <axis xyz="0.08715 0.99619 0" />
    <limit effort="0.0" lower="-3.14159265359" upper="3.14159265359" velocity="0.0" />
  </joint>
  <joint name="hip_left_sphere_axis2" type="revolute">
    <parent link="hip_left_sphere_link2" />
    <child link="upper_leg_left" />
    <origin rpy="0 0 0" xyz="0 0 0" />
    <axis xyz="0 0 1" />
    <limit effort="0.0" lower="-3.14159265359" upper="3.14159265359" velocity="0.0" />
  </joint>
  <joint name="hip_right_sphere_axis0" type="revolute">
    <parent link="base" />
    <child link="hip_right_sphere_link1" />
    <origin rpy="0 0 0" xyz="-0.02991 -0.10262  0.89709" />
    <axis xyz="0.99619 -0.08715  0" />
    <limit effort="0.0" lower="-3.14159265359" upper="3.14159265359" velocity="0.0" />
  </joint>
  <joint name="hip_right_sphere_axis1" type="revolute">
    <parent link="hip_right_sphere_link1" />
    <child link="hip_right_sphere_link2" />
    <origin rpy="0 0 0" xyz="0 0 0" />
    <axis xyz="0.08715 0.99619 0" />
    <limit effort="0.0" lower="-3.14159265359" upper="3.14159265359" velocity="0.0" />
  </joint>
  <joint name="hip_right_sphere_axis2" type="revolute">
    <parent link="hip_right_sphere_link2" />
    <child link="upper_leg_right" />
    <origin rpy="0 0 0" xyz="0 0 0" />
    <axis xyz="0 0 1" />
    <limit effort="0.0" lower="-3.14159265359" upper="3.14159265359" velocity="0.0" />
  </joint>
  <joint name="spine_sphere_axis0" type="revolute">
    <parent link="base" />
    <child link="spine_sphere_link1" />
    <origin rpy="0 0 0" xyz="-0.02036 -0.00333  1.03023" />
    <axis xyz="0.99619 -0.08715  0" />
    <limit effort="0.0" lower="-3.14159265359" upper="3.14159265359" velocity="0.0" />
  </joint>
  <joint name="spine_sphere_axis1" type="revolute">
    <parent link="spine_sphere_link1" />
    <child link="spine_sphere_link2" />
    <origin rpy="0 0 0" xyz="0 0 0" />
    <axis xyz="0.08715 0.99619 0" />
    <limit effort="0.0" lower="-3.14159265359" upper="3.14159265359" velocity="0.0" />
  </joint>
  <joint name="spine_sphere_axis2" type="revolute">
    <parent link="spine_sphere_link2" />
    <child link="torso" />
    <origin rpy="0 0 0" xyz="0 0 0" />
    <axis xyz="0 0 1" />
    <limit effort="0.0" lower="-3.14159265359" upper="3.14159265359" velocity="0.0" />
  </joint>
  <link name="base">
    <inertial>
      <mass value="48.77412205270252" />
      <origin rpy="0 0 0" xyz="-0.01751 -0.00301  0.9287" />
      <inertia ixx="52.62295381392352" ixy="-0.005398094555838205" ixz="0.8072875162500746" iyy="52.60999467690776" iyz="0.1393777960961568" izz="12.865303201489157" />
    </inertial>
    <collision name="base_collision">
      <origin rpy="0 0 0" xyz="-0.01751 -0.00301  0.9287" />
      <geometry>
        <mesh filename="package://robots/VRpuppet/meshes/collisions/base.stl" scale="0.001 0.001 0.001" />
      </geometry>
    </collision>
    <visual name="base_visual">
      <origin rpy="0 0 0" xyz="-0.01751 -0.00301  0.9287" />
      <geometry>
        <mesh filename="package://robots/VRpuppet/meshes/visuals/base.stl" scale="0.001 0.001 0.001" />
      </geometry>
    </visual>
  </link>
  <link name="motor3">
    <inertial>
      <mass value="0.5354312076773345" />
      <origin rpy="0 0 0" xyz="0.00164 -1.2341   0.00951" />
      <inertia ixx="0.8156965421447707" ixy="-0.9801543652769608" ixz="0.008352521216719092" iyy="1.1784568974700376" iyz="0.006949308002204232" izz="1.9939591873759976" />
    </inertial>
    <collision name="motor3_collision">
      <origin rpy="0 0 0" xyz="0.00164 -1.2341   0.00951" />
      <geometry>
        <mesh filename="package://robots/VRpuppet/meshes/collisions/motor3.stl" scale="0.001 0.001 0.001" />
      </geometry>
    </collision>
    <visual name="motor3_visual">
      <origin rpy="0 0 0" xyz="0.00164 -1.2341   0.00951" />
      <geometry>
        <mesh filename="package://robots/VRpuppet/meshes/visuals/motor3.stl" scale="0.001 0.001 0.001" />
      </geometry>
    </visual>
  </link>
  <link name="motor2">
    <inertial>
      <mass value="0.5354311012721492" />
      <origin rpy="0 0 0" xyz="0.00164 1.2341  0.00948" />
      <inertia ixx="0.8156960015022827" ixy="0.980154168264201" ixz="0.008326458123108008" iyy="1.1784562855207728" iyz="-0.0069269878929037534" izz="1.9939587869422881" />
    </inertial>
    <collision name="motor2_collision">
      <origin rpy="0 0 0" xyz="0.00164 1.2341  0.00948" />
      <geometry>
        <mesh filename="package://robots/VRpuppet/meshes/collisions/motor2.stl" scale="0.001 0.001 0.001" />
      </geometry>
    </collision>
    <visual name="motor2_visual">
      <origin rpy="0 0 0" xyz="0.00164 1.2341  0.00948" />
      <geometry>
        <mesh filename="package://robots/VRpuppet/meshes/visuals/motor2.stl" scale="0.001 0.001 0.001" />
      </geometry>
    </visual>
  </link>
  <link name="motor0">
    <inertial>
      <mass value="0.53543110127207" />
      <origin rpy="0 0 0" xyz="-0.00164  1.2341   0.00951" />
      <inertia ixx="0.8156963775721258" ixy="-0.9801541682640564" ixz="-0.008352519774264891" iyy="1.1784566615905638" iyz="-0.006949306797386737" izz="1.993958786941995" />
    </inertial>
    <collision name="motor0_collision">
      <origin rpy="0 0 0" xyz="-0.00164  1.2341   0.00951" />
      <geometry>
        <mesh filename="package://robots/VRpuppet/meshes/collisions/motor0.stl" scale="0.001 0.001 0.001" />
      </geometry>
    </collision>
    <visual name="motor0_visual">
      <origin rpy="0 0 0" xyz="-0.00164  1.2341   0.00951" />
      <geometry>
        <mesh filename="package://robots/VRpuppet/meshes/visuals/motor0.stl" scale="0.001 0.001 0.001" />
      </geometry>
    </visual>
  </link>
  <link name="motor4">
    <inertial>
      <mass value="0.5354312076773345" />
      <origin rpy="0 0 0" xyz="-1.2341  -0.00164  0.00951" />
      <inertia ixx="1.1784568974700371" ixy="0.9801543652769604" ixz="0.006949308002204232" iyy="0.8156965421447707" iyz="-0.008352521216719089" izz="1.9939591873759972" />
    </inertial>
    <collision name="motor4_collision">
      <origin rpy="0 0 0" xyz="-1.2341  -0.00164  0.00951" />
      <geometry>
        <mesh filename="package://robots/VRpuppet/meshes/collisions/motor4.stl" scale="0.001 0.001 0.001" />
      </geometry>
    </collision>
    <visual name="motor4_visual">
      <origin rpy="0 0 0" xyz="-1.2341  -0.00164  0.00951" />
      <geometry>
        <mesh filename="package://robots/VRpuppet/meshes/visuals/motor4.stl" scale="0.001 0.001 0.001" />
      </geometry>
    </visual>
  </link>
  <link name="motor5">
    <inertial>
      <mass value="0.5354311012721493" />
      <origin rpy="0 0 0" xyz="1.2341  -0.00164  0.00948" />
      <inertia ixx="1.178456285520773" ixy="-0.9801541682642012" ixz="-0.006926987892903752" iyy="0.8156960015022829" iyz="-0.008326458123108007" izz="1.993958786942289" />
    </inertial>
    <collision name="motor5_collision">
      <origin rpy="0 0 0" xyz="1.2341  -0.00164  0.00948" />
      <geometry>
        <mesh filename="package://robots/VRpuppet/meshes/collisions/motor5.stl" scale="0.001 0.001 0.001" />
      </geometry>
    </collision>
    <visual name="motor5_visual">
      <origin rpy="0 0 0" xyz="1.2341  -0.00164  0.00948" />
      <geometry>
        <mesh filename="package://robots/VRpuppet/meshes/visuals/motor5.stl" scale="0.001 0.001 0.001" />
      </geometry>
    </visual>
  </link>
  <link name="motor6">
    <inertial>
      <mass value="0.5354312076774133" />
      <origin rpy="0 0 0" xyz="-1.2341   0.00164  0.00948" />
      <inertia ixx="1.1784565214064806" ixy="-0.9801543652771041" ixz="0.006926989466895778" iyy="0.815696166081162" iyz="0.008326460007537074" izz="1.9939591873762894" />
    </inertial>
    <collision name="motor6_collision">
      <origin rpy="0 0 0" xyz="-1.2341   0.00164  0.00948" />
      <geometry>
        <mesh filename="package://robots/VRpuppet/meshes/collisions/motor6.stl" scale="0.001 0.001 0.001" />
      </geometry>
    </collision>
    <visual name="motor6_visual">
      <origin rpy="0 0 0" xyz="-1.2341   0.00164  0.00948" />
      <geometry>
        <mesh filename="package://robots/VRpuppet/meshes/visuals/motor6.stl" scale="0.001 0.001 0.001" />
      </geometry>
    </visual>
  </link>
  <link name="motor7">
    <inertial>
      <mass value="0.5354311012720704" />
      <origin rpy="0 0 0" xyz="1.2341  0.00164 0.00951" />
      <inertia ixx="1.1784566615905638" ixy="0.9801541682640568" ixz="-0.00694930679738674" iyy="0.8156963775721262" iyz="0.008352519774264891" izz="1.993958786941995" />
    </inertial>
    <collision name="motor7_collision">
      <origin rpy="0 0 0" xyz="1.2341  0.00164 0.00951" />
      <geometry>
        <mesh filename="package://robots/VRpuppet/meshes/collisions/motor7.stl" scale="0.001 0.001 0.001" />
      </geometry>
    </collision>
    <visual name="motor7_visual">
      <origin rpy="0 0 0" xyz="1.2341  0.00164 0.00951" />
      <geometry>
        <mesh filename="package://robots/VRpuppet/meshes/visuals/motor7.stl" scale="0.001 0.001 0.001" />
      </geometry>
    </visual>
  </link>
  <link name="motor1">
    <inertial>
      <mass value="0.5354312076774133" />
      <origin rpy="0 0 0" xyz="-0.00164 -1.2341   0.00948" />
      <inertia ixx="0.8156961660811622" ixy="0.9801543652771049" ixz="-0.008326460007537078" iyy="1.1784565214064817" iyz="0.00692698946689578" izz="1.9939591873762907" />
    </inertial>
    <collision name="motor1_collision">
      <origin rpy="0 0 0" xyz="-0.00164 -1.2341   0.00948" />
      <geometry>
        <mesh filename="package://robots/VRpuppet/meshes/collisions/motor1.stl" scale="0.001 0.001 0.001" />
      </geometry>
    </collision>
    <visual name="motor1_visual">
      <origin rpy="0 0 0" xyz="-0.00164 -1.2341   0.00948" />
      <geometry>
        <mesh filename="package://robots/VRpuppet/meshes/visuals/motor1.stl" scale="0.001 0.001 0.001" />
      </geometry>
    </visual>
  </link>
  <link name="motor11">
    <inertial>
      <mass value="0.540728915658689" />
      <origin rpy="0 0 0" xyz="1.19000e-03 -1.23423e+00  9.51000e-03" />
      <inertia ixx="1.3760540653848898" ixy="-0.9902621278821995" ixz="0.8107722932610368" iyy="1.7429368845367943" iyz="0.6744076770188961" izz="2.0145909271886877" />
    </inertial>
    <collision name="motor11_collision">
      <origin rpy="0 0 0" xyz="1.19000e-03 -1.23423e+00  9.51000e-03" />
      <geometry>
        <mesh filename="package://robots/VRpuppet/meshes/collisions/motor11.stl" scale="0.001 0.001 0.001" />
      </geometry>
    </collision>
    <visual name="motor11_visual">
      <origin rpy="0 0 0" xyz="1.19000e-03 -1.23423e+00  9.51000e-03" />
      <geometry>
        <mesh filename="package://robots/VRpuppet/meshes/visuals/motor11.stl" scale="0.001 0.001 0.001" />
      </geometry>
    </visual>
  </link>
  <link name="motor10">
    <inertial>
      <mass value="0.5407288092535038" />
      <origin rpy="0 0 0" xyz="1.19000e-03 1.23423e+00 9.48000e-03" />
      <inertia ixx="1.3760176002125752" ixy="0.99026193086944" ixz="0.8107460717445298" iyy="1.7429003480577039" iyz="-0.6743852245854303" izz="2.0145905267549784" />
    </inertial>
    <collision name="motor10_collision">
      <origin rpy="0 0 0" xyz="1.19000e-03 1.23423e+00 9.48000e-03" />
      <geometry>
        <mesh filename="package://robots/VRpuppet/meshes/collisions/motor10.stl" scale="0.001 0.001 0.001" />
      </geometry>
    </collision>
    <visual name="motor10_visual">
      <origin rpy="0 0 0" xyz="1.19000e-03 1.23423e+00 9.48000e-03" />
      <geometry>
        <mesh filename="package://robots/VRpuppet/meshes/visuals/motor10.stl" scale="0.001 0.001 0.001" />
      </geometry>
    </visual>
  </link>
  <link name="motor8">
    <inertial>
      <mass value="0.5407288092534246" />
      <origin rpy="0 0 0" xyz="-1.19000e-03  1.23423e+00  9.51000e-03" />
      <inertia ixx="1.3760537924693779" ixy="-0.9902619308692957" ixz="-0.8107721333955696" iyy="1.7429365403144546" iyz="-0.6744075434898156" izz="2.014590526754685" />
    </inertial>
    <collision name="motor8_collision">
      <origin rpy="0 0 0" xyz="-1.19000e-03  1.23423e+00  9.51000e-03" />
      <geometry>
        <mesh filename="package://robots/VRpuppet/meshes/collisions/motor8.stl" scale="0.001 0.001 0.001" />
      </geometry>
    </collision>
    <visual name="motor8_visual">
      <origin rpy="0 0 0" xyz="-1.19000e-03  1.23423e+00  9.51000e-03" />
      <geometry>
        <mesh filename="package://robots/VRpuppet/meshes/visuals/motor8.stl" scale="0.001 0.001 0.001" />
      </geometry>
    </visual>
  </link>
  <link name="motor12">
    <inertial>
      <mass value="0.5407289156586891" />
      <origin rpy="0 0 0" xyz="-1.23423e+00 -1.19000e-03  9.51000e-03" />
      <inertia ixx="1.7429368845367943" ixy="0.9902621278821994" ixz="0.6744076770188963" iyy="1.3760540653848898" iyz="-0.810772293261037" izz="2.0145909271886873" />
    </inertial>
    <collision name="motor12_collision">
      <origin rpy="0 0 0" xyz="-1.23423e+00 -1.19000e-03  9.51000e-03" />
      <geometry>
        <mesh filename="package://robots/VRpuppet/meshes/collisions/motor12.stl" scale="0.001 0.001 0.001" />
      </geometry>
    </collision>
    <visual name="motor12_visual">
      <origin rpy="0 0 0" xyz="-1.23423e+00 -1.19000e-03  9.51000e-03" />
      <geometry>
        <mesh filename="package://robots/VRpuppet/meshes/visuals/motor12.stl" scale="0.001 0.001 0.001" />
      </geometry>
    </visual>
  </link>
  <link name="motor13">
    <inertial>
      <mass value="0.5407288092535051" />
      <origin rpy="0 0 0" xyz="1.23423e+00 -1.19000e-03  9.48000e-03" />
      <inertia ixx="1.7429003480577074" ixy="-0.9902619308694421" ixz="-0.6743852245854316" iyy="1.3760176002125781" iyz="-0.8107460717445316" izz="2.0145905267549824" />
    </inertial>
    <collision name="motor13_collision">
      <origin rpy="0 0 0" xyz="1.23423e+00 -1.19000e-03  9.48000e-03" />
      <geometry>
        <mesh filename="package://robots/VRpuppet/meshes/collisions/motor13.stl" scale="0.001 0.001 0.001" />
      </geometry>
    </collision>
    <visual name="motor13_visual">
      <origin rpy="0 0 0" xyz="1.23423e+00 -1.19000e-03  9.48000e-03" />
      <geometry>
        <mesh filename="package://robots/VRpuppet/meshes/visuals/motor13.stl" scale="0.001 0.001 0.001" />
      </geometry>
    </visual>
  </link>
  <link name="motor14">
    <inertial>
      <mass value="0.5407289156587678" />
      <origin rpy="0 0 0" xyz="-1.23423e+00  1.19000e-03  9.48000e-03" />
      <inertia ixx="1.742900692880094" ixy="-0.9902621278823432" ixz="0.6743853584836851" iyy="1.3760178737281379" iyz="0.8107462320519715" izz="2.0145909271889795" />
    </inertial>
    <collision name="motor14_collision">
      <origin rpy="0 0 0" xyz="-1.23423e+00  1.19000e-03  9.48000e-03" />
      <geometry>
        <mesh filename="package://robots/VRpuppet/meshes/collisions/motor14.stl" scale="0.001 0.001 0.001" />
      </geometry>
    </collision>
    <visual name="motor14_visual">
      <origin rpy="0 0 0" xyz="-1.23423e+00  1.19000e-03  9.48000e-03" />
      <geometry>
        <mesh filename="package://robots/VRpuppet/meshes/visuals/motor14.stl" scale="0.001 0.001 0.001" />
      </geometry>
    </visual>
  </link>
  <link name="motor15">
    <inertial>
      <mass value="0.5407288092534249" />
      <origin rpy="0 0 0" xyz="1.23423e+00 1.19000e-03 9.51000e-03" />
      <inertia ixx="1.7429365403144548" ixy="0.9902619308692958" ixz="-0.6744075434898158" iyy="1.376053792469379" iyz="0.81077213339557" izz="2.0145905267546853" />
    </inertial>
    <collision name="motor15_collision">
      <origin rpy="0 0 0" xyz="1.23423e+00 1.19000e-03 9.51000e-03" />
      <geometry>
        <mesh filename="package://robots/VRpuppet/meshes/collisions/motor15.stl" scale="0.001 0.001 0.001" />
      </geometry>
    </collision>
    <visual name="motor15_visual">
      <origin rpy="0 0 0" xyz="1.23423e+00 1.19000e-03 9.51000e-03" />
      <geometry>
        <mesh filename="package://robots/VRpuppet/meshes/visuals/motor15.stl" scale="0.001 0.001 0.001" />
      </geometry>
    </visual>
  </link>
  <link name="motor9">
    <inertial>
      <mass value="0.5915182656350185" />
      <origin rpy="0 0 0" xyz="3.30000e-04 -1.23581e+00  9.48000e-03" />
      <inertia ixx="1.5075636020635315" ixy="1.085791131251597" ixz="-0.8878154774061241" iyy="1.909309332296448" iyz="0.7386693790802477" izz="2.2088182211992584" />
    </inertial>
    <collision name="motor9_collision">
      <origin rpy="0 0 0" xyz="3.30000e-04 -1.23581e+00  9.48000e-03" />
      <geometry>
        <mesh filename="package://robots/VRpuppet/meshes/collisions/motor9.stl" scale="0.001 0.001 0.001" />
      </geometry>
    </collision>
    <visual name="motor9_visual">
      <origin rpy="0 0 0" xyz="3.30000e-04 -1.23581e+00  9.48000e-03" />
      <geometry>
        <mesh filename="package://robots/VRpuppet/meshes/visuals/motor9.stl" scale="0.001 0.001 0.001" />
      </geometry>
    </visual>
  </link>
  <link name="motor19">
    <inertial>
      <mass value="0.5407289156586891" />
      <origin rpy="0 0 0" xyz="1.19000e-03 -1.23423e+00  9.51000e-03" />
      <inertia ixx="3.009614027386401" ixy="-0.9902621278821997" ixz="1.6131070410655353" iyy="3.3764968465383065" iyz="1.3417966109637172" izz="2.0145909271886877" />
    </inertial>
    <collision name="motor19_collision">
      <origin rpy="0 0 0" xyz="1.19000e-03 -1.23423e+00  9.51000e-03" />
      <geometry>
        <mesh filename="package://robots/VRpuppet/meshes/collisions/motor19.stl" scale="0.001 0.001 0.001" />
      </geometry>
    </collision>
    <visual name="motor19_visual">
      <origin rpy="0 0 0" xyz="1.19000e-03 -1.23423e+00  9.51000e-03" />
      <geometry>
        <mesh filename="package://robots/VRpuppet/meshes/visuals/motor19.stl" scale="0.001 0.001 0.001" />
      </geometry>
    </visual>
  </link>
  <link name="motor18">
    <inertial>
      <mass value="0.5407288092535049" />
      <origin rpy="0 0 0" xyz="1.19000e-03 1.23423e+00 9.48000e-03" />
      <inertia ixx="3.009541424873896" ixy="0.9902619308694421" ixz="1.6130806611261352" iyy="3.3764241727190254" iyz="-1.3417740262060884" izz="2.0145905267549824" />
    </inertial>
    <collision name="motor18_collision">
      <origin rpy="0 0 0" xyz="1.19000e-03 1.23423e+00 9.48000e-03" />
      <geometry>
        <mesh filename="package://robots/VRpuppet/meshes/collisions/motor18.stl" scale="0.001 0.001 0.001" />
      </geometry>
    </collision>
    <visual name="motor18_visual">
      <origin rpy="0 0 0" xyz="1.19000e-03 1.23423e+00 9.48000e-03" />
      <geometry>
        <mesh filename="package://robots/VRpuppet/meshes/visuals/motor18.stl" scale="0.001 0.001 0.001" />
      </geometry>
    </visual>
  </link>
  <link name="motor16">
    <inertial>
      <mass value="0.5407288092534246" />
      <origin rpy="0 0 0" xyz="-1.19000e-03  1.23423e+00  9.51000e-03" />
      <inertia ixx="3.0096134333174938" ixy="-0.9902619308692957" ixz="-1.6131067227770544" iyy="3.3764961811625707" iyz="-1.3417963451103734" izz="2.014590526754685" />
    </inertial>
    <collision name="motor16_collision">
      <origin rpy="0 0 0" xyz="-1.19000e-03  1.23423e+00  9.51000e-03" />
      <geometry>
        <mesh filename="package://robots/VRpuppet/meshes/collisions/motor16.stl" scale="0.001 0.001 0.001" />
      </geometry>
    </collision>
    <visual name="motor16_visual">
      <origin rpy="0 0 0" xyz="-1.19000e-03  1.23423e+00  9.51000e-03" />
      <geometry>
        <mesh filename="package://robots/VRpuppet/meshes/visuals/motor16.stl" scale="0.001 0.001 0.001" />
      </geometry>
    </visual>
  </link>
  <link name="motor20">
    <inertial>
      <mass value="0.540728915658689" />
      <origin rpy="0 0 0" xyz="-1.23423e+00 -1.19000e-03  9.51000e-03" />
      <inertia ixx="3.3764968465383056" ixy="0.9902621278821991" ixz="1.3417966109637167" iyy="3.0096140273864003" iyz="-1.613107041065535" izz="2.0145909271886864" />
    </inertial>
    <collision name="motor20_collision">
      <origin rpy="0 0 0" xyz="-1.23423e+00 -1.19000e-03  9.51000e-03" />
      <geometry>
        <mesh filename="package://robots/VRpuppet/meshes/collisions/motor20.stl" scale="0.001 0.001 0.001" />
      </geometry>
    </collision>
    <visual name="motor20_visual">
      <origin rpy="0 0 0" xyz="-1.23423e+00 -1.19000e-03  9.51000e-03" />
      <geometry>
        <mesh filename="package://robots/VRpuppet/meshes/visuals/motor20.stl" scale="0.001 0.001 0.001" />
      </geometry>
    </visual>
  </link>
  <link name="motor21">
    <inertial>
      <mass value="0.540728809253504" />
      <origin rpy="0 0 0" xyz="1.23423e+00 -1.19000e-03  9.48000e-03" />
      <inertia ixx="3.3764241727190205" ixy="-0.9902619308694405" ixz="-1.3417740262060864" iyy="3.009541424873891" iyz="-1.6130806611261326" izz="2.0145905267549797" />
    </inertial>
    <collision name="motor21_collision">
      <origin rpy="0 0 0" xyz="1.23423e+00 -1.19000e-03  9.48000e-03" />
      <geometry>
        <mesh filename="package://robots/VRpuppet/meshes/collisions/motor21.stl" scale="0.001 0.001 0.001" />
      </geometry>
    </collision>
    <visual name="motor21_visual">
      <origin rpy="0 0 0" xyz="1.23423e+00 -1.19000e-03  9.48000e-03" />
      <geometry>
        <mesh filename="package://robots/VRpuppet/meshes/visuals/motor21.stl" scale="0.001 0.001 0.001" />
      </geometry>
    </visual>
  </link>
  <link name="motor22">
    <inertial>
      <mass value="0.5407289156587689" />
      <origin rpy="0 0 0" xyz="-1.23423e+00  1.19000e-03  9.48000e-03" />
      <inertia ixx="3.376424839288627" ixy="-0.9902621278823452" ixz="1.3417742924286062" iyy="3.00954202013667" iyz="1.6130809798565893" izz="2.0145909271889835" />
    </inertial>
    <collision name="motor22_collision">
      <origin rpy="0 0 0" xyz="-1.23423e+00  1.19000e-03  9.48000e-03" />
      <geometry>
        <mesh filename="package://robots/VRpuppet/meshes/collisions/motor22.stl" scale="0.001 0.001 0.001" />
      </geometry>
    </collision>
    <visual name="motor22_visual">
      <origin rpy="0 0 0" xyz="-1.23423e+00  1.19000e-03  9.48000e-03" />
      <geometry>
        <mesh filename="package://robots/VRpuppet/meshes/visuals/motor22.stl" scale="0.001 0.001 0.001" />
      </geometry>
    </visual>
  </link>
  <link name="motor23">
    <inertial>
      <mass value="0.5407288092534249" />
      <origin rpy="0 0 0" xyz="1.23423e+00 1.19000e-03 9.51000e-03" />
      <inertia ixx="3.376496181162572" ixy="0.9902619308692958" ixz="-1.3417963451103738" iyy="3.0096134333174955" iyz="1.6131067227770552" izz="2.0145905267546853" />
    </inertial>
    <collision name="motor23_collision">
      <origin rpy="0 0 0" xyz="1.23423e+00 1.19000e-03 9.51000e-03" />
      <geometry>
        <mesh filename="package://robots/VRpuppet/meshes/collisions/motor23.stl" scale="0.001 0.001 0.001" />
      </geometry>
    </collision>
    <visual name="motor23_visual">
      <origin rpy="0 0 0" xyz="1.23423e+00 1.19000e-03 9.51000e-03" />
      <geometry>
        <mesh filename="package://robots/VRpuppet/meshes/visuals/motor23.stl" scale="0.001 0.001 0.001" />
      </geometry>
    </visual>
  </link>
  <link name="motor17">
    <inertial>
      <mass value="0.5407289156587689" />
      <origin rpy="0 0 0" xyz="-1.19000e-03 -1.23423e+00  9.48000e-03" />
      <inertia ixx="3.0095420201366694" ixy="0.9902621278823456" ixz="-1.6130809798565902" iyy="3.376424839288629" iyz="1.341774292428606" izz="2.014590927188985" />
    </inertial>
    <collision name="motor17_collision">
      <origin rpy="0 0 0" xyz="-1.19000e-03 -1.23423e+00  9.48000e-03" />
      <geometry>
        <mesh filename="package://robots/VRpuppet/meshes/collisions/motor17.stl" scale="0.001 0.001 0.001" />
      </geometry>
    </collision>
    <visual name="motor17_visual">
      <origin rpy="0 0 0" xyz="-1.19000e-03 -1.23423e+00  9.48000e-03" />
      <geometry>
        <mesh filename="package://robots/VRpuppet/meshes/visuals/motor17.stl" scale="0.001 0.001 0.001" />
      </geometry>
    </visual>
  </link>
  <link name="neck_link1">
    <inertial>
      <mass value="0.06979037783542182" />
      <origin rpy="0 0 0" xyz="0 0 0" />
      <inertia ixx="0.1809198577960802" ixy="-4.542072684547092e-06" ixz="0.0033945845073235633" iyy="0.1809832304363084" iyz="0.00024206107360706246" izz="7.566768967812972e-05" />
    </inertial>
    <collision name="neck_link1_collision">
      <origin rpy="0 0 0" xyz="0 0 0" />
      <geometry>
        <mesh filename="package://robots/VRpuppet/meshes/collisions/neck_link1.stl" scale="0.001 0.001 0.001" />
      </geometry>
    </collision>
    <visual name="neck_link1_visual">
      <origin rpy="0 0 0" xyz="0 0 0" />
      <geometry>
        <mesh filename="package://robots/VRpuppet/meshes/visuals/neck_link1.stl" scale="0.001 0.001 0.001" />
      </geometry>
    </visual>
  </link>
  <link name="neck_link2">
    <inertial>
      <mass value="0.04678255602502142" />
      <origin rpy="0 0 0" xyz="0 0 0" />
      <inertia ixx="0.12127338974092727" ixy="-3.044685735890851e-06" ixz="0.0022754904719635917" iyy="0.12131587029742415" iyz="0.00016226070115084863" izz="4.817621074330742e-05" />
    </inertial>
    <collision name="neck_link2_collision">
      <origin rpy="0 0 0" xyz="0 0 0" />
      <geometry>
        <mesh filename="package://robots/VRpuppet/meshes/collisions/neck_link2.stl" scale="0.001 0.001 0.001" />
      </geometry>
    </collision>
    <visual name="neck_link2_visual">
      <origin rpy="0 0 0" xyz="0 0 0" />
      <geometry>
        <mesh filename="package://robots/VRpuppet/meshes/visuals/neck_link2.stl" scale="0.001 0.001 0.001" />
      </geometry>
    </visual>
  </link>
  <link name="ankle_right_link1">
    <inertial>
      <mass value="0.06979037783542485" />
      <origin rpy="0 0 0" xyz="0 0 0" />
      <inertia ixx="0.0019245011944293432" ixy="-0.0002630040199617997" ixz="0.0002394887786265198" iyy="0.0009448988338829647" iyz="0.0009522470098621112" izz="0.0011235399170855089" />
    </inertial>
    <collision name="ankle_right_link1_collision">
      <origin rpy="0 0 0" xyz="0 0 0" />
      <geometry>
        <mesh filename="package://robots/VRpuppet/meshes/collisions/ankle_right_link1.stl" scale="0.001 0.001 0.001" />
      </geometry>
    </collision>
    <visual name="ankle_right_link1_visual">
      <origin rpy="0 0 0" xyz="0 0 0" />
      <geometry>
        <mesh filename="package://robots/VRpuppet/meshes/visuals/ankle_right_link1.stl" scale="0.001 0.001 0.001" />
      </geometry>
    </visual>
  </link>
  <link name="ankle_right_link2">
    <inertial>
      <mass value="0.046782556025021446" />
      <origin rpy="0 0 0" xyz="0 0 0" />
      <inertia ixx="0.0012875040333462835" ixy="-0.00017629937924279254" ixz="0.00016053641697158822" iyy="0.0006308475754659841" iyz="0.0006383193566728546" izz="0.0007505959810860087" />
    </inertial>
    <collision name="ankle_right_link2_collision">
      <origin rpy="0 0 0" xyz="0 0 0" />
      <geometry>
        <mesh filename="package://robots/VRpuppet/meshes/collisions/ankle_right_link2.stl" scale="0.001 0.001 0.001" />
      </geometry>
    </collision>
    <visual name="ankle_right_link2_visual">
      <origin rpy="0 0 0" xyz="0 0 0" />
      <geometry>
        <mesh filename="package://robots/VRpuppet/meshes/visuals/ankle_right_link2.stl" scale="0.001 0.001 0.001" />
      </geometry>
    </visual>
  </link>
  <link name="knee_right_link1">
    <inertial>
      <mass value="0.0697903778354249" />
      <origin rpy="0 0 0" xyz="0 0 0" />
      <inertia ixx="0.015965914179044468" ixy="-0.00022913812110194966" ixz="0.0009766365711272257" iyy="0.015196585914201251" iyz="0.0035478860924073184" izz="0.0009071265304925711" />
    </inertial>
    <collision name="knee_right_link1_collision">
      <origin rpy="0 0 0" xyz="0 0 0" />
      <geometry>
        <mesh filename="package://robots/VRpuppet/meshes/collisions/knee_right_link1.stl" scale="0.001 0.001 0.001" />
      </geometry>
    </collision>
    <visual name="knee_right_link1_visual">
      <origin rpy="0 0 0" xyz="0 0 0" />
      <geometry>
        <mesh filename="package://robots/VRpuppet/meshes/visuals/knee_right_link1.stl" scale="0.001 0.001 0.001" />
      </geometry>
    </visual>
  </link>
  <link name="knee_right_link2">
    <inertial>
      <mass value="0.046782556025021425" />
      <origin rpy="0 0 0" xyz="0 0 0" />
      <inertia ixx="0.010699878776091546" ixy="-0.00015359806483449144" ixz="0.0006546684012049039" iyy="0.010184175268552753" iyz="0.002378253063079667" izz="0.0006055276823434818" />
    </inertial>
    <collision name="knee_right_link2_collision">
      <origin rpy="0 0 0" xyz="0 0 0" />
      <geometry>
        <mesh filename="package://robots/VRpuppet/meshes/collisions/knee_right_link2.stl" scale="0.001 0.001 0.001" />
      </geometry>
    </collision>
    <visual name="knee_right_link2_visual">
      <origin rpy="0 0 0" xyz="0 0 0" />
      <geometry>
        <mesh filename="package://robots/VRpuppet/meshes/visuals/knee_right_link2.stl" scale="0.001 0.001 0.001" />
      </geometry>
    </visual>
  </link>
  <link name="wrist_right_link1">
    <inertial>
      <mass value="0.06979037783542315" />
      <origin rpy="0 0 0" xyz="0 0 0" />
      <inertia ixx="0.05753723714569883" ixy="-0.0017824877678100535" ixz="0.0058940712455224" iyy="0.053376050432351635" iyz="0.01593915061452127" izz="0.005491111250237795" />
    </inertial>
    <collision name="wrist_right_link1_collision">
      <origin rpy="0 0 0" xyz="0 0 0" />
      <geometry>
        <mesh filename="package://robots/VRpuppet/meshes/collisions/wrist_right_link1.stl" scale="0.001 0.001 0.001" />
      </geometry>
    </collision>
    <visual name="wrist_right_link1_visual">
      <origin rpy="0 0 0" xyz="0 0 0" />
      <geometry>
        <mesh filename="package://robots/VRpuppet/meshes/visuals/wrist_right_link1.stl" scale="0.001 0.001 0.001" />
      </geometry>
    </visual>
  </link>
  <link name="wrist_right_link2">
    <inertial>
      <mass value="0.046782556025034956" />
      <origin rpy="0 0 0" xyz="0 0 0" />
      <inertia ixx="0.038566367051744425" ixy="-0.0011948543112435836" ixz="0.003950970416830831" iyy="0.03577700042892654" iyz="0.010684484447436892" izz="0.0036783083233753516" />
    </inertial>
    <collision name="wrist_right_link2_collision">
      <origin rpy="0 0 0" xyz="0 0 0" />
      <geometry>
        <mesh filename="package://robots/VRpuppet/meshes/collisions/wrist_right_link2.stl" scale="0.001 0.001 0.001" />
      </geometry>
    </collision>
    <visual name="wrist_right_link2_visual">
      <origin rpy="0 0 0" xyz="0 0 0" />
      <geometry>
        <mesh filename="package://robots/VRpuppet/meshes/visuals/wrist_right_link2.stl" scale="0.001 0.001 0.001" />
      </geometry>
    </visual>
  </link>
  <link name="shoulder_left_link1">
    <inertial>
      <mass value="0.0697903778354231" />
      <origin rpy="0 0 0" xyz="0 0 0" />
      <inertia ixx="0.13921241902852993" ixy="0.0006339772072438079" ixz="0.004778402767111253" iyy="0.13697139957424642" iyz="-0.01814906434902278" izz="0.002586501950999001" />
    </inertial>
    <collision name="shoulder_left_link1_collision">
      <origin rpy="0 0 0" xyz="0 0 0" />
      <geometry>
        <mesh filename="package://robots/VRpuppet/meshes/collisions/shoulder_left_link1.stl" scale="0.001 0.001 0.001" />
      </geometry>
    </collision>
    <visual name="shoulder_left_link1_visual">
      <origin rpy="0 0 0" xyz="0 0 0" />
      <geometry>
        <mesh filename="package://robots/VRpuppet/meshes/visuals/shoulder_left_link1.stl" scale="0.001 0.001 0.001" />
      </geometry>
    </visual>
  </link>
  <link name="shoulder_left_link2">
    <inertial>
      <mass value="0.04678255602503103" />
      <origin rpy="0 0 0" xyz="0 0 0" />
      <inertia ixx="0.0933156590150584" ixy="0.0004249736873216092" ixz="0.0032031048120405516" iyy="0.09181343734134118" iyz="-0.012165855038011845" izz="0.0017312627358952296" />
    </inertial>
    <collision name="shoulder_left_link2_collision">
      <origin rpy="0 0 0" xyz="0 0 0" />
      <geometry>
        <mesh filename="package://robots/VRpuppet/meshes/collisions/shoulder_left_link2.stl" scale="0.001 0.001 0.001" />
      </geometry>
    </collision>
    <visual name="shoulder_left_link2_visual">
      <origin rpy="0 0 0" xyz="0 0 0" />
      <geometry>
        <mesh filename="package://robots/VRpuppet/meshes/visuals/shoulder_left_link2.stl" scale="0.001 0.001 0.001" />
      </geometry>
    </visual>
  </link>
  <link name="elbow_right_link1">
    <inertial>
      <mass value="0.06979037783542313" />
      <origin rpy="0 0 0" xyz="0 0 0" />
      <inertia ixx="0.0934936422088936" ixy="-0.001660527248588653" ixz="0.008740952190120837" iyy="0.09108429556020144" iyz="0.01714029064816496" izz="0.004114616232233811" />
    </inertial>
    <collision name="elbow_right_link1_collision">
      <origin rpy="0 0 0" xyz="0 0 0" />
      <geometry>
        <mesh filename="package://robots/VRpuppet/meshes/collisions/elbow_right_link1.stl" scale="0.001 0.001 0.001" />
      </geometry>
    </collision>
    <visual name="elbow_right_link1_visual">
      <origin rpy="0 0 0" xyz="0 0 0" />
      <geometry>
        <mesh filename="package://robots/VRpuppet/meshes/visuals/elbow_right_link1.stl" scale="0.001 0.001 0.001" />
      </geometry>
    </visual>
  </link>
  <link name="elbow_right_link2">
    <inertial>
      <mass value="0.04678255602503495" />
      <origin rpy="0 0 0" xyz="0 0 0" />
      <inertia ixx="0.06266900965815193" ixy="-0.0011131005652651998" ixz="0.005859318980085708" iyy="0.061053953284201525" iyz="0.011489644164931511" izz="0.0027556029692682293" />
    </inertial>
    <collision name="elbow_right_link2_collision">
      <origin rpy="0 0 0" xyz="0 0 0" />
      <geometry>
        <mesh filename="package://robots/VRpuppet/meshes/collisions/elbow_right_link2.stl" scale="0.001 0.001 0.001" />
      </geometry>
    </collision>
    <visual name="elbow_right_link2_visual">
      <origin rpy="0 0 0" xyz="0 0 0" />
      <geometry>
        <mesh filename="package://robots/VRpuppet/meshes/visuals/elbow_right_link2.stl" scale="0.001 0.001 0.001" />
      </geometry>
    </visual>
  </link>
  <link name="shoulder_right_link1">
    <inertial>
      <mass value="0.06979037783542312" />
      <origin rpy="0 0 0" xyz="0 0 0" />
      <inertia ixx="0.13902613917927265" ixy="-0.0010056854983776684" ixz="0.007891423245213683" iyy="0.13725972920730342" iyz="0.01743292253525537" izz="0.002688551734802003" />
    </inertial>
    <collision name="shoulder_right_link1_collision">
      <origin rpy="0 0 0" xyz="0 0 0" />
      <geometry>
        <mesh filename="package://robots/VRpuppet/meshes/collisions/shoulder_right_link1.stl" scale="0.001 0.001 0.001" />
      </geometry>
    </collision>
    <visual name="shoulder_right_link1_visual">
      <origin rpy="0 0 0" xyz="0 0 0" />
      <geometry>
        <mesh filename="package://robots/VRpuppet/meshes/visuals/shoulder_right_link1.stl" scale="0.001 0.001 0.001" />
      </geometry>
    </visual>
  </link>
  <link name="shoulder_right_link2">
    <inertial>
      <mass value="0.04678255602503495" />
      <origin rpy="0 0 0" xyz="0 0 0" />
      <inertia ixx="0.09319079011769002" ixy="-0.0006741407571522098" ixz="0.005289854582436727" iyy="0.09200671322875241" iyz="0.011685803980387287" izz="0.0017996697259244627" />
    </inertial>
    <collision name="shoulder_right_link2_collision">
      <origin rpy="0 0 0" xyz="0 0 0" />
      <geometry>
        <mesh filename="package://robots/VRpuppet/meshes/collisions/shoulder_right_link2.stl" scale="0.001 0.001 0.001" />
      </geometry>
    </collision>
    <visual name="shoulder_right_link2_visual">
      <origin rpy="0 0 0" xyz="0 0 0" />
      <geometry>
        <mesh filename="package://robots/VRpuppet/meshes/visuals/shoulder_right_link2.stl" scale="0.001 0.001 0.001" />
      </geometry>
    </visual>
  </link>
  <link name="knee_left_link1">
    <inertial>
      <mass value="0.06979037783542481" />
      <origin rpy="0 0 0" xyz="0 0 0" />
      <inertia ixx="0.01595946997615608" ixy="8.344389583585825e-05" ixz="0.00035704078835077944" iyy="0.015141940474037626" iyz="-0.0035341261112977734" izz="0.0008460368874405992" />
    </inertial>
    <collision name="knee_left_link1_collision">
      <origin rpy="0 0 0" xyz="0 0 0" />
      <geometry>
        <mesh filename="package://robots/VRpuppet/meshes/collisions/knee_left_link1.stl" scale="0.001 0.001 0.001" />
      </geometry>
    </collision>
    <visual name="knee_left_link1_visual">
      <origin rpy="0 0 0" xyz="0 0 0" />
      <geometry>
        <mesh filename="package://robots/VRpuppet/meshes/visuals/knee_left_link1.stl" scale="0.001 0.001 0.001" />
      </geometry>
    </visual>
  </link>
  <link name="knee_left_link2">
    <inertial>
      <mass value="0.046782556025046794" />
      <origin rpy="0 0 0" xyz="0 0 0" />
      <inertia ixx="0.010695559036529741" ixy="5.5934913194482276e-05" ixz="0.0002393350082696423" iyy="0.010147544812570268" iyz="-0.0023690293412525084" izz="0.0005645774867881984" />
    </inertial>
    <collision name="knee_left_link2_collision">
      <origin rpy="0 0 0" xyz="0 0 0" />
      <geometry>
        <mesh filename="package://robots/VRpuppet/meshes/collisions/knee_left_link2.stl" scale="0.001 0.001 0.001" />
      </geometry>
    </collision>
    <visual name="knee_left_link2_visual">
      <origin rpy="0 0 0" xyz="0 0 0" />
      <geometry>
        <mesh filename="package://robots/VRpuppet/meshes/visuals/knee_left_link2.stl" scale="0.001 0.001 0.001" />
      </geometry>
    </visual>
  </link>
  <link name="elbow_left_link1">
    <inertial>
      <mass value="0.0697903778354231" />
      <origin rpy="0 0 0" xyz="0 0 0" />
      <inertia ixx="0.09386108056253778" ixy="0.001134169624769473" ixz="0.005659441522875583" iyy="0.0905924745003948" iyz="-0.018081537449965733" izz="0.00399023352606866" />
    </inertial>
    <collision name="elbow_left_link1_collision">
      <origin rpy="0 0 0" xyz="0 0 0" />
      <geometry>
        <mesh filename="package://robots/VRpuppet/meshes/collisions/elbow_left_link1.stl" scale="0.001 0.001 0.001" />
      </geometry>
    </collision>
    <visual name="elbow_left_link1_visual">
      <origin rpy="0 0 0" xyz="0 0 0" />
      <geometry>
        <mesh filename="package://robots/VRpuppet/meshes/visuals/elbow_left_link1.stl" scale="0.001 0.001 0.001" />
      </geometry>
    </visual>
  </link>
  <link name="elbow_left_link2">
    <inertial>
      <mass value="0.046782556025031015" />
      <origin rpy="0 0 0" xyz="0 0 0" />
      <inertia ixx="0.06291531446335553" ixy="0.0007602674702295211" ixz="0.003793691168582457" iyy="0.06072427107020524" iyz="-0.012120589758584321" izz="0.0026722255604843107" />
    </inertial>
    <collision name="elbow_left_link2_collision">
      <origin rpy="0 0 0" xyz="0 0 0" />
      <geometry>
        <mesh filename="package://robots/VRpuppet/meshes/collisions/elbow_left_link2.stl" scale="0.001 0.001 0.001" />
      </geometry>
    </collision>
    <visual name="elbow_left_link2_visual">
      <origin rpy="0 0 0" xyz="0 0 0" />
      <geometry>
        <mesh filename="package://robots/VRpuppet/meshes/visuals/elbow_left_link2.stl" scale="0.001 0.001 0.001" />
      </geometry>
    </visual>
  </link>
  <link name="wrist_left_link1">
    <inertial>
      <mass value="0.06979037783542305" />
      <origin rpy="0 0 0" xyz="0 0 0" />
      <inertia ixx="0.057869177372650134" ixy="0.0009560720302020307" ixz="0.0030578662925360538" iyy="0.05289432380005012" iyz="-0.016478820339463716" izz="0.005341324844885649" />
    </inertial>
    <collision name="wrist_left_link1_collision">
      <origin rpy="0 0 0" xyz="0 0 0" />
      <geometry>
        <mesh filename="package://robots/VRpuppet/meshes/collisions/wrist_left_link1.stl" scale="0.001 0.001 0.001" />
      </geometry>
    </collision>
    <visual name="wrist_left_link1_visual">
      <origin rpy="0 0 0" xyz="0 0 0" />
      <geometry>
        <mesh filename="package://robots/VRpuppet/meshes/visuals/wrist_left_link1.stl" scale="0.001 0.001 0.001" />
      </geometry>
    </visual>
  </link>
  <link name="wrist_left_link2">
    <inertial>
      <mass value="0.04678255602503101" />
      <origin rpy="0 0 0" xyz="0 0 0" />
      <inertia ixx="0.038788876412055716" ixy="0.0006408833809314679" ixz="0.0020497782865278114" iyy="0.035454084808492985" iyz="-0.011046241039521867" izz="0.0035779020632579653" />
    </inertial>
    <collision name="wrist_left_link2_collision">
      <origin rpy="0 0 0" xyz="0 0 0" />
      <geometry>
        <mesh filename="package://robots/VRpuppet/meshes/collisions/wrist_left_link2.stl" scale="0.001 0.001 0.001" />
      </geometry>
    </collision>
    <visual name="wrist_left_link2_visual">
      <origin rpy="0 0 0" xyz="0 0 0" />
      <geometry>
        <mesh filename="package://robots/VRpuppet/meshes/visuals/wrist_left_link2.stl" scale="0.001 0.001 0.001" />
      </geometry>
    </visual>
  </link>
  <link name="foot_left_link1">
    <inertial>
      <mass value="0.06979037783542483" />
      <origin rpy="0 0 0" xyz="0 0 0" />
      <inertia ixx="0.0019160003117788468" ixy="8.006711139542831e-05" ixz="7.32064499826225e-05" iyy="0.0008849342323485516" iyz="-0.0009483687035625753" izz="0.0010550744329006008" />
    </inertial>
    <collision name="foot_left_link1_collision">
      <origin rpy="0 0 0" xyz="0 0 0" />
      <geometry>
        <mesh filename="package://robots/VRpuppet/meshes/collisions/foot_left_link1.stl" scale="0.001 0.001 0.001" />
      </geometry>
    </collision>
    <visual name="foot_left_link1_visual">
      <origin rpy="0 0 0" xyz="0 0 0" />
      <geometry>
        <mesh filename="package://robots/VRpuppet/meshes/visuals/foot_left_link1.stl" scale="0.001 0.001 0.001" />
      </geometry>
    </visual>
  </link>
  <link name="foot_left_link2">
    <inertial>
      <mass value="0.0467825560250468" />
      <origin rpy="0 0 0" xyz="0 0 0" />
      <inertia ixx="0.00128180564050321" ixy="5.367135462023979e-05" ixz="4.907245020381618e-05" iyy="0.000590651528170771" iyz="-0.0006357196133557313" izz="0.0007047015409470922" />
    </inertial>
    <collision name="foot_left_link2_collision">
      <origin rpy="0 0 0" xyz="0 0 0" />
      <geometry>
        <mesh filename="package://robots/VRpuppet/meshes/collisions/foot_left_link2.stl" scale="0.001 0.001 0.001" />
      </geometry>
    </collision>
    <visual name="foot_left_link2_visual">
      <origin rpy="0 0 0" xyz="0 0 0" />
      <geometry>
        <mesh filename="package://robots/VRpuppet/meshes/visuals/foot_left_link2.stl" scale="0.001 0.001 0.001" />
      </geometry>
    </visual>
  </link>
  <link name="spine_sphere_link1">
    <inertial>
      <mass value="0.03806502733617433" />
      <origin rpy="0 0 0" xyz="0 0 0" />
      <inertia ixx="0.04040395348385381" ixy="-2.5851123855890627e-06" ixz="0.0007987565191239688" iyy="0.040419321949745485" iyz="0.00013075740172269605" izz="1.7893505613608954e-05" />
    </inertial>
    <collision name="spine_sphere_link1_collision">
      <origin rpy="0 0 0" xyz="0 0 0" />
      <geometry>
        <mesh filename="package://robots/VRpuppet/meshes/collisions/spine_sphere_link1.stl" scale="0.001 0.001 0.001" />
      </geometry>
    </collision>
    <visual name="spine_sphere_link1_visual">
      <origin rpy="0 0 0" xyz="0 0 0" />
      <geometry>
        <mesh filename="package://robots/VRpuppet/meshes/visuals/spine_sphere_link1.stl" scale="0.001 0.001 0.001" />
      </geometry>
    </visual>
  </link>
  <link name="spine_sphere_link2">
    <inertial>
      <mass value="0.002996372533177607" />
      <origin rpy="0 0 0" xyz="0 0 0" />
      <inertia ixx="0.0031803783911504586" ixy="-2.034928125593611e-07" ixz="6.287587978140801e-05" iyy="0.0031815881538093307" iyz="1.0292856790487888e-05" izz="1.3006573104353652e-06" />
    </inertial>
    <collision name="spine_sphere_link2_collision">
      <origin rpy="0 0 0" xyz="0 0 0" />
      <geometry>
        <mesh filename="package://robots/VRpuppet/meshes/collisions/spine_sphere_link2.stl" scale="0.001 0.001 0.001" />
      </geometry>
    </collision>
    <visual name="spine_sphere_link2_visual">
      <origin rpy="0 0 0" xyz="0 0 0" />
      <geometry>
        <mesh filename="package://robots/VRpuppet/meshes/visuals/spine_sphere_link2.stl" scale="0.001 0.001 0.001" />
      </geometry>
    </visual>
  </link>
  <link name="hip_left_sphere_link1">
    <inertial>
      <mass value="0.03806502733617433" />
      <origin rpy="0 0 0" xyz="0 0 0" />
      <inertia ixx="0.030987104968491903" ixy="4.581190834706321e-05" ixz="0.0004277113269835763" iyy="0.030641630600247754" iyz="-0.0032811875817166567" izz="0.00035909643853781" />
    </inertial>
    <collision name="hip_left_sphere_link1_collision">
      <origin rpy="0 0 0" xyz="0 0 0" />
      <geometry>
        <mesh filename="package://robots/VRpuppet/meshes/collisions/hip_left_sphere_link1.stl" scale="0.001 0.001 0.001" />
      </geometry>
    </collision>
    <visual name="hip_left_sphere_link1_visual">
      <origin rpy="0 0 0" xyz="0 0 0" />
      <geometry>
        <mesh filename="package://robots/VRpuppet/meshes/visuals/hip_left_sphere_link1.stl" scale="0.001 0.001 0.001" />
      </geometry>
    </visual>
  </link>
  <link name="hip_left_sphere_link2">
    <inertial>
      <mass value="0.002996372533177607" />
      <origin rpy="0 0 0" xyz="0 0 0" />
      <inertia ixx="0.002439110402846494" ixy="3.606185322902754e-06" ixz="3.366823963088628e-05" iyy="0.0024119156263578876" iyz="-0.00025828591346124965" izz="2.8159198351524762e-05" />
    </inertial>
    <collision name="hip_left_sphere_link2_collision">
      <origin rpy="0 0 0" xyz="0 0 0" />
      <geometry>
        <mesh filename="package://robots/VRpuppet/meshes/collisions/hip_left_sphere_link2.stl" scale="0.001 0.001 0.001" />
      </geometry>
    </collision>
    <visual name="hip_left_sphere_link2_visual">
      <origin rpy="0 0 0" xyz="0 0 0" />
      <geometry>
        <mesh filename="package://robots/VRpuppet/meshes/visuals/hip_left_sphere_link2.stl" scale="0.001 0.001 0.001" />
      </geometry>
    </visual>
  </link>
  <link name="hip_right_sphere_link1">
    <inertial>
      <mass value="0.038065027336174326" />
      <origin rpy="0 0 0" xyz="0 0 0" />
      <inertia ixx="0.031036549619113625" ixy="-0.00011684122684853358" ixz="0.001021374052680195" iyy="0.03066971274854031" iyz="0.003504408423215542" izz="0.00043662323749224925" />
    </inertial>
    <collision name="hip_right_sphere_link1_collision">
      <origin rpy="0 0 0" xyz="0 0 0" />
      <geometry>
        <mesh filename="package://robots/VRpuppet/meshes/collisions/hip_right_sphere_link1.stl" scale="0.001 0.001 0.001" />
      </geometry>
    </collision>
    <visual name="hip_right_sphere_link1_visual">
      <origin rpy="0 0 0" xyz="0 0 0" />
      <geometry>
        <mesh filename="package://robots/VRpuppet/meshes/visuals/hip_right_sphere_link1.stl" scale="0.001 0.001 0.001" />
      </geometry>
    </visual>
  </link>
  <link name="hip_right_sphere_link2">
    <inertial>
      <mass value="0.002996372533177607" />
      <origin rpy="0 0 0" xyz="0 0 0" />
      <inertia ixx="0.002443002547389655" ixy="-9.197414683155272e-06" ixz="8.039970968970905e-05" iyy="0.0024141261745513906" iyz="0.00027585723349759345" izz="3.426189109135013e-05" />
    </inertial>
    <collision name="hip_right_sphere_link2_collision">
      <origin rpy="0 0 0" xyz="0 0 0" />
      <geometry>
        <mesh filename="package://robots/VRpuppet/meshes/collisions/hip_right_sphere_link2.stl" scale="0.001 0.001 0.001" />
      </geometry>
    </collision>
    <visual name="hip_right_sphere_link2_visual">
      <origin rpy="0 0 0" xyz="0 0 0" />
      <geometry>
        <mesh filename="package://robots/VRpuppet/meshes/visuals/hip_right_sphere_link2.stl" scale="0.001 0.001 0.001" />
      </geometry>
    </visual>
  </link>
  <link name="lower_leg_right">
    <inertial>
      <mass value="27.22911787247933" />
      <origin rpy="0 0 0" xyz="-0.01758 -0.00328 -0.1373" />
      <inertia ixx="3.5579731242419097" ixy="-0.14332021627451483" ixz="0.41848033730353784" iyy="3.285422931495319" iyz="0.9974952828432662" izz="0.45288695207992324" />
    </inertial>
    <collision name="lower_leg_right_collision">
      <origin rpy="0 0 0" xyz="-0.01758 -0.00328 -0.1373" />
      <geometry>
        <mesh filename="package://robots/VRpuppet/meshes/collisions/lower_leg_right.stl" scale="0.001 0.001 0.001" />
      </geometry>
    </collision>
    <visual name="lower_leg_right_visual">
      <origin rpy="0 0 0" xyz="-0.01758 -0.00328 -0.1373" />
      <geometry>
        <mesh filename="package://robots/VRpuppet/meshes/visuals/lower_leg_right.stl" scale="0.001 0.001 0.001" />
      </geometry>
    </visual>
  </link>
  <link name="foot_right">
    <inertial>
      <mass value="0.2795712981996832" />
      <origin rpy="0 0 0" xyz="0      0     -0.0006" />
      <inertia ixx="0.007669426553180407" ixy="-0.0010535607179814883" ixz="0.0009541471208166398" iyy="0.0037452666563460853" iyz="0.0037938449303246287" izz="0.004496457668169397" />
    </inertial>
    <collision name="foot_right_collision">
      <origin rpy="0 0 0" xyz="0      0     -0.0006" />
      <geometry>
        <mesh filename="package://robots/VRpuppet/meshes/collisions/foot_right.stl" scale="0.001 0.001 0.001" />
      </geometry>
    </collision>
    <visual name="foot_right_visual">
      <origin rpy="0 0 0" xyz="0      0     -0.0006" />
      <geometry>
        <mesh filename="package://robots/VRpuppet/meshes/visuals/foot_right.stl" scale="0.001 0.001 0.001" />
      </geometry>
    </visual>
  </link>
  <link name="torso">
    <inertial>
      <mass value="2.0895139865867263" />
      <origin rpy="0 0 0" xyz="-0.00469  0.00059  0.31475" />
      <inertia ixx="3.953151182767228" ixy="-0.0006656008249198482" ixz="0.07119590305463287" iyy="3.9482728202691266" iyz="0.007666163374829815" izz="0.009024596759740145" />
    </inertial>
    <collision name="torso_collision">
      <origin rpy="0 0 0" xyz="-0.00469  0.00059  0.31475" />
      <geometry>
        <mesh filename="package://robots/VRpuppet/meshes/collisions/torso.stl" scale="0.001 0.001 0.001" />
      </geometry>
    </collision>
    <visual name="torso_visual">
      <origin rpy="0 0 0" xyz="-0.00469  0.00059  0.31475" />
      <geometry>
        <mesh filename="package://robots/VRpuppet/meshes/visuals/torso.stl" scale="0.001 0.001 0.001" />
      </geometry>
    </visual>
  </link>
  <link name="upper_arm_right">
    <inertial>
      <mass value="0.11563807156317799" />
      <origin rpy="0 0 0" xyz="-0.0251  -0.03104 -0.22543" />
      <inertia ixx="0.16564830019102675" ixy="-0.00258524984112483" ixz="0.014267436827144889" iyy="0.16185014433988829" iyz="0.028271285489196375" izz="0.006439566613380333" />
    </inertial>
    <collision name="upper_arm_right_collision">
      <origin rpy="0 0 0" xyz="-0.0251  -0.03104 -0.22543" />
      <geometry>
        <mesh filename="package://robots/VRpuppet/meshes/collisions/upper_arm_right.stl" scale="0.001 0.001 0.001" />
      </geometry>
    </collision>
    <visual name="upper_arm_right_visual">
      <origin rpy="0 0 0" xyz="-0.0251  -0.03104 -0.22543" />
      <geometry>
        <mesh filename="package://robots/VRpuppet/meshes/visuals/upper_arm_right.stl" scale="0.001 0.001 0.001" />
      </geometry>
    </visual>
  </link>
  <link name="lower_arm_right">
    <inertial>
      <mass value="0.115638071563178" />
      <origin rpy="0 0 0" xyz="0.0112  -0.03895 -0.22972" />
      <inertia ixx="0.1037952358192096" ixy="-0.00290773074489254" ixz="0.010427544319140373" iyy="0.09736536466204024" iyz="0.026531502939236902" izz="0.00872149600005539" />
    </inertial>
    <collision name="lower_arm_right_collision">
      <origin rpy="0 0 0" xyz="0.0112  -0.03895 -0.22972" />
      <geometry>
        <mesh filename="package://robots/VRpuppet/meshes/collisions/lower_arm_right.stl" scale="0.001 0.001 0.001" />
      </geometry>
    </collision>
    <visual name="lower_arm_right_visual">
      <origin rpy="0 0 0" xyz="0.0112  -0.03895 -0.22972" />
      <geometry>
        <mesh filename="package://robots/VRpuppet/meshes/visuals/lower_arm_right.stl" scale="0.001 0.001 0.001" />
      </geometry>
    </visual>
  </link>
  <link name="hand_right">
    <inertial>
      <mass value="0.01651527333909785" />
      <origin rpy="0 0 0" xyz="0.00089 0.01021 0" />
      <inertia ixx="0.013526669952126582" ixy="-0.0004017221677441583" ixz="0.0013819549252235511" iyy="0.012625637080884393" iyz="0.0036252228248703704" izz="0.0012075580529869038" />
    </inertial>
    <collision name="hand_right_collision">
      <origin rpy="0 0 0" xyz="0.00089 0.01021 0" />
      <geometry>
        <mesh filename="package://robots/VRpuppet/meshes/collisions/hand_right.stl" scale="0.001 0.001 0.001" />
      </geometry>
    </collision>
    <visual name="hand_right_visual">
      <origin rpy="0 0 0" xyz="0.00089 0.01021 0" />
      <geometry>
        <mesh filename="package://robots/VRpuppet/meshes/visuals/hand_right.stl" scale="0.001 0.001 0.001" />
      </geometry>
    </visual>
  </link>
  <link name="upper_arm_left">
    <inertial>
      <mass value="0.11563810874472027" />
      <origin rpy="0 0 0" xyz="-0.01909  0.03726 -0.22543" />
      <inertia ixx="0.16630741358216797" ixy="0.0017639251461552604" ixz="0.009148892975354943" iyy="0.16108329631059937" iyz="-0.030173755987746763" izz="0.006331735454186378" />
    </inertial>
    <collision name="upper_arm_left_collision">
      <origin rpy="0 0 0" xyz="-0.01909  0.03726 -0.22543" />
      <geometry>
        <mesh filename="package://robots/VRpuppet/meshes/collisions/upper_arm_left.stl" scale="0.001 0.001 0.001" />
      </geometry>
    </collision>
    <visual name="upper_arm_left_visual">
      <origin rpy="0 0 0" xyz="-0.01909  0.03726 -0.22543" />
      <geometry>
        <mesh filename="package://robots/VRpuppet/meshes/visuals/upper_arm_left.stl" scale="0.001 0.001 0.001" />
      </geometry>
    </visual>
  </link>
  <link name="lower_arm_left">
    <inertial>
      <mass value="0.11563810874472033" />
      <origin rpy="0 0 0" xyz="0.01803  0.03875 -0.22972" />
      <inertia ixx="0.10446759284304319" ixy="0.0016332345481314349" ixz="0.005666093468570909" iyy="0.09656499331827889" iyz="-0.02784611885307521" izz="0.008593425228288779" />
    </inertial>
    <collision name="lower_arm_left_collision">
      <origin rpy="0 0 0" xyz="0.01803  0.03875 -0.22972" />
      <geometry>
        <mesh filename="package://robots/VRpuppet/meshes/collisions/lower_arm_left.stl" scale="0.001 0.001 0.001" />
      </geometry>
    </collision>
    <visual name="lower_arm_left_visual">
      <origin rpy="0 0 0" xyz="0.01803  0.03875 -0.22972" />
      <geometry>
        <mesh filename="package://robots/VRpuppet/meshes/visuals/lower_arm_left.stl" scale="0.001 0.001 0.001" />
      </geometry>
    </visual>
  </link>
  <link name="hand_left">
    <inertial>
      <mass value="0.016515273339097858" />
      <origin rpy="0 0 0" xyz="0.00089 0.01021 0" />
      <inertia ixx="0.013785606741828639" ixy="0.00023055167682189333" ixz="0.0007107841423446757" iyy="0.012513020167321505" iyz="-0.004046203520421022" izz="0.0013538779291266824" />
    </inertial>
    <collision name="hand_left_collision">
      <origin rpy="0 0 0" xyz="0.00089 0.01021 0" />
      <geometry>
        <mesh filename="package://robots/VRpuppet/meshes/collisions/hand_left.stl" scale="0.001 0.001 0.001" />
      </geometry>
    </collision>
    <visual name="hand_left_visual">
      <origin rpy="0 0 0" xyz="0.00089 0.01021 0" />
      <geometry>
        <mesh filename="package://robots/VRpuppet/meshes/visuals/hand_left.stl" scale="0.001 0.001 0.001" />
      </geometry>
    </visual>
  </link>
  <link name="lower_leg_left">
    <inertial>
      <mass value="28.43783650100289" />
      <origin rpy="0 0 0" xyz="-0.01635  0.00036 -0.14667" />
      <inertia ixx="3.5664796438702537" ixy="0.08401137312564953" ixz="0.2477114654783178" iyy="3.260810826061813" iyz="-0.9790790917248035" izz="0.4078059442215795" />
    </inertial>
    <collision name="lower_leg_left_collision">
      <origin rpy="0 0 0" xyz="-0.01635  0.00036 -0.14667" />
      <geometry>
        <mesh filename="package://robots/VRpuppet/meshes/collisions/lower_leg_left.stl" scale="0.001 0.001 0.001" />
      </geometry>
    </collision>
    <visual name="lower_leg_left_visual">
      <origin rpy="0 0 0" xyz="-0.01635  0.00036 -0.14667" />
      <geometry>
        <mesh filename="package://robots/VRpuppet/meshes/visuals/lower_leg_left.stl" scale="0.001 0.001 0.001" />
      </geometry>
    </visual>
  </link>
  <link name="foot_left">
    <inertial>
      <mass value="0.2795712981996832" />
      <origin rpy="0 0 0" xyz="-0.0005  -0.00582 -0.00153" />
      <inertia ixx="0.007192350249843101" ixy="0.0003219000689589345" ixz="0.0003047762519740455" iyy="0.0034515392248869194" iyz="-0.0035691649816709616" izz="0.003838201031576945" />
    </inertial>
    <collision name="foot_left_collision">
      <origin rpy="0 0 0" xyz="-0.0005  -0.00582 -0.00153" />
      <geometry>
        <mesh filename="package://robots/VRpuppet/meshes/collisions/foot_left.stl" scale="0.001 0.001 0.001" />
      </geometry>
    </collision>
    <visual name="foot_left_visual">
      <origin rpy="0 0 0" xyz="-0.0005  -0.00582 -0.00153" />
      <geometry>
        <mesh filename="package://robots/VRpuppet/meshes/visuals/foot_left.stl" scale="0.001 0.001 0.001" />
      </geometry>
    </visual>
  </link>
  <link name="head">
    <inertial>
      <mass value="35.90620293890531" />
      <origin rpy="0 0 0" xyz="0.01312 -0.00149  0.04421" />
      <inertia ixx="98.4016398560236" ixy="0.0024270841017597815" ixz="1.0425153185535418" iyy="98.46385951878611" iyz="0.2143105314031048" izz="0.1679277732426822" />
    </inertial>
    <collision name="head_collision">
      <origin rpy="0 0 0" xyz="0.01312 -0.00149  0.04421" />
      <geometry>
        <mesh filename="package://robots/VRpuppet/meshes/collisions/head.stl" scale="0.001 0.001 0.001" />
      </geometry>
    </collision>
    <visual name="head_visual">
      <origin rpy="0 0 0" xyz="0.01312 -0.00149  0.04421" />
      <geometry>
        <mesh filename="package://robots/VRpuppet/meshes/visuals/head.stl" scale="0.001 0.001 0.001" />
      </geometry>
    </visual>
  </link>
  <link name="upper_leg_left">
    <inertial>
      <mass value="63.29155578858412" />
      <origin rpy="0 0 0" xyz="0.00824  0.00569 -0.15492" />
      <inertia ixx="36.55200563879288" ixy="0.02551891161194341" ixz="0.22943564579310455" iyy="35.955343530288445" iyz="-4.79170851279825" izz="0.850720367977724" />
    </inertial>
    <collision name="upper_leg_left_collision">
      <origin rpy="0 0 0" xyz="0.00824  0.00569 -0.15492" />
      <geometry>
        <mesh filename="package://robots/VRpuppet/meshes/collisions/upper_leg_left.stl" scale="0.001 0.001 0.001" />
      </geometry>
    </collision>
    <visual name="upper_leg_left_visual">
      <origin rpy="0 0 0" xyz="0.00824  0.00569 -0.15492" />
      <geometry>
        <mesh filename="package://robots/VRpuppet/meshes/visuals/upper_leg_left.stl" scale="0.001 0.001 0.001" />
      </geometry>
    </visual>
  </link>
  <link name="upper_leg_right">
    <inertial>
      <mass value="63.292721361055634" />
      <origin rpy="0 0 0" xyz="0.00713 -0.00704 -0.15493" />
      <inertia ixx="36.65936278681766" ixy="-0.14630344895881642" ixz="1.099859971934093" iyy="35.98388068571897" iyz="5.157654079972659" izz="0.988009570045742" />
    </inertial>
    <collision name="upper_leg_right_collision">
      <origin rpy="0 0 0" xyz="0.00713 -0.00704 -0.15493" />
      <geometry>
        <mesh filename="package://robots/VRpuppet/meshes/collisions/upper_leg_right.stl" scale="0.001 0.001 0.001" />
      </geometry>
    </collision>
    <visual name="upper_leg_right_visual">
      <origin rpy="0 0 0" xyz="0.00713 -0.00704 -0.15493" />
      <geometry>
        <mesh filename="package://robots/VRpuppet/meshes/visuals/upper_leg_right.stl" scale="0.001 0.001 0.001" />
      </geometry>
    </visual>
  </link>
</robot>