<robot name="VRpuppet">
  <joint name="elbow_left_axis0" type="revolute">
    <parent link="arm_left_upper" />
    <child link="elbow_left_link1" />
    <origin rpy="0 0 0" xyz="0.04   0.026 -0.263" />
    <axis xyz="0  0 -1" />
    <limit effort="0.0" lower="-3.14159265359" upper="3.14159265359" velocity="0.0" />
  </joint>
  <joint name="elbow_left_axis2" type="revolute">
    <parent link="elbow_left_link2" />
    <child link="arm_left_lower" />
    <origin rpy="0 0 0" xyz="0 0 0" />
    <axis xyz="1 0 0" />
    <limit effort="0.0" lower="-3.14159265359" upper="3.14159265359" velocity="0.0" />
  </joint>
  <joint name="elbow_left_axis1" type="revolute">
    <parent link="elbow_left_link1" />
    <child link="elbow_left_link2" />
    <origin rpy="0 0 0" xyz="0 0 0" />
    <axis xyz="0 -1  0" />
    <limit effort="0.0" lower="-3.14159265359" upper="3.14159265359" velocity="0.0" />
  </joint>
  <joint name="wrist_left_axis0" type="revolute">
    <parent link="arm_left_lower" />
    <child link="wrist_left_link1" />
    <origin rpy="0 0 0" xyz="0.0455 -0.017  -0.268" />
    <axis xyz="0  0 -1" />
    <limit effort="0.0" lower="-3.14159265359" upper="3.14159265359" velocity="0.0" />
  </joint>
  <joint name="wrist_left_axis2" type="revolute">
    <parent link="wrist_left_link2" />
    <child link="hand_left" />
    <origin rpy="0 0 0" xyz="0 0 0" />
    <axis xyz="1 0 0" />
    <limit effort="0.0" lower="-3.14159265359" upper="3.14159265359" velocity="0.0" />
  </joint>
  <joint name="wrist_left_axis1" type="revolute">
    <parent link="wrist_left_link1" />
    <child link="wrist_left_link2" />
    <origin rpy="0 0 0" xyz="0 0 0" />
    <axis xyz="0 -1  0" />
    <limit effort="0.0" lower="-3.14159265359" upper="3.14159265359" velocity="0.0" />
  </joint>
  <joint name="shoulder_left_axis0" type="revolute">
    <parent link="base" />
    <child link="shoulder_left_link1" />
    <origin rpy="0 0 0" xyz="0.18077 0.0649  0.70001" />
    <axis xyz="0  0 -1" />
    <limit effort="0.0" lower="-3.14159265359" upper="3.14159265359" velocity="0.0" />
  </joint>
  <joint name="shoulder_left_axis2" type="revolute">
    <parent link="shoulder_left_link2" />
    <child link="arm_left_upper" />
    <origin rpy="0 0 0" xyz="0 0 0" />
    <axis xyz="1 0 0" />
    <limit effort="0.0" lower="-3.14159265359" upper="3.14159265359" velocity="0.0" />
  </joint>
  <joint name="shoulder_left_axis1" type="revolute">
    <parent link="shoulder_left_link1" />
    <child link="shoulder_left_link2" />
    <origin rpy="0 0 0" xyz="0 0 0" />
    <axis xyz="0 -1  0" />
    <limit effort="0.0" lower="-3.14159265359" upper="3.14159265359" velocity="0.0" />
  </joint>
  <joint name="motor0" type="prismatic">
    <parent link="base" />
    <child link="motor0" />
    <origin rpy="0 0 0" xyz="-0.13521 -1.4939  -0.39996" />
    <axis xyz="0  0 -1" />
    <limit effort="0.0" lower="-1.5" upper="0" velocity="0.0" />
  </joint>
  <joint name="motor6" type="prismatic">
    <parent link="base" />
    <child link="motor6" />
    <origin rpy="0 0 0" xyz="1.30608  0.06065 -0.39996" />
    <axis xyz="0  0 -1" />
    <limit effort="0.0" lower="-1.5" upper="0" velocity="0.0" />
  </joint>
  <joint name="motor1" type="prismatic">
    <parent link="base" />
    <child link="motor1" />
    <origin rpy="0 0 0" xyz="0.25875 -1.42561 -0.39996" />
    <axis xyz="0  0 -1" />
    <limit effort="0.0" lower="-1.5" upper="0" velocity="0.0" />
  </joint>
  <joint name="motor2" type="prismatic">
    <parent link="base" />
    <child link="motor2" />
    <origin rpy="0 0 0" xyz="0.61257 -1.26191 -0.39996" />
    <axis xyz="0  0 -1" />
    <limit effort="0.0" lower="-1.5" upper="0" velocity="0.0" />
  </joint>
  <joint name="motor3" type="prismatic">
    <parent link="base" />
    <child link="motor3" />
    <origin rpy="0 0 0" xyz="0.91196 -1.01221 -0.39996" />
    <axis xyz="0  0 -1" />
    <limit effort="0.0" lower="-1.5" upper="0" velocity="0.0" />
  </joint>
  <joint name="motor4" type="prismatic">
    <parent link="base" />
    <child link="motor4" />
    <origin rpy="0 0 0" xyz="1.13652 -0.69354 -0.39996" />
    <axis xyz="0  0 -1" />
    <limit effort="0.0" lower="-1.5" upper="0" velocity="0.0" />
  </joint>
  <joint name="motor5" type="prismatic">
    <parent link="base" />
    <child link="motor5" />
    <origin rpy="0 0 0" xyz="1.27095 -0.3276  -0.39996" />
    <axis xyz="0  0 -1" />
    <limit effort="0.0" lower="-1.5" upper="0" velocity="0.0" />
  </joint>
  <joint name="motor7" type="prismatic">
    <parent link="base" />
    <child link="motor7" />
    <origin rpy="0 0 0" xyz="1.23953  0.44478 -0.39996" />
    <axis xyz="0  0 -1" />
    <limit effort="0.0" lower="-1.5" upper="0" velocity="0.0" />
  </joint>
  <joint name="motor8" type="prismatic">
    <parent link="base" />
    <child link="motor8" />
    <origin rpy="0 0 0" xyz="1.07583  0.79859 -0.39996" />
    <axis xyz="0  0 -1" />
    <limit effort="0.0" lower="-1.5" upper="0" velocity="0.0" />
  </joint>
  <joint name="motor9" type="prismatic">
    <parent link="base" />
    <child link="motor9" />
    <origin rpy="0 0 0" xyz="0.82614  1.09798 -0.39996" />
    <axis xyz="0  0 -1" />
    <limit effort="0.0" lower="-1.5" upper="0" velocity="0.0" />
  </joint>
  <joint name="motor11" type="prismatic">
    <parent link="base" />
    <child link="motor11" />
    <origin rpy="0 0 0" xyz="0.14152  1.45697 -0.39996" />
    <axis xyz="0  0 -1" />
    <limit effort="0.0" lower="-1.5" upper="0" velocity="0.0" />
  </joint>
  <joint name="motor10" type="prismatic">
    <parent link="base" />
    <child link="motor10" />
    <origin rpy="0 0 0" xyz="0.50746  1.32254 -0.39996" />
    <axis xyz="0  0 -1" />
    <limit effort="0.0" lower="-1.5" upper="0" velocity="0.0" />
  </joint>
  <joint name="motor12" type="prismatic">
    <parent link="base" />
    <child link="motor12" />
    <origin rpy="0 0 0" xyz="-0.24673  1.49211 -0.39996" />
    <axis xyz="0  0 -1" />
    <limit effort="0.0" lower="-1.5" upper="0" velocity="0.0" />
  </joint>
  <joint name="motor13" type="prismatic">
    <parent link="base" />
    <child link="motor13" />
    <origin rpy="0 0 0" xyz="-0.63086  1.42556 -0.39996" />
    <axis xyz="0  0 -1" />
    <limit effort="0.0" lower="-1.5" upper="0" velocity="0.0" />
  </joint>
  <link name="base">
    <inertial>
      <mass value="18.83497146103242" />
      <origin rpy="0 0 0" xyz="0.60297 0.13842 0.2783" />
      <inertia ixx="33.33959964657787" ixy="1.3999987984804347" ixz="-2.9720294621167302" iyy="23.29825486423085" iyz="-0.7006446566367024" izz="37.405102655876675" />
    </inertial>
    <collision name="base_collision">
      <origin rpy="0 0 0" xyz="0.60297 0.13842 0.2783" />
      <geometry>
        <mesh filename="package://robots/VRpuppet/meshes/collisions/base.stl" scale="0.001 0.001 0.001" />
      </geometry>
    </collision>
    <visual name="base_visual">
      <origin rpy="0 0 0" xyz="0.60297 0.13842 0.2783" />
      <geometry>
        <mesh filename="package://robots/VRpuppet/meshes/visuals/base.stl" scale="0.001 0.001 0.001" />
      </geometry>
    </visual>
  </link>
  <link name="shoulder_left_link1">
    <inertial>
      <mass value="0.06979038134801809" />
      <origin rpy="0 0 0" xyz="0 0 0" />
      <inertia ixx="0.03450481088643034" ixy="-0.0008189201815306329" ixz="-0.008831887922651223" iyy="0.03649160635049412" iyz="-0.003171050314257621" izz="0.002586502083462145" />
    </inertial>
    <collision name="shoulder_left_link1_collision">
      <origin rpy="0 0 0" xyz="0 0 0" />
      <geometry>
        <mesh filename="package://robots/VRpuppet/meshes/collisions/shoulder_left_link1.stl" scale="0.001 0.001 0.001" />
      </geometry>
    </collision>
    <visual name="shoulder_left_link1_visual">
      <origin rpy="0 0 0" xyz="0 0 0" />
      <geometry>
        <mesh filename="package://robots/VRpuppet/meshes/visuals/shoulder_left_link1.stl" scale="0.001 0.001 0.001" />
      </geometry>
    </visual>
  </link>
  <link name="shoulder_left_link2">
    <inertial>
      <mass value="0.04678255835713114" />
      <origin rpy="0 0 0" xyz="0 0 0" />
      <inertia ixx="0.023127049970576203" ixy="-0.000548946437063391" ixz="-0.005920275891382745" iyy="0.02445885777769733" iyz="-0.0021256488862038438" izz="0.0017312628234954627" />
    </inertial>
    <collision name="shoulder_left_link2_collision">
      <origin rpy="0 0 0" xyz="0 0 0" />
      <geometry>
        <mesh filename="package://robots/VRpuppet/meshes/collisions/shoulder_left_link2.stl" scale="0.001 0.001 0.001" />
      </geometry>
    </collision>
    <visual name="shoulder_left_link2_visual">
      <origin rpy="0 0 0" xyz="0 0 0" />
      <geometry>
        <mesh filename="package://robots/VRpuppet/meshes/visuals/shoulder_left_link2.stl" scale="0.001 0.001 0.001" />
      </geometry>
    </visual>
  </link>
  <link name="elbow_left_link1">
    <inertial>
      <mass value="0.0697903813480181" />
      <origin rpy="0 0 0" xyz="0 0 0" />
      <inertia ixx="0.013917365071566613" ixy="-0.0014007328524469267" ixz="-0.0067336997093007354" iyy="0.01674242083368397" iyz="-0.0027726661998714753" izz="0.003990233729513199" />
    </inertial>
    <collision name="elbow_left_link1_collision">
      <origin rpy="0 0 0" xyz="0 0 0" />
      <geometry>
        <mesh filename="package://robots/VRpuppet/meshes/collisions/elbow_left_link1.stl" scale="0.001 0.001 0.001" />
      </geometry>
    </collision>
    <visual name="elbow_left_link1_visual">
      <origin rpy="0 0 0" xyz="0 0 0" />
      <geometry>
        <mesh filename="package://robots/VRpuppet/meshes/visuals/elbow_left_link1.stl" scale="0.001 0.001 0.001" />
      </geometry>
    </visual>
  </link>
  <link name="elbow_left_link2">
    <inertial>
      <mass value="0.04678255835713113" />
      <origin rpy="0 0 0" xyz="0 0 0" />
      <inertia ixx="0.009326675668917664" ixy="-0.0009389526915690209" ixz="-0.004513798227278331" iyy="0.01122039416565951" iyz="-0.0018586002224791661" izz="0.0026722256951792244" />
    </inertial>
    <collision name="elbow_left_link2_collision">
      <origin rpy="0 0 0" xyz="0 0 0" />
      <geometry>
        <mesh filename="package://robots/VRpuppet/meshes/collisions/elbow_left_link2.stl" scale="0.001 0.001 0.001" />
      </geometry>
    </collision>
    <visual name="elbow_left_link2_visual">
      <origin rpy="0 0 0" xyz="0 0 0" />
      <geometry>
        <mesh filename="package://robots/VRpuppet/meshes/visuals/elbow_left_link2.stl" scale="0.001 0.001 0.001" />
      </geometry>
    </visual>
  </link>
  <link name="wrist_left_link1">
    <inertial>
      <mass value="0.06979038134801814" />
      <origin rpy="0 0 0" xyz="0 0 0" />
      <inertia ixx="0.0023865980990384135" ixy="-0.0013734843440707217" ixz="-0.0031409999254738905" iyy="0.006953832371751661" iyz="-0.0008718101511550842" izz="0.0053413251174183485" />
    </inertial>
    <collision name="wrist_left_link1_collision">
      <origin rpy="0 0 0" xyz="0 0 0" />
      <geometry>
        <mesh filename="package://robots/VRpuppet/meshes/collisions/wrist_left_link1.stl" scale="0.001 0.001 0.001" />
      </geometry>
    </collision>
    <visual name="wrist_left_link1_visual">
      <origin rpy="0 0 0" xyz="0 0 0" />
      <geometry>
        <mesh filename="package://robots/VRpuppet/meshes/visuals/wrist_left_link1.stl" scale="0.001 0.001 0.001" />
      </geometry>
    </visual>
  </link>
  <link name="wrist_left_link2">
    <inertial>
      <mass value="0.04678255835713115" />
      <origin rpy="0 0 0" xyz="0 0 0" />
      <inertia ixx="0.0015972612657379286" ixy="-0.0009206872098703605" ixz="-0.0021055052211346567" iyy="0.0046588135852248585" iyz="-0.0005844001492035248" izz="0.0035779022437181867" />
    </inertial>
    <collision name="wrist_left_link2_collision">
      <origin rpy="0 0 0" xyz="0 0 0" />
      <geometry>
        <mesh filename="package://robots/VRpuppet/meshes/collisions/wrist_left_link2.stl" scale="0.001 0.001 0.001" />
      </geometry>
    </collision>
    <visual name="wrist_left_link2_visual">
      <origin rpy="0 0 0" xyz="0 0 0" />
      <geometry>
        <mesh filename="package://robots/VRpuppet/meshes/visuals/wrist_left_link2.stl" scale="0.001 0.001 0.001" />
      </geometry>
    </visual>
  </link>
  <link name="arm_left_upper">
    <inertial>
      <mass value="0.11563830149074947" />
      <origin rpy="0 0 0" xyz="0.03546  0.02226 -0.22543" />
      <inertia ixx="0.02793525054980266" ixy="-0.002190710498888394" ixz="-0.011757687480349638" iyy="0.03246740586200935" iyz="-0.0046874002961990405" izz="0.006331747557804084" />
    </inertial>
    <collision name="arm_left_upper_collision">
      <origin rpy="0 0 0" xyz="0.03546  0.02226 -0.22543" />
      <geometry>
        <mesh filename="package://robots/VRpuppet/meshes/collisions/arm_left_upper.stl" scale="0.001 0.001 0.001" />
      </geometry>
    </collision>
    <visual name="arm_left_upper_visual">
      <origin rpy="0 0 0" xyz="0.03546  0.02226 -0.22543" />
      <geometry>
        <mesh filename="package://robots/VRpuppet/meshes/visuals/arm_left_upper.stl" scale="0.001 0.001 0.001" />
      </geometry>
    </visual>
  </link>
  <link name="arm_left_lower">
    <inertial>
      <mass value="0.1156383014907495" />
      <origin rpy="0 0 0" xyz="0.04017 -0.01459 -0.22972" />
      <inertia ixx="0.006686379201650511" ixy="-0.0022945620539641946" ixz="-0.006122953136491075" iyy="0.013901718009694416" iyz="-0.001893965440112791" izz="0.008593441282457053" />
    </inertial>
    <collision name="arm_left_lower_collision">
      <origin rpy="0 0 0" xyz="0.04017 -0.01459 -0.22972" />
      <geometry>
        <mesh filename="package://robots/VRpuppet/meshes/collisions/arm_left_lower.stl" scale="0.001 0.001 0.001" />
      </geometry>
    </collision>
    <visual name="arm_left_lower_visual">
      <origin rpy="0 0 0" xyz="0.04017 -0.01459 -0.22972" />
      <geometry>
        <mesh filename="package://robots/VRpuppet/meshes/visuals/arm_left_lower.stl" scale="0.001 0.001 0.001" />
      </geometry>
    </visual>
  </link>
  <link name="hand_left">
    <inertial>
      <mass value="0.016515273339096418" />
      <origin rpy="0 0 0" xyz="0.01025 0      0" />
      <inertia ixx="0.0005622818231408339" ixy="-0.00033754024859741674" ixz="-0.0007719195821289069" iyy="0.001735465190983193" iyz="-0.00020630562661710128" izz="0.0013538779291615921" />
    </inertial>
    <collision name="hand_left_collision">
      <origin rpy="0 0 0" xyz="0.01025 0      0" />
      <geometry>
        <mesh filename="package://robots/VRpuppet/meshes/collisions/hand_left.stl" scale="0.001 0.001 0.001" />
      </geometry>
    </collision>
    <visual name="hand_left_visual">
      <origin rpy="0 0 0" xyz="0.01025 0      0" />
      <geometry>
        <mesh filename="package://robots/VRpuppet/meshes/visuals/hand_left.stl" scale="0.001 0.001 0.001" />
      </geometry>
    </visual>
  </link>
  <link name="motor0">
    <inertial>
      <mass value="0.08230729665227556" />
      <origin rpy="0 0 0" xyz="-0.02439  0.01011 -0.01505" />
      <inertia ixx="0.1954490060380128" ixy="-0.019494691043757666" ixz="-0.005455176090205054" iyy="0.01630461916189472" iyz="-0.05067704979872532" izz="0.18334979209292157" />
    </inertial>
    <collision name="motor0_collision">
      <origin rpy="0 0 0" xyz="-0.02439  0.01011 -0.01505" />
      <geometry>
        <mesh filename="package://robots/VRpuppet/meshes/collisions/motor0.stl" scale="0.001 0.001 0.001" />
      </geometry>
    </collision>
    <visual name="motor0_visual">
      <origin rpy="0 0 0" xyz="-0.02439  0.01011 -0.01505" />
      <geometry>
        <mesh filename="package://robots/VRpuppet/meshes/visuals/motor0.stl" scale="0.001 0.001 0.001" />
      </geometry>
    </visual>
  </link>
  <link name="motor1">
    <inertial>
      <mass value="0.08230729785162337" />
      <origin rpy="0 0 0" xyz="-0.02618  0.00345 -0.01505" />
      <inertia ixx="0.1807078468393261" ixy="0.027230313814513643" ixz="0.007939708490801344" iyy="0.018661093331227743" iyz="-0.04857295302980304" izz="0.1709651066683428" />
    </inertial>
    <collision name="motor1_collision">
      <origin rpy="0 0 0" xyz="-0.02618  0.00345 -0.01505" />
      <geometry>
        <mesh filename="package://robots/VRpuppet/meshes/collisions/motor1.stl" scale="0.001 0.001 0.001" />
      </geometry>
    </collision>
    <visual name="motor1_visual">
      <origin rpy="0 0 0" xyz="-0.02618  0.00345 -0.01505" />
      <geometry>
        <mesh filename="package://robots/VRpuppet/meshes/visuals/motor1.stl" scale="0.001 0.001 0.001" />
      </geometry>
    </visual>
  </link>
  <link name="motor2">
    <inertial>
      <mass value="0.08230729747387144" />
      <origin rpy="0 0 0" xyz="-0.02618 -0.00343 -0.01505" />
      <inertia ixx="0.14601680021354385" ixy="0.061083750165110064" ixz="0.020024004991755728" iyy="0.042515460908058224" iyz="-0.04321806270663767" izz="0.1601284277435439" />
    </inertial>
    <collision name="motor2_collision">
      <origin rpy="0 0 0" xyz="-0.02618 -0.00343 -0.01505" />
      <geometry>
        <mesh filename="package://robots/VRpuppet/meshes/collisions/motor2.stl" scale="0.001 0.001 0.001" />
      </geometry>
    </collision>
    <visual name="motor2_visual">
      <origin rpy="0 0 0" xyz="-0.02618 -0.00343 -0.01505" />
      <geometry>
        <mesh filename="package://robots/VRpuppet/meshes/visuals/motor2.stl" scale="0.001 0.001 0.001" />
      </geometry>
    </visual>
  </link>
  <link name="motor3">
    <inertial>
      <mass value="0.08230729713170418" />
      <origin rpy="0 0 0" xyz="-0.0244  -0.01009 -0.01505" />
      <inertia ixx="0.10024729014679647" ixy="0.0746986387565248" ixz="0.03031059144014415" iyy="0.07906013849168987" iyz="-0.0349179898218747" izz="0.1509035953761763" />
    </inertial>
    <collision name="motor3_collision">
      <origin rpy="0 0 0" xyz="-0.0244  -0.01009 -0.01505" />
      <geometry>
        <mesh filename="package://robots/VRpuppet/meshes/collisions/motor3.stl" scale="0.001 0.001 0.001" />
      </geometry>
    </collision>
    <visual name="motor3_visual">
      <origin rpy="0 0 0" xyz="-0.0244  -0.01009 -0.01505" />
      <geometry>
        <mesh filename="package://robots/VRpuppet/meshes/visuals/motor3.stl" scale="0.001 0.001 0.001" />
      </geometry>
    </visual>
  </link>
  <link name="motor4">
    <inertial>
      <mass value="0.08230729711800862" />
      <origin rpy="0 0 0" xyz="-0.02096 -0.01607 -0.01505" />
      <inertia ixx="0.05566302453043872" ixy="0.06517059958514165" ixz="0.03809845413385201" iyy="0.11666007579932021" iyz="-0.02423837072610677" izz="0.14391926707244077" />
    </inertial>
    <collision name="motor4_collision">
      <origin rpy="0 0 0" xyz="-0.02096 -0.01607 -0.01505" />
      <geometry>
        <mesh filename="package://robots/VRpuppet/meshes/collisions/motor4.stl" scale="0.001 0.001 0.001" />
      </geometry>
    </collision>
    <visual name="motor4_visual">
      <origin rpy="0 0 0" xyz="-0.02096 -0.01607 -0.01505" />
      <geometry>
        <mesh filename="package://robots/VRpuppet/meshes/visuals/motor4.stl" scale="0.001 0.001 0.001" />
      </geometry>
    </visual>
  </link>
  <link name="motor5">
    <inertial>
      <mass value="0.08230729671347992" />
      <origin rpy="0 0 0" xyz="-0.01608 -0.02094 -0.01505" />
      <inertia ixx="0.02421006917174091" ixy="0.03600950692268823" ixz="0.042856862830796885" iyy="0.14384517594593763" iyz="-0.011907003588606758" izz="0.13965141199035708" />
    </inertial>
    <collision name="motor5_collision">
      <origin rpy="0 0 0" xyz="-0.01608 -0.02094 -0.01505" />
      <geometry>
        <mesh filename="package://robots/VRpuppet/meshes/collisions/motor5.stl" scale="0.001 0.001 0.001" />
      </geometry>
    </collision>
    <visual name="motor5_visual">
      <origin rpy="0 0 0" xyz="-0.01608 -0.02094 -0.01505" />
      <geometry>
        <mesh filename="package://robots/VRpuppet/meshes/visuals/motor5.stl" scale="0.001 0.001 0.001" />
      </geometry>
    </visual>
  </link>
  <link name="motor6">
    <inertial>
      <mass value="0.0823072966522758" />
      <origin rpy="0 0 0" xyz="-0.01011 -0.02439 -0.01505" />
      <inertia ixx="0.014315927921432985" ixy="-0.003866184299175448" ixz="0.04426154018599078" iyy="0.15247878376021504" iyz="0.0012357491327068607" izz="0.13839087857466206" />
    </inertial>
    <collision name="motor6_collision">
      <origin rpy="0 0 0" xyz="-0.01011 -0.02439 -0.01505" />
      <geometry>
        <mesh filename="package://robots/VRpuppet/meshes/collisions/motor6.stl" scale="0.001 0.001 0.001" />
      </geometry>
    </collision>
    <visual name="motor6_visual">
      <origin rpy="0 0 0" xyz="-0.01011 -0.02439 -0.01505" />
      <geometry>
        <mesh filename="package://robots/VRpuppet/meshes/visuals/motor6.stl" scale="0.001 0.001 0.001" />
      </geometry>
    </visual>
  </link>
  <link name="motor7">
    <inertial>
      <mass value="0.08230729791585122" />
      <origin rpy="0 0 0" xyz="-0.00345 -0.02618 -0.01505" />
      <inertia ixx="0.028631418642994504" ixy="-0.04259442137182155" ixz="0.04221676027297695" iyy="0.13999598658891765" iyz="0.014294230877206321" izz="0.14022357170777844" />
    </inertial>
    <collision name="motor7_collision">
      <origin rpy="0 0 0" xyz="-0.00345 -0.02618 -0.01505" />
      <geometry>
        <mesh filename="package://robots/VRpuppet/meshes/collisions/motor7.stl" scale="0.001 0.001 0.001" />
      </geometry>
    </collision>
    <visual name="motor7_visual">
      <origin rpy="0 0 0" xyz="-0.00345 -0.02618 -0.01505" />
      <geometry>
        <mesh filename="package://robots/VRpuppet/meshes/visuals/motor7.stl" scale="0.001 0.001 0.001" />
      </geometry>
    </visual>
  </link>
  <link name="motor8">
    <inertial>
      <mass value="0.08230729718839874" />
      <origin rpy="0 0 0" xyz="0.00343 -0.02618 -0.01505" />
      <inertia ixx="0.06332040892538632" ixy="-0.06862821512395866" ixz="0.03686186982096071" iyy="0.1101080153875266" iyz="0.02637852725067415" izz="0.14502459103229598" />
    </inertial>
    <collision name="motor8_collision">
      <origin rpy="0 0 0" xyz="0.00343 -0.02618 -0.01505" />
      <geometry>
        <mesh filename="package://robots/VRpuppet/meshes/collisions/motor8.stl" scale="0.001 0.001 0.001" />
      </geometry>
    </collision>
    <visual name="motor8_visual">
      <origin rpy="0 0 0" xyz="0.00343 -0.02618 -0.01505" />
      <geometry>
        <mesh filename="package://robots/VRpuppet/meshes/visuals/motor8.stl" scale="0.001 0.001 0.001" />
      </geometry>
    </visual>
  </link>
  <link name="motor9">
    <inertial>
      <mass value="0.0823072971317042" />
      <origin rpy="0 0 0" xyz="0.01009 -0.0244  -0.01505" />
      <inertia ixx="0.1090877279741889" ixy="-0.07390936987242522" ixz="0.02856179708753074" iyy="0.07178286460319029" iyz="0.03666511376123685" izz="0.15246675931506945" />
    </inertial>
    <collision name="motor9_collision">
      <origin rpy="0 0 0" xyz="0.01009 -0.0244  -0.01505" />
      <geometry>
        <mesh filename="package://robots/VRpuppet/meshes/collisions/motor9.stl" scale="0.001 0.001 0.001" />
      </geometry>
    </collision>
    <visual name="motor9_visual">
      <origin rpy="0 0 0" xyz="0.01009 -0.0244  -0.01505" />
      <geometry>
        <mesh filename="package://robots/VRpuppet/meshes/visuals/motor9.stl" scale="0.001 0.001 0.001" />
      </geometry>
    </visual>
  </link>
  <link name="motor10">
    <inertial>
      <mass value="0.08230729711800873" />
      <origin rpy="0 0 0" xyz="0.01607 -0.02096 -0.01505" />
      <inertia ixx="0.15366981725647116" ixy="-0.056101435066266504" ixz="0.01788217799285131" iyy="0.036776920074991434" iyz="0.04445297645385545" izz="0.16204290407414487" />
    </inertial>
    <collision name="motor10_collision">
      <origin rpy="0 0 0" xyz="0.01607 -0.02096 -0.01505" />
      <geometry>
        <mesh filename="package://robots/VRpuppet/meshes/collisions/motor10.stl" scale="0.001 0.001 0.001" />
      </geometry>
    </collision>
    <visual name="motor10_visual">
      <origin rpy="0 0 0" xyz="0.01607 -0.02096 -0.01505" />
      <geometry>
        <mesh filename="package://robots/VRpuppet/meshes/visuals/motor10.stl" scale="0.001 0.001 0.001" />
      </geometry>
    </visual>
  </link>
  <link name="motor11">
    <inertial>
      <mass value="0.08230729671348162" />
      <origin rpy="0 0 0" xyz="0.02094 -0.01608 -0.01505" />
      <inertia ixx="0.18512075770486444" ixy="-0.01927854645615867" ixz="0.00555081088553821" iyy="0.016383501405961357" iyz="0.04921138512077989" izz="0.17310042598350406" />
    </inertial>
    <collision name="motor11_collision">
      <origin rpy="0 0 0" xyz="0.02094 -0.01608 -0.01505" />
      <geometry>
        <mesh filename="package://robots/VRpuppet/meshes/collisions/motor11.stl" scale="0.001 0.001 0.001" />
      </geometry>
    </collision>
    <visual name="motor11_visual">
      <origin rpy="0 0 0" xyz="0.02094 -0.01608 -0.01505" />
      <geometry>
        <mesh filename="package://robots/VRpuppet/meshes/visuals/motor11.stl" scale="0.001 0.001 0.001" />
      </geometry>
    </visual>
  </link>
  <link name="motor12">
    <inertial>
      <mass value="0.08230729665223203" />
      <origin rpy="0 0 0" xyz="0.02439 -0.01011 -0.01505" />
      <inertia ixx="0.1950131845223458" ixy="0.027118702401607277" ixz="-0.00759194183112989" iyy="0.018276423168218713" iyz="0.05061606247116418" izz="0.1848857745835936" />
    </inertial>
    <collision name="motor12_collision">
      <origin rpy="0 0 0" xyz="0.02439 -0.01011 -0.01505" />
      <geometry>
        <mesh filename="package://robots/VRpuppet/meshes/collisions/motor12.stl" scale="0.001 0.001 0.001" />
      </geometry>
    </collision>
    <visual name="motor12_visual">
      <origin rpy="0 0 0" xyz="0.02439 -0.01011 -0.01505" />
      <geometry>
        <mesh filename="package://robots/VRpuppet/meshes/visuals/motor12.stl" scale="0.001 0.001 0.001" />
      </geometry>
    </visual>
  </link>
  <link name="motor13">
    <inertial>
      <mass value="0.08230729778739827" />
      <origin rpy="0 0 0" xyz="0.02618 -0.00345 -0.01505" />
      <inertia ixx="0.18069639884603586" ixy="0.0707838257275863" ixz="-0.020650423639268677" iyy="0.04430323461811527" iyz="0.048571282578412006" izz="0.1965957999838652" />
    </inertial>
    <collision name="motor13_collision">
      <origin rpy="0 0 0" xyz="0.02618 -0.00345 -0.01505" />
      <geometry>
        <mesh filename="package://robots/VRpuppet/meshes/collisions/motor13.stl" scale="0.001 0.001 0.001" />
      </geometry>
    </collision>
    <visual name="motor13_visual">
      <origin rpy="0 0 0" xyz="0.02618 -0.00345 -0.01505" />
      <geometry>
        <mesh filename="package://robots/VRpuppet/meshes/visuals/motor13.stl" scale="0.001 0.001 0.001" />
      </geometry>
    </visual>
  </link>
</robot>