<?xml version="1.0" ?>
<sdf version="1.6">
	<model name="yatr">
		<link name="link0">
			<self_collide>false</self_collide>
			<pose frame="">-5.563947494092521e-09 0.0 0.0999988906728854 0.0 -0.0 0.0</pose>
			<inertial>
				<pose frame="">0.0 0.0 0.0 0 0 0</pose>
				<mass>0.8836370946540533</mass>
				<inertia>
					<ixx>0.0128359314450565</ixx>
					<ixy>-2.2311041902867146e-20</ixy>
					<ixz>2.2311041902867146e-20</ixz>
					<iyy>0.013012482239917657</iyy>
					<iyz>-7.015541185751317e-11</iyz>
					<izz>0.00019127807977205796</izz>
				</inertia>
			</inertial>
			<collision name="link0_collision">
				<geometry>
					<mesh>
						<uri>model://yatr/meshes/CAD/link0.stl</uri>
						<scale>0.001 0.001 0.001</scale>
					</mesh>
				</geometry>
			</collision>
			<visual name="link0_visual">
				<geometry>
					<mesh>
						<uri>model://yatr/meshes/CAD/link0.stl</uri>
						<scale>0.001 0.001 0.001</scale>
					</mesh>
				</geometry>
			</visual>
		</link>
		<link name="base">
			<self_collide>false</self_collide>
			<pose frame="">0.0 0.005 0.0 0.0 -0.0 0.0</pose>
			<inertial>
				<pose frame="">0.0 0.0 0.0 0 0 0</pose>
				<mass>0.024661502330679867</mass>
				<inertia>
					<ixx>8.220500378772341e-07</ixx>
					<ixy>8.715250743307479e-23</ixy>
					<ixz>-9.670511946779926e-17</ixz>
					<iyy>1.2330750369097686e-06</iyy>
					<iyz>0.0</iyz>
					<izz>8.220500378771992e-07</izz>
				</inertia>
			</inertial>
			<collision name="base_collision">
				<geometry>
					<mesh>
						<uri>model://yatr/meshes/CAD/base.stl</uri>
						<scale>0.001 0.001 0.001</scale>
					</mesh>
				</geometry>
			</collision>
			<visual name="base_visual">
				<geometry>
					<mesh>
						<uri>model://yatr/meshes/CAD/base.stl</uri>
						<scale>0.001 0.001 0.001</scale>
					</mesh>
				</geometry>
			</visual>
		</link>
		<link name="link1">
			<self_collide>false</self_collide>
			<pose frame="">5.546390191122689e-09 -0.009999999999999992 0.29999662680277434 0.0 -0.0 0.0</pose>
			<inertial>
				<pose frame="">0.0 0.0 0.0 0 0 0</pose>
				<mass>0.8836370946540533</mass>
				<inertia>
					<ixx>0.08361367037501313</ixx>
					<ixy>4.900996110954736e-11</ixy>
					<ixz>0.002650881477140194</ixz>
					<iyy>0.08370185746040888</iyy>
					<iyz>-9.084812706589674e-10</iyz>
					<izz>0.00027964178923746305</izz>
				</inertia>
			</inertial>
			<collision name="link1_collision">
				<geometry>
					<mesh>
						<uri>model://yatr/meshes/CAD/link1.stl</uri>
						<scale>0.001 0.001 0.001</scale>
					</mesh>
				</geometry>
			</collision>
			<visual name="link1_visual">
				<geometry>
					<mesh>
						<uri>model://yatr/meshes/CAD/link1.stl</uri>
						<scale>0.001 0.001 0.001</scale>
					</mesh>
				</geometry>
			</visual>
		</link>
		<link name="link2">
			<self_collide>false</self_collide>
			<pose frame="">-5.5639488625937765e-09 1.1993322788254998e-17 0.4999943629326631 0.0 -0.0 0.0</pose>
			<inertial>
				<pose frame="">0.0 0.0 0.0 0 0 0</pose>
				<mass>0.8836370946540533</mass>
				<inertia>
					<ixx>0.22490404911573442</ixx>
					<ixy>0.0</ixy>
					<ixz>-5.354650056688115e-18</ixz>
					<iyy>0.2250805999105956</iyy>
					<iyz>1.8964270946713667e-09</iyz>
					<izz>0.00019127807977205842</izz>
				</inertia>
			</inertial>
			<collision name="link2_collision">
				<geometry>
					<mesh>
						<uri>model://yatr/meshes/CAD/link2.stl</uri>
						<scale>0.001 0.001 0.001</scale>
					</mesh>
				</geometry>
			</collision>
			<visual name="link2_visual">
				<geometry>
					<mesh>
						<uri>model://yatr/meshes/CAD/link2.stl</uri>
						<scale>0.001 0.001 0.001</scale>
					</mesh>
				</geometry>
			</visual>
		</link>
		<joint name="joint0" type="revolute">
			<parent>base</parent>
			<child>link0</child>
			<pose frame="">5.563947494092521e-09 -0.005 -0.0999988906728854 0 0 0</pose>
			<axis>
				<xyz>0.0 -1.0 0.0</xyz>
				<limit>
					<lower>-3.141592653589793</lower>
					<upper>0.0</upper>
				</limit>
				<use_parent_model_frame>0</use_parent_model_frame>
			</axis>
		</joint>
		<joint name="joint1" type="revolute">
			<parent>link0</parent>
			<child>link1</child>
			<pose frame="">-5.563946838776726e-09 0.004999999999999993 -0.09999889067288535 0 0 0</pose>
			<axis>
				<xyz>0.0 -0.9999999999999996 0.0</xyz>
				<limit>
					<lower>-6.283185307179586</lower>
					<upper>-3.141592653589793</upper>
				</limit>
				<use_parent_model_frame>0</use_parent_model_frame>
			</axis>
		</joint>
		<joint name="joint2" type="revolute">
			<parent>link1</parent>
			<child>link2</child>
			<pose frame="">5.5639475612636e-09 -0.005000000000000001 -0.09999889067288542 0 0 0</pose>
			<axis>
				<xyz>0.0 -0.9999999999999984 0.0</xyz>
				<limit>
					<lower>0.0</lower>
					<upper>3.141592653589793</upper>
				</limit>
				<use_parent_model_frame>0</use_parent_model_frame>
			</axis>
		</joint>
		<plugin filename="libmusc_plugin.so" name="musc_plugin">
			<myoMuscle name="motor0">
				<link name="link0">
					<viaPoint type="FIXPOINT">-0.019999994682043144 0.0049999999999999975 0.05999929866129644</viaPoint>
				</link>
				<link name="link1">
					<viaPoint type="FIXPOINT">0.019999994682042478 0.005000000000000001 0.0599992986612962</viaPoint>
				</link>
			</myoMuscle>
			<myoMuscle name="motor1">
				<link name="link0">
					<viaPoint type="FIXPOINT">0.020000004579677762 0.0049999999999999975 0.05999386440291945</viaPoint>
				</link>
				<link name="link1">
					<viaPoint type="FIXPOINT">-0.02000000457967841 0.005000000000000001 0.05999386440291921</viaPoint>
				</link>
			</myoMuscle>
			<myoMuscle name="motor2">
				<link name="link1">
					<viaPoint type="FIXPOINT">0.01999863611759988 0.004999999999999993 -0.060000702630692335</viaPoint>
				</link>
				<link name="link2">
					<viaPoint type="FIXPOINT">-0.019998636117599267 0.005 -0.06000070263069219</viaPoint>
				</link>
			</myoMuscle>
			<myoMuscle name="motor3">
				<link name="link1">
					<viaPoint type="FIXPOINT">-0.02000136314412074 0.004999999999999993 -0.06000613688906935</viaPoint>
				</link>
				<link name="link2">
					<viaPoint type="FIXPOINT">0.02000136314412157 0.005 -0.06000613688906917</viaPoint>
				</link>
			</myoMuscle>
			<myoMuscle name="motor4">
				<link name="link0">
					<viaPoint type="FIXPOINT">0.020001363144121535 0.005 -0.060006136889069084</viaPoint>
				</link>
				<link name="link2">
					<viaPoint type="FIXPOINT">-0.01999999468204317 0.004999999999999999 0.0599992986612962</viaPoint>
				</link>
			</myoMuscle>
			<myoMuscle name="motor5">
				<link name="link0">
					<viaPoint type="FIXPOINT">-0.01999863611759937 0.005 -0.06000070263069209</viaPoint>
				</link>
				<link name="link2">
					<viaPoint type="FIXPOINT">0.020000004579677672 0.004999999999999999 0.05999386440291921</viaPoint>
				</link>
			</myoMuscle>
		</plugin>
	</model>
</sdf>
