<sdf version="1.6">
	<model name="yatr">
		<link name="link0">
			<self_collide>false</self_collide>
			<pose frame="">-5.563947494092521e-09 0.0 0.0999988906728854 0.0 -0.0 0.0</pose>
			<inertial>
				<pose frame="">0.0 0.0 0.0 0 0 0</pose>
				<mass>0.8836370946540533</mass>
				<inertia>
					<ixx>0.0128359314450565</ixx>
					<ixy>-2.2311041902867146e-20</ixy>
					<ixz>2.2311041902867146e-20</ixz>
					<iyy>0.013012482239917657</iyy>
					<iyz>-7.015541185751317e-11</iyz>
					<izz>0.00019127807977205796</izz>
				</inertia>
			</inertial>
			<collision name="link0_collision">
				<geometry>
					<mesh>
						<uri>model://yatr/meshes/collisions/link0.stl</uri>
						<scale>0.001 0.001 0.001</scale>
					</mesh>
				</geometry>
			</collision>
			<visual name="link0_visual">
				<geometry>
					<mesh>
						<uri>model://yatr/meshes/visuals/link0.stl</uri>
						<scale>0.001 0.001 0.001</scale>
					</mesh>
				</geometry>
			</visual>
		</link>
		<link name="base">
			<self_collide>false</self_collide>
			<pose frame="">0.0 0.005 0.0 0.0 -0.0 0.0</pose>
			<inertial>
				<pose frame="">0.0 0.0 0.0 0 0 0</pose>
				<mass>0.049323004661358645</mass>
				<inertia>
					<ixx>4.264384748154175e-06</ixx>
					<ixy>-2.4065857640032105e-18</ixy>
					<ixz>-9.662493916096083e-17</ixz>
					<iyy>0.0022242106194684656</iyy>
					<iyz>2.578881552750545e-16</iyz>
					<izz>0.0022206655285581956</izz>
				</inertia>
			</inertial>
			<collision name="base_collision">
				<geometry>
					<mesh>
						<uri>model://yatr/meshes/collisions/base.stl</uri>
						<scale>0.001 0.001 0.001</scale>
					</mesh>
				</geometry>
			</collision>
			<visual name="base_visual">
				<geometry>
					<mesh>
						<uri>model://yatr/meshes/visuals/base.stl</uri>
						<scale>0.001 0.001 0.001</scale>
					</mesh>
				</geometry>
			</visual>
		</link>
		<link name="link1">
			<self_collide>false</self_collide>
			<pose frame="">5.546390191122689e-09 -0.009999999999999992 0.29999662680277434 0.0 -0.0 0.0</pose>
			<inertial>
				<pose frame="">0.0 0.0 0.0 0 0 0</pose>
				<mass>0.8836370946540533</mass>
				<inertia>
					<ixx>0.08361367037501313</ixx>
					<ixy>4.900996110954736e-11</ixy>
					<ixz>0.002650881477140194</ixz>
					<iyy>0.08370185746040888</iyy>
					<iyz>-9.084812706589674e-10</iyz>
					<izz>0.00027964178923746305</izz>
				</inertia>
			</inertial>
			<collision name="link1_collision">
				<geometry>
					<mesh>
						<uri>model://yatr/meshes/collisions/link1.stl</uri>
						<scale>0.001 0.001 0.001</scale>
					</mesh>
				</geometry>
			</collision>
			<visual name="link1_visual">
				<geometry>
					<mesh>
						<uri>model://yatr/meshes/visuals/link1.stl</uri>
						<scale>0.001 0.001 0.001</scale>
					</mesh>
				</geometry>
			</visual>
		</link>
		<link name="link2">
			<self_collide>false</self_collide>
			<pose frame="">-5.5639488625937765e-09 1.1993322788254998e-17 0.4999943629326631 0.0 -0.0 0.0</pose>
			<inertial>
				<pose frame="">0.0 0.0 0.0 0 0 0</pose>
				<mass>0.8836370946540533</mass>
				<inertia>
					<ixx>0.22490404911573442</ixx>
					<ixy>0.0</ixy>
					<ixz>-5.354650056688115e-18</ixz>
					<iyy>0.2250805999105956</iyy>
					<iyz>1.8964270946713667e-09</iyz>
					<izz>0.00019127807977205842</izz>
				</inertia>
			</inertial>
			<collision name="link2_collision">
				<geometry>
					<mesh>
						<uri>model://yatr/meshes/collisions/link2.stl</uri>
						<scale>0.001 0.001 0.001</scale>
					</mesh>
				</geometry>
			</collision>
			<visual name="link2_visual">
				<geometry>
					<mesh>
						<uri>model://yatr/meshes/visuals/link2.stl</uri>
						<scale>0.001 0.001 0.001</scale>
					</mesh>
				</geometry>
			</visual>
		</link>
		<joint name="joint0" type="revolute">
			<parent>base</parent>
			<child>link0</child>
			<pose frame="">5.563947494092521e-09 -0.005 -0.0999988906728854 0 0 0</pose>
			<axis>
				<xyz>0.0 -1.0 0.0</xyz>
				<limit>
					<lower>-3.141592653589793</lower>
					<upper>3.14159265359</upper>
				</limit>
				<use_parent_model_frame>0</use_parent_model_frame>
			</axis>
		</joint>
		<joint name="joint1" type="revolute">
			<parent>link0</parent>
			<child>link1</child>
			<pose frame="">-5.563946838776726e-09 0.004999999999999993 -0.09999889067288535 0 0 0</pose>
			<axis>
				<xyz>0.0 -0.9999999999999996 0.0</xyz>
				<limit>
					<lower>-3.14159265359</lower>
					<upper>3.141592653589793</upper>
				</limit>
				<use_parent_model_frame>0</use_parent_model_frame>
			</axis>
		</joint>
		<joint name="joint2" type="revolute">
			<parent>link1</parent>
			<child>link2</child>
			<pose frame="">5.5639475612636e-09 -0.005000000000000001 -0.09999889067288542 0 0 0</pose>
			<axis>
				<xyz>0.0 -0.9999999999999984 0.0</xyz>
				<limit>
					<lower>-3.14159265359</lower>
					<upper>3.141592653589793</upper>
				</limit>
				<use_parent_model_frame>0</use_parent_model_frame>
			</axis>
		</joint>
		<plugin filename="libmusc_plugin.so" name="musc_plugin">
		</plugin>
	</model>
</sdf>