<?xml version="1.0" ?>
<sdf version="1.6">
	<model name="yatr">
		<link name="link0">
			<self_collide>false</self_collide>
			<pose frame="">0.0 0.0 0.0 0.0 -0.0 0.0</pose>
			<inertial>
				<pose frame="">0.0 0.0 0.0 0 0 0</pose>
				<mass>0.8836370946540533</mass>
				<inertia>
					<ixx>0.0128359314450565</ixx>
					<ixy>-2.2311041902867146e-20</ixy>
					<ixz>2.2311041902867146e-20</ixz>
					<iyy>0.013012482239917657</iyy>
					<iyz>-7.015541194675734e-11</iyz>
					<izz>0.00019127807977205796</izz>
				</inertia>
			</inertial>
			<collision name="link0_collision">
				<geometry>
					<mesh>
						<uri>model://yatr/meshes/CAD/link0.stl</uri>
						<scale>0.001 0.001 0.001</scale>
					</mesh>
				</geometry>
			</collision>
			<visual name="link0_visual">
				<geometry>
					<mesh>
						<uri>model://yatr/meshes/CAD/link0.stl</uri>
						<scale>0.001 0.001 0.001</scale>
					</mesh>
				</geometry>
			</visual>
		</link>
		<link name="base">
			<self_collide>false</self_collide>
			<pose frame="">0.0 0.0 0.0 0.0 -0.0 0.0</pose>
			<inertial>
				<pose frame="">0.0 0.0 0.0 0 0 0</pose>
				<mass>0.024661502330679867</mass>
				<inertia>
					<ixx>8.220500378772341e-07</ixx>
					<ixy>8.715250743307479e-23</ixy>
					<ixz>-9.670511946779926e-17</ixz>
					<iyy>1.2330750369097686e-06</iyy>
					<iyz>0.0</iyz>
					<izz>8.220500378771992e-07</izz>
				</inertia>
			</inertial>
			<collision name="base_collision">
				<geometry>
					<mesh>
						<uri>model://yatr/meshes/CAD/base.stl</uri>
						<scale>0.001 0.001 0.001</scale>
					</mesh>
				</geometry>
			</collision>
			<visual name="base_visual">
				<geometry>
					<mesh>
						<uri>model://yatr/meshes/CAD/base.stl</uri>
						<scale>0.001 0.001 0.001</scale>
					</mesh>
				</geometry>
			</visual>
		</link>
		<link name="link1">
			<self_collide>false</self_collide>
			<pose frame="">0.0 0.0 0.0 0.0 -0.0 0.0</pose>
			<inertial>
				<pose frame="">0.0 0.0 0.0 0 0 0</pose>
				<mass>0.883637094654053</mass>
				<inertia>
					<ixx>0.08361367037501313</ixx>
					<ixy>4.900996116532497e-11</ixy>
					<ixz>0.002650881477140194</ixz>
					<iyy>0.08370185746040888</iyy>
					<iyz>-9.084812707482116e-10</iyz>
					<izz>0.00027964178923746305</izz>
				</inertia>
			</inertial>
			<collision name="link1_collision">
				<geometry>
					<mesh>
						<uri>model://yatr/meshes/CAD/link1.stl</uri>
						<scale>0.001 0.001 0.001</scale>
					</mesh>
				</geometry>
			</collision>
			<visual name="link1_visual">
				<geometry>
					<mesh>
						<uri>model://yatr/meshes/CAD/link1.stl</uri>
						<scale>0.001 0.001 0.001</scale>
					</mesh>
				</geometry>
			</visual>
		</link>
		<link name="link2">
			<self_collide>false</self_collide>
			<pose frame="">0.0 0.0 0.0 0.0 -0.0 0.0</pose>
			<inertial>
				<pose frame="">0.0 0.0 0.0 0 0 0</pose>
				<mass>0.883637094654053</mass>
				<inertia>
					<ixx>0.22490404911573442</ixx>
					<ixy>0.0</ixy>
					<ixz>-5.354650056688115e-18</ixz>
					<iyy>0.2250805999105956</iyy>
					<iyz>1.8964270946713667e-09</iyz>
					<izz>0.00019127807977205842</izz>
				</inertia>
			</inertial>
			<collision name="link2_collision">
				<geometry>
					<mesh>
						<uri>model://yatr/meshes/CAD/link2.stl</uri>
						<scale>0.001 0.001 0.001</scale>
					</mesh>
				</geometry>
			</collision>
			<visual name="link2_visual">
				<geometry>
					<mesh>
						<uri>model://yatr/meshes/CAD/link2.stl</uri>
						<scale>0.001 0.001 0.001</scale>
					</mesh>
				</geometry>
			</visual>
		</link>
		<joint name="joint0" type="revolute">
			<parent>base</parent>
			<child>link0</child>
			<pose frame="">0.0 -0.005 0.0 0 0 0</pose>
			<axis>
				<xyz>0.0 -1.0 0.0</xyz>
				<limit>
					<lower>-3.141592653589793</lower>
					<upper>0.0</upper>
				</limit>
				<use_parent_model_frame>0</use_parent_model_frame>
			</axis>
		</joint>
		<joint name="joint1" type="revolute">
			<parent>link0</parent>
			<child>link1</child>
			<pose frame="">-1.7556647654035476e-11 -0.0049999999999999975 0.19999773612988897 0 0 0</pose>
			<axis>
				<xyz>0.0 -0.9999999999999996 0.0</xyz>
				<limit>
					<lower>-6.283185307179586</lower>
					<upper>-3.141592653589793</upper>
				</limit>
				<use_parent_model_frame>0</use_parent_model_frame>
			</axis>
		</joint>
		<joint name="joint2" type="revolute">
			<parent>link1</parent>
			<child>link2</child>
			<pose frame="">-1.3013301767506253e-15 -0.004999999999999989 0.39999547225977766 0 0 0</pose>
			<axis>
				<xyz>0.0 -0.9999999999999984 0.0</xyz>
				<limit>
					<lower>0.0</lower>
					<upper>3.141592653589793</upper>
				</limit>
				<use_parent_model_frame>0</use_parent_model_frame>
			</axis>
		</joint>
		<plugin filename="libmusc_plugin.so" name="musc_plugin">
			<myoMuscle name="motor0">
				<link name="link0">
					<viaPoint type="FIXPOINT">-0.005 -0.15999818933418183 -0.02000000024599064</viaPoint>
				</link>
				<link name="link1">
					<viaPoint type="FIXPOINT">0.004999999999999992 -0.3599959254640705 0.020000000228432672</viaPoint>
				</link>
			</myoMuscle>
			<myoMuscle name="motor1">
				<link name="link0">
					<viaPoint type="FIXPOINT">-0.0049999999999999975 -0.15999275507580485 0.01999999901573027</viaPoint>
				</link>
				<link name="link1">
					<viaPoint type="FIXPOINT">0.00499999999999999 -0.35999049120569354 -0.019999999033288224</viaPoint>
				</link>
			</myoMuscle>
			<myoMuscle name="motor2">
				<link name="link1">
					<viaPoint type="FIXPOINT">0.005 -0.239995924172082 0.019998641663990076</viaPoint>
				</link>
				<link name="link2">
					<viaPoint type="FIXPOINT">-0.005000000000000015 -0.4399936603019709 -0.01999864168154813</viaPoint>
				</link>
			</myoMuscle>
			<myoMuscle name="motor3">
				<link name="link1">
					<viaPoint type="FIXPOINT">0.0049999999999999975 -0.23999048991370497 -0.020001357597730553</viaPoint>
				</link>
				<link name="link2">
					<viaPoint type="FIXPOINT">-0.005000000000000012 -0.4399882260435939 0.020001357580172713</viaPoint>
				</link>
			</myoMuscle>
			<myoMuscle name="motor4">
				<link name="link0">
					<viaPoint type="FIXPOINT">-0.005 -0.0399927537838163 0.020001357580174045</viaPoint>
				</link>
				<link name="link2">
					<viaPoint type="FIXPOINT">-0.005000000000000013 -0.5599936615939592 -0.020000000245992036</viaPoint>
				</link>
			</myoMuscle>
			<myoMuscle name="motor5">
				<link name="link0">
					<viaPoint type="FIXPOINT">-0.005000000000000003 -0.039998188042193294 -0.01999864168154687</viaPoint>
				</link>
				<link name="link2">
					<viaPoint type="FIXPOINT">-0.005000000000000011 -0.5599882273355823 0.019999999015728815</viaPoint>
				</link>
			</myoMuscle>
		</plugin>
	</model>
</sdf>
