<?xml version="1.0" ?>
<robot name="yatr">
  <joint name="joint0" type="revolute">
    <parent link="base"/>
    <child link="link0"/>
    <origin rpy="0 0 0" xyz="0    -0.005  0"/>
    <axis xyz="0 -1  0"/>
    <limit effort="0.0" lower="-3.14159265359" upper="0.0" velocity="0.0"/>
  </joint>
  <joint name="joint1" type="revolute">
    <parent link="link0"/>
    <child link="link1"/>
    <origin rpy="0 0 0" xyz="0      0      0.19999"/>
    <axis xyz="0 -1  0"/>
    <limit effort="0.0" lower="-6.28318530718" upper="-3.14159265359" velocity="0.0"/>
  </joint>
  <joint name="joint2" type="revolute">
    <parent link="link1"/>
    <child link="link2"/>
    <origin rpy="0 0 0" xyz="0      0      0.19999"/>
    <axis xyz="0 -1  0"/>
    <limit effort="0.0" lower="0.0" upper="3.14159265359" velocity="0.0"/>
  </joint>
  <link name="link0">
    <inertial>
      <mass value="0.8836370946540533"/>
      <origin rpy="0 0 0" xyz="0      0.005   0.09999"/>
      <inertia ixx="0.0128359314450565" ixy="-2.2311041902867146e-20" ixz="2.2311041902867146e-20" iyy="0.013012482239917657" iyz="-7.015541185751317e-11" izz="0.00019127807977205796"/>
    </inertial>
    <collision name="link0_collision">
      <origin rpy="0 0 0" xyz="0      0.005   0.09999"/>
      <geometry>
        <mesh filename="package://robots/yatr/meshes/CAD/link0.stl" scale="0.001 0.001 0.001"/>
      </geometry>
    </collision>
    <visual name="link0_visual">
      <origin rpy="0 0 0" xyz="0      0.005   0.09999"/>
      <geometry>
        <mesh filename="package://robots/yatr/meshes/CAD/link0.stl" scale="0.001 0.001 0.001"/>
      </geometry>
    </visual>
  </link>
  <link name="base">
    <inertial>
      <mass value="0.024661502330679867"/>
      <origin rpy="0 0 0" xyz="0    0.005 0"/>
      <inertia ixx="8.220500378772341e-07" ixy="8.715250743307479e-23" ixz="-9.670511946779926e-17" iyy="1.2330750369097686e-06" iyz="0.0" izz="8.220500378771992e-07"/>
    </inertial>
    <collision name="base_collision">
      <origin rpy="0 0 0" xyz="0    0.005 0"/>
      <geometry>
        <mesh filename="package://robots/yatr/meshes/CAD/base.stl" scale="0.001 0.001 0.001"/>
      </geometry>
    </collision>
    <visual name="base_visual">
      <origin rpy="0 0 0" xyz="0    0.005 0"/>
      <geometry>
        <mesh filename="package://robots/yatr/meshes/CAD/base.stl" scale="0.001 0.001 0.001"/>
      </geometry>
    </visual>
  </link>
  <link name="link1">
    <inertial>
      <mass value="0.8836370946540533"/>
      <origin rpy="0 0 0" xyz="0      -0.005    0.09999"/>
      <inertia ixx="0.08361367037501313" ixy="4.900996110954736e-11" ixz="0.002650881477140194" iyy="0.08370185746040888" iyz="-9.084812706589674e-10" izz="0.00027964178923746305"/>
    </inertial>
    <collision name="link1_collision">
      <origin rpy="0 0 0" xyz="0      -0.005    0.09999"/>
      <geometry>
        <mesh filename="package://robots/yatr/meshes/CAD/link1.stl" scale="0.001 0.001 0.001"/>
      </geometry>
    </collision>
    <visual name="link1_visual">
      <origin rpy="0 0 0" xyz="0      -0.005    0.09999"/>
      <geometry>
        <mesh filename="package://robots/yatr/meshes/CAD/link1.stl" scale="0.001 0.001 0.001"/>
      </geometry>
    </visual>
  </link>
  <link name="link2">
    <inertial>
      <mass value="0.8836370946540533"/>
      <origin rpy="0 0 0" xyz="0      0.005   0.09999"/>
      <inertia ixx="0.22490404911573442" ixy="0.0" ixz="-5.354650056688115e-18" iyy="0.2250805999105956" iyz="1.8964270946713667e-09" izz="0.00019127807977205842"/>
    </inertial>
    <collision name="link2_collision">
      <origin rpy="0 0 0" xyz="0      0.005   0.09999"/>
      <geometry>
        <mesh filename="package://robots/yatr/meshes/CAD/link2.stl" scale="0.001 0.001 0.001"/>
      </geometry>
    </collision>
    <visual name="link2_visual">
      <origin rpy="0 0 0" xyz="0      0.005   0.09999"/>
      <geometry>
        <mesh filename="package://robots/yatr/meshes/CAD/link2.stl" scale="0.001 0.001 0.001"/>
      </geometry>
    </visual>
  </link>
</robot>
