<?xml version="1.0" ?>
<robot name="roboy_xylophone">
  <joint name="left_wrist_0" type="revolute">
    <parent link="lower_arm_left"/>
    <child link="wrist_left_1"/>
    <origin rpy="0  0  0" xyz="-0.01441 -0.00671 -0.26206"/>
    <axis xyz="-0.99743 -0.06112  0.03722"/>
    <limit effort="0.0" lower="-0.523598775598" upper="0.523598775598" velocity="0.0"/>
  </joint>
  <joint name="left_wrist_1" type="revolute">
    <parent link="wrist_left_1"/>
    <child link="left_hand"/>
    <origin rpy="0  0  0" xyz="0.01155 -0.01682  0"/>
    <axis xyz="-0.06197  0.99783 -0.02217"/>
    <limit effort="0.0" lower="-0.523598775598" upper="0.523598775598" velocity="0.0"/>
  </joint>
  <joint name="sphere_left_axis0" type="revolute">
    <parent link="torso"/>
    <child link="sphere_left_link1"/>
    <origin rpy="0  0  0" xyz="0.29218  0.00921  0.54861"/>
    <axis xyz="0.99863  0.05074 -0.01234"/>
    <limit effort="0.0" lower="-3.14159265359" upper="3.14159265359" velocity="0.0"/>
  </joint>
  <joint name="sphere_left_axis1" type="revolute">
    <parent link="sphere_left_link1"/>
    <child link="sphere_left_link2"/>
    <origin rpy="0  0  0" xyz="0  0  0"/>
    <axis xyz="-0.05101  0.99844 -0.02231"/>
    <limit effort="0.0" lower="-3.14159265359" upper="3.14159265359" velocity="0.0"/>
  </joint>
  <joint name="sphere_left_axis2" type="revolute">
    <parent link="sphere_left_link2"/>
    <child link="upper_arm_left"/>
    <origin rpy="0  0  0" xyz="0  0  0"/>
    <axis xyz="-0.01118 -0.0229  -0.99967"/>
    <limit effort="0.0" lower="-3.14159265359" upper="3.14159265359" velocity="0.0"/>
  </joint>
  <joint name="elbow_left_rot1" type="revolute">
    <parent link="elbow_left"/>
    <child link="lower_arm_left"/>
    <origin rpy="0  0  0" xyz="-0.01877  0.00257 -0.06612"/>
    <axis xyz="-0.01118 -0.0229  -0.99967"/>
    <limit effort="0.0" lower="-1.57079632679" upper="1.57079632679" velocity="0.0"/>
  </joint>
  <joint name="elbow_left_rot0" type="revolute">
    <parent link="upper_arm_left"/>
    <child link="elbow_left"/>
    <origin rpy="0  0  0" xyz="0.01493 -0.01022 -0.26751"/>
    <axis xyz="-0.99863 -0.05074  0.01234"/>
    <limit effort="0.0" lower="0.0" upper="1.57079632679" velocity="0.0"/>
  </joint>
  <joint name="elbow_right_rot1" type="revolute">
    <parent link="elbow_right"/>
    <child link="lower_arm_right"/>
    <origin rpy="0  0  0" xyz="0.01877  0.00257 -0.06612"/>
    <axis xyz="-0.01118  0.0229   0.99967"/>
    <limit effort="0.0" lower="-1.57079632679" upper="1.57079632679" velocity="0.0"/>
  </joint>
  <joint name="sphere_right_axis0" type="revolute">
    <parent link="torso"/>
    <child link="sphere_right_link1"/>
    <origin rpy="0  0  0" xyz="-0.29218  0.00921  0.54861"/>
    <axis xyz="0.05101  0.99844 -0.02231"/>
    <limit effort="0.0" lower="-3.14159265359" upper="3.14159265359" velocity="0.0"/>
  </joint>
  <joint name="sphere_right_axis2" type="revolute">
    <parent link="sphere_right_link2"/>
    <child link="upper_arm_right"/>
    <origin rpy="0  0  0" xyz="0  0  0"/>
    <axis xyz="0.01118 -0.0229  -0.99967"/>
    <limit effort="0.0" lower="-3.14159265359" upper="3.14159265359" velocity="0.0"/>
  </joint>
  <joint name="sphere_right_axis1" type="revolute">
    <parent link="sphere_right_link1"/>
    <child link="sphere_right_link2"/>
    <origin rpy="0  0  0" xyz="0  0  0"/>
    <axis xyz="-0.99863  0.05074 -0.01234"/>
    <limit effort="0.0" lower="-3.14159265359" upper="3.14159265359" velocity="0.0"/>
  </joint>
  <joint name="elbow_right_rot0" type="revolute">
    <parent link="upper_arm_right"/>
    <child link="elbow_right"/>
    <origin rpy="0  0  0" xyz="-0.01492 -0.01024 -0.26851"/>
    <axis xyz="-0.99863  0.05074 -0.01234"/>
    <limit effort="0.0" lower="0.0" upper="1.57079632679" velocity="0.0"/>
  </joint>
  <joint name="right_wrist_0" type="revolute">
    <parent link="lower_arm_right"/>
    <child link="wrist_right_1"/>
    <origin rpy="0  0  0" xyz="0.01274 -0.00645 -0.26461"/>
    <axis xyz="0.9991  -0.04032 -0.01255"/>
    <limit effort="0.0" lower="-0.523598775598" upper="0.523598775598" velocity="0.0"/>
  </joint>
  <joint name="right_wrist_1" type="revolute">
    <parent link="wrist_right_1"/>
    <child link="right_hand"/>
    <origin rpy="0  0  0" xyz="-0.00979  0.0179  -0.00026"/>
    <axis xyz="0.04003  0.99894 -0.02244"/>
    <limit effort="0.0" lower="-0.523598775598" upper="0.523598775598" velocity="0.0"/>
  </joint>
  <joint name="zed_camera_mount" type="fixed">
    <parent link="head"/>
    <child link="zed_camera"/>
    <origin rpy="0  0  0" xyz="0.0215  -0.1026   0.20755"/>
    <axis xyz="0  0  0"/>
    <limit effort="0" lower="0" upper="0" velocity="0"/>
  </joint>
  <joint name="zed_camera_right" type="fixed">
    <parent link="zed_camera"/>
    <child link="zed_camera_right_lense"/>
    <origin rpy="0  0  0" xyz="-0.0815  0     -0.008"/>
    <axis xyz="0  0  0"/>
    <limit effort="0" lower="0" upper="0" velocity="0"/>
  </joint>
  <joint name="zed_camera_left" type="fixed">
    <parent link="zed_camera"/>
    <child link="zed_camera_left_lense"/>
    <origin rpy="0  0  0" xyz="0.03848  0      -0.008"/>
    <axis xyz="0  0  0"/>
    <limit effort="0" lower="0" upper="0" velocity="0"/>
  </joint>
  <joint name="sphere_head_axis0" type="revolute">
    <parent link="torso"/>
    <child link="sphere_head_link1"/>
    <origin rpy="0  0  0" xyz="0       0.00152  0.71109"/>
    <axis xyz="0 -1  0"/>
    <limit effort="0.0" lower="-0.523598775598" upper="0.523598775598" velocity="0.0"/>
  </joint>
  <joint name="sphere_head_axis2" type="revolute">
    <parent link="sphere_head_link2"/>
    <child link="head"/>
    <origin rpy="0  0  0" xyz="0  0  0"/>
    <axis xyz="0  0  1"/>
    <limit effort="0.0" lower="-0.523598775598" upper="0.523598775598" velocity="0.0"/>
  </joint>
  <joint name="sphere_head_axis1" type="revolute">
    <parent link="sphere_head_link1"/>
    <child link="sphere_head_link2"/>
    <origin rpy="0  0  0" xyz="0  0  0"/>
    <axis xyz="-1  0  0"/>
    <limit effort="0.0" lower="-0.523598775598" upper="0.523598775598" velocity="0.0"/>
  </joint>
  <link name="torso">
    <inertial>
      <mass value="13.72368407897035"/>
      <origin rpy="0  0  0" xyz="0  0  0"/>
      <inertia ixx="3.9107546591332416" ixy="-0.0010952263908086445" ixz="0.04330210411716705" iyy="4.168428239818963" iyz="-0.013228801413080223" izz="0.35244129847907524"/>
    </inertial>
    <collision name="torso_collision">
      <origin rpy="0  0  0" xyz="0  0  0"/>
      <geometry>
        <mesh filename="package://roboy_models/roboy_xylophone_left_arm/meshes/CAD/torso.stl OR roboy_models/roboy_xylophone/meshes/CAD/torso.stl OR roboy_models/roboy_xylophone_left_arm_mod1/meshes/CAD/torso.stl OR robots/roboy_xylophone/meshes/CAD/torso.stl" scale="0.001 0.001 0.001"/>
      </geometry>
    </collision>
    <visual name="torso_visual">
      <origin rpy="0  0  0" xyz="0  0  0"/>
      <geometry>
        <mesh filename="package://roboy_models/roboy_xylophone_left_arm/meshes/CAD/torso.stl OR roboy_models/roboy_xylophone/meshes/CAD/torso.stl OR roboy_models/roboy_xylophone_left_arm_mod1/meshes/CAD/torso.stl OR robots/roboy_xylophone/meshes/CAD/torso.stl" scale="0.001 0.001 0.001"/>
      </geometry>
    </visual>
  </link>
  <link name="right_hand">
    <inertial>
      <mass value="0.21252404217367002"/>
      <origin rpy="0  0  0" xyz="0.01278 -0.11323 -0.10121"/>
      <inertia ixx="0.010559071920739614" ixy="-0.005796169824888327" ixz="-0.004155602157837263" iyy="0.021099760318960162" iyz="-0.008785024822047877" izz="0.021099634806025287"/>
    </inertial>
    <collision name="right_hand_collision">
      <origin rpy="0  0  0" xyz="0.01278 -0.11323 -0.10121"/>
      <geometry>
        <mesh filename="package://robots/roboy_xylophone/meshes/CAD/right_hand.stl" scale="0.001 0.001 0.001"/>
      </geometry>
    </collision>
    <visual name="right_hand_visual">
      <origin rpy="0  0  0" xyz="0.01278 -0.11323 -0.10121"/>
      <geometry>
        <mesh filename="package://robots/roboy_xylophone/meshes/CAD/right_hand.stl" scale="0.001 0.001 0.001"/>
      </geometry>
    </visual>
  </link>
  <link name="left_hand">
    <inertial>
      <mass value="0.21252725802131714"/>
      <origin rpy="0  0  0" xyz="-0.01611 -0.07816 -0.10336"/>
      <inertia ixx="0.010477933741675032" ixy="0.005732875848548024" ixz="-0.004151697433279145" iyy="0.02064226532498634" iyz="0.008587946608863889" izz="0.020737226003257853"/>
    </inertial>
    <collision name="left_hand_collision">
      <origin rpy="0  0  0" xyz="-0.01611 -0.07816 -0.10336"/>
      <geometry>
        <mesh filename="package://robots/roboy_xylophone/meshes/CAD/left_hand.stl" scale="0.001 0.001 0.001"/>
      </geometry>
    </collision>
    <visual name="left_hand_visual">
      <origin rpy="0  0  0" xyz="-0.01611 -0.07816 -0.10336"/>
      <geometry>
        <mesh filename="package://robots/roboy_xylophone/meshes/CAD/left_hand.stl" scale="0.001 0.001 0.001"/>
      </geometry>
    </visual>
  </link>
  <link name="elbow_left">
    <inertial>
      <mass value="0.15681537170418472"/>
      <origin rpy="0  0  0" xyz="-0.01465  0.00368 -0.03741"/>
      <inertia ixx="0.009431698862560036" ixy="-0.00012517065329605505" ixz="-9.888407193471934e-05" iyy="0.02286554082855366" iyz="-0.011162091401140762" izz="0.013542050845884987"/>
    </inertial>
    <collision name="elbow_left_collision">
      <origin rpy="0  0  0" xyz="-0.01465  0.00368 -0.03741"/>
      <geometry>
        <mesh filename="package://robots/roboy_xylophone/meshes/CAD/elbow_left.stl" scale="0.001 0.001 0.001"/>
      </geometry>
    </collision>
    <visual name="elbow_left_visual">
      <origin rpy="0  0  0" xyz="-0.01465  0.00368 -0.03741"/>
      <geometry>
        <mesh filename="package://robots/roboy_xylophone/meshes/CAD/elbow_left.stl" scale="0.001 0.001 0.001"/>
      </geometry>
    </visual>
  </link>
  <link name="elbow_right">
    <inertial>
      <mass value="0.1737509895656351"/>
      <origin rpy="0  0  0" xyz="0.01505  0.00359 -0.03935"/>
      <inertia ixx="0.010199555394575916" ixy="0.00013260458236474714" ixz="-0.00010416566355679025" iyy="0.025041221467723144" iyz="0.012203629438521501" izz="0.014951862461248409"/>
    </inertial>
    <collision name="elbow_right_collision">
      <origin rpy="0  0  0" xyz="0.01505  0.00359 -0.03935"/>
      <geometry>
        <mesh filename="package://robots/roboy_xylophone/meshes/CAD/elbow_right.stl" scale="0.001 0.001 0.001"/>
      </geometry>
    </collision>
    <visual name="elbow_right_visual">
      <origin rpy="0  0  0" xyz="0.01505  0.00359 -0.03935"/>
      <geometry>
        <mesh filename="package://robots/roboy_xylophone/meshes/CAD/elbow_right.stl" scale="0.001 0.001 0.001"/>
      </geometry>
    </visual>
  </link>
  <link name="sphere_right_link1">
    <inertial>
      <mass value="0.04675596089362314"/>
      <origin rpy="0  0  0" xyz="0  0  0"/>
      <inertia ixx="0.014082448769507056" ixy="0.0001258220199864553" ixz="-0.00023625091114734805" iyy="0.01806999836888698" iyz="0.007494707505303508" izz="0.004001456143427335"/>
    </inertial>
    <collision name="sphere_right_link1_collision">
      <origin rpy="0  0  0" xyz="0  0  0"/>
      <geometry>
        <mesh filename="package://robots/roboy_xylophone/meshes/CAD/sphere_right_link1.stl" scale="0.001 0.001 0.001"/>
      </geometry>
    </collision>
    <visual name="sphere_right_link1_visual">
      <origin rpy="0  0  0" xyz="0  0  0"/>
      <geometry>
        <mesh filename="package://robots/roboy_xylophone/meshes/CAD/sphere_right_link1.stl" scale="0.001 0.001 0.001"/>
      </geometry>
    </visual>
  </link>
  <link name="sphere_right_link2">
    <inertial>
      <mass value="0.03133941577358247"/>
      <origin rpy="0  0  0" xyz="0  0  0"/>
      <inertia ixx="0.009437826715277597" ixy="8.43328831384499e-05" ixz="-0.0001583483241304999" iyy="0.012110590969874203" iyz="0.005023528861128496" izz="0.002680779380039669"/>
    </inertial>
    <collision name="sphere_right_link2_collision">
      <origin rpy="0  0  0" xyz="0  0  0"/>
      <geometry>
        <mesh filename="package://robots/roboy_xylophone/meshes/CAD/sphere_right_link2.stl" scale="0.001 0.001 0.001"/>
      </geometry>
    </collision>
    <visual name="sphere_right_link2_visual">
      <origin rpy="0  0  0" xyz="0  0  0"/>
      <geometry>
        <mesh filename="package://robots/roboy_xylophone/meshes/CAD/sphere_right_link2.stl" scale="0.001 0.001 0.001"/>
      </geometry>
    </visual>
  </link>
  <link name="sphere_left_link1">
    <inertial>
      <mass value="0.04675551932795345"/>
      <origin rpy="0  0  0" xyz="0  0  0"/>
      <inertia ixx="0.014082317102489413" ixy="-0.00012582086921548888" ixz="-0.0002362486921235582" iyy="0.018069831351724127" iyz="-0.007494639257681569" izz="0.004001420718449538"/>
    </inertial>
    <collision name="sphere_left_link1_collision">
      <origin rpy="0  0  0" xyz="0  0  0"/>
      <geometry>
        <mesh filename="package://robots/roboy_xylophone/meshes/CAD/sphere_left_link1.stl" scale="0.001 0.001 0.001"/>
      </geometry>
    </collision>
    <visual name="sphere_left_link1_visual">
      <origin rpy="0  0  0" xyz="0  0  0"/>
      <geometry>
        <mesh filename="package://robots/roboy_xylophone/meshes/CAD/sphere_left_link1.stl" scale="0.001 0.001 0.001"/>
      </geometry>
    </visual>
  </link>
  <link name="sphere_left_link2">
    <inertial>
      <mass value="0.03134020848172156"/>
      <origin rpy="0  0  0" xyz="0  0  0"/>
      <inertia ixx="0.00943806590033507" ixy="-8.433488846064251e-05" ixz="-0.00015835214886943715" iyy="0.01211089584076998" iyz="-0.005023654239591552" izz="0.002680845187770803"/>
    </inertial>
    <collision name="sphere_left_link2_collision">
      <origin rpy="0  0  0" xyz="0  0  0"/>
      <geometry>
        <mesh filename="package://robots/roboy_xylophone/meshes/CAD/sphere_left_link2.stl" scale="0.001 0.001 0.001"/>
      </geometry>
    </collision>
    <visual name="sphere_left_link2_visual">
      <origin rpy="0  0  0" xyz="0  0  0"/>
      <geometry>
        <mesh filename="package://robots/roboy_xylophone/meshes/CAD/sphere_left_link2.stl" scale="0.001 0.001 0.001"/>
      </geometry>
    </visual>
  </link>
  <link name="wrist_left_1">
    <inertial>
      <mass value="0.012764273069100239"/>
      <origin rpy="0  0  0" xyz="0.0099   0.00063  0.00106"/>
      <inertia ixx="2.993413449516953e-05" ixy="1.6313062661204826e-05" ixz="-2.6061840543168082e-06" iyy="0.0010588603851108488" iyz="0.00016684563210761069" izz="0.0010339769540120521"/>
    </inertial>
    <collision name="wrist_left_1_collision">
      <origin rpy="0  0  0" xyz="0.0099   0.00063  0.00106"/>
      <geometry>
        <mesh filename="package://robots/roboy_xylophone/meshes/CAD/wrist_left_1.stl" scale="0.001 0.001 0.001"/>
      </geometry>
    </collision>
    <visual name="wrist_left_1_visual">
      <origin rpy="0  0  0" xyz="0.0099   0.00063  0.00106"/>
      <geometry>
        <mesh filename="package://robots/roboy_xylophone/meshes/CAD/wrist_left_1.stl" scale="0.001 0.001 0.001"/>
      </geometry>
    </visual>
  </link>
  <link name="wrist_right_1">
    <inertial>
      <mass value="0.012762562533547076"/>
      <origin rpy="0  0  0" xyz="-0.01109  0.00048  0.00157"/>
      <inertia ixx="3.359777448488186e-05" ixy="-1.6206001652051455e-05" ixz="-2.7382864732840017e-06" iyy="0.0010832085862183094" iyz="-0.0001794755232555011" izz="0.001054639875188283"/>
    </inertial>
    <collision name="wrist_right_1_collision">
      <origin rpy="0  0  0" xyz="-0.01109  0.00048  0.00157"/>
      <geometry>
        <mesh filename="package://robots/roboy_xylophone/meshes/CAD/wrist_right_1.stl" scale="0.001 0.001 0.001"/>
      </geometry>
    </collision>
    <visual name="wrist_right_1_visual">
      <origin rpy="0  0  0" xyz="-0.01109  0.00048  0.00157"/>
      <geometry>
        <mesh filename="package://robots/roboy_xylophone/meshes/CAD/wrist_right_1.stl" scale="0.001 0.001 0.001"/>
      </geometry>
    </visual>
  </link>
  <link name="upper_arm_left">
    <inertial>
      <mass value="1.1809063299086702"/>
      <origin rpy="0  0  0" xyz="0.01098 -0.0026  -0.15154"/>
      <inertia ixx="0.19249833126625412" ixy="-0.002306334871592668" ixz="-0.0030893124346191994" iyy="0.29973127460686877" iyz="-0.14192218408420157" izz="0.11100085723502044"/>
    </inertial>
    <collision name="upper_arm_left_collision">
      <origin rpy="0  0  0" xyz="0.01098 -0.0026  -0.15154"/>
      <geometry>
        <mesh filename="package://roboy_models/roboy_xylophone_left_arm/meshes/CAD/upper_arm_left.stl OR roboy_models/roboy_xylophone/meshes/CAD/upper_arm_left.stl OR roboy_models/roboy_xylophone_left_arm_mod1/meshes/CAD/upper_arm_left.stl OR robots/roboy_xylophone/meshes/CAD/upper_arm_left.stl" scale="0.001 0.001 0.001"/>
      </geometry>
    </collision>
    <visual name="upper_arm_left_visual">
      <origin rpy="0  0  0" xyz="0.01098 -0.0026  -0.15154"/>
      <geometry>
        <mesh filename="package://roboy_models/roboy_xylophone_left_arm/meshes/CAD/upper_arm_left.stl OR roboy_models/roboy_xylophone/meshes/CAD/upper_arm_left.stl OR roboy_models/roboy_xylophone_left_arm_mod1/meshes/CAD/upper_arm_left.stl OR robots/roboy_xylophone/meshes/CAD/upper_arm_left.stl" scale="0.001 0.001 0.001"/>
      </geometry>
    </visual>
  </link>
  <link name="lower_arm_left">
    <inertial>
      <mass value="1.4159186820881702"/>
      <origin rpy="0  0  0" xyz="-0.00158 -0.00276 -0.12014"/>
      <inertia ixx="0.01972453759664721" ixy="0.0004870846174634047" ixz="3.185352964212202e-05" iyy="0.13615164739951632" iyz="-0.0385608557623002" izz="0.11772501099801319"/>
    </inertial>
    <collision name="lower_arm_left_collision">
      <origin rpy="0  0  0" xyz="-0.00158 -0.00276 -0.12014"/>
      <geometry>
        <mesh filename="package://roboy_models/roboy_xylophone_left_arm/meshes/CAD/lower_arm_left.stl OR roboy_models/roboy_xylophone/meshes/CAD/lower_arm_left.stl OR roboy_models/roboy_xylophone_left_arm_mod1/meshes/CAD/lower_arm_left.stl OR robots/roboy_xylophone/meshes/CAD/lower_arm_left.stl" scale="0.001 0.001 0.001"/>
      </geometry>
    </collision>
    <visual name="lower_arm_left_visual">
      <origin rpy="0  0  0" xyz="-0.00158 -0.00276 -0.12014"/>
      <geometry>
        <mesh filename="package://roboy_models/roboy_xylophone_left_arm/meshes/CAD/lower_arm_left.stl OR roboy_models/roboy_xylophone/meshes/CAD/lower_arm_left.stl OR roboy_models/roboy_xylophone_left_arm_mod1/meshes/CAD/lower_arm_left.stl OR robots/roboy_xylophone/meshes/CAD/lower_arm_left.stl" scale="0.001 0.001 0.001"/>
      </geometry>
    </visual>
  </link>
  <link name="lower_arm_right">
    <inertial>
      <mass value="1.3992272098398937"/>
      <origin rpy="0  0  0" xyz="0.00143 -0.00283 -0.12369"/>
      <inertia ixx="0.018109663582786668" ixy="-0.0005191321679580465" ixz="4.004976923881273e-05" iyy="0.1332810801368647" iyz="0.03631075913323457" izz="0.11646776713622453"/>
    </inertial>
    <collision name="lower_arm_right_collision">
      <origin rpy="0  0  0" xyz="0.00143 -0.00283 -0.12369"/>
      <geometry>
        <mesh filename="package://robots/roboy_xylophone/meshes/CAD/lower_arm_right.stl" scale="0.001 0.001 0.001"/>
      </geometry>
    </collision>
    <visual name="lower_arm_right_visual">
      <origin rpy="0  0  0" xyz="0.00143 -0.00283 -0.12369"/>
      <geometry>
        <mesh filename="package://robots/roboy_xylophone/meshes/CAD/lower_arm_right.stl" scale="0.001 0.001 0.001"/>
      </geometry>
    </visual>
  </link>
  <link name="upper_arm_right">
    <inertial>
      <mass value="1.0958327493598587"/>
      <origin rpy="0  0  0" xyz="-0.01036 -0.00496 -0.15098"/>
      <inertia ixx="0.17904183127745843" ixy="0.0013739028297231812" ixz="-0.0018802459141019135" iyy="0.27814445786523145" iyz="0.13162874177792994" izz="0.10257941183247427"/>
    </inertial>
    <collision name="upper_arm_right_collision">
      <origin rpy="0  0  0" xyz="-0.01036 -0.00496 -0.15098"/>
      <geometry>
        <mesh filename="package://robots/roboy_xylophone/meshes/CAD/upper_arm_right.stl" scale="0.001 0.001 0.001"/>
      </geometry>
    </collision>
    <visual name="upper_arm_right_visual">
      <origin rpy="0  0  0" xyz="-0.01036 -0.00496 -0.15098"/>
      <geometry>
        <mesh filename="package://robots/roboy_xylophone/meshes/CAD/upper_arm_right.stl" scale="0.001 0.001 0.001"/>
      </geometry>
    </visual>
  </link>
  <link name="zed_camera_left_lense">
    <inertial>
      <mass value="0.0057554218156879965"/>
      <origin rpy="0  0  0" xyz="1.00000000e-05   1.93400000e-02   4.22100000e-02"/>
      <inertia ixx="0.004846003994033088" ixy="3.881518938735634e-05" ixz="0.0005891022505389009" iyy="0.004793823223689041" iyz="-0.0003144804806087313" izz="9.383240644717274e-05"/>
    </inertial>
    <collision name="zed_camera_left_lense_collision">
      <origin rpy="0  0  0" xyz="1.00000000e-05   1.93400000e-02   4.22100000e-02"/>
      <geometry>
        <mesh filename="package://robots/roboy_xylophone/meshes/CAD/zed_camera_left_lense.stl" scale="0.001 0.001 0.001"/>
      </geometry>
    </collision>
    <visual name="zed_camera_left_lense_visual">
      <origin rpy="0  0  0" xyz="1.00000000e-05   1.93400000e-02   4.22100000e-02"/>
      <geometry>
        <mesh filename="package://robots/roboy_xylophone/meshes/CAD/zed_camera_left_lense.stl" scale="0.001 0.001 0.001"/>
      </geometry>
    </visual>
  </link>
  <link name="zed_camera_right_lense">
    <inertial>
      <mass value="0.0057554218156880485"/>
      <origin rpy="0  0  0" xyz="0       0.01934  0.04221"/>
      <inertia ixx="0.004846003993869442" ixy="-3.881429332761528e-05" ixz="0.0005891022505287467" iyy="0.004793822275803509" iyz="0.00031447328687670046" izz="9.383145872528843e-05"/>
    </inertial>
    <collision name="zed_camera_right_lense_collision">
      <origin rpy="0  0  0" xyz="0       0.01934  0.04221"/>
      <geometry>
        <mesh filename="package://robots/roboy_xylophone/meshes/CAD/zed_camera_right_lense.stl" scale="0.001 0.001 0.001"/>
      </geometry>
    </collision>
    <visual name="zed_camera_right_lense_visual">
      <origin rpy="0  0  0" xyz="0       0.01934  0.04221"/>
      <geometry>
        <mesh filename="package://robots/roboy_xylophone/meshes/CAD/zed_camera_right_lense.stl" scale="0.001 0.001 0.001"/>
      </geometry>
    </visual>
  </link>
  <link name="zed_camera">
    <inertial>
      <mass value="0.009633908092012306"/>
      <origin rpy="0  0  0" xyz="-0.0215   0.04477  0.0288"/>
      <inertia ixx="0.008084577088634314" ixy="4.052560334214884e-06" ixz="0.0008835525556697587" iyy="0.008001669367456716" iyz="-3.558753230110404e-05" izz="0.00011263547643344076"/>
    </inertial>
    <collision name="zed_camera_collision">
      <origin rpy="0  0  0" xyz="-0.0215   0.04477  0.0288"/>
      <geometry>
        <mesh filename="package://robots/roboy_xylophone/meshes/CAD/zed_camera.stl" scale="0.001 0.001 0.001"/>
      </geometry>
    </collision>
    <visual name="zed_camera_visual">
      <origin rpy="0  0  0" xyz="-0.0215   0.04477  0.0288"/>
      <geometry>
        <mesh filename="package://robots/roboy_xylophone/meshes/CAD/zed_camera.stl" scale="0.001 0.001 0.001"/>
      </geometry>
    </visual>
  </link>
  <link name="sphere_head_link1">
    <inertial>
      <mass value="0.023938100802369737"/>
      <origin rpy="0  0  0" xyz="0  0  0"/>
      <inertia ixx="0.012106569631450062" ixy="7.493571735350812e-19" ixz="-2.5904276728695797e-05" iyy="0.012106514195173217" iyz="3.5035169210217987e-16" izz="2.012994235293793e-06"/>
    </inertial>
    <collision name="sphere_head_link1_collision">
      <origin rpy="0  0  0" xyz="0  0  0"/>
      <geometry>
        <mesh filename="package://robots/roboy_xylophone/meshes/CAD/sphere_head_link1.stl" scale="0.001 0.001 0.001"/>
      </geometry>
    </collision>
    <visual name="sphere_head_link1_visual">
      <origin rpy="0  0  0" xyz="0  0  0"/>
      <geometry>
        <mesh filename="package://robots/roboy_xylophone/meshes/CAD/sphere_head_link1.stl" scale="0.001 0.001 0.001"/>
      </geometry>
    </visual>
  </link>
  <link name="sphere_head_link2">
    <inertial>
      <mass value="0.016046417516495697"/>
      <origin rpy="0  0  0" xyz="0  0  0"/>
      <inertia ixx="0.008114964048845503" ixy="5.02587338066518e-19" ixz="-1.736440343714945e-05" iyy="0.008114926888268263" iyz="2.3476776078723563e-16" izz="9.214497104106378e-07"/>
    </inertial>
    <collision name="sphere_head_link2_collision">
      <origin rpy="0  0  0" xyz="0  0  0"/>
      <geometry>
        <mesh filename="package://robots/roboy_xylophone/meshes/CAD/sphere_head_link2.stl" scale="0.001 0.001 0.001"/>
      </geometry>
    </collision>
    <visual name="sphere_head_link2_visual">
      <origin rpy="0  0  0" xyz="0  0  0"/>
      <geometry>
        <mesh filename="package://robots/roboy_xylophone/meshes/CAD/sphere_head_link2.stl" scale="0.001 0.001 0.001"/>
      </geometry>
    </visual>
  </link>
  <link name="head">
    <inertial>
      <mass value="2.0664381552877806"/>
      <origin rpy="0  0  0" xyz="0.00064  0.01352  0.15538"/>
      <inertia ixx="1.584602072446883" ixy="-2.8828445995492527e-05" ixz="-0.029442678579422673" iyy="1.57889377620563" iyz="-0.0012884336458265217" izz="0.025550832000821585"/>
    </inertial>
    <collision name="head_collision">
      <origin rpy="0  0  0" xyz="0.00064  0.01352  0.15538"/>
      <geometry>
        <mesh filename="package://robots/roboy_xylophone/meshes/CAD/head.stl" scale="0.001 0.001 0.001"/>
      </geometry>
    </collision>
    <visual name="head_visual">
      <origin rpy="0  0  0" xyz="0.00064  0.01352  0.15538"/>
      <geometry>
        <mesh filename="package://robots/roboy_xylophone/meshes/CAD/head.stl" scale="0.001 0.001 0.001"/>
      </geometry>
    </visual>
  </link>
</robot>
