<?xml version="1.0" ?>
<sdf version="1.6">
	<model name="roboy_xylophone">
		<link name="torso">
			<self_collide>false</self_collide>
			<pose frame="">0.0 0.0 0.0 0.0 -0.0 0.0</pose>
			<inertial>
				<pose frame="">0.0 0.0 0.0 0 0 0</pose>
				<mass>13.723684078915307</mass>
				<inertia>
					<ixx>3.910765453374194</ixx>
					<ixy>-0.0010952247971131627</ixy>
					<ixz>0.04330215463386242</ixz>
					<iyy>4.168439034043003</iyy>
					<iyz>-0.013228815176824244</iyz>
					<izz>0.35244129850162914</izz>
				</inertia>
			</inertial>
			<collision name="torso_collision">
				<geometry>
					<mesh>
						<uri>model://roboy_xylophone/meshes/CAD/torso.stl</uri>
						<scale>0.001 0.001 0.001</scale>
					</mesh>
				</geometry>
			</collision>
			<visual name="torso_visual">
				<geometry>
					<mesh>
						<uri>model://roboy_xylophone/meshes/CAD/torso.stl</uri>
						<scale>0.001 0.001 0.001</scale>
					</mesh>
				</geometry>
			</visual>
		</link>
		<link name="right_hand">
			<self_collide>false</self_collide>
			<pose frame="">0.2697594900165811 -0.006792324262862302 -0.1314462184560031 0.0 -0.0 0.0</pose>
			<inertial>
				<pose frame="">0.0 0.0 0.0 0 0 0</pose>
				<mass>0.21252404217775137</mass>
				<inertia>
					<ixx>0.010559022552571623</ixx>
					<ixy>-0.0057961698249285685</ixy>
					<ixz>-0.004155585891089943</ixz>
					<iyy>0.021099710950629093</iyy>
					<iyz>-0.008784980587098938</iyz>
					<izz>0.021099634805862383</izz>
				</inertia>
			</inertial>
			<collision name="right_hand_collision">
				<geometry>
					<mesh>
						<uri>model://roboy_xylophone/meshes/CAD/right_hand.stl</uri>
						<scale>0.001 0.001 0.001</scale>
					</mesh>
				</geometry>
			</collision>
			<visual name="right_hand_visual">
				<geometry>
					<mesh>
						<uri>model://roboy_xylophone/meshes/CAD/right_hand.stl</uri>
						<scale>0.001 0.001 0.001</scale>
					</mesh>
				</geometry>
			</visual>
		</link>
		<link name="left_hand">
			<self_collide>false</self_collide>
			<pose frame="">0.2697594900165811 -0.006792324262862302 -0.1314462184560031 0.0 -0.0 0.0</pose>
			<inertial>
				<pose frame="">0.0 0.0 0.0 0 0 0</pose>
				<mass>0.21252725801946043</mass>
				<inertia>
					<ixx>0.01047788491144677</ixx>
					<ixy>0.00573287584850848</ixy>
					<ixz>-0.004151681182266932</ixz>
					<iyy>0.020642216495308573</iyy>
					<iyz>0.00858790289787774</iyz>
					<izz>0.0207372260038187</izz>
				</inertia>
			</inertial>
			<collision name="left_hand_collision">
				<geometry>
					<mesh>
						<uri>model://roboy_xylophone/meshes/CAD/left_hand.stl</uri>
						<scale>0.001 0.001 0.001</scale>
					</mesh>
				</geometry>
			</collision>
			<visual name="left_hand_visual">
				<geometry>
					<mesh>
						<uri>model://roboy_xylophone/meshes/CAD/left_hand.stl</uri>
						<scale>0.001 0.001 0.001</scale>
					</mesh>
				</geometry>
			</visual>
		</link>
		<link name="elbow_left">
			<self_collide>false</self_collide>
			<pose frame="">0.2924609988878633 0.0026742978127772166 0.243685199783117 0.0 -0.0 0.0</pose>
			<inertial>
				<pose frame="">0.0 0.0 0.0 0 0 0</pose>
				<mass>0.15681537170757617</mass>
				<inertia>
					<ixx>0.009431757217366237</ixx>
					<ixy>-0.00012517065329440102</ixy>
					<ixz>-9.888439213856398e-05</ixz>
					<iyy>0.022865599183320432</iyy>
					<iyz>-0.011162126418704265</iyz>
					<izz>0.013542050845845421</izz>
				</inertia>
			</inertial>
			<collision name="elbow_left_collision">
				<geometry>
					<mesh>
						<uri>model://roboy_xylophone/meshes/CAD/elbow_left.stl</uri>
						<scale>0.001 0.001 0.001</scale>
					</mesh>
				</geometry>
			</collision>
			<visual name="elbow_left_visual">
				<geometry>
					<mesh>
						<uri>model://roboy_xylophone/meshes/CAD/elbow_left.stl</uri>
						<scale>0.001 0.001 0.001</scale>
					</mesh>
				</geometry>
			</visual>
		</link>
		<link name="elbow_right">
			<self_collide>false</self_collide>
			<pose frame="">-0.2920543656172187 0.0025621368659477423 0.24074497758680108 0.0 -0.0 0.0</pose>
			<inertial>
				<pose frame="">0.0 0.0 0.0 0 0 0</pose>
				<mass>0.17375098956720564</mass>
				<inertia>
					<ixx>0.01019961927086434</ixx>
					<ixy>0.00013260458239467034</ixy>
					<ixz>-0.00010416600348480155</ixz>
					<iyy>0.02504128534266076</iyy>
					<iyz>0.012203668183089615</iyz>
					<izz>0.014951862459897956</izz>
				</inertia>
			</inertial>
			<collision name="elbow_right_collision">
				<geometry>
					<mesh>
						<uri>model://roboy_xylophone/meshes/CAD/elbow_right.stl</uri>
						<scale>0.001 0.001 0.001</scale>
					</mesh>
				</geometry>
			</collision>
			<visual name="elbow_right_visual">
				<geometry>
					<mesh>
						<uri>model://roboy_xylophone/meshes/CAD/elbow_right.stl</uri>
						<scale>0.001 0.001 0.001</scale>
					</mesh>
				</geometry>
			</visual>
		</link>
		<link name="sphere_right_link1">
			<self_collide>false</self_collide>
			<pose frame="">-0.2921799666276168 0.009210203783611738 0.548615244082417 0.0 -0.0 0.0</pose>
			<inertial>
				<pose frame="">0.0 0.0 0.0 0 0 0</pose>
				<mass>0.046755960893623175</mass>
				<inertia>
					<ixx>0.014082487940467327</ixx>
					<ixy>0.0001258220199864557</ixy>
					<ixz>-0.00023625123995044117</ixz>
					<iyy>0.01807003753984725</iyy>
					<iyz>0.0074947179360907975</iyz>
					<izz>0.004001456143427335</izz>
				</inertia>
			</inertial>
			<collision name="sphere_right_link1_collision">
				<geometry>
					<mesh>
						<uri>model://roboy_xylophone/meshes/CAD/sphere_right_link1.stl</uri>
						<scale>0.001 0.001 0.001</scale>
					</mesh>
				</geometry>
			</collision>
			<visual name="sphere_right_link1_visual">
				<geometry>
					<mesh>
						<uri>model://roboy_xylophone/meshes/CAD/sphere_right_link1.stl</uri>
						<scale>0.001 0.001 0.001</scale>
					</mesh>
				</geometry>
			</visual>
		</link>
		<link name="sphere_right_link2">
			<self_collide>false</self_collide>
			<pose frame="">-0.2921801724945091 0.009209908408672508 0.5486152414548352 0.0 -0.0 0.0</pose>
			<inertial>
				<pose frame="">0.0 0.0 0.0 0 0 0</pose>
				<mass>0.03133941577358246</mass>
				<inertia>
					<ixx>0.009437852970646556</ixx>
					<ixy>8.433288313845014e-05</ixy>
					<ixz>-0.0001583485445123758</ixz>
					<iyy>0.012110617225243162</iyy>
					<iyz>0.005023535852643668</iyz>
					<izz>0.002680779380039669</izz>
				</inertia>
			</inertial>
			<collision name="sphere_right_link2_collision">
				<geometry>
					<mesh>
						<uri>model://roboy_xylophone/meshes/CAD/sphere_right_link2.stl</uri>
						<scale>0.001 0.001 0.001</scale>
					</mesh>
				</geometry>
			</collision>
			<visual name="sphere_right_link2_visual">
				<geometry>
					<mesh>
						<uri>model://roboy_xylophone/meshes/CAD/sphere_right_link2.stl</uri>
						<scale>0.001 0.001 0.001</scale>
					</mesh>
				</geometry>
			</visual>
		</link>
		<link name="sphere_left_link1">
			<self_collide>false</self_collide>
			<pose frame="">0.29218005222734156 0.009210203825021938 0.5486152687569047 0.0 -0.0 0.0</pose>
			<inertial>
				<pose frame="">0.0 0.0 0.0 0 0 0</pose>
				<mass>0.04675551932795345</mass>
				<inertia>
					<ixx>0.014082356273081548</ixx>
					<ixy>-0.00012582086921548958</ixy>
					<ixz>-0.00023624902092354817</ixz>
					<iyy>0.01806987052231626</iyy>
					<iyz>-0.00749464968837342</iyz>
					<izz>0.004001420718449545</izz>
				</inertia>
			</inertial>
			<collision name="sphere_left_link1_collision">
				<geometry>
					<mesh>
						<uri>model://roboy_xylophone/meshes/CAD/sphere_left_link1.stl</uri>
						<scale>0.001 0.001 0.001</scale>
					</mesh>
				</geometry>
			</collision>
			<visual name="sphere_left_link1_visual">
				<geometry>
					<mesh>
						<uri>model://roboy_xylophone/meshes/CAD/sphere_left_link1.stl</uri>
						<scale>0.001 0.001 0.001</scale>
					</mesh>
				</geometry>
			</visual>
		</link>
		<link name="sphere_left_link2">
			<self_collide>false</self_collide>
			<pose frame="">0.2921800660285928 0.009209897632250984 0.5486152570091472 0.0 -0.0 0.0</pose>
			<inertial>
				<pose frame="">0.0 0.0 0.0 0 0 0</pose>
				<mass>0.031340208481721574</mass>
				<inertia>
					<ixx>0.009438092156368896</ixx>
					<ixy>-8.433488846064293e-05</ixy>
					<ixz>-0.00015835236925662997</ixz>
					<iyy>0.012110922096803804</iyy>
					<iyz>-0.005023661231281029</iyz>
					<izz>0.0026808451877708057</izz>
				</inertia>
			</inertial>
			<collision name="sphere_left_link2_collision">
				<geometry>
					<mesh>
						<uri>model://roboy_xylophone/meshes/CAD/sphere_left_link2.stl</uri>
						<scale>0.001 0.001 0.001</scale>
					</mesh>
				</geometry>
			</collision>
			<visual name="sphere_left_link2_visual">
				<geometry>
					<mesh>
						<uri>model://roboy_xylophone/meshes/CAD/sphere_left_link2.stl</uri>
						<scale>0.001 0.001 0.001</scale>
					</mesh>
				</geometry>
			</visual>
		</link>
		<link name="wrist_left_1">
			<self_collide>false</self_collide>
			<pose frame="">0.2838291081215929 -0.004517829187733993 -0.0460263795467499 0.0 -0.0 0.0</pose>
			<inertial>
				<pose frame="">0.0 0.0 0.0 0 0 0</pose>
				<mass>0.012764273069100246</mass>
				<inertia>
					<ixx>2.9933237342887354e-05</ixx>
					<ixy>1.6313062661204246e-05</ixy>
					<ixz>-2.60614002361967e-06</ixz>
					<iyy>0.001058859487958565</iyy>
					<iyz>0.00016684286591328332</iyz>
					<izz>0.0010339769540120504</izz>
				</inertia>
			</inertial>
			<collision name="wrist_left_1_collision">
				<geometry>
					<mesh>
						<uri>model://roboy_xylophone/meshes/CAD/wrist_left_1.stl</uri>
						<scale>0.001 0.001 0.001</scale>
					</mesh>
				</geometry>
			</collision>
			<visual name="wrist_left_1_visual">
				<geometry>
					<mesh>
						<uri>model://roboy_xylophone/meshes/CAD/wrist_left_1.stl</uri>
						<scale>0.001 0.001 0.001</scale>
					</mesh>
				</geometry>
			</visual>
		</link>
		<link name="wrist_right_1">
			<self_collide>false</self_collide>
			<pose frame="">-0.2866867429541466 -0.004439510879921008 -0.04905987848597987 0.0 -0.0 0.0</pose>
			<inertial>
				<pose frame="">0.0 0.0 0.0 0 0 0</pose>
				<mass>0.012762562533547097</mass>
				<inertia>
					<ixx>3.3596818331877835e-05</ixx>
					<ixy>-1.6206001652051634e-05</ixy>
					<ixz>-2.7382432116743297e-06</ixz>
					<iyy>0.0010832076300652943</iyy>
					<iyz>-0.00017947272958513367</iyz>
					<izz>0.001054639875188272</izz>
				</inertia>
			</inertial>
			<collision name="wrist_right_1_collision">
				<geometry>
					<mesh>
						<uri>model://roboy_xylophone/meshes/CAD/wrist_right_1.stl</uri>
						<scale>0.001 0.001 0.001</scale>
					</mesh>
				</geometry>
			</collision>
			<visual name="wrist_right_1_visual">
				<geometry>
					<mesh>
						<uri>model://roboy_xylophone/meshes/CAD/wrist_right_1.stl</uri>
						<scale>0.001 0.001 0.001</scale>
					</mesh>
				</geometry>
			</visual>
		</link>
		<link name="upper_arm_left">
			<self_collide>false</self_collide>
			<pose frame="">0.3031614980118545 0.006609366620463159 0.3970754157042758 0.0 -0.0 0.0</pose>
			<inertial>
				<pose frame="">0.0 0.0 0.0 0 0 0</pose>
				<mass>1.1809063299122724</mass>
				<inertia>
					<ixx>0.19249904732344378</ixx>
					<ixy>-0.002306334871591317</ixy>
					<ixz>-0.0030893183940510194</ixz>
					<iyy>0.29973199066407874</iyy>
					<iyz>-0.1419224574342764</iyz>
					<izz>0.1110008572350409</izz>
				</inertia>
			</inertial>
			<collision name="upper_arm_left_collision">
				<geometry>
					<mesh>
						<uri>model://roboy_xylophone/meshes/CAD/upper_arm_left.stl</uri>
						<scale>0.001 0.001 0.001</scale>
					</mesh>
				</geometry>
			</collision>
			<visual name="upper_arm_left_visual">
				<geometry>
					<mesh>
						<uri>model://roboy_xylophone/meshes/CAD/upper_arm_left.stl</uri>
						<scale>0.001 0.001 0.001</scale>
					</mesh>
				</geometry>
			</visual>
		</link>
		<link name="lower_arm_left">
			<self_collide>false</self_collide>
			<pose frame="">0.2867576752988603 -0.0012029774645435035 0.09482915225116281 0.0 -0.0 0.0</pose>
			<inertial>
				<pose frame="">0.0 0.0 0.0 0 0 0</pose>
				<mass>1.41591868208817</mass>
				<inertia>
					<ixx>0.01972474263641184</ixx>
					<ixy>0.000487084617463389</ixy>
					<ixz>3.185483018737706e-05</ixz>
					<iyy>0.1361518524392809</iyy>
					<iyz>-0.03856116577753053</iyz>
					<izz>0.11772501099801312</izz>
				</inertia>
			</inertial>
			<collision name="lower_arm_left_collision">
				<geometry>
					<mesh>
						<uri>model://roboy_xylophone/meshes/CAD/lower_arm_left.stl</uri>
						<scale>0.001 0.001 0.001</scale>
					</mesh>
				</geometry>
			</collision>
			<visual name="lower_arm_left_visual">
				<geometry>
					<mesh>
						<uri>model://roboy_xylophone/meshes/CAD/lower_arm_left.stl</uri>
						<scale>0.001 0.001 0.001</scale>
					</mesh>
				</geometry>
			</visual>
		</link>
		<link name="lower_arm_right">
			<self_collide>false</self_collide>
			<pose frame="">-0.28690316197811633 -0.0012971012985662463 0.09028215193184677 0.0 -0.0 0.0</pose>
			<inertial>
				<pose frame="">0.0 0.0 0.0 0 0 0</pose>
				<mass>1.3992272098398937</mass>
				<inertia>
					<ixx>0.018109856489779336</ixx>
					<ixy>-0.000519132167958026</ixy>
					<ixz>4.0051155010875704e-05</ixz>
					<iyy>0.1332812730438574</iyy>
					<iyz>0.036311065649301234</iyz>
					<izz>0.11646776713622453</izz>
				</inertia>
			</inertial>
			<collision name="lower_arm_right_collision">
				<geometry>
					<mesh>
						<uri>model://roboy_xylophone/meshes/CAD/lower_arm_right.stl</uri>
						<scale>0.001 0.001 0.001</scale>
					</mesh>
				</geometry>
			</collision>
			<visual name="lower_arm_right_visual">
				<geometry>
					<mesh>
						<uri>model://roboy_xylophone/meshes/CAD/lower_arm_right.stl</uri>
						<scale>0.001 0.001 0.001</scale>
					</mesh>
				</geometry>
			</visual>
		</link>
		<link name="upper_arm_right">
			<self_collide>false</self_collide>
			<pose frame="">-0.3025447305327413 0.0042424198844845315 0.39763297257341446 0.0 -0.0 0.0</pose>
			<inertial>
				<pose frame="">0.0 0.0 0.0 0 0 0</pose>
				<mass>1.0958327493598465</mass>
				<inertia>
					<ixx>0.17904249668221814</ixx>
					<ixy>0.001373902829722357</ixy>
					<ixz>-0.0018802494637678855</ixz>
					<iyy>0.27814512326998064</iyy>
					<iyz>0.1316289949195273</iyz>
					<izz>0.1025794118324634</izz>
				</inertia>
			</inertial>
			<collision name="upper_arm_right_collision">
				<geometry>
					<mesh>
						<uri>model://roboy_xylophone/meshes/CAD/upper_arm_right.stl</uri>
						<scale>0.001 0.001 0.001</scale>
					</mesh>
				</geometry>
			</collision>
			<visual name="upper_arm_right_visual">
				<geometry>
					<mesh>
						<uri>model://roboy_xylophone/meshes/CAD/upper_arm_right.stl</uri>
						<scale>0.001 0.001 0.001</scale>
					</mesh>
				</geometry>
			</visual>
		</link>
		<link name="zed_camera_left_lense">
			<self_collide>false</self_collide>
			<pose frame="">0.05999964724565572 -0.08173913560527492 0.9528625747224352 0.0 -0.0 0.0</pose>
			<inertial>
				<pose frame="">0.0 0.0 0.0 0 0 0</pose>
				<mass>0.0057554218156879965</mass>
				<inertia>
					<ixx>0.004846011997714692</ixx>
					<ixy>3.881518938735634e-05</ixy>
					<ixz>0.0005891027444713397</ixz>
					<iyy>0.004793831227370645</iyy>
					<iyz>-0.000314480744284707</iyz>
					<izz>9.383240644717274e-05</izz>
				</inertia>
			</inertial>
			<collision name="zed_camera_left_lense_collision">
				<geometry>
					<mesh>
						<uri>model://roboy_xylophone/meshes/CAD/zed_camera_left_lense.stl</uri>
						<scale>0.001 0.001 0.001</scale>
					</mesh>
				</geometry>
			</collision>
			<visual name="zed_camera_left_lense_visual">
				<geometry>
					<mesh>
						<uri>model://roboy_xylophone/meshes/CAD/zed_camera_left_lense.stl</uri>
						<scale>0.001 0.001 0.001</scale>
					</mesh>
				</geometry>
			</visual>
		</link>
		<link name="zed_camera_right_lense">
			<self_collide>false</self_collide>
			<pose frame="">-0.06000035275434433 -0.08173913560527538 0.9528625747224347 0.0 -0.0 0.0</pose>
			<inertial>
				<pose frame="">0.0 0.0 0.0 0 0 0</pose>
				<mass>0.0057554218156880485</mass>
				<inertia>
					<ixx>0.004846011997551049</ixx>
					<ixy>-3.881429332761528e-05</ixy>
					<ixz>0.0005891027444611853</ixz>
					<iyy>0.004793830279485115</iyy>
					<iyz>0.00031447355054664474</iyz>
					<izz>9.383145872528843e-05</izz>
				</inertia>
			</inertial>
			<collision name="zed_camera_right_lense_collision">
				<geometry>
					<mesh>
						<uri>model://roboy_xylophone/meshes/CAD/zed_camera_right_lense.stl</uri>
						<scale>0.001 0.001 0.001</scale>
					</mesh>
				</geometry>
			</collision>
			<visual name="zed_camera_right_lense_visual">
				<geometry>
					<mesh>
						<uri>model://roboy_xylophone/meshes/CAD/zed_camera_right_lense.stl</uri>
						<scale>0.001 0.001 0.001</scale>
					</mesh>
				</geometry>
			</visual>
		</link>
		<link name="zed_camera">
			<self_collide>false</self_collide>
			<pose frame="">-3.51796944748628e-07 -0.05630729805909612 0.9474568704182059 0.0 -0.0 0.0</pose>
			<inertial>
				<pose frame="">0.0 0.0 0.0 0 0 0</pose>
				<mass>0.009633908092012306</mass>
				<inertia>
					<ixx>0.008084590483556824</ixx>
					<ixy>4.052560334214878e-06</ixy>
					<ixz>0.0008835532966109025</ixz>
					<iyy>0.008001682762379227</iyy>
					<iyz>-3.558756214861936e-05</iyz>
					<izz>0.00011263547643344076</izz>
				</inertia>
			</inertial>
			<collision name="zed_camera_collision">
				<geometry>
					<mesh>
						<uri>model://roboy_xylophone/meshes/CAD/zed_camera.stl</uri>
						<scale>0.001 0.001 0.001</scale>
					</mesh>
				</geometry>
			</collision>
			<visual name="zed_camera_visual">
				<geometry>
					<mesh>
						<uri>model://roboy_xylophone/meshes/CAD/zed_camera.stl</uri>
						<scale>0.001 0.001 0.001</scale>
					</mesh>
				</geometry>
			</visual>
		</link>
		<link name="sphere_head_link1">
			<self_collide>false</self_collide>
			<pose frame="">-2.0591149070298685e-14 0.0015217810850767161 0.7110989936345878 0.0 -0.0 0.0</pose>
			<inertial>
				<pose frame="">0.0 0.0 0.0 0 0 0</pose>
				<mass>0.023938100802369734</mass>
				<inertia>
					<ixx>0.012106595625813408</ixx>
					<ixy>7.508425305113864e-19</ixy>
					<ixz>-2.5904304543214497e-05</ixz>
					<iyy>0.012106540189536562</iyy>
					<iyz>3.5051683777709287e-16</iyz>
					<izz>2.012994235293797e-06</izz>
				</inertia>
			</inertial>
			<collision name="sphere_head_link1_collision">
				<geometry>
					<mesh>
						<uri>model://roboy_xylophone/meshes/CAD/sphere_head_link1.stl</uri>
						<scale>0.001 0.001 0.001</scale>
					</mesh>
				</geometry>
			</collision>
			<visual name="sphere_head_link1_visual">
				<geometry>
					<mesh>
						<uri>model://roboy_xylophone/meshes/CAD/sphere_head_link1.stl</uri>
						<scale>0.001 0.001 0.001</scale>
					</mesh>
				</geometry>
			</visual>
		</link>
		<link name="shere_head_link2">
			<self_collide>false</self_collide>
			<pose frame="">-2.0576940733084e-14 0.0015217810850767244 0.7110989936345874 0.0 -0.0 0.0</pose>
			<inertial>
				<pose frame="">0.0 0.0 0.0 0 0 0</pose>
				<mass>0.016046417516495697</mass>
				<inertia>
					<ixx>0.008114981473636667</ixx>
					<ixy>5.029288617508509e-19</ixy>
					<ixz>-1.7364422082044675e-05</ixz>
					<iyy>0.008114944313059425</iyy>
					<iyz>2.347552707782086e-16</iyz>
					<izz>9.214497104106406e-07</izz>
				</inertia>
			</inertial>
			<collision name="shere_head_link2_collision">
				<geometry>
					<mesh>
						<uri>model://roboy_xylophone/meshes/CAD/shere_head_link2.stl</uri>
						<scale>0.001 0.001 0.001</scale>
					</mesh>
				</geometry>
			</collision>
			<visual name="shere_head_link2_visual">
				<geometry>
					<mesh>
						<uri>model://roboy_xylophone/meshes/CAD/shere_head_link2.stl</uri>
						<scale>0.001 0.001 0.001</scale>
					</mesh>
				</geometry>
			</visual>
		</link>
		<link name="head">
			<self_collide>false</self_collide>
			<pose frame="">0.0006492376358659671 0.015046110821376588 0.8664862621002404 0.0 -0.0 0.0</pose>
			<inertial>
				<pose frame="">0.0 0.0 0.0 0 0 0</pose>
				<mass>2.066438155287772</mass>
				<inertia>
					<ixx>1.584604806730509</ixx>
					<ixy>-2.8828445995227988e-05</ixy>
					<ixz>-0.029442702319178716</ixz>
					<iyy>1.5788965104892563</iyy>
					<iyz>-0.0012884346701906664</iyz>
					<izz>0.025550832000819076</izz>
				</inertia>
			</inertial>
			<collision name="head_collision">
				<geometry>
					<mesh>
						<uri>model://roboy_xylophone/meshes/CAD/head.stl</uri>
						<scale>0.001 0.001 0.001</scale>
					</mesh>
				</geometry>
			</collision>
			<visual name="head_visual">
				<geometry>
					<mesh>
						<uri>model://roboy_xylophone/meshes/CAD/head.stl</uri>
						<scale>0.001 0.001 0.001</scale>
					</mesh>
				</geometry>
			</visual>
		</link>
		<link name="base">
			<self_collide>false</self_collide>
			<pose frame="">0.0 0.0 0.0 0.0 -0.0 0.0</pose>
			<inertial>
				<pose frame="">0.0 0.0 0.0 0 0 0</pose>
				<mass>0.8375538014504047</mass>
				<inertia>
					<ixx>0.004947439478836188</ixx>
					<ixy>1.8900910193672462e-05</ixy>
					<ixz>1.8376373411173705e-05</ixz>
					<iyy>0.0130208829910244</iyy>
					<iyz>7.086050217485074e-06</iyz>
					<izz>0.012613089761592724</izz>
				</inertia>
			</inertial>
			<collision name="base_collision">
				<geometry>
					<mesh>
						<uri>model://roboy_xylophone/meshes/CAD/base.stl</uri>
						<scale>0.001 0.001 0.001</scale>
					</mesh>
				</geometry>
			</collision>
			<visual name="base_visual">
				<geometry>
					<mesh>
						<uri>model://roboy_xylophone/meshes/CAD/base.stl</uri>
						<scale>0.001 0.001 0.001</scale>
					</mesh>
				</geometry>
			</visual>
		</link>
		<joint name="sphere_right_axis0" type="revolute">
			<parent>torso</parent>
			<child>sphere_right_link1</child>
			<pose frame="">-8.958507578427089e-08 -1.6805291933041921e-07 -1.2962123818738291e-08 0 0 0</pose>
			<axis>
				<xyz>0.05101049431667341 0.998448888302569 -0.022310242422112804</xyz>
				<limit>
					<lower>-3.141592653589793</lower>
					<upper>3.141592653589793</upper>
				</limit>
				<use_parent_model_frame>0</use_parent_model_frame>
			</axis>
		</joint>
		<joint name="sphere_right_axis2" type="revolute">
			<parent>sphere_right_link2</parent>
			<child>upper_arm_right</child>
			<pose frame="">0.010364674320048835 0.004967615846207849 0.1509822585468786 0 0 0</pose>
			<axis>
				<xyz>0.011188426489535866 -0.022909252225335328 -0.9996749398055187</xyz>
				<limit>
					<lower>-3.141592653589793</lower>
					<upper>3.141592653589793</upper>
				</limit>
				<use_parent_model_frame>0</use_parent_model_frame>
			</axis>
		</joint>
		<joint name="sphere_right_axis1" type="revolute">
			<parent>sphere_right_link1</parent>
			<child>sphere_right_link2</child>
			<pose frame="">1.1628181660228165e-07 1.2732201988607807e-07 -1.033454232413078e-08 0 0 0</pose>
			<axis>
				<xyz>-0.9986354432836146 0.050744296328166766 -0.012339684270771867</xyz>
				<limit>
					<lower>-3.141592653589793</lower>
					<upper>3.141592653589793</upper>
				</limit>
				<use_parent_model_frame>0</use_parent_model_frame>
			</axis>
		</joint>
		<joint name="left_wrist_0" type="revolute">
			<parent>lower_arm_left</parent>
			<child>wrist_left_1</child>
			<pose frame="">-0.009900625387205118 -0.0006389576348572506 -0.0010673226779253132 0 0 0</pose>
			<axis>
				<xyz>-0.9974356911086111 -0.06112686075287341 0.037222963304743374</xyz>
				<limit>
					<lower>-0.5235987755982988</lower>
					<upper>0.5235987755982988</upper>
				</limit>
				<use_parent_model_frame>0</use_parent_model_frame>
			</axis>
		</joint>
		<joint name="left_wrist_1" type="revolute">
			<parent>wrist_left_1</parent>
			<child>left_hand</child>
			<pose frame="">0.015726692712065785 -0.015184675598829038 0.08434970839173359 0 0 0</pose>
			<axis>
				<xyz>-0.06197857490501217 0.9978311478764739 -0.022173330382833693</xyz>
				<limit>
					<lower>-0.5235987755982988</lower>
					<upper>0.5235987755982988</upper>
				</limit>
				<use_parent_model_frame>0</use_parent_model_frame>
			</axis>
		</joint>
		<joint name="zed_camera_right" type="fixed">
			<parent>zed_camera</parent>
			<child>zed_camera_right_lense</child>
			<pose frame="">-1.1119993814645568e-14 -0.019342045553250423 -0.04220906861921591 0 0 0</pose>
		</joint>
		<joint name="zed_camera_left" type="fixed">
			<parent>zed_camera</parent>
			<child>zed_camera_left_lense</child>
			<pose frame="">-1.7810504181934308e-05 -0.01934204555325101 -0.04220906875296009 0 0 0</pose>
		</joint>
		<joint name="zed_camera_mount" type="fixed">
			<parent>head</parent>
			<child>zed_camera</child>
			<pose frame="">0.02149999999998915 -0.04477388309942952 -0.028803364797665838 0 0 0</pose>
		</joint>
		<joint name="sphere_left_axis0" type="revolute">
			<parent>torso</parent>
			<child>sphere_left_link1</child>
			<pose frame="">3.9283446540139265e-09 -1.6697847606939043e-07 -3.766154485163043e-08 0 0 0</pose>
			<axis>
				<xyz>0.9986354432836129 0.05074429632816833 -0.012339684270770038</xyz>
				<limit>
					<lower>-3.141592653589793</lower>
					<upper>3.141592653589793</upper>
				</limit>
				<use_parent_model_frame>0</use_parent_model_frame>
			</axis>
		</joint>
		<joint name="sphere_left_axis1" type="revolute">
			<parent>sphere_left_link1</parent>
			<child>sphere_left_link2</child>
			<pose frame="">-9.872906687746764e-09 1.3921429486973835e-07 -2.5913787311537816e-08 0 0 0</pose>
			<axis>
				<xyz>-0.05101049431667493 0.9984488883025682 -0.022310242422112825</xyz>
				<limit>
					<lower>-3.141592653589793</lower>
					<upper>3.141592653589793</upper>
				</limit>
				<use_parent_model_frame>0</use_parent_model_frame>
			</axis>
		</joint>
		<joint name="sphere_left_axis2" type="revolute">
			<parent>sphere_left_link2</parent>
			<child>upper_arm_left</child>
			<pose frame="">-0.01098144179915991 0.002600669110229097 0.1515398154160176 0 0 0</pose>
			<axis>
				<xyz>-0.01118842648953418 -0.022909252225335505 -0.9996749398055222</xyz>
				<limit>
					<lower>-3.141592653589793</lower>
					<upper>3.141592653589793</upper>
				</limit>
				<use_parent_model_frame>0</use_parent_model_frame>
			</axis>
		</joint>
		<joint name="elbow_left_rot1" type="revolute">
			<parent>elbow_left</parent>
			<child>lower_arm_left</child>
			<pose frame="">0.0015883800233882184 0.0027619758351277875 0.12014580167753083 0 0 0</pose>
			<axis>
				<xyz>-0.011188426489533955 -0.022909252225335637 -0.9996749398055156</xyz>
				<limit>
					<lower>-1.5707963267948966</lower>
					<upper>1.5707963267948966</upper>
				</limit>
				<use_parent_model_frame>0</use_parent_model_frame>
			</axis>
		</joint>
		<joint name="elbow_left_rot0" type="revolute">
			<parent>upper_arm_left</parent>
			<child>elbow_left</child>
			<pose frame="">0.01465705305134879 -0.003686557449135954 0.03741012373978347 0 0 0</pose>
			<axis>
				<xyz>-0.9986354432836098 -0.05074429632816577 0.012339684270769044</xyz>
				<limit>
					<lower>0.0</lower>
					<upper>1.5707963267948966</upper>
				</limit>
				<use_parent_model_frame>0</use_parent_model_frame>
			</axis>
		</joint>
		<joint name="hip_joint" type="revolute">
			<parent>base</parent>
			<child>torso</child>
			<pose frame="">6.8199713028958765e-19 0.001521781085074027 0.10423789166998208 0 0 0</pose>
			<axis>
				<xyz>-9.863650210179225e-31 5.148659276699155e-15 -1.0000000000000002</xyz>
				<limit>
					<lower>-0.17453292519943295</lower>
					<upper>0.17453292519943295</upper>
				</limit>
				<use_parent_model_frame>0</use_parent_model_frame>
			</axis>
		</joint>
		<joint name="elbow_right_rot1" type="revolute">
			<parent>elbow_right</parent>
			<child>lower_arm_right</child>
			<pose frame="">-0.0014317049176433016 0.0028331904169268964 0.1236931270570428 0 0 0</pose>
			<axis>
				<xyz>-0.01118842648953284 0.022909252225335578 0.999674939805517</xyz>
				<limit>
					<lower>-1.5707963267948966</lower>
					<upper>1.5707963267948966</upper>
				</limit>
				<use_parent_model_frame>0</use_parent_model_frame>
			</axis>
		</joint>
		<joint name="right_wrist_0" type="revolute">
			<parent>lower_arm_right</parent>
			<child>wrist_right_1</child>
			<pose frame="">0.011094392792996715 -0.00048043688755373905 -0.0015766831427710582 0 0 0</pose>
			<axis>
				<xyz>0.9991077747968851 -0.04032476901588534 -0.012552583169695498</xyz>
				<limit>
					<lower>-0.5235987755982988</lower>
					<upper>0.5235987755982988</upper>
				</limit>
				<use_parent_model_frame>0</use_parent_model_frame>
			</axis>
		</joint>
		<joint name="right_wrist_1" type="revolute">
			<parent>wrist_right_1</parent>
			<child>right_hand</child>
			<pose frame="">-0.5551418373190008 0.019777343614169544 0.08054868087193331 0 0 0</pose>
			<axis>
				<xyz>0.040036256805536984 0.9989461168065814 -0.022444461634320585</xyz>
				<limit>
					<lower>-0.5235987755982988</lower>
					<upper>0.5235987755982988</upper>
				</limit>
				<use_parent_model_frame>0</use_parent_model_frame>
			</axis>
		</joint>
		<joint name="elbow_right_rot0" type="revolute">
			<parent>upper_arm_right</parent>
			<child>elbow_right</child>
			<pose frame="">-0.015052497895504367 -0.0035973057545301518 0.039350670996294676 0 0 0</pose>
			<axis>
				<xyz>-0.9986354432836139 0.050744296328165295 -0.012339684270768765</xyz>
				<limit>
					<lower>0.0</lower>
					<upper>1.5707963267948966</upper>
				</limit>
				<use_parent_model_frame>0</use_parent_model_frame>
			</axis>
		</joint>
		<joint name="sphere_head_axis0" type="revolute">
			<parent>torso</parent>
			<child>sphere_head_link1</child>
			<pose frame="">-3.0802094775900282e-18 -3.608224830031759e-18 -1.4210854715202004e-16 0 0 0</pose>
			<axis>
				<xyz>2.506675422786485e-16 -1.0000000000000004 8.242631900833768e-15</xyz>
				<limit>
					<lower>-0.5235987755982988</lower>
					<upper>0.5235987755982988</upper>
				</limit>
				<use_parent_model_frame>0</use_parent_model_frame>
			</axis>
		</joint>
		<joint name="sphere_head_axis2" type="revolute">
			<parent>shere_head_link2</parent>
			<child>head</child>
			<pose frame="">-0.0006492376358865611 -0.013524329736299884 -0.15538726846565296 0 0 0</pose>
			<axis>
				<xyz>-2.4131887955448744e-14 8.24263190083376e-15 1.0</xyz>
				<limit>
					<lower>-0.5235987755982988</lower>
					<upper>0.5235987755982988</upper>
				</limit>
				<use_parent_model_frame>0</use_parent_model_frame>
			</axis>
		</joint>
		<joint name="sphere_head_axis1" type="revolute">
			<parent>sphere_head_link1</parent>
			<child>shere_head_link2</child>
			<pose frame="">-1.7288546692289503e-17 -1.27675647831893e-17 2.842170943040401e-16 0 0 0</pose>
			<axis>
				<xyz>-1.0000000000000004 -2.506675422788488e-16 -2.413188795544875e-14</xyz>
				<limit>
					<lower>-0.5235987755982988</lower>
					<upper>0.5235987755982988</upper>
				</limit>
				<use_parent_model_frame>0</use_parent_model_frame>
			</axis>
		</joint>
	</model>
</sdf>
