<?xml version="1.0" ?>
<sdf version="1.6">
	<model name="roboy_xylophone">
		<link name="torso">
			<self_collide>false</self_collide>
			<pose frame="">0.0 0.0 0.0 0.0 -0.0 0.0</pose>
			<inertial>
				<pose frame="">0.0 0.0 0.0 0 0 0</pose>
				<mass>13.72368407897035</mass>
				<inertia>
					<ixx>3.9107546591332416</ixx>
					<ixy>-0.0010952263908086445</ixy>
					<ixz>0.04330210411716705</ixz>
					<iyy>4.168428239818963</iyy>
					<iyz>-0.013228801413080223</iyz>
					<izz>0.35244129847907524</izz>
				</inertia>
			</inertial>
			<collision name="torso_collision">
				<geometry>
					<mesh>
						<uri>model://roboy_xylophone/meshes/CAD/torso.stl</uri>
						<scale>0.001 0.001 0.001</scale>
					</mesh>
				</geometry>
			</collision>
			<visual name="torso_visual">
				<geometry>
					<mesh>
						<uri>model://roboy_xylophone/meshes/CAD/torso.stl</uri>
						<scale>0.001 0.001 0.001</scale>
					</mesh>
				</geometry>
			</visual>
		</link>
		<link name="right_hand">
			<self_collide>false</self_collide>
			<pose frame="">-0.2726006967706916 -0.10024518398036296 -0.15211778521664104 0.0 -0.0 0.0</pose>
			<inertial>
				<pose frame="">0.0 0.0 0.0 0 0 0</pose>
				<mass>0.21252404217367002</mass>
				<inertia>
					<ixx>0.010559071920739614</ixx>
					<ixy>-0.005796169824888327</ixy>
					<ixz>-0.004155602157837263</ixz>
					<iyy>0.021099760318960162</iyy>
					<iyz>-0.008785024822047877</iyz>
					<izz>0.021099634806025287</izz>
				</inertia>
			</inertial>
			<collision name="right_hand_collision">
				<geometry>
					<mesh>
						<uri>model://roboy_xylophone/meshes/CAD/right_hand.stl</uri>
						<scale>0.001 0.001 0.001</scale>
					</mesh>
				</geometry>
			</collision>
			<visual name="right_hand_visual">
				<geometry>
					<mesh>
						<uri>model://roboy_xylophone/meshes/CAD/right_hand.stl</uri>
						<scale>0.001 0.001 0.001</scale>
					</mesh>
				</geometry>
			</visual>
		</link>
		<link name="left_hand">
			<self_collide>false</self_collide>
			<pose frame="">0.2693698565379346 -0.10014645572149362 -0.15045851695284457 0.0 -0.0 0.0</pose>
			<inertial>
				<pose frame="">0.0 0.0 0.0 0 0 0</pose>
				<mass>0.21252725802131714</mass>
				<inertia>
					<ixx>0.010477933741675032</ixx>
					<ixy>0.005732875848548024</ixy>
					<ixz>-0.004151697433279145</ixz>
					<iyy>0.02064226532498634</iyy>
					<iyz>0.008587946608863889</iyz>
					<izz>0.020737226003257853</izz>
				</inertia>
			</inertial>
			<collision name="left_hand_collision">
				<geometry>
					<mesh>
						<uri>model://roboy_xylophone/meshes/CAD/left_hand.stl</uri>
						<scale>0.001 0.001 0.001</scale>
					</mesh>
				</geometry>
			</collision>
			<visual name="left_hand_visual">
				<geometry>
					<mesh>
						<uri>model://roboy_xylophone/meshes/CAD/left_hand.stl</uri>
						<scale>0.001 0.001 0.001</scale>
					</mesh>
				</geometry>
			</visual>
		</link>
		<link name="elbow_left">
			<self_collide>false</self_collide>
			<pose frame="">0.2924609988893645 0.002674297812459018 0.2436844362458517 0.0 -0.0 0.0</pose>
			<inertial>
				<pose frame="">0.0 0.0 0.0 0 0 0</pose>
				<mass>0.15681537170418472</mass>
				<inertia>
					<ixx>0.009431698862560036</ixx>
					<ixy>-0.00012517065329605505</ixy>
					<ixz>-9.888407193471934e-05</ixz>
					<iyy>0.02286554082855366</iyy>
					<iyz>-0.011162091401140762</iyz>
					<izz>0.013542050845884987</izz>
				</inertia>
			</inertial>
			<collision name="elbow_left_collision">
				<geometry>
					<mesh>
						<uri>model://roboy_xylophone/meshes/CAD/elbow_left.stl</uri>
						<scale>0.001 0.001 0.001</scale>
					</mesh>
				</geometry>
			</collision>
			<visual name="elbow_left_visual">
				<geometry>
					<mesh>
						<uri>model://roboy_xylophone/meshes/CAD/elbow_left.stl</uri>
						<scale>0.001 0.001 0.001</scale>
					</mesh>
				</geometry>
			</visual>
		</link>
		<link name="elbow_right">
			<self_collide>false</self_collide>
			<pose frame="">-0.29205436561441206 0.0025621368665047525 0.24074421405226445 0.0 -0.0 0.0</pose>
			<inertial>
				<pose frame="">0.0 0.0 0.0 0 0 0</pose>
				<mass>0.1737509895656351</mass>
				<inertia>
					<ixx>0.010199555394575916</ixx>
					<ixy>0.00013260458236474714</ixy>
					<ixz>-0.00010416566355679025</ixz>
					<iyy>0.025041221467723144</iyy>
					<iyz>0.012203629438521501</iyz>
					<izz>0.014951862461248409</izz>
				</inertia>
			</inertial>
			<collision name="elbow_right_collision">
				<geometry>
					<mesh>
						<uri>model://roboy_xylophone/meshes/CAD/elbow_right.stl</uri>
						<scale>0.001 0.001 0.001</scale>
					</mesh>
				</geometry>
			</collision>
			<visual name="elbow_right_visual">
				<geometry>
					<mesh>
						<uri>model://roboy_xylophone/meshes/CAD/elbow_right.stl</uri>
						<scale>0.001 0.001 0.001</scale>
					</mesh>
				</geometry>
			</visual>
		</link>
		<link name="sphere_right_link1">
			<self_collide>false</self_collide>
			<pose frame="">-0.2921799666276168 0.009210203783611712 0.5486144805461556 0.0 -0.0 0.0</pose>
			<inertial>
				<pose frame="">0.0 0.0 0.0 0 0 0</pose>
				<mass>0.04675596089362314</mass>
				<inertia>
					<ixx>0.014082448769507056</ixx>
					<ixy>0.0001258220199864553</ixy>
					<ixz>-0.00023625091114734805</ixz>
					<iyy>0.01806999836888698</iyy>
					<iyz>0.007494707505303508</iyz>
					<izz>0.004001456143427335</izz>
				</inertia>
			</inertial>
			<collision name="sphere_right_link1_collision">
				<geometry>
					<mesh>
						<uri>model://roboy_xylophone/meshes/CAD/sphere_right_link1.stl</uri>
						<scale>0.001 0.001 0.001</scale>
					</mesh>
				</geometry>
			</collision>
			<visual name="sphere_right_link1_visual">
				<geometry>
					<mesh>
						<uri>model://roboy_xylophone/meshes/CAD/sphere_right_link1.stl</uri>
						<scale>0.001 0.001 0.001</scale>
					</mesh>
				</geometry>
			</visual>
		</link>
		<link name="sphere_right_link2">
			<self_collide>false</self_collide>
			<pose frame="">-0.2921801724945091 0.009209908408672482 0.5486144779185737 0.0 -0.0 0.0</pose>
			<inertial>
				<pose frame="">0.0 0.0 0.0 0 0 0</pose>
				<mass>0.03133941577358247</mass>
				<inertia>
					<ixx>0.009437826715277597</ixx>
					<ixy>8.43328831384499e-05</ixy>
					<ixz>-0.0001583483241304999</ixz>
					<iyy>0.012110590969874203</iyy>
					<iyz>0.005023528861128496</iyz>
					<izz>0.002680779380039669</izz>
				</inertia>
			</inertial>
			<collision name="sphere_right_link2_collision">
				<geometry>
					<mesh>
						<uri>model://roboy_xylophone/meshes/CAD/sphere_right_link2.stl</uri>
						<scale>0.001 0.001 0.001</scale>
					</mesh>
				</geometry>
			</collision>
			<visual name="sphere_right_link2_visual">
				<geometry>
					<mesh>
						<uri>model://roboy_xylophone/meshes/CAD/sphere_right_link2.stl</uri>
						<scale>0.001 0.001 0.001</scale>
					</mesh>
				</geometry>
			</visual>
		</link>
		<link name="sphere_left_link1">
			<self_collide>false</self_collide>
			<pose frame="">0.29218005222734156 0.009210203825021905 0.5486145052206429 0.0 -0.0 0.0</pose>
			<inertial>
				<pose frame="">0.0 0.0 0.0 0 0 0</pose>
				<mass>0.04675551932795345</mass>
				<inertia>
					<ixx>0.014082317102489413</ixx>
					<ixy>-0.00012582086921548888</ixy>
					<ixz>-0.0002362486921235582</ixz>
					<iyy>0.018069831351724127</iyy>
					<iyz>-0.007494639257681569</iyz>
					<izz>0.004001420718449538</izz>
				</inertia>
			</inertial>
			<collision name="sphere_left_link1_collision">
				<geometry>
					<mesh>
						<uri>model://roboy_xylophone/meshes/CAD/sphere_left_link1.stl</uri>
						<scale>0.001 0.001 0.001</scale>
					</mesh>
				</geometry>
			</collision>
			<visual name="sphere_left_link1_visual">
				<geometry>
					<mesh>
						<uri>model://roboy_xylophone/meshes/CAD/sphere_left_link1.stl</uri>
						<scale>0.001 0.001 0.001</scale>
					</mesh>
				</geometry>
			</visual>
		</link>
		<link name="sphere_left_link2">
			<self_collide>false</self_collide>
			<pose frame="">0.29218006602859287 0.009209897632250946 0.5486144934728855 0.0 -0.0 0.0</pose>
			<inertial>
				<pose frame="">0.0 0.0 0.0 0 0 0</pose>
				<mass>0.03134020848172156</mass>
				<inertia>
					<ixx>0.00943806590033507</ixx>
					<ixy>-8.433488846064251e-05</ixy>
					<ixz>-0.00015835214886943715</ixz>
					<iyy>0.01211089584076998</iyy>
					<iyz>-0.005023654239591552</iyz>
					<izz>0.002680845187770803</izz>
				</inertia>
			</inertial>
			<collision name="sphere_left_link2_collision">
				<geometry>
					<mesh>
						<uri>model://roboy_xylophone/meshes/CAD/sphere_left_link2.stl</uri>
						<scale>0.001 0.001 0.001</scale>
					</mesh>
				</geometry>
			</collision>
			<visual name="sphere_left_link2_visual">
				<geometry>
					<mesh>
						<uri>model://roboy_xylophone/meshes/CAD/sphere_left_link2.stl</uri>
						<scale>0.001 0.001 0.001</scale>
					</mesh>
				</geometry>
			</visual>
		</link>
		<link name="left_ring_limb0">
			<self_collide>false</self_collide>
			<pose frame="">0.2803577238006067 0.012332314369452533 -0.14556469260486563 0.0 -0.0 0.0</pose>
			<inertial>
				<pose frame="">0.0 0.0 0.0 0 0 0</pose>
				<mass>0.00042699873719355484</mass>
				<inertia>
					<ixx>9.120242551499906e-06</ixx>
					<ixy>-1.4761134565218337e-06</ixy>
					<ixz>7.659111214427992e-07</ixz>
					<iyy>4.261536011971524e-05</iyy>
					<iyz>1.7425521328413886e-05</iyz>
					<izz>3.363486114605222e-05</izz>
				</inertia>
			</inertial>
			<collision name="left_ring_limb0_collision">
				<geometry>
					<mesh>
						<uri>model://roboy_xylophone/meshes/CAD/left_ring_limb0.stl</uri>
						<scale>0.001 0.001 0.001</scale>
					</mesh>
				</geometry>
			</collision>
			<visual name="left_ring_limb0_visual">
				<geometry>
					<mesh>
						<uri>model://roboy_xylophone/meshes/CAD/left_ring_limb0.stl</uri>
						<scale>0.001 0.001 0.001</scale>
					</mesh>
				</geometry>
			</visual>
		</link>
		<link name="left_little_limb0">
			<self_collide>false</self_collide>
			<pose frame="">0.27994336876615206 0.027296783159214015 -0.1312906744461279 0.0 -0.0 0.0</pose>
			<inertial>
				<pose frame="">0.0 0.0 0.0 0 0 0</pose>
				<mass>0.000427003127688874</mass>
				<inertia>
					<ixx>7.686181650061806e-06</ixx>
					<ixy>-3.2626844917209604e-06</ixy>
					<ixz>1.5292278115436921e-06</ixz>
					<iyy>4.082965360232849e-05</iyy>
					<iyz>1.5693721506371443e-05</iyz>
					<izz>3.3788793366054075e-05</izz>
				</inertia>
			</inertial>
			<collision name="left_little_limb0_collision">
				<geometry>
					<mesh>
						<uri>model://roboy_xylophone/meshes/CAD/left_little_limb0.stl</uri>
						<scale>0.001 0.001 0.001</scale>
					</mesh>
				</geometry>
			</collision>
			<visual name="left_little_limb0_visual">
				<geometry>
					<mesh>
						<uri>model://roboy_xylophone/meshes/CAD/left_little_limb0.stl</uri>
						<scale>0.001 0.001 0.001</scale>
					</mesh>
				</geometry>
			</visual>
		</link>
		<link name="wrist_left_1">
			<self_collide>false</self_collide>
			<pose frame="">0.2838291081215929 -0.004517829187734139 -0.04602714308301151 0.0 -0.0 0.0</pose>
			<inertial>
				<pose frame="">0.0 0.0 0.0 0 0 0</pose>
				<mass>0.012764273069100239</mass>
				<inertia>
					<ixx>2.993413449516953e-05</ixx>
					<ixy>1.6313062661204826e-05</ixy>
					<ixz>-2.6061840543168082e-06</ixz>
					<iyy>0.0010588603851108488</iyy>
					<iyz>0.00016684563210761069</iyz>
					<izz>0.0010339769540120521</izz>
				</inertia>
			</inertial>
			<collision name="wrist_left_1_collision">
				<geometry>
					<mesh>
						<uri>model://roboy_xylophone/meshes/CAD/wrist_left_1.stl</uri>
						<scale>0.001 0.001 0.001</scale>
					</mesh>
				</geometry>
			</collision>
			<visual name="wrist_left_1_visual">
				<geometry>
					<mesh>
						<uri>model://roboy_xylophone/meshes/CAD/wrist_left_1.stl</uri>
						<scale>0.001 0.001 0.001</scale>
					</mesh>
				</geometry>
			</visual>
		</link>
		<link name="wrist_right_1">
			<self_collide>false</self_collide>
			<pose frame="">-0.2866867429541464 -0.00443951087992092 -0.049060642022241474 0.0 -0.0 0.0</pose>
			<inertial>
				<pose frame="">0.0 0.0 0.0 0 0 0</pose>
				<mass>0.012762562533547076</mass>
				<inertia>
					<ixx>3.359777448488186e-05</ixx>
					<ixy>-1.6206001652051455e-05</ixy>
					<ixz>-2.7382864732840017e-06</ixz>
					<iyy>0.0010832085862183094</iyy>
					<iyz>-0.0001794755232555011</iyz>
					<izz>0.001054639875188283</izz>
				</inertia>
			</inertial>
			<collision name="wrist_right_1_collision">
				<geometry>
					<mesh>
						<uri>model://roboy_xylophone/meshes/CAD/wrist_right_1.stl</uri>
						<scale>0.001 0.001 0.001</scale>
					</mesh>
				</geometry>
			</collision>
			<visual name="wrist_right_1_visual">
				<geometry>
					<mesh>
						<uri>model://roboy_xylophone/meshes/CAD/wrist_right_1.stl</uri>
						<scale>0.001 0.001 0.001</scale>
					</mesh>
				</geometry>
			</visual>
		</link>
		<link name="upper_arm_left">
			<self_collide>false</self_collide>
			<pose frame="">0.30316149801185627 0.006609366620460144 0.39707465216796217 0.0 -0.0 0.0</pose>
			<inertial>
				<pose frame="">0.0 0.0 0.0 0 0 0</pose>
				<mass>1.1809063299086702</mass>
				<inertia>
					<ixx>0.19249833126625412</ixx>
					<ixy>-0.002306334871592668</ixy>
					<ixz>-0.0030893124346191994</ixz>
					<iyy>0.29973127460686877</iyy>
					<iyz>-0.14192218408420157</iyz>
					<izz>0.11100085723502044</izz>
				</inertia>
			</inertial>
			<collision name="upper_arm_left_collision">
				<geometry>
					<mesh>
						<uri>model://roboy_xylophone/meshes/CAD/upper_arm_left.stl</uri>
						<scale>0.001 0.001 0.001</scale>
					</mesh>
				</geometry>
			</collision>
			<visual name="upper_arm_left_visual">
				<geometry>
					<mesh>
						<uri>model://roboy_xylophone/meshes/CAD/upper_arm_left.stl</uri>
						<scale>0.001 0.001 0.001</scale>
					</mesh>
				</geometry>
			</visual>
		</link>
		<link name="lower_arm_left">
			<self_collide>false</self_collide>
			<pose frame="">0.2867576752988604 -0.0012029774645435486 0.09482838871490118 0.0 -0.0 0.0</pose>
			<inertial>
				<pose frame="">0.0 0.0 0.0 0 0 0</pose>
				<mass>1.4159186820881702</mass>
				<inertia>
					<ixx>0.01972453759664721</ixx>
					<ixy>0.0004870846174634047</ixy>
					<ixz>3.185352964212202e-05</ixz>
					<iyy>0.13615164739951632</iyy>
					<iyz>-0.0385608557623002</iyz>
					<izz>0.11772501099801319</izz>
				</inertia>
			</inertial>
			<collision name="lower_arm_left_collision">
				<geometry>
					<mesh>
						<uri>model://roboy_xylophone/meshes/CAD/lower_arm_left.stl</uri>
						<scale>0.001 0.001 0.001</scale>
					</mesh>
				</geometry>
			</collision>
			<visual name="lower_arm_left_visual">
				<geometry>
					<mesh>
						<uri>model://roboy_xylophone/meshes/CAD/lower_arm_left.stl</uri>
						<scale>0.001 0.001 0.001</scale>
					</mesh>
				</geometry>
			</visual>
		</link>
		<link name="lower_arm_right">
			<self_collide>false</self_collide>
			<pose frame="">-0.28690316197811633 -0.0012971012985662847 0.09028138839558518 0.0 -0.0 0.0</pose>
			<inertial>
				<pose frame="">0.0 0.0 0.0 0 0 0</pose>
				<mass>1.3992272098398937</mass>
				<inertia>
					<ixx>0.018109663582786668</ixx>
					<ixy>-0.0005191321679580465</ixy>
					<ixz>4.004976923881273e-05</ixz>
					<iyy>0.1332810801368647</iyy>
					<iyz>0.03631075913323457</iyz>
					<izz>0.11646776713622453</izz>
				</inertia>
			</inertial>
			<collision name="lower_arm_right_collision">
				<geometry>
					<mesh>
						<uri>model://roboy_xylophone/meshes/CAD/lower_arm_right.stl</uri>
						<scale>0.001 0.001 0.001</scale>
					</mesh>
				</geometry>
			</collision>
			<visual name="lower_arm_right_visual">
				<geometry>
					<mesh>
						<uri>model://roboy_xylophone/meshes/CAD/lower_arm_right.stl</uri>
						<scale>0.001 0.001 0.001</scale>
					</mesh>
				</geometry>
			</visual>
		</link>
		<link name="upper_arm_right">
			<self_collide>false</self_collide>
			<pose frame="">-0.30254473053274356 0.004242419884486809 0.39763220903709906 0.0 -0.0 0.0</pose>
			<inertial>
				<pose frame="">0.0 0.0 0.0 0 0 0</pose>
				<mass>1.0958327493598587</mass>
				<inertia>
					<ixx>0.17904183127745843</ixx>
					<ixy>0.0013739028297231812</ixy>
					<ixz>-0.0018802459141019135</ixz>
					<iyy>0.27814445786523145</iyy>
					<iyz>0.13162874177792994</iyz>
					<izz>0.10257941183247427</izz>
				</inertia>
			</inertial>
			<collision name="upper_arm_right_collision">
				<geometry>
					<mesh>
						<uri>model://roboy_xylophone/meshes/CAD/upper_arm_right.stl</uri>
						<scale>0.001 0.001 0.001</scale>
					</mesh>
				</geometry>
			</collision>
			<visual name="upper_arm_right_visual">
				<geometry>
					<mesh>
						<uri>model://roboy_xylophone/meshes/CAD/upper_arm_right.stl</uri>
						<scale>0.001 0.001 0.001</scale>
					</mesh>
				</geometry>
			</visual>
		</link>
		<link name="zed_camera_left_lense">
			<self_collide>false</self_collide>
			<pose frame="">0.05999964724565572 -0.08173913560527492 0.9528625747224352 0.0 -0.0 0.0</pose>
			<inertial>
				<pose frame="">0.0 0.0 0.0 0 0 0</pose>
				<mass>0.0057554218156879965</mass>
				<inertia>
					<ixx>0.004846003994033088</ixx>
					<ixy>3.881518938735634e-05</ixy>
					<ixz>0.0005891022505389009</ixz>
					<iyy>0.004793823223689041</iyy>
					<iyz>-0.0003144804806087313</iyz>
					<izz>9.383240644717274e-05</izz>
				</inertia>
			</inertial>
			<collision name="zed_camera_left_lense_collision">
				<geometry>
					<mesh>
						<uri>model://roboy_xylophone/meshes/CAD/zed_camera_left_lense.stl</uri>
						<scale>0.001 0.001 0.001</scale>
					</mesh>
				</geometry>
			</collision>
			<visual name="zed_camera_left_lense_visual">
				<geometry>
					<mesh>
						<uri>model://roboy_xylophone/meshes/CAD/zed_camera_left_lense.stl</uri>
						<scale>0.001 0.001 0.001</scale>
					</mesh>
				</geometry>
			</visual>
		</link>
		<link name="zed_camera_right_lense">
			<self_collide>false</self_collide>
			<pose frame="">-0.06000035275434433 -0.08173913560527538 0.9528625747224347 0.0 -0.0 0.0</pose>
			<inertial>
				<pose frame="">0.0 0.0 0.0 0 0 0</pose>
				<mass>0.0057554218156880485</mass>
				<inertia>
					<ixx>0.004846003993869442</ixx>
					<ixy>-3.881429332761528e-05</ixy>
					<ixz>0.0005891022505287467</ixz>
					<iyy>0.004793822275803509</iyy>
					<iyz>0.00031447328687670046</iyz>
					<izz>9.383145872528843e-05</izz>
				</inertia>
			</inertial>
			<collision name="zed_camera_right_lense_collision">
				<geometry>
					<mesh>
						<uri>model://roboy_xylophone/meshes/CAD/zed_camera_right_lense.stl</uri>
						<scale>0.001 0.001 0.001</scale>
					</mesh>
				</geometry>
			</collision>
			<visual name="zed_camera_right_lense_visual">
				<geometry>
					<mesh>
						<uri>model://roboy_xylophone/meshes/CAD/zed_camera_right_lense.stl</uri>
						<scale>0.001 0.001 0.001</scale>
					</mesh>
				</geometry>
			</visual>
		</link>
		<link name="zed_camera">
			<self_collide>false</self_collide>
			<pose frame="">-3.51796944748628e-07 -0.05630729805909612 0.9474568704182059 0.0 -0.0 0.0</pose>
			<inertial>
				<pose frame="">0.0 0.0 0.0 0 0 0</pose>
				<mass>0.009633908092012306</mass>
				<inertia>
					<ixx>0.008084577088634314</ixx>
					<ixy>4.052560334214884e-06</ixy>
					<ixz>0.0008835525556697587</ixz>
					<iyy>0.008001669367456716</iyy>
					<iyz>-3.558753230110404e-05</iyz>
					<izz>0.00011263547643344076</izz>
				</inertia>
			</inertial>
			<collision name="zed_camera_collision">
				<geometry>
					<mesh>
						<uri>model://roboy_xylophone/meshes/CAD/zed_camera.stl</uri>
						<scale>0.001 0.001 0.001</scale>
					</mesh>
				</geometry>
			</collision>
			<visual name="zed_camera_visual">
				<geometry>
					<mesh>
						<uri>model://roboy_xylophone/meshes/CAD/zed_camera.stl</uri>
						<scale>0.001 0.001 0.001</scale>
					</mesh>
				</geometry>
			</visual>
		</link>
		<link name="sphere_head_link1">
			<self_collide>false</self_collide>
			<pose frame="">-2.0585079955112284e-14 0.0015217810850766808 0.7110982300983261 0.0 -0.0 0.0</pose>
			<inertial>
				<pose frame="">0.0 0.0 0.0 0 0 0</pose>
				<mass>0.023938100802369737</mass>
				<inertia>
					<ixx>0.012106569631450062</ixx>
					<ixy>7.493571735350812e-19</ixy>
					<ixz>-2.5904276728695797e-05</ixz>
					<iyy>0.012106514195173217</iyy>
					<iyz>3.5035169210217987e-16</iyz>
					<izz>2.012994235293793e-06</izz>
				</inertia>
			</inertial>
			<collision name="sphere_head_link1_collision">
				<geometry>
					<mesh>
						<uri>model://roboy_xylophone/meshes/CAD/sphere_head_link1.stl</uri>
						<scale>0.001 0.001 0.001</scale>
					</mesh>
				</geometry>
			</collision>
			<visual name="sphere_head_link1_visual">
				<geometry>
					<mesh>
						<uri>model://roboy_xylophone/meshes/CAD/sphere_head_link1.stl</uri>
						<scale>0.001 0.001 0.001</scale>
					</mesh>
				</geometry>
			</visual>
		</link>
		<link name="shere_head_link2">
			<self_collide>false</self_collide>
			<pose frame="">-2.0576940733084e-14 0.0015217810850766884 0.7110982300983255 0.0 -0.0 0.0</pose>
			<inertial>
				<pose frame="">0.0 0.0 0.0 0 0 0</pose>
				<mass>0.016046417516495697</mass>
				<inertia>
					<ixx>0.008114964048845503</ixx>
					<ixy>5.02587338066518e-19</ixy>
					<ixz>-1.736440343714945e-05</ixz>
					<iyy>0.008114926888268263</iyy>
					<iyz>2.3476776078723563e-16</iyz>
					<izz>9.214497104106378e-07</izz>
				</inertia>
			</inertial>
			<collision name="shere_head_link2_collision">
				<geometry>
					<mesh>
						<uri>model://roboy_xylophone/meshes/CAD/shere_head_link2.stl</uri>
						<scale>0.001 0.001 0.001</scale>
					</mesh>
				</geometry>
			</collision>
			<visual name="shere_head_link2_visual">
				<geometry>
					<mesh>
						<uri>model://roboy_xylophone/meshes/CAD/shere_head_link2.stl</uri>
						<scale>0.001 0.001 0.001</scale>
					</mesh>
				</geometry>
			</visual>
		</link>
		<link name="head">
			<self_collide>false</self_collide>
			<pose frame="">0.000649237635868437 0.015046110821381155 0.8664854985670138 0.0 -0.0 0.0</pose>
			<inertial>
				<pose frame="">0.0 0.0 0.0 0 0 0</pose>
				<mass>2.0664381552877806</mass>
				<inertia>
					<ixx>1.584602072446883</ixx>
					<ixy>-2.8828445995492527e-05</ixy>
					<ixz>-0.029442678579422673</ixz>
					<iyy>1.57889377620563</iyy>
					<iyz>-0.0012884336458265217</iyz>
					<izz>0.025550832000821585</izz>
				</inertia>
			</inertial>
			<collision name="head_collision">
				<geometry>
					<mesh>
						<uri>model://roboy_xylophone/meshes/CAD/head.stl</uri>
						<scale>0.001 0.001 0.001</scale>
					</mesh>
				</geometry>
			</collision>
			<visual name="head_visual">
				<geometry>
					<mesh>
						<uri>model://roboy_xylophone/meshes/CAD/head.stl</uri>
						<scale>0.001 0.001 0.001</scale>
					</mesh>
				</geometry>
			</visual>
		</link>
		<joint name="left_wrist_0" type="revolute">
			<parent>lower_arm_left</parent>
			<child>wrist_left_1</child>
			<pose frame="">-0.009900625387205082 -0.0006389576348571357 -0.0010673226779252954 0 0 0</pose>
			<axis>
				<xyz>-0.9974356911086111 -0.061126860752873415 0.037222963304743374</xyz>
				<limit>
					<lower>-0.5235987755982988</lower>
					<upper>0.5235987755982988</upper>
				</limit>
				<use_parent_model_frame>0</use_parent_model_frame>
			</axis>
		</joint>
		<joint name="left_wrist_1" type="revolute">
			<parent>wrist_left_1</parent>
			<child>left_hand</child>
			<pose frame="">0.016116326190712266 0.07816945585980226 0.10336124335231345 0 0 0</pose>
			<axis>
				<xyz>-0.06197857490501217 0.9978311478764739 -0.022173330382833693</xyz>
				<limit>
					<lower>-0.5235987755982988</lower>
					<upper>0.5235987755982988</upper>
				</limit>
				<use_parent_model_frame>0</use_parent_model_frame>
			</axis>
		</joint>
		<joint name="sphere_left_axis0" type="revolute">
			<parent>torso</parent>
			<child>sphere_left_link1</child>
			<pose frame="">3.928344547432516e-09 -1.6697847608382331e-07 -3.76615449226847e-08 0 0 0</pose>
			<axis>
				<xyz>0.9986354432836129 0.05074429632816833 -0.012339684270770038</xyz>
				<limit>
					<lower>-3.141592653589793</lower>
					<upper>3.141592653589793</upper>
				</limit>
				<use_parent_model_frame>0</use_parent_model_frame>
			</axis>
		</joint>
		<joint name="sphere_left_axis1" type="revolute">
			<parent>sphere_left_link1</parent>
			<child>sphere_left_link2</child>
			<pose frame="">-9.872906794328173e-09 1.3921429488195082e-07 -2.5913787453646363e-08 0 0 0</pose>
			<axis>
				<xyz>-0.051010494316674926 0.9984488883025682 -0.022310242422112825</xyz>
				<limit>
					<lower>-3.141592653589793</lower>
					<upper>3.141592653589793</upper>
				</limit>
				<use_parent_model_frame>0</use_parent_model_frame>
			</axis>
		</joint>
		<joint name="sphere_left_axis2" type="revolute">
			<parent>sphere_left_link2</parent>
			<child>upper_arm_left</child>
			<pose frame="">-0.010981441799161615 0.002600669110232077 0.15153981541606967 0 0 0</pose>
			<axis>
				<xyz>-0.01118842648953418 -0.022909252225335505 -0.9996749398055222</xyz>
				<limit>
					<lower>-3.141592653589793</lower>
					<upper>3.141592653589793</upper>
				</limit>
				<use_parent_model_frame>0</use_parent_model_frame>
			</axis>
		</joint>
		<joint name="elbow_left_rot1" type="revolute">
			<parent>elbow_left</parent>
			<child>lower_arm_left</child>
			<pose frame="">0.0015883800233880408 0.00276197583512779 0.12014580167753088 0 0 0</pose>
			<axis>
				<xyz>-0.011188426489533955 -0.022909252225335637 -0.9996749398055156</xyz>
				<limit>
					<lower>-1.5707963267948966</lower>
					<upper>1.5707963267948966</upper>
				</limit>
				<use_parent_model_frame>0</use_parent_model_frame>
			</axis>
		</joint>
		<joint name="elbow_left_rot0" type="revolute">
			<parent>upper_arm_left</parent>
			<child>elbow_left</child>
			<pose frame="">0.014657053049847591 -0.003686557448817787 0.037410123740787074 0 0 0</pose>
			<axis>
				<xyz>-0.9986354432836098 -0.05074429632816577 0.012339684270769044</xyz>
				<limit>
					<lower>0.0</lower>
					<upper>1.5707963267948966</upper>
				</limit>
				<use_parent_model_frame>0</use_parent_model_frame>
			</axis>
		</joint>
		<joint name="elbow_right_rot1" type="revolute">
			<parent>elbow_right</parent>
			<child>lower_arm_right</child>
			<pose frame="">-0.0014317049176434792 0.0028331904169269064 0.12369312705704284 0 0 0</pose>
			<axis>
				<xyz>-0.01118842648953284 0.022909252225335578 0.999674939805517</xyz>
				<limit>
					<lower>-1.5707963267948966</lower>
					<upper>1.5707963267948966</upper>
				</limit>
				<use_parent_model_frame>0</use_parent_model_frame>
			</axis>
		</joint>
		<joint name="sphere_right_axis0" type="revolute">
			<parent>torso</parent>
			<child>sphere_right_link1</child>
			<pose frame="">-8.958507574874375e-08 -1.680529193437419e-07 -1.2962124245063933e-08 0 0 0</pose>
			<axis>
				<xyz>0.05101049431667341 0.998448888302569 -0.022310242422112807</xyz>
				<limit>
					<lower>-3.141592653589793</lower>
					<upper>3.141592653589793</upper>
				</limit>
				<use_parent_model_frame>0</use_parent_model_frame>
			</axis>
		</joint>
		<joint name="sphere_right_axis2" type="revolute">
			<parent>sphere_right_link2</parent>
			<child>upper_arm_right</child>
			<pose frame="">0.010364674320051073 0.004967615846205553 0.15098225854693234 0 0 0</pose>
			<axis>
				<xyz>0.011188426489535866 -0.02290925222533533 -0.9996749398055187</xyz>
				<limit>
					<lower>-3.141592653589793</lower>
					<upper>3.141592653589793</upper>
				</limit>
				<use_parent_model_frame>0</use_parent_model_frame>
			</axis>
		</joint>
		<joint name="sphere_right_axis1" type="revolute">
			<parent>sphere_right_link1</parent>
			<child>sphere_right_link2</child>
			<pose frame="">1.1628181656675451e-07 1.2732201987719626e-07 -1.0334542182022233e-08 0 0 0</pose>
			<axis>
				<xyz>-0.9986354432836146 0.050744296328166766 -0.012339684270771867</xyz>
				<limit>
					<lower>-3.141592653589793</lower>
					<upper>3.141592653589793</upper>
				</limit>
				<use_parent_model_frame>0</use_parent_model_frame>
			</axis>
		</joint>
		<joint name="elbow_right_rot0" type="revolute">
			<parent>upper_arm_right</parent>
			<child>elbow_right</child>
			<pose frame="">-0.01505249789831094 -0.0035973057550871853 0.03935067099456973 0 0 0</pose>
			<axis>
				<xyz>-0.9986354432836139 0.050744296328165295 -0.012339684270768765</xyz>
				<limit>
					<lower>0.0</lower>
					<upper>1.5707963267948966</upper>
				</limit>
				<use_parent_model_frame>0</use_parent_model_frame>
			</axis>
		</joint>
		<joint name="right_wrist_0" type="revolute">
			<parent>lower_arm_right</parent>
			<child>wrist_right_1</child>
			<pose frame="">0.011094392792996502 -0.00048043688755387007 -0.0015766831427710582 0 0 0</pose>
			<axis>
				<xyz>0.9991077747968851 -0.04032476901588534 -0.012552583169695498</xyz>
				<limit>
					<lower>-0.5235987755982988</lower>
					<upper>0.5235987755982988</upper>
				</limit>
				<use_parent_model_frame>0</use_parent_model_frame>
			</axis>
		</joint>
		<joint name="right_wrist_1" type="revolute">
			<parent>wrist_right_1</parent>
			<child>right_hand</child>
			<pose frame="">-0.012781650531728026 0.11323020333167018 0.10121948409630965 0 0 0</pose>
			<axis>
				<xyz>0.04003625680553698 0.9989461168065814 -0.022444461634320585</xyz>
				<limit>
					<lower>-0.5235987755982988</lower>
					<upper>0.5235987755982988</upper>
				</limit>
				<use_parent_model_frame>0</use_parent_model_frame>
			</axis>
		</joint>
		<joint name="zed_camera_mount" type="fixed">
			<parent>head</parent>
			<child>zed_camera</child>
			<pose frame="">0.02149999999998915 -0.044773883099429555 -0.028804128333927537 0 0 0</pose>
		</joint>
		<joint name="zed_camera_right" type="fixed">
			<parent>zed_camera</parent>
			<child>zed_camera_right_lense</child>
			<pose frame="">-1.1119993814645568e-14 -0.019342045553250423 -0.042209832155477474 0 0 0</pose>
		</joint>
		<joint name="zed_camera_left" type="fixed">
			<parent>zed_camera</parent>
			<child>zed_camera_left_lense</child>
			<pose frame="">-1.7810504181934308e-05 -0.01934204555325101 -0.04220983228922165 0 0 0</pose>
		</joint>
		<joint name="sphere_head_axis0" type="revolute">
			<parent>torso</parent>
			<child>sphere_head_link1</child>
			<pose frame="">-9.148004729306069e-18 -3.3306690738754695e-18 0.0 0 0 0</pose>
			<axis>
				<xyz>2.498001805406601e-16 -1.0000000000000004 8.24263190083377e-15</xyz>
				<limit>
					<lower>-0.5235987755982988</lower>
					<upper>0.5235987755982988</upper>
				</limit>
				<use_parent_model_frame>0</use_parent_model_frame>
			</axis>
		</joint>
		<joint name="sphere_head_axis2" type="revolute">
			<parent>shere_head_link2</parent>
			<child>head</child>
			<pose frame="">-0.0006492376358890309 -0.013524329736304486 -0.15538726846868797 0 0 0</pose>
			<axis>
				<xyz>-2.4131887955448744e-14 8.242631900833762e-15 1.0</xyz>
				<limit>
					<lower>-0.5235987755982988</lower>
					<upper>0.5235987755982988</upper>
				</limit>
				<use_parent_model_frame>0</use_parent_model_frame>
			</axis>
		</joint>
		<joint name="sphere_head_axis1" type="revolute">
			<parent>sphere_head_link1</parent>
			<child>shere_head_link2</child>
			<pose frame="">-1.7287226757593036e-17 -1.1657341758564143e-17 5.684341886080802e-16 0 0 0</pose>
			<axis>
				<xyz>-1.0000000000000004 -2.4980018054086044e-16 -2.413188795544875e-14</xyz>
				<limit>
					<lower>-0.5235987755982988</lower>
					<upper>0.5235987755982988</upper>
				</limit>
				<use_parent_model_frame>0</use_parent_model_frame>
			</axis>
		</joint>
	</model>
</sdf>
