<?xml version="1.0" ?>
<sdf version="1.6">
	<model name="roboy_xylophone">
		<link name="torso">
			<self_collide>false</self_collide>
			<pose frame="">0.0 0.0 0.0 0.0 -0.0 0.0</pose>
			<inertial>
				<pose frame="">0.0 0.0 0.0 0 0 0</pose>
				<mass>13.72368407891531</mass>
				<inertia>
					<ixx>3.910765453374194</ixx>
					<ixy>-0.001095224797113174</ixy>
					<ixz>0.043302154633862465</ixz>
					<iyy>4.168439034043004</iyy>
					<iyz>-0.013228815176824301</iyz>
					<izz>0.3524412985016293</izz>
				</inertia>
			</inertial>
			<collision name="torso_collision">
				<geometry>
					<mesh>
						<uri>model://roboy_xylophone/meshes/CAD/torso.stl</uri>
						<scale>0.001 0.001 0.001</scale>
					</mesh>
				</geometry>
			</collision>
			<visual name="torso_visual">
				<geometry>
					<mesh>
						<uri>model://roboy_xylophone/meshes/CAD/torso.stl</uri>
						<scale>0.001 0.001 0.001</scale>
					</mesh>
				</geometry>
			</visual>
		</link>
		<link name="right_hand">
			<self_collide>false</self_collide>
			<pose frame="">-0.2698510367085325 -0.0017499434157416084 -0.1302469819688276 0.0 -0.0 0.0</pose>
			<inertial>
				<pose frame="">0.0 0.0 0.0 0 0 0</pose>
				<mass>0.20805908239869125</mass>
				<inertia>
					<ixx>0.0075567109842610385</ixx>
					<ixy>-0.003870948682374514</ixy>
					<ixz>-0.0027023479542121133</ixz>
					<iyy>0.019913740298193046</iyy>
					<iyz>-0.0076257923873708664</iyz>
					<izz>0.018971657099651783</izz>
				</inertia>
			</inertial>
			<collision name="right_hand_collision">
				<geometry>
					<mesh>
						<uri>model://roboy_xylophone/meshes/CAD/right_hand.stl</uri>
						<scale>0.001 0.001 0.001</scale>
					</mesh>
				</geometry>
			</collision>
			<visual name="right_hand_visual">
				<geometry>
					<mesh>
						<uri>model://roboy_xylophone/meshes/CAD/right_hand.stl</uri>
						<scale>0.001 0.001 0.001</scale>
					</mesh>
				</geometry>
			</visual>
		</link>
		<link name="left_hand">
			<self_collide>false</self_collide>
			<pose frame="">0.2697594900165811 -0.006792324262862302 -0.1314462184560031 0.0 -0.0 0.0</pose>
			<inertial>
				<pose frame="">0.0 0.0 0.0 0 0 0</pose>
				<mass>0.18650433962187907</mass>
				<inertia>
					<ixx>0.00742411081802007</ixx>
					<ixy>0.0038015046666095465</ixy>
					<ixz>-0.002693661217771364</ixz>
					<iyy>0.01767984161098725</iyy>
					<iyz>0.007164025065289065</iyz>
					<izz>0.016872438513441758</izz>
				</inertia>
			</inertial>
			<collision name="left_hand_collision">
				<geometry>
					<mesh>
						<uri>model://roboy_xylophone/meshes/CAD/left_hand.stl</uri>
						<scale>0.001 0.001 0.001</scale>
					</mesh>
				</geometry>
			</collision>
			<visual name="left_hand_visual">
				<geometry>
					<mesh>
						<uri>model://roboy_xylophone/meshes/CAD/left_hand.stl</uri>
						<scale>0.001 0.001 0.001</scale>
					</mesh>
				</geometry>
			</visual>
		</link>
		<link name="elbow_left">
			<self_collide>false</self_collide>
			<pose frame="">0.2924609988878703 0.0026742978127753526 0.24368519978311523 0.0 -0.0 0.0</pose>
			<inertial>
				<pose frame="">0.0 0.0 0.0 0 0 0</pose>
				<mass>0.15681537169755258</mass>
				<inertia>
					<ixx>0.009431757217348843</ixx>
					<ixy>-0.00012517065329283248</ixy>
					<ixz>-9.888439213748464e-05</ixz>
					<iyy>0.022865599183266166</iyy>
					<iyz>-0.011162126418678987</iyz>
					<izz>0.013542050845808416</izz>
				</inertia>
			</inertial>
			<collision name="elbow_left_collision">
				<geometry>
					<mesh>
						<uri>model://roboy_xylophone/meshes/CAD/elbow_left.stl</uri>
						<scale>0.001 0.001 0.001</scale>
					</mesh>
				</geometry>
			</collision>
			<visual name="elbow_left_visual">
				<geometry>
					<mesh>
						<uri>model://roboy_xylophone/meshes/CAD/elbow_left.stl</uri>
						<scale>0.001 0.001 0.001</scale>
					</mesh>
				</geometry>
			</visual>
		</link>
		<link name="elbow_right">
			<self_collide>false</self_collide>
			<pose frame="">-0.29205436561642706 0.002562136866253571 0.2407449775865269 0.0 -0.0 0.0</pose>
			<inertial>
				<pose frame="">0.0 0.0 0.0 0 0 0</pose>
				<mass>0.1737509895674572</mass>
				<inertia>
					<ixx>0.010199619270761047</ixx>
					<ixy>0.00013260458238670674</ixy>
					<ixz>-0.0001041660034778284</ixz>
					<iyy>0.02504128534242205</iyy>
					<iyz>0.012203668182971939</iyz>
					<izz>0.014951862459761598</izz>
				</inertia>
			</inertial>
			<collision name="elbow_right_collision">
				<geometry>
					<mesh>
						<uri>model://roboy_xylophone/meshes/CAD/elbow_right.stl</uri>
						<scale>0.001 0.001 0.001</scale>
					</mesh>
				</geometry>
			</collision>
			<visual name="elbow_right_visual">
				<geometry>
					<mesh>
						<uri>model://roboy_xylophone/meshes/CAD/elbow_right.stl</uri>
						<scale>0.001 0.001 0.001</scale>
					</mesh>
				</geometry>
			</visual>
		</link>
		<link name="sphere_right_link1">
			<self_collide>false</self_collide>
			<pose frame="">-0.2921799666276168 0.009210203783611735 0.548615244082417 0.0 -0.0 0.0</pose>
			<inertial>
				<pose frame="">0.0 0.0 0.0 0 0 0</pose>
				<mass>0.04675596089362313</mass>
				<inertia>
					<ixx>0.014082487940467327</ixx>
					<ixy>0.00012582201998645568</ixy>
					<ixz>-0.00023625123995044107</ixz>
					<iyy>0.01807003753984725</iyy>
					<iyz>0.0074947179360907975</iyz>
					<izz>0.004001456143427335</izz>
				</inertia>
			</inertial>
			<collision name="sphere_right_link1_collision">
				<geometry>
					<mesh>
						<uri>model://roboy_xylophone/meshes/CAD/sphere_right_link1.stl</uri>
						<scale>0.001 0.001 0.001</scale>
					</mesh>
				</geometry>
			</collision>
			<visual name="sphere_right_link1_visual">
				<geometry>
					<mesh>
						<uri>model://roboy_xylophone/meshes/CAD/sphere_right_link1.stl</uri>
						<scale>0.001 0.001 0.001</scale>
					</mesh>
				</geometry>
			</visual>
		</link>
		<link name="sphere_right_link2">
			<self_collide>false</self_collide>
			<pose frame="">-0.2921801724945091 0.009209908408672508 0.5486152414548352 0.0 -0.0 0.0</pose>
			<inertial>
				<pose frame="">0.0 0.0 0.0 0 0 0</pose>
				<mass>0.03133941577358247</mass>
				<inertia>
					<ixx>0.009437852970646556</ixx>
					<ixy>8.433288313845014e-05</ixy>
					<ixz>-0.00015834854451237578</ixz>
					<iyy>0.012110617225243162</iyy>
					<iyz>0.005023535852643668</iyz>
					<izz>0.002680779380039669</izz>
				</inertia>
			</inertial>
			<collision name="sphere_right_link2_collision">
				<geometry>
					<mesh>
						<uri>model://roboy_xylophone/meshes/CAD/sphere_right_link2.stl</uri>
						<scale>0.001 0.001 0.001</scale>
					</mesh>
				</geometry>
			</collision>
			<visual name="sphere_right_link2_visual">
				<geometry>
					<mesh>
						<uri>model://roboy_xylophone/meshes/CAD/sphere_right_link2.stl</uri>
						<scale>0.001 0.001 0.001</scale>
					</mesh>
				</geometry>
			</visual>
		</link>
		<link name="sphere_left_link1">
			<self_collide>false</self_collide>
			<pose frame="">0.29218005222734156 0.009210203825021935 0.5486152687569047 0.0 -0.0 0.0</pose>
			<inertial>
				<pose frame="">0.0 0.0 0.0 0 0 0</pose>
				<mass>0.046755519327953445</mass>
				<inertia>
					<ixx>0.014082356273081548</ixx>
					<ixy>-0.00012582086921548955</ixy>
					<ixz>-0.00023624902092354817</ixz>
					<iyy>0.01806987052231626</iyy>
					<iyz>-0.00749464968837342</iyz>
					<izz>0.004001420718449545</izz>
				</inertia>
			</inertial>
			<collision name="sphere_left_link1_collision">
				<geometry>
					<mesh>
						<uri>model://roboy_xylophone/meshes/CAD/sphere_left_link1.stl</uri>
						<scale>0.001 0.001 0.001</scale>
					</mesh>
				</geometry>
			</collision>
			<visual name="sphere_left_link1_visual">
				<geometry>
					<mesh>
						<uri>model://roboy_xylophone/meshes/CAD/sphere_left_link1.stl</uri>
						<scale>0.001 0.001 0.001</scale>
					</mesh>
				</geometry>
			</visual>
		</link>
		<link name="sphere_left_link2">
			<self_collide>false</self_collide>
			<pose frame="">0.2921800660285928 0.009209897632250984 0.5486152570091472 0.0 -0.0 0.0</pose>
			<inertial>
				<pose frame="">0.0 0.0 0.0 0 0 0</pose>
				<mass>0.031340208481721574</mass>
				<inertia>
					<ixx>0.009438092156368896</ixx>
					<ixy>-8.433488846064293e-05</ixy>
					<ixz>-0.00015835236925662997</ixz>
					<iyy>0.012110922096803804</iyy>
					<iyz>-0.005023661231281029</iyz>
					<izz>0.0026808451877708057</izz>
				</inertia>
			</inertial>
			<collision name="sphere_left_link2_collision">
				<geometry>
					<mesh>
						<uri>model://roboy_xylophone/meshes/CAD/sphere_left_link2.stl</uri>
						<scale>0.001 0.001 0.001</scale>
					</mesh>
				</geometry>
			</collision>
			<visual name="sphere_left_link2_visual">
				<geometry>
					<mesh>
						<uri>model://roboy_xylophone/meshes/CAD/sphere_left_link2.stl</uri>
						<scale>0.001 0.001 0.001</scale>
					</mesh>
				</geometry>
			</visual>
		</link>
		<link name="wrist_left_1">
			<self_collide>false</self_collide>
			<pose frame="">0.2838291081215929 -0.004517829187733993 -0.0460263795467499 0.0 -0.0 0.0</pose>
			<inertial>
				<pose frame="">0.0 0.0 0.0 0 0 0</pose>
				<mass>0.012764273069100246</mass>
				<inertia>
					<ixx>2.9933237342887354e-05</ixx>
					<ixy>1.6313062661204246e-05</ixy>
					<ixz>-2.60614002361967e-06</ixz>
					<iyy>0.001058859487958565</iyy>
					<iyz>0.00016684286591328332</iyz>
					<izz>0.0010339769540120504</izz>
				</inertia>
			</inertial>
			<collision name="wrist_left_1_collision">
				<geometry>
					<mesh>
						<uri>model://roboy_xylophone/meshes/CAD/wrist_left_1.stl</uri>
						<scale>0.001 0.001 0.001</scale>
					</mesh>
				</geometry>
			</collision>
			<visual name="wrist_left_1_visual">
				<geometry>
					<mesh>
						<uri>model://roboy_xylophone/meshes/CAD/wrist_left_1.stl</uri>
						<scale>0.001 0.001 0.001</scale>
					</mesh>
				</geometry>
			</visual>
		</link>
		<link name="wrist_right_1">
			<self_collide>false</self_collide>
			<pose frame="">-0.2866867429541466 -0.004439510879921008 -0.04905987848597987 0.0 -0.0 0.0</pose>
			<inertial>
				<pose frame="">0.0 0.0 0.0 0 0 0</pose>
				<mass>0.012762562533547099</mass>
				<inertia>
					<ixx>3.3596818331877835e-05</ixx>
					<ixy>-1.6206001652051634e-05</ixy>
					<ixz>-2.73824321167433e-06</ixz>
					<iyy>0.0010832076300652943</iyy>
					<iyz>-0.00017947272958513367</iyz>
					<izz>0.001054639875188272</izz>
				</inertia>
			</inertial>
			<collision name="wrist_right_1_collision">
				<geometry>
					<mesh>
						<uri>model://roboy_xylophone/meshes/CAD/wrist_right_1.stl</uri>
						<scale>0.001 0.001 0.001</scale>
					</mesh>
				</geometry>
			</collision>
			<visual name="wrist_right_1_visual">
				<geometry>
					<mesh>
						<uri>model://roboy_xylophone/meshes/CAD/wrist_right_1.stl</uri>
						<scale>0.001 0.001 0.001</scale>
					</mesh>
				</geometry>
			</visual>
		</link>
		<link name="upper_arm_left">
			<self_collide>false</self_collide>
			<pose frame="">0.30316149801185677 0.006609366620456846 0.3970754157042611 0.0 -0.0 0.0</pose>
			<inertial>
				<pose frame="">0.0 0.0 0.0 0 0 0</pose>
				<mass>1.1809063299122686</mass>
				<inertia>
					<ixx>0.1924990473234301</ixx>
					<ixy>-0.0023063348715922343</ixy>
					<ixz>-0.00308931839405198</ixz>
					<iyy>0.2997319906640523</iyy>
					<iyz>-0.14192245743426316</iyz>
					<izz>0.11100085723502803</izz>
				</inertia>
			</inertial>
			<collision name="upper_arm_left_collision">
				<geometry>
					<mesh>
						<uri>model://roboy_xylophone/meshes/CAD/upper_arm_left.stl</uri>
						<scale>0.001 0.001 0.001</scale>
					</mesh>
				</geometry>
			</collision>
			<visual name="upper_arm_left_visual">
				<geometry>
					<mesh>
						<uri>model://roboy_xylophone/meshes/CAD/upper_arm_left.stl</uri>
						<scale>0.001 0.001 0.001</scale>
					</mesh>
				</geometry>
			</visual>
		</link>
		<link name="lower_arm_left">
			<self_collide>false</self_collide>
			<pose frame="">0.2867576752988603 -0.0012029774645435035 0.09482915225116281 0.0 -0.0 0.0</pose>
			<inertial>
				<pose frame="">0.0 0.0 0.0 0 0 0</pose>
				<mass>1.41591868208817</mass>
				<inertia>
					<ixx>0.01972474263641184</ixx>
					<ixy>0.0004870846174633889</ixy>
					<ixz>3.185483018737706e-05</ixz>
					<iyy>0.1361518524392809</iyy>
					<iyz>-0.03856116577753053</iyz>
					<izz>0.11772501099801312</izz>
				</inertia>
			</inertial>
			<collision name="lower_arm_left_collision">
				<geometry>
					<mesh>
						<uri>model://roboy_xylophone/meshes/CAD/lower_arm_left.stl</uri>
						<scale>0.001 0.001 0.001</scale>
					</mesh>
				</geometry>
			</collision>
			<visual name="lower_arm_left_visual">
				<geometry>
					<mesh>
						<uri>model://roboy_xylophone/meshes/CAD/lower_arm_left.stl</uri>
						<scale>0.001 0.001 0.001</scale>
					</mesh>
				</geometry>
			</visual>
		</link>
		<link name="lower_arm_right">
			<self_collide>false</self_collide>
			<pose frame="">-0.28690316197811633 -0.0012971012985662463 0.09028215193184677 0.0 -0.0 0.0</pose>
			<inertial>
				<pose frame="">0.0 0.0 0.0 0 0 0</pose>
				<mass>1.3992272098398937</mass>
				<inertia>
					<ixx>0.018109856489779336</ixx>
					<ixy>-0.000519132167958026</ixy>
					<ixz>4.0051155010875704e-05</ixz>
					<iyy>0.1332812730438574</iyy>
					<iyz>0.036311065649301234</iyz>
					<izz>0.11646776713622453</izz>
				</inertia>
			</inertial>
			<collision name="lower_arm_right_collision">
				<geometry>
					<mesh>
						<uri>model://roboy_xylophone/meshes/CAD/lower_arm_right.stl</uri>
						<scale>0.001 0.001 0.001</scale>
					</mesh>
				</geometry>
			</collision>
			<visual name="lower_arm_right_visual">
				<geometry>
					<mesh>
						<uri>model://roboy_xylophone/meshes/CAD/lower_arm_right.stl</uri>
						<scale>0.001 0.001 0.001</scale>
					</mesh>
				</geometry>
			</visual>
		</link>
		<link name="upper_arm_right">
			<self_collide>false</self_collide>
			<pose frame="">-0.3025447305327413 0.004242419884484555 0.39763297257341446 0.0 -0.0 0.0</pose>
			<inertial>
				<pose frame="">0.0 0.0 0.0 0 0 0</pose>
				<mass>1.0958327493598512</mass>
				<inertia>
					<ixx>0.17904249668222721</ixx>
					<ixy>0.0013739028297231495</ixy>
					<ixz>-0.0018802494637687244</ixz>
					<iyy>0.2781451232699976</iyy>
					<iyz>0.13162899491953578</iyz>
					<izz>0.10257941183247153</izz>
				</inertia>
			</inertial>
			<collision name="upper_arm_right_collision">
				<geometry>
					<mesh>
						<uri>model://roboy_xylophone/meshes/CAD/upper_arm_right.stl</uri>
						<scale>0.001 0.001 0.001</scale>
					</mesh>
				</geometry>
			</collision>
			<visual name="upper_arm_right_visual">
				<geometry>
					<mesh>
						<uri>model://roboy_xylophone/meshes/CAD/upper_arm_right.stl</uri>
						<scale>0.001 0.001 0.001</scale>
					</mesh>
				</geometry>
			</visual>
		</link>
		<link name="zed_camera_left_lense">
			<self_collide>false</self_collide>
			<pose frame="">0.05999964724565572 -0.08173913560527492 0.9528625747224352 0.0 -0.0 0.0</pose>
			<inertial>
				<pose frame="">0.0 0.0 0.0 0 0 0</pose>
				<mass>0.0057554218156879965</mass>
				<inertia>
					<ixx>0.004846011997714692</ixx>
					<ixy>3.8815189387356356e-05</ixy>
					<ixz>0.0005891027444713396</ixz>
					<iyy>0.004793831227370643</iyy>
					<iyz>-0.00031448074428470696</iyz>
					<izz>9.383240644717277e-05</izz>
				</inertia>
			</inertial>
			<collision name="zed_camera_left_lense_collision">
				<geometry>
					<mesh>
						<uri>model://roboy_xylophone/meshes/CAD/zed_camera_left_lense.stl</uri>
						<scale>0.001 0.001 0.001</scale>
					</mesh>
				</geometry>
			</collision>
			<visual name="zed_camera_left_lense_visual">
				<geometry>
					<mesh>
						<uri>model://roboy_xylophone/meshes/CAD/zed_camera_left_lense.stl</uri>
						<scale>0.001 0.001 0.001</scale>
					</mesh>
				</geometry>
			</visual>
		</link>
		<link name="zed_camera_right_lense">
			<self_collide>false</self_collide>
			<pose frame="">-0.06000035275434433 -0.08173913560527538 0.9528625747224347 0.0 -0.0 0.0</pose>
			<inertial>
				<pose frame="">0.0 0.0 0.0 0 0 0</pose>
				<mass>0.0057554218156880485</mass>
				<inertia>
					<ixx>0.004846011997551049</ixx>
					<ixy>-3.881429332761528e-05</ixy>
					<ixz>0.0005891027444611853</ixz>
					<iyy>0.004793830279485115</iyy>
					<iyz>0.00031447355054664474</iyz>
					<izz>9.383145872528843e-05</izz>
				</inertia>
			</inertial>
			<collision name="zed_camera_right_lense_collision">
				<geometry>
					<mesh>
						<uri>model://roboy_xylophone/meshes/CAD/zed_camera_right_lense.stl</uri>
						<scale>0.001 0.001 0.001</scale>
					</mesh>
				</geometry>
			</collision>
			<visual name="zed_camera_right_lense_visual">
				<geometry>
					<mesh>
						<uri>model://roboy_xylophone/meshes/CAD/zed_camera_right_lense.stl</uri>
						<scale>0.001 0.001 0.001</scale>
					</mesh>
				</geometry>
			</visual>
		</link>
		<link name="zed_camera">
			<self_collide>false</self_collide>
			<pose frame="">-3.51796944748628e-07 -0.05630729805909612 0.9474568704182059 0.0 -0.0 0.0</pose>
			<inertial>
				<pose frame="">0.0 0.0 0.0 0 0 0</pose>
				<mass>0.009633908092012306</mass>
				<inertia>
					<ixx>0.008084590483556824</ixx>
					<ixy>4.052560334214878e-06</ixy>
					<ixz>0.0008835532966109025</ixz>
					<iyy>0.008001682762379227</iyy>
					<iyz>-3.558756214861936e-05</iyz>
					<izz>0.00011263547643344076</izz>
				</inertia>
			</inertial>
			<collision name="zed_camera_collision">
				<geometry>
					<mesh>
						<uri>model://roboy_xylophone/meshes/CAD/zed_camera.stl</uri>
						<scale>0.001 0.001 0.001</scale>
					</mesh>
				</geometry>
			</collision>
			<visual name="zed_camera_visual">
				<geometry>
					<mesh>
						<uri>model://roboy_xylophone/meshes/CAD/zed_camera.stl</uri>
						<scale>0.001 0.001 0.001</scale>
					</mesh>
				</geometry>
			</visual>
		</link>
		<link name="sphere_head_link1">
			<self_collide>false</self_collide>
			<pose frame="">-2.0591149070298685e-14 0.0015217810850767161 0.7110989936345878 0.0 -0.0 0.0</pose>
			<inertial>
				<pose frame="">0.0 0.0 0.0 0 0 0</pose>
				<mass>0.023938100802369734</mass>
				<inertia>
					<ixx>0.012106595625813408</ixx>
					<ixy>7.508425305113864e-19</ixy>
					<ixz>-2.5904304543214497e-05</ixz>
					<iyy>0.012106540189536562</iyy>
					<iyz>3.5051683777709287e-16</iyz>
					<izz>2.012994235293797e-06</izz>
				</inertia>
			</inertial>
			<collision name="sphere_head_link1_collision">
				<geometry>
					<mesh>
						<uri>model://roboy_xylophone/meshes/CAD/sphere_head_link1.stl</uri>
						<scale>0.001 0.001 0.001</scale>
					</mesh>
				</geometry>
			</collision>
			<visual name="sphere_head_link1_visual">
				<geometry>
					<mesh>
						<uri>model://roboy_xylophone/meshes/CAD/sphere_head_link1.stl</uri>
						<scale>0.001 0.001 0.001</scale>
					</mesh>
				</geometry>
			</visual>
		</link>
		<link name="shere_head_link2">
			<self_collide>false</self_collide>
			<pose frame="">-2.0576940733084e-14 0.001521781085076725 0.7110989936345874 0.0 -0.0 0.0</pose>
			<inertial>
				<pose frame="">0.0 0.0 0.0 0 0 0</pose>
				<mass>0.016046417516495697</mass>
				<inertia>
					<ixx>0.008114981473636663</ixx>
					<ixy>5.029234407399885e-19</ixy>
					<ixz>-1.7364422082044644e-05</ixz>
					<iyy>0.008114944313059423</iyy>
					<iyz>2.348593541867672e-16</iyz>
					<izz>9.214497104106424e-07</izz>
				</inertia>
			</inertial>
			<collision name="shere_head_link2_collision">
				<geometry>
					<mesh>
						<uri>model://roboy_xylophone/meshes/CAD/shere_head_link2.stl</uri>
						<scale>0.001 0.001 0.001</scale>
					</mesh>
				</geometry>
			</collision>
			<visual name="shere_head_link2_visual">
				<geometry>
					<mesh>
						<uri>model://roboy_xylophone/meshes/CAD/shere_head_link2.stl</uri>
						<scale>0.001 0.001 0.001</scale>
					</mesh>
				</geometry>
			</visual>
		</link>
		<link name="head">
			<self_collide>false</self_collide>
			<pose frame="">0.0006492376358659663 0.015046110821376588 0.8664862621002404 0.0 -0.0 0.0</pose>
			<inertial>
				<pose frame="">0.0 0.0 0.0 0 0 0</pose>
				<mass>2.066438155287756</mass>
				<inertia>
					<ixx>1.5846048067305112</ixx>
					<ixy>-2.8828445995337716e-05</ixy>
					<ixz>-0.02944270231917974</ixz>
					<iyy>1.578896510489258</iyy>
					<iyz>-0.0012884346701907063</iyz>
					<izz>0.0255508320008188</izz>
				</inertia>
			</inertial>
			<collision name="head_collision">
				<geometry>
					<mesh>
						<uri>model://roboy_xylophone/meshes/CAD/head.stl</uri>
						<scale>0.001 0.001 0.001</scale>
					</mesh>
				</geometry>
			</collision>
			<visual name="head_visual">
				<geometry>
					<mesh>
						<uri>model://roboy_xylophone/meshes/CAD/head.stl</uri>
						<scale>0.001 0.001 0.001</scale>
					</mesh>
				</geometry>
			</visual>
		</link>
		<link name="base">
			<self_collide>false</self_collide>
			<pose frame="">0.0 0.0 0.0 0.0 -0.0 0.0</pose>
			<inertial>
				<pose frame="">0.0 0.0 0.0 0 0 0</pose>
				<mass>0.8375538014504047</mass>
				<inertia>
					<ixx>0.004947439478836191</ixx>
					<ixy>1.8900910193672462e-05</ixy>
					<ixz>1.8376373411173705e-05</ixz>
					<iyy>0.013020882991024406</iyy>
					<iyz>7.086050217485074e-06</iyz>
					<izz>0.012613089761592724</izz>
				</inertia>
			</inertial>
			<collision name="base_collision">
				<geometry>
					<mesh>
						<uri>model://roboy_xylophone/meshes/CAD/base.stl</uri>
						<scale>0.001 0.001 0.001</scale>
					</mesh>
				</geometry>
			</collision>
			<visual name="base_visual">
				<geometry>
					<mesh>
						<uri>model://roboy_xylophone/meshes/CAD/base.stl</uri>
						<scale>0.001 0.001 0.001</scale>
					</mesh>
				</geometry>
			</visual>
		</link>
		<link name="left_stick_tip">
			<self_collide>false</self_collide>
			<pose frame="">0.2692093428891479 -0.27579017670378486 -0.20327503666285687 0.0 -0.0 0.0</pose>
			<inertial>
				<pose frame="">0.0 0.0 0.0 0 0 0</pose>
				<mass>0.026023156971151314</mass>
				<inertia>
					<ixx>0.003055544257033057</ixx>
					<ixy>0.0019320978532239472</ixy>
					<ixz>-0.0014587537400506572</ixz>
					<iyy>0.002962679652716562</iyy>
					<iyz>0.001424079527170524</iyz>
					<izz>0.003866281674384223</izz>
				</inertia>
			</inertial>
			<collision name="left_stick_tip_collision">
				<geometry>
					<mesh>
						<uri>model://roboy_xylophone/meshes/CAD/left_stick_tip.stl</uri>
						<scale>0.001 0.001 0.001</scale>
					</mesh>
				</geometry>
			</collision>
			<visual name="left_stick_tip_visual">
				<geometry>
					<mesh>
						<uri>model://roboy_xylophone/meshes/CAD/left_stick_tip.stl</uri>
						<scale>0.001 0.001 0.001</scale>
					</mesh>
				</geometry>
			</visual>
		</link>
		<link name="right_stick_tip">
			<self_collide>false</self_collide>
			<pose frame="">-0.272131258246756 -0.2756784841545138 -0.20336496032974374 0.0 -0.0 0.0</pose>
			<inertial>
				<pose frame="">0.0 0.0 0.0 0 0 0</pose>
				<mass>0.02602315697115411</mass>
				<inertia>
					<ixx>0.00305489268329945</ixx>
					<ixy>-0.0019522723505767325</ixy>
					<ixz>-0.001458818403558204</ixz>
					<iyy>0.003004799357065121</iyy>
					<iyz>-0.0014401715227325498</iyz>
					<izz>0.0039058346651765483</izz>
				</inertia>
			</inertial>
			<collision name="right_stick_tip_collision">
				<geometry>
					<mesh>
						<uri>model://roboy_xylophone/meshes/CAD/right_stick_tip.stl</uri>
						<scale>0.001 0.001 0.001</scale>
					</mesh>
				</geometry>
			</collision>
			<visual name="right_stick_tip_visual">
				<geometry>
					<mesh>
						<uri>model://roboy_xylophone/meshes/CAD/right_stick_tip.stl</uri>
						<scale>0.001 0.001 0.001</scale>
					</mesh>
				</geometry>
			</visual>
		</link>
		<joint name="left_wrist_0" type="revolute">
			<parent>lower_arm_left</parent>
			<child>wrist_left_1</child>
			<pose frame="">-0.009900625387205118 -0.0006389576348572506 -0.0010673226779253132 0 0 0</pose>
			<axis>
				<xyz>-0.9974356911086111 -0.06112686075287341 0.037222963304743374</xyz>
				<limit>
					<lower>-0.5235987755982988</lower>
					<upper>0.5235987755982988</upper>
				</limit>
				<use_parent_model_frame>0</use_parent_model_frame>
			</axis>
		</joint>
		<joint name="left_wrist_1" type="revolute">
			<parent>wrist_left_1</parent>
			<child>left_hand</child>
			<pose frame="">0.015726692712065785 -0.015184675598829038 0.08434970839173359 0 0 0</pose>
			<axis>
				<xyz>-0.06197857490501217 0.9978311478764739 -0.022173330382833693</xyz>
				<limit>
					<lower>-0.5235987755982988</lower>
					<upper>0.5235987755982988</upper>
				</limit>
				<use_parent_model_frame>0</use_parent_model_frame>
			</axis>
		</joint>
		<joint name="sphere_left_axis0" type="revolute">
			<parent>torso</parent>
			<child>sphere_left_link1</child>
			<pose frame="">3.9283446540139265e-09 -1.6697847606605976e-07 -3.766154485163043e-08 0 0 0</pose>
			<axis>
				<xyz>0.9986354432836129 0.05074429632816833 -0.012339684270770038</xyz>
				<limit>
					<lower>-3.141592653589793</lower>
					<upper>3.141592653589793</upper>
				</limit>
				<use_parent_model_frame>0</use_parent_model_frame>
			</axis>
		</joint>
		<joint name="sphere_left_axis1" type="revolute">
			<parent>sphere_left_link1</parent>
			<child>sphere_left_link2</child>
			<pose frame="">-9.872906687746764e-09 1.3921429486973835e-07 -2.5913787311537816e-08 0 0 0</pose>
			<axis>
				<xyz>-0.05101049431667493 0.9984488883025682 -0.022310242422112825</xyz>
				<limit>
					<lower>-3.141592653589793</lower>
					<upper>3.141592653589793</upper>
				</limit>
				<use_parent_model_frame>0</use_parent_model_frame>
			</axis>
		</joint>
		<joint name="sphere_left_axis2" type="revolute">
			<parent>sphere_left_link2</parent>
			<child>upper_arm_left</child>
			<pose frame="">-0.010981441799162148 0.0026006691102354105 0.15153981541603231 0 0 0</pose>
			<axis>
				<xyz>-0.01118842648953418 -0.022909252225335505 -0.9996749398055222</xyz>
				<limit>
					<lower>-3.141592653589793</lower>
					<upper>3.141592653589793</upper>
				</limit>
				<use_parent_model_frame>0</use_parent_model_frame>
			</axis>
		</joint>
		<joint name="elbow_left_rot1" type="revolute">
			<parent>elbow_left</parent>
			<child>lower_arm_left</child>
			<pose frame="">0.0015883800233882184 0.0027619758351277875 0.12014580167753083 0 0 0</pose>
			<axis>
				<xyz>-0.011188426489533955 -0.022909252225335637 -0.9996749398055156</xyz>
				<limit>
					<lower>-1.5707963267948966</lower>
					<upper>1.5707963267948966</upper>
				</limit>
				<use_parent_model_frame>0</use_parent_model_frame>
			</axis>
		</joint>
		<joint name="elbow_left_rot0" type="revolute">
			<parent>upper_arm_left</parent>
			<child>elbow_left</child>
			<pose frame="">0.014657053051341755 -0.00368655744913409 0.03741012373978524 0 0 0</pose>
			<axis>
				<xyz>-0.9986354432836098 -0.05074429632816577 0.012339684270769044</xyz>
				<limit>
					<lower>0.0</lower>
					<upper>1.5707963267948966</upper>
				</limit>
				<use_parent_model_frame>0</use_parent_model_frame>
			</axis>
		</joint>
		<joint name="elbow_right_rot1" type="revolute">
			<parent>elbow_right</parent>
			<child>lower_arm_right</child>
			<pose frame="">-0.0014317049176433016 0.0028331904169268964 0.1236931270570428 0 0 0</pose>
			<axis>
				<xyz>-0.01118842648953284 0.022909252225335578 0.999674939805517</xyz>
				<limit>
					<lower>-1.5707963267948966</lower>
					<upper>1.5707963267948966</upper>
				</limit>
				<use_parent_model_frame>0</use_parent_model_frame>
			</axis>
		</joint>
		<joint name="hip_joint" type="revolute">
			<parent>base</parent>
			<child>torso</child>
			<pose frame="">6.8199713028958765e-19 0.001521781085074027 0.10423789166998208 0 0 0</pose>
			<axis>
				<xyz>-9.863650210179225e-31 5.148659276699155e-15 -1.0000000000000002</xyz>
				<limit>
					<lower>-0.17453292519943295</lower>
					<upper>0.17453292519943295</upper>
				</limit>
				<use_parent_model_frame>0</use_parent_model_frame>
			</axis>
		</joint>
		<joint name="sphere_right_axis0" type="revolute">
			<parent>torso</parent>
			<child>sphere_right_link1</child>
			<pose frame="">-8.958507578427089e-08 -1.6805291932708855e-07 -1.2962123818738291e-08 0 0 0</pose>
			<axis>
				<xyz>0.05101049431667341 0.998448888302569 -0.022310242422112804</xyz>
				<limit>
					<lower>-3.141592653589793</lower>
					<upper>3.141592653589793</upper>
				</limit>
				<use_parent_model_frame>0</use_parent_model_frame>
			</axis>
		</joint>
		<joint name="sphere_right_axis2" type="revolute">
			<parent>sphere_right_link2</parent>
			<child>upper_arm_right</child>
			<pose frame="">0.010364674320048835 0.004967615846207826 0.1509822585468786 0 0 0</pose>
			<axis>
				<xyz>0.011188426489535866 -0.022909252225335328 -0.9996749398055187</xyz>
				<limit>
					<lower>-3.141592653589793</lower>
					<upper>3.141592653589793</upper>
				</limit>
				<use_parent_model_frame>0</use_parent_model_frame>
			</axis>
		</joint>
		<joint name="sphere_right_axis1" type="revolute">
			<parent>sphere_right_link1</parent>
			<child>sphere_right_link2</child>
			<pose frame="">1.1628181660228165e-07 1.2732201988607807e-07 -1.033454232413078e-08 0 0 0</pose>
			<axis>
				<xyz>-0.9986354432836146 0.050744296328166766 -0.012339684270771867</xyz>
				<limit>
					<lower>-3.141592653589793</lower>
					<upper>3.141592653589793</upper>
				</limit>
				<use_parent_model_frame>0</use_parent_model_frame>
			</axis>
		</joint>
		<joint name="elbow_right_rot0" type="revolute">
			<parent>upper_arm_right</parent>
			<child>elbow_right</child>
			<pose frame="">-0.015052497896296053 -0.0035973057548359805 0.03935067099656884 0 0 0</pose>
			<axis>
				<xyz>-0.9986354432836139 0.050744296328165295 -0.012339684270768765</xyz>
				<limit>
					<lower>0.0</lower>
					<upper>1.5707963267948966</upper>
				</limit>
				<use_parent_model_frame>0</use_parent_model_frame>
			</axis>
		</joint>
		<joint name="right_wrist_0" type="revolute">
			<parent>lower_arm_right</parent>
			<child>wrist_right_1</child>
			<pose frame="">0.011094392792996715 -0.00048043688755373905 -0.0015766831427710582 0 0 0</pose>
			<axis>
				<xyz>0.9991077747968851 -0.04032476901588534 -0.012552583169695498</xyz>
				<limit>
					<lower>-0.5235987755982988</lower>
					<upper>0.5235987755982988</upper>
				</limit>
				<use_parent_model_frame>0</use_parent_model_frame>
			</axis>
		</joint>
		<joint name="right_wrist_1" type="revolute">
			<parent>wrist_right_1</parent>
			<child>right_hand</child>
			<pose frame="">-0.015531310593887149 0.014734962767048852 0.07934944438475781 0 0 0</pose>
			<axis>
				<xyz>0.040036256805536984 0.9989461168065814 -0.022444461634320585</xyz>
				<limit>
					<lower>-0.5235987755982988</lower>
					<upper>0.5235987755982988</upper>
				</limit>
				<use_parent_model_frame>0</use_parent_model_frame>
			</axis>
		</joint>
		<joint name="zed_camera_mount" type="fixed">
			<parent>head</parent>
			<child>zed_camera</child>
			<pose frame="">0.02149999999998915 -0.04477388309942952 -0.028803364797665838 0 0 0</pose>
		</joint>
		<joint name="sphere_head_axis0" type="revolute">
			<parent>torso</parent>
			<child>sphere_head_link1</child>
			<pose frame="">-3.0802094775900282e-18 -3.608224830031759e-18 -1.4210854715202004e-16 0 0 0</pose>
			<axis>
				<xyz>2.506675422786485e-16 -1.0000000000000004 8.242631900833768e-15</xyz>
				<limit>
					<lower>-0.5235987755982988</lower>
					<upper>0.5235987755982988</upper>
				</limit>
				<use_parent_model_frame>0</use_parent_model_frame>
			</axis>
		</joint>
		<joint name="sphere_head_axis2" type="revolute">
			<parent>shere_head_link2</parent>
			<child>head</child>
			<pose frame="">-0.0006492376358865602 -0.013524329736299884 -0.15538726846565296 0 0 0</pose>
			<axis>
				<xyz>-2.4131887955448744e-14 8.24263190083376e-15 1.0</xyz>
				<limit>
					<lower>-0.5235987755982988</lower>
					<upper>0.5235987755982988</upper>
				</limit>
				<use_parent_model_frame>0</use_parent_model_frame>
			</axis>
		</joint>
		<joint name="sphere_head_axis1" type="revolute">
			<parent>sphere_head_link1</parent>
			<child>shere_head_link2</child>
			<pose frame="">-1.7288546692289503e-17 -1.3322676295501878e-17 2.842170943040401e-16 0 0 0</pose>
			<axis>
				<xyz>-1.0000000000000004 -2.506675422788488e-16 -2.413188795544875e-14</xyz>
				<limit>
					<lower>-0.5235987755982988</lower>
					<upper>0.5235987755982988</upper>
				</limit>
				<use_parent_model_frame>0</use_parent_model_frame>
			</axis>
		</joint>
		<joint name="zed_camera_right" type="fixed">
			<parent>zed_camera</parent>
			<child>zed_camera_right_lense</child>
			<pose frame="">-1.1119993814645568e-14 -0.019342045553250423 -0.04220906861921591 0 0 0</pose>
		</joint>
		<joint name="zed_camera_left" type="fixed">
			<parent>zed_camera</parent>
			<child>zed_camera_left_lense</child>
			<pose frame="">-1.7810504181934308e-05 -0.01934204555325101 -0.04220906875296009 0 0 0</pose>
		</joint>
		<joint name="right_stick_tip_joint" type="fixed">
			<parent>right_hand</parent>
			<child>right_stick_tip</child>
			<pose frame="">3.641937525824091e-05 0.004375147831467672 0.0011678299880273713 0 0 0</pose>
		</joint>
		<joint name="left_stick_tip_joint" type="fixed">
			<parent>left_hand</parent>
			<child>left_stick_tip</child>
			<pose frame="">8.740522319321542e-06 0.004273732635654888 0.0011412002917457898 0 0 0</pose>
		</joint>
		<!--<plugin filename="libmusc_plugin.so" name="musc_plugin">-->
			<!--<myoMuscle name="motor0">-->
				<!--<link name="torso">-->
					<!--<viaPoint type="FIXPOINT">0.28894109223784714 -0.010689615277494027 0.57625463538261</viaPoint>-->
				<!--</link>-->
				<!--<link name="upper_arm_left">-->
					<!--<viaPoint type="FIXPOINT">0.009107007608151 -0.019682077874090643 0.10331945289902862</viaPoint>-->
				<!--</link>-->
			<!--</myoMuscle>-->
			<!--<myoMuscle name="motor1">-->
				<!--<link name="torso">-->
					<!--<viaPoint type="FIXPOINT">0.24003539451940256 -0.0255094396635371 0.46729404948318215</viaPoint>-->
				<!--</link>-->
				<!--<link name="upper_arm_left">-->
					<!--<viaPoint type="FIXPOINT">-0.02769330790705368 -0.01834408211222374 0.1037006619574678</viaPoint>-->
				<!--</link>-->
			<!--</myoMuscle>-->
			<!--<myoMuscle name="motor2">-->
				<!--<link name="torso">-->
					<!--<viaPoint type="FIXPOINT">0.2512180133128362 -0.028667405657345723 0.5145590997255798</viaPoint>-->
				<!--</link>-->
				<!--<link name="upper_arm_left">-->
					<!--<viaPoint type="FIXPOINT">-0.0015912445044742895 -0.013291804419699434 0.10029176894046536</viaPoint>-->
				<!--</link>-->
			<!--</myoMuscle>-->
			<!--<myoMuscle name="motor3">-->
				<!--<link name="torso">-->
					<!--<viaPoint type="FIXPOINT">0.28063665292590684 -0.028534400330317792 0.5580004259562042</viaPoint>-->
				<!--</link>-->
				<!--<link name="upper_arm_left">-->
					<!--<viaPoint type="FIXPOINT">0.009445707262645904 -0.020187291891001814 0.1033272399894566</viaPoint>-->
				<!--</link>-->
			<!--</myoMuscle>-->
			<!--<myoMuscle name="motor4">-->
				<!--<link name="torso">-->
					<!--<viaPoint type="FIXPOINT">0.3033935027253936 5.329351681328665e-15 0.596144953020783</viaPoint>-->
				<!--</link>-->
				<!--<link name="upper_arm_left">-->
					<!--<viaPoint type="FIXPOINT">0.018050177151121363 0.004002076468392529 0.10267659767179275</viaPoint>-->
				<!--</link>-->
			<!--</myoMuscle>-->
			<!--<myoMuscle name="motor5">-->
				<!--<link name="torso">-->
					<!--<viaPoint type="FIXPOINT">0.2769871340021271 0.04289909901328503 0.5564042514238003</viaPoint>-->
				<!--</link>-->
				<!--<link name="upper_arm_left">-->
					<!--<viaPoint type="FIXPOINT">0.007177908382789937 0.02420124620918829 0.10233538246186505</viaPoint>-->
				<!--</link>-->
			<!--</myoMuscle>-->
			<!--<myoMuscle name="motor6">-->
				<!--<link name="torso">-->
					<!--<viaPoint type="FIXPOINT">0.247561326172623 0.04290640006489306 0.512959790060908</viaPoint>-->
				<!--</link>-->
				<!--<link name="upper_arm_left">-->
					<!--<viaPoint type="FIXPOINT">-0.003092303189397079 0.016089019963885454 0.0996352573030257</viaPoint>-->
				<!--</link>-->
			<!--</myoMuscle>-->
			<!--<myoMuscle name="motor7">-->
				<!--<link name="torso">-->
					<!--<viaPoint type="FIXPOINT">0.23617466540192175 0.050058161611911685 0.465605498848829</viaPoint>-->
				<!--</link>-->
				<!--<link name="upper_arm_left">-->
					<!--<viaPoint type="FIXPOINT">-0.030174246989765764 0.018727900188507857 0.10287886123429629</viaPoint>-->
				<!--</link>-->
			<!--</myoMuscle>-->
			<!--<myoMuscle name="motor8">-->
				<!--<link name="torso">-->
					<!--<viaPoint type="FIXPOINT">0.2865401700456322 0.026075605770317516 0.576140812491758</viaPoint>-->
				<!--</link>-->
				<!--<link name="upper_arm_left">-->
					<!--<viaPoint type="FIXPOINT">0.006892451578777852 0.023664316534178047 0.10235088196995783</viaPoint>-->
				<!--</link>-->
			<!--</myoMuscle>-->
			<!--<myoMuscle name="motor27">-->
				<!--<link name="base">-->
					<!--<viaPoint type="FIXPOINT">-0.19499999851461478 -0.11347765649897372 0.08723717349165262</viaPoint>-->
				<!--</link>-->
				<!--<link name="torso">-->
					<!--<viaPoint type="FIXPOINT">0.13543876459810386 -0.06208086211104811 0.32683191492848634</viaPoint>-->
				<!--</link>-->
			<!--</myoMuscle>-->
			<!--<myoMuscle name="motor28">-->
				<!--<link name="base">-->
					<!--<viaPoint type="FIXPOINT">0.1949999985146147 -0.1134776564989737 0.0872371734916526</viaPoint>-->
				<!--</link>-->
				<!--<link name="torso">-->
					<!--<viaPoint type="FIXPOINT">-0.13663898856535112 -0.06000468869766767 0.32502942598649015</viaPoint>-->
				<!--</link>-->
			<!--</myoMuscle>-->
			<!--<myoMuscle name="motor29">-->
				<!--<link name="base">-->
					<!--<viaPoint type="FIXPOINT">-0.22500000148538477 0.0015223435010262346 0.08723717349165344</viaPoint>-->
				<!--</link>-->
				<!--<link name="torso">-->
					<!--<viaPoint type="FIXPOINT">-0.15008296104407917 2.500672069228397e-06 0.31561285492544516</viaPoint>-->
				<!--</link>-->
			<!--</myoMuscle>-->
			<!--<myoMuscle name="motor30">-->
				<!--<link name="base">-->
					<!--<viaPoint type="FIXPOINT">0.2250000014853848 0.0015223435010263528 0.08723717349165344</viaPoint>-->
				<!--</link>-->
				<!--<link name="torso">-->
					<!--<viaPoint type="FIXPOINT">0.15008296104408234 2.5006720701115108e-06 0.31561285492544544</viaPoint>-->
				<!--</link>-->
			<!--</myoMuscle>-->
			<!--<myoMuscle name="motor31">-->
				<!--<link name="base">-->
					<!--<viaPoint type="FIXPOINT">-0.19499999851461464 0.11652234350102626 0.08723717349165426</viaPoint>-->
				<!--</link>-->
				<!--<link name="torso">-->
					<!--<viaPoint type="FIXPOINT">0.11845723973009747 0.06717115764172317 0.29715852041937835</viaPoint>-->
				<!--</link>-->
			<!--</myoMuscle>-->
			<!--<myoMuscle name="motor32">-->
				<!--<link name="base">-->
					<!--<viaPoint type="FIXPOINT">0.19499999851461486 0.1165223435010261 0.08723717349165426</viaPoint>-->
				<!--</link>-->
				<!--<link name="torso">-->
					<!--<viaPoint type="FIXPOINT">-0.11544125735968605 0.06857597545288843 0.2934261837171483</viaPoint>-->
				<!--</link>-->
			<!--</myoMuscle>-->
			<!--<myoMuscle name="motor9">-->
				<!--<link name="upper_arm_left">-->
					<!--<viaPoint type="FIXPOINT">-0.014868521600140525 0.0622381133496837 -0.03434353144139649</viaPoint>-->
				<!--</link>-->
				<!--<link name="elbow_left">-->
					<!--<viaPoint type="FIXPOINT">-0.0058831795287725445 0.03527685362976118 -0.00016029939334099907</viaPoint>-->
				<!--</link>-->
			<!--</myoMuscle>-->
			<!--<myoMuscle name="motor10">-->
				<!--<link name="upper_arm_left">-->
					<!--<viaPoint type="FIXPOINT">-0.009118540788152992 -0.06636484890920305 -0.03146072989568488</viaPoint>-->
				<!--</link>-->
				<!--<link name="elbow_left">-->
					<!--<viaPoint type="FIXPOINT">-0.0020836081541752093 -0.036966509506902105 -0.01220932153872191</viaPoint>-->
				<!--</link>-->
			<!--</myoMuscle>-->
			<!--<myoMuscle name="motor11">-->
				<!--<link name="upper_arm_left">-->
					<!--<viaPoint type="FIXPOINT">0.0349226439890149 -0.00603080871552032 -0.09361434790349041</viaPoint>-->
				<!--</link>-->
				<!--<link name="elbow_left">-->
					<!--<viaPoint type="FIXPOINT">0.034895878738453484 -0.00896976499414947 -0.026894224867603605</viaPoint>-->
				<!--</link>-->
				<!--<link name="lower_arm_left">-->
					<!--<viaPoint type="FIXPOINT">-0.015052310925987201 -0.03492666285889448 0.11318452084683087</viaPoint>-->
				<!--</link>-->
			<!--</myoMuscle>-->
			<!--<myoMuscle name="motor12">-->
				<!--<link name="upper_arm_left">-->
					<!--<viaPoint type="FIXPOINT">0.026733833354088576 -0.006446911945411308 -0.09351316249246981</viaPoint>-->
				<!--</link>-->
				<!--<link name="elbow_left">-->
					<!--<viaPoint type="FIXPOINT">0.03673749832195622 0.013578966681067983 -0.033852639949793435</viaPoint>-->
				<!--</link>-->
				<!--<link name="lower_arm_left">-->
					<!--<viaPoint type="FIXPOINT">-0.018858472519074992 0.03703540487490793 0.11207814900820809</viaPoint>-->
				<!--</link>-->
			<!--</myoMuscle>-->
			<!--<myoMuscle name="motor13">-->
				<!--<link name="torso">-->
					<!--<viaPoint type="FIXPOINT">-0.2865417124191222 0.027567759775711326 0.5754772798049546</viaPoint>-->
				<!--</link>-->
				<!--<link name="upper_arm_right">-->
					<!--<viaPoint type="FIXPOINT">-0.00751481327113833 0.026042717896263005 0.10229316257070728</viaPoint>-->
				<!--</link>-->
			<!--</myoMuscle>-->
			<!--<myoMuscle name="motor14">-->
				<!--<link name="torso">-->
					<!--<viaPoint type="FIXPOINT">-0.2361746654013883 0.051580505123396486 0.4649412915804758</viaPoint>-->
				<!--</link>-->
				<!--<link name="upper_arm_right">-->
					<!--<viaPoint type="FIXPOINT">0.029551885297424824 0.021106301550601298 0.12482114183504585</viaPoint>-->
				<!--</link>-->
			<!--</myoMuscle>-->
			<!--<myoMuscle name="motor15">-->
				<!--<link name="torso">-->
					<!--<viaPoint type="FIXPOINT">-0.2475613261720895 0.04442874357637785 0.5122955827925547</viaPoint>-->
				<!--</link>-->
				<!--<link name="upper_arm_right">-->
					<!--<viaPoint type="FIXPOINT">0.0024699414970366365 0.01846742132597041 0.09957753790377524</viaPoint>-->
				<!--</link>-->
			<!--</myoMuscle>-->
			<!--<myoMuscle name="motor16">-->
				<!--<link name="torso">-->
					<!--<viaPoint type="FIXPOINT">-0.276988676375617 0.04439125301867884 0.5557407187369969</viaPoint>-->
				<!--</link>-->
				<!--<link name="upper_arm_right">-->
					<!--<viaPoint type="FIXPOINT">-0.0078002700751511255 0.02657964757127411 0.10227766306261452</viaPoint>-->
				<!--</link>-->
			<!--</myoMuscle>-->
			<!--<myoMuscle name="motor17">-->
				<!--<link name="torso">-->
					<!--<viaPoint type="FIXPOINT">-0.3100988054292128 0.0015223435010265783 0.5915377063521623</viaPoint>-->
				<!--</link>-->
				<!--<link name="upper_arm_right">-->
					<!--<viaPoint type="FIXPOINT">-0.018825437428896558 0.0033877324223911287 0.10268575087498022</viaPoint>-->
				<!--</link>-->
			<!--</myoMuscle>-->
			<!--<myoMuscle name="motor19">-->
				<!--<link name="torso">-->
					<!--<viaPoint type="FIXPOINT">-0.28063819529939676 -0.02704224632492396 0.5573368932694007</viaPoint>-->
				<!--</link>-->
				<!--<link name="upper_arm_right">-->
					<!--<viaPoint type="FIXPOINT">-0.009729369300511373 -0.017303676512005668 0.10326173349977807</viaPoint>-->
				<!--</link>-->
			<!--</myoMuscle>-->
			<!--<myoMuscle name="motor20">-->
				<!--<link name="torso">-->
					<!--<viaPoint type="FIXPOINT">-0.25121801331230276 -0.027145062145860932 0.5138948924572266</viaPoint>-->
				<!--</link>-->
				<!--<link name="upper_arm_right">-->
					<!--<viaPoint type="FIXPOINT">0.0009688828121138827 -0.010913403057614459 0.10023404954121481</viaPoint>-->
				<!--</link>-->
			<!--</myoMuscle>-->
			<!--<myoMuscle name="motor21">-->
				<!--<link name="torso">-->
					<!--<viaPoint type="FIXPOINT">-0.2400353945188691 -0.023987096152052287 0.4666298422148289</viaPoint>-->
				<!--</link>-->
				<!--<link name="upper_arm_right">-->
					<!--<viaPoint type="FIXPOINT">0.02764846758848492 -0.01615005757521661 0.10365363152340144</viaPoint>-->
				<!--</link>-->
			<!--</myoMuscle>-->
			<!--<myoMuscle name="motor22">-->
				<!--<link name="torso">-->
					<!--<viaPoint type="FIXPOINT">-0.28894263461133707 -0.009197461272100206 0.5755911026958066</viaPoint>-->
				<!--</link>-->
				<!--<link name="upper_arm_right">-->
					<!--<viaPoint type="FIXPOINT">-0.010068068955005529 -0.017808890528916054 0.10326952059020605</viaPoint>-->
				<!--</link>-->
			<!--</myoMuscle>-->
			<!--<myoMuscle name="motor23">-->
				<!--<link name="upper_arm_right">-->
					<!--<viaPoint type="FIXPOINT">0.0098267923747526 0.06497121713882363 -0.04663297257341483</viaPoint>-->
				<!--</link>-->
				<!--<link name="elbow_right">-->
					<!--<viaPoint type="FIXPOINT">0.0054765462573284655 0.03538901457628306 0.0027799228032479206</viaPoint>-->
				<!--</link>-->
			<!--</myoMuscle>-->
			<!--<myoMuscle name="motor24">-->
				<!--<link name="upper_arm_right">-->
					<!--<viaPoint type="FIXPOINT">0.00982953330524417 -0.0651136392019534 -0.022362332959808173</viaPoint>-->
				<!--</link>-->
				<!--<link name="elbow_right">-->
					<!--<viaPoint type="FIXPOINT">0.0031012347764160708 -0.034009001703024046 -0.009334104242035686</viaPoint>-->
				<!--</link>-->
			<!--</myoMuscle>-->
			<!--<myoMuscle name="motor25">-->
				<!--<link name="upper_arm_right">-->
					<!--<viaPoint type="FIXPOINT">-0.03553941146813035 -0.0036638619795479627 -0.09417190477264295</viaPoint>-->
				<!--</link>-->
				<!--<link name="elbow_right">-->
					<!--<viaPoint type="FIXPOINT">-0.03714413159340015 0.013691127627589872 -0.03091241775320441</viaPoint>-->
				<!--</link>-->
				<!--<link name="lower_arm_right">-->
					<!--<viaPoint type="FIXPOINT">-0.017241690742177553 0.03892662045364999 0.11417765192556642</viaPoint>-->
				<!--</link>-->
			<!--</myoMuscle>-->
			<!--<myoMuscle name="motor26">-->
				<!--<link name="upper_arm_right">-->
					<!--<viaPoint type="FIXPOINT">-0.02735060083320473 -0.00407996520943892 -0.09407071936162271</viaPoint>-->
				<!--</link>-->
				<!--<link name="elbow_right">-->
					<!--<viaPoint type="FIXPOINT">-0.03530251200989728 -0.008857604047627652 -0.023954002671015183</viaPoint>-->
				<!--</link>-->
				<!--<link name="lower_arm_right">-->
					<!--<viaPoint type="FIXPOINT">-0.02078027686830133 -0.03304234154382556 0.11558727402964776</viaPoint>-->
				<!--</link>-->
			<!--</myoMuscle>-->
			<!--<myoMuscle name="motor33">-->
				<!--<link name="torso">-->
					<!--<viaPoint type="FIXPOINT">-0.046024372034541225 0.052015214059931314 0.674697514155262</viaPoint>-->
				<!--</link>-->
				<!--<link name="head">-->
					<!--<viaPoint type="FIXPOINT">-0.03600457669519973 0.021831571738978612 -0.15098875018024302</viaPoint>-->
				<!--</link>-->
			<!--</myoMuscle>-->
			<!--<myoMuscle name="motor34">-->
				<!--<link name="torso">-->
					<!--<viaPoint type="FIXPOINT">-0.046000000000006314 0.0015223435010275532 0.6766975121882185</viaPoint>-->
				<!--</link>-->
				<!--<link name="head">-->
					<!--<viaPoint type="FIXPOINT">-0.000649237635872254 -0.06352376732034896 -0.15098875018024246</viaPoint>-->
				<!--</link>-->
			<!--</myoMuscle>-->
			<!--<myoMuscle name="motor35">-->
				<!--<link name="torso">-->
					<!--<viaPoint type="FIXPOINT">-0.0460290385705623 -0.048974867289732 0.6746975141552634</viaPoint>-->
				<!--</link>-->
				<!--<link name="head">-->
					<!--<viaPoint type="FIXPOINT">-0.036004576695199714 -0.0488791063796763 -0.1509887501802426</viaPoint>-->
				<!--</link>-->
			<!--</myoMuscle>-->
			<!--<myoMuscle name="motor36">-->
				<!--<link name="torso">-->
					<!--<viaPoint type="FIXPOINT">0.04603087891830206 0.05201809336370206 0.6746975141552624</viaPoint>-->
				<!--</link>-->
				<!--<link name="head">-->
					<!--<viaPoint type="FIXPOINT">0.0347061014234552 0.02183157173897862 -0.15098875018024288</viaPoint>-->
				<!--</link>-->
			<!--</myoMuscle>-->
			<!--<myoMuscle name="motor37">-->
				<!--<link name="torso">-->
					<!--<viaPoint type="FIXPOINT">0.04599999999999385 0.0015223435010275582 0.6746975121882186</viaPoint>-->
				<!--</link>-->
				<!--<link name="head">-->
					<!--<viaPoint type="FIXPOINT">-0.000649237635872254 -0.06352376732034896 -0.15098875018024246</viaPoint>-->
				<!--</link>-->
			<!--</myoMuscle>-->
			<!--<myoMuscle name="motor38">-->
				<!--<link name="torso">-->
					<!--<viaPoint type="FIXPOINT">0.04603508786431375 -0.048975343773744184 0.673697514156121</viaPoint>-->
				<!--</link>-->
				<!--<link name="head">-->
					<!--<viaPoint type="FIXPOINT">0.034706101423455205 -0.0488791063796763 -0.15098875018024246</viaPoint>-->
				<!--</link>-->
			<!--</myoMuscle>-->
		<!--</plugin>-->
	</model>
</sdf>
