<?xml version="1.0" ?>
<robot name="roboy_xylophone">
  <joint name="left_wrist_0" type="revolute">
    <parent link="lower_arm_left"/>
    <child link="wrist_left_1"/>
    <origin rpy="0  0  0" xyz="-0.01441 -0.00671 -0.26206"/>
    <axis xyz="-0.99743 -0.06112  0.03722"/>
    <limit effort="0.0" lower="-0.523598775598" upper="0.523598775598" velocity="0.0"/>
  </joint>
  <joint name="left_wrist_1" type="revolute">
    <parent link="wrist_left_1"/>
    <child link="left_hand"/>
    <origin rpy="0  0  0" xyz="0.01155 -0.01682  0"/>
    <axis xyz="-0.06197  0.99783 -0.02217"/>
    <limit effort="0.0" lower="-0.523598775598" upper="0.523598775598" velocity="0.0"/>
  </joint>
  <joint name="sphere_left_axis0" type="revolute">
    <parent link="torso"/>
    <child link="sphere_left_link1"/>
    <origin rpy="0  0  0" xyz="0.29218  0.00768  0.44437"/>
    <axis xyz="0.99863  0.05074 -0.01234"/>
    <limit effort="0.0" lower="-3.14159265359" upper="3.14159265359" velocity="0.0"/>
  </joint>
  <joint name="sphere_left_axis1" type="revolute">
    <parent link="sphere_left_link1"/>
    <child link="sphere_left_link2"/>
    <origin rpy="0  0  0" xyz="0  0  0"/>
    <axis xyz="-0.05101  0.99844 -0.02231"/>
    <limit effort="0.0" lower="-3.14159265359" upper="3.14159265359" velocity="0.0"/>
  </joint>
  <joint name="sphere_left_axis2" type="revolute">
    <parent link="sphere_left_link2"/>
    <child link="upper_arm_left"/>
    <origin rpy="0  0  0" xyz="0  0  0"/>
    <axis xyz="-0.01118 -0.0229  -0.99967"/>
    <limit effort="0.0" lower="-3.14159265359" upper="3.14159265359" velocity="0.0"/>
  </joint>
  <joint name="elbow_left_rot1" type="revolute">
    <parent link="elbow_left"/>
    <child link="lower_arm_left"/>
    <origin rpy="0  0  0" xyz="-0.01877  0.00257 -0.06612"/>
    <axis xyz="-0.01118 -0.0229  -0.99967"/>
    <limit effort="0.0" lower="-1.57079632679" upper="1.57079632679" velocity="0.0"/>
  </joint>
  <joint name="elbow_left_rot0" type="revolute">
    <parent link="upper_arm_left"/>
    <child link="elbow_left"/>
    <origin rpy="0  0  0" xyz="0.01493 -0.01022 -0.26751"/>
    <axis xyz="-0.99863 -0.05074  0.01234"/>
    <limit effort="0.0" lower="0.0" upper="1.57079632679" velocity="0.0"/>
  </joint>
  <joint name="elbow_right_rot1" type="revolute">
    <parent link="elbow_right"/>
    <child link="lower_arm_right"/>
    <origin rpy="0  0  0" xyz="0.01877  0.00257 -0.06612"/>
    <axis xyz="-0.01118  0.0229   0.99967"/>
    <limit effort="0.0" lower="-1.57079632679" upper="1.57079632679" velocity="0.0"/>
  </joint>
  <joint name="hip_joint" type="revolute">
    <parent link="base"/>
    <child link="torso"/>
    <origin rpy="0  0  0" xyz="0       0.00152  0.10423"/>
    <axis xyz="0  0 -1"/>
    <limit effort="0.0" lower="-0.174532925199" upper="0.174532925199" velocity="0.0"/>
  </joint>
  <joint name="sphere_right_axis0" type="revolute">
    <parent link="torso"/>
    <child link="sphere_right_link1"/>
    <origin rpy="0  0  0" xyz="-0.29218  0.00768  0.44437"/>
    <axis xyz="0.05101  0.99844 -0.02231"/>
    <limit effort="0.0" lower="-3.14159265359" upper="3.14159265359" velocity="0.0"/>
  </joint>
  <joint name="sphere_right_axis2" type="revolute">
    <parent link="sphere_right_link2"/>
    <child link="upper_arm_right"/>
    <origin rpy="0  0  0" xyz="0  0  0"/>
    <axis xyz="0.01118 -0.0229  -0.99967"/>
    <limit effort="0.0" lower="-3.14159265359" upper="3.14159265359" velocity="0.0"/>
  </joint>
  <joint name="sphere_right_axis1" type="revolute">
    <parent link="sphere_right_link1"/>
    <child link="sphere_right_link2"/>
    <origin rpy="0  0  0" xyz="0  0  0"/>
    <axis xyz="-0.99863  0.05074 -0.01234"/>
    <limit effort="0.0" lower="-3.14159265359" upper="3.14159265359" velocity="0.0"/>
  </joint>
  <joint name="elbow_right_rot0" type="revolute">
    <parent link="upper_arm_right"/>
    <child link="elbow_right"/>
    <origin rpy="0  0  0" xyz="-0.01492 -0.01024 -0.26851"/>
    <axis xyz="-0.99863  0.05074 -0.01234"/>
    <limit effort="0.0" lower="0.0" upper="1.57079632679" velocity="0.0"/>
  </joint>
  <joint name="right_wrist_0" type="revolute">
    <parent link="lower_arm_right"/>
    <child link="wrist_right_1"/>
    <origin rpy="0  0  0" xyz="0.01274 -0.00645 -0.26461"/>
    <axis xyz="0.9991  -0.04032 -0.01255"/>
    <limit effort="0.0" lower="-0.523598775598" upper="0.523598775598" velocity="0.0"/>
  </joint>
  <joint name="right_wrist_1" type="revolute">
    <parent link="wrist_right_1"/>
    <child link="right_hand"/>
    <origin rpy="0  0  0" xyz="-0.00979  0.0179  -0.00026"/>
    <axis xyz="0.04003  0.99894 -0.02244"/>
    <limit effort="0.0" lower="-0.523598775598" upper="0.523598775598" velocity="0.0"/>
  </joint>
  <joint name="zed_camera_mount" type="fixed">
    <parent link="head"/>
    <child link="zed_camera"/>
    <origin rpy="0  0  0" xyz="0.0215  -0.1026   0.20755"/>
    <axis xyz="0  0  0"/>
    <limit effort="0" lower="0" upper="0" velocity="0"/>
  </joint>
  <joint name="sphere_head_axis0" type="revolute">
    <parent link="torso"/>
    <child link="sphere_head_link1"/>
    <origin rpy="0  0  0" xyz="0       0       0.60686"/>
    <axis xyz="0 -1  0"/>
    <limit effort="0.0" lower="-0.523598775598" upper="0.523598775598" velocity="0.0"/>
  </joint>
  <joint name="sphere_head_axis2" type="revolute">
    <parent link="shere_head_link2"/>
    <child link="head"/>
    <origin rpy="0  0  0" xyz="0  0  0"/>
    <axis xyz="0  0  1"/>
    <limit effort="0.0" lower="-0.523598775598" upper="0.523598775598" velocity="0.0"/>
  </joint>
  <joint name="sphere_head_axis1" type="revolute">
    <parent link="sphere_head_link1"/>
    <child link="shere_head_link2"/>
    <origin rpy="0  0  0" xyz="0  0  0"/>
    <axis xyz="-1  0  0"/>
    <limit effort="0.0" lower="-0.523598775598" upper="0.523598775598" velocity="0.0"/>
  </joint>
  <joint name="zed_camera_right" type="fixed">
    <parent link="zed_camera"/>
    <child link="zed_camera_right_lense"/>
    <origin rpy="0  0  0" xyz="-0.0815  0     -0.008"/>
    <axis xyz="0  0  0"/>
    <limit effort="0" lower="0" upper="0" velocity="0"/>
  </joint>
  <joint name="zed_camera_left" type="fixed">
    <parent link="zed_camera"/>
    <child link="zed_camera_left_lense"/>
    <origin rpy="0  0  0" xyz="0.03848  0      -0.008"/>
    <axis xyz="0  0  0"/>
    <limit effort="0" lower="0" upper="0" velocity="0"/>
  </joint>
  <joint name="right_stick_tip_joint" type="revolute">
    <parent link="right_hand"/>
    <child link="right_stick_tip"/>
    <origin rpy="0  0  0" xyz="0.01328 -0.28428 -0.15129"/>
    <axis xyz="0  0  0"/>
    <limit effort="0" lower="0" upper="0" velocity="0"/>
  </joint>
  <joint name="left_stick_tip_joint" type="revolute">
    <parent link="left_hand"/>
    <child link="left_stick_tip"/>
    <origin rpy="0  0  0" xyz="-0.01626 -0.24953 -0.15503"/>
    <axis xyz="0  0  0"/>
    <limit effort="0" lower="0" upper="0" velocity="0"/>
  </joint>
  <link name="torso">
    <inertial>
      <mass value="13.72368407891531"/>
      <origin rpy="0  0  0" xyz="0      -0.00152 -0.10423"/>
      <inertia ixx="3.910765453374194" ixy="-0.001095224797113174" ixz="0.043302154633862465" iyy="4.168439034043004" iyz="-0.013228815176824301" izz="0.3524412985016293"/>
    </inertial>
    <collision name="torso_collision">
      <origin rpy="0  0  0" xyz="0      -0.00152 -0.10423"/>
      <geometry>
        <mesh filename="package://robots/roboy_xylophone/meshes/CAD/torso.stl" scale="0.001 0.001 0.001"/>
      </geometry>
    </collision>
    <visual name="torso_visual">
      <origin rpy="0  0  0" xyz="0      -0.00152 -0.10423"/>
      <geometry>
        <mesh filename="package://robots/roboy_xylophone/meshes/CAD/torso.stl" scale="0.001 0.001 0.001"/>
      </geometry>
    </visual>
  </link>
  <link name="right_hand">
    <inertial>
      <mass value="0.20805908239869125"/>
      <origin rpy="0  0  0" xyz="0.01553 -0.01473 -0.07934"/>
      <inertia ixx="0.0075567109842610385" ixy="-0.003870948682374514" ixz="-0.0027023479542121133" iyy="0.019913740298193046" iyz="-0.0076257923873708664" izz="0.018971657099651783"/>
    </inertial>
    <collision name="right_hand_collision">
      <origin rpy="0  0  0" xyz="0.01553 -0.01473 -0.07934"/>
      <geometry>
        <mesh filename="package://robots/roboy_xylophone/meshes/CAD/right_hand.stl" scale="0.001 0.001 0.001"/>
      </geometry>
    </collision>
    <visual name="right_hand_visual">
      <origin rpy="0  0  0" xyz="0.01553 -0.01473 -0.07934"/>
      <geometry>
        <mesh filename="package://robots/roboy_xylophone/meshes/CAD/right_hand.stl" scale="0.001 0.001 0.001"/>
      </geometry>
    </visual>
  </link>
  <link name="left_hand">
    <inertial>
      <mass value="0.18650433962187907"/>
      <origin rpy="0  0  0" xyz="-0.01572  0.01518 -0.08435"/>
      <inertia ixx="0.00742411081802007" ixy="0.0038015046666095465" ixz="-0.002693661217771364" iyy="0.01767984161098725" iyz="0.007164025065289065" izz="0.016872438513441758"/>
    </inertial>
    <collision name="left_hand_collision">
      <origin rpy="0  0  0" xyz="-0.01572  0.01518 -0.08435"/>
      <geometry>
        <mesh filename="package://robots/roboy_xylophone/meshes/CAD/left_hand.stl" scale="0.001 0.001 0.001"/>
      </geometry>
    </collision>
    <visual name="left_hand_visual">
      <origin rpy="0  0  0" xyz="-0.01572  0.01518 -0.08435"/>
      <geometry>
        <mesh filename="package://robots/roboy_xylophone/meshes/CAD/left_hand.stl" scale="0.001 0.001 0.001"/>
      </geometry>
    </visual>
  </link>
  <link name="elbow_left">
    <inertial>
      <mass value="0.15681537169755258"/>
      <origin rpy="0  0  0" xyz="-0.01465  0.00368 -0.03741"/>
      <inertia ixx="0.009431757217348843" ixy="-0.00012517065329283248" ixz="-9.888439213748464e-05" iyy="0.022865599183266166" iyz="-0.011162126418678987" izz="0.013542050845808416"/>
    </inertial>
    <collision name="elbow_left_collision">
      <origin rpy="0  0  0" xyz="-0.01465  0.00368 -0.03741"/>
      <geometry>
        <mesh filename="package://robots/roboy_xylophone/meshes/CAD/elbow_left.stl" scale="0.001 0.001 0.001"/>
      </geometry>
    </collision>
    <visual name="elbow_left_visual">
      <origin rpy="0  0  0" xyz="-0.01465  0.00368 -0.03741"/>
      <geometry>
        <mesh filename="package://robots/roboy_xylophone/meshes/CAD/elbow_left.stl" scale="0.001 0.001 0.001"/>
      </geometry>
    </visual>
  </link>
  <link name="elbow_right">
    <inertial>
      <mass value="0.1737509895674572"/>
      <origin rpy="0  0  0" xyz="0.01505  0.00359 -0.03935"/>
      <inertia ixx="0.010199619270761047" ixy="0.00013260458238670674" ixz="-0.0001041660034778284" iyy="0.02504128534242205" iyz="0.012203668182971939" izz="0.014951862459761598"/>
    </inertial>
    <collision name="elbow_right_collision">
      <origin rpy="0  0  0" xyz="0.01505  0.00359 -0.03935"/>
      <geometry>
        <mesh filename="package://robots/roboy_xylophone/meshes/CAD/elbow_right.stl" scale="0.001 0.001 0.001"/>
      </geometry>
    </collision>
    <visual name="elbow_right_visual">
      <origin rpy="0  0  0" xyz="0.01505  0.00359 -0.03935"/>
      <geometry>
        <mesh filename="package://robots/roboy_xylophone/meshes/CAD/elbow_right.stl" scale="0.001 0.001 0.001"/>
      </geometry>
    </visual>
  </link>
  <link name="sphere_right_link1">
    <inertial>
      <mass value="0.04675596089362313"/>
      <origin rpy="0  0  0" xyz="0  0  0"/>
      <inertia ixx="0.014082487940467327" ixy="0.00012582201998645568" ixz="-0.00023625123995044107" iyy="0.01807003753984725" iyz="0.0074947179360907975" izz="0.004001456143427335"/>
    </inertial>
    <collision name="sphere_right_link1_collision">
      <origin rpy="0  0  0" xyz="0  0  0"/>
      <geometry>
        <mesh filename="package://robots/roboy_xylophone/meshes/CAD/sphere_right_link1.stl" scale="0.001 0.001 0.001"/>
      </geometry>
    </collision>
    <visual name="sphere_right_link1_visual">
      <origin rpy="0  0  0" xyz="0  0  0"/>
      <geometry>
        <mesh filename="package://robots/roboy_xylophone/meshes/CAD/sphere_right_link1.stl" scale="0.001 0.001 0.001"/>
      </geometry>
    </visual>
  </link>
  <link name="sphere_right_link2">
    <inertial>
      <mass value="0.03133941577358247"/>
      <origin rpy="0  0  0" xyz="0  0  0"/>
      <inertia ixx="0.009437852970646556" ixy="8.433288313845014e-05" ixz="-0.00015834854451237578" iyy="0.012110617225243162" iyz="0.005023535852643668" izz="0.002680779380039669"/>
    </inertial>
    <collision name="sphere_right_link2_collision">
      <origin rpy="0  0  0" xyz="0  0  0"/>
      <geometry>
        <mesh filename="package://robots/roboy_xylophone/meshes/CAD/sphere_right_link2.stl" scale="0.001 0.001 0.001"/>
      </geometry>
    </collision>
    <visual name="sphere_right_link2_visual">
      <origin rpy="0  0  0" xyz="0  0  0"/>
      <geometry>
        <mesh filename="package://robots/roboy_xylophone/meshes/CAD/sphere_right_link2.stl" scale="0.001 0.001 0.001"/>
      </geometry>
    </visual>
  </link>
  <link name="sphere_left_link1">
    <inertial>
      <mass value="0.046755519327953445"/>
      <origin rpy="0  0  0" xyz="0  0  0"/>
      <inertia ixx="0.014082356273081548" ixy="-0.00012582086921548955" ixz="-0.00023624902092354817" iyy="0.01806987052231626" iyz="-0.00749464968837342" izz="0.004001420718449545"/>
    </inertial>
    <collision name="sphere_left_link1_collision">
      <origin rpy="0  0  0" xyz="0  0  0"/>
      <geometry>
        <mesh filename="package://robots/roboy_xylophone/meshes/CAD/sphere_left_link1.stl" scale="0.001 0.001 0.001"/>
      </geometry>
    </collision>
    <visual name="sphere_left_link1_visual">
      <origin rpy="0  0  0" xyz="0  0  0"/>
      <geometry>
        <mesh filename="package://robots/roboy_xylophone/meshes/CAD/sphere_left_link1.stl" scale="0.001 0.001 0.001"/>
      </geometry>
    </visual>
  </link>
  <link name="sphere_left_link2">
    <inertial>
      <mass value="0.031340208481721574"/>
      <origin rpy="0  0  0" xyz="0  0  0"/>
      <inertia ixx="0.009438092156368896" ixy="-8.433488846064293e-05" ixz="-0.00015835236925662997" iyy="0.012110922096803804" iyz="-0.005023661231281029" izz="0.0026808451877708057"/>
    </inertial>
    <collision name="sphere_left_link2_collision">
      <origin rpy="0  0  0" xyz="0  0  0"/>
      <geometry>
        <mesh filename="package://robots/roboy_xylophone/meshes/CAD/sphere_left_link2.stl" scale="0.001 0.001 0.001"/>
      </geometry>
    </collision>
    <visual name="sphere_left_link2_visual">
      <origin rpy="0  0  0" xyz="0  0  0"/>
      <geometry>
        <mesh filename="package://robots/roboy_xylophone/meshes/CAD/sphere_left_link2.stl" scale="0.001 0.001 0.001"/>
      </geometry>
    </visual>
  </link>
  <link name="wrist_left_1">
    <inertial>
      <mass value="0.012764273069100246"/>
      <origin rpy="0  0  0" xyz="0.0099   0.00063  0.00106"/>
      <inertia ixx="2.9933237342887354e-05" ixy="1.6313062661204246e-05" ixz="-2.60614002361967e-06" iyy="0.001058859487958565" iyz="0.00016684286591328332" izz="0.0010339769540120504"/>
    </inertial>
    <collision name="wrist_left_1_collision">
      <origin rpy="0  0  0" xyz="0.0099   0.00063  0.00106"/>
      <geometry>
        <mesh filename="package://robots/roboy_xylophone/meshes/CAD/wrist_left_1.stl" scale="0.001 0.001 0.001"/>
      </geometry>
    </collision>
    <visual name="wrist_left_1_visual">
      <origin rpy="0  0  0" xyz="0.0099   0.00063  0.00106"/>
      <geometry>
        <mesh filename="package://robots/roboy_xylophone/meshes/CAD/wrist_left_1.stl" scale="0.001 0.001 0.001"/>
      </geometry>
    </visual>
  </link>
  <link name="wrist_right_1">
    <inertial>
      <mass value="0.012762562533547099"/>
      <origin rpy="0  0  0" xyz="-0.01109  0.00048  0.00157"/>
      <inertia ixx="3.3596818331877835e-05" ixy="-1.6206001652051634e-05" ixz="-2.73824321167433e-06" iyy="0.0010832076300652943" iyz="-0.00017947272958513367" izz="0.001054639875188272"/>
    </inertial>
    <collision name="wrist_right_1_collision">
      <origin rpy="0  0  0" xyz="-0.01109  0.00048  0.00157"/>
      <geometry>
        <mesh filename="package://robots/roboy_xylophone/meshes/CAD/wrist_right_1.stl" scale="0.001 0.001 0.001"/>
      </geometry>
    </collision>
    <visual name="wrist_right_1_visual">
      <origin rpy="0  0  0" xyz="-0.01109  0.00048  0.00157"/>
      <geometry>
        <mesh filename="package://robots/roboy_xylophone/meshes/CAD/wrist_right_1.stl" scale="0.001 0.001 0.001"/>
      </geometry>
    </visual>
  </link>
  <link name="upper_arm_left">
    <inertial>
      <mass value="1.1809063299122686"/>
      <origin rpy="0  0  0" xyz="0.01098 -0.0026  -0.15154"/>
      <inertia ixx="0.1924990473234301" ixy="-0.0023063348715922343" ixz="-0.00308931839405198" iyy="0.2997319906640523" iyz="-0.14192245743426316" izz="0.11100085723502803"/>
    </inertial>
    <collision name="upper_arm_left_collision">
      <origin rpy="0  0  0" xyz="0.01098 -0.0026  -0.15154"/>
      <geometry>
        <mesh filename="package://robots/roboy_xylophone/meshes/CAD/upper_arm_left.stl" scale="0.001 0.001 0.001"/>
      </geometry>
    </collision>
    <visual name="upper_arm_left_visual">
      <origin rpy="0  0  0" xyz="0.01098 -0.0026  -0.15154"/>
      <geometry>
        <mesh filename="package://robots/roboy_xylophone/meshes/CAD/upper_arm_left.stl" scale="0.001 0.001 0.001"/>
      </geometry>
    </visual>
  </link>
  <link name="lower_arm_left">
    <inertial>
      <mass value="1.41591868208817"/>
      <origin rpy="0  0  0" xyz="-0.00158 -0.00276 -0.12014"/>
      <inertia ixx="0.01972474263641184" ixy="0.0004870846174633889" ixz="3.185483018737706e-05" iyy="0.1361518524392809" iyz="-0.03856116577753053" izz="0.11772501099801312"/>
    </inertial>
    <collision name="lower_arm_left_collision">
      <origin rpy="0  0  0" xyz="-0.00158 -0.00276 -0.12014"/>
      <geometry>
        <mesh filename="package://robots/roboy_xylophone/meshes/CAD/lower_arm_left.stl" scale="0.001 0.001 0.001"/>
      </geometry>
    </collision>
    <visual name="lower_arm_left_visual">
      <origin rpy="0  0  0" xyz="-0.00158 -0.00276 -0.12014"/>
      <geometry>
        <mesh filename="package://robots/roboy_xylophone/meshes/CAD/lower_arm_left.stl" scale="0.001 0.001 0.001"/>
      </geometry>
    </visual>
  </link>
  <link name="lower_arm_right">
    <inertial>
      <mass value="1.3992272098398937"/>
      <origin rpy="0  0  0" xyz="0.00143 -0.00283 -0.12369"/>
      <inertia ixx="0.018109856489779336" ixy="-0.000519132167958026" ixz="4.0051155010875704e-05" iyy="0.1332812730438574" iyz="0.036311065649301234" izz="0.11646776713622453"/>
    </inertial>
    <collision name="lower_arm_right_collision">
      <origin rpy="0  0  0" xyz="0.00143 -0.00283 -0.12369"/>
      <geometry>
        <mesh filename="package://robots/roboy_xylophone/meshes/CAD/lower_arm_right.stl" scale="0.001 0.001 0.001"/>
      </geometry>
    </collision>
    <visual name="lower_arm_right_visual">
      <origin rpy="0  0  0" xyz="0.00143 -0.00283 -0.12369"/>
      <geometry>
        <mesh filename="package://robots/roboy_xylophone/meshes/CAD/lower_arm_right.stl" scale="0.001 0.001 0.001"/>
      </geometry>
    </visual>
  </link>
  <link name="upper_arm_right">
    <inertial>
      <mass value="1.0958327493598512"/>
      <origin rpy="0  0  0" xyz="-0.01036 -0.00496 -0.15098"/>
      <inertia ixx="0.17904249668222721" ixy="0.0013739028297231495" ixz="-0.0018802494637687244" iyy="0.2781451232699976" iyz="0.13162899491953578" izz="0.10257941183247153"/>
    </inertial>
    <collision name="upper_arm_right_collision">
      <origin rpy="0  0  0" xyz="-0.01036 -0.00496 -0.15098"/>
      <geometry>
        <mesh filename="package://robots/roboy_xylophone/meshes/CAD/upper_arm_right.stl" scale="0.001 0.001 0.001"/>
      </geometry>
    </collision>
    <visual name="upper_arm_right_visual">
      <origin rpy="0  0  0" xyz="-0.01036 -0.00496 -0.15098"/>
      <geometry>
        <mesh filename="package://robots/roboy_xylophone/meshes/CAD/upper_arm_right.stl" scale="0.001 0.001 0.001"/>
      </geometry>
    </visual>
  </link>
  <link name="zed_camera_left_lense">
    <inertial>
      <mass value="0.0057554218156879965"/>
      <origin rpy="0  0  0" xyz="1.00000000e-05   1.93400000e-02   4.22000000e-02"/>
      <inertia ixx="0.004846011997714692" ixy="3.8815189387356356e-05" ixz="0.0005891027444713396" iyy="0.004793831227370643" iyz="-0.00031448074428470696" izz="9.383240644717277e-05"/>
    </inertial>
    <collision name="zed_camera_left_lense_collision">
      <origin rpy="0  0  0" xyz="1.00000000e-05   1.93400000e-02   4.22000000e-02"/>
      <geometry>
        <mesh filename="package://robots/roboy_xylophone/meshes/CAD/zed_camera_left_lense.stl" scale="0.001 0.001 0.001"/>
      </geometry>
    </collision>
    <visual name="zed_camera_left_lense_visual">
      <origin rpy="0  0  0" xyz="1.00000000e-05   1.93400000e-02   4.22000000e-02"/>
      <geometry>
        <mesh filename="package://robots/roboy_xylophone/meshes/CAD/zed_camera_left_lense.stl" scale="0.001 0.001 0.001"/>
      </geometry>
    </visual>
  </link>
  <link name="zed_camera_right_lense">
    <inertial>
      <mass value="0.0057554218156880485"/>
      <origin rpy="0  0  0" xyz="0       0.01934  0.0422"/>
      <inertia ixx="0.004846011997551049" ixy="-3.881429332761528e-05" ixz="0.0005891027444611853" iyy="0.004793830279485115" iyz="0.00031447355054664474" izz="9.383145872528843e-05"/>
    </inertial>
    <collision name="zed_camera_right_lense_collision">
      <origin rpy="0  0  0" xyz="0       0.01934  0.0422"/>
      <geometry>
        <mesh filename="package://robots/roboy_xylophone/meshes/CAD/zed_camera_right_lense.stl" scale="0.001 0.001 0.001"/>
      </geometry>
    </collision>
    <visual name="zed_camera_right_lense_visual">
      <origin rpy="0  0  0" xyz="0       0.01934  0.0422"/>
      <geometry>
        <mesh filename="package://robots/roboy_xylophone/meshes/CAD/zed_camera_right_lense.stl" scale="0.001 0.001 0.001"/>
      </geometry>
    </visual>
  </link>
  <link name="zed_camera">
    <inertial>
      <mass value="0.009633908092012306"/>
      <origin rpy="0  0  0" xyz="-0.0215   0.04477  0.0288"/>
      <inertia ixx="0.008084590483556824" ixy="4.052560334214878e-06" ixz="0.0008835532966109025" iyy="0.008001682762379227" iyz="-3.558756214861936e-05" izz="0.00011263547643344076"/>
    </inertial>
    <collision name="zed_camera_collision">
      <origin rpy="0  0  0" xyz="-0.0215   0.04477  0.0288"/>
      <geometry>
        <mesh filename="package://robots/roboy_xylophone/meshes/CAD/zed_camera.stl" scale="0.001 0.001 0.001"/>
      </geometry>
    </collision>
    <visual name="zed_camera_visual">
      <origin rpy="0  0  0" xyz="-0.0215   0.04477  0.0288"/>
      <geometry>
        <mesh filename="package://robots/roboy_xylophone/meshes/CAD/zed_camera.stl" scale="0.001 0.001 0.001"/>
      </geometry>
    </visual>
  </link>
  <link name="sphere_head_link1">
    <inertial>
      <mass value="0.023938100802369734"/>
      <origin rpy="0  0  0" xyz="0  0  0"/>
      <inertia ixx="0.012106595625813408" ixy="7.508425305113864e-19" ixz="-2.5904304543214497e-05" iyy="0.012106540189536562" iyz="3.5051683777709287e-16" izz="2.012994235293797e-06"/>
    </inertial>
    <collision name="sphere_head_link1_collision">
      <origin rpy="0  0  0" xyz="0  0  0"/>
      <geometry>
        <mesh filename="package://robots/roboy_xylophone/meshes/CAD/sphere_head_link1.stl" scale="0.001 0.001 0.001"/>
      </geometry>
    </collision>
    <visual name="sphere_head_link1_visual">
      <origin rpy="0  0  0" xyz="0  0  0"/>
      <geometry>
        <mesh filename="package://robots/roboy_xylophone/meshes/CAD/sphere_head_link1.stl" scale="0.001 0.001 0.001"/>
      </geometry>
    </visual>
  </link>
  <link name="shere_head_link2">
    <inertial>
      <mass value="0.016046417516495697"/>
      <origin rpy="0  0  0" xyz="0  0  0"/>
      <inertia ixx="0.008114981473636663" ixy="5.029234407399885e-19" ixz="-1.7364422082044644e-05" iyy="0.008114944313059423" iyz="2.348593541867672e-16" izz="9.214497104106424e-07"/>
    </inertial>
    <collision name="shere_head_link2_collision">
      <origin rpy="0  0  0" xyz="0  0  0"/>
      <geometry>
        <mesh filename="package://robots/roboy_xylophone/meshes/CAD/shere_head_link2.stl" scale="0.001 0.001 0.001"/>
      </geometry>
    </collision>
    <visual name="shere_head_link2_visual">
      <origin rpy="0  0  0" xyz="0  0  0"/>
      <geometry>
        <mesh filename="package://robots/roboy_xylophone/meshes/CAD/shere_head_link2.stl" scale="0.001 0.001 0.001"/>
      </geometry>
    </visual>
  </link>
  <link name="head">
    <inertial>
      <mass value="2.066438155287756"/>
      <origin rpy="0  0  0" xyz="0.00064  0.01352  0.15538"/>
      <inertia ixx="1.5846048067305112" ixy="-2.8828445995337716e-05" ixz="-0.02944270231917974" iyy="1.578896510489258" iyz="-0.0012884346701907063" izz="0.0255508320008188"/>
    </inertial>
    <collision name="head_collision">
      <origin rpy="0  0  0" xyz="0.00064  0.01352  0.15538"/>
      <geometry>
        <mesh filename="package://robots/roboy_xylophone/meshes/CAD/head.stl" scale="0.001 0.001 0.001"/>
      </geometry>
    </collision>
    <visual name="head_visual">
      <origin rpy="0  0  0" xyz="0.00064  0.01352  0.15538"/>
      <geometry>
        <mesh filename="package://robots/roboy_xylophone/meshes/CAD/head.stl" scale="0.001 0.001 0.001"/>
      </geometry>
    </visual>
  </link>
  <link name="base">
    <inertial>
      <mass value="0.8375538014504047"/>
      <origin rpy="0  0  0" xyz="0  0  0"/>
      <inertia ixx="0.004947439478836191" ixy="1.8900910193672462e-05" ixz="1.8376373411173705e-05" iyy="0.013020882991024406" iyz="7.086050217485074e-06" izz="0.012613089761592724"/>
    </inertial>
    <collision name="base_collision">
      <origin rpy="0  0  0" xyz="0  0  0"/>
      <geometry>
        <mesh filename="package://robots/roboy_xylophone/meshes/CAD/base.stl" scale="0.001 0.001 0.001"/>
      </geometry>
    </collision>
    <visual name="base_visual">
      <origin rpy="0  0  0" xyz="0  0  0"/>
      <geometry>
        <mesh filename="package://robots/roboy_xylophone/meshes/CAD/base.stl" scale="0.001 0.001 0.001"/>
      </geometry>
    </visual>
  </link>
  <link name="left_stick_tip">
    <inertial>
      <mass value="0.026023156971151314"/>
      <origin rpy="0  0  0" xyz="0      -0.00427 -0.00114"/>
      <inertia ixx="0.003055544257033057" ixy="0.0019320978532239472" ixz="-0.0014587537400506572" iyy="0.002962679652716562" iyz="0.001424079527170524" izz="0.003866281674384223"/>
    </inertial>
    <collision name="left_stick_tip_collision">
      <origin rpy="0  0  0" xyz="0      -0.00427 -0.00114"/>
      <geometry>
        <mesh filename="package://robots/roboy_xylophone/meshes/CAD/left_stick_tip.stl" scale="0.001 0.001 0.001"/>
      </geometry>
    </collision>
    <visual name="left_stick_tip_visual">
      <origin rpy="0  0  0" xyz="0      -0.00427 -0.00114"/>
      <geometry>
        <mesh filename="package://robots/roboy_xylophone/meshes/CAD/left_stick_tip.stl" scale="0.001 0.001 0.001"/>
      </geometry>
    </visual>
  </link>
  <link name="right_stick_tip">
    <inertial>
      <mass value="0.02602315697115411"/>
      <origin rpy="0  0  0" xyz="-3.00000000e-05  -4.37000000e-03  -1.16000000e-03"/>
      <inertia ixx="0.00305489268329945" ixy="-0.0019522723505767325" ixz="-0.001458818403558204" iyy="0.003004799357065121" iyz="-0.0014401715227325498" izz="0.0039058346651765483"/>
    </inertial>
    <collision name="right_stick_tip_collision">
      <origin rpy="0  0  0" xyz="-3.00000000e-05  -4.37000000e-03  -1.16000000e-03"/>
      <geometry>
        <mesh filename="package://robots/roboy_xylophone/meshes/CAD/right_stick_tip.stl" scale="0.001 0.001 0.001"/>
      </geometry>
    </collision>
    <visual name="right_stick_tip_visual">
      <origin rpy="0  0  0" xyz="-3.00000000e-05  -4.37000000e-03  -1.16000000e-03"/>
      <geometry>
        <mesh filename="package://robots/roboy_xylophone/meshes/CAD/right_stick_tip.stl" scale="0.001 0.001 0.001"/>
      </geometry>
    </visual>
  </link>
</robot>
