<robot name="msj_platform_head">
  <joint name="sphere_axis0" type="revolute">
    <parent link="base" />
    <child link="sphere_link1" />
    <origin rpy="0 0 0" xyz="0.00424 0.00424 0.1155" />
    <axis xyz="0.79015 -0.6129   0" />
    <limit effort="0.0" lower="-3.14159265359" upper="3.14159265359" velocity="0.0" />
  </joint>
  <joint name="sphere_axis1" type="revolute">
    <parent link="sphere_link1" />
    <child link="sphere_link2" />
    <origin rpy="0 0 0" xyz="0 0 0" />
    <axis xyz="0.6129  0.79015 0" />
    <limit effort="0.0" lower="-3.14159265359" upper="3.14159265359" velocity="0.0" />
  </joint>
  <joint name="sphere_axis2" type="revolute">
    <parent link="sphere_link2" />
    <child link="top" />
    <origin rpy="0 0 0" xyz="0 0 0" />
    <axis xyz="0 0 1" />
    <limit effort="0.0" lower="-3.14159265359" upper="3.14159265359" velocity="0.0" />
  </joint>
  <link name="base">
    <inertial>
      <mass value="14.48736963274618" />
      <origin rpy="0 0 0" xyz="9.000e-05 7.000e-05 2.911e-02" />
      <inertia ixx="0.18023729674326666" ixy="1.708904356017246e-07" ixz="-9.474145118069151e-05" iyy="0.18027389536315788" iyz="-8.974531140534303e-05" izz="0.28755005501113196" />
    </inertial>
    <collision name="base_collision">
      <origin rpy="0 0 0" xyz="9.000e-05 7.000e-05 2.911e-02" />
      <geometry>
        <mesh filename="package://robots/msj_platform_head/meshes/collisions/base.stl" scale="0.001 0.001 0.001" />
      </geometry>
    </collision>
    <visual name="base_visual">
      <origin rpy="0 0 0" xyz="9.000e-05 7.000e-05 2.911e-02" />
      <geometry>
        <mesh filename="package://robots/msj_platform_head/meshes/visuals/base.stl" scale="0.001 0.001 0.001" />
      </geometry>
    </visual>
  </link>
  <link name="top">
    <inertial>
      <mass value="1.1528106885784282" />
      <origin rpy="0 0 0" xyz="-0.00042  0.00027  0.06479" />
      <inertia ixx="0.038542401055929064" ixy="-2.351626500806073e-05" ixz="-0.000786477372240961" iyy="0.03853476710792224" iyz="-0.0009392855659467607" izz="0.001170791523029024" />
    </inertial>
    <collision name="top_collision">
      <origin rpy="0 0 0" xyz="-0.00042  0.00027  0.06479" />
      <geometry>
        <mesh filename="package://robots/msj_platform_head/meshes/collisions/top.stl" scale="0.001 0.001 0.001" />
      </geometry>
    </collision>
    <visual name="top_visual">
      <origin rpy="0 0 0" xyz="-0.00042  0.00027  0.06479" />
      <geometry>
        <mesh filename="package://robots/msj_platform_head/meshes/visuals/top.stl" scale="0.001 0.001 0.001" />
      </geometry>
    </visual>
  </link>
  <link name="sphere_link1">
    <inertial>
      <mass value="0.022028373175580263" />
      <origin rpy="0 0 0" xyz="0 0 0" />
      <inertia ixx="0.0002949351348937359" ixy="-3.965107173325048e-07" ixz="-1.07944535545109e-05" iyy="0.000294935134893882" iyz="-1.0794453552522944e-05" izz="1.467640363167159e-06" />
    </inertial>
    <collision name="sphere_link1_collision">
      <origin rpy="0 0 0" xyz="0 0 0" />
      <geometry>
        <mesh filename="package://robots/msj_platform_head/meshes/collisions/sphere_link1.stl" scale="0.001 0.001 0.001" />
      </geometry>
    </collision>
    <visual name="sphere_link1_visual">
      <origin rpy="0 0 0" xyz="0 0 0" />
      <geometry>
        <mesh filename="package://robots/msj_platform_head/meshes/visuals/sphere_link1.stl" scale="0.001 0.001 0.001" />
      </geometry>
    </visual>
  </link>
  <link name="sphere_link2">
    <inertial>
      <mass value="0.0017340118826259295" />
      <origin rpy="0 0 0" xyz="0 0 0" />
      <inertia ixx="2.3173118047323903e-05" ixy="-3.121221390100324e-08" ixz="-8.497091719340116e-07" iyy="2.3173118047335395e-05" iyz="-8.49709171777279e-07" izz="7.217824464186812e-08" />
    </inertial>
    <collision name="sphere_link2_collision">
      <origin rpy="0 0 0" xyz="0 0 0" />
      <geometry>
        <mesh filename="package://robots/msj_platform_head/meshes/collisions/sphere_link2.stl" scale="0.001 0.001 0.001" />
      </geometry>
    </collision>
    <visual name="sphere_link2_visual">
      <origin rpy="0 0 0" xyz="0 0 0" />
      <geometry>
        <mesh filename="package://robots/msj_platform_head/meshes/visuals/sphere_link2.stl" scale="0.001 0.001 0.001" />
      </geometry>
    </visual>
  </link>
</robot>