<robot name="msj_platform_head">
  <joint name="sphere_axis0" type="revolute">
    <parent link="base" />
    <child link="sphere_link1" />
    <origin rpy="0 0 0" xyz="0     0.006  0.1155" />
    <axis xyz="0.99211 0.12533 0" />
    <limit effort="0.0" lower="-3.14159265359" upper="3.14159265359" velocity="0.0" />
  </joint>
  <joint name="sphere_axis1" type="revolute">
    <parent link="sphere_link1" />
    <child link="sphere_link2" />
    <origin rpy="0 0 0" xyz="0 0 0" />
    <axis xyz="-0.12533  0.99211  0" />
    <limit effort="0.0" lower="-3.14159265359" upper="3.14159265359" velocity="0.0" />
  </joint>
  <joint name="sphere_axis2" type="revolute">
    <parent link="sphere_link2" />
    <child link="top" />
    <origin rpy="0 0 0" xyz="0 0 0" />
    <axis xyz="0 0 1" />
    <limit effort="0.0" lower="-3.14159265359" upper="3.14159265359" velocity="0.0" />
  </joint>
  <link name="base">
    <inertial>
      <mass value="14.488893321678509" />
      <origin rpy="0 0 0" xyz="1.000e-05 1.200e-04 2.911e-02" />
      <inertia ixx="0.18025975509095166" ixy="-1.83158947684374e-05" ixz="-3.5910554247763628e-06" iyy="0.18026005572374784" iyz="-0.00013086650671482176" izz="0.2875503759819749" />
    </inertial>
    <collision name="base_collision">
      <origin rpy="0 0 0" xyz="1.000e-05 1.200e-04 2.911e-02" />
      <geometry>
        <mesh filename="package://robots/msj_platform_head/meshes/collisions/base.stl" scale="0.001 0.001 0.001" />
      </geometry>
    </collision>
    <visual name="base_visual">
      <origin rpy="0 0 0" xyz="1.000e-05 1.200e-04 2.911e-02" />
      <geometry>
        <mesh filename="package://robots/msj_platform_head/meshes/visuals/base.stl" scale="0.001 0.001 0.001" />
      </geometry>
    </visual>
  </link>
  <link name="top">
    <inertial>
      <mass value="1.1948687198419368" />
      <origin rpy="0 0 0" xyz="0.00021 -0.00014  0.08392" />
      <inertia ixx="0.04933285145966646" ixy="-4.425753219042965e-06" ixz="-5.984794849927179e-05" iyy="0.04928858140994544" iyz="-0.00140614613944832" izz="0.001186553580431596" />
    </inertial>
    <collision name="top_collision">
      <origin rpy="0 0 0" xyz="0.00021 -0.00014  0.08392" />
      <geometry>
        <mesh filename="package://robots/msj_platform_head/meshes/collisions/top.stl" scale="0.001 0.001 0.001" />
      </geometry>
    </collision>
    <visual name="top_visual">
      <origin rpy="0 0 0" xyz="0.00021 -0.00014  0.08392" />
      <geometry>
        <mesh filename="package://robots/msj_platform_head/meshes/visuals/top.stl" scale="0.001 0.001 0.001" />
      </geometry>
    </visual>
  </link>
  <link name="sphere_link1">
    <inertial>
      <mass value="0.02202837149664189" />
      <origin rpy="0 0 0" xyz="0 0 0" />
      <inertia ixx="0.00029533162308761527" ixy="2.1945655720185392e-14" ixz="4.2245388090500495e-13" iyy="0.0002945386017574293" iyz="-1.5265661026424e-05" izz="1.4676402158221274e-06" />
    </inertial>
    <collision name="sphere_link1_collision">
      <origin rpy="0 0 0" xyz="0 0 0" />
      <geometry>
        <mesh filename="package://robots/msj_platform_head/meshes/collisions/sphere_link1.stl" scale="0.001 0.001 0.001" />
      </geometry>
    </collision>
    <visual name="sphere_link1_visual">
      <origin rpy="0 0 0" xyz="0 0 0" />
      <geometry>
        <mesh filename="package://robots/msj_platform_head/meshes/visuals/sphere_link1.stl" scale="0.001 0.001 0.001" />
      </geometry>
    </visual>
  </link>
  <link name="sphere_link2">
    <inertial>
      <mass value="0.001734011882625929" />
      <origin rpy="0 0 0" xyz="0 0 0" />
      <inertia ixx="2.320433026123045e-05" ixy="-5.932798079444054e-18" ixz="-1.1637901471510393e-16" iyy="2.3141905833428446e-05" iyz="-1.2016702349073352e-06" izz="7.217824464148089e-08" />
    </inertial>
    <collision name="sphere_link2_collision">
      <origin rpy="0 0 0" xyz="0 0 0" />
      <geometry>
        <mesh filename="package://robots/msj_platform_head/meshes/collisions/sphere_link2.stl" scale="0.001 0.001 0.001" />
      </geometry>
    </collision>
    <visual name="sphere_link2_visual">
      <origin rpy="0 0 0" xyz="0 0 0" />
      <geometry>
        <mesh filename="package://robots/msj_platform_head/meshes/visuals/sphere_link2.stl" scale="0.001 0.001 0.001" />
      </geometry>
    </visual>
  </link>
</robot>