<sdf version="1.6">
	<model name="msj_platform_head">
		<link name="base">
			<self_collide>false</self_collide>
			<pose frame="">-0.009722422261997021 0.00986687305771657 0.0551351522633794 0.0 -0.0 0.0</pose>
			<inertial>
				<pose frame="">0.0 0.0 0.0 0 0 0</pose>
				<mass>15.629842988436991</mass>
				<inertia>
					<ixx>0.37101179139154744</ixx>
					<ixy>0.020544761689086373</ixy>
					<ixz>0.058964832543668265</ixz>
					<iyy>0.37110336276629335</iyy>
					<iyz>-0.05906303191293011</iyz>
					<izz>0.32968638674351486</izz>
				</inertia>
			</inertial>
			<collision name="base_collision">
				<geometry>
					<mesh>
						<uri>model://msj_platform_head/meshes/collisions/base.stl</uri>
						<scale>0.001 0.001 0.001</scale>
					</mesh>
				</geometry>
			</collision>
			<visual name="base_visual">
				<geometry>
					<mesh>
						<uri>model://msj_platform_head/meshes/visuals/base.stl</uri>
						<scale>0.001 0.001 0.001</scale>
					</mesh>
				</geometry>
			</visual>
		</link>
		<link name="top">
			<self_collide>false</self_collide>
			<pose frame="">0.003902664851542784 0.004492463597073772 0.1754722146164014 0.0 -0.0 0.0</pose>
			<inertial>
				<pose frame="">0.0 0.0 0.0 0 0 0</pose>
				<mass>1.20591356597939</mass>
				<inertia>
					<ixx>0.03819643364705958</ixx>
					<ixy>-2.4663343568917342e-05</ixy>
					<ixz>-0.0008183781921683772</ixz>
					<iyy>0.0381888418670597</iyy>
					<iyz>-0.0009525221954992814</iyz>
					<izz>0.0011780867159781737</izz>
				</inertia>
			</inertial>
			<collision name="top_collision">
				<geometry>
					<mesh>
						<uri>model://msj_platform_head/meshes/collisions/top.stl</uri>
						<scale>0.001 0.001 0.001</scale>
					</mesh>
				</geometry>
			</collision>
			<visual name="top_visual">
				<geometry>
					<mesh>
						<uri>model://msj_platform_head/meshes/visuals/top.stl</uri>
						<scale>0.001 0.001 0.001</scale>
					</mesh>
				</geometry>
			</visual>
		</link>
		<link name="sphere_link1">
			<self_collide>false</self_collide>
			<pose frame="">0.004242640688430471 0.004242640687649124 0.11549999999851424 0.0 -0.0 0.0</pose>
			<inertial>
				<pose frame="">0.0 0.0 0.0 0 0 0</pose>
				<mass>0.022028373175580263</mass>
				<inertia>
					<ixx>0.0002949351348937359</ixx>
					<ixy>-3.9651071733250453e-07</ixy>
					<ixz>-1.07944535545109e-05</ixz>
					<iyy>0.000294935134893882</iyy>
					<iyz>-1.0794453552522937e-05</iyz>
					<izz>1.4676403631671595e-06</izz>
				</inertia>
			</inertial>
			<collision name="sphere_link1_collision">
				<geometry>
					<mesh>
						<uri>model://msj_platform_head/meshes/collisions/sphere_link1.stl</uri>
						<scale>0.001 0.001 0.001</scale>
					</mesh>
				</geometry>
			</collision>
			<visual name="sphere_link1_visual">
				<geometry>
					<mesh>
						<uri>model://msj_platform_head/meshes/visuals/sphere_link1.stl</uri>
						<scale>0.001 0.001 0.001</scale>
					</mesh>
				</geometry>
			</visual>
		</link>
		<link name="sphere_link2">
			<self_collide>false</self_collide>
			<pose frame="">0.004242640688453875 0.0042426406876713415 0.11549999999847281 0.0 -0.0 0.0</pose>
			<inertial>
				<pose frame="">0.0 0.0 0.0 0 0 0</pose>
				<mass>0.0017340118826259295</mass>
				<inertia>
					<ixx>2.3173118047323906e-05</ixx>
					<ixy>-3.1212213901003247e-08</ixy>
					<ixz>-8.497091719340116e-07</ixz>
					<iyy>2.31731180473354e-05</iyy>
					<iyz>-8.497091717772792e-07</iyz>
					<izz>7.217824464186813e-08</izz>
				</inertia>
			</inertial>
			<collision name="sphere_link2_collision">
				<geometry>
					<mesh>
						<uri>model://msj_platform_head/meshes/collisions/sphere_link2.stl</uri>
						<scale>0.001 0.001 0.001</scale>
					</mesh>
				</geometry>
			</collision>
			<visual name="sphere_link2_visual">
				<geometry>
					<mesh>
						<uri>model://msj_platform_head/meshes/visuals/sphere_link2.stl</uri>
						<scale>0.001 0.001 0.001</scale>
					</mesh>
				</geometry>
			</visual>
		</link>
		<joint name="sphere_axis0" type="revolute">
			<parent>base</parent>
			<child>sphere_link1</child>
			<pose frame="">1.2199685706093533e-14 -9.303668946358811e-15 -4.142464149481384e-14 0 0 0</pose>
			<axis>
				<xyz>0.7901550123756897 -0.6129070536529773 -2.634760832362838e-12</xyz>
				<limit>
					<lower>-3.141592653589793</lower>
					<upper>3.141592653589793</upper>
				</limit>
				<use_parent_model_frame>0</use_parent_model_frame>
			</axis>
		</joint>
		<joint name="sphere_axis1" type="revolute">
			<parent>sphere_link1</parent>
			<child>sphere_link2</child>
			<pose frame="">-2.3314683517128287e-14 -2.2127299992291683e-14 0.0 0 0 0</pose>
			<axis>
				<xyz>0.6129070536529773 0.7901550123756897 -2.0217668703762803e-11</xyz>
				<limit>
					<lower>-3.141592653589793</lower>
					<upper>3.141592653589793</upper>
				</limit>
				<use_parent_model_frame>0</use_parent_model_frame>
			</axis>
		</joint>
		<joint name="sphere_axis2" type="revolute">
			<parent>sphere_link2</parent>
			<child>top</child>
			<pose frame="">0.00033997583688777643 -0.00024982290942455744 -0.05997221461792858 0 0 0</pose>
			<axis>
				<xyz>1.4409679196985146e-11 1.4409672158911102e-11 1.0</xyz>
				<limit>
					<lower>-3.141592653589793</lower>
					<upper>3.141592653589793</upper>
				</limit>
				<use_parent_model_frame>0</use_parent_model_frame>
			</axis>
		</joint>
		<plugin filename="libcardsflow_gazebo_plugin.so" name="cardsflow_gazebo_plugin" />
	</model>
</sdf>