<?xml version="1.0" ?>
<sdf version="1.6">
	<model name="msj_platform">
		<link name="top">
			<self_collide>true</self_collide>
			<pose frame="">0.007571428571428571 -0.006 0.1615714285714286 0.0 -0.0 0.0</pose>
			<inertial>
				<pose frame="">0.0 0.0 0.0 0 0 0</pose>
				<mass>0.046344510214942534</mass>
				<inertia>
					<ixx>0.0009124106535391846</ixx>
					<ixy>1.5564939397719483e-06</ixy>
					<ixz>2.8398605159216807e-05</ixz>
					<iyy>0.0009141553298271258</iyy>
					<iyz>-4.853967208793866e-05</iyz>
					<izz>1.769936787542794e-05</izz>
				</inertia>
			</inertial>
			<collision name="top_collision">
				<geometry>
					<mesh>
						<uri>model://msj_platform/meshes/CAD/top.stl</uri>
						<scale>0.001 0.001 0.001</scale>
					</mesh>
				</geometry>
			</collision>
			<visual name="top_visual">
				<geometry>
					<mesh>
						<uri>model://msj_platform/meshes/CAD/top.stl</uri>
						<scale>0.001 0.001 0.001</scale>
					</mesh>
				</geometry>
			</visual>
		</link>
		<link name="base">
			<self_collide>true</self_collide>
			<kinematic>true</kinematic>
			<pose frame="">0.0 0.0 0.0 0.0 -0.0 0.0</pose>
			<inertial>
				<pose frame="">0.0 0.0 0.0 0 0 0</pose>
				<mass>4.349060626991739</mass>
				<inertia>
					<ixx>0.05688819427126439</ixx>
					<ixy>-8.480336115266774e-06</ixy>
					<ixz>0.00015679296593942954</ixz>
					<iyy>0.05688150299610186</iyy>
					<iyz>-6.039738279929029e-05</iyz>
					<izz>0.05703669386104075</izz>
				</inertia>
			</inertial>
			<collision name="base_collision">
				<geometry>
					<mesh>
						<uri>model://msj_platform/meshes/CAD/base.stl</uri>
						<scale>0.001 0.001 0.001</scale>
					</mesh>
				</geometry>
			</collision>
			<visual name="base_visual">
				<geometry>
					<mesh>
						<uri>model://msj_platform/meshes/CAD/base.stl</uri>
						<scale>0.001 0.001 0.001</scale>
					</mesh>
				</geometry>
			</visual>
		</link>
		<link name="tlv_1">
			<self_collide>false</self_collide>
			<pose frame="">0.018087101486926254 -0.007308597178967146 0.08493915848607692 0.0 -0.0 0.0</pose>
			<inertial>
				<pose frame="">0.0 0.0 0.0 0 0 0</pose>
				<mass>3.1292573869887955e-05</mass>
				<inertia>
					<ixx>2.2749992911955388e-07</ixx>
					<ixy>4.133627993295111e-09</ixy>
					<ixz>1.9427791666491183e-08</ixz>
					<iyy>2.3607099250794133e-07</iyy>
					<iyz>-4.80924610457384e-08</iyz>
					<izz>1.1934955243298671e-08</izz>
				</inertia>
			</inertial>
			<collision name="tlv_1_collision">
				<geometry>
					<mesh>
						<uri>model://msj_platform/meshes/CAD/tlv_1.stl</uri>
						<scale>0.001 0.001 0.001</scale>
					</mesh>
				</geometry>
			</collision>
			<visual name="tlv_1_visual">
				<geometry>
					<mesh>
						<uri>model://msj_platform/meshes/CAD/tlv_1.stl</uri>
						<scale>0.001 0.001 0.001</scale>
					</mesh>
				</geometry>
			</visual>
		</link>
		<link name="tlv_2">
			<self_collide>false</self_collide>
			<pose frame="">-0.001878879286683719 -0.022543335744795362 0.09224600747982091 0.0 -0.0 0.0</pose>
			<inertial>
				<pose frame="">0.0 0.0 0.0 0 0 0</pose>
				<mass>3.129257386988798e-05</mass>
				<inertia>
					<ixx>2.822583258786262e-07</ixx>
					<ixy>-1.3192741101177688e-09</ixy>
					<ixz>6.509354989436371e-08</ixz>
					<iyy>2.6646496939158655e-07</iyy>
					<iyz>5.421998802117643e-09</iyz>
					<izz>1.6036894497439735e-08</izz>
				</inertia>
			</inertial>
			<collision name="tlv_2_collision">
				<geometry>
					<mesh>
						<uri>model://msj_platform/meshes/CAD/tlv_2.stl</uri>
						<scale>0.001 0.001 0.001</scale>
					</mesh>
				</geometry>
			</collision>
			<visual name="tlv_2_visual">
				<geometry>
					<mesh>
						<uri>model://msj_platform/meshes/CAD/tlv_2.stl</uri>
						<scale>0.001 0.001 0.001</scale>
					</mesh>
				</geometry>
			</visual>
		</link>
		<link name="tlv_0">
			<self_collide>false</self_collide>
			<pose frame="">-0.007780735498961288 -0.0038096554005765384 0.08727872187436782 0.0 -0.0 0.0</pose>
			<inertial>
				<pose frame="">0.0 0.0 0.0 0 0 0</pose>
				<mass>3.1292573869887995e-05</mass>
				<inertia>
					<ixx>2.3890164127606934e-07</ixx>
					<ixy>-9.292669243402631e-10</ixy>
					<ixz>1.0404886293081997e-08</ixz>
					<iyy>2.403270346380996e-07</iyy>
					<iyz>2.125789854846454e-08</iyz>
					<izz>2.374795271079367e-09</izz>
				</inertia>
			</inertial>
			<collision name="tlv_0_collision">
				<geometry>
					<mesh>
						<uri>model://msj_platform/meshes/CAD/tlv_0.stl</uri>
						<scale>0.001 0.001 0.001</scale>
					</mesh>
				</geometry>
			</collision>
			<visual name="tlv_0_visual">
				<geometry>
					<mesh>
						<uri>model://msj_platform/meshes/CAD/tlv_0.stl</uri>
						<scale>0.001 0.001 0.001</scale>
					</mesh>
				</geometry>
			</visual>
		</link>
		<link name="sphere_link1">
			<self_collide>true</self_collide>
			<pose frame="">0.007571428571428578 -0.004500000000000007 0.10500000000000043 0.0 -0.0 0.0</pose>
			<inertial>
				<pose frame="">0.0 0.0 0.0 0 0 0</pose>
				<mass>0.06979038134801682</mass>
				<inertia>
					<ixx>0.0007824994872568728</ixx>
					<ixy>2.3778579930717192e-06</ixy>
					<ixz>3.297595518693813e-05</ixz>
					<iyy>0.0007850870724673629</iyy>
					<iyz>-5.5483353171673625e-05</iyz>
					<izz>1.706137332776843e-05</izz>
				</inertia>
			</inertial>
			<collision name="sphere_link1_collision">
				<geometry>
					<mesh>
						<uri>model://msj_platform/meshes/CAD/sphere_link1.stl</uri>
						<scale>0.001 0.001 0.001</scale>
					</mesh>
				</geometry>
			</collision>
			<visual name="sphere_link1_visual">
				<geometry>
					<mesh>
						<uri>model://msj_platform/meshes/CAD/sphere_link1.stl</uri>
						<scale>0.001 0.001 0.001</scale>
					</mesh>
				</geometry>
			</visual>
		</link>
		<link name="sphere_link2">
			<self_collide>true</self_collide>
			<pose frame="">0.00757142857142861 -0.0045000000624834495 0.10499999990919114 0.0 -0.0 0.0</pose>
			<inertial>
				<pose frame="">0.0 0.0 0.0 0 0 0</pose>
				<mass>0.04678255760927329</mass>
				<inertia>
					<ixx>0.0005219864769988443</ixx>
					<ixy>1.593948592105417e-06</ixy>
					<ixz>2.2104758795776802e-05</ixz>
					<iyy>0.0005237210119708344</iyy>
					<iyz>-3.719213326720699e-05</iyz>
					<izz>8.890661998540551e-06</izz>
				</inertia>
			</inertial>
			<collision name="sphere_link2_collision">
				<geometry>
					<mesh>
						<uri>model://msj_platform/meshes/CAD/sphere_link2.stl</uri>
						<scale>0.001 0.001 0.001</scale>
					</mesh>
				</geometry>
			</collision>
			<visual name="sphere_link2_visual">
				<geometry>
					<mesh>
						<uri>model://msj_platform/meshes/CAD/sphere_link2.stl</uri>
						<scale>0.001 0.001 0.001</scale>
					</mesh>
				</geometry>
			</visual>
		</link>
		<joint name="sphere_axis0" type="revolute">
			<parent>base</parent>
			<child>sphere_link1</child>
			<pose frame="">-2.220446049250313e-18 -7.771561172376097e-18 -5.329070518200751e-17 0 0 0</pose>
			<axis>
				<xyz>0.9999999999999998 0.0 0.0</xyz>
				<limit>
					<lower>-3.141592653589793</lower>
					<upper>3.141592653589793</upper>
				</limit>
				<use_parent_model_frame>0</use_parent_model_frame>
			</axis>
		</joint>
		<joint name="sphere_axis2" type="revolute">
			<parent>sphere_link2</parent>
			<child>top</child>
			<pose frame="">0.0 0.0014999999999999857 -0.05657142857142821 0 0 0</pose>
			<axis>
				<xyz>0.0 -1.387778780781446e-17 0.9999999999999998</xyz>
				<limit>
					<lower>-3.141592653589793</lower>
					<upper>3.141592653589793</upper>
				</limit>
				<use_parent_model_frame>0</use_parent_model_frame>
			</axis>
		</joint>
		<joint name="sphere_axis1" type="revolute">
			<parent>sphere_link1</parent>
			<child>sphere_link2</child>
			<pose frame="">-3.441691376337985e-17 6.248343509263066e-11 9.080929785909576e-11 0 0 0</pose>
			<axis>
				<xyz>0.0 -1.0 -1.3877787807814463e-17</xyz>
				<limit>
					<lower>-3.141592653589793</lower>
					<upper>3.141592653589793</upper>
				</limit>
				<use_parent_model_frame>0</use_parent_model_frame>
			</axis>
		</joint>
		<joint name="tlv_sensor_2" type="revolute">
			<parent>base</parent>
			<child>tlv_2</child>
			<pose frame="">-0.00037814752563089 -0.00021737785862032235 -0.0003735723606328634 0 0 0</pose>
		</joint>
		<joint name="tlv_sensor_1" type="revolute">
			<parent>base</parent>
			<child>tlv_1</child>
			<pose frame="">5.299256044452916e-05 -0.0001393603702689261 -0.0005488750296033018 0 0 0</pose>
		</joint>
		<joint name="tlv_sensor_0" type="revolute">
			<parent>base</parent>
			<child>tlv_0</child>
			<pose frame="">-0.0003737561913427301 -0.00023097892352251737 -0.0003700683787619852 0 0 0</pose>
		</joint>
		<!--<plugin filename="libmusc_plugin.so" name="musc_plugin">-->
			<!--<myoMuscle name="motor0">-->
				<!--<link name="base">-->
					<!--<viaPoint type="FIXPOINT">-0.014092248151036385 -0.10899999990083967 0.14710003484599582</viaPoint>-->
				<!--</link>-->
				<!--<link name="top">-->
					<!--<viaPoint type="FIXPOINT">-0.0008137377009677926 -0.036575094380420656 -0.001999999999999993</viaPoint>-->
				<!--</link>-->
			<!--</myoMuscle>-->
			<!--<myoMuscle name="motor1">-->
				<!--<link name="base">-->
					<!--<viaPoint type="FIXPOINT">-0.10899999990083986 -0.01410775184896366 0.14609999999254936</viaPoint>-->
				<!--</link>-->
				<!--<link name="top">-->
					<!--<viaPoint type="FIXPOINT">-0.0008137377009677926 -0.036575094380420656 -0.001999999999999993</viaPoint>-->
				<!--</link>-->
			<!--</myoMuscle>-->
			<!--<myoMuscle name="motor2">-->
				<!--<link name="base">-->
					<!--<viaPoint type="FIXPOINT">-0.10899999990083979 0.014107751848963773 0.05710003484599585</viaPoint>-->
				<!--</link>-->
				<!--<link name="top">-->
					<!--<viaPoint type="FIXPOINT">0.0008137377009677994 0.039775094380420636 -0.005</viaPoint>-->
				<!--</link>-->
			<!--</myoMuscle>-->
			<!--<myoMuscle name="motor3">-->
				<!--<link name="base">-->
					<!--<viaPoint type="FIXPOINT">-0.014092248151036296 0.10899999990083979 0.0570999999925494</viaPoint>-->
				<!--</link>-->
				<!--<link name="top">-->
					<!--<viaPoint type="FIXPOINT">0.0008137377009677994 0.039775094380420636 -0.005</viaPoint>-->
				<!--</link>-->
			<!--</myoMuscle>-->
			<!--<myoMuscle name="motor4">-->
				<!--<link name="base">-->
					<!--<viaPoint type="FIXPOINT">0.014107751848963752 0.10899999990083976 0.23110003484599573</viaPoint>-->
				<!--</link>-->
				<!--<link name="top">-->
					<!--<viaPoint type="FIXPOINT">-0.03817509438042065 0.0024137377009677973 -0.001999999999999993</viaPoint>-->
				<!--</link>-->
			<!--</myoMuscle>-->
			<!--<myoMuscle name="motor5">-->
				<!--<link name="base">-->
					<!--<viaPoint type="FIXPOINT">0.10899999989668285 0.014107716991127268 0.05735570917661107</viaPoint>-->
				<!--</link>-->
				<!--<link name="top">-->
					<!--<viaPoint type="FIXPOINT">0.03817509438042066 0.0007862622990321922 -0.005</viaPoint>-->
				<!--</link>-->
			<!--</myoMuscle>-->
			<!--<myoMuscle name="motor6">-->
				<!--<link name="base">-->
					<!--<viaPoint type="FIXPOINT">0.10899999989668285 -0.014107716991127246 0.1413557440300574</viaPoint>-->
				<!--</link>-->
				<!--<link name="top">-->
					<!--<viaPoint type="FIXPOINT">0.0008137377009677994 0.039775094380420636 -0.005</viaPoint>-->
				<!--</link>-->
			<!--</myoMuscle>-->
			<!--<myoMuscle name="motor7">-->
				<!--<link name="base">-->
					<!--<viaPoint type="FIXPOINT">0.014107716991127062 -0.10899999989668292 0.14635570917661103</viaPoint>-->
				<!--</link>-->
				<!--<link name="top">-->
					<!--<viaPoint type="FIXPOINT">0.03817509438042066 0.0007862622990321922 -0.001999999999999993</viaPoint>-->
				<!--</link>-->
			<!--</myoMuscle>-->
		<!--</plugin>-->
	</model>
</sdf>
