<?xml version="1.0" ?>
<robot name="msj_platform">
  <joint name="tlv_sensor_1" type="revolute">
    <parent link="base"/>
    <child link="tlv_1"/>
    <origin rpy="0 0 0" xyz="0.01814 -0.00744  0.08439"/>
    <axis xyz="0 0 0"/>
    <limit effort="0" lower="0" upper="0" velocity="0"/>
  </joint>
  <joint name="tlv_sensor_2" type="revolute">
    <parent link="base"/>
    <child link="tlv_2"/>
    <origin rpy="0 0 0" xyz="-0.00225 -0.02276  0.09187"/>
    <axis xyz="0 0 0"/>
    <limit effort="0" lower="0" upper="0" velocity="0"/>
  </joint>
  <joint name="sphere_axis0" type="revolute">
    <parent link="base"/>
    <child link="sphere_link1"/>
    <origin rpy="0 0 0" xyz="0.00757 -0.00449  0.105"/>
    <axis xyz="1 0 0"/>
    <limit effort="0.0" lower="-3.14159265359" upper="3.14159265359" velocity="0.0"/>
  </joint>
  <joint name="sphere_axis2" type="revolute">
    <parent link="sphere_link2"/>
    <child link="top"/>
    <origin rpy="0 0 0" xyz="0 0 0"/>
    <axis xyz="0 0 1"/>
    <limit effort="0.0" lower="-3.14159265359" upper="3.14159265359" velocity="0.0"/>
  </joint>
  <joint name="sphere_axis1" type="revolute">
    <parent link="sphere_link1"/>
    <child link="sphere_link2"/>
    <origin rpy="0 0 0" xyz="0 0 0"/>
    <axis xyz="0 -1  0"/>
    <limit effort="0.0" lower="-3.14159265359" upper="3.14159265359" velocity="0.0"/>
  </joint>
  <joint name="tlv_sensor_0" type="revolute">
    <parent link="base"/>
    <child link="tlv_0"/>
    <origin rpy="0 0 0" xyz="-0.00815 -0.00404  0.0869"/>
    <axis xyz="0 0 0"/>
    <limit effort="0" lower="0" upper="0" velocity="0"/>
  </joint>
  <link name="top">
    <inertial>
      <mass value="0.046344510214942534"/>
      <origin rpy="0 0 0" xyz="0      -0.0015   0.05657"/>
      <inertia ixx="0.0009124106535391846" ixy="1.5564939397719483e-06" ixz="2.8398605159216807e-05" iyy="0.0009141553298271258" iyz="-4.853967208793866e-05" izz="1.769936787542794e-05"/>
    </inertial>
    <collision name="top_collision">
      <origin rpy="0 0 0" xyz="0      -0.0015   0.05657"/>
      <geometry>
        <mesh filename="package://robots/msj_platform/meshes/CAD/top.stl" scale="0.001 0.001 0.001"/>
      </geometry>
    </collision>
    <visual name="top_visual">
      <origin rpy="0 0 0" xyz="0      -0.0015   0.05657"/>
      <geometry>
        <mesh filename="package://robots/msj_platform/meshes/CAD/top.stl" scale="0.001 0.001 0.001"/>
      </geometry>
    </visual>
  </link>
  <link name="base">
    <inertial>
      <mass value="4.349060626991739"/>
      <origin rpy="0 0 0" xyz="0 0 0"/>
      <inertia ixx="0.05682038569331961" ixy="-8.480336115268207e-06" ixz="0.00016839935321024028" iyy="0.05681369441815707" iyz="-5.932486536184817e-05" izz="0.05703669386104073"/>
    </inertial>
    <collision name="base_collision">
      <origin rpy="0 0 0" xyz="0 0 0"/>
      <geometry>
        <mesh filename="package://robots/msj_platform/meshes/CAD/base.stl" scale="0.001 0.001 0.001"/>
      </geometry>
    </collision>
    <visual name="base_visual">
      <origin rpy="0 0 0" xyz="0 0 0"/>
      <geometry>
        <mesh filename="package://robots/msj_platform/meshes/CAD/base.stl" scale="0.001 0.001 0.001"/>
      </geometry>
    </visual>
  </link>
  <link name="tlv_1">
    <inertial>
      <mass value="3.1292573869887955e-05"/>
      <origin rpy="0 0 0" xyz="-5.0e-05  1.3e-04  5.4e-04"/>
      <inertia ixx="2.2749992911955388e-07" ixy="4.133627993295111e-09" ixz="1.9427791666491183e-08" iyy="2.3607099250794133e-07" iyz="-4.80924610457384e-08" izz="1.1934955243298671e-08"/>
    </inertial>
    <collision name="tlv_1_collision">
      <origin rpy="0 0 0" xyz="-5.0e-05  1.3e-04  5.4e-04"/>
      <geometry>
        <mesh filename="package://robots/msj_platform/meshes/CAD/tlv_1.stl" scale="0.001 0.001 0.001"/>
      </geometry>
    </collision>
    <visual name="tlv_1_visual">
      <origin rpy="0 0 0" xyz="-5.0e-05  1.3e-04  5.4e-04"/>
      <geometry>
        <mesh filename="package://robots/msj_platform/meshes/CAD/tlv_1.stl" scale="0.001 0.001 0.001"/>
      </geometry>
    </visual>
  </link>
  <link name="tlv_2">
    <inertial>
      <mass value="3.129257386988798e-05"/>
      <origin rpy="0 0 0" xyz="0.00037 0.00021 0.00037"/>
      <inertia ixx="2.822583258786262e-07" ixy="-1.3192741101177688e-09" ixz="6.509354989436371e-08" iyy="2.6646496939158655e-07" iyz="5.421998802117643e-09" izz="1.6036894497439735e-08"/>
    </inertial>
    <collision name="tlv_2_collision">
      <origin rpy="0 0 0" xyz="0.00037 0.00021 0.00037"/>
      <geometry>
        <mesh filename="package://robots/msj_platform/meshes/CAD/tlv_2.stl" scale="0.001 0.001 0.001"/>
      </geometry>
    </collision>
    <visual name="tlv_2_visual">
      <origin rpy="0 0 0" xyz="0.00037 0.00021 0.00037"/>
      <geometry>
        <mesh filename="package://robots/msj_platform/meshes/CAD/tlv_2.stl" scale="0.001 0.001 0.001"/>
      </geometry>
    </visual>
  </link>
  <link name="tlv_0">
    <inertial>
      <mass value="3.1292573869887995e-05"/>
      <origin rpy="0 0 0" xyz="0.00037 0.00023 0.00037"/>
      <inertia ixx="2.3890164127606934e-07" ixy="-9.292669243402631e-10" ixz="1.0404886293081997e-08" iyy="2.403270346380996e-07" iyz="2.125789854846454e-08" izz="2.374795271079367e-09"/>
    </inertial>
    <collision name="tlv_0_collision">
      <origin rpy="0 0 0" xyz="0.00037 0.00023 0.00037"/>
      <geometry>
        <mesh filename="package://robots/msj_platform/meshes/CAD/tlv_0.stl" scale="0.001 0.001 0.001"/>
      </geometry>
    </collision>
    <visual name="tlv_0_visual">
      <origin rpy="0 0 0" xyz="0.00037 0.00023 0.00037"/>
      <geometry>
        <mesh filename="package://robots/msj_platform/meshes/CAD/tlv_0.stl" scale="0.001 0.001 0.001"/>
      </geometry>
    </visual>
  </link>
  <link name="sphere_link1">
    <inertial>
      <mass value="0.06979038134801682"/>
      <origin rpy="0 0 0" xyz="0 0 0"/>
      <inertia ixx="0.0007824994872568728" ixy="2.3778579930717192e-06" ixz="3.297595518693813e-05" iyy="0.0007850870724673629" iyz="-5.5483353171673625e-05" izz="1.706137332776843e-05"/>
    </inertial>
    <collision name="sphere_link1_collision">
      <origin rpy="0 0 0" xyz="0 0 0"/>
      <geometry>
        <mesh filename="package://robots/msj_platform/meshes/CAD/sphere_link1.stl" scale="0.001 0.001 0.001"/>
      </geometry>
    </collision>
    <visual name="sphere_link1_visual">
      <origin rpy="0 0 0" xyz="0 0 0"/>
      <geometry>
        <mesh filename="package://robots/msj_platform/meshes/CAD/sphere_link1.stl" scale="0.001 0.001 0.001"/>
      </geometry>
    </visual>
  </link>
  <link name="sphere_link2">
    <inertial>
      <mass value="0.04678255760927329"/>
      <origin rpy="0 0 0" xyz="0 0 0"/>
      <inertia ixx="0.0005219864769988443" ixy="1.593948592105417e-06" ixz="2.2104758795776802e-05" iyy="0.0005237210119708344" iyz="-3.719213326720699e-05" izz="8.890661998540551e-06"/>
    </inertial>
    <collision name="sphere_link2_collision">
      <origin rpy="0 0 0" xyz="0 0 0"/>
      <geometry>
        <mesh filename="package://robots/msj_platform/meshes/CAD/sphere_link2.stl" scale="0.001 0.001 0.001"/>
      </geometry>
    </collision>
    <visual name="sphere_link2_visual">
      <origin rpy="0 0 0" xyz="0 0 0"/>
      <geometry>
        <mesh filename="package://robots/msj_platform/meshes/CAD/sphere_link2.stl" scale="0.001 0.001 0.001"/>
      </geometry>
    </visual>
  </link>
</robot>
