<?xml version="1.0" ?>
<sdf version="1.6">
	<model name="msj_platform">
		<link name="top">
			<self_collide>false</self_collide>
			<pose frame="">0.007571428571428571 -0.006 0.1615714285714286 0.0 -0.0 0.0</pose>
			<inertial>
				<pose frame="">0.0 0.0 0.0 0 0 0</pose>
				<mass>0.23742047095738525</mass>
				<inertia>
					<ixx>0.005348764726767645</ixx>
					<ixy>7.90954829828298e-06</ixy>
					<ixz>0.00015532022596724323</ixz>
					<iyy>0.00535777860993333</iyy>
					<iyz>-0.00026727130384107244</iyz>
					<izz>0.00012112228123112415</izz>
				</inertia>
			</inertial>
			<collision name="top_collision">
				<geometry>
					<mesh>
						<uri>model://msj_platform/meshes/CAD/top.stl</uri>
						<scale>0.001 0.001 0.001</scale>
					</mesh>
				</geometry>
			</collision>
			<visual name="top_visual">
				<geometry>
					<mesh>
						<uri>model://msj_platform/meshes/CAD/top.stl</uri>
						<scale>0.001 0.001 0.001</scale>
					</mesh>
				</geometry>
			</visual>
		</link>
		<link name="base">
			<self_collide>false</self_collide>
			<pose frame="">0.0 0.0 0.0 0.0 -0.0 0.0</pose>
			<inertial>
				<pose frame="">0.0 0.0 0.0 0 0 0</pose>
				<mass>4.79165268238437</mass>
				<inertia>
					<ixx>0.059715457299525224</ixx>
					<ixy>-0.00012306055034292355</ixy>
					<ixz>0.00035583462750129666</ixz>
					<iyy>0.05970371843637196</iyy>
					<iyz>0.0001332547369782908</iyz>
					<izz>0.06052389979046516</izz>
				</inertia>
			</inertial>
			<collision name="base_collision">
				<geometry>
					<mesh>
						<uri>model://msj_platform/meshes/CAD/base.stl</uri>
						<scale>0.001 0.001 0.001</scale>
					</mesh>
				</geometry>
			</collision>
			<visual name="base_visual">
				<geometry>
					<mesh>
						<uri>model://msj_platform/meshes/CAD/base.stl</uri>
						<scale>0.001 0.001 0.001</scale>
					</mesh>
				</geometry>
			</visual>
		</link>
		<link name="sphere_link1">
			<self_collide>false</self_collide>
			<pose frame="">0.007571428571428573 -0.0044 0.106 0.0 -0.0 0.0</pose>
			<inertial>
				<pose frame="">0.0 0.0 0.0 0 0 0</pose>
				<mass>0.06979038134801681</mass>
				<inertia>
					<ixx>0.0007971631442818987</ixx>
					<ixy>2.3250167043367996e-06</ixy>
					<ixz>3.255023386071506e-05</ixz>
					<iyy>0.0007998128429317884</iyy>
					<iyz>-5.601176605902272e-05</iyz>
					<izz>1.69992598883687e-05</izz>
				</inertia>
			</inertial>
			<collision name="sphere_link1_collision">
				<geometry>
					<mesh>
						<uri>model://msj_platform/meshes/CAD/sphere_link1.stl</uri>
						<scale>0.001 0.001 0.001</scale>
					</mesh>
				</geometry>
			</collision>
			<visual name="sphere_link1_visual">
				<geometry>
					<mesh>
						<uri>model://msj_platform/meshes/CAD/sphere_link1.stl</uri>
						<scale>0.001 0.001 0.001</scale>
					</mesh>
				</geometry>
			</visual>
		</link>
		<link name="sphere_link2">
			<self_collide>false</self_collide>
			<pose frame="">0.007571428571428629 -0.004400000062483439 0.10599999990919072 0.0 -0.0 0.0</pose>
			<inertial>
				<pose frame="">0.0 0.0 0.0 0 0 0</pose>
				<mass>0.04678255760927329</mass>
				<inertia>
					<ixx>0.0005318159601690438</ixx>
					<ixy>1.5585275127726798e-06</ixy>
					<ixz>2.181938519770807e-05</ixz>
					<iyy>0.0005335921316178907</iyy>
					<iyz>-3.7546344060534264e-05</iyz>
					<izz>8.849025521683672e-06</izz>
				</inertia>
			</inertial>
			<collision name="sphere_link2_collision">
				<geometry>
					<mesh>
						<uri>model://msj_platform/meshes/CAD/sphere_link2.stl</uri>
						<scale>0.001 0.001 0.001</scale>
					</mesh>
				</geometry>
			</collision>
			<visual name="sphere_link2_visual">
				<geometry>
					<mesh>
						<uri>model://msj_platform/meshes/CAD/sphere_link2.stl</uri>
						<scale>0.001 0.001 0.001</scale>
					</mesh>
				</geometry>
			</visual>
		</link>
		<link name="tlv_1">
			<self_collide>false</self_collide>
			<pose frame="">0.018087101486926254 -0.007308597178967146 0.08493915848607692 0.0 -0.0 0.0</pose>
			<inertial>
				<pose frame="">0.0 0.0 0.0 0 0 0</pose>
				<mass>3.1292573869887955e-05</mass>
				<inertia>
					<ixx>2.2749992911955388e-07</ixx>
					<ixy>4.133627993295111e-09</ixy>
					<ixz>1.9427791666491183e-08</ixz>
					<iyy>2.3607099250794133e-07</iyy>
					<iyz>-4.80924610457384e-08</iyz>
					<izz>1.1934955243298671e-08</izz>
				</inertia>
			</inertial>
			<collision name="tlv_1_collision">
				<geometry>
					<mesh>
						<uri>model://msj_platform/meshes/CAD/tlv_1.stl</uri>
						<scale>0.001 0.001 0.001</scale>
					</mesh>
				</geometry>
			</collision>
			<visual name="tlv_1_visual">
				<geometry>
					<mesh>
						<uri>model://msj_platform/meshes/CAD/tlv_1.stl</uri>
						<scale>0.001 0.001 0.001</scale>
					</mesh>
				</geometry>
			</visual>
		</link>
		<link name="tlv_2">
			<self_collide>false</self_collide>
			<pose frame="">-0.001878879286683719 -0.022543335744795362 0.09224600747982091 0.0 -0.0 0.0</pose>
			<inertial>
				<pose frame="">0.0 0.0 0.0 0 0 0</pose>
				<mass>3.129257386988798e-05</mass>
				<inertia>
					<ixx>2.822583258786262e-07</ixx>
					<ixy>-1.3192741101177688e-09</ixy>
					<ixz>6.509354989436371e-08</ixz>
					<iyy>2.6646496939158655e-07</iyy>
					<iyz>5.421998802117643e-09</iyz>
					<izz>1.6036894497439735e-08</izz>
				</inertia>
			</inertial>
			<collision name="tlv_2_collision">
				<geometry>
					<mesh>
						<uri>model://msj_platform/meshes/CAD/tlv_2.stl</uri>
						<scale>0.001 0.001 0.001</scale>
					</mesh>
				</geometry>
			</collision>
			<visual name="tlv_2_visual">
				<geometry>
					<mesh>
						<uri>model://msj_platform/meshes/CAD/tlv_2.stl</uri>
						<scale>0.001 0.001 0.001</scale>
					</mesh>
				</geometry>
			</visual>
		</link>
		<link name="tlv_0">
			<self_collide>false</self_collide>
			<pose frame="">-0.007780735498961288 -0.0038096554005765384 0.08727872187436782 0.0 -0.0 0.0</pose>
			<inertial>
				<pose frame="">0.0 0.0 0.0 0 0 0</pose>
				<mass>3.1292573869887995e-05</mass>
				<inertia>
					<ixx>2.3890164127606934e-07</ixx>
					<ixy>-9.292669243402631e-10</ixy>
					<ixz>1.0404886293081997e-08</ixz>
					<iyy>2.403270346380996e-07</iyy>
					<iyz>2.125789854846454e-08</iyz>
					<izz>2.374795271079367e-09</izz>
				</inertia>
			</inertial>
			<collision name="tlv_0_collision">
				<geometry>
					<mesh>
						<uri>model://msj_platform/meshes/CAD/tlv_0.stl</uri>
						<scale>0.001 0.001 0.001</scale>
					</mesh>
				</geometry>
			</collision>
			<visual name="tlv_0_visual">
				<geometry>
					<mesh>
						<uri>model://msj_platform/meshes/CAD/tlv_0.stl</uri>
						<scale>0.001 0.001 0.001</scale>
					</mesh>
				</geometry>
			</visual>
		</link>
		<joint name="sphere_axis0" type="revolute">
			<parent>base</parent>
			<child>sphere_link1</child>
			<pose frame="">0.0 -4.996003610813204e-18 1.7763568394002505e-17 0 0 0</pose>
			<axis>
				<xyz>0.9999999999999998 6.162975822039155e-33 -3.0814879110195774e-33</xyz>
				<limit>
					<lower>-3.141592653589793</lower>
					<upper>3.141592653589793</upper>
				</limit>
				<use_parent_model_frame>0</use_parent_model_frame>
			</axis>
		</joint>
		<joint name="sphere_axis2" type="revolute">
			<parent>sphere_link2</parent>
			<child>top</child>
			<pose frame="">1.7763568394002505e-17 0.0015999999999999949 -0.05557142857142857 0 0 0</pose>
			<axis>
				<xyz>-3.0814879110195774e-33 7.703719777548943e-34 1.0</xyz>
				<limit>
					<lower>-3.141592653589793</lower>
					<upper>3.141592653589793</upper>
				</limit>
				<use_parent_model_frame>0</use_parent_model_frame>
			</axis>
		</joint>
		<joint name="sphere_axis1" type="revolute">
			<parent>sphere_link1</parent>
			<child>sphere_link2</child>
			<pose frame="">-5.662137425588298e-17 6.248343398240763e-11 9.080929785909576e-11 0 0 0</pose>
			<axis>
				<xyz>6.162975822039155e-33 -0.9999999999999998 7.703719777548941e-34</xyz>
				<limit>
					<lower>-3.141592653589793</lower>
					<upper>3.141592653589793</upper>
				</limit>
				<use_parent_model_frame>0</use_parent_model_frame>
			</axis>
		</joint>
		<joint name="tlv_sensor_1" type="revolute">
			<parent>base</parent>
			<child>tlv_1</child>
			<pose frame="">5.299256044452916e-05 -0.0001393603702689261 -0.0005488750296033018 0 0 0</pose>
		</joint>
		<joint name="tlv_sensor_2" type="revolute">
			<parent>base</parent>
			<child>tlv_2</child>
			<pose frame="">-0.00037814752563089 -0.00021737785862032235 -0.0003735723606328634 0 0 0</pose>
		</joint>
		<joint name="tlv_sensor_0" type="revolute">
			<parent>base</parent>
			<child>tlv_0</child>
			<pose frame="">-0.0003737561913427301 -0.00023097892352251737 -0.0003700683787619852 0 0 0</pose>
		</joint>
		<plugin filename="libmusc_plugin.so" name="musc_plugin">
			<!--<myoMuscle name="motor0">-->
				<!--<link name="base">-->
					<!--<viaPoint type="FIXPOINT">-0.01410775184896403 -0.10899999990083968 0.3311000348459956</viaPoint>-->
				<!--</link>-->
				<!--<link name="top">-->
					<!--<viaPoint type="FIXPOINT">-0.000813737700967796 -0.03657509438042065 -0.001999999999999993</viaPoint>-->
				<!--</link>-->
			<!--</myoMuscle>-->
			<!--<myoMuscle name="motor1">-->
				<!--<link name="base">-->
					<!--<viaPoint type="FIXPOINT">-0.10899999990083986 -0.014092248151036126 0.0560999999925494</viaPoint>-->
				<!--</link>-->
				<!--<link name="top">-->
					<!--<viaPoint type="FIXPOINT">-0.000813737700967796 -0.03657509438042065 -0.005</viaPoint>-->
				<!--</link>-->
			<!--</myoMuscle>-->
			<!--<myoMuscle name="motor2">-->
				<!--<link name="base">-->
					<!--<viaPoint type="FIXPOINT">-0.10899999990083986 0.014092248151036392 0.3311000348459956</viaPoint>-->
				<!--</link>-->
				<!--<link name="top">-->
					<!--<viaPoint type="FIXPOINT">-0.03817509438042066 0.002413737700967805 -0.001999999999999993</viaPoint>-->
				<!--</link>-->
			<!--</myoMuscle>-->
			<!--<myoMuscle name="motor3">-->
				<!--<link name="base">-->
					<!--<viaPoint type="FIXPOINT">-0.0140922481510363 0.10899999990083979 0.0560999999925494</viaPoint>-->
				<!--</link>-->
				<!--<link name="top">-->
					<!--<viaPoint type="FIXPOINT">0.03817509438042066 0.0007862622990321977 -0.005</viaPoint>-->
				<!--</link>-->
			<!--</myoMuscle>-->
			<!--<myoMuscle name="motor4">-->
				<!--<link name="base">-->
					<!--<viaPoint type="FIXPOINT">0.014107751848963786 0.10899999990083979 0.3311000348459956</viaPoint>-->
				<!--</link>-->
				<!--<link name="top">-->
					<!--<viaPoint type="FIXPOINT">0.0008137377009677937 0.03977509438042065 -0.001999999999999993</viaPoint>-->
				<!--</link>-->
			<!--</myoMuscle>-->
			<!--<myoMuscle name="motor5">-->
				<!--<link name="base">-->
					<!--<viaPoint type="FIXPOINT">0.10899999990083961 0.014092248151036244 0.0560999999925494</viaPoint>-->
				<!--</link>-->
				<!--<link name="top">-->
					<!--<viaPoint type="FIXPOINT">0.0008137377009677937 0.03977509438042065 -0.005</viaPoint>-->
				<!--</link>-->
			<!--</myoMuscle>-->
			<!--<myoMuscle name="motor6">-->
				<!--<link name="base">-->
					<!--<viaPoint type="FIXPOINT">0.10899999990083961 -0.014107751848963868 0.3311000348459956</viaPoint>-->
				<!--</link>-->
				<!--<link name="top">-->
					<!--<viaPoint type="FIXPOINT">0.03817509438042066 0.0007862622990321977 -0.001999999999999993</viaPoint>-->
				<!--</link>-->
			<!--</myoMuscle>-->
			<!--<myoMuscle name="motor7">-->
				<!--<link name="base">-->
					<!--<viaPoint type="FIXPOINT">0.014092248151036055 -0.10899999990083968 0.0560999999925494</viaPoint>-->
				<!--</link>-->
				<!--<link name="top">-->
					<!--<viaPoint type="FIXPOINT">-0.03817509438042066 0.002413737700967805 -0.005</viaPoint>-->
				<!--</link>-->
			<!--</myoMuscle>-->
		</plugin>
	</model>
</sdf>
