<?xml version="1.0" ?>
<sdf version="1.6">
	<model name="msj_platform">
		<link name="base">
			<self_collide>false</self_collide>
			<pose frame="">0.0 0.0 0.0 0.0 -0.0 0.0</pose>
			<inertial>
				<pose frame="">0.0 0.0 0.0 0 0 0</pose>
				<mass>4.6860081359406145</mass>
				<inertia>
					<ixx>0.044613098595856306</ixx>
					<ixy>0.00010672551986971293</ixy>
					<ixz>-0.00013070797640611924</ixz>
					<iyy>0.04463635532622607</iyy>
					<iyz>0.00031152389134664094</iyz>
					<izz>0.060445945893651515</izz>
				</inertia>
			</inertial>
			<collision name="base_collision">
				<geometry>
					<mesh>
						<uri>model://msj_platform/meshes/CAD/base.stl</uri>
						<scale>0.001 0.001 0.001</scale>
					</mesh>
				</geometry>
			</collision>
			<visual name="base_visual">
				<geometry>
					<mesh>
						<uri>model://msj_platform/meshes/CAD/base.stl</uri>
						<scale>0.001 0.001 0.001</scale>
					</mesh>
				</geometry>
			</visual>
		</link>
		<link name="sphere_link1">
			<self_collide>false</self_collide>
			<pose frame="">-0.006043925290475482 -0.00788164209642117 0.11050000000000004 0.0 -0.0 0.0</pose>
			<inertial>
				<pose frame="">0.0 0.0 0.0 0 0 0</pose>
				<mass>0.046754103129628445</mass>
				<inertia>
					<ixx>0.0005797576586090932</ixx>
					<ixy>-2.227181074774182e-06</ixy>
					<ixz>4.071915136846208e-05</ixz>
					<iyy>0.0005785611627038813</iyy>
					<iyz>3.122490285042198e-05</iyz>
					<izz>1.0586253042766894e-05</izz>
				</inertia>
			</inertial>
			<collision name="sphere_link1_collision">
				<geometry>
					<mesh>
						<uri>model://msj_platform/meshes/CAD/sphere_link1.stl</uri>
						<scale>0.001 0.001 0.001</scale>
					</mesh>
				</geometry>
			</collision>
			<visual name="sphere_link1_visual">
				<geometry>
					<mesh>
						<uri>model://msj_platform/meshes/CAD/sphere_link1.stl</uri>
						<scale>0.001 0.001 0.001</scale>
					</mesh>
				</geometry>
			</visual>
		</link>
		<link name="sphere_link2">
			<self_collide>false</self_collide>
			<pose frame="">-0.006043925290475499 -0.007881642096421096 0.1105000000000001 0.0 -0.0 0.0</pose>
			<inertial>
				<pose frame="">0.0 0.0 0.0 0 0 0</pose>
				<mass>0.031340659211905667</mass>
				<inertia>
					<ixx>0.00038732281100541</ixx>
					<ixy>-1.4929453972023549e-06</ixy>
					<ixz>2.7295252416642847e-05</ixz>
					<iyy>0.0003865207643848234</iyy>
					<iyz>2.0930976612826685e-05</iyz>
					<izz>5.790370835226186e-06</izz>
				</inertia>
			</inertial>
			<collision name="sphere_link2_collision">
				<geometry>
					<mesh>
						<uri>model://msj_platform/meshes/CAD/sphere_link2.stl</uri>
						<scale>0.001 0.001 0.001</scale>
					</mesh>
				</geometry>
			</collision>
			<visual name="sphere_link2_visual">
				<geometry>
					<mesh>
						<uri>model://msj_platform/meshes/CAD/sphere_link2.stl</uri>
						<scale>0.001 0.001 0.001</scale>
					</mesh>
				</geometry>
			</visual>
		</link>
		<link name="top">
			<self_collide>false</self_collide>
			<pose frame="">-0.00587138069535635 -0.007891642905929171 0.17258054213920437 0.0 -0.0 0.0</pose>
			<inertial>
				<pose frame="">0.0 0.0 0.0 0 0 0</pose>
				<mass>1.4260572685939936</mass>
				<inertia>
					<ixx>0.043542077636869486</ixx>
					<ixy>-6.876785753277771e-05</ixy>
					<ixz>0.0019412423968921766</ixz>
					<iyy>0.04349888467787417</iyy>
					<iyz>0.0014371173983565712</iyz>
					<izz>0.0015565610316381198</izz>
				</inertia>
			</inertial>
			<collision name="top_collision">
				<geometry>
					<mesh>
						<uri>model://msj_platform/meshes/CAD/top.stl</uri>
						<scale>0.001 0.001 0.001</scale>
					</mesh>
				</geometry>
			</collision>
			<visual name="top_visual">
				<geometry>
					<mesh>
						<uri>model://msj_platform/meshes/CAD/top.stl</uri>
						<scale>0.001 0.001 0.001</scale>
					</mesh>
				</geometry>
			</visual>
		</link>
		<joint name="sphere_axis0" type="revolute">
			<parent>base</parent>
			<child>sphere_link1</child>
			<pose frame="">-1.5543122344752193e-17 3.3306690738754695e-18 7.105427357601002e-17 0 0 0</pose>
			<axis>
				<xyz>-3.885780586188049e-16 -1.0000000000000007 -4.0850449977618627e-16</xyz>
				<limit>
					<lower>-3.141592653589793</lower>
					<upper>3.141592653589793</upper>
				</limit>
				<use_parent_model_frame>0</use_parent_model_frame>
			</axis>
		</joint>
		<joint name="sphere_axis2" type="revolute">
			<parent>sphere_link2</parent>
			<child>top</child>
			<pose frame="">-0.00017254459511915622 1.0000809508018405e-05 -0.0620805421392043 0 0 0</pose>
			<axis>
				<xyz>1.253073569852045e-17 -4.501378631996293e-16 1.0</xyz>
				<limit>
					<lower>-3.141592653589793</lower>
					<upper>3.141592653589793</upper>
				</limit>
				<use_parent_model_frame>0</use_parent_model_frame>
			</axis>
		</joint>
		<joint name="sphere_axis1" type="revolute">
			<parent>sphere_link1</parent>
			<child>sphere_link2</child>
			<pose frame="">1.6653345369377347e-17 -7.216449660063518e-17 -1.7763568394002505e-17 0 0 0</pose>
			<axis>
				<xyz>-1.0000000000000009 3.885780586188048e-16 1.6501212279885653e-16</xyz>
				<limit>
					<lower>-3.141592653589793</lower>
					<upper>3.141592653589793</upper>
				</limit>
				<use_parent_model_frame>0</use_parent_model_frame>
			</axis>
		</joint>
		<plugin filename="libmusc_plugin.so" name="musc_plugin">
			<myoMuscle name="motor0">
				<link name="base">
					<viaPoint type="FIXPOINT">0.05539662834999366 -0.1303643367913177 0.01950000000000014</viaPoint>
					<viaPoint type="FIXPOINT">0.02000000029802305 -0.14400000022351767 0.019700000000000002</viaPoint>
					<viaPoint type="FIXPOINT">0.01684999999999982 -0.12275000000000016 0.023467807133094157</viaPoint>
					<viaPoint type="FIXPOINT">0.016000000238418466 -0.11800000175833716 0.05000000000000001</viaPoint>
					<viaPoint type="FIXPOINT">0.015999999999999834 -0.11500000000000013 0.07500003504716107</viaPoint>
				</link>
				<link name="top">
					<viaPoint type="FIXPOINT">0.01188486506811415 -0.04696732214756318 -0.014080542139204297</viaPoint>
				</link>
			</myoMuscle>
			<myoMuscle name="motor1">
				<link name="base">
					<viaPoint type="FIXPOINT">-0.06104023868482099 -0.12810655313356226 0.019500000000000385</viaPoint>
					<viaPoint type="FIXPOINT">-0.020000000298023388 -0.14400000022351758 0.018299999999999983</viaPoint>
					<viaPoint type="FIXPOINT">-0.01670000000000009 -0.1227500000000002 0.02346780713309415</viaPoint>
					<viaPoint type="FIXPOINT">-0.01623031725074893 -0.11805899530950152 0.05</viaPoint>
					<viaPoint type="FIXPOINT">-0.0160000000000002 -0.11500000000000023 0.2370000350471611</viaPoint>
				</link>
				<link name="top">
					<viaPoint type="FIXPOINT">-0.04714986755219034 -0.012047408853725315 -0.009080542139204261</viaPoint>
				</link>
			</myoMuscle>
			<myoMuscle name="motor2">
				<link name="base">
					<viaPoint type="FIXPOINT">-0.12740600895913295 -0.061740782859250304 0.019500000000000114</viaPoint>
					<viaPoint type="FIXPOINT">-0.14400000022351783 -0.02000000029802312 0.019700000000000002</viaPoint>
					<viaPoint type="FIXPOINT">-0.12275000000000034 -0.01544999999999989 0.023467807133094157</viaPoint>
					<viaPoint type="FIXPOINT">-0.11800000175833734 -0.01600000023841854 0.05000000000000001</viaPoint>
					<viaPoint type="FIXPOINT">-0.11500000000000031 -0.015999999999999903 0.07500003504716107</viaPoint>
				</link>
				<link name="top">
					<viaPoint type="FIXPOINT">-0.04714986755219034 -0.01204740885372531 -0.014080542139204262</viaPoint>
				</link>
			</myoMuscle>
			<myoMuscle name="motor3">
				<link name="base">
					<viaPoint type="FIXPOINT">-0.12810655313356242 0.06104023868482091 0.019500000000000385</viaPoint>
					<viaPoint type="FIXPOINT">-0.14400000022351775 0.02000000029802332 0.017799999999999986</viaPoint>
					<viaPoint type="FIXPOINT">-0.12275000000000037 0.01670000000000002 0.02346780713309415</viaPoint>
					<viaPoint type="FIXPOINT">-0.1180589953095017 0.016230317250748864 0.05</viaPoint>
					<viaPoint type="FIXPOINT">-0.1150000000000004 0.01460000000000013 0.2370000350471611</viaPoint>
				</link>
				<link name="top">
					<viaPoint type="FIXPOINT">-0.01222995425835244 0.04698732376657918 -0.009080542139204227</viaPoint>
				</link>
			</myoMuscle>
			<myoMuscle name="motor4">
				<link name="base">
					<viaPoint type="FIXPOINT">-0.06174078285925048 0.1274060089591329 0.019500000000000114</viaPoint>
					<viaPoint type="FIXPOINT">-0.0200000002980233 0.14400000022351775 0.018300000000000007</viaPoint>
					<viaPoint type="FIXPOINT">-0.016850000000000066 0.12275000000000028 0.023467807133094157</viaPoint>
					<viaPoint type="FIXPOINT">-0.01600000023841871 0.11800000175833728 0.05000000000000001</viaPoint>
					<viaPoint type="FIXPOINT">-0.01600000000000008 0.11500000000000023 0.07500003504716107</viaPoint>
				</link>
				<link name="top">
					<viaPoint type="FIXPOINT">-0.01222995425835244 0.046987323766579187 -0.014080542139204226</viaPoint>
				</link>
			</myoMuscle>
			<myoMuscle name="motor5">
				<link name="base">
					<viaPoint type="FIXPOINT">0.06104023868482074 0.12810655313356237 0.019500000000000385</viaPoint>
					<viaPoint type="FIXPOINT">0.020000000298023145 0.1440000002235177 0.01969999999999998</viaPoint>
					<viaPoint type="FIXPOINT">0.015299999999999843 0.1227500000000003 0.02346780713309415</viaPoint>
					<viaPoint type="FIXPOINT">0.016230317250748687 0.11805899530950162 0.05</viaPoint>
					<viaPoint type="FIXPOINT">0.014599999999999955 0.11500000000000032 0.2370000350471611</viaPoint>
				</link>
				<link name="top">
					<viaPoint type="FIXPOINT">-0.03258339770119593 0.03609028075487859 -0.009080542139204261</viaPoint>
				</link>
			</myoMuscle>
			<myoMuscle name="motor6">
				<link name="base">
					<viaPoint type="FIXPOINT">0.1274060089591327 0.06174078285925043 0.019500000000000114</viaPoint>
					<viaPoint type="FIXPOINT">0.14400000022351758 0.020000000298023245 0.018300000000000007</viaPoint>
					<viaPoint type="FIXPOINT">0.1227500000000001 0.015450000000000009 0.023467807133094157</viaPoint>
					<viaPoint type="FIXPOINT">0.1180000017583371 0.016000000238418657 0.05000000000000001</viaPoint>
					<viaPoint type="FIXPOINT">0.11500000000000006 0.014600000000000026 0.07500003504716107</viaPoint>
				</link>
				<link name="top">
					<viaPoint type="FIXPOINT">0.04680477836195206 0.012067410472741288 -0.014080542139204262</viaPoint>
				</link>
			</myoMuscle>
			<myoMuscle name="motor7">
				<link name="base">
					<viaPoint type="FIXPOINT">0.12810655313356217 -0.06104023868482083 0.019500000000000385</viaPoint>
					<viaPoint type="FIXPOINT">0.14400000022351753 -0.020000000298023197 0.018299999999999983</viaPoint>
					<viaPoint type="FIXPOINT">0.12275000000000014 -0.015299999999999897 0.02346780713309415</viaPoint>
					<viaPoint type="FIXPOINT">0.11805899530950145 -0.016230317250748742 0.05</viaPoint>
					<viaPoint type="FIXPOINT">0.11500000000000016 -0.01600000000000001 0.2370000350471611</viaPoint>
				</link>
				<link name="top">
					<viaPoint type="FIXPOINT">0.01188486506811415 -0.0469673221475632 -0.009080542139204298</viaPoint>
				</link>
			</myoMuscle>
		</plugin>
	</model>
</sdf>
