<robot name="msj_platform">
  <joint name="tlv_sensor_2" type="fixed">
    <parent link="base" />
    <child link="tlv_2" />
    <origin rpy="0  0  0" xyz="-0.0139   0.00098  0.08529" />
    <axis xyz="0  0  0" />
    <limit effort="0" lower="0" upper="0" velocity="0" />
  </joint>
  <joint name="tlv_sensor_1" type="fixed">
    <parent link="base" />
    <child link="tlv_1" />
    <origin rpy="0  0  0" xyz="0.01259  0.00116  0.08334" />
    <axis xyz="0  0  0" />
    <limit effort="0" lower="0" upper="0" velocity="0" />
  </joint>
  <joint name="sphere_axis0" type="revolute">
    <parent link="base" />
    <child link="sphere_link1" />
    <origin rpy="0  0  0" xyz="0.00157 -0.00449  0.102" />
    <axis xyz="1  0  0" />
    <limit effort="0.0" lower="-3.14159265359" upper="3.14159265359" velocity="0.0" />
  </joint>
  <joint name="sphere_axis2" type="revolute">
    <parent link="sphere_link2" />
    <child link="top" />
    <origin rpy="0  0  0" xyz="0  0  0" />
    <axis xyz="0  0  1" />
    <limit effort="0.0" lower="-3.14159265359" upper="3.14159265359" velocity="0.0" />
  </joint>
  <joint name="sphere_axis1" type="revolute">
    <parent link="sphere_link1" />
    <child link="sphere_link2" />
    <origin rpy="0  0  0" xyz="0  0  0" />
    <axis xyz="0 -1  0" />
    <limit effort="0.0" lower="-3.14159265359" upper="3.14159265359" velocity="0.0" />
  </joint>
  <joint name="tlv_sensor_0" type="fixed">
    <parent link="base" />
    <child link="tlv_0" />
    <origin rpy="0  0  0" xyz="-0.00566  0.01698  0.09455" />
    <axis xyz="0  0  0" />
    <limit effort="0" lower="0" upper="0" velocity="0" />
  </joint>
  <link name="base">
    <inertial>
      <mass value="4.448797943180804" />
      <origin rpy="0  0  0" xyz="0  0  0" />
      <inertia ixx="0.05727592310541465" ixy="0.00012290217214213836" ixz="-0.00024830920575398503" iyy="0.05720227497311322" iyz="0.00018485788595171346" izz="0.057271534245981616" />
    </inertial>
    <collision name="base_collision">
      <origin rpy="0  0  0" xyz="0  0  0" />
      <geometry>
        <mesh filename="package://robots/msj_platform/meshes/collisions/base.stl" scale="0.001 0.001 0.001" />
      </geometry>
    </collision>
    <visual name="base_visual">
      <origin rpy="0  0  0" xyz="0  0  0" />
      <geometry>
        <mesh filename="package://robots/msj_platform/meshes/visuals/base.stl" scale="0.001 0.001 0.001" />
      </geometry>
    </visual>
  </link>
  <link name="top">
    <inertial>
      <mass value="0.04408362730485983" />
      <origin rpy="0  0  0" xyz="0       0.0001   0.05457" />
      <inertia ixx="0.0008183452788580439" ixy="3.128717612906996e-07" ixz="2.6329027458980525e-05" iyy="0.0008175212363323387" iyz="-9.322778138461973e-06" izz="1.1841425912850233e-05" />
    </inertial>
    <collision name="top_collision">
      <origin rpy="0  0  0" xyz="0       0.0001   0.05457" />
      <geometry>
        <mesh filename="package://robots/msj_platform/meshes/collisions/top.stl" scale="0.001 0.001 0.001" />
      </geometry>
    </collision>
    <visual name="top_visual">
      <origin rpy="0  0  0" xyz="0       0.0001   0.05457" />
      <geometry>
        <mesh filename="package://robots/msj_platform/meshes/visuals/top.stl" scale="0.001 0.001 0.001" />
      </geometry>
    </visual>
  </link>
  <link name="tlv_1">
    <inertial>
      <mass value="3.129257386988798e-05" />
      <origin rpy="0  0  0" xyz="-8.00000000e-05  -2.50000000e-04   5.00000000e-04" />
      <inertia ixx="2.2008521095762138e-07" ixy="-3.491762356133812e-10" ixz="-2.375401686411031e-09" iyy="2.2496401029476372e-07" iyz="-3.285804213322665e-08" izz="4.955279890652638e-09" />
    </inertial>
    <collision name="tlv_1_collision">
      <origin rpy="0  0  0" xyz="-8.00000000e-05  -2.50000000e-04   5.00000000e-04" />
      <geometry>
        <mesh filename="package://robots/msj_platform/meshes/collisions/tlv_1.stl" scale="0.001 0.001 0.001" />
      </geometry>
    </collision>
    <visual name="tlv_1_visual">
      <origin rpy="0  0  0" xyz="-8.00000000e-05  -2.50000000e-04   5.00000000e-04" />
      <geometry>
        <mesh filename="package://robots/msj_platform/meshes/visuals/tlv_1.stl" scale="0.001 0.001 0.001" />
      </geometry>
    </visual>
  </link>
  <link name="tlv_2">
    <inertial>
      <mass value="3.1292573869887934e-05" />
      <origin rpy="0  0  0" xyz="0.00033 -0.00036  0.00029" />
      <inertia ixx="2.2932150676593563e-07" ixy="2.6068692193400166e-10" ixz="-1.654772588383988e-09" iyy="2.3506468365436475e-07" iyz="3.6376532210445136e-08" izz="5.807899196545732e-09" />
    </inertial>
    <collision name="tlv_2_collision">
      <origin rpy="0  0  0" xyz="0.00033 -0.00036  0.00029" />
      <geometry>
        <mesh filename="package://robots/msj_platform/meshes/collisions/tlv_2.stl" scale="0.001 0.001 0.001" />
      </geometry>
    </collision>
    <visual name="tlv_2_visual">
      <origin rpy="0  0  0" xyz="0.00033 -0.00036  0.00029" />
      <geometry>
        <mesh filename="package://robots/msj_platform/meshes/visuals/tlv_2.stl" scale="0.001 0.001 0.001" />
      </geometry>
    </visual>
  </link>
  <link name="tlv_0">
    <inertial>
      <mass value="3.129257386988798e-05" />
      <origin rpy="0  0  0" xyz="0.00033 -0.00035  0.0003" />
      <inertia ixx="2.9030526397336794e-07" ixy="2.7666123708233105e-09" ixz="-4.937942987159648e-08" iyy="2.825445911324978e-07" iyz="1.580272584191468e-08" izz="9.561086775994239e-09" />
    </inertial>
    <collision name="tlv_0_collision">
      <origin rpy="0  0  0" xyz="0.00033 -0.00035  0.0003" />
      <geometry>
        <mesh filename="package://robots/msj_platform/meshes/collisions/tlv_0.stl" scale="0.001 0.001 0.001" />
      </geometry>
    </collision>
    <visual name="tlv_0_visual">
      <origin rpy="0  0  0" xyz="0.00033 -0.00035  0.0003" />
      <geometry>
        <mesh filename="package://robots/msj_platform/meshes/visuals/tlv_0.stl" scale="0.001 0.001 0.001" />
      </geometry>
    </visual>
  </link>
  <link name="sphere_link1">
    <inertial>
      <mass value="0.0697903813480168" />
      <origin rpy="0  0  0" xyz="0  0  0" />
      <inertia ixx="0.0007391596604397545" ixy="4.93517696675261e-07" ixz="3.203378503873992e-05" iyy="0.0007379187447305817" iyz="-1.118640112463933e-05" izz="1.3232872408105817e-05" />
    </inertial>
    <collision name="sphere_link1_collision">
      <origin rpy="0  0  0" xyz="0  0  0" />
      <geometry>
        <mesh filename="package://robots/msj_platform/meshes/collisions/sphere_link1.stl" scale="0.001 0.001 0.001" />
      </geometry>
    </collision>
    <visual name="sphere_link1_visual">
      <origin rpy="0  0  0" xyz="0  0  0" />
      <geometry>
        <mesh filename="package://robots/msj_platform/meshes/visuals/sphere_link1.stl" scale="0.001 0.001 0.001" />
      </geometry>
    </visual>
  </link>
  <link name="sphere_link2">
    <inertial>
      <mass value="0.046782557609273294" />
      <origin rpy="0  0  0" xyz="0  0  0" />
      <inertia ixx="0.0004929345087489758" ixy="3.3081951911622943e-07" ixz="2.1473194259282223e-05" iyy="0.0004921026862749714" iyz="-7.4985756558394376e-06" izz="6.3243045525461035e-06" />
    </inertial>
    <collision name="sphere_link2_collision">
      <origin rpy="0  0  0" xyz="0  0  0" />
      <geometry>
        <mesh filename="package://robots/msj_platform/meshes/collisions/sphere_link2.stl" scale="0.001 0.001 0.001" />
      </geometry>
    </collision>
    <visual name="sphere_link2_visual">
      <origin rpy="0  0  0" xyz="0  0  0" />
      <geometry>
        <mesh filename="package://robots/msj_platform/meshes/visuals/sphere_link2.stl" scale="0.001 0.001 0.001" />
      </geometry>
    </visual>
  </link>
</robot>