<?xml version="1.0" ?>
<sdf version="1.6">
	<model name="msj_platform">
		<link name="base">
			<self_collide>false</self_collide>
			<pose frame="">-0.0001999063137023958 1.2357904545724126e-05 0.0344222981707344 0.0 -0.0 0.0</pose>
			<inertial>
				<pose frame="">0.0 0.0 0.0 0 0 0</pose>
				<mass>4.518359714742866</mass>
				<inertia>
					<ixx>0.04369951520384483</ixx>
					<ixy>1.4127681154620406e-05</ixy>
					<ixz>2.4162806555812674e-05</ixz>
					<iyy>0.043698648614054474</iyy>
					<iyz>6.906314562333575e-05</iyz>
					<izz>0.06019399435534187</izz>
				</inertia>
			</inertial>
			<collision name="base_collision">
				<geometry>
					<mesh>
						<uri>model://msj_platform/meshes/CAD/base.stl</uri>
						<scale>0.001 0.001 0.001</scale>
					</mesh>
				</geometry>
			</collision>
			<visual name="base_visual">
				<geometry>
					<mesh>
						<uri>model://msj_platform/meshes/CAD/base.stl</uri>
						<scale>0.001 0.001 0.001</scale>
					</mesh>
				</geometry>
			</visual>
		</link>
		<link name="top">
			<self_collide>false</self_collide>
			<pose frame="">-0.0047851400286808435 -0.005318652122115687 0.16615473201489125 0.0 -0.0 0.0</pose>
			<inertial>
				<pose frame="">0.0 0.0 0.0 0 0 0</pose>
				<mass>1.046069596988917</mass>
				<inertia>
					<ixx>0.02953939584046645</ixx>
					<ixy>-2.9853673494097152e-05</ixy>
					<ixz>0.0009240300543645074</ixz>
					<iyy>0.02953304416853176</iyy>
					<iyz>0.0008245839074650718</iyz>
					<izz>0.0010854311272441596</izz>
				</inertia>
			</inertial>
			<collision name="top_collision">
				<geometry>
					<mesh>
						<uri>model://msj_platform/meshes/CAD/top.stl</uri>
						<scale>0.001 0.001 0.001</scale>
					</mesh>
				</geometry>
			</collision>
			<visual name="top_visual">
				<geometry>
					<mesh>
						<uri>model://msj_platform/meshes/CAD/top.stl</uri>
						<scale>0.001 0.001 0.001</scale>
					</mesh>
				</geometry>
			</visual>
		</link>
		<link name="sphere_link1">
			<self_collide>false</self_collide>
			<pose frame="">-0.006000000000000005 -0.006999999999999992 0.10999999999999997 0.0 -0.0 0.0</pose>
			<inertial>
				<pose frame="">0.0 0.0 0.0 0 0 0</pose>
				<mass>0.04675410312962846</mass>
				<inertia>
					<ixx>0.0005739895917149713</ixx>
					<ixy>-1.9636723314443955e-06</ixy>
					<ixz>3.600065940981386e-05</ixz>
					<iyy>0.000573381788374286</iyy>
					<iyz>3.085770806555481e-05</iyz>
					<izz>9.948091559133534e-06</izz>
				</inertia>
			</inertial>
			<collision name="sphere_link1_collision">
				<geometry>
					<mesh>
						<uri>model://msj_platform/meshes/CAD/sphere_link1.stl</uri>
						<scale>0.001 0.001 0.001</scale>
					</mesh>
				</geometry>
			</collision>
			<visual name="sphere_link1_visual">
				<geometry>
					<mesh>
						<uri>model://msj_platform/meshes/CAD/sphere_link1.stl</uri>
						<scale>0.001 0.001 0.001</scale>
					</mesh>
				</geometry>
			</visual>
		</link>
		<link name="shere_link2">
			<self_collide>false</self_collide>
			<pose frame="">-0.005999999999999985 -0.0070000000546730085 0.10999999992054192 0.0 -0.0 0.0</pose>
			<inertial>
				<pose frame="">0.0 0.0 0.0 0 0 0</pose>
				<mass>0.03134065871089989</mass>
				<inertia>
					<ixx>0.0003834562983753192</ixx>
					<ixy>-1.3163076761387219e-06</ixy>
					<ixz>2.4132307397721476e-05</ixz>
					<iyy>0.00038304886982346855</iyy>
					<iyz>2.068483473425227e-05</iyz>
					<izz>5.362592249699947e-06</izz>
				</inertia>
			</inertial>
			<collision name="shere_link2_collision">
				<geometry>
					<mesh>
						<uri>model://msj_platform/meshes/CAD/shere_link2.stl</uri>
						<scale>0.001 0.001 0.001</scale>
					</mesh>
				</geometry>
			</collision>
			<visual name="shere_link2_visual">
				<geometry>
					<mesh>
						<uri>model://msj_platform/meshes/CAD/shere_link2.stl</uri>
						<scale>0.001 0.001 0.001</scale>
					</mesh>
				</geometry>
			</visual>
		</link>
		<joint name="sphere_axis0" type="revolute">
			<parent>base</parent>
			<child>sphere_link1</child>
			<pose frame="">4.440892098500626e-18 -8.881784197001253e-18 3.552713678800501e-17 0 0 0</pose>
			<axis>
				<xyz>1.0 0.0 0.0</xyz>
				<limit>
					<lower>-3.141592653589793</lower>
					<upper>3.141592653589793</upper>
				</limit>
				<use_parent_model_frame>0</use_parent_model_frame>
			</axis>
		</joint>
		<joint name="sphere_axis2" type="revolute">
			<parent>shere_link2</parent>
			<child>top</child>
			<pose frame="">-0.0012148599713191534 -0.0016813478778843138 -0.05615473201489124 0 0 0</pose>
			<axis>
				<xyz>0.0 0.0 1.0</xyz>
				<limit>
					<lower>-3.141592653589793</lower>
					<upper>3.141592653589793</upper>
				</limit>
				<use_parent_model_frame>0</use_parent_model_frame>
			</axis>
		</joint>
		<joint name="sphere_axis1" type="revolute">
			<parent>sphere_link1</parent>
			<child>shere_link2</child>
			<pose frame="">-1.5543122344752193e-17 5.467300723260848e-11 7.945807567466545e-11 0 0 0</pose>
			<axis>
				<xyz>0.0 -1.0 0.0</xyz>
				<limit>
					<lower>-3.141592653589793</lower>
					<upper>3.141592653589793</upper>
				</limit>
				<use_parent_model_frame>0</use_parent_model_frame>
			</axis>
		</joint>
		<plugin filename="libmusc_plugin.so" name="musc_plugin">
			<myoMuscle name="motor0">
				<link name="base">
					<viaPoint type="FIXPOINT">0.05559653466369618 -0.1303766946958635 -0.014922298170734262</viaPoint>
					<viaPoint type="FIXPOINT">0.020199906611725563 -0.14401235812806343 -0.0147222981707344</viaPoint>
					<viaPoint type="FIXPOINT">0.01704990631370233 -0.12276235790454594 -0.010954491037640244</viaPoint>
					<viaPoint type="FIXPOINT">0.016199906552120977 -0.11801235966288294 0.015577701829265607</viaPoint>
					<viaPoint type="FIXPOINT">0.016199906313702345 -0.1150123579045459 0.04057773687642668</viaPoint>
				</link>
				<link name="top">
					<viaPoint type="FIXPOINT">0.010798624401438644 -0.049540312931376666 -0.037654732014891154</viaPoint>
				</link>
			</myoMuscle>
			<myoMuscle name="motor1">
				<link name="base">
					<viaPoint type="FIXPOINT">-0.06084033237111847 -0.12811891103810802 -0.01492229817073402</viaPoint>
					<viaPoint type="FIXPOINT">-0.019800093984320876 -0.14401235812806337 -0.01612229817073442</viaPoint>
					<viaPoint type="FIXPOINT">-0.016500093686297578 -0.12276235790454598 -0.010954491037640252</viaPoint>
					<viaPoint type="FIXPOINT">-0.016030410937046418 -0.1180713532140473 0.015577701829265598</viaPoint>
					<viaPoint type="FIXPOINT">-0.01580009368629769 -0.115012357904546 0.20257773687642672</viaPoint>
				</link>
				<link name="top">
					<viaPoint type="FIXPOINT">-0.04823610821886584 -0.014620399637538802 -0.032654732014891115</viaPoint>
				</link>
			</myoMuscle>
			<myoMuscle name="motor2">
				<link name="base">
					<viaPoint type="FIXPOINT">-0.12720610264543045 -0.06175314076379608 -0.014922298170734288</viaPoint>
					<viaPoint type="FIXPOINT">-0.14380009390981532 -0.0200123582025689 -0.0147222981707344</viaPoint>
					<viaPoint type="FIXPOINT">-0.12255009368629782 -0.015462357904545665 -0.010954491037640244</viaPoint>
					<viaPoint type="FIXPOINT">-0.11780009544463482 -0.016012358142964315 0.015577701829265607</viaPoint>
					<viaPoint type="FIXPOINT">-0.11480009368629779 -0.01601235790454568 0.04057773687642668</viaPoint>
				</link>
				<link name="top">
					<viaPoint type="FIXPOINT">-0.04823610821886584 -0.014620399637538797 -0.03765473201489112</viaPoint>
				</link>
			</myoMuscle>
			<myoMuscle name="motor3">
				<link name="base">
					<viaPoint type="FIXPOINT">-0.12790664681985991 0.061027880780275136 -0.01492229817073402</viaPoint>
					<viaPoint type="FIXPOINT">-0.14380009390981524 0.019987642393477546 -0.016622298170734417</viaPoint>
					<viaPoint type="FIXPOINT">-0.12255009368629786 0.016687642095454244 -0.010954491037640252</viaPoint>
					<viaPoint type="FIXPOINT">-0.11785908899579918 0.016217959346203088 0.015577701829265598</viaPoint>
					<viaPoint type="FIXPOINT">-0.11480009368629787 0.014587642095454354 0.20257773687642672</viaPoint>
				</link>
				<link name="top">
					<viaPoint type="FIXPOINT">-0.013316194925027947 0.044414332982765696 -0.03265473201489108</viaPoint>
				</link>
			</myoMuscle>
			<myoMuscle name="motor4">
				<link name="base">
					<viaPoint type="FIXPOINT">-0.06154087654554797 0.1273936510545871 -0.014922298170734288</viaPoint>
					<viaPoint type="FIXPOINT">-0.01980009398432079 0.143987642318972 -0.0161222981707344</viaPoint>
					<viaPoint type="FIXPOINT">-0.016650093686297555 0.1227376420954545 -0.010954491037640244</viaPoint>
					<viaPoint type="FIXPOINT">-0.0158000939247162 0.1179876438537915 0.015577701829265607</viaPoint>
					<viaPoint type="FIXPOINT">-0.01580009368629757 0.11498764209545445 0.04057773687642668</viaPoint>
				</link>
				<link name="top">
					<viaPoint type="FIXPOINT">-0.013316194925027947 0.0444143329827657 -0.037654732014891085</viaPoint>
				</link>
			</myoMuscle>
			<myoMuscle name="motor5">
				<link name="base">
					<viaPoint type="FIXPOINT">0.06124014499852325 0.12809419522901658 -0.01492229817073402</viaPoint>
					<viaPoint type="FIXPOINT">0.020199906611725656 0.1439876423189719 -0.014722298170734421</viaPoint>
					<viaPoint type="FIXPOINT">0.015499906313702355 0.12273764209545453 -0.010954491037640252</viaPoint>
					<viaPoint type="FIXPOINT">0.016430223564451195 0.11804663740495584 0.015577701829265598</viaPoint>
					<viaPoint type="FIXPOINT">0.014799906313702467 0.11498764209545455 0.20257773687642672</viaPoint>
				</link>
				<link name="top">
					<viaPoint type="FIXPOINT">-0.033669638367871436 0.03351728997106511 -0.032654732014891115</viaPoint>
				</link>
			</myoMuscle>
			<myoMuscle name="motor6">
				<link name="base">
					<viaPoint type="FIXPOINT">0.12760591527283524 0.06172842495470465 -0.014922298170734288</viaPoint>
					<viaPoint type="FIXPOINT">0.14419990653722012 0.01998764239347747 -0.0161222981707344</viaPoint>
					<viaPoint type="FIXPOINT">0.12294990631370262 0.015437642095454231 -0.010954491037640244</viaPoint>
					<viaPoint type="FIXPOINT">0.11819990807203962 0.01598764233387288 0.015577701829265607</viaPoint>
					<viaPoint type="FIXPOINT">0.11519990631370258 0.01458764209545425 0.04057773687642668</viaPoint>
				</link>
				<link name="top">
					<viaPoint type="FIXPOINT">0.04571853769527654 0.009494419688927802 -0.03765473201489112</viaPoint>
				</link>
			</myoMuscle>
			<myoMuscle name="motor7">
				<link name="base">
					<viaPoint type="FIXPOINT">0.12830645944726468 -0.061052596589366605 -0.01492229817073402</viaPoint>
					<viaPoint type="FIXPOINT">0.14419990653722004 -0.020012358202568973 -0.01612229817073442</viaPoint>
					<viaPoint type="FIXPOINT">0.12294990631370264 -0.015312357904545673 -0.010954491037640252</viaPoint>
					<viaPoint type="FIXPOINT">0.11825890162320396 -0.01624267515529452 0.015577701829265598</viaPoint>
					<viaPoint type="FIXPOINT">0.11519990631370268 -0.016012357904545787 0.20257773687642672</viaPoint>
				</link>
				<link name="top">
					<viaPoint type="FIXPOINT">0.010798624401438644 -0.04954031293137667 -0.03265473201489115</viaPoint>
				</link>
			</myoMuscle>
		</plugin>
	</model>
</sdf>
