<?xml version="1.0" ?>
<sdf version="1.6">
	<model name="msj_platform">
		<link name="base">
			<self_collide>false</self_collide>
			<pose frame="">0.0 0.0 0.0 0.0 -0.0 0.0</pose>
			<inertial>
				<pose frame="">0.0 0.0 0.0 0 0 0</pose>
				<mass>4.686007862792891</mass>
				<inertia>
					<ixx>0.04460594028890755</ixx>
					<ixy>0.00010670397991643834</ixy>
					<ixz>-0.00012998164470001694</ixz>
					<iyy>0.044628998866831276</iyy>
					<iyz>0.00031087502181145483</iyz>
					<izz>0.060446040582081084</izz>
				</inertia>
			</inertial>
			<collision name="base_collision">
				<geometry>
					<mesh>
						<uri>model://msj_platform/meshes/CAD/base.stl</uri>
						<scale>0.001 0.001 0.001</scale>
					</mesh>
				</geometry>
			</collision>
			<visual name="base_visual">
				<geometry>
					<mesh>
						<uri>model://msj_platform/meshes/CAD/base.stl</uri>
						<scale>0.001 0.001 0.001</scale>
					</mesh>
				</geometry>
			</visual>
		</link>
		<link name="top">
			<self_collide>false</self_collide>
			<pose frame="">-0.005871036493208736 -0.00789256150380153 0.1725766629321328 0.0 -0.0 0.0</pose>
			<inertial>
				<pose frame="">0.0 0.0 0.0 0 0 0</pose>
				<mass>1.4259339831467317</mass>
				<inertia>
					<ixx>0.043540779448718085</ixx>
					<ixy>-6.8771844250587e-05</ixy>
					<ixz>0.0019413546516229485</ixz>
					<iyy>0.043497559582407475</iyy>
					<iyz>0.0014370255220575831</iyz>
					<izz>0.0015565759249338302</izz>
				</inertia>
			</inertial>
			<collision name="top_collision">
				<geometry>
					<mesh>
						<uri>model://msj_platform/meshes/CAD/top.stl</uri>
						<scale>0.001 0.001 0.001</scale>
					</mesh>
				</geometry>
			</collision>
			<visual name="top_visual">
				<geometry>
					<mesh>
						<uri>model://msj_platform/meshes/CAD/top.stl</uri>
						<scale>0.001 0.001 0.001</scale>
					</mesh>
				</geometry>
			</visual>
		</link>
		<link name="sphere_link1">
			<self_collide>false</self_collide>
			<pose frame="">-0.0060000000000000045 -0.007999999999999993 0.10999999999999999 0.0 -0.0 0.0</pose>
			<inertial>
				<pose frame="">0.0 0.0 0.0 0 0 0</pose>
				<mass>0.04675410312962845</mass>
				<inertia>
					<ixx>0.0005746909032619158</ixx>
					<ixy>-2.2441969502221693e-06</ixy>
					<ixz>4.1143610754073024e-05</ixz>
					<iyy>0.0005733817883742863</iyy>
					<iyz>3.085770806555482e-05</iyz>
					<izz>1.064940310607797e-05</izz>
				</inertia>
			</inertial>
			<collision name="sphere_link1_collision">
				<geometry>
					<mesh>
						<uri>model://msj_platform/meshes/CAD/sphere_link1.stl</uri>
						<scale>0.001 0.001 0.001</scale>
					</mesh>
				</geometry>
			</collision>
			<visual name="sphere_link1_visual">
				<geometry>
					<mesh>
						<uri>model://msj_platform/meshes/CAD/sphere_link1.stl</uri>
						<scale>0.001 0.001 0.001</scale>
					</mesh>
				</geometry>
			</visual>
		</link>
		<link name="sphere_link2">
			<self_collide>false</self_collide>
			<pose frame="">-0.005999999999999988 -0.00800000005467301 0.10999999992054188 0.0 -0.0 0.0</pose>
			<inertial>
				<pose frame="">0.0 0.0 0.0 0 0 0</pose>
				<mass>0.03134065871089989</mass>
				<inertia>
					<ixx>0.0003839264082594096</ixx>
					<ixy>-1.504351628404124e-06</ixy>
					<ixz>2.7579779853430193e-05</ixz>
					<iyy>0.00038304886982346855</iyy>
					<iyz>2.068483473425228e-05</iyz>
					<izz>5.832702133790424e-06</izz>
				</inertia>
			</inertial>
			<collision name="sphere_link2_collision">
				<geometry>
					<mesh>
						<uri>model://msj_platform/meshes/CAD/sphere_link2.stl</uri>
						<scale>0.001 0.001 0.001</scale>
					</mesh>
				</geometry>
			</collision>
			<visual name="sphere_link2_visual">
				<geometry>
					<mesh>
						<uri>model://msj_platform/meshes/CAD/sphere_link2.stl</uri>
						<scale>0.001 0.001 0.001</scale>
					</mesh>
				</geometry>
			</visual>
		</link>
		<joint name="sphere_axis0" type="revolute">
			<parent>base</parent>
			<child>sphere_link1</child>
			<pose frame="">3.3306690738754695e-18 -6.661338147750939e-18 1.7763568394002505e-17 0 0 0</pose>
			<axis>
				<xyz>1.0 0.0 0.0</xyz>
				<limit>
					<lower>-3.141592653589793</lower>
					<upper>3.141592653589793</upper>
				</limit>
				<use_parent_model_frame>0</use_parent_model_frame>
			</axis>
		</joint>
		<joint name="sphere_axis2" type="revolute">
			<parent>sphere_link2</parent>
			<child>top</child>
			<pose frame="">-0.0001289635067912609 -0.00010743849619847201 -0.06257666293213279 0 0 0</pose>
			<axis>
				<xyz>0.0 0.0 1.0</xyz>
				<limit>
					<lower>-3.141592653589793</lower>
					<upper>3.141592653589793</upper>
				</limit>
				<use_parent_model_frame>0</use_parent_model_frame>
			</axis>
		</joint>
		<joint name="sphere_axis1" type="revolute">
			<parent>sphere_link1</parent>
			<child>sphere_link2</child>
			<pose frame="">-1.3322676295501878e-17 5.467300834283151e-11 7.945812896537064e-11 0 0 0</pose>
			<axis>
				<xyz>0.0 -1.0 0.0</xyz>
				<limit>
					<lower>-3.141592653589793</lower>
					<upper>3.141592653589793</upper>
				</limit>
				<use_parent_model_frame>0</use_parent_model_frame>
			</axis>
		</joint>
		<plugin filename="libmusc_plugin.so" name="musc_plugin">
			<myoMuscle name="motor0">
				<link name="base">
					<viaPoint type="FIXPOINT">0.05539662834999366 -0.1303643367913177 0.01950000000000014</viaPoint>
					<viaPoint type="FIXPOINT">0.02000000029802305 -0.14400000022351767 0.019700000000000002</viaPoint>
					<viaPoint type="FIXPOINT">0.01684999999999982 -0.12275000000000016 0.023467807133094157</viaPoint>
					<viaPoint type="FIXPOINT">0.016000000238418466 -0.11800000175833716 0.05000000000000001</viaPoint>
					<viaPoint type="FIXPOINT">0.015999999999999834 -0.11500000000000013 0.07500003504716107</viaPoint>
				</link>
				<link name="top">
					<viaPoint type="FIXPOINT">0.011884520865966537 -0.04696640354969083 -0.014076662932132713</viaPoint>
				</link>
			</myoMuscle>
			<myoMuscle name="motor1">
				<link name="base">
					<viaPoint type="FIXPOINT">-0.06104023868482099 -0.12810655313356226 0.019500000000000385</viaPoint>
					<viaPoint type="FIXPOINT">-0.020000000298023388 -0.14400000022351758 0.018299999999999983</viaPoint>
					<viaPoint type="FIXPOINT">-0.01670000000000009 -0.1227500000000002 0.02346780713309415</viaPoint>
					<viaPoint type="FIXPOINT">-0.01623031725074893 -0.11805899530950152 0.05</viaPoint>
					<viaPoint type="FIXPOINT">-0.0160000000000002 -0.11500000000000023 0.2370000350471611</viaPoint>
				</link>
				<link name="top">
					<viaPoint type="FIXPOINT">-0.04715021175433795 -0.01204649025585296 -0.009076662932132678</viaPoint>
				</link>
			</myoMuscle>
			<myoMuscle name="motor2">
				<link name="base">
					<viaPoint type="FIXPOINT">-0.12740600895913295 -0.061740782859250304 0.019500000000000114</viaPoint>
					<viaPoint type="FIXPOINT">-0.14400000022351783 -0.02000000029802312 0.019700000000000002</viaPoint>
					<viaPoint type="FIXPOINT">-0.12275000000000034 -0.01544999999999989 0.023467807133094157</viaPoint>
					<viaPoint type="FIXPOINT">-0.11800000175833734 -0.01600000023841854 0.05000000000000001</viaPoint>
					<viaPoint type="FIXPOINT">-0.11500000000000031 -0.015999999999999903 0.07500003504716107</viaPoint>
				</link>
				<link name="top">
					<viaPoint type="FIXPOINT">-0.04715021175433795 -0.012046490255852955 -0.014076662932132679</viaPoint>
				</link>
			</myoMuscle>
			<myoMuscle name="motor3">
				<link name="base">
					<viaPoint type="FIXPOINT">-0.12810655313356242 0.06104023868482091 0.019500000000000385</viaPoint>
					<viaPoint type="FIXPOINT">-0.14400000022351775 0.02000000029802332 0.017799999999999986</viaPoint>
					<viaPoint type="FIXPOINT">-0.12275000000000037 0.01670000000000002 0.02346780713309415</viaPoint>
					<viaPoint type="FIXPOINT">-0.1180589953095017 0.016230317250748864 0.05</viaPoint>
					<viaPoint type="FIXPOINT">-0.1150000000000004 0.01460000000000013 0.2370000350471611</viaPoint>
				</link>
				<link name="top">
					<viaPoint type="FIXPOINT">-0.012230298460500055 0.04698824236445154 -0.009076662932132643</viaPoint>
				</link>
			</myoMuscle>
			<myoMuscle name="motor4">
				<link name="base">
					<viaPoint type="FIXPOINT">-0.06174078285925048 0.1274060089591329 0.019500000000000114</viaPoint>
					<viaPoint type="FIXPOINT">-0.0200000002980233 0.14400000022351775 0.018300000000000007</viaPoint>
					<viaPoint type="FIXPOINT">-0.016850000000000066 0.12275000000000028 0.023467807133094157</viaPoint>
					<viaPoint type="FIXPOINT">-0.01600000023841871 0.11800000175833728 0.05000000000000001</viaPoint>
					<viaPoint type="FIXPOINT">-0.01600000000000008 0.11500000000000023 0.07500003504716107</viaPoint>
				</link>
				<link name="top">
					<viaPoint type="FIXPOINT">-0.012230298460500055 0.046988242364451545 -0.014076662932132642</viaPoint>
				</link>
			</myoMuscle>
			<myoMuscle name="motor5">
				<link name="base">
					<viaPoint type="FIXPOINT">0.06104023868482074 0.12810655313356237 0.019500000000000385</viaPoint>
					<viaPoint type="FIXPOINT">0.020000000298023145 0.1440000002235177 0.01969999999999998</viaPoint>
					<viaPoint type="FIXPOINT">0.015299999999999843 0.1227500000000003 0.02346780713309415</viaPoint>
					<viaPoint type="FIXPOINT">0.016230317250748687 0.11805899530950162 0.05</viaPoint>
					<viaPoint type="FIXPOINT">0.014599999999999955 0.11500000000000032 0.2370000350471611</viaPoint>
				</link>
				<link name="top">
					<viaPoint type="FIXPOINT">-0.032583741903343545 0.03609119935275095 -0.009076662932132678</viaPoint>
				</link>
			</myoMuscle>
			<myoMuscle name="motor6">
				<link name="base">
					<viaPoint type="FIXPOINT">0.1274060089591327 0.06174078285925043 0.019500000000000114</viaPoint>
					<viaPoint type="FIXPOINT">0.14400000022351758 0.020000000298023245 0.018300000000000007</viaPoint>
					<viaPoint type="FIXPOINT">0.1227500000000001 0.015450000000000009 0.023467807133094157</viaPoint>
					<viaPoint type="FIXPOINT">0.1180000017583371 0.016000000238418657 0.05000000000000001</viaPoint>
					<viaPoint type="FIXPOINT">0.11500000000000006 0.014600000000000026 0.07500003504716107</viaPoint>
				</link>
				<link name="top">
					<viaPoint type="FIXPOINT">0.04680443415980443 0.012068329070613644 -0.014076662932132679</viaPoint>
				</link>
			</myoMuscle>
			<myoMuscle name="motor7">
				<link name="base">
					<viaPoint type="FIXPOINT">0.12810655313356217 -0.06104023868482083 0.019500000000000385</viaPoint>
					<viaPoint type="FIXPOINT">0.14400000022351753 -0.020000000298023197 0.018299999999999983</viaPoint>
					<viaPoint type="FIXPOINT">0.12275000000000014 -0.015299999999999897 0.02346780713309415</viaPoint>
					<viaPoint type="FIXPOINT">0.11805899530950145 -0.016230317250748742 0.05</viaPoint>
					<viaPoint type="FIXPOINT">0.11500000000000016 -0.01600000000000001 0.2370000350471611</viaPoint>
				</link>
				<link name="top">
					<viaPoint type="FIXPOINT">0.011884520865966537 -0.04696640354969084 -0.009076662932132714</viaPoint>
				</link>
			</myoMuscle>
		</plugin>
	</model>
</sdf>
