<?xml version="1.0" ?>
<robot name="msj_platform">
  <joint name="sphere_axis0" type="revolute">
    <parent link="base"/>
    <child link="sphere_link1"/>
    <origin rpy="0 0 0" xyz="0.00757 -0.006    0.108"/>
    <axis xyz="1 0 0"/>
    <limit effort="0.0" lower="-3.14159265359" upper="3.14159265359" velocity="0.0"/>
  </joint>
  <joint name="sphere_axis2" type="revolute">
    <parent link="sphere_link2"/>
    <child link="top"/>
    <origin rpy="0 0 0" xyz="0 0 0"/>
    <axis xyz="0 0 1"/>
    <limit effort="0.0" lower="-3.14159265359" upper="3.14159265359" velocity="0.0"/>
  </joint>
  <joint name="sphere_axis1" type="revolute">
    <parent link="sphere_link1"/>
    <child link="sphere_link2"/>
    <origin rpy="0 0 0" xyz="0 0 0"/>
    <axis xyz="0 -1  0"/>
    <limit effort="0.0" lower="-3.14159265359" upper="3.14159265359" velocity="0.0"/>
  </joint>
  <link name="base">
    <inertial>
      <mass value="4.787830008043328"/>
      <origin rpy="0 0 0" xyz="0 0 0"/>
      <inertia ixx="0.059725352730152184" ixy="-0.00012363610369375952" ixz="0.0003620560331229921" iyy="0.05970927541564337" iyz="0.0001365062619005527" izz="0.06052438459760994"/>
    </inertial>
    <collision name="base_collision">
      <origin rpy="0 0 0" xyz="0 0 0"/>
      <geometry>
        <mesh filename="package://robots/msj_platform/meshes/CAD/base.stl" scale="0.001 0.001 0.001"/>
      </geometry>
    </collision>
    <visual name="base_visual">
      <origin rpy="0 0 0" xyz="0 0 0"/>
      <geometry>
        <mesh filename="package://robots/msj_platform/meshes/CAD/base.stl" scale="0.001 0.001 0.001"/>
      </geometry>
    </visual>
  </link>
  <link name="top">
    <inertial>
      <mass value="0.34662562132958163"/>
      <origin rpy="0 0 0" xyz="0      0      0.05557"/>
      <inertia ixx="0.00887380200495079" ixy="1.574676768628226e-05" ixz="0.00032821023304260155" iyy="0.008881194143478306" iyz="-0.0004141698012586527" izz="0.000415840735681214"/>
    </inertial>
    <collision name="top_collision">
      <origin rpy="0 0 0" xyz="0      0      0.05557"/>
      <geometry>
        <mesh filename="package://robots/msj_platform/meshes/CAD/top.stl" scale="0.001 0.001 0.001"/>
      </geometry>
    </collision>
    <visual name="top_visual">
      <origin rpy="0 0 0" xyz="0      0      0.05557"/>
      <geometry>
        <mesh filename="package://robots/msj_platform/meshes/CAD/top.stl" scale="0.001 0.001 0.001"/>
      </geometry>
    </visual>
  </link>
  <link name="sphere_link1">
    <inertial>
      <mass value="0.06979038134801685"/>
      <origin rpy="0 0 0" xyz="0 0 0"/>
      <inertia ixx="0.000828194739444481" ixy="3.1704773240956278e-06" ixz="4.52241671135149e-05" iyy="0.0008296831261487397" iyz="-5.706859183372124e-05" izz="1.81605718339997e-05"/>
    </inertial>
    <collision name="sphere_link1_collision">
      <origin rpy="0 0 0" xyz="0 0 0"/>
      <geometry>
        <mesh filename="package://robots/msj_platform/meshes/CAD/sphere_link1.stl" scale="0.001 0.001 0.001"/>
      </geometry>
    </collision>
    <visual name="sphere_link1_visual">
      <origin rpy="0 0 0" xyz="0 0 0"/>
      <geometry>
        <mesh filename="package://robots/msj_platform/meshes/CAD/sphere_link1.stl" scale="0.001 0.001 0.001"/>
      </geometry>
    </visual>
  </link>
  <link name="sphere_link2">
    <inertial>
      <mass value="0.04678255760927329"/>
      <origin rpy="0 0 0" xyz="0 0 0"/>
      <inertia ixx="0.0005526173565767919" ixy="2.1252647820964374e-06" ixz="3.03150976586011e-05" iyy="0.0005536150662576664" iyz="-3.825476564718879e-05" izz="9.627487289655988e-06"/>
    </inertial>
    <collision name="sphere_link2_collision">
      <origin rpy="0 0 0" xyz="0 0 0"/>
      <geometry>
        <mesh filename="package://robots/msj_platform/meshes/CAD/sphere_link2.stl" scale="0.001 0.001 0.001"/>
      </geometry>
    </collision>
    <visual name="sphere_link2_visual">
      <origin rpy="0 0 0" xyz="0 0 0"/>
      <geometry>
        <mesh filename="package://robots/msj_platform/meshes/CAD/sphere_link2.stl" scale="0.001 0.001 0.001"/>
      </geometry>
    </visual>
  </link>
</robot>
