<?xml version="1.0" ?>
<sdf version="1.6">
	<model name="msj_platform">
		<link name="base">
			<self_collide>false</self_collide>
			<pose frame="">0.0 0.0 0.0 0.0 -0.0 0.0</pose>
			<inertial>
				<pose frame="">0.0 0.0 0.0 0 0 0</pose>
				<mass>4.65338916050554</mass>
				<inertia>
					<ixx>0.044199135035504954</ixx>
					<ixy>0.000109866384138346</ixy>
					<ixz>-0.00018795822523209353</ixz>
					<iyy>0.04422736485497324</iyy>
					<iyz>0.00028934733318711507</iyz>
					<izz>0.060432720857576436</izz>
				</inertia>
			</inertial>
			<collision name="base_collision">
				<geometry>
					<mesh>
						<uri>model://msj_platform/meshes/CAD/base.stl</uri>
						<scale>0.001 0.001 0.001</scale>
					</mesh>
				</geometry>
			</collision>
			<visual name="base_visual">
				<geometry>
					<mesh>
						<uri>model://msj_platform/meshes/CAD/base.stl</uri>
						<scale>0.001 0.001 0.001</scale>
					</mesh>
				</geometry>
			</visual>
		</link>
		<link name="top">
			<self_collide>false</self_collide>
			<pose frame="">-0.005871036493208736 -0.007892561503801526 0.1725766629321328 0.0 -0.0 0.0</pose>
			<inertial>
				<pose frame="">0.0 0.0 0.0 0 0 0</pose>
				<mass>1.4259339831467317</mass>
				<inertia>
					<ixx>0.04354077944871786</ixx>
					<ixy>-6.877184425058423e-05</ixy>
					<ixz>0.0019413546516229077</ixz>
					<iyy>0.04349755958240726</iyy>
					<iyz>0.0014370255220575643</iyz>
					<izz>0.0015565759249338191</izz>
				</inertia>
			</inertial>
			<collision name="top_collision">
				<geometry>
					<mesh>
						<uri>model://msj_platform/meshes/CAD/top.stl</uri>
						<scale>0.001 0.001 0.001</scale>
					</mesh>
				</geometry>
			</collision>
			<visual name="top_visual">
				<geometry>
					<mesh>
						<uri>model://msj_platform/meshes/CAD/top.stl</uri>
						<scale>0.001 0.001 0.001</scale>
					</mesh>
				</geometry>
			</visual>
		</link>
		<link name="top">
			<self_collide>false</self_collide>
			<pose frame="">-0.005871036493208736 -0.007892561503801526 0.1725766629321328 0.0 -0.0 0.0</pose>
			<inertial>
				<pose frame="">0.0 0.0 0.0 0 0 0</pose>
				<mass>1.4259339831467317</mass>
				<inertia>
					<ixx>0.04354077944871786</ixx>
					<ixy>-6.877184425058423e-05</ixy>
					<ixz>0.0019413546516229077</ixz>
					<iyy>0.04349755958240726</iyy>
					<iyz>0.0014370255220575643</iyz>
					<izz>0.0015565759249338191</izz>
				</inertia>
			</inertial>
			<collision name="top_collision">
				<geometry>
					<mesh>
						<uri>model://msj_platform/meshes/CAD/top.stl</uri>
						<scale>0.001 0.001 0.001</scale>
					</mesh>
				</geometry>
			</collision>
			<visual name="top_visual">
				<geometry>
					<mesh>
						<uri>model://msj_platform/meshes/CAD/top.stl</uri>
						<scale>0.001 0.001 0.001</scale>
					</mesh>
				</geometry>
			</visual>
		</link>
		<link name="sphere_link1">
			<self_collide>false</self_collide>
			<pose frame="">-0.0060000000000000045 -0.007999999999999993 0.10999999999999999 0.0 -0.0 0.0</pose>
			<inertial>
				<pose frame="">0.0 0.0 0.0 0 0 0</pose>
				<mass>0.04675410312962845</mass>
				<inertia>
					<ixx>0.0005746909032619158</ixx>
					<ixy>-2.2441969502221693e-06</ixy>
					<ixz>4.1143610754073024e-05</ixz>
					<iyy>0.0005733817883742863</iyy>
					<iyz>3.085770806555482e-05</iyz>
					<izz>1.064940310607797e-05</izz>
				</inertia>
			</inertial>
			<collision name="sphere_link1_collision">
				<geometry>
					<mesh>
						<uri>model://msj_platform/meshes/CAD/sphere_link1.stl</uri>
						<scale>0.001 0.001 0.001</scale>
					</mesh>
				</geometry>
			</collision>
			<visual name="sphere_link1_visual">
				<geometry>
					<mesh>
						<uri>model://msj_platform/meshes/CAD/sphere_link1.stl</uri>
						<scale>0.001 0.001 0.001</scale>
					</mesh>
				</geometry>
			</visual>
		</link>
		<link name="shere_link2">
			<self_collide>false</self_collide>
			<pose frame="">-0.005999999999999988 -0.00800000005467301 0.10999999992054188 0.0 -0.0 0.0</pose>
			<inertial>
				<pose frame="">0.0 0.0 0.0 0 0 0</pose>
				<mass>0.03134065871089989</mass>
				<inertia>
					<ixx>0.0003839264082594096</ixx>
					<ixy>-1.504351628404124e-06</ixy>
					<ixz>2.7579779853430193e-05</ixz>
					<iyy>0.00038304886982346855</iyy>
					<iyz>2.068483473425228e-05</iyz>
					<izz>5.832702133790424e-06</izz>
				</inertia>
			</inertial>
			<collision name="shere_link2_collision">
				<geometry>
					<mesh>
						<uri>model://msj_platform/meshes/CAD/shere_link2.stl</uri>
						<scale>0.001 0.001 0.001</scale>
					</mesh>
				</geometry>
			</collision>
			<visual name="shere_link2_visual">
				<geometry>
					<mesh>
						<uri>model://msj_platform/meshes/CAD/shere_link2.stl</uri>
						<scale>0.001 0.001 0.001</scale>
					</mesh>
				</geometry>
			</visual>
		</link>
		<joint name="sphere_axis2" type="revolute">
			<parent>shere_link2</parent>
			<child>top</child>
			<pose frame="">-0.005999999999999997 -0.008 0.11 0 0 0</pose>
			<axis>
				<xyz>0.0 0.0 1.0</xyz>
				<limit>
					<lower>-3.141592653589793</lower>
					<upper>3.141592653589793</upper>
				</limit>
				<use_parent_model_frame>0</use_parent_model_frame>
			</axis>
		</joint>
		<joint name="sphere_axis1" type="revolute">
			<parent>sphere_link1</parent>
			<child>shere_link2</child>
			<pose frame="">-1.3322676295501878e-17 5.467300834283151e-11 7.945812896537064e-11 0 0 0</pose>
			<axis>
				<xyz>0.0 -1.0 0.0</xyz>
				<limit>
					<lower>-3.141592653589793</lower>
					<upper>3.141592653589793</upper>
				</limit>
				<use_parent_model_frame>0</use_parent_model_frame>
			</axis>
		</joint>
		<plugin filename="libmusc_plugin.so" name="musc_plugin">
			<myoMuscle name="motor0">
				<link name="base">
					<viaPoint type="FIXPOINT">0.05539662834999366 -0.1303643367913177 0.01950000000000014</viaPoint>
					<viaPoint type="FIXPOINT">0.02000000029802305 -0.14400000022351767 0.019700000000000002</viaPoint>
					<viaPoint type="FIXPOINT">0.01684999999999982 -0.12275000000000016 0.023467807133094157</viaPoint>
					<viaPoint type="FIXPOINT">0.016000000238418466 -0.11800000175833716 0.05000000000000001</viaPoint>
					<viaPoint type="FIXPOINT">0.015999999999999834 -0.11500000000000013 0.07500003504716107</viaPoint>
				</link>
				<link name="top">
					<viaPoint type="FIXPOINT">0.006013484372757801 -0.05485896505349236 0.15850000000000009</viaPoint>
				</link>
			</myoMuscle>
			<myoMuscle name="motor1">
				<link name="base">
					<viaPoint type="FIXPOINT">-0.06104023868482099 -0.12810655313356226 0.019500000000000385</viaPoint>
					<viaPoint type="FIXPOINT">-0.020000000298023388 -0.14400000022351758 0.018299999999999983</viaPoint>
					<viaPoint type="FIXPOINT">-0.01670000000000009 -0.1227500000000002 0.02346780713309415</viaPoint>
					<viaPoint type="FIXPOINT">-0.01623031725074893 -0.11805899530950152 0.05</viaPoint>
					<viaPoint type="FIXPOINT">-0.0160000000000002 -0.11500000000000023 0.2370000350471611</viaPoint>
				</link>
				<link name="top">
					<viaPoint type="FIXPOINT">-0.053021248247546685 -0.019939051759654488 0.16350000000000012</viaPoint>
				</link>
			</myoMuscle>
			<myoMuscle name="motor2">
				<link name="base">
					<viaPoint type="FIXPOINT">-0.12740600895913295 -0.061740782859250304 0.019500000000000114</viaPoint>
					<viaPoint type="FIXPOINT">-0.14400000022351783 -0.02000000029802312 0.019700000000000002</viaPoint>
					<viaPoint type="FIXPOINT">-0.12275000000000034 -0.01544999999999989 0.023467807133094157</viaPoint>
					<viaPoint type="FIXPOINT">-0.11800000175833734 -0.01600000023841854 0.05000000000000001</viaPoint>
					<viaPoint type="FIXPOINT">-0.11500000000000031 -0.015999999999999903 0.07500003504716107</viaPoint>
				</link>
				<link name="top">
					<viaPoint type="FIXPOINT">-0.053021248247546685 -0.019939051759654484 0.1585000000000001</viaPoint>
				</link>
			</myoMuscle>
			<myoMuscle name="motor3">
				<link name="base">
					<viaPoint type="FIXPOINT">-0.12810655313356242 0.06104023868482091 0.019500000000000385</viaPoint>
					<viaPoint type="FIXPOINT">-0.14400000022351775 0.02000000029802332 0.017799999999999986</viaPoint>
					<viaPoint type="FIXPOINT">-0.12275000000000037 0.01670000000000002 0.02346780713309415</viaPoint>
					<viaPoint type="FIXPOINT">-0.1180589953095017 0.016230317250748864 0.05</viaPoint>
					<viaPoint type="FIXPOINT">-0.1150000000000004 0.01460000000000013 0.2370000350471611</viaPoint>
				</link>
				<link name="top">
					<viaPoint type="FIXPOINT">-0.01810133495370879 0.03909568086065001 0.16350000000000017</viaPoint>
				</link>
			</myoMuscle>
			<myoMuscle name="motor4">
				<link name="base">
					<viaPoint type="FIXPOINT">-0.06174078285925048 0.1274060089591329 0.019500000000000114</viaPoint>
					<viaPoint type="FIXPOINT">-0.0200000002980233 0.14400000022351775 0.018300000000000007</viaPoint>
					<viaPoint type="FIXPOINT">-0.016850000000000066 0.12275000000000028 0.023467807133094157</viaPoint>
					<viaPoint type="FIXPOINT">-0.01600000023841871 0.11800000175833728 0.05000000000000001</viaPoint>
					<viaPoint type="FIXPOINT">-0.01600000000000008 0.11500000000000023 0.07500003504716107</viaPoint>
				</link>
				<link name="top">
					<viaPoint type="FIXPOINT">-0.01810133495370879 0.03909568086065002 0.15850000000000017</viaPoint>
				</link>
			</myoMuscle>
			<myoMuscle name="motor5">
				<link name="base">
					<viaPoint type="FIXPOINT">0.06104023868482074 0.12810655313356237 0.019500000000000385</viaPoint>
					<viaPoint type="FIXPOINT">0.020000000298023145 0.1440000002235177 0.01969999999999998</viaPoint>
					<viaPoint type="FIXPOINT">0.015299999999999843 0.1227500000000003 0.02346780713309415</viaPoint>
					<viaPoint type="FIXPOINT">0.016230317250748687 0.11805899530950162 0.05</viaPoint>
					<viaPoint type="FIXPOINT">0.014599999999999955 0.11500000000000032 0.2370000350471611</viaPoint>
				</link>
				<link name="top">
					<viaPoint type="FIXPOINT">-0.03845477839655228 0.028198637848949423 0.16350000000000012</viaPoint>
				</link>
			</myoMuscle>
			<myoMuscle name="motor6">
				<link name="base">
					<viaPoint type="FIXPOINT">0.1274060089591327 0.06174078285925043 0.019500000000000114</viaPoint>
					<viaPoint type="FIXPOINT">0.14400000022351758 0.020000000298023245 0.018300000000000007</viaPoint>
					<viaPoint type="FIXPOINT">0.1227500000000001 0.015450000000000009 0.023467807133094157</viaPoint>
					<viaPoint type="FIXPOINT">0.1180000017583371 0.016000000238418657 0.05000000000000001</viaPoint>
					<viaPoint type="FIXPOINT">0.11500000000000006 0.014600000000000026 0.07500003504716107</viaPoint>
				</link>
				<link name="top">
					<viaPoint type="FIXPOINT">0.0409333976665957 0.004175767566812115 0.1585000000000001</viaPoint>
				</link>
			</myoMuscle>
			<myoMuscle name="motor7">
				<link name="base">
					<viaPoint type="FIXPOINT">0.12810655313356217 -0.06104023868482083 0.019500000000000385</viaPoint>
					<viaPoint type="FIXPOINT">0.14400000022351753 -0.020000000298023197 0.018299999999999983</viaPoint>
					<viaPoint type="FIXPOINT">0.12275000000000014 -0.015299999999999897 0.02346780713309415</viaPoint>
					<viaPoint type="FIXPOINT">0.11805899530950145 -0.016230317250748742 0.05</viaPoint>
					<viaPoint type="FIXPOINT">0.11500000000000016 -0.01600000000000001 0.2370000350471611</viaPoint>
				</link>
				<link name="top">
					<viaPoint type="FIXPOINT">0.006013484372757801 -0.054858965053492366 0.1635000000000001</viaPoint>
				</link>
			</myoMuscle>
		</plugin>
	</model>
</sdf>
