<robot name="msj_platform">
  <joint name="sphere_axis0" type="revolute">
    <parent link="base" />
    <child link="sphere_link1" />
    <origin rpy="0 0 0" xyz="0.00097 0.0022  0.101" />
    <axis xyz="1 0 0" />
    <limit effort="0.0" lower="-3.14159265359" upper="3.14159265359" velocity="0.0" />
  </joint>
  <joint name="sphere_axis2" type="revolute">
    <parent link="sphere_link2" />
    <child link="top" />
    <origin rpy="0 0 0" xyz="0 0 0" />
    <axis xyz="0 0 1" />
    <limit effort="0.0" lower="-3.14159265359" upper="3.14159265359" velocity="0.0" />
  </joint>
  <joint name="sphere_axis1" type="revolute">
    <parent link="sphere_link1" />
    <child link="sphere_link2" />
    <origin rpy="0 0 0" xyz="0 0 0" />
    <axis xyz="0 -1  0" />
    <limit effort="0.0" lower="-3.14159265359" upper="3.14159265359" velocity="0.0" />
  </joint>
  <link name="base">
    <inertial>
      <mass value="14.618542676185154" />
      <origin rpy="0 0 0" xyz="-0.00023  0.00049  0.0294" />
      <inertia ixx="0.18108194334607391" ixy="9.641806370071291e-05" ixz="-0.0004347853751398022" iyy="0.1809689893100023" iyz="0.000191147663980453" izz="0.2881289835539741" />
    </inertial>
    <collision name="base_collision">
      <origin rpy="0 0 0" xyz="-0.00023  0.00049  0.0294" />
      <geometry>
        <mesh filename="package://robots/msj_platform/meshes/collisions/base.stl" scale="0.001 0.001 0.001" />
      </geometry>
    </collision>
    <visual name="base_visual">
      <origin rpy="0 0 0" xyz="-0.00023  0.00049  0.0294" />
      <geometry>
        <mesh filename="package://robots/msj_platform/meshes/visuals/base.stl" scale="0.001 0.001 0.001" />
      </geometry>
    </visual>
  </link>
  <link name="top">
    <inertial>
      <mass value="0.10109351801613384" />
      <origin rpy="0 0 0" xyz="0      0      0.04935" />
      <inertia ixx="0.002347107809378347" ixy="-2.154262353122067e-07" ixz="-3.3435251316251536e-05" iyy="0.0023467129563446896" iyz="-1.4759883129495016e-05" izz="4.1794852712685354e-05" />
    </inertial>
    <collision name="top_collision">
      <origin rpy="0 0 0" xyz="0      0      0.04935" />
      <geometry>
        <mesh filename="package://robots/msj_platform/meshes/collisions/top.stl" scale="0.001 0.001 0.001" />
      </geometry>
    </collision>
    <visual name="top_visual">
      <origin rpy="0 0 0" xyz="0      0      0.04935" />
      <geometry>
        <mesh filename="package://robots/msj_platform/meshes/visuals/top.stl" scale="0.001 0.001 0.001" />
      </geometry>
    </visual>
  </link>
  <link name="sphere_link1">
    <inertial>
      <mass value="0.06979038134801682" />
      <origin rpy="0 0 0" xyz="0 0 0" />
      <inertia ixx="0.0007239167432495283" ixy="-1.491520149951873e-07" ixz="-1.5507422735529385e-05" iyy="0.0007236448171351005" iyz="-6.847433415688365e-06" izz="1.2050922449704735e-05" />
    </inertial>
    <collision name="sphere_link1_collision">
      <origin rpy="0 0 0" xyz="0 0 0" />
      <geometry>
        <mesh filename="package://robots/msj_platform/meshes/collisions/sphere_link1.stl" scale="0.001 0.001 0.001" />
      </geometry>
    </collision>
    <visual name="sphere_link1_visual">
      <origin rpy="0 0 0" xyz="0 0 0" />
      <geometry>
        <mesh filename="package://robots/msj_platform/meshes/visuals/sphere_link1.stl" scale="0.001 0.001 0.001" />
      </geometry>
    </visual>
  </link>
  <link name="sphere_link2">
    <inertial>
      <mass value="0.046782557609273294" />
      <origin rpy="0 0 0" xyz="0 0 0" />
      <inertia ixx="0.0004827167303108567" ixy="-9.99810059939195e-08" ixz="-1.0395083958614549e-05" iyy="0.00048253445027231456" iyz="-4.590037219594454e-06" izz="5.532008484150464e-06" />
    </inertial>
    <collision name="sphere_link2_collision">
      <origin rpy="0 0 0" xyz="0 0 0" />
      <geometry>
        <mesh filename="package://robots/msj_platform/meshes/collisions/sphere_link2.stl" scale="0.001 0.001 0.001" />
      </geometry>
    </collision>
    <visual name="sphere_link2_visual">
      <origin rpy="0 0 0" xyz="0 0 0" />
      <geometry>
        <mesh filename="package://robots/msj_platform/meshes/visuals/sphere_link2.stl" scale="0.001 0.001 0.001" />
      </geometry>
    </visual>
  </link>
</robot>