<sdf version='1.6'>
  <world name='default'>
    <light name='sun' type='directional'>
      <cast_shadows>1</cast_shadows>
      <pose frame=''>0 0 10 0 -0 0</pose>
      <diffuse>0.8 0.8 0.8 1</diffuse>
      <specular>0.2 0.2 0.2 1</specular>
      <attenuation>
        <range>1000</range>
        <constant>0.9</constant>
        <linear>0.01</linear>
        <quadratic>0.001</quadratic>
      </attenuation>
      <direction>-0.5 0.1 -0.9</direction>
    </light>
    <model name='ground_plane'>
      <static>1</static>
      <link name='link'>
        <collision name='collision'>
          <geometry>
            <plane>
              <normal>0 0 1</normal>
              <size>100 100</size>
            </plane>
          </geometry>
          <surface>
            <contact>
              <collide_bitmask>65535</collide_bitmask>
              <ode/>
            </contact>
            <friction>
              <ode>
                <mu>100</mu>
                <mu2>50</mu2>
              </ode>
              <torsional>
                <ode/>
              </torsional>
            </friction>
            <bounce/>
          </surface>
          <max_contacts>10</max_contacts>
        </collision>
        <visual name='visual'>
          <cast_shadows>0</cast_shadows>
          <geometry>
            <plane>
              <normal>0 0 1</normal>
              <size>100 100</size>
            </plane>
          </geometry>
          <material>
            <script>
              <uri>file://media/materials/scripts/gazebo.material</uri>
              <name>Gazebo/Grey</name>
            </script>
          </material>
        </visual>
        <self_collide>0</self_collide>
        <enable_wind>0</enable_wind>
        <kinematic>0</kinematic>
      </link>
    </model>
    <gravity>0 0 -9.81</gravity>
    <magnetic_field>6e-06 2.3e-05 -4.2e-05</magnetic_field>
    <atmosphere type='adiabatic'/>
    <physics name='default_physics' default='0' type='ode'>
      <max_step_size>0.001</max_step_size>
      <real_time_factor>1</real_time_factor>
      <real_time_update_rate>1000</real_time_update_rate>
    </physics>
    <scene>
      <ambient>0.4 0.4 0.4 1</ambient>
      <background>0.7 0.7 0.7 1</background>
      <shadows>1</shadows>
    </scene>
    <audio>
      <device>default</device>
    </audio>
    <wind/>
    <spherical_coordinates>
      <surface_model>EARTH_WGS84</surface_model>
      <latitude_deg>0</latitude_deg>
      <longitude_deg>0</longitude_deg>
      <elevation>0</elevation>
      <heading_deg>0</heading_deg>
    </spherical_coordinates>
    <model name='biking_legs'>
      <link name='bike'>
        <self_collide>0</self_collide>
        <pose frame=''>-0 0 0 0 -0 0</pose>
        <inertial>
          <pose frame=''>0 0 0 0 -0 0</pose>
          <mass>21.8195</mass>
          <inertia>
            <ixx>7.74875</ixx>
            <ixy>0.0634634</ixy>
            <ixz>-3.10839</ixz>
            <iyy>11.3423</iyy>
            <iyz>0.17003</iyz>
            <izz>4.19727</izz>
          </inertia>
        </inertial>
        <collision name='bike_collision'>
          <geometry>
            <mesh>
              <uri>model://biking_legs/meshes/collisions/bike.stl</uri>
              <scale>0.001 0.001 0.001</scale>
            </mesh>
          </geometry>
          <max_contacts>10</max_contacts>
          <surface>
            <contact>
              <ode/>
            </contact>
            <bounce/>
            <friction>
              <torsional>
                <ode/>
              </torsional>
              <ode/>
            </friction>
          </surface>
        </collision>
        <visual name='bike_visual'>
          <geometry>
            <mesh>
              <uri>model://biking_legs/meshes/CAD/bike.stl</uri>
              <scale>0.001 0.001 0.001</scale>
            </mesh>
          </geometry>
        </visual>
        <enable_wind>0</enable_wind>
        <kinematic>0</kinematic>
      </link>
      <link name='front_part'>
        <self_collide>0</self_collide>
        <pose frame=''>-0.71639 0.010389 0.216438 0 -0 0</pose>
        <inertial>
          <pose frame=''>0 0 0 0 -0 0</pose>
          <mass>16.8107</mass>
          <inertia>
            <ixx>3.20923</ixx>
            <ixy>0.181136</ixy>
            <ixz>1.24197</ixz>
            <iyy>14.663</iyy>
            <iyz>-0.00672308</iyz>
            <izz>13.9129</izz>
          </inertia>
        </inertial>
        <collision name='front_part_collision'>
          <geometry>
            <mesh>
              <uri>model://biking_legs/meshes/collisions/front_part.stl</uri>
              <scale>0.001 0.001 0.001</scale>
            </mesh>
          </geometry>
          <max_contacts>10</max_contacts>
          <surface>
            <contact>
              <ode/>
            </contact>
            <bounce/>
            <friction>
              <torsional>
                <ode/>
              </torsional>
              <ode/>
            </friction>
          </surface>
        </collision>
        <visual name='front_part_visual'>
          <geometry>
            <mesh>
              <uri>model://biking_legs/meshes/CAD/front_part.stl</uri>
              <scale>0.001 0.001 0.001</scale>
            </mesh>
          </geometry>
        </visual>
        <enable_wind>0</enable_wind>
        <kinematic>0</kinematic>
      </link>
      <link name='left_wheel'>
        <self_collide>0</self_collide>
        <pose frame=''>-0.998426 -0.35 0.045667 0 -0 0</pose>
        <inertial>
          <pose frame=''>0 0 0 0 -0 0</pose>
          <mass>13.3402</mass>
          <inertia>
            <ixx>2.17117</ixx>
            <ixy>-4.66171</ixy>
            <ixz>0.608246</ixz>
            <iyy>14.3423</iyy>
            <iyz>0.213222</iyz>
            <izz>15.4415</izz>
          </inertia>
        </inertial>
        <collision name='left_wheel_collision'>
          <geometry>
            <mesh>
              <uri>model://biking_legs/meshes/CAD/left_wheel.stl</uri>
              <scale>0.001 0.001 0.001</scale>
            </mesh>
          </geometry>
          <surface>
            <contact>
              <ode/>
            </contact>
            <bounce/>
            <friction>
              <torsional>
                <ode/>
              </torsional>
              <ode/>
            </friction>
          </surface>
          <max_contacts>10</max_contacts>
        </collision>
        <visual name='left_wheel_visual'>
          <geometry>
            <mesh>
              <uri>model://biking_legs/meshes/CAD/left_wheel.stl</uri>
              <scale>0.001 0.001 0.001</scale>
            </mesh>
          </geometry>
        </visual>
        <enable_wind>0</enable_wind>
        <kinematic>0</kinematic>
      </link>
      <link name='right_wheel'>
        <self_collide>0</self_collide>
        <pose frame=''>-0.998426 0.342 0.045667 0 -0 0</pose>
        <inertial>
          <pose frame=''>0 0 0 0 -0 0</pose>
          <mass>13.3402</mass>
          <inertia>
            <ixx>2.09732</ixx>
            <ixy>4.55516</ixy>
            <ixz>0.608246</ixz>
            <iyy>14.3423</iyy>
            <iyz>-0.208348</iyz>
            <izz>15.3677</izz>
          </inertia>
        </inertial>
        <collision name='right_wheel_collision'>
          <geometry>
            <mesh>
              <uri>model://biking_legs/meshes/CAD/right_wheel.stl</uri>
              <scale>0.001 0.001 0.001</scale>
            </mesh>
          </geometry>
          <max_contacts>10</max_contacts>
          <surface>
            <contact>
              <ode/>
            </contact>
            <bounce/>
            <friction>
              <torsional>
                <ode/>
              </torsional>
              <ode/>
            </friction>
          </surface>
        </collision>
        <visual name='right_wheel_visual'>
          <geometry>
            <mesh>
              <uri>model://biking_legs/meshes/CAD/right_wheel.stl</uri>
              <scale>0.001 0.001 0.001</scale>
            </mesh>
          </geometry>
        </visual>
        <enable_wind>0</enable_wind>
        <kinematic>0</kinematic>
      </link>
      <link name='pedal_right'>
        <self_collide>0</self_collide>
        <pose frame=''>0.077746 0.147989 0.171813 0 -0 0</pose>
        <inertial>
          <pose frame=''>0 0 0 0 -0 0</pose>
          <mass>0.946003</mass>
          <inertia>
            <ixx>0.0493529</ixx>
            <ixy>-0.0108843</ixy>
            <ixz>-0.0127863</ixz>
            <iyy>0.0340586</iyy>
            <iyz>-0.0240535</iyz>
            <izz>0.0272547</izz>
          </inertia>
        </inertial>
        <collision name='pedal_right_collision'>
          <geometry>
            <mesh>
              <uri>model://biking_legs/meshes/CAD/pedal_right.stl</uri>
              <scale>0.001 0.001 0.001</scale>
            </mesh>
          </geometry>
          <max_contacts>10</max_contacts>
          <surface>
            <contact>
              <ode/>
            </contact>
            <bounce/>
            <friction>
              <torsional>
                <ode/>
              </torsional>
              <ode/>
            </friction>
          </surface>
        </collision>
        <visual name='pedal_right_visual'>
          <geometry>
            <mesh>
              <uri>model://biking_legs/meshes/CAD/pedal_right.stl</uri>
              <scale>0.001 0.001 0.001</scale>
            </mesh>
          </geometry>
        </visual>
        <enable_wind>0</enable_wind>
        <kinematic>0</kinematic>
      </link>
      <link name='kurbel'>
        <self_collide>0</self_collide>
        <pose frame=''>0.092229 0.000132 0.004277 0 -0 0</pose>
        <inertial>
          <pose frame=''>0 0 0 0 -0 0</pose>
          <mass>2.78327</mass>
          <inertia>
            <ixx>0.0332153</ixx>
            <ixy>0.00102181</ixy>
            <ixz>0.000301436</ixz>
            <iyy>0.0415869</iyy>
            <iyz>-0.0129372</iyz>
            <izz>0.0397311</izz>
          </inertia>
        </inertial>
        <collision name='kurbel_collision'>
          <geometry>
            <mesh>
              <uri>model://biking_legs/meshes/CAD/kurbel.stl</uri>
              <scale>0.001 0.001 0.001</scale>
            </mesh>
          </geometry>
          <max_contacts>10</max_contacts>
          <surface>
            <contact>
              <ode/>
            </contact>
            <bounce/>
            <friction>
              <torsional>
                <ode/>
              </torsional>
              <ode/>
            </friction>
          </surface>
        </collision>
        <visual name='kurbel_visual'>
          <geometry>
            <mesh>
              <uri>model://biking_legs/meshes/CAD/kurbel.stl</uri>
              <scale>0.001 0.001 0.001</scale>
            </mesh>
          </geometry>
        </visual>
        <enable_wind>0</enable_wind>
        <kinematic>0</kinematic>
      </link>
      <link name='pedal_left'>
        <self_collide>0</self_collide>
        <pose frame=''>0.107358 -0.149245 -0.165248 0 -0 0</pose>
        <inertial>
          <pose frame=''>0 0 0 0 -0 0</pose>
          <mass>0.946003</mass>
          <inertia>
            <ixx>0.0475877</ixx>
            <ixy>0.0151574</ixy>
            <ixz>0.0166445</ixz>
            <iyy>0.0371506</iyy>
            <iyz>-0.0233307</iyz>
            <izz>0.0328179</izz>
          </inertia>
        </inertial>
        <collision name='pedal_left_collision'>
          <geometry>
            <mesh>
              <uri>model://biking_legs/meshes/CAD/pedal_left.stl</uri>
              <scale>0.001 0.001 0.001</scale>
            </mesh>
          </geometry>
          <max_contacts>10</max_contacts>
          <surface>
            <contact>
              <ode/>
            </contact>
            <bounce/>
            <friction>
              <torsional>
                <ode/>
              </torsional>
              <ode/>
            </friction>
          </surface>
        </collision>
        <visual name='pedal_left_visual'>
          <geometry>
            <mesh>
              <uri>model://biking_legs/meshes/CAD/pedal_left.stl</uri>
              <scale>0.001 0.001 0.001</scale>
            </mesh>
          </geometry>
        </visual>
        <enable_wind>0</enable_wind>
        <kinematic>0</kinematic>
      </link>
      <link name='foot_left'>
        <self_collide>0</self_collide>
        <pose frame=''>0.189767 -0.185435 -0.082866 0 -0 0</pose>
        <inertial>
          <pose frame=''>0 0 0 0 -0 0</pose>
          <mass>0.729404</mass>
          <inertia>
            <ixx>0.0306577</ixx>
            <ixy>0.0256701</ixy>
            <ixz>0.0114065</ixz>
            <iyy>0.0319233</iyy>
            <iyz>-0.0112088</iyz>
            <izz>0.0519604</izz>
          </inertia>
        </inertial>
        <collision name='foot_left_collision'>
          <geometry>
            <mesh>
              <uri>model://biking_legs/meshes/collisions/foot_left.stl</uri>
              <scale>0.001 0.001 0.001</scale>
            </mesh>
          </geometry>
          <max_contacts>10</max_contacts>
          <surface>
            <contact>
              <ode/>
            </contact>
            <bounce/>
            <friction>
              <torsional>
                <ode/>
              </torsional>
              <ode/>
            </friction>
          </surface>
        </collision>
        <visual name='foot_left_visual'>
          <geometry>
            <mesh>
              <uri>model://biking_legs/meshes/visuals/foot_left.stl</uri>
              <scale>0.001 0.001 0.001</scale>
            </mesh>
          </geometry>
        </visual>
        <enable_wind>0</enable_wind>
        <kinematic>0</kinematic>
      </link>
      <link name='foot_left_tip'>
        <self_collide>0</self_collide>
        <pose frame=''>0.108261 -0.18435 -0.145518 0 -0 0</pose>
        <inertial>
          <pose frame=''>0 0 0 0 -0 0</pose>
          <mass>0.277946</mass>
          <inertia>
            <ixx>0.0154469</ixx>
            <ixy>0.00555427</ixy>
            <ixz>0.00432897</ixz>
            <iyy>0.00925802</iyy>
            <iyz>-0.00745169</iyz>
            <izz>0.0128642</izz>
          </inertia>
        </inertial>
        <collision name='foot_left_tip_collision'>
          <geometry>
            <mesh>
              <uri>model://biking_legs/meshes/collisions/foot_left_tip.stl</uri>
              <scale>0.001 0.001 0.001</scale>
            </mesh>
          </geometry>
          <max_contacts>10</max_contacts>
          <surface>
            <contact>
              <ode/>
            </contact>
            <bounce/>
            <friction>
              <torsional>
                <ode/>
              </torsional>
              <ode/>
            </friction>
          </surface>
        </collision>
        <visual name='foot_left_tip_visual'>
          <geometry>
            <mesh>
              <uri>model://biking_legs/meshes/visuals/foot_left_tip.stl</uri>
              <scale>0.001 0.001 0.001</scale>
            </mesh>
          </geometry>
        </visual>
        <enable_wind>0</enable_wind>
        <kinematic>0</kinematic>
      </link>
      <link name='foot_right'>
        <self_collide>0</self_collide>
        <pose frame=''>0.160105 0.16245 0.266247 0 -0 0</pose>
        <inertial>
          <pose frame=''>0 0 0 0 -0 0</pose>
          <mass>0.729388</mass>
          <inertia>
            <ixx>0.0715324</ixx>
            <ixy>-0.0189714</ixy>
            <ixz>-0.031158</ixz>
            <iyy>0.0710483</iyy>
            <iyz>-0.031546</iyz>
            <izz>0.0385452</izz>
          </inertia>
        </inertial>
        <collision name='foot_right_collision'>
          <geometry>
            <mesh>
              <uri>model://biking_legs/meshes/collisions/foot_right.stl</uri>
              <scale>0.001 0.001 0.001</scale>
            </mesh>
          </geometry>
          <max_contacts>10</max_contacts>
          <surface>
            <contact>
              <ode/>
            </contact>
            <bounce/>
            <friction>
              <torsional>
                <ode/>
              </torsional>
              <ode/>
            </friction>
          </surface>
        </collision>
        <visual name='foot_right_visual'>
          <geometry>
            <mesh>
              <uri>model://biking_legs/meshes/visuals/foot_right.stl</uri>
              <scale>0.001 0.001 0.001</scale>
            </mesh>
          </geometry>
        </visual>
        <enable_wind>0</enable_wind>
        <kinematic>0</kinematic>
      </link>
      <link name='foot_right_tip'>
        <self_collide>0</self_collide>
        <pose frame=''>0.084244 0.161366 0.196675 0 -0 0</pose>
        <inertial>
          <pose frame=''>0 0 0 0 -0 0</pose>
          <mass>0.277961</mass>
          <inertia>
            <ixx>0.0181134</ixx>
            <ixy>-0.0037852</ixy>
            <ixz>-0.00465819</ixz>
            <iyy>0.0128388</iyy>
            <iyz>-0.00882627</iyz>
            <izz>0.00936199</izz>
          </inertia>
        </inertial>
        <collision name='foot_right_tip_collision'>
          <geometry>
            <mesh>
              <uri>model://biking_legs/meshes/collisions/foot_right_tip.stl</uri>
              <scale>0.001 0.001 0.001</scale>
            </mesh>
          </geometry>
          <max_contacts>10</max_contacts>
          <surface>
            <contact>
              <ode/>
            </contact>
            <bounce/>
            <friction>
              <torsional>
                <ode/>
              </torsional>
              <ode/>
            </friction>
          </surface>
        </collision>
        <visual name='foot_right_tip_visual'>
          <geometry>
            <mesh>
              <uri>model://biking_legs/meshes/visuals/foot_right_tip.stl</uri>
              <scale>0.001 0.001 0.001</scale>
            </mesh>
          </geometry>
        </visual>
        <enable_wind>0</enable_wind>
        <kinematic>0</kinematic>
      </link>
      <link name='thigh_right'>
        <self_collide>0</self_collide>
        <pose frame=''>0.152917 0.187234 0.588125 0 -0 0</pose>
        <inertial>
          <pose frame=''>0 0 0 0 -0 0</pose>
          <mass>5.56245</mass>
          <inertia>
            <ixx>2.13116</ixx>
            <ixy>-0.162313</ixy>
            <ixz>-0.499165</ixz>
            <iyy>2.08522</iyy>
            <iyz>-0.612531</iyz>
            <izz>0.353279</izz>
          </inertia>
        </inertial>
        <collision name='thigh_right_collision'>
          <geometry>
            <mesh>
              <uri>model://biking_legs/meshes/collisions/thigh_right.stl</uri>
              <scale>0.001 0.001 0.001</scale>
            </mesh>
          </geometry>
          <max_contacts>10</max_contacts>
          <surface>
            <contact>
              <ode/>
            </contact>
            <bounce/>
            <friction>
              <torsional>
                <ode/>
              </torsional>
              <ode/>
            </friction>
          </surface>
        </collision>
        <visual name='thigh_right_visual'>
          <geometry>
            <mesh>
              <uri>model://biking_legs/meshes/visuals/thigh_right.stl</uri>
              <scale>0.001 0.001 0.001</scale>
            </mesh>
          </geometry>
        </visual>
        <enable_wind>0</enable_wind>
        <kinematic>0</kinematic>
      </link>
      <link name='thigh_left'>
        <self_collide>0</self_collide>
        <pose frame=''>0.239271 -0.209617 0.484082 0 -0 0</pose>
        <inertial>
          <pose frame=''>0 0 0 0 -0 0</pose>
          <mass>5.5625</mass>
          <inertia>
            <ixx>1.57564</ixx>
            <ixy>0.278754</ixy>
            <ixz>-0.647309</ixz>
            <iyy>1.65309</iyy>
            <iyz>0.567528</iyz>
            <izz>0.5755</izz>
          </inertia>
        </inertial>
        <collision name='thigh_left_collision'>
          <geometry>
            <mesh>
              <uri>model://biking_legs/meshes/collisions/thigh_left.stl</uri>
              <scale>0.001 0.001 0.001</scale>
            </mesh>
          </geometry>
          <max_contacts>10</max_contacts>
          <surface>
            <contact>
              <ode/>
            </contact>
            <bounce/>
            <friction>
              <torsional>
                <ode/>
              </torsional>
              <ode/>
            </friction>
          </surface>
        </collision>
        <visual name='thigh_left_visual'>
          <geometry>
            <mesh>
              <uri>model://biking_legs/meshes/visuals/thigh_left.stl</uri>
              <scale>0.001 0.001 0.001</scale>
            </mesh>
          </geometry>
        </visual>
        <enable_wind>0</enable_wind>
        <kinematic>0</kinematic>
      </link>
      <link name='shin_right'>
        <self_collide>0</self_collide>
        <pose frame=''>0.031394 0.186662 0.450507 0 -0 0</pose>
        <inertial>
          <pose frame=''>0 0 0 0 -0 0</pose>
          <mass>5.74056</mass>
          <inertia>
            <ixx>1.39436</ixx>
            <ixy>-0.0321225</ixy>
            <ixz>-0.0676332</ixz>
            <iyy>1.21352</iyy>
            <iyz>-0.485848</iyz>
            <izz>0.228689</izz>
          </inertia>
        </inertial>
        <collision name='shin_right_collision'>
          <geometry>
            <mesh>
              <uri>model://biking_legs/meshes/collisions/shin_right.stl</uri>
              <scale>0.001 0.001 0.001</scale>
            </mesh>
          </geometry>
          <max_contacts>10</max_contacts>
          <surface>
            <contact>
              <ode/>
            </contact>
            <bounce/>
            <friction>
              <torsional>
                <ode/>
              </torsional>
              <ode/>
            </friction>
          </surface>
        </collision>
        <visual name='shin_right_visual'>
          <geometry>
            <mesh>
              <uri>model://biking_legs/meshes/visuals/shin_right.stl</uri>
              <scale>0.001 0.001 0.001</scale>
            </mesh>
          </geometry>
        </visual>
        <enable_wind>0</enable_wind>
        <kinematic>0</kinematic>
      </link>
      <link name='shin_left'>
        <self_collide>0</self_collide>
        <pose frame=''>0.198184 -0.20868 0.138684 0 -0 0</pose>
        <inertial>
          <pose frame=''>0 0 0 0 -0 0</pose>
          <mass>5.74153</mass>
          <inertia>
            <ixx>0.400402</ixx>
            <ixy>0.237799</ixy>
            <ixz>-0.159346</ixz>
            <iyy>0.378731</iyy>
            <iyz>0.169585</iyz>
            <izz>0.487872</izz>
          </inertia>
        </inertial>
        <collision name='shin_left_collision'>
          <geometry>
            <mesh>
              <uri>model://biking_legs/meshes/collisions/shin_left.stl</uri>
              <scale>0.001 0.001 0.001</scale>
            </mesh>
          </geometry>
          <max_contacts>10</max_contacts>
          <surface>
            <contact>
              <ode/>
            </contact>
            <bounce/>
            <friction>
              <torsional>
                <ode/>
              </torsional>
              <ode/>
            </friction>
          </surface>
        </collision>
        <visual name='shin_left_visual'>
          <geometry>
            <mesh>
              <uri>model://biking_legs/meshes/visuals/shin_left.stl</uri>
              <scale>0.001 0.001 0.001</scale>
            </mesh>
          </geometry>
        </visual>
        <enable_wind>0</enable_wind>
        <kinematic>0</kinematic>
      </link>
      <link name='wheel_back'>
        <self_collide>0</self_collide>
        <pose frame=''>0.536897 0.00355 0.049416 0 -0 0</pose>
        <inertial>
          <pose frame=''>0 0 0 0 -0 0</pose>
          <mass>13.3402</mass>
          <inertia>
            <ixx>0.541919</ixx>
            <ixy>-0.0254258</ixy>
            <ixz>-0.353931</ixz>
            <iyy>4.8943</iyy>
            <iyz>-0.00234019</iyz>
            <izz>4.35476</izz>
          </inertia>
        </inertial>
        <collision name='wheel_back_collision'>
          <geometry>
            <mesh>
              <uri>model://biking_legs/meshes/CAD/wheel_back.stl</uri>
              <scale>0.001 0.001 0.001</scale>
            </mesh>
          </geometry>
          <max_contacts>10</max_contacts>
          <surface>
            <contact>
              <ode/>
            </contact>
            <bounce/>
            <friction>
              <torsional>
                <ode/>
              </torsional>
              <ode/>
            </friction>
          </surface>
        </collision>
        <visual name='wheel_back_visual'>
          <geometry>
            <mesh>
              <uri>model://biking_legs/meshes/CAD/wheel_back.stl</uri>
              <scale>0.001 0.001 0.001</scale>
            </mesh>
          </geometry>
        </visual>
        <enable_wind>0</enable_wind>
        <kinematic>0</kinematic>
      </link>
      <joint name='joint_pedal_right' type='revolute'>
        <parent>kurbel</parent>
        <child>pedal_right</child>
        <pose frame=''>7.8e-05 0.042 -4e-06 0 -0 0</pose>
        <axis>
          <xyz>-0 1 -0</xyz>
          <limit>
            <lower>-3.14159e+17</lower>
            <upper>3.14159e+17</upper>
          </limit>
          <use_parent_model_frame>0</use_parent_model_frame>
          <dynamics>
            <spring_reference>0</spring_reference>
            <spring_stiffness>0</spring_stiffness>
          </dynamics>
        </axis>
      </joint>
      <joint name='joint_pedal_left' type='revolute'>
        <parent>kurbel</parent>
        <child>pedal_left</child>
        <pose frame=''>-3e-05 -0.042 -7.2e-05 0 -0 0</pose>
        <axis>
          <xyz>0 -1 0</xyz>
          <limit>
            <lower>-3.14159e+17</lower>
            <upper>3.14159e+17</upper>
          </limit>
          <use_parent_model_frame>0</use_parent_model_frame>
          <dynamics>
            <spring_reference>0</spring_reference>
            <spring_stiffness>0</spring_stiffness>
          </dynamics>
        </axis>
      </joint>
      <joint name='joint_hip_left' type='revolute'>
        <parent>bike</parent>
        <child>thigh_left</child>
        <pose frame=''>0.009267 0.010551 0.110839 0 -0 0</pose>
        <axis>
          <xyz>-0 -1 -0</xyz>
          <limit>
            <lower>-3.14159</lower>
            <upper>3.14159</upper>
          </limit>
          <use_parent_model_frame>0</use_parent_model_frame>
          <dynamics>
            <spring_reference>0</spring_reference>
            <spring_stiffness>0</spring_stiffness>
          </dynamics>
        </axis>
      </joint>
      <joint name='joint_hip_right' type='revolute'>
        <parent>bike</parent>
        <child>thigh_right</child>
        <pose frame=''>0.111196 -0.021903 0.002128 0 -0 0</pose>
        <axis>
          <xyz>-0 -1 0</xyz>
          <limit>
            <lower>-3.14159</lower>
            <upper>3.14159</upper>
          </limit>
          <use_parent_model_frame>0</use_parent_model_frame>
          <dynamics>
            <spring_reference>0</spring_reference>
            <spring_stiffness>0</spring_stiffness>
          </dynamics>
        </axis>
      </joint>
      <joint name='joint_knee_left' type='revolute'>
        <parent>thigh_left</parent>
        <child>shin_left</child>
        <pose frame=''>0.027854 0.033665 0.147878 0 -0 0</pose>
        <axis>
          <xyz>-0 -1 -0</xyz>
          <limit>
            <lower>-3.14159</lower>
            <upper>3.14159</upper>
          </limit>
          <use_parent_model_frame>0</use_parent_model_frame>
          <dynamics>
            <spring_reference>0</spring_reference>
            <spring_stiffness>0</spring_stiffness>
          </dynamics>
        </axis>
      </joint>
      <joint name='joint_foot_left' type='fixed'>
        <parent>shin_left</parent>
        <child>foot_left</child>
        <pose frame=''>-0.010876 0.023919 0.023483 0 -0 0</pose>
        <axis>
          <xyz>0 1 -0</xyz>
          <limit>
            <lower>-3.14159</lower>
            <upper>3.14159</upper>
          </limit>
          <use_parent_model_frame>0</use_parent_model_frame>
        </axis>
      </joint>
      <joint name='joint_foot_left_tip' type='fixed'>
        <parent>foot_left</parent>
        <child>foot_left_tip</child>
        <pose frame=''>0.033571 -0.001166 0.024324 0 -0 0</pose>
      </joint>
      <joint name='joint_knee_right' type='revolute'>
        <parent>thigh_right</parent>
        <child>shin_right</child>
        <pose frame=''>-0.076281 -0.013632 0.129746 0 -0 0</pose>
        <axis>
          <xyz>0 1 -0</xyz>
          <limit>
            <lower>-3.14159</lower>
            <upper>3.14159</upper>
          </limit>
          <use_parent_model_frame>0</use_parent_model_frame>
          <dynamics>
            <spring_reference>0</spring_reference>
            <spring_stiffness>0</spring_stiffness>
          </dynamics>
        </axis>
      </joint>
      <joint name='joint_foot_right' type='fixed'>
        <parent>shin_right</parent>
        <child>foot_right</child>
        <pose frame=''>-0.013005 0.02408 0.022387 0 -0 0</pose>
        <axis>
          <xyz>0 1 -0</xyz>
          <limit>
            <lower>-3.14159</lower>
            <upper>3.14159</upper>
          </limit>
          <use_parent_model_frame>0</use_parent_model_frame>
        </axis>
      </joint>
      <joint name='joint_foot_right_tip' type='fixed'>
        <parent>foot_right</parent>
        <child>foot_right_tip</child>
        <pose frame=''>0.031324 0.001164 0.027153 0 -0 0</pose>
      </joint>
      <joint name='joint_wheel_right' type='revolute'>
        <parent>front_part</parent>
        <child>right_wheel</child>
        <pose frame=''>0 -0.004 0 0 -0 0</pose>
        <axis>
          <xyz>-0 1 0</xyz>
          <limit>
            <lower>-3.14159e+15</lower>
            <upper>3.14159e+15</upper>
          </limit>
          <use_parent_model_frame>0</use_parent_model_frame>
          <dynamics>
            <spring_reference>0</spring_reference>
            <spring_stiffness>0</spring_stiffness>
          </dynamics>
        </axis>
      </joint>
      <joint name='joint_wheel_back' type='revolute'>
        <parent>bike</parent>
        <child>wheel_back</child>
        <pose frame=''>-0 -0.069 0 0 -0 0</pose>
        <axis>
          <xyz>0 1 0</xyz>
          <limit>
            <lower>-3.14159e+15</lower>
            <upper>3.14159e+15</upper>
          </limit>
          <use_parent_model_frame>0</use_parent_model_frame>
          <dynamics>
            <spring_reference>0</spring_reference>
            <spring_stiffness>0</spring_stiffness>
          </dynamics>
        </axis>
      </joint>
      <joint name='joint_pedal' type='revolute'>
        <parent>bike</parent>
        <child>kurbel</child>
        <pose frame=''>0.000278 -0.035132 -0.001009 0 -0 0</pose>
        <axis>
          <xyz>-0 1 -0</xyz>
          <limit>
            <lower>-3.14159e+15</lower>
            <upper>3.14159e+15</upper>
          </limit>
          <use_parent_model_frame>0</use_parent_model_frame>
          <dynamics>
            <spring_reference>0</spring_reference>
            <spring_stiffness>0</spring_stiffness>
          </dynamics>
        </axis>
      </joint>
      <joint name='joint_wheel_left' type='revolute'>
        <parent>front_part</parent>
        <child>left_wheel</child>
        <pose frame=''>0 0.046 0 0 -0 0</pose>
        <axis>
          <xyz>0 1 -0</xyz>
          <limit>
            <lower>-3.14159e+15</lower>
            <upper>3.14159e+15</upper>
          </limit>
          <use_parent_model_frame>0</use_parent_model_frame>
          <dynamics>
            <spring_reference>0</spring_reference>
            <spring_stiffness>0</spring_stiffness>
          </dynamics>
        </axis>
      </joint>
      <joint name='joint_front' type='fixed'>
        <parent>bike</parent>
        <child>front_part</child>
        <pose frame=''>-0.230035 -0.010388 -0.205271 0 -0 0</pose>
        <axis>
          <xyz>0 -0 1</xyz>
          <limit>
            <lower>-0.523599</lower>
            <upper>0.523599</upper>
          </limit>
          <use_parent_model_frame>0</use_parent_model_frame>
        </axis>
      </joint>
      <joint name='joint_foot_pedal_left' type='prismatic'>
        <parent>pedal_left</parent>
        <child>foot_left_tip</child>
        <pose frame=''>-0.006838 -0.006895 -0.009398 0 -0 0</pose>
        <axis>
          <xyz>0.866025 -0 0.5</xyz>
          <limit>
            <lower>0</lower>
            <upper>0</upper>
          </limit>
          <use_parent_model_frame>0</use_parent_model_frame>
          <dynamics>
            <spring_reference>0</spring_reference>
            <spring_stiffness>0</spring_stiffness>
          </dynamics>
        </axis>
      </joint>
      <joint name='joint_foot_pedal_right' type='prismatic'>
        <parent>pedal_right</parent>
        <child>foot_right_tip</child>
        <pose frame=''>6.8e-05 0.028623 -0.005719 0 -0 0</pose>
        <axis>
          <xyz>-0.819152 -0 -0.573576</xyz>
          <limit>
            <lower>0</lower>
            <upper>0</upper>
          </limit>
          <use_parent_model_frame>0</use_parent_model_frame>
          <dynamics>
            <spring_reference>0</spring_reference>
            <spring_stiffness>0</spring_stiffness>
          </dynamics>
        </axis>
      </joint>
      <plugin name='cardsflow_gazebo_plugin' filename='libcardsflow_gazebo_plugin.so'/>
      <pose frame=''>0.148399 -0.099679 0 0 -0 0</pose>
    </model>
    <state world_name='default'>
      <sim_time>7 993000000</sim_time>
      <real_time>9 698580626</real_time>
      <wall_time>1557845659 930204745</wall_time>
      <iterations>7993</iterations>
      <model name='biking_legs'>
        <pose frame=''>-0.091813 -0.080759 0.247251 -0.011614 0.004975 -0.009352</pose>
        <scale>1 1 1</scale>
        <link name='bike'>
          <pose frame=''>-0.091813 -0.080759 0.247251 -0.011614 0.004975 -0.009352</pose>
          <velocity>-0.692605 -0.040597 -0.038491 0.190328 -0.045312 0.000608</velocity>
          <acceleration>-0.015398 0.034594 -10.0558 -0.213907 0.087257 0.07395</acceleration>
          <wrench>-0.335974 0.754833 -219.413 0 -0 0</wrench>
        </link>
        <link name='foot_left'>
          <pose frame=''>0.233268 -0.269506 0.225325 -0.011807 0.158339 -0.011061</pose>
          <velocity>-0.44209 -0.034 0.23245 0.204361 0.33721 -0.011484</velocity>
          <acceleration>-0.699813 -0.261121 -8.00339 -1.15646 -1.08534 -2.97039</acceleration>
          <wrench>-0.510446 -0.190462 -5.83771 0 -0 0</wrench>
        </link>
        <link name='foot_left_tip'>
          <pose frame=''>0.142919 -0.268135 0.176351 -0.011451 0.158229 -0.011223</pose>
          <velocity>-0.460179 -0.0252 0.260067 0.174708 0.358156 0.005264</velocity>
          <acceleration>-0.784942 0.003447 -9.46793 2.01792 -1.53486 1.04107</acceleration>
          <wrench>-0.218171 0.000958 -2.63157 0 -0 0</wrench>
        </link>
        <link name='foot_right'>
          <pose frame=''>-0.029713 0.083003 0.407198 -0.012068 0.319859 -0.013019</pose>
          <velocity>-0.879709 -0.075163 -0.395788 0.184305 0.636376 -0.012099</velocity>
          <acceleration>0.513604 -0.164258 -8.83795 -1.92496 0.154612 -3.05568</acceleration>
          <wrench>0.374617 -0.119807 -6.4463 0 -0 0</wrench>
        </link>
        <link name='foot_right_tip'>
          <pose frame=''>-0.123611 0.082287 0.365087 -0.0128 0.319815 -0.013451</pose>
          <velocity>-0.906505 -0.065165 -0.34203 0.242694 0.631879 0.003866</velocity>
          <acceleration>0.725403 0.229902 -10.4415 2.58632 0.013095 0.841434</acceleration>
          <wrench>0.201634 0.063904 -2.90234 0 -0 0</wrench>
        </link>
        <link name='front_part'>
          <pose frame=''>-0.806966 -0.061168 0.467115 -0.011614 0.004975 -0.009352</pose>
          <velocity>-0.702558 -0.082911 -0.067171 0.190339 -0.045317 0.000661</velocity>
          <acceleration>0.060153 -0.02819 -10.0078 -0.183902 0.090666 0.185007</acceleration>
          <wrench>1.01121 -0.47389 -168.239 0 -0 0</wrench>
        </link>
        <link name='kurbel'>
          <pose frame=''>-0.00025 -0.08144 0.250479 -0.01834 -0.8852 0.004911</pose>
          <velocity>-0.693694 -0.041185 -0.036579 -2.97299 -0.772662 -3.11424</velocity>
          <acceleration>-0.003966 0.065443 -10.0446 -2.89794 1.53785 -2.27237</acceleration>
          <wrench>-0.011039 0.182145 -27.957 0 -0 0</wrench>
        </link>
        <link name='left_wheel'>
          <pose frame=''>-1.0932 -0.420855 0.301947 -0.016432 -0.785777 0.002331</pose>
          <velocity>-0.694871 -0.051648 -0.148613 -2.97278 -0.772004 -3.11369</velocity>
          <acceleration>0.078408 -0.078876 -9.92115 -0.125819 -0.989912 2.0774</acceleration>
          <wrench>1.04597 -1.05222 -132.35 0 -0 0</wrench>
        </link>
        <link name='pedal_left'>
          <pose frame=''>0.139228 -0.233221 0.156607 -0.011695 0.158797 -0.011168</pose>
          <velocity>-0.466412 -0.021392 0.267844 0.189624 0.327182 -0.002343</velocity>
          <acceleration>-0.854119 -0.056649 -9.58238 -2.64821 0.330116 0.669394</acceleration>
          <wrench>-0.807999 -0.05359 -9.06496 0 -0 0</wrench>
        </link>
        <link name='pedal_right'>
          <pose frame=''>-0.137739 0.068791 0.343696 -0.012328 0.32046 -0.013196</pose>
          <velocity>-0.919071 -0.060611 -0.336599 0.203573 0.5764 -0.005096</velocity>
          <acceleration>0.859744 0.265287 -10.5389 -0.924127 -0.136564 -0.473987</acceleration>
          <wrench>0.81332 0.250962 -9.96978 0 -0 0</wrench>
        </link>
        <link name='right_wheel'>
          <pose frame=''>-1.08677 0.271068 0.29391 -0.016428 -0.785627 0.002327</pose>
          <velocity>-0.694781 -0.050216 -0.016619 -2.973 -0.771948 -3.11382</velocity>
          <acceleration>0.131716 -0.206371 -10.0429 -1.09988 -0.041228 -2.09286</acceleration>
          <wrench>1.75712 -2.75304 -133.974 0 -0 0</wrench>
        </link>
        <link name='shin_left'>
          <pose frame=''>0.276312 -0.29061 0.443029 -0.011765 0.158173 -0.011148</pose>
          <velocity>-0.366918 -0.077616 0.213724 0.194027 0.351832 -0.00403</velocity>
          <acceleration>-0.763551 -0.359818 -8.28937 -2.44361 -1.18496 0.350095</acceleration>
          <wrench>-4.38395 -2.06591 -47.5937 0 -0 0</wrench>
        </link>
        <link name='shin_right'>
          <pose frame=''>-0.093706 0.110296 0.622276 -0.012234 0.319743 -0.013144</pose>
          <velocity>-0.742177 -0.115816 -0.348568 0.196677 0.64444 -0.007023</velocity>
          <acceleration>0.136355 0.122378 -8.78561 0.353607 0.152714 2.91336</acceleration>
          <wrench>0.782753 0.702516 -50.4343 0 -0 0</wrench>
        </link>
        <link name='thigh_left'>
          <pose frame=''>0.217716 -0.287441 0.749636 -0.014617 -0.652501 -0.000418</pose>
          <velocity>-0.57374 -0.136343 0.026544 0.176029 -1.55479 0.018196</velocity>
          <acceleration>0.267556 -0.008146 -9.64166 -0.881754 1.04647 -2.77132</acceleration>
          <wrench>1.48828 -0.045311 -53.6318 0 -0 0</wrench>
        </link>
        <link name='thigh_right'>
          <pose frame=''>0.067967 0.111572 0.812183 -0.011801 -0.178026 -0.007205</pose>
          <velocity>-0.695035 -0.149668 -0.111679 0.180351 -1.11827 0.013465</velocity>
          <acceleration>0.064639 0.114071 -9.66318 -2.24435 1.47766 2.98596</acceleration>
          <wrench>0.359554 0.634512 -53.7509 0 -0 0</wrench>
        </link>
        <link name='wheel_back'>
          <pose frame=''>0.445339 -0.08166 0.29395 -0.016289 -0.776769 0.002123</pose>
          <velocity>-0.694826 -0.048923 -0.014316 -2.97216 -0.771939 -3.11297</velocity>
          <acceleration>-0.117456 0.312168 -10.1027 0.848513 -0.003462 1.92765</acceleration>
          <wrench>-1.56688 4.16439 -134.772 0 -0 0</wrench>
        </link>
      </model>
      <model name='ground_plane'>
        <pose frame=''>0 0 0 0 -0 0</pose>
        <scale>1 1 1</scale>
        <link name='link'>
          <pose frame=''>0 0 0 0 -0 0</pose>
          <velocity>0 0 0 0 -0 0</velocity>
          <acceleration>0 0 0 0 -0 0</acceleration>
          <wrench>0 0 0 0 -0 0</wrench>
        </link>
      </model>
      <light name='sun'>
        <pose frame=''>0 0 10 0 -0 0</pose>
      </light>
    </state>
    <gui fullscreen='0'>
      <camera name='user_camera'>
        <pose frame=''>5 -5 2 0 0.275643 2.35619</pose>
        <view_controller>orbit</view_controller>
        <projection_type>perspective</projection_type>
      </camera>
    </gui>
  </world>
</sdf>
