<?xml version="1.0" ?>
<sdf version="1.6">
	<model name="human">
		<link name="base">
			<self_collide>false</self_collide>
			<pose frame="">-0.003000131331279944 0.018810229640317006 0.9218898557500742 0.0 -0.0 0.0</pose>
			<inertial>
				<pose frame="">0.0 0.0 0.0 0 0 0</pose>
				<mass>44.520816362098905</mass>
				<inertia>
					<ixx>39.2794918899991</ixx>
					<ixy>0.002498865664063125</ixy>
					<ixz>0.12637697727543706</ixz>
					<iyy>39.29338856242114</iyy>
					<iyz>-0.7913062051966605</iyz>
					<izz>0.33705199839441813</izz>
				</inertia>
			</inertial>
			<collision name="base_collision">
				<geometry>
					<mesh>
						<uri>model://human/meshes/CAD/base.stl</uri>
						<scale>0.001 0.001 0.001</scale>
					</mesh>
				</geometry>
			</collision>
			<visual name="base_visual">
				<geometry>
					<mesh>
						<uri>model://human/meshes/CAD/base.stl</uri>
						<scale>0.001 0.001 0.001</scale>
					</mesh>
				</geometry>
			</visual>
		</link>
		<link name="ankle_right_link1">
			<self_collide>false</self_collide>
			<pose frame="">-0.12262700433836331 0.020000000000004788 0.11146497559651634 0.0 -0.0 0.0</pose>
			<inertial>
				<pose frame="">0.0 0.0 0.0 0 0 0</pose>
				<mass>0.06979038134801686</mass>
				<inertia>
					<ixx>0.000906669890614203</ixx>
					<ixy>0.00017116370792682678</ixy>
					<ixz>0.0009539379263534221</ixz>
					<iyy>0.0019282183758003988</iyy>
					<iyz>-0.00015558366307660257</iyz>
					<izz>0.00108902806793732</izz>
				</inertia>
			</inertial>
			<collision name="ankle_right_link1_collision">
				<geometry>
					<mesh>
						<uri>model://human/meshes/CAD/ankle_right_link1.stl</uri>
						<scale>0.001 0.001 0.001</scale>
					</mesh>
				</geometry>
			</collision>
			<visual name="ankle_right_link1_visual">
				<geometry>
					<mesh>
						<uri>model://human/meshes/CAD/ankle_right_link1.stl</uri>
						<scale>0.001 0.001 0.001</scale>
					</mesh>
				</geometry>
			</visual>
		</link>
		<link name="ankle_right_link2">
			<self_collide>false</self_collide>
			<pose frame="">-0.1226270043383633 0.019999999937521364 0.11146497550570718 0.0 -0.0 0.0</pose>
			<inertial>
				<pose frame="">0.0 0.0 0.0 0 0 0</pose>
				<mass>0.046782557609273294</mass>
				<inertia>
					<ixx>0.000605221572185299</ixx>
					<ixy>0.00011473609753981396</ixy>
					<ixz>0.0006394528170923969</ixz>
					<iyy>0.0012899957480642134</iyy>
					<iyz>-0.00010429233239685434</iyz>
					<izz>0.0007274616551232586</izz>
				</inertia>
			</inertial>
			<collision name="ankle_right_link2_collision">
				<geometry>
					<mesh>
						<uri>model://human/meshes/CAD/ankle_right_link2.stl</uri>
						<scale>0.001 0.001 0.001</scale>
					</mesh>
				</geometry>
			</collision>
			<visual name="ankle_right_link2_visual">
				<geometry>
					<mesh>
						<uri>model://human/meshes/CAD/ankle_right_link2.stl</uri>
						<scale>0.001 0.001 0.001</scale>
					</mesh>
				</geometry>
			</visual>
		</link>
		<link name="knee_right_link1">
			<self_collide>false</self_collide>
			<pose frame="">-0.10941629950839378 0.02043018916516386 0.4654841277672509 0.0 -0.0 0.0</pose>
			<inertial>
				<pose frame="">0.0 0.0 0.0 0 0 0</pose>
				<mass>0.06979038134801685</mass>
				<inertia>
					<ixx>0.015162641172061096</ixx>
					<ixy>0.00015600911813701664</ixy>
					<ixz>0.003554532348803379</ixz>
					<iyy>0.015969036504041297</iyy>
					<iyz>-0.0006637015564045487</iyz>
					<izz>0.0008763025911976836</izz>
				</inertia>
			</inertial>
			<collision name="knee_right_link1_collision">
				<geometry>
					<mesh>
						<uri>model://human/meshes/CAD/knee_right_link1.stl</uri>
						<scale>0.001 0.001 0.001</scale>
					</mesh>
				</geometry>
			</collision>
			<visual name="knee_right_link1_visual">
				<geometry>
					<mesh>
						<uri>model://human/meshes/CAD/knee_right_link1.stl</uri>
						<scale>0.001 0.001 0.001</scale>
					</mesh>
				</geometry>
			</visual>
		</link>
		<link name="knee_right_link2">
			<self_collide>false</self_collide>
			<pose frame="">-0.10941629950839328 0.020430189102680418 0.46548412767644237 0.0 -0.0 0.0</pose>
			<inertial>
				<pose frame="">0.0 0.0 0.0 0 0 0</pose>
				<mass>0.0467825576092733</mass>
				<inertia>
					<ixx>0.010161420931730525</ixx>
					<ixy>0.00010457752764095777</ixy>
					<ixz>0.00238270820616749</ixz>
					<iyy>0.010701971582961982</iyy>
					<iyz>-0.0004448987896969037</iyz>
					<izz>0.0005848654738374431</izz>
				</inertia>
			</inertial>
			<collision name="knee_right_link2_collision">
				<geometry>
					<mesh>
						<uri>model://human/meshes/CAD/knee_right_link2.stl</uri>
						<scale>0.001 0.001 0.001</scale>
					</mesh>
				</geometry>
			</collision>
			<visual name="knee_right_link2_visual">
				<geometry>
					<mesh>
						<uri>model://human/meshes/CAD/knee_right_link2.stl</uri>
						<scale>0.001 0.001 0.001</scale>
					</mesh>
				</geometry>
			</visual>
		</link>
		<link name="hip_right_link1">
			<self_collide>false</self_collide>
			<pose frame="">-0.10441629950839147 0.02043018916516434 0.8954841277672507 0.0 -0.0 0.0</pose>
			<inertial>
				<pose frame="">0.0 0.0 0.0 0 0 0</pose>
				<mass>0.06979038134801685</mass>
				<inertia>
					<ixx>0.056005113401269284</ixx>
					<ixy>0.00014887996467277236</ixy>
					<ixz>0.0065256197203666134</ixz>
					<iyy>0.05673689144009935</iyy>
					<iyz>-0.0012768087543296091</iyz>
					<izz>0.000801685298047556</izz>
				</inertia>
			</inertial>
			<collision name="hip_right_link1_collision">
				<geometry>
					<mesh>
						<uri>model://human/meshes/CAD/hip_right_link1.stl</uri>
						<scale>0.001 0.001 0.001</scale>
					</mesh>
				</geometry>
			</collision>
			<visual name="hip_right_link1_visual">
				<geometry>
					<mesh>
						<uri>model://human/meshes/CAD/hip_right_link1.stl</uri>
						<scale>0.001 0.001 0.001</scale>
					</mesh>
				</geometry>
			</visual>
		</link>
		<link name="hip_right_link2">
			<self_collide>false</self_collide>
			<pose frame="">-0.1044162995083887 0.020430189102680966 0.8954841276764428 0.0 -0.0 0.0</pose>
			<inertial>
				<pose frame="">0.0 0.0 0.0 0 0 0</pose>
				<mass>0.0467825576092733</mass>
				<inertia>
					<ixx>0.0375393385302191</ixx>
					<ixy>9.979864514763338e-05</ixy>
					<ixz>0.004374315981323548</ixz>
					<iyy>0.0380298710020393</iyy>
					<iyz>-0.0008558826841226575</iyz>
					<izz>0.0005348472944261825</izz>
				</inertia>
			</inertial>
			<collision name="hip_right_link2_collision">
				<geometry>
					<mesh>
						<uri>model://human/meshes/CAD/hip_right_link2.stl</uri>
						<scale>0.001 0.001 0.001</scale>
					</mesh>
				</geometry>
			</collision>
			<visual name="hip_right_link2_visual">
				<geometry>
					<mesh>
						<uri>model://human/meshes/CAD/hip_right_link2.stl</uri>
						<scale>0.001 0.001 0.001</scale>
					</mesh>
				</geometry>
			</visual>
		</link>
		<link name="spine_link1">
			<self_collide>false</self_collide>
			<pose frame="">-0.002779095629306737 0.01990793509010296 1.0300189040829886 0.0 -0.0 0.0</pose>
			<inertial>
				<pose frame="">0.0 0.0 0.0 0 0 0</pose>
				<mass>0.06979038134801684</mass>
				<inertia>
					<ixx>0.0740826404147076</ixx>
					<ixy>3.861226504667896e-06</ixy>
					<ixz>0.00019977643461031183</ixz>
					<iyy>0.07405551969754884</iyy>
					<iyz>-0.001431090118243397</iyz>
					<izz>3.984602905793133e-05</izz>
				</inertia>
			</inertial>
			<collision name="spine_link1_collision">
				<geometry>
					<mesh>
						<uri>model://human/meshes/CAD/spine_link1.stl</uri>
						<scale>0.001 0.001 0.001</scale>
					</mesh>
				</geometry>
			</collision>
			<visual name="spine_link1_visual">
				<geometry>
					<mesh>
						<uri>model://human/meshes/CAD/spine_link1.stl</uri>
						<scale>0.001 0.001 0.001</scale>
					</mesh>
				</geometry>
			</visual>
		</link>
		<link name="spine_link2">
			<self_collide>false</self_collide>
			<pose frame="">-0.0027790956293058805 0.019907935027619585 1.0300189039921805 0.0 -0.0 0.0</pose>
			<inertial>
				<pose frame="">0.0 0.0 0.0 0 0 0</pose>
				<mass>0.04678255760927329</mass>
				<inertia>
					<ixx>0.04965723977283559</ixx>
					<ixy>2.588294365799482e-06</ixy>
					<ixz>0.0001339160551896147</ixz>
					<iyy>0.04963905995384849</iyy>
					<iyz>-0.0009593020469149476</iyz>
					<izz>2.41638907552324e-05</izz>
				</inertia>
			</inertial>
			<collision name="spine_link2_collision">
				<geometry>
					<mesh>
						<uri>model://human/meshes/CAD/spine_link2.stl</uri>
						<scale>0.001 0.001 0.001</scale>
					</mesh>
				</geometry>
			</collision>
			<visual name="spine_link2_visual">
				<geometry>
					<mesh>
						<uri>model://human/meshes/CAD/spine_link2.stl</uri>
						<scale>0.001 0.001 0.001</scale>
					</mesh>
				</geometry>
			</visual>
		</link>
		<link name="shoulder_right_link1">
			<self_collide>false</self_collide>
			<pose frame="">-0.18277909562930625 0.0649079350901036 1.4000189040829911 0.0 -0.0 0.0</pose>
			<inertial>
				<pose frame="">0.0 0.0 0.0 0 0 0</pose>
				<mass>0.06979038134801557</mass>
				<inertia>
					<ixx>0.13709851852043742</ixx>
					<ixy>0.0008279800806155059</ixy>
					<ixz>0.017858953045674784</ixz>
					<iyy>0.13913605971412144</iyy>
					<iyz>-0.006342014993972898</iyz>
					<izz>0.002637247813082338</izz>
				</inertia>
			</inertial>
			<collision name="shoulder_right_link1_collision">
				<geometry>
					<mesh>
						<uri>model://human/meshes/CAD/shoulder_right_link1.stl</uri>
						<scale>0.001 0.001 0.001</scale>
					</mesh>
				</geometry>
			</collision>
			<visual name="shoulder_right_link1_visual">
				<geometry>
					<mesh>
						<uri>model://human/meshes/CAD/shoulder_right_link1.stl</uri>
						<scale>0.001 0.001 0.001</scale>
					</mesh>
				</geometry>
			</visual>
		</link>
		<link name="shoulder_right_link2">
			<self_collide>false</self_collide>
			<pose frame="">-0.18277909562930872 0.06490793509010352 1.4000189040829918 0.0 -0.0 0.0</pose>
			<inertial>
				<pose frame="">0.0 0.0 0.0 0 0 0</pose>
				<mass>0.046782558357129474</mass>
				<inertia>
					<ixx>0.09189864888946782</ixx>
					<ixy>0.000555019555585758</ixy>
					<ixz>0.011971384837264301</ixz>
					<iyy>0.09326447306118643</iyy>
					<iyz>-0.004251240369039246</iyz>
					<izz>0.0017652791880929425</izz>
				</inertia>
			</inertial>
			<collision name="shoulder_right_link2_collision">
				<geometry>
					<mesh>
						<uri>model://human/meshes/CAD/shoulder_right_link2.stl</uri>
						<scale>0.001 0.001 0.001</scale>
					</mesh>
				</geometry>
			</collision>
			<visual name="shoulder_right_link2_visual">
				<geometry>
					<mesh>
						<uri>model://human/meshes/CAD/shoulder_right_link2.stl</uri>
						<scale>0.001 0.001 0.001</scale>
					</mesh>
				</geometry>
			</visual>
		</link>
		<link name="elbow_right_link1">
			<self_collide>false</self_collide>
			<pose frame="">-0.22277909562923995 0.09090793509010674 1.1370189040829806 0.0 -0.0 0.0</pose>
			<inertial>
				<pose frame="">0.0 0.0 0.0 0 0 0</pose>
				<mass>0.06979038134801559</mass>
				<inertia>
					<ixx>0.09081425429323405</ixx>
					<ixy>0.0014134218513618753</ixy>
					<ixz>0.017678185769476478</ixz>
					<iyy>0.09370122224598725</iyy>
					<iyz>-0.007213815820120803</iyz>
					<izz>0.004052145920149003</izz>
				</inertia>
			</inertial>
			<collision name="elbow_right_link1_collision">
				<geometry>
					<mesh>
						<uri>model://human/meshes/CAD/elbow_right_link1.stl</uri>
						<scale>0.001 0.001 0.001</scale>
					</mesh>
				</geometry>
			</collision>
			<visual name="elbow_right_link1_visual">
				<geometry>
					<mesh>
						<uri>model://human/meshes/CAD/elbow_right_link1.stl</uri>
						<scale>0.001 0.001 0.001</scale>
					</mesh>
				</geometry>
			</visual>
		</link>
		<link name="elbow_right_link2">
			<self_collide>false</self_collide>
			<pose frame="">-0.22277909562924222 0.09090793509010682 1.1370189040829812 0.0 -0.0 0.0</pose>
			<inertial>
				<pose frame="">0.0 0.0 0.0 0 0 0</pose>
				<mass>0.046782558357129474</mass>
				<inertia>
					<ixx>0.060872936600713926</ixx>
					<ixy>0.0009474585031259434</ixy>
					<ixz>0.011850211181461519</ixz>
					<iyy>0.06280815667139038</iyy>
					<iyz>-0.004835634267414437</iyz>
					<izz>0.002713727269113793</izz>
				</inertia>
			</inertial>
			<collision name="elbow_right_link2_collision">
				<geometry>
					<mesh>
						<uri>model://human/meshes/CAD/elbow_right_link2.stl</uri>
						<scale>0.001 0.001 0.001</scale>
					</mesh>
				</geometry>
			</collision>
			<visual name="elbow_right_link2_visual">
				<geometry>
					<mesh>
						<uri>model://human/meshes/CAD/elbow_right_link2.stl</uri>
						<scale>0.001 0.001 0.001</scale>
					</mesh>
				</geometry>
			</visual>
		</link>
		<link name="wrist_right_link1">
			<self_collide>false</self_collide>
			<pose frame="">-0.2682790956292395 0.0739079350901101 0.8690189040829809 0.0 -0.0 0.0</pose>
			<inertial>
				<pose frame="">0.0 0.0 0.0 0 0 0</pose>
				<mass>0.06979038134801557</mass>
				<inertia>
					<ixx>0.05309813623893083</ixx>
					<ixy>0.0013838004700198379</ixy>
					<ixz>0.01627090198718148</ixz>
					<iyy>0.05773998455168521</iyy>
					<iyz>-0.004482454233363266</iyz>
					<izz>0.005415939157459446</izz>
				</inertia>
			</inertial>
			<collision name="wrist_right_link1_collision">
				<geometry>
					<mesh>
						<uri>model://human/meshes/CAD/wrist_right_link1.stl</uri>
						<scale>0.001 0.001 0.001</scale>
					</mesh>
				</geometry>
			</collision>
			<visual name="wrist_right_link1_visual">
				<geometry>
					<mesh>
						<uri>model://human/meshes/CAD/wrist_right_link1.stl</uri>
						<scale>0.001 0.001 0.001</scale>
					</mesh>
				</geometry>
			</visual>
		</link>
		<link name="wrist_right_link2">
			<self_collide>false</self_collide>
			<pose frame="">-0.2682790956292419 0.0739079350901101 0.8690189040829838 0.0 -0.0 0.0</pose>
			<inertial>
				<pose frame="">0.0 0.0 0.0 0 0 0</pose>
				<mass>0.04678255835712947</mass>
				<inertia>
					<ixx>0.03559070630193965</ixx>
					<ixy>0.0009276024144431399</ixy>
					<ixz>0.010906867207713063</ixz>
					<iyy>0.03870227462098214</iyy>
					<iyz>-0.0030047217496891082</iyz>
					<izz>0.003627918243273718</izz>
				</inertia>
			</inertial>
			<collision name="wrist_right_link2_collision">
				<geometry>
					<mesh>
						<uri>model://human/meshes/CAD/wrist_right_link2.stl</uri>
						<scale>0.001 0.001 0.001</scale>
					</mesh>
				</geometry>
			</collision>
			<visual name="wrist_right_link2_visual">
				<geometry>
					<mesh>
						<uri>model://human/meshes/CAD/wrist_right_link2.stl</uri>
						<scale>0.001 0.001 0.001</scale>
					</mesh>
				</geometry>
			</visual>
		</link>
		<link name="shoulder_left_link1">
			<self_collide>false</self_collide>
			<pose frame="">0.1827790956293064 0.064907935090104 1.4000189040829916 0.0 -0.0 0.0</pose>
			<inertial>
				<pose frame="">0.0 0.0 0.0 0 0 0</pose>
				<mass>0.06979038134801813</mass>
				<inertia>
					<ixx>0.13709851852044247</ixx>
					<ixy>-0.0008279800806155413</ixy>
					<ixz>-0.017858953045675446</ixz>
					<iyy>0.13913605971412657</iyy>
					<iyz>-0.006342014993973167</iyz>
					<izz>0.002637247813082439</izz>
				</inertia>
			</inertial>
			<collision name="shoulder_left_link1_collision">
				<geometry>
					<mesh>
						<uri>model://human/meshes/CAD/shoulder_left_link1.stl</uri>
						<scale>0.001 0.001 0.001</scale>
					</mesh>
				</geometry>
			</collision>
			<visual name="shoulder_left_link1_visual">
				<geometry>
					<mesh>
						<uri>model://human/meshes/CAD/shoulder_left_link1.stl</uri>
						<scale>0.001 0.001 0.001</scale>
					</mesh>
				</geometry>
			</visual>
		</link>
		<link name="shoulder_left_link2">
			<self_collide>false</self_collide>
			<pose frame="">0.1827790956293088 0.06490793509010383 1.4000189040829925 0.0 -0.0 0.0</pose>
			<inertial>
				<pose frame="">0.0 0.0 0.0 0 0 0</pose>
				<mass>0.046782558357131146</mass>
				<inertia>
					<ixx>0.09189864888947114</ixx>
					<ixy>-0.0005550195555857809</ixy>
					<ixz>-0.011971384837264738</ixz>
					<iyy>0.0932644730611898</iyy>
					<iyz>-0.00425124036903942</iyz>
					<izz>0.0017652791880930082</izz>
				</inertia>
			</inertial>
			<collision name="shoulder_left_link2_collision">
				<geometry>
					<mesh>
						<uri>model://human/meshes/CAD/shoulder_left_link2.stl</uri>
						<scale>0.001 0.001 0.001</scale>
					</mesh>
				</geometry>
			</collision>
			<visual name="shoulder_left_link2_visual">
				<geometry>
					<mesh>
						<uri>model://human/meshes/CAD/shoulder_left_link2.stl</uri>
						<scale>0.001 0.001 0.001</scale>
					</mesh>
				</geometry>
			</visual>
		</link>
		<link name="elbow_left_link1">
			<self_collide>false</self_collide>
			<pose frame="">0.22277909562924003 0.09090793509010708 1.137018904082981 0.0 -0.0 0.0</pose>
			<inertial>
				<pose frame="">0.0 0.0 0.0 0 0 0</pose>
				<mass>0.06979038134801813</mass>
				<inertia>
					<ixx>0.0908142542932374</ixx>
					<ixy>-0.001413421851361933</ixy>
					<ixz>-0.01767818576947713</ixz>
					<iyy>0.0937012222459907</iyy>
					<iyz>-0.007213815820121099</iyz>
					<izz>0.0040521459201491574</izz>
				</inertia>
			</inertial>
			<collision name="elbow_left_link1_collision">
				<geometry>
					<mesh>
						<uri>model://human/meshes/CAD/elbow_left_link1.stl</uri>
						<scale>0.001 0.001 0.001</scale>
					</mesh>
				</geometry>
			</collision>
			<visual name="elbow_left_link1_visual">
				<geometry>
					<mesh>
						<uri>model://human/meshes/CAD/elbow_left_link1.stl</uri>
						<scale>0.001 0.001 0.001</scale>
					</mesh>
				</geometry>
			</visual>
		</link>
		<link name="elbow_left_link2">
			<self_collide>false</self_collide>
			<pose frame="">0.22277909562924225 0.09090793509010714 1.137018904082981 0.0 -0.0 0.0</pose>
			<inertial>
				<pose frame="">0.0 0.0 0.0 0 0 0</pose>
				<mass>0.046782558357131146</mass>
				<inertia>
					<ixx>0.06087293660071612</ixx>
					<ixy>-0.0009474585031259807</ixy>
					<ixz>-0.011850211181461947</ixz>
					<iyy>0.06280815667139264</iyy>
					<iyz>-0.004835634267414628</iyz>
					<izz>0.002713727269113893</izz>
				</inertia>
			</inertial>
			<collision name="elbow_left_link2_collision">
				<geometry>
					<mesh>
						<uri>model://human/meshes/CAD/elbow_left_link2.stl</uri>
						<scale>0.001 0.001 0.001</scale>
					</mesh>
				</geometry>
			</collision>
			<visual name="elbow_left_link2_visual">
				<geometry>
					<mesh>
						<uri>model://human/meshes/CAD/elbow_left_link2.stl</uri>
						<scale>0.001 0.001 0.001</scale>
					</mesh>
				</geometry>
			</visual>
		</link>
		<link name="wrist_left_link1">
			<self_collide>false</self_collide>
			<pose frame="">0.2682790956292395 0.07390793509011048 0.8690189040829812 0.0 -0.0 0.0</pose>
			<inertial>
				<pose frame="">0.0 0.0 0.0 0 0 0</pose>
				<mass>0.06979038134801814</mass>
				<inertia>
					<ixx>0.05309813623893281</ixx>
					<ixy>-0.001383800470019896</ixy>
					<ixz>-0.01627090198718209</ixz>
					<iyy>0.05773998455168735</iyy>
					<iyz>-0.004482454233363455</iyz>
					<izz>0.005415939157459651</izz>
				</inertia>
			</inertial>
			<collision name="wrist_left_link1_collision">
				<geometry>
					<mesh>
						<uri>model://human/meshes/CAD/wrist_left_link1.stl</uri>
						<scale>0.001 0.001 0.001</scale>
					</mesh>
				</geometry>
			</collision>
			<visual name="wrist_left_link1_visual">
				<geometry>
					<mesh>
						<uri>model://human/meshes/CAD/wrist_left_link1.stl</uri>
						<scale>0.001 0.001 0.001</scale>
					</mesh>
				</geometry>
			</visual>
		</link>
		<link name="wrist_left_link2">
			<self_collide>false</self_collide>
			<pose frame="">0.2682790956292419 0.0739079350901104 0.8690189040829839 0.0 -0.0 0.0</pose>
			<inertial>
				<pose frame="">0.0 0.0 0.0 0 0 0</pose>
				<mass>0.04678255835713115</mass>
				<inertia>
					<ixx>0.03559070630194095</ixx>
					<ixy>-0.0009276024144431773</ixy>
					<ixz>-0.010906867207713458</ixz>
					<iyy>0.03870227462098355</iyy>
					<iyz>-0.0030047217496892292</iyz>
					<izz>0.003627918243273852</izz>
				</inertia>
			</inertial>
			<collision name="wrist_left_link2_collision">
				<geometry>
					<mesh>
						<uri>model://human/meshes/CAD/wrist_left_link2.stl</uri>
						<scale>0.001 0.001 0.001</scale>
					</mesh>
				</geometry>
			</collision>
			<visual name="wrist_left_link2_visual">
				<geometry>
					<mesh>
						<uri>model://human/meshes/CAD/wrist_left_link2.stl</uri>
						<scale>0.001 0.001 0.001</scale>
					</mesh>
				</geometry>
			</visual>
		</link>
		<link name="knee_left_link1">
			<self_collide>false</self_collide>
			<pose frame="">0.10941629950839385 0.02043018916516386 0.46548412776725095 0.0 -0.0 0.0</pose>
			<inertial>
				<pose frame="">0.0 0.0 0.0 0 0 0</pose>
				<mass>0.06979038134801685</mass>
				<inertia>
					<ixx>0.015162641172061099</ixx>
					<ixy>-0.00015600911813701677</ixy>
					<ixz>-0.0035545323488033803</ixz>
					<iyy>0.015969036504041294</iyy>
					<iyz>-0.0006637015564045489</iyz>
					<izz>0.0008763025911976847</izz>
				</inertia>
			</inertial>
			<collision name="knee_left_link1_collision">
				<geometry>
					<mesh>
						<uri>model://human/meshes/CAD/knee_left_link1.stl</uri>
						<scale>0.001 0.001 0.001</scale>
					</mesh>
				</geometry>
			</collision>
			<visual name="knee_left_link1_visual">
				<geometry>
					<mesh>
						<uri>model://human/meshes/CAD/knee_left_link1.stl</uri>
						<scale>0.001 0.001 0.001</scale>
					</mesh>
				</geometry>
			</visual>
		</link>
		<link name="knee_left_link2">
			<self_collide>false</self_collide>
			<pose frame="">0.10941629950839335 0.02043018922764729 0.4654841278580611 0.0 -0.0 0.0</pose>
			<inertial>
				<pose frame="">0.0 0.0 0.0 0 0 0</pose>
				<mass>0.04678255910498688</mass>
				<inertia>
					<ixx>0.010161421264783936</ixx>
					<ixy>-0.00010457753162414676</ixy>
					<ixz>-0.0023827082832761685</ixz>
					<iyy>0.010701971932920828</iyy>
					<iyz>-0.00044489880689113214</iyz>
					<izz>0.0005848654927451553</izz>
				</inertia>
			</inertial>
			<collision name="knee_left_link2_collision">
				<geometry>
					<mesh>
						<uri>model://human/meshes/CAD/knee_left_link2.stl</uri>
						<scale>0.001 0.001 0.001</scale>
					</mesh>
				</geometry>
			</collision>
			<visual name="knee_left_link2_visual">
				<geometry>
					<mesh>
						<uri>model://human/meshes/CAD/knee_left_link2.stl</uri>
						<scale>0.001 0.001 0.001</scale>
					</mesh>
				</geometry>
			</visual>
		</link>
		<link name="foot_left_link1">
			<self_collide>false</self_collide>
			<pose frame="">0.12262700433836339 0.020000000000004788 0.11146497559651634 0.0 -0.0 0.0</pose>
			<inertial>
				<pose frame="">0.0 0.0 0.0 0 0 0</pose>
				<mass>0.06979038134801686</mass>
				<inertia>
					<ixx>0.0009066698906142029</ixx>
					<ixy>-0.00017116370792682686</ixy>
					<ixz>-0.0009539379263534223</ixz>
					<iyy>0.0019282183758004</iyy>
					<iyz>-0.00015558366307660257</iyz>
					<izz>0.0010890280679373208</izz>
				</inertia>
			</inertial>
			<collision name="foot_left_link1_collision">
				<geometry>
					<mesh>
						<uri>model://human/meshes/CAD/foot_left_link1.stl</uri>
						<scale>0.001 0.001 0.001</scale>
					</mesh>
				</geometry>
			</collision>
			<visual name="foot_left_link1_visual">
				<geometry>
					<mesh>
						<uri>model://human/meshes/CAD/foot_left_link1.stl</uri>
						<scale>0.001 0.001 0.001</scale>
					</mesh>
				</geometry>
			</visual>
		</link>
		<link name="foot_left_link2">
			<self_collide>false</self_collide>
			<pose frame="">0.12262700433836336 0.020000000062488227 0.1114649756873257 0.0 -0.0 0.0</pose>
			<inertial>
				<pose frame="">0.0 0.0 0.0 0 0 0</pose>
				<mass>0.0467825591049869</mass>
				<inertia>
					<ixx>0.0006052215936907204</ixx>
					<ixy>-0.00011473610192502215</ixy>
					<ixz>-0.0006394528385786422</ixz>
					<iyy>0.0012899957910911585</iyy>
					<iyz>-0.00010429233662800017</iyz>
					<izz>0.0007274616785849704</izz>
				</inertia>
			</inertial>
			<collision name="foot_left_link2_collision">
				<geometry>
					<mesh>
						<uri>model://human/meshes/CAD/foot_left_link2.stl</uri>
						<scale>0.001 0.001 0.001</scale>
					</mesh>
				</geometry>
			</collision>
			<visual name="foot_left_link2_visual">
				<geometry>
					<mesh>
						<uri>model://human/meshes/CAD/foot_left_link2.stl</uri>
						<scale>0.001 0.001 0.001</scale>
					</mesh>
				</geometry>
			</visual>
		</link>
		<link name="hip_left_link1">
			<self_collide>false</self_collide>
			<pose frame="">0.10441629950839185 0.02043018916516427 0.8954841277672543 0.0 -0.0 0.0</pose>
			<inertial>
				<pose frame="">0.0 0.0 0.0 0 0 0</pose>
				<mass>0.06979038134801682</mass>
				<inertia>
					<ixx>0.056005113401269686</ixx>
					<ixy>-0.00014887996467277244</ixy>
					<ixz>-0.006525619720366656</ixz>
					<iyy>0.05673689144009975</iyy>
					<iyz>-0.0012768087543296102</iyz>
					<izz>0.0008016852980475604</izz>
				</inertia>
			</inertial>
			<collision name="hip_left_link1_collision">
				<geometry>
					<mesh>
						<uri>model://human/meshes/CAD/hip_left_link1.stl</uri>
						<scale>0.001 0.001 0.001</scale>
					</mesh>
				</geometry>
			</collision>
			<visual name="hip_left_link1_visual">
				<geometry>
					<mesh>
						<uri>model://human/meshes/CAD/hip_left_link1.stl</uri>
						<scale>0.001 0.001 0.001</scale>
					</mesh>
				</geometry>
			</visual>
		</link>
		<link name="hip_left_link2">
			<self_collide>false</self_collide>
			<pose frame="">0.10441629950839289 0.020430189227647763 0.8954841278580636 0.0 -0.0 0.0</pose>
			<inertial>
				<pose frame="">0.0 0.0 0.0 0 0 0</pose>
				<mass>0.04678255910498687</mass>
				<inertia>
					<ixx>0.037539339745895815</ixx>
					<ixy>-9.979864894880639e-05</ixy>
					<ixz>-0.00437431612206483</ixz>
					<iyy>0.03802987223302232</iyy>
					<iyz>-0.0008558827169705971</iyz>
					<izz>0.0005348473117347727</izz>
				</inertia>
			</inertial>
			<collision name="hip_left_link2_collision">
				<geometry>
					<mesh>
						<uri>model://human/meshes/CAD/hip_left_link2.stl</uri>
						<scale>0.001 0.001 0.001</scale>
					</mesh>
				</geometry>
			</collision>
			<visual name="hip_left_link2_visual">
				<geometry>
					<mesh>
						<uri>model://human/meshes/CAD/hip_left_link2.stl</uri>
						<scale>0.001 0.001 0.001</scale>
					</mesh>
				</geometry>
			</visual>
		</link>
		<link name="neck_link1">
			<self_collide>false</self_collide>
			<pose frame="">-0.002779095629307454 0.029907935090094064 1.6100189040829918 0.0 -0.0 0.0</pose>
			<inertial>
				<pose frame="">0.0 0.0 0.0 0 0 0</pose>
				<mass>0.06979038134801685</mass>
				<inertia>
					<ixx>0.1809819694354287</ixx>
					<ixy>5.800767942386892e-06</ixy>
					<ixz>0.0003122698379981084</ixz>
					<iyy>0.18092008203249943</iyy>
					<iyz>-0.0033605702326151973</iyz>
					<izz>7.461271482849317e-05</izz>
				</inertia>
			</inertial>
			<collision name="neck_link1_collision">
				<geometry>
					<mesh>
						<uri>model://human/meshes/CAD/neck_link1.stl</uri>
						<scale>0.001 0.001 0.001</scale>
					</mesh>
				</geometry>
			</collision>
			<visual name="neck_link1_visual">
				<geometry>
					<mesh>
						<uri>model://human/meshes/CAD/neck_link1.stl</uri>
						<scale>0.001 0.001 0.001</scale>
					</mesh>
				</geometry>
			</visual>
		</link>
		<link name="neck_link2">
			<self_collide>false</self_collide>
			<pose frame="">-0.0027790956293067383 0.0299079350276108 1.610018903992183 0.0 -0.0 0.0</pose>
			<inertial>
				<pose frame="">0.0 0.0 0.0 0 0 0</pose>
				<mass>0.04678255760927329</mass>
				<inertia>
					<ixx>0.12131502299970208</ixx>
					<ixy>3.888426379596355e-06</ixy>
					<ixz>0.00020932371198989497</ixz>
					<iyy>0.12127353804260783</iyy>
					<iyz>-0.0022526896562351643</iyz>
					<izz>4.746902886236099e-05</izz>
				</inertia>
			</inertial>
			<collision name="neck_link2_collision">
				<geometry>
					<mesh>
						<uri>model://human/meshes/CAD/neck_link2.stl</uri>
						<scale>0.001 0.001 0.001</scale>
					</mesh>
				</geometry>
			</collision>
			<visual name="neck_link2_visual">
				<geometry>
					<mesh>
						<uri>model://human/meshes/CAD/neck_link2.stl</uri>
						<scale>0.001 0.001 0.001</scale>
					</mesh>
				</geometry>
			</visual>
		</link>
		<link name="lower_leg_right">
			<self_collide>false</self_collide>
			<pose frame="">-0.1142164112603577 0.03766314571861082 0.3281766077120575 0.0 -0.0 0.0</pose>
			<inertial>
				<pose frame="">0.0 0.0 0.0 0 0 0</pose>
				<mass>27.229177078483698</mass>
				<inertia>
					<ixx>3.2626206523749337</ixx>
					<ixy>0.11542833244609388</ixy>
					<ixz>1.0123019424894697</ixz>
					<iyy>3.5682556618743053</iyy>
					<iyz>-0.3299525486438061</iyz>
					<izz>0.4403383220330142</izz>
				</inertia>
			</inertial>
			<collision name="lower_leg_right_collision">
				<geometry>
					<mesh>
						<uri>model://human/meshes/CAD/lower_leg_right.stl</uri>
						<scale>0.001 0.001 0.001</scale>
					</mesh>
				</geometry>
			</collision>
			<visual name="lower_leg_right_visual">
				<geometry>
					<mesh>
						<uri>model://human/meshes/CAD/lower_leg_right.stl</uri>
						<scale>0.001 0.001 0.001</scale>
					</mesh>
				</geometry>
			</visual>
		</link>
		<link name="foot_right">
			<self_collide>false</self_collide>
			<pose frame="">-0.1226269909231338 0.02000001627163421 0.11085911144948236 0.0 -0.0 0.0</pose>
			<inertial>
				<pose frame="">0.0 0.0 0.0 0 0 0</pose>
				<mass>0.27957129819968174</mass>
				<inertia>
					<ixx>0.0035921261608274245</ixx>
					<ixy>0.0006856602948312347</ixy>
					<ixz>0.0038005815545695564</ixz>
					<iyy>0.00768431681532605</iyy>
					<iyz>-0.0006198609301855902</iyz>
					<izz>0.004358207434796413</izz>
				</inertia>
			</inertial>
			<collision name="foot_right_collision">
				<geometry>
					<mesh>
						<uri>model://human/meshes/CAD/foot_right.stl</uri>
						<scale>0.001 0.001 0.001</scale>
					</mesh>
				</geometry>
			</collision>
			<visual name="foot_right_visual">
				<geometry>
					<mesh>
						<uri>model://human/meshes/CAD/foot_right.stl</uri>
						<scale>0.001 0.001 0.001</scale>
					</mesh>
				</geometry>
			</visual>
		</link>
		<link name="upper_leg_right">
			<self_collide>false</self_collide>
			<pose frame="">-0.10923361613810233 0.01314414061942326 0.742390053697992 0.0 -0.0 0.0</pose>
			<inertial>
				<pose frame="">0.0 0.0 0.0 0 0 0</pose>
				<mass>63.39048809535572</mass>
				<inertia>
					<ixx>36.04145362577871</ixx>
					<ixy>0.08398443387069625</ixy>
					<ixz>5.149072361637548</ixz>
					<iyy>36.73060594220727</iyy>
					<iyz>-0.6479750897148607</iyz>
					<izz>0.9612344348733743</izz>
				</inertia>
			</inertial>
			<collision name="upper_leg_right_collision">
				<geometry>
					<mesh>
						<uri>model://human/meshes/CAD/upper_leg_right.stl</uri>
						<scale>0.001 0.001 0.001</scale>
					</mesh>
				</geometry>
			</collision>
			<visual name="upper_leg_right_visual">
				<geometry>
					<mesh>
						<uri>model://human/meshes/CAD/upper_leg_right.stl</uri>
						<scale>0.001 0.001 0.001</scale>
					</mesh>
				</geometry>
			</visual>
		</link>
		<link name="chest">
			<self_collide>false</self_collide>
			<pose frame="">-0.002916133514134312 0.02473110771132084 1.3448244742154645 0.0 -0.0 0.0</pose>
			<inertial>
				<pose frame="">0.0 0.0 0.0 0 0 0</pose>
				<mass>2.0895121123827427</mass>
				<inertia>
					<ixx>3.9474837447924243</ixx>
					<ixy>0.00012846466220939486</ixy>
					<ixz>0.008214942167101209</ixz>
					<iyy>3.9524864442069267</iyy>
					<iyz>-0.07024839489432631</iyz>
					<izz>0.008991766641741568</izz>
				</inertia>
			</inertial>
			<collision name="chest_collision">
				<geometry>
					<mesh>
						<uri>model://human/meshes/CAD/chest.stl</uri>
						<scale>0.001 0.001 0.001</scale>
					</mesh>
				</geometry>
			</collision>
			<visual name="chest_visual">
				<geometry>
					<mesh>
						<uri>model://human/meshes/CAD/chest.stl</uri>
						<scale>0.001 0.001 0.001</scale>
					</mesh>
				</geometry>
			</visual>
		</link>
		<link name="upper_arm_right">
			<self_collide>false</self_collide>
			<pose frame="">-0.2158929447668363 0.08721460705246126 1.1745802516822599 0.0 -0.0 0.0</pose>
			<inertial>
				<pose frame="">0.0 0.0 0.0 0 0 0</pose>
				<mass>0.11563826303369742</mass>
				<inertia>
					<ixx>0.1614303206612466</ixx>
					<ixy>0.0021960356684295745</ixy>
					<ixz>0.029135587681741404</ixz>
					<iyy>0.16596830464103818</iyy>
					<iyz>-0.011749159586960123</iyz>
					<izz>0.006339252507454719</izz>
				</inertia>
			</inertial>
			<collision name="upper_arm_right_collision">
				<geometry>
					<mesh>
						<uri>model://human/meshes/CAD/upper_arm_right.stl</uri>
						<scale>0.001 0.001 0.001</scale>
					</mesh>
				</geometry>
			</collision>
			<visual name="upper_arm_right_visual">
				<geometry>
					<mesh>
						<uri>model://human/meshes/CAD/upper_arm_right.stl</uri>
						<scale>0.001 0.001 0.001</scale>
					</mesh>
				</geometry>
			</visual>
		</link>
		<link name="lower_arm_right">
			<self_collide>false</self_collide>
			<pose frame="">-0.26060744348911713 0.07635579886000855 0.9072943437529074 0.0 -0.0 0.0</pose>
			<inertial>
				<pose frame="">0.0 0.0 0.0 0 0 0</pose>
				<mass>0.11563826303369745</mass>
				<inertia>
					<ixx>0.09690943015247781</ixx>
					<ixy>0.002287632401748886</ixy>
					<ixz>0.0271295703484379</ixz>
					<iyy>0.10413046605259298</iyy>
					<iyz>-0.00807550363283824</iyz>
					<izz>0.008600502676070716</izz>
				</inertia>
			</inertial>
			<collision name="lower_arm_right_collision">
				<geometry>
					<mesh>
						<uri>model://human/meshes/CAD/lower_arm_right.stl</uri>
						<scale>0.001 0.001 0.001</scale>
					</mesh>
				</geometry>
			</collision>
			<visual name="lower_arm_right_visual">
				<geometry>
					<mesh>
						<uri>model://human/meshes/CAD/lower_arm_right.stl</uri>
						<scale>0.001 0.001 0.001</scale>
					</mesh>
				</geometry>
			</visual>
		</link>
		<link name="hand_right">
			<self_collide>false</self_collide>
			<pose frame="">-0.25802299979347026 0.07390821053699395 0.8690191311766213 0.0 -0.0 0.0</pose>
			<inertial>
				<pose frame="">0.0 0.0 0.0 0 0 0</pose>
				<mass>0.016515273339096425</mass>
				<inertia>
					<ixx>0.012562723115436644</ixx>
					<ixy>0.0003149465186986404</ixy>
					<ixz>0.0037031688885040496</ixz>
					<iyy>0.013572472574863216</iyy>
					<iyz>-0.0010607371815798486</iyz>
					<izz>0.00119044671045102</izz>
				</inertia>
			</inertial>
			<collision name="hand_right_collision">
				<geometry>
					<mesh>
						<uri>model://human/meshes/CAD/hand_right.stl</uri>
						<scale>0.001 0.001 0.001</scale>
					</mesh>
				</geometry>
			</collision>
			<visual name="hand_right_visual">
				<geometry>
					<mesh>
						<uri>model://human/meshes/CAD/hand_right.stl</uri>
						<scale>0.001 0.001 0.001</scale>
					</mesh>
				</geometry>
			</visual>
		</link>
		<link name="upper_arm_left">
			<self_collide>false</self_collide>
			<pose frame="">0.21823978254645032 0.08717470687284024 1.174580238551715 0.0 -0.0 0.0</pose>
			<inertial>
				<pose frame="">0.0 0.0 0.0 0 0 0</pose>
				<mass>0.11563830149074954</mass>
				<inertia>
					<ixx>0.1614295320703429</ixx>
					<ixy>-0.0022108719689598565</ixy>
					<ixz>-0.02953326122573156</ixz>
					<iyy>0.16606217234042916</iyy>
					<iyz>-0.011743914821209534</iyz>
					<izz>0.006432232515683653</izz>
				</inertia>
			</inertial>
			<collision name="upper_arm_left_collision">
				<geometry>
					<mesh>
						<uri>model://human/meshes/CAD/upper_arm_left.stl</uri>
						<scale>0.001 0.001 0.001</scale>
					</mesh>
				</geometry>
			</collision>
			<visual name="upper_arm_left_visual">
				<geometry>
					<mesh>
						<uri>model://human/meshes/CAD/upper_arm_left.stl</uri>
						<scale>0.001 0.001 0.001</scale>
					</mesh>
				</geometry>
			</visual>
		</link>
		<link name="lower_arm_left">
			<self_collide>false</self_collide>
			<pose frame="">0.2629542815299026 0.0763158966380528 0.9072943303848884 0.0 -0.0 0.0</pose>
			<inertial>
				<pose frame="">0.0 0.0 0.0 0 0 0</pose>
				<mass>0.11563830149074963</mass>
				<inertia>
					<ixx>0.09690877691623691</ixx>
					<ixy>-0.0023122121352921357</ixy>
					<ixz>-0.027456206005126656</ixz>
					<iyy>0.10424528351701823</iyy>
					<iyz>-0.008071493904890415</iyz>
					<izz>0.00871460907519445</izz>
				</inertia>
			</inertial>
			<collision name="lower_arm_left_collision">
				<geometry>
					<mesh>
						<uri>model://human/meshes/CAD/lower_arm_left.stl</uri>
						<scale>0.001 0.001 0.001</scale>
					</mesh>
				</geometry>
			</collision>
			<visual name="lower_arm_left_visual">
				<geometry>
					<mesh>
						<uri>model://human/meshes/CAD/lower_arm_left.stl</uri>
						<scale>0.001 0.001 0.001</scale>
					</mesh>
				</geometry>
			</visual>
		</link>
		<link name="hand_left">
			<self_collide>false</self_collide>
			<pose frame="">0.27853519146500794 0.07390765964322622 0.8690191311766101 0.0 -0.0 0.0</pose>
			<inertial>
				<pose frame="">0.0 0.0 0.0 0 0 0</pose>
				<mass>0.016515273339096418</mass>
				<inertia>
					<ixx>0.01256272177058372</ixx>
					<ixy>-0.0003399814589991388</ixy>
					<ixz>-0.00399756175155226</ixz>
					<iyy>0.013754239416619133</iyy>
					<iyz>-0.0010607292672196534</iyz>
					<izz>0.0013722122073546437</izz>
				</inertia>
			</inertial>
			<collision name="hand_left_collision">
				<geometry>
					<mesh>
						<uri>model://human/meshes/CAD/hand_left.stl</uri>
						<scale>0.001 0.001 0.001</scale>
					</mesh>
				</geometry>
			</collision>
			<visual name="hand_left_visual">
				<geometry>
					<mesh>
						<uri>model://human/meshes/CAD/hand_left.stl</uri>
						<scale>0.001 0.001 0.001</scale>
					</mesh>
				</geometry>
			</visual>
		</link>
		<link name="upper_leg_left">
			<self_collide>false</self_collide>
			<pose frame="">0.10302389137863152 0.013133059321610177 0.7422474815580153 0.0 -0.0 0.0</pose>
			<inertial>
				<pose frame="">0.0 0.0 0.0 0 0 0</pose>
				<mass>63.325475265879184</mass>
				<inertia>
					<ixx>35.99086872292955</ixx>
					<ixy>-0.0786500679859208</ixy>
					<ixz>-4.850691981704141</ixz>
					<iyy>36.59583010936491</iyy>
					<iyz>-0.6465918049622089</iyz>
					<izz>0.8769563939878825</izz>
				</inertia>
			</inertial>
			<collision name="upper_leg_left_collision">
				<geometry>
					<mesh>
						<uri>model://human/meshes/CAD/upper_leg_left.stl</uri>
						<scale>0.001 0.001 0.001</scale>
					</mesh>
				</geometry>
			</collision>
			<visual name="upper_leg_left_visual">
				<geometry>
					<mesh>
						<uri>model://human/meshes/CAD/upper_leg_left.stl</uri>
						<scale>0.001 0.001 0.001</scale>
					</mesh>
				</geometry>
			</visual>
		</link>
		<link name="lower_leg_left">
			<self_collide>false</self_collide>
			<pose frame="">0.10835573006014868 0.036757247321291285 0.31881340704912275 0.0 -0.0 0.0</pose>
			<inertial>
				<pose frame="">0.0 0.0 0.0 0 0 0</pose>
				<mass>28.437794425853458</mass>
				<inertia>
					<ixx>3.277717752725288</ixx>
					<ixy>-0.11136513791797928</ixy>
					<ixz>-0.9718949461416362</ixz>
					<iyy>3.5617770388517136</iyy>
					<iyz>-0.3321020557635479</iyz>
					<izz>0.4200171787126586</izz>
				</inertia>
			</inertial>
			<collision name="lower_leg_left_collision">
				<geometry>
					<mesh>
						<uri>model://human/meshes/CAD/lower_leg_left.stl</uri>
						<scale>0.001 0.001 0.001</scale>
					</mesh>
				</geometry>
			</collision>
			<visual name="lower_leg_left_visual">
				<geometry>
					<mesh>
						<uri>model://human/meshes/CAD/lower_leg_left.stl</uri>
						<scale>0.001 0.001 0.001</scale>
					</mesh>
				</geometry>
			</visual>
		</link>
		<link name="foot_left">
			<self_collide>false</self_collide>
			<pose frame="">0.11678337391556814 0.01999998372837581 0.10993444486070424 0.0 -0.0 0.0</pose>
			<inertial>
				<pose frame="">0.0 0.0 0.0 0 0 0</pose>
				<mass>0.27957129819968174</mass>
				<inertia>
					<ixx>0.003535852247798972</ixx>
					<ixy>-0.0006529850351774065</ixy>
					<ixz>-0.0035904892616794295</ixz>
					<iyy>0.007237516059558897</iyy>
					<iyz>-0.0006146897112867636</iyz>
					<izz>0.003967679864204833</izz>
				</inertia>
			</inertial>
			<collision name="foot_left_collision">
				<geometry>
					<mesh>
						<uri>model://human/meshes/CAD/foot_left.stl</uri>
						<scale>0.001 0.001 0.001</scale>
					</mesh>
				</geometry>
			</collision>
			<visual name="foot_left_visual">
				<geometry>
					<mesh>
						<uri>model://human/meshes/CAD/foot_left.stl</uri>
						<scale>0.001 0.001 0.001</scale>
					</mesh>
				</geometry>
			</visual>
		</link>
		<link name="head">
			<self_collide>false</self_collide>
			<pose frame="">-0.0031270906408866696 0.01669789662623116 1.654228822555002 0.0 -0.0 0.0</pose>
			<inertial>
				<pose frame="">0.0 0.0 0.0 0 0 0</pose>
				<mass>35.90636554635465</mass>
				<inertia>
					<ixx>98.46428610030569</ixx>
					<ixy>0.0018125397861483905</ixy>
					<ixz>0.18554310178823422</ixz>
					<iyy>98.40157541220677</iyy>
					<iyz>-1.0198764831213685</iyz>
					<izz>0.16733682760579385</izz>
				</inertia>
			</inertial>
			<collision name="head_collision">
				<geometry>
					<mesh>
						<uri>model://human/meshes/CAD/head.stl</uri>
						<scale>0.001 0.001 0.001</scale>
					</mesh>
				</geometry>
			</collision>
			<visual name="head_visual">
				<geometry>
					<mesh>
						<uri>model://human/meshes/CAD/head.stl</uri>
						<scale>0.001 0.001 0.001</scale>
					</mesh>
				</geometry>
			</visual>
		</link>
		<link name="hip">
			<self_collide>false</self_collide>
			<pose frame="">-0.003093334757331421 0.01939459667419104 0.9505141664226162 0.0 -0.0 0.0</pose>
			<inertial>
				<pose frame="">0.0 0.0 0.0 0 0 0</pose>
				<mass>43.179386177175836</mass>
				<inertia>
					<ixx>39.26125010746488</ixx>
					<ixy>0.0024988656640630527</ixy>
					<ixz>0.126376977275437</ixz>
					<iyy>39.27514677988692</iyy>
					<iyz>-0.7913062051966586</iyz>
					<izz>0.30056932761275523</izz>
				</inertia>
			</inertial>
			<collision name="hip_collision">
				<geometry>
					<mesh>
						<uri>model://human/meshes/CAD/hip.stl</uri>
						<scale>0.001 0.001 0.001</scale>
					</mesh>
				</geometry>
			</collision>
			<visual name="hip_visual">
				<geometry>
					<mesh>
						<uri>model://human/meshes/CAD/hip.stl</uri>
						<scale>0.001 0.001 0.001</scale>
					</mesh>
				</geometry>
			</visual>
		</link>
		<joint name="hip_right_axis0" type="revolute">
			<parent>hip</parent>
			<child>hip_right_link1</child>
			<pose frame="">-2.842170943040401e-16 -4.884981308350689e-17 3.4106051316484808e-15 0 0 0</pose>
			<axis>
				<xyz>0.9999999999999997 4.2500725161431646e-16 -2.2343238370581173e-15</xyz>
				<limit>
					<lower>-3.141592653589793</lower>
					<upper>3.141592653589793</upper>
				</limit>
				<use_parent_model_frame>0</use_parent_model_frame>
			</axis>
		</joint>
		<joint name="hip_right_axis2" type="revolute">
			<parent>hip_right_link2</parent>
			<child>upper_leg_right</child>
			<pose frame="">0.004817316629713649 0.0072860485457411014 0.15309407406925998 0 0 0</pose>
			<axis>
				<xyz>-2.917023895426859e-17 1.376760001370904e-14 -1.0</xyz>
				<limit>
					<lower>-3.141592653589793</lower>
					<upper>3.141592653589793</upper>
				</limit>
				<use_parent_model_frame>0</use_parent_model_frame>
			</axis>
		</joint>
		<joint name="hip_right_axis1" type="revolute">
			<parent>hip_right_link1</parent>
			<child>hip_right_link2</child>
			<pose frame="">-2.913225216616411e-15 6.24833829121485e-11 9.080821428142372e-11 0 0 0</pose>
			<axis>
				<xyz>-2.5847379792051265e-16 1.0 1.3732071035832402e-14</xyz>
				<limit>
					<lower>-3.141592653589793</lower>
					<upper>3.141592653589793</upper>
				</limit>
				<use_parent_model_frame>0</use_parent_model_frame>
			</axis>
		</joint>
		<joint name="foot_right_axis0" type="revolute">
			<parent>lower_leg_right</parent>
			<child>ankle_right_link1</child>
			<pose frame="">-4.440892098500626e-16 0.0 2.451372438372346e-15 0 0 0</pose>
			<axis>
				<xyz>1.0 -8.981190387175154e-31 -2.220446049250303e-15</xyz>
				<limit>
					<lower>-3.141592653589793</lower>
					<upper>3.141592653589793</upper>
				</limit>
				<use_parent_model_frame>0</use_parent_model_frame>
			</axis>
		</joint>
		<joint name="foot_right_axis2" type="revolute">
			<parent>ankle_right_link2</parent>
			<child>foot_right</child>
			<pose frame="">-1.3415229531688055e-08 -1.6271629417197177e-08 0.0006058641470340476 0 0 0</pose>
			<axis>
				<xyz>-3.944304526105243e-31 1.374594882364021e-14 -0.9999999999999998</xyz>
				<limit>
					<lower>-3.141592653589793</lower>
					<upper>3.141592653589793</upper>
				</limit>
				<use_parent_model_frame>0</use_parent_model_frame>
			</axis>
		</joint>
		<joint name="foot_right_axis1" type="revolute">
			<parent>ankle_right_link1</parent>
			<child>ankle_right_link2</child>
			<pose frame="">-3.552713678800501e-17 6.248342510062344e-11 9.08091379869802e-11 0 0 0</pose>
			<axis>
				<xyz>3.1420256797366275e-29 0.9999999999999998 1.3745948823640213e-14</xyz>
				<limit>
					<lower>-3.141592653589793</lower>
					<upper>3.141592653589793</upper>
				</limit>
				<use_parent_model_frame>0</use_parent_model_frame>
			</axis>
		</joint>
		<joint name="knee_right_axis0" type="revolute">
			<parent>upper_leg_right</parent>
			<child>knee_right_link1</child>
			<pose frame="">-4.085620730620576e-16 -4.440892098500626e-18 3.126388037344441e-15 0 0 0</pose>
			<axis>
				<xyz>0.9999999999999996 4.180683577104098e-16 -2.2343238370581173e-15</xyz>
				<limit>
					<lower>-3.141592653589793</lower>
					<upper>3.141592653589793</upper>
				</limit>
				<use_parent_model_frame>0</use_parent_model_frame>
			</axis>
		</joint>
		<joint name="knee_right_axis2" type="revolute">
			<parent>knee_right_link2</parent>
			<child>lower_leg_right</child>
			<pose frame="">0.004800111751964415 -0.017232956553446956 0.13730752005519428 0 0 0</pose>
			<axis>
				<xyz>-2.9170238954268624e-17 1.376760001370899e-14 -0.9999999999999998</xyz>
				<limit>
					<lower>-3.141592653589793</lower>
					<upper>3.141592653589793</upper>
				</limit>
				<use_parent_model_frame>0</use_parent_model_frame>
			</axis>
		</joint>
		<joint name="knee_right_axis1" type="revolute">
			<parent>knee_right_link1</parent>
			<child>knee_right_link2</child>
			<pose frame="">-6.039613253960852e-16 6.248344508463787e-11 9.08085695527916e-11 0 0 0</pose>
			<axis>
				<xyz>-2.5153490401660533e-16 0.9999999999999998 1.3732071035832397e-14</xyz>
				<limit>
					<lower>-3.141592653589793</lower>
					<upper>3.141592653589793</upper>
				</limit>
				<use_parent_model_frame>0</use_parent_model_frame>
			</axis>
		</joint>
		<joint name="shoulder_right_axis0" type="revolute">
			<parent>chest</parent>
			<child>shoulder_right_link1</child>
			<pose frame="">-4.0145664570445665e-15 9.769962616701378e-17 0.0 0 0 0</pose>
			<axis>
				<xyz>-2.4821811273056937e-13 -1.3346308960332139e-14 1.000000000000005</xyz>
				<limit>
					<lower>-3.141592653589793</lower>
					<upper>3.141592653589793</upper>
				</limit>
				<use_parent_model_frame>0</use_parent_model_frame>
			</axis>
		</joint>
		<joint name="shoulder_right_axis2" type="revolute">
			<parent>shoulder_right_link2</parent>
			<child>upper_arm_right</child>
			<pose frame="">0.033113849137527185 -0.022306671962357482 0.22543865240073302 0 0 0</pose>
			<axis>
				<xyz>1.0 1.0267234056411306e-16 2.50716114535976e-13</xyz>
				<limit>
					<lower>-3.141592653589793</lower>
					<upper>3.141592653589793</upper>
				</limit>
				<use_parent_model_frame>0</use_parent_model_frame>
			</axis>
		</joint>
		<joint name="shoulder_right_axis1" type="revolute">
			<parent>shoulder_right_link1</parent>
			<child>shoulder_right_link2</child>
			<pose frame="">3.304023721284466e-15 2.6645352591003756e-16 -5.684341886080802e-16 0 0 0</pose>
			<axis>
				<xyz>-8.544045600203017e-17 1.0000000000000024 1.402739820058213e-14</xyz>
				<limit>
					<lower>-3.141592653589793</lower>
					<upper>3.141592653589793</upper>
				</limit>
				<use_parent_model_frame>0</use_parent_model_frame>
			</axis>
		</joint>
		<joint name="spine_axis0" type="revolute">
			<parent>hip</parent>
			<child>spine_link1</child>
			<pose frame="">-1.8984813721090176e-16 -3.552713678800501e-17 3.836930773104541e-15 0 0 0</pose>
			<axis>
				<xyz>1.000000000000005 6.736891369063674e-16 -2.1197893720368185e-15</xyz>
				<limit>
					<lower>-3.141592653589793</lower>
					<upper>3.141592653589793</upper>
				</limit>
				<use_parent_model_frame>0</use_parent_model_frame>
			</axis>
		</joint>
		<joint name="spine_axis2" type="revolute">
			<parent>spine_link2</parent>
			<child>chest</child>
			<pose frame="">0.00013703788482884394 -0.004823172621217853 -0.3148055701324745 0 0 0</pose>
			<axis>
				<xyz>2.1688924369416723e-16 1.391195659261643e-14 -0.9999999999999997</xyz>
				<limit>
					<lower>-3.141592653589793</lower>
					<upper>3.141592653589793</upper>
				</limit>
				<use_parent_model_frame>0</use_parent_model_frame>
			</axis>
		</joint>
		<joint name="spine_axis1" type="revolute">
			<parent>spine_link1</parent>
			<child>spine_link2</child>
			<pose frame="">-1.0363931934875837e-15 6.248340289616294e-11 9.080807217287657e-11 0 0 0</pose>
			<axis>
				<xyz>7.400103343714163e-18 1.0000000000000024 1.3894724708050838e-14</xyz>
				<limit>
					<lower>-3.141592653589793</lower>
					<upper>3.141592653589793</upper>
				</limit>
				<use_parent_model_frame>0</use_parent_model_frame>
			</axis>
		</joint>
		<joint name="elbow_right_axis0" type="revolute">
			<parent>upper_arm_right</parent>
			<child>elbow_right_link1</child>
			<pose frame="">-3.588240815588506e-15 1.7763568394002506e-16 -2.842170943040401e-16 0 0 0</pose>
			<axis>
				<xyz>-2.482181127305694e-13 -1.3339370066427911e-14 1.000000000000005</xyz>
				<limit>
					<lower>-3.141592653589793</lower>
					<upper>3.141592653589793</upper>
				</limit>
				<use_parent_model_frame>0</use_parent_model_frame>
			</axis>
		</joint>
		<joint name="elbow_right_axis2" type="revolute">
			<parent>elbow_right_link2</parent>
			<child>lower_arm_right</child>
			<pose frame="">0.03782834785987482 0.014552136230098309 0.22972456033007363 0 0 0</pose>
			<axis>
				<xyz>0.9999999999999986 8.879455281983275e-17 2.5071611453597593e-13</xyz>
				<limit>
					<lower>-3.141592653589793</lower>
					<upper>3.141592653589793</upper>
				</limit>
				<use_parent_model_frame>0</use_parent_model_frame>
			</axis>
		</joint>
		<joint name="elbow_right_axis1" type="revolute">
			<parent>elbow_right_link1</parent>
			<child>elbow_right_link2</child>
			<pose frame="">3.0908609005564358e-15 1.0658141036401502e-16 -5.684341886080802e-16 0 0 0</pose>
			<axis>
				<xyz>-7.156266817764565e-17 1.0000000000000004 1.4020459306677995e-14</xyz>
				<limit>
					<lower>-3.141592653589793</lower>
					<upper>3.141592653589793</upper>
				</limit>
				<use_parent_model_frame>0</use_parent_model_frame>
			</axis>
		</joint>
		<joint name="wrist_left_axis0" type="revolute">
			<parent>lower_arm_left</parent>
			<child>wrist_left_link1</child>
			<pose frame="">2.2382096176443156e-15 -3.907985046680551e-16 2.1316282072803005e-15 0 0 0</pose>
			<axis>
				<xyz>-2.530475828876854e-13 1.351978130792962e-14 -1.000000000000005</xyz>
				<limit>
					<lower>-3.141592653589793</lower>
					<upper>3.141592653589793</upper>
				</limit>
				<use_parent_model_frame>0</use_parent_model_frame>
			</axis>
		</joint>
		<joint name="wrist_left_axis2" type="revolute">
			<parent>wrist_left_link2</parent>
			<child>hand_left</child>
			<pose frame="">-0.010256095835765961 2.7544688388836394e-07 -2.2709362653472454e-07 0 0 0</pose>
			<axis>
				<xyz>0.9999999999999986 -3.328340158902757e-17 -2.5071611453597603e-13</xyz>
				<limit>
					<lower>-3.141592653589793</lower>
					<upper>3.141592653589793</upper>
				</limit>
				<use_parent_model_frame>0</use_parent_model_frame>
			</axis>
		</joint>
		<joint name="wrist_left_axis1" type="revolute">
			<parent>wrist_left_link1</parent>
			<child>wrist_left_link2</child>
			<pose frame="">-3.232969447708456e-15 -8.881784197001253e-17 -3.126388037344441e-15 0 0 0</pose>
			<axis>
				<xyz>-1.605151694599803e-17 -1.0000000000000004 -1.4034337094485807e-14</xyz>
				<limit>
					<lower>-3.141592653589793</lower>
					<upper>3.141592653589793</upper>
				</limit>
				<use_parent_model_frame>0</use_parent_model_frame>
			</axis>
		</joint>
		<joint name="elbow_left_axis0" type="revolute">
			<parent>upper_arm_left</parent>
			<child>elbow_left_link1</child>
			<pose frame="">2.2026824808563106e-15 -2.3092638912203257e-16 -4.263256414560601e-16 0 0 0</pose>
			<axis>
				<xyz>-2.5304758288768916e-13 1.3505903520121705e-14 -1.000000000000005</xyz>
				<limit>
					<lower>-3.141592653589793</lower>
					<upper>3.141592653589793</upper>
				</limit>
				<use_parent_model_frame>0</use_parent_model_frame>
			</axis>
		</joint>
		<joint name="elbow_left_axis2" type="revolute">
			<parent>elbow_left_link2</parent>
			<child>lower_arm_left</child>
			<pose frame="">-0.04017518590066026 0.014592038452054057 0.22972457369809263 0 0 0</pose>
			<axis>
				<xyz>0.9999999999999986 -8.879455281983275e-17 -2.5071611453597593e-13</xyz>
				<limit>
					<lower>-3.141592653589793</lower>
					<upper>3.141592653589793</upper>
				</limit>
				<use_parent_model_frame>0</use_parent_model_frame>
			</axis>
		</joint>
		<joint name="ankle_right_axis1" type="revolute">
			<parent>elbow_left_link1</parent>
			<child>elbow_left_link2</child>
			<pose frame="">-3.126388037344441e-15 -2.1316282072803005e-16 -4.263256414560601e-16 0 0 0</pose>
			<axis>
				<xyz>-7.156266817764565e-17 -1.0000000000000004 -1.4020459306677995e-14</xyz>
				<limit>
					<lower>-3.141592653589793</lower>
					<upper>3.141592653589793</upper>
				</limit>
				<use_parent_model_frame>0</use_parent_model_frame>
			</axis>
		</joint>
		<joint name="shoulder_left_axis0" type="revolute">
			<parent>chest</parent>
			<child>shoulder_left_link1</child>
			<pose frame="">2.806643806252396e-15 -2.220446049250313e-16 1.4210854715202005e-15 0 0 0</pose>
			<axis>
				<xyz>-2.530475828876892e-13 1.3512842414025933e-14 -1.000000000000005</xyz>
				<limit>
					<lower>-3.141592653589793</lower>
					<upper>3.141592653589793</upper>
				</limit>
				<use_parent_model_frame>0</use_parent_model_frame>
			</axis>
		</joint>
		<joint name="shoulder_left_axis2" type="revolute">
			<parent>shoulder_left_link2</parent>
			<child>upper_arm_left</child>
			<pose frame="">-0.03546068691714119 -0.02226677178273647 0.22543866553127787 0 0 0</pose>
			<axis>
				<xyz>1.0 -1.0267234056411306e-16 -2.50716114535976e-13</xyz>
				<limit>
					<lower>-3.141592653589793</lower>
					<upper>3.141592653589793</upper>
				</limit>
				<use_parent_model_frame>0</use_parent_model_frame>
			</axis>
		</joint>
		<joint name="shoulder_left_axis1" type="revolute">
			<parent>shoulder_left_link1</parent>
			<child>shoulder_left_link2</child>
			<pose frame="">-3.375077994860476e-15 -4.4408920985006264e-17 -1.1368683772161603e-15 0 0 0</pose>
			<axis>
				<xyz>-8.544045600203017e-17 -1.0000000000000024 -1.402739820058213e-14</xyz>
				<limit>
					<lower>-3.141592653589793</lower>
					<upper>3.141592653589793</upper>
				</limit>
				<use_parent_model_frame>0</use_parent_model_frame>
			</axis>
		</joint>
		<joint name="wrist_right_axis0" type="revolute">
			<parent>lower_arm_right</parent>
			<child>wrist_right_link1</child>
			<pose frame="">-3.0908609005564358e-15 1.2434497875801754e-16 2.9842794901924207e-15 0 0 0</pose>
			<axis>
				<xyz>-2.48218112730569e-13 -1.3353247854235727e-14 1.000000000000005</xyz>
				<limit>
					<lower>-3.141592653589793</lower>
					<upper>3.141592653589793</upper>
				</limit>
				<use_parent_model_frame>0</use_parent_model_frame>
			</axis>
		</joint>
		<joint name="wrist_right_axis2" type="revolute">
			<parent>wrist_right_link2</parent>
			<child>hand_right</child>
			<pose frame="">-0.010256095835771717 -2.75446883843955e-07 -2.2709363776129976e-07 0 0 0</pose>
			<axis>
				<xyz>0.9999999999999986 3.328340158902757e-17 2.5071611453597603e-13</xyz>
				<limit>
					<lower>-3.141592653589793</lower>
					<upper>3.141592653589793</upper>
				</limit>
				<use_parent_model_frame>0</use_parent_model_frame>
			</axis>
		</joint>
		<joint name="wrist_right_axis1" type="revolute">
			<parent>wrist_right_link1</parent>
			<child>wrist_right_link2</child>
			<pose frame="">3.197442310920451e-15 2.220446049250313e-16 -2.9842794901924207e-15 0 0 0</pose>
			<axis>
				<xyz>-1.605151694599803e-17 1.0000000000000004 1.4034337094485807e-14</xyz>
				<limit>
					<lower>-3.141592653589793</lower>
					<upper>3.141592653589793</upper>
				</limit>
				<use_parent_model_frame>0</use_parent_model_frame>
			</axis>
		</joint>
		<joint name="knee_left_axis0" type="revolute">
			<parent>upper_leg_left</parent>
			<child>knee_left_link1</child>
			<pose frame="">-5.861977570020827e-16 8.881784197001253e-18 6.394884621840901e-16 0 0 0</pose>
			<axis>
				<xyz>0.9999999999999996 -4.180683577103487e-16 -1.9598976533926182e-17</xyz>
				<limit>
					<lower>-3.141592653589793</lower>
					<upper>3.141592653589793</upper>
				</limit>
				<use_parent_model_frame>0</use_parent_model_frame>
			</axis>
		</joint>
		<joint name="knee_left_axis2" type="revolute">
			<parent>knee_left_link2</parent>
			<child>lower_leg_left</child>
			<pose frame="">0.0010605694482446104 -0.01632705815612743 0.146670720718129 0 0 0</pose>
			<axis>
				<xyz>-2.9170238954268624e-17 -1.376760001370899e-14 0.9999999999999998</xyz>
				<limit>
					<lower>-3.141592653589793</lower>
					<upper>3.141592653589793</upper>
				</limit>
				<use_parent_model_frame>0</use_parent_model_frame>
			</axis>
		</joint>
		<joint name="knee_left_axis1" type="revolute">
			<parent>knee_left_link1</parent>
			<child>knee_left_link2</child>
			<pose frame="">5.329070518200751e-16 -6.248342732106949e-11 -9.081013274681026e-11 0 0 0</pose>
			<axis>
				<xyz>-2.5153490401660533e-16 -0.9999999999999998 -1.3732071035832397e-14</xyz>
				<limit>
					<lower>-3.141592653589793</lower>
					<upper>3.141592653589793</upper>
				</limit>
				<use_parent_model_frame>0</use_parent_model_frame>
			</axis>
		</joint>
		<joint name="foot_left_axis0" type="revolute">
			<parent>lower_leg_left</parent>
			<child>foot_left_link1</child>
			<pose frame="">-3.552713678800501e-17 4.440892098500626e-18 -1.7763568394002505e-17 0 0 0</pose>
			<axis>
				<xyz>1.0 6.194239455601504e-29 -6.123233995736777e-17</xyz>
				<limit>
					<lower>-3.141592653589793</lower>
					<upper>3.141592653589793</upper>
				</limit>
				<use_parent_model_frame>0</use_parent_model_frame>
			</axis>
		</joint>
		<joint name="foot_left_axis2" type="revolute">
			<parent>foot_left_link2</parent>
			<child>foot_left</child>
			<pose frame="">0.005843630422795183 1.627162898198975e-08 0.0015305307358121744 0 0 0</pose>
			<axis>
				<xyz>-3.944304526105243e-31 -1.374594882364021e-14 0.9999999999999998</xyz>
				<limit>
					<lower>-3.141592653589793</lower>
					<upper>3.141592653589793</upper>
				</limit>
				<use_parent_model_frame>0</use_parent_model_frame>
			</axis>
		</joint>
		<joint name="foot_left_axis1" type="revolute">
			<parent>foot_left_link1</parent>
			<child>foot_left_link2</child>
			<pose frame="">-3.552713678800501e-17 -6.248344064374579e-11 -9.080938667693772e-11 0 0 0</pose>
			<axis>
				<xyz>3.1420256797366275e-29 -0.9999999999999998 -1.3745948823640213e-14</xyz>
				<limit>
					<lower>-3.141592653589793</lower>
					<upper>3.141592653589793</upper>
				</limit>
				<use_parent_model_frame>0</use_parent_model_frame>
			</axis>
		</joint>
		<joint name="neck_axis0" type="revolute">
			<parent>chest</parent>
			<child>neck_link1</child>
			<pose frame="">-1.837419105754634e-16 4.884981308350689e-17 3.4106051316484808e-15 0 0 0</pose>
			<axis>
				<xyz>1.0000000000000049 6.73689136906828e-16 -2.119789372036836e-15</xyz>
				<limit>
					<lower>-3.141592653589793</lower>
					<upper>3.141592653589793</upper>
				</limit>
				<use_parent_model_frame>0</use_parent_model_frame>
			</axis>
		</joint>
		<joint name="neck_axis2" type="revolute">
			<parent>neck_link2</parent>
			<child>head</child>
			<pose frame="">0.00034799501158033096 0.013210038463863056 -0.04420991847200924 0 0 0</pose>
			<axis>
				<xyz>2.1688924369418607e-16 -1.0103029524088925e-14 -0.9999999999999997</xyz>
				<limit>
					<lower>-3.141592653589793</lower>
					<upper>3.141592653589793</upper>
				</limit>
				<use_parent_model_frame>0</use_parent_model_frame>
			</axis>
		</joint>
		<joint name="neck_axis1" type="revolute">
			<parent>neck_link1</parent>
			<child>neck_link2</child>
			<pose frame="">-8.887335312124379e-16 6.248329853519863e-11 9.080849849851802e-11 0 0 0</pose>
			<axis>
				<xyz>7.400103344332542e-18 1.0000000000000022 -1.0186296250935811e-14</xyz>
				<limit>
					<lower>-3.141592653589793</lower>
					<upper>3.141592653589793</upper>
				</limit>
				<use_parent_model_frame>0</use_parent_model_frame>
			</axis>
		</joint>
		<joint name="hip_left_axis0" type="revolute">
			<parent>hip</parent>
			<child>upper_leg_left</child>
			<pose frame="">0.0013924081297602342 0.007297129843554113 0.1532366462092388 0 0 0</pose>
			<axis>
				<xyz>0.9999999999999997 -4.2500725161431646e-16 2.2343238370581173e-15</xyz>
				<limit>
					<lower>-3.141592653589793</lower>
					<upper>3.141592653589793</upper>
				</limit>
				<use_parent_model_frame>0</use_parent_model_frame>
			</axis>
		</joint>
		<joint name="hip_leftt_axis2" type="revolute">
			<parent>hip_left_link2</parent>
			<child>upper_leg_left</child>
			<pose frame="">0.001392408129760323 0.0072971298435541175 0.15323664620923894 0 0 0</pose>
			<axis>
				<xyz>2.185554621569935e-15 1.3809233377132487e-14 -1.0</xyz>
				<limit>
					<lower>-3.141592653589793</lower>
					<upper>3.141592653589793</upper>
				</limit>
				<use_parent_model_frame>0</use_parent_model_frame>
			</axis>
		</joint>
		<joint name="hip_left_axis1" type="revolute">
			<parent>hip_left_link1</parent>
			<child>hip_left_link2</child>
			<pose frame="">-1.1013412404281553e-15 -6.248347172999046e-11 -9.080949325834809e-11 0 0 0</pose>
			<axis>
				<xyz>5.915407053081494e-16 1.0 1.3732071035832403e-14</xyz>
				<limit>
					<lower>-3.141592653589793</lower>
					<upper>3.141592653589793</upper>
				</limit>
				<use_parent_model_frame>0</use_parent_model_frame>
			</axis>
		</joint>
		<plugin filename="libcardsflow_gazebo_plugin.so" name="cardsflow_gazebo_plugin"/>
	</model>
</sdf>
