<robot name="human">
  <joint name="knee_right_axis0" type="revolute">
    <parent link="upper_leg_right" />
    <child link="knee_right_link1" />
    <origin rpy="0 0 0" xyz="0.00085 -0.00644 -0.43155" />
    <axis xyz="1 0 0" />
    <limit effort="0.0" lower="-3.14159265359" upper="3.14159265359" velocity="0.0" />
  </joint>
  <joint name="knee_right_axis1" type="revolute">
    <parent link="knee_right_link1" />
    <child link="knee_right_link2" />
    <origin rpy="0 0 0" xyz="0 0 0" />
    <axis xyz="0 1 0" />
    <limit effort="0.0" lower="-3.14159265359" upper="3.14159265359" velocity="0.0" />
  </joint>
  <joint name="knee_right_axis2" type="revolute">
    <parent link="knee_right_link2" />
    <child link="lower_leg_right" />
    <origin rpy="0 0 0" xyz="0 0 0" />
    <axis xyz="0 0 1" />
    <limit effort="0.0" lower="-3.14159265359" upper="3.14159265359" velocity="0.0" />
  </joint>
  <joint name="elbow_right_axis0" type="revolute">
    <parent link="upper_arm_right" />
    <child link="elbow_right_link1" />
    <origin rpy="0 0 0" xyz="-0.02347 -0.0356  -0.26001" />
    <axis xyz="1 0 0" />
    <limit effort="0.0" lower="-3.14159265359" upper="3.14159265359" velocity="0.0" />
  </joint>
  <joint name="elbow_right_axis1" type="revolute">
    <parent link="elbow_right_link1" />
    <child link="elbow_right_link2" />
    <origin rpy="0 0 0" xyz="0 0 0" />
    <axis xyz="0 1 0" />
    <limit effort="0.0" lower="-3.14159265359" upper="3.14159265359" velocity="0.0" />
  </joint>
  <joint name="elbow_right_axis2" type="revolute">
    <parent link="elbow_right_link2" />
    <child link="lower_arm_right" />
    <origin rpy="0 0 0" xyz="0 0 0" />
    <axis xyz="0 0 1" />
    <limit effort="0.0" lower="-3.14159265359" upper="3.14159265359" velocity="0.0" />
  </joint>
  <joint name="hip_right_axis0" type="revolute">
    <parent link="hip" />
    <child link="hip_right_link1" />
    <origin rpy="0 0 0" xyz="-0.02085 -0.10284 -0.1029" />
    <axis xyz="1 0 0" />
    <limit effort="0.0" lower="-3.14159265359" upper="3.14159265359" velocity="0.0" />
  </joint>
  <joint name="hip_right_axis1" type="revolute">
    <parent link="hip_right_link1" />
    <child link="hip_right_link2" />
    <origin rpy="0 0 0" xyz="0 0 0" />
    <axis xyz="0 1 0" />
    <limit effort="0.0" lower="-3.14159265359" upper="3.14159265359" velocity="0.0" />
  </joint>
  <joint name="hip_right_axis2" type="revolute">
    <parent link="hip_right_link2" />
    <child link="upper_leg_right" />
    <origin rpy="0 0 0" xyz="0 0 0" />
    <axis xyz="0 0 1" />
    <limit effort="0.0" lower="-3.14159265359" upper="3.14159265359" velocity="0.0" />
  </joint>
  <joint name="motor8" type="prismatic">
    <parent link="base" />
    <child link="motor8" />
    <origin rpy="0 0 0" xyz="1.485   0      1.00099" />
    <axis xyz="0 -1  0" />
    <limit effort="0.0" lower="-1.4" upper="0.0" velocity="0.0" />
  </joint>
  <joint name="motor9" type="prismatic">
    <parent link="base" />
    <child link="motor9" />
    <origin rpy="0 0 0" xyz="1.485   0      1.00099" />
    <axis xyz="0 -1  0" />
    <limit effort="0.0" lower="0.0" upper="0.0" velocity="0.0" />
  </joint>
  <joint name="motor11" type="prismatic">
    <parent link="base" />
    <child link="motor10" />
    <origin rpy="0 0 0" xyz="-1.485    0       1.00099" />
    <axis xyz="0 1 0" />
    <limit effort="0.0" lower="0.0" upper="1.4" velocity="0.0" />
  </joint>
  <joint name="motor12" type="prismatic">
    <parent link="base" />
    <child link="motor12" />
    <origin rpy="0 0 0" xyz="0      1.485   1.00099" />
    <axis xyz="1 0 0" />
    <limit effort="0.0" lower="-1.4" upper="0.0" velocity="0.0" />
  </joint>
  <joint name="motor13" type="prismatic">
    <parent link="base" />
    <child link="motor13" />
    <origin rpy="0 0 0" xyz="0      1.485   1.00099" />
    <axis xyz="1 0 0" />
    <limit effort="0.0" lower="0.0" upper="1.4" velocity="0.0" />
  </joint>
  <joint name="motor14" type="prismatic">
    <parent link="base" />
    <child link="motor15" />
    <origin rpy="0 0 0" xyz="0      -1.485    1.00099" />
    <axis xyz="-1  0  0" />
    <limit effort="0.0" lower="-1.4" upper="0.0" velocity="0.0" />
  </joint>
  <joint name="motor15" type="prismatic">
    <parent link="base" />
    <child link="motor14" />
    <origin rpy="0 0 0" xyz="0      -1.485    1.00099" />
    <axis xyz="-1  0  0" />
    <limit effort="0.0" lower="0.0" upper="1.4" velocity="0.0" />
  </joint>
  <joint name="spine_axis0" type="revolute">
    <parent link="hip" />
    <child link="spine_link1" />
    <origin rpy="0 0 0" xyz="-0.02    -0.00309  0.03023" />
    <axis xyz="1 0 0" />
    <limit effort="0.0" lower="-3.14159265359" upper="3.14159265359" velocity="0.0" />
  </joint>
  <joint name="spine_axis1" type="revolute">
    <parent link="spine_link1" />
    <child link="spine_link2" />
    <origin rpy="0 0 0" xyz="0 0 0" />
    <axis xyz="0 1 0" />
    <limit effort="0.0" lower="-3.14159265359" upper="3.14159265359" velocity="0.0" />
  </joint>
  <joint name="spine_axis2" type="revolute">
    <parent link="spine_link2" />
    <child link="torso" />
    <origin rpy="0 0 0" xyz="0 0 0" />
    <axis xyz="0 0 1" />
    <limit effort="0.0" lower="-3.14159265359" upper="3.14159265359" velocity="0.0" />
  </joint>
  <joint name="ankle_right_axis0" type="revolute">
    <parent link="lower_leg_right" />
    <child link="ankle_right_link1" />
    <origin rpy="0 0 0" xyz="0      -0.01334 -0.35407" />
    <axis xyz="1 0 0" />
    <limit effort="0.0" lower="-3.14159265359" upper="3.14159265359" velocity="0.0" />
  </joint>
  <joint name="ankle_right_axis1" type="revolute">
    <parent link="ankle_right_link1" />
    <child link="ankle_right_link2" />
    <origin rpy="0 0 0" xyz="0 0 0" />
    <axis xyz="0 1 0" />
    <limit effort="0.0" lower="-3.14159265359" upper="3.14159265359" velocity="0.0" />
  </joint>
  <joint name="ankle_right_axis2" type="revolute">
    <parent link="ankle_right_link2" />
    <child link="foot_right" />
    <origin rpy="0 0 0" xyz="0 0 0" />
    <axis xyz="0 0 1" />
    <limit effort="0.0" lower="-3.14159265359" upper="3.14159265359" velocity="0.0" />
  </joint>
  <joint name="dof6_axis0" type="revolute">
    <parent link="base" />
    <child link="dof6_link1" />
    <origin rpy="0 0 0" xyz="0.e+00 -1.e-05  1.e+00" />
    <axis xyz="1 0 0" />
    <limit effort="0.0" lower="-3.14159265359" upper="3.14159265359" velocity="0.0" />
  </joint>
  <joint name="dof6_axis1" type="revolute">
    <parent link="dof6_link1" />
    <child link="dof6_link2" />
    <origin rpy="0 0 0" xyz="0 0 0" />
    <axis xyz="0 1 0" />
    <limit effort="0.0" lower="-3.14159265359" upper="3.14159265359" velocity="0.0" />
  </joint>
  <joint name="dof6_axis2" type="revolute">
    <parent link="dof6_link2" />
    <child link="dof6_link3" />
    <origin rpy="0 0 0" xyz="0 0 0" />
    <axis xyz="0 0 1" />
    <limit effort="0.0" lower="-3.14159265359" upper="3.14159265359" velocity="0.0" />
  </joint>
  <joint name="motor16" type="prismatic">
    <parent link="base" />
    <child link="motor16" />
    <origin rpy="0 0 0" xyz="1.485 0    2.001" />
    <axis xyz="0 -1  0" />
    <limit effort="0.0" lower="-1.4" upper="0.0" velocity="0.0" />
  </joint>
  <joint name="motor17" type="prismatic">
    <parent link="base" />
    <child link="motor17" />
    <origin rpy="0 0 0" xyz="1.485 0    2.001" />
    <axis xyz="0 -1  0" />
    <limit effort="0.0" lower="0.0" upper="1.4" velocity="0.0" />
  </joint>
  <joint name="motor18" type="prismatic">
    <parent link="base" />
    <child link="motor19" />
    <origin rpy="0 0 0" xyz="-1.485  0     2.001" />
    <axis xyz="0 1 0" />
    <limit effort="0.0" lower="-1.4" upper="0.0" velocity="0.0" />
  </joint>
  <joint name="motor19" type="prismatic">
    <parent link="base" />
    <child link="motor18" />
    <origin rpy="0 0 0" xyz="-1.485  0     2.001" />
    <axis xyz="0 1 0" />
    <limit effort="0.0" lower="0.0" upper="1.4" velocity="0.0" />
  </joint>
  <joint name="motor20" type="prismatic">
    <parent link="base" />
    <child link="motor20" />
    <origin rpy="0 0 0" xyz="0    1.485 2.001" />
    <axis xyz="1 0 0" />
    <limit effort="0.0" lower="-1.4" upper="0.0" velocity="0.0" />
  </joint>
  <joint name="motor21" type="prismatic">
    <parent link="base" />
    <child link="motor21" />
    <origin rpy="0 0 0" xyz="0    1.485 2.001" />
    <axis xyz="1 0 0" />
    <limit effort="0.0" lower="0.0" upper="1.4" velocity="0.0" />
  </joint>
  <joint name="motor22" type="prismatic">
    <parent link="base" />
    <child link="motor23" />
    <origin rpy="0 0 0" xyz="0    -1.485  2.001" />
    <axis xyz="-1  0  0" />
    <limit effort="0.0" lower="-1.4" upper="0.0" velocity="0.0" />
  </joint>
  <joint name="motor23" type="prismatic">
    <parent link="base" />
    <child link="motor22" />
    <origin rpy="0 0 0" xyz="0    -1.485  2.001" />
    <axis xyz="-1  0  0" />
    <limit effort="0.0" lower="0.0" upper="1.4" velocity="0.0" />
  </joint>
  <joint name="dof6_axis3" type="prismatic">
    <parent link="dof6_link3" />
    <child link="dof6_link4" />
    <origin rpy="0 0 0" xyz="0 0 0" />
    <axis xyz="-1  0  0" />
    <limit effort="0.0" lower="-1.0" upper="1.0" velocity="0.0" />
  </joint>
  <joint name="dof6_axis4" type="prismatic">
    <parent link="dof6_link4" />
    <child link="dof6_link5" />
    <origin rpy="0 0 0" xyz="0 0 0" />
    <axis xyz="0 1 0" />
    <limit effort="0.0" lower="-1.0" upper="1.0" velocity="0.0" />
  </joint>
  <joint name="dof6_axis5" type="prismatic">
    <parent link="dof6_link5" />
    <child link="hip" />
    <origin rpy="0 0 0" xyz="0.e+00 1.e-05 0.e+00" />
    <axis xyz="0 0 1" />
    <limit effort="0.0" lower="-1.0" upper="1.0" velocity="0.0" />
  </joint>
  <joint name="hip_left_axis0" type="revolute">
    <parent link="hip" />
    <child link="hip_left_link1" />
    <origin rpy="0 0 0" xyz="-0.02085  0.09663 -0.1029" />
    <axis xyz="1 0 0" />
    <limit effort="0.0" lower="-3.14159265359" upper="3.14159265359" velocity="0.0" />
  </joint>
  <joint name="hip_left_axis1" type="revolute">
    <parent link="hip_left_link1" />
    <child link="hip_left_link2" />
    <origin rpy="0 0 0" xyz="0 0 0" />
    <axis xyz="0 1 0" />
    <limit effort="0.0" lower="-3.14159265359" upper="3.14159265359" velocity="0.0" />
  </joint>
  <joint name="hip_left_axis2" type="revolute">
    <parent link="hip_left_link2" />
    <child link="upper_leg_left" />
    <origin rpy="0 0 0" xyz="0 0 0" />
    <axis xyz="0 0 1" />
    <limit effort="0.0" lower="-3.14159265359" upper="3.14159265359" velocity="0.0" />
  </joint>
  <joint name="motor0" type="prismatic">
    <parent link="base" />
    <child link="motor0" />
    <origin rpy="0 0 0" xyz="1.485e+00 0.000e+00 1.000e-03" />
    <axis xyz="0 -1  0" />
    <limit effort="0.0" lower="-1.4" upper="0.0" velocity="0.0" />
  </joint>
  <joint name="motor1" type="prismatic">
    <parent link="base" />
    <child link="motor1" />
    <origin rpy="0 0 0" xyz="1.485e+00 0.000e+00 1.000e-03" />
    <axis xyz="0 -1  0" />
    <limit effort="0.0" lower="0.0" upper="1.4" velocity="0.0" />
  </joint>
  <joint name="motor2" type="prismatic">
    <parent link="base" />
    <child link="motor2" />
    <origin rpy="0 0 0" xyz="-1.485e+00  0.000e+00  1.000e-03" />
    <axis xyz="0 1 0" />
    <limit effort="0.0" lower="0.0" upper="1.4" velocity="0.0" />
  </joint>
  <joint name="motor3" type="prismatic">
    <parent link="base" />
    <child link="motor3" />
    <origin rpy="0 0 0" xyz="-1.485e+00  0.000e+00  1.000e-03" />
    <axis xyz="0 1 0" />
    <limit effort="0.0" lower="-1.4" upper="0.0" velocity="0.0" />
  </joint>
  <joint name="motor4" type="prismatic">
    <parent link="base" />
    <child link="motor5" />
    <origin rpy="0 0 0" xyz="0.000e+00 1.485e+00 1.000e-03" />
    <axis xyz="1 0 0" />
    <limit effort="0.0" lower="0.0" upper="1.4" velocity="0.0" />
  </joint>
  <joint name="motor5" type="prismatic">
    <parent link="base" />
    <child link="motor4" />
    <origin rpy="0 0 0" xyz="0.000e+00 1.485e+00 1.000e-03" />
    <axis xyz="1 0 0" />
    <limit effort="0.0" lower="-1.4" upper="0.0" velocity="0.0" />
  </joint>
  <joint name="motor7" type="prismatic">
    <parent link="base" />
    <child link="motor6" />
    <origin rpy="0 0 0" xyz="0.000e+00 -1.485e+00  1.000e-03" />
    <axis xyz="-1  0  0" />
    <limit effort="0.0" lower="0.0" upper="1.4" velocity="0.0" />
  </joint>
  <joint name="ankle_left_axis0" type="revolute">
    <parent link="lower_leg_left" />
    <child link="ankle_left_link1" />
    <origin rpy="0 0 0" xyz="0       0.01442 -0.35633" />
    <axis xyz="1 0 0" />
    <limit effort="0.0" lower="-3.14159265359" upper="3.14159265359" velocity="0.0" />
  </joint>
  <joint name="ankle_left_axis1" type="revolute">
    <parent link="ankle_left_link1" />
    <child link="ankle_left_link2" />
    <origin rpy="0 0 0" xyz="0 0 0" />
    <axis xyz="0 1 0" />
    <limit effort="0.0" lower="-3.14159265359" upper="3.14159265359" velocity="0.0" />
  </joint>
  <joint name="ankle_left_axis2" type="revolute">
    <parent link="ankle_left_link2" />
    <child link="foot_left" />
    <origin rpy="0 0 0" xyz="0 0 0" />
    <axis xyz="0 0 1" />
    <limit effort="0.0" lower="-3.14159265359" upper="3.14159265359" velocity="0.0" />
  </joint>
  <joint name="knee_left_axis0" type="revolute">
    <parent link="upper_leg_left" />
    <child link="knee_left_link1" />
    <origin rpy="0 0 0" xyz="0.00085  0.00536 -0.43156" />
    <axis xyz="1 0 0" />
    <limit effort="0.0" lower="-3.14159265359" upper="3.14159265359" velocity="0.0" />
  </joint>
  <joint name="knee_left_axis1" type="revolute">
    <parent link="knee_left_link1" />
    <child link="knee_left_link2" />
    <origin rpy="0 0 0" xyz="0 0 0" />
    <axis xyz="0 1 0" />
    <limit effort="0.0" lower="-3.14159265359" upper="3.14159265359" velocity="0.0" />
  </joint>
  <joint name="knee_left_axis2" type="revolute">
    <parent link="knee_left_link2" />
    <child link="lower_leg_left" />
    <origin rpy="0 0 0" xyz="0 0 0" />
    <axis xyz="0 0 1" />
    <limit effort="0.0" lower="-3.14159265359" upper="3.14159265359" velocity="0.0" />
  </joint>
  <joint name="shoulder_left_axis0" type="revolute">
    <parent link="torso" />
    <child link="shoulder_left_link1" />
    <origin rpy="0 0 0" xyz="-0.04588  0.18435  0.36707" />
    <axis xyz="1 0 0" />
    <limit effort="0.0" lower="-3.14159265359" upper="3.14159265359" velocity="0.0" />
  </joint>
  <joint name="shoulder_left_axis1" type="revolute">
    <parent link="shoulder_left_link1" />
    <child link="shoulder_left_link2" />
    <origin rpy="0 0 0" xyz="0 0 0" />
    <axis xyz="0 1 0" />
    <limit effort="0.0" lower="-3.14159265359" upper="3.14159265359" velocity="0.0" />
  </joint>
  <joint name="shoulder_left_axis2" type="revolute">
    <parent link="shoulder_left_link2" />
    <child link="upper_arm_left" />
    <origin rpy="0 0 0" xyz="0 0 0" />
    <axis xyz="0 0 1" />
    <limit effort="0.0" lower="-3.14159265359" upper="3.14159265359" velocity="0.0" />
  </joint>
  <joint name="elbow_left_axis0" type="revolute">
    <parent link="upper_arm_left" />
    <child link="elbow_left_link1" />
    <origin rpy="0 0 0" xyz="-0.02347  0.0356  -0.26001" />
    <axis xyz="1 0 0" />
    <limit effort="0.0" lower="-3.14159265359" upper="3.14159265359" velocity="0.0" />
  </joint>
  <joint name="elbow_left_axis1" type="revolute">
    <parent link="elbow_left_link1" />
    <child link="elbow_left_link2" />
    <origin rpy="0 0 0" xyz="0 0 0" />
    <axis xyz="0 1 0" />
    <limit effort="0.0" lower="-3.14159265359" upper="3.14159265359" velocity="0.0" />
  </joint>
  <joint name="elbow_left_axis2" type="revolute">
    <parent link="elbow_left_link2" />
    <child link="lower_arm_left" />
    <origin rpy="0 0 0" xyz="0 0 0" />
    <axis xyz="0 0 1" />
    <limit effort="0.0" lower="-3.14159265359" upper="3.14159265359" velocity="0.0" />
  </joint>
  <joint name="shoulder_right_axis0" type="revolute">
    <parent link="torso" />
    <child link="shoulder_right_link1" />
    <origin rpy="0 0 0" xyz="-0.04588 -0.18436  0.36707" />
    <axis xyz="1 0 0" />
    <limit effort="0.0" lower="-3.14159265359" upper="3.14159265359" velocity="0.0" />
  </joint>
  <joint name="shoulder_right_axis1" type="revolute">
    <parent link="shoulder_right_link1" />
    <child link="shoulder_right_link2" />
    <origin rpy="0 0 0" xyz="0 0 0" />
    <axis xyz="0 1 0" />
    <limit effort="0.0" lower="-3.14159265359" upper="3.14159265359" velocity="0.0" />
  </joint>
  <joint name="shoulder_right_axis2" type="revolute">
    <parent link="shoulder_right_link2" />
    <child link="upper_arm_right" />
    <origin rpy="0 0 0" xyz="0 0 0" />
    <axis xyz="0 0 1" />
    <limit effort="0.0" lower="-3.14159265359" upper="3.14159265359" velocity="0.0" />
  </joint>
  <link name="base">
    <inertial>
      <mass value="5.670211945411031" />
      <origin rpy="0 0 0" xyz="0      0      0.76391" />
      <inertia ixx="13.426879502251602" ixy="-3.887718206911639e-12" ixz="3.940811655216425e-07" iyy="13.426879502241684" iyz="1.1174684337865282e-06" izz="12.564006179452424" />
    </inertial>
    <collision name="base_collision">
      <origin rpy="0 0 0" xyz="0      0      0.76391" />
      <geometry>
        <mesh filename="package://robots/human/meshes/collisions/base.stl" scale="0.001 0.001 0.001" />
      </geometry>
    </collision>
    <visual name="base_visual">
      <origin rpy="0 0 0" xyz="0      0      0.76391" />
      <geometry>
        <mesh filename="package://robots/human/meshes/visuals/base.stl" scale="0.001 0.001 0.001" />
      </geometry>
    </visual>
  </link>
  <link name="hip">
    <inertial>
      <mass value="43.24409919015801" />
      <origin rpy="0 0 0" xyz="-0.01938 -0.0031  -0.04942" />
      <inertia ixx="39.338954158435655" ixy="-0.002514620735701843" ixz="0.7920766825179428" iyy="39.325027251694706" iyz="0.127065516007698" izz="0.3005991852048205" />
    </inertial>
    <collision name="hip_collision">
      <origin rpy="0 0 0" xyz="-0.01938 -0.0031  -0.04942" />
      <geometry>
        <mesh filename="package://robots/human/meshes/collisions/hip.stl" scale="0.001 0.001 0.001" />
      </geometry>
    </collision>
    <visual name="hip_visual">
      <origin rpy="0 0 0" xyz="-0.01938 -0.0031  -0.04942" />
      <geometry>
        <mesh filename="package://robots/human/meshes/visuals/hip.stl" scale="0.001 0.001 0.001" />
      </geometry>
    </visual>
  </link>
  <link name="upper_leg_left">
    <inertial>
      <mass value="63.30402235160809" />
      <origin rpy="0 0 0" xyz="0.00771  0.00637 -0.15497" />
      <inertia ixx="36.57190754572642" ixy="0.0786067246776424" ixz="0.6462990522451668" iyy="35.96736804228855" iyz="-4.847722704192384" izz="0.8765201070874777" />
    </inertial>
    <collision name="upper_leg_left_collision">
      <origin rpy="0 0 0" xyz="0.00771  0.00637 -0.15497" />
      <geometry>
        <mesh filename="package://robots/human/meshes/collisions/upper_leg_left.stl" scale="0.001 0.001 0.001" />
      </geometry>
    </collision>
    <visual name="upper_leg_left_visual">
      <origin rpy="0 0 0" xyz="0.00771  0.00637 -0.15497" />
      <geometry>
        <mesh filename="package://robots/human/meshes/visuals/upper_leg_left.stl" scale="0.001 0.001 0.001" />
      </geometry>
    </visual>
  </link>
  <link name="lower_leg_left">
    <inertial>
      <mass value="28.449648630223585" />
      <origin rpy="0 0 0" xyz="-0.01675  0.00633 -0.14681" />
      <inertia ixx="3.5618512908284417" ixy="0.11137748128345827" ixz="0.3321209674824219" iyy="3.277808953441893" iyz="-0.9718967324191882" izz="0.4199966653173898" />
    </inertial>
    <collision name="lower_leg_left_collision">
      <origin rpy="0 0 0" xyz="-0.01675  0.00633 -0.14681" />
      <geometry>
        <mesh filename="package://robots/human/meshes/collisions/lower_leg_left.stl" scale="0.001 0.001 0.001" />
      </geometry>
    </collision>
    <visual name="lower_leg_left_visual">
      <origin rpy="0 0 0" xyz="-0.01675  0.00633 -0.14681" />
      <geometry>
        <mesh filename="package://robots/human/meshes/visuals/lower_leg_left.stl" scale="0.001 0.001 0.001" />
      </geometry>
    </visual>
  </link>
  <link name="foot_left">
    <inertial>
      <mass value="0.2795713024331067" />
      <origin rpy="0 0 0" xyz="0     0     0.0006" />
      <inertia ixx="0.007203954491699386" ixy="0.0006509337921648627" ixz="0.0006139398708679091" iyy="0.003526808635494107" iyz="-0.0035736391223248043" izz="0.003943161605729023" />
    </inertial>
    <collision name="foot_left_collision">
      <origin rpy="0 0 0" xyz="0     0     0.0006" />
      <geometry>
        <mesh filename="package://robots/human/meshes/collisions/foot_left.stl" scale="0.001 0.001 0.001" />
      </geometry>
    </collision>
    <visual name="foot_left_visual">
      <origin rpy="0 0 0" xyz="0     0     0.0006" />
      <geometry>
        <mesh filename="package://robots/human/meshes/visuals/foot_left.stl" scale="0.001 0.001 0.001" />
      </geometry>
    </visual>
  </link>
  <link name="upper_leg_right">
    <inertial>
      <mass value="63.30480762272283" />
      <origin rpy="0 0 0" xyz="0.00771 -0.0064  -0.15498" />
      <inertia ixx="36.654533662691485" ixy="-0.08379280764495882" ixz="0.646254140736353" iyy="35.966271731076944" iyz="5.140564976562167" izz="0.9602361139729543" />
    </inertial>
    <collision name="upper_leg_right_collision">
      <origin rpy="0 0 0" xyz="0.00771 -0.0064  -0.15498" />
      <geometry>
        <mesh filename="package://robots/human/meshes/collisions/upper_leg_right.stl" scale="0.001 0.001 0.001" />
      </geometry>
    </collision>
    <visual name="upper_leg_right_visual">
      <origin rpy="0 0 0" xyz="0.00771 -0.0064  -0.15498" />
      <geometry>
        <mesh filename="package://robots/human/meshes/visuals/upper_leg_right.stl" scale="0.001 0.001 0.001" />
      </geometry>
    </visual>
  </link>
  <link name="lower_leg_right">
    <inertial>
      <mass value="27.241031189816738" />
      <origin rpy="0 0 0" xyz="-0.01765 -0.00493 -0.13744" />
      <inertia ixx="3.5688762186354137" ixy="-0.11545630015272085" ixz="0.32998155868610246" iyy="3.263067799956089" iyz="1.0124959528503439" izz="0.440507796966936" />
    </inertial>
    <collision name="lower_leg_right_collision">
      <origin rpy="0 0 0" xyz="-0.01765 -0.00493 -0.13744" />
      <geometry>
        <mesh filename="package://robots/human/meshes/collisions/lower_leg_right.stl" scale="0.001 0.001 0.001" />
      </geometry>
    </collision>
    <visual name="lower_leg_right_visual">
      <origin rpy="0 0 0" xyz="-0.01765 -0.00493 -0.13744" />
      <geometry>
        <mesh filename="package://robots/human/meshes/visuals/lower_leg_right.stl" scale="0.001 0.001 0.001" />
      </geometry>
    </visual>
  </link>
  <link name="foot_right">
    <inertial>
      <mass value="0.2795713024331067" />
      <origin rpy="0 0 0" xyz="0     0     0.0006" />
      <inertia ixx="0.007759839909093018" ixy="-0.0006856594548557962" ixz="0.0006266353224701174" iyy="0.0036676464565357832" iyz="0.003842124230428521" izz="0.004358209202080964" />
    </inertial>
    <collision name="foot_right_collision">
      <origin rpy="0 0 0" xyz="0     0     0.0006" />
      <geometry>
        <mesh filename="package://robots/human/meshes/collisions/foot_right.stl" scale="0.001 0.001 0.001" />
      </geometry>
    </collision>
    <visual name="foot_right_visual">
      <origin rpy="0 0 0" xyz="0     0     0.0006" />
      <geometry>
        <mesh filename="package://robots/human/meshes/visuals/foot_right.stl" scale="0.001 0.001 0.001" />
      </geometry>
    </visual>
  </link>
  <link name="torso">
    <inertial>
      <mass value="37.90394723937322" />
      <origin rpy="0 0 0" xyz="2.860e-03 -3.000e-05  6.069e-01" />
      <inertia ixx="102.1011103005115" ixy="-0.001971690796654316" ixz="1.0869837332175591" iyy="102.15792220015128" iyz="0.19411618767898478" izz="0.17722591078345298" />
    </inertial>
    <collision name="torso_collision">
      <origin rpy="0 0 0" xyz="2.860e-03 -3.000e-05  6.069e-01" />
      <geometry>
        <mesh filename="package://robots/human/meshes/collisions/torso.stl" scale="0.001 0.001 0.001" />
      </geometry>
    </collision>
    <visual name="torso_visual">
      <origin rpy="0 0 0" xyz="2.860e-03 -3.000e-05  6.069e-01" />
      <geometry>
        <mesh filename="package://robots/human/meshes/visuals/torso.stl" scale="0.001 0.001 0.001" />
      </geometry>
    </visual>
  </link>
  <link name="upper_arm_left">
    <inertial>
      <mass value="0.12749203806058093" />
      <origin rpy="0 0 0" xyz="-0.02043  0.03098 -0.225" />
      <inertia ixx="0.18203449514488937" ixy="0.0023478029049020972" ixz="0.012810352043252878" iyy="0.17723110178953327" iyz="-0.03158328681375136" izz="0.0067294875823005135" />
    </inertial>
    <collision name="upper_arm_left_collision">
      <origin rpy="0 0 0" xyz="-0.02043  0.03098 -0.225" />
      <geometry>
        <mesh filename="package://robots/human/meshes/collisions/upper_arm_left.stl" scale="0.001 0.001 0.001" />
      </geometry>
    </collision>
    <visual name="upper_arm_left_visual">
      <origin rpy="0 0 0" xyz="-0.02043  0.03098 -0.225" />
      <geometry>
        <mesh filename="package://robots/human/meshes/visuals/upper_arm_left.stl" scale="0.001 0.001 0.001" />
      </geometry>
    </visual>
  </link>
  <link name="lower_arm_left">
    <inertial>
      <mass value="0.016515277572521365" />
      <origin rpy="0 0 0" xyz="0      0      0.01025" />
      <inertia ixx="0.02252584776365808" ixy="0.0003200426138108468" ixz="0.0016936096164630087" iyy="0.021881095979910607" iyz="-0.004109828560888341" izz="0.0009087930467704993" />
    </inertial>
    <collision name="lower_arm_left_collision">
      <origin rpy="0 0 0" xyz="0      0      0.01025" />
      <geometry>
        <mesh filename="package://robots/human/meshes/collisions/lower_arm_left.stl" scale="0.001 0.001 0.001" />
      </geometry>
    </collision>
    <visual name="lower_arm_left_visual">
      <origin rpy="0 0 0" xyz="0      0      0.01025" />
      <geometry>
        <mesh filename="package://robots/human/meshes/visuals/lower_arm_left.stl" scale="0.001 0.001 0.001" />
      </geometry>
    </visual>
  </link>
  <link name="upper_arm_right">
    <inertial>
      <mass value="0.12749203806058088" />
      <origin rpy="0 0 0" xyz="-0.02043 -0.03098 -0.225" />
      <inertia ixx="0.18237551746795594" ixy="-0.002416151840534216" ixz="0.012810352043256907" iyy="0.17723110178950618" iyz="0.032511517597940305" izz="0.007070509905396119" />
    </inertial>
    <collision name="upper_arm_right_collision">
      <origin rpy="0 0 0" xyz="-0.02043 -0.03098 -0.225" />
      <geometry>
        <mesh filename="package://robots/human/meshes/collisions/upper_arm_right.stl" scale="0.001 0.001 0.001" />
      </geometry>
    </collision>
    <visual name="upper_arm_right_visual">
      <origin rpy="0 0 0" xyz="-0.02043 -0.03098 -0.225" />
      <geometry>
        <mesh filename="package://robots/human/meshes/visuals/upper_arm_right.stl" scale="0.001 0.001 0.001" />
      </geometry>
    </visual>
  </link>
  <link name="lower_arm_right">
    <inertial>
      <mass value="0.016515277572521362" />
      <origin rpy="0 0 0" xyz="0      0      0.01025" />
      <inertia ixx="0.02257097325055043" ixy="-0.0003292091613496685" ixz="0.0016936096164640027" iyy="0.0218810959799065" iyz="0.0042275410117780885" izz="0.0009539185336673193" />
    </inertial>
    <collision name="lower_arm_right_collision">
      <origin rpy="0 0 0" xyz="0      0      0.01025" />
      <geometry>
        <mesh filename="package://robots/human/meshes/collisions/lower_arm_right.stl" scale="0.001 0.001 0.001" />
      </geometry>
    </collision>
    <visual name="lower_arm_right_visual">
      <origin rpy="0 0 0" xyz="0      0      0.01025" />
      <geometry>
        <mesh filename="package://robots/human/meshes/visuals/lower_arm_right.stl" scale="0.001 0.001 0.001" />
      </geometry>
    </visual>
  </link>
  <link name="motor3">
    <inertial>
      <mass value="0.5407289156586891" />
      <origin rpy="0 0 0" xyz="1.19000e-03 -1.23423e+00  9.51000e-03" />
      <inertia ixx="0.8239519347007563" ixy="-0.9902621278821997" ixz="0.008437545456538848" iyy="1.1908347538526611" iyz="0.007018743074075354" izz="2.0145909271886877" />
    </inertial>
    <collision name="motor3_collision">
      <origin rpy="0 0 0" xyz="1.19000e-03 -1.23423e+00  9.51000e-03" />
      <geometry>
        <mesh filename="package://robots/human/meshes/collisions/motor3.stl" scale="0.001 0.001 0.001" />
      </geometry>
    </collision>
    <visual name="motor3_visual">
      <origin rpy="0 0 0" xyz="1.19000e-03 -1.23423e+00  9.51000e-03" />
      <geometry>
        <mesh filename="package://robots/human/meshes/visuals/motor3.stl" scale="0.001 0.001 0.001" />
      </geometry>
    </visual>
  </link>
  <link name="motor2">
    <inertial>
      <mass value="0.5915184316952449" />
      <origin rpy="0 0 0" xyz="-3.30000e-04  1.23581e+00  9.48000e-03" />
      <inertia ixx="0.9036405133260113" ixy="1.0857914520512877" ixz="0.009213108679123352" iyy="1.3053863599243112" iyz="-0.007665084014776147" izz="2.2088188733016993" />
    </inertial>
    <collision name="motor2_collision">
      <origin rpy="0 0 0" xyz="-3.30000e-04  1.23581e+00  9.48000e-03" />
      <geometry>
        <mesh filename="package://robots/human/meshes/collisions/motor2.stl" scale="0.001 0.001 0.001" />
      </geometry>
    </collision>
    <visual name="motor2_visual">
      <origin rpy="0 0 0" xyz="-3.30000e-04  1.23581e+00  9.48000e-03" />
      <geometry>
        <mesh filename="package://robots/human/meshes/visuals/motor2.stl" scale="0.001 0.001 0.001" />
      </geometry>
    </visual>
  </link>
  <link name="motor0">
    <inertial>
      <mass value="0.5915184316951642" />
      <origin rpy="0 0 0" xyz="3.30000e-04 1.23581e+00 9.51000e-03" />
      <inertia ixx="0.9036408660165021" ixy="-1.0857914520511684" ixz="-0.009237546389943497" iyy="1.305386712614818" iyz="-0.007686010628829871" izz="2.2088188733014675" />
    </inertial>
    <collision name="motor0_collision">
      <origin rpy="0 0 0" xyz="3.30000e-04 1.23581e+00 9.51000e-03" />
      <geometry>
        <mesh filename="package://robots/human/meshes/collisions/motor0.stl" scale="0.001 0.001 0.001" />
      </geometry>
    </collision>
    <visual name="motor0_visual">
      <origin rpy="0 0 0" xyz="3.30000e-04 1.23581e+00 9.51000e-03" />
      <geometry>
        <mesh filename="package://robots/human/meshes/visuals/motor0.stl" scale="0.001 0.001 0.001" />
      </geometry>
    </visual>
  </link>
  <link name="motor4">
    <inertial>
      <mass value="0.5915182656349381" />
      <origin rpy="0 0 0" xyz="-1.23581e+00  3.30000e-04  9.51000e-03" />
      <inertia ixx="1.3053863288187992" ixy="1.085791131455688" ixz="0.007686007040985962" iyy="0.9036405981034654" iyz="-0.009237542099685631" izz="2.2088182216814296" />
    </inertial>
    <collision name="motor4_collision">
      <origin rpy="0 0 0" xyz="-1.23581e+00  3.30000e-04  9.51000e-03" />
      <geometry>
        <mesh filename="package://robots/human/meshes/collisions/motor4.stl" scale="0.001 0.001 0.001" />
      </geometry>
    </collision>
    <visual name="motor4_visual">
      <origin rpy="0 0 0" xyz="-1.23581e+00  3.30000e-04  9.51000e-03" />
      <geometry>
        <mesh filename="package://robots/human/meshes/visuals/motor4.stl" scale="0.001 0.001 0.001" />
      </geometry>
    </visual>
  </link>
  <link name="motor5">
    <inertial>
      <mass value="0.5915184316952438" />
      <origin rpy="0 0 0" xyz="1.23581e+00 3.30000e-04 9.48000e-03" />
      <inertia ixx="1.3053863599242819" ixy="-1.0857914520512741" ixz="-0.007665084014776132" iyy="0.9036405133260096" iyz="-0.009213108679123314" izz="2.2088188733016674" />
    </inertial>
    <collision name="motor5_collision">
      <origin rpy="0 0 0" xyz="1.23581e+00 3.30000e-04 9.48000e-03" />
      <geometry>
        <mesh filename="package://robots/human/meshes/collisions/motor5.stl" scale="0.001 0.001 0.001" />
      </geometry>
    </collision>
    <visual name="motor5_visual">
      <origin rpy="0 0 0" xyz="1.23581e+00 3.30000e-04 9.48000e-03" />
      <geometry>
        <mesh filename="package://robots/human/meshes/visuals/motor5.stl" scale="0.001 0.001 0.001" />
      </geometry>
    </visual>
  </link>
  <link name="motor6">
    <inertial>
      <mass value="0.5915182656350185" />
      <origin rpy="0 0 0" xyz="-1.23581e+00 -3.30000e-04  9.48000e-03" />
      <inertia ixx="1.3053859761740971" ixy="-1.0857911314557949" ixz="0.007665083173063848" iyy="0.9036402454588066" iyz="0.009213107668262954" izz="2.2088182216816317" />
    </inertial>
    <collision name="motor6_collision">
      <origin rpy="0 0 0" xyz="-1.23581e+00 -3.30000e-04  9.48000e-03" />
      <geometry>
        <mesh filename="package://robots/human/meshes/collisions/motor6.stl" scale="0.001 0.001 0.001" />
      </geometry>
    </collision>
    <visual name="motor6_visual">
      <origin rpy="0 0 0" xyz="-1.23581e+00 -3.30000e-04  9.48000e-03" />
      <geometry>
        <mesh filename="package://robots/human/meshes/visuals/motor6.stl" scale="0.001 0.001 0.001" />
      </geometry>
    </visual>
  </link>
  <link name="motor1">
    <inertial>
      <mass value="0.5915182656350185" />
      <origin rpy="0 0 0" xyz="3.30000e-04 -1.23581e+00  9.48000e-03" />
      <inertia ixx="0.9036402454588068" ixy="1.0857911314557955" ixz="-0.009213107668262955" iyy="1.3053859761740987" iyz="0.007665083173063846" izz="2.208818221681633" />
    </inertial>
    <collision name="motor1_collision">
      <origin rpy="0 0 0" xyz="3.30000e-04 -1.23581e+00  9.48000e-03" />
      <geometry>
        <mesh filename="package://robots/human/meshes/collisions/motor1.stl" scale="0.001 0.001 0.001" />
      </geometry>
    </collision>
    <visual name="motor1_visual">
      <origin rpy="0 0 0" xyz="3.30000e-04 -1.23581e+00  9.48000e-03" />
      <geometry>
        <mesh filename="package://robots/human/meshes/visuals/motor1.stl" scale="0.001 0.001 0.001" />
      </geometry>
    </visual>
  </link>
  <link name="motor10">
    <inertial>
      <mass value="0.5407288092535038" />
      <origin rpy="0 0 0" xyz="1.19000e-03 1.23423e+00 9.48000e-03" />
      <inertia ixx="1.3760176002125752" ixy="0.99026193086944" ixz="0.8107460717445298" iyy="1.7429003480577039" iyz="-0.6743852245854303" izz="2.0145905267549784" />
    </inertial>
    <collision name="motor10_collision">
      <origin rpy="0 0 0" xyz="1.19000e-03 1.23423e+00 9.48000e-03" />
      <geometry>
        <mesh filename="package://robots/human/meshes/collisions/motor10.stl" scale="0.001 0.001 0.001" />
      </geometry>
    </collision>
    <visual name="motor10_visual">
      <origin rpy="0 0 0" xyz="1.19000e-03 1.23423e+00 9.48000e-03" />
      <geometry>
        <mesh filename="package://robots/human/meshes/visuals/motor10.stl" scale="0.001 0.001 0.001" />
      </geometry>
    </visual>
  </link>
  <link name="motor8">
    <inertial>
      <mass value="0.5407288092534246" />
      <origin rpy="0 0 0" xyz="-1.19000e-03  1.23423e+00  9.51000e-03" />
      <inertia ixx="1.3760537924693779" ixy="-0.9902619308692957" ixz="-0.8107721333955696" iyy="1.7429365403144546" iyz="-0.6744075434898156" izz="2.014590526754685" />
    </inertial>
    <collision name="motor8_collision">
      <origin rpy="0 0 0" xyz="-1.19000e-03  1.23423e+00  9.51000e-03" />
      <geometry>
        <mesh filename="package://robots/human/meshes/collisions/motor8.stl" scale="0.001 0.001 0.001" />
      </geometry>
    </collision>
    <visual name="motor8_visual">
      <origin rpy="0 0 0" xyz="-1.19000e-03  1.23423e+00  9.51000e-03" />
      <geometry>
        <mesh filename="package://robots/human/meshes/visuals/motor8.stl" scale="0.001 0.001 0.001" />
      </geometry>
    </visual>
  </link>
  <link name="motor12">
    <inertial>
      <mass value="0.5407289156586891" />
      <origin rpy="0 0 0" xyz="-1.23423e+00 -1.19000e-03  9.51000e-03" />
      <inertia ixx="1.7429368845367943" ixy="0.9902621278821994" ixz="0.6744076770188963" iyy="1.3760540653848898" iyz="-0.810772293261037" izz="2.0145909271886873" />
    </inertial>
    <collision name="motor12_collision">
      <origin rpy="0 0 0" xyz="-1.23423e+00 -1.19000e-03  9.51000e-03" />
      <geometry>
        <mesh filename="package://robots/human/meshes/collisions/motor12.stl" scale="0.001 0.001 0.001" />
      </geometry>
    </collision>
    <visual name="motor12_visual">
      <origin rpy="0 0 0" xyz="-1.23423e+00 -1.19000e-03  9.51000e-03" />
      <geometry>
        <mesh filename="package://robots/human/meshes/visuals/motor12.stl" scale="0.001 0.001 0.001" />
      </geometry>
    </visual>
  </link>
  <link name="motor13">
    <inertial>
      <mass value="0.5407288092535051" />
      <origin rpy="0 0 0" xyz="1.23423e+00 -1.19000e-03  9.48000e-03" />
      <inertia ixx="1.7429003480577074" ixy="-0.9902619308694421" ixz="-0.6743852245854316" iyy="1.3760176002125781" iyz="-0.8107460717445316" izz="2.0145905267549824" />
    </inertial>
    <collision name="motor13_collision">
      <origin rpy="0 0 0" xyz="1.23423e+00 -1.19000e-03  9.48000e-03" />
      <geometry>
        <mesh filename="package://robots/human/meshes/collisions/motor13.stl" scale="0.001 0.001 0.001" />
      </geometry>
    </collision>
    <visual name="motor13_visual">
      <origin rpy="0 0 0" xyz="1.23423e+00 -1.19000e-03  9.48000e-03" />
      <geometry>
        <mesh filename="package://robots/human/meshes/visuals/motor13.stl" scale="0.001 0.001 0.001" />
      </geometry>
    </visual>
  </link>
  <link name="motor14">
    <inertial>
      <mass value="0.5407289156587678" />
      <origin rpy="0 0 0" xyz="-1.23423e+00  1.19000e-03  9.48000e-03" />
      <inertia ixx="1.742900692880094" ixy="-0.9902621278823432" ixz="0.6743853584836851" iyy="1.3760178737281379" iyz="0.8107462320519715" izz="2.0145909271889795" />
    </inertial>
    <collision name="motor14_collision">
      <origin rpy="0 0 0" xyz="-1.23423e+00  1.19000e-03  9.48000e-03" />
      <geometry>
        <mesh filename="package://robots/human/meshes/collisions/motor14.stl" scale="0.001 0.001 0.001" />
      </geometry>
    </collision>
    <visual name="motor14_visual">
      <origin rpy="0 0 0" xyz="-1.23423e+00  1.19000e-03  9.48000e-03" />
      <geometry>
        <mesh filename="package://robots/human/meshes/visuals/motor14.stl" scale="0.001 0.001 0.001" />
      </geometry>
    </visual>
  </link>
  <link name="motor15">
    <inertial>
      <mass value="0.5407288092534249" />
      <origin rpy="0 0 0" xyz="1.23423e+00 1.19000e-03 9.51000e-03" />
      <inertia ixx="1.7429365403144548" ixy="0.9902619308692958" ixz="-0.6744075434898158" iyy="1.376053792469379" iyz="0.81077213339557" izz="2.0145905267546853" />
    </inertial>
    <collision name="motor15_collision">
      <origin rpy="0 0 0" xyz="1.23423e+00 1.19000e-03 9.51000e-03" />
      <geometry>
        <mesh filename="package://robots/human/meshes/collisions/motor15.stl" scale="0.001 0.001 0.001" />
      </geometry>
    </collision>
    <visual name="motor15_visual">
      <origin rpy="0 0 0" xyz="1.23423e+00 1.19000e-03 9.51000e-03" />
      <geometry>
        <mesh filename="package://robots/human/meshes/visuals/motor15.stl" scale="0.001 0.001 0.001" />
      </geometry>
    </visual>
  </link>
  <link name="motor9">
    <inertial>
      <mass value="0.5915182656350185" />
      <origin rpy="0 0 0" xyz="3.30000e-04 -1.23581e+00  9.48000e-03" />
      <inertia ixx="1.5075636020635315" ixy="1.085791131251597" ixz="-0.8878154774061241" iyy="1.909309332296448" iyz="0.7386693790802477" izz="2.2088182211992584" />
    </inertial>
    <collision name="motor9_collision">
      <origin rpy="0 0 0" xyz="3.30000e-04 -1.23581e+00  9.48000e-03" />
      <geometry>
        <mesh filename="package://robots/human/meshes/collisions/motor9.stl" scale="0.001 0.001 0.001" />
      </geometry>
    </collision>
    <visual name="motor9_visual">
      <origin rpy="0 0 0" xyz="3.30000e-04 -1.23581e+00  9.48000e-03" />
      <geometry>
        <mesh filename="package://robots/human/meshes/visuals/motor9.stl" scale="0.001 0.001 0.001" />
      </geometry>
    </visual>
  </link>
  <link name="motor19">
    <inertial>
      <mass value="0.5407289156586891" />
      <origin rpy="0 0 0" xyz="1.19000e-03 -1.23423e+00  9.51000e-03" />
      <inertia ixx="3.009614027386401" ixy="-0.9902621278821997" ixz="1.6131070410655353" iyy="3.3764968465383065" iyz="1.3417966109637172" izz="2.0145909271886877" />
    </inertial>
    <collision name="motor19_collision">
      <origin rpy="0 0 0" xyz="1.19000e-03 -1.23423e+00  9.51000e-03" />
      <geometry>
        <mesh filename="package://robots/human/meshes/collisions/motor19.stl" scale="0.001 0.001 0.001" />
      </geometry>
    </collision>
    <visual name="motor19_visual">
      <origin rpy="0 0 0" xyz="1.19000e-03 -1.23423e+00  9.51000e-03" />
      <geometry>
        <mesh filename="package://robots/human/meshes/visuals/motor19.stl" scale="0.001 0.001 0.001" />
      </geometry>
    </visual>
  </link>
  <link name="motor18">
    <inertial>
      <mass value="0.5407288092535049" />
      <origin rpy="0 0 0" xyz="1.19000e-03 1.23423e+00 9.48000e-03" />
      <inertia ixx="3.009541424873896" ixy="0.9902619308694421" ixz="1.6130806611261352" iyy="3.3764241727190254" iyz="-1.3417740262060884" izz="2.0145905267549824" />
    </inertial>
    <collision name="motor18_collision">
      <origin rpy="0 0 0" xyz="1.19000e-03 1.23423e+00 9.48000e-03" />
      <geometry>
        <mesh filename="package://robots/human/meshes/collisions/motor18.stl" scale="0.001 0.001 0.001" />
      </geometry>
    </collision>
    <visual name="motor18_visual">
      <origin rpy="0 0 0" xyz="1.19000e-03 1.23423e+00 9.48000e-03" />
      <geometry>
        <mesh filename="package://robots/human/meshes/visuals/motor18.stl" scale="0.001 0.001 0.001" />
      </geometry>
    </visual>
  </link>
  <link name="motor16">
    <inertial>
      <mass value="0.5407288092534246" />
      <origin rpy="0 0 0" xyz="-1.19000e-03  1.23423e+00  9.51000e-03" />
      <inertia ixx="3.0096134333174938" ixy="-0.9902619308692957" ixz="-1.6131067227770544" iyy="3.3764961811625707" iyz="-1.3417963451103734" izz="2.014590526754685" />
    </inertial>
    <collision name="motor16_collision">
      <origin rpy="0 0 0" xyz="-1.19000e-03  1.23423e+00  9.51000e-03" />
      <geometry>
        <mesh filename="package://robots/human/meshes/collisions/motor16.stl" scale="0.001 0.001 0.001" />
      </geometry>
    </collision>
    <visual name="motor16_visual">
      <origin rpy="0 0 0" xyz="-1.19000e-03  1.23423e+00  9.51000e-03" />
      <geometry>
        <mesh filename="package://robots/human/meshes/visuals/motor16.stl" scale="0.001 0.001 0.001" />
      </geometry>
    </visual>
  </link>
  <link name="motor20">
    <inertial>
      <mass value="0.540728915658689" />
      <origin rpy="0 0 0" xyz="-1.23423e+00 -1.19000e-03  9.51000e-03" />
      <inertia ixx="3.3764968465383056" ixy="0.9902621278821991" ixz="1.3417966109637167" iyy="3.0096140273864003" iyz="-1.613107041065535" izz="2.0145909271886864" />
    </inertial>
    <collision name="motor20_collision">
      <origin rpy="0 0 0" xyz="-1.23423e+00 -1.19000e-03  9.51000e-03" />
      <geometry>
        <mesh filename="package://robots/human/meshes/collisions/motor20.stl" scale="0.001 0.001 0.001" />
      </geometry>
    </collision>
    <visual name="motor20_visual">
      <origin rpy="0 0 0" xyz="-1.23423e+00 -1.19000e-03  9.51000e-03" />
      <geometry>
        <mesh filename="package://robots/human/meshes/visuals/motor20.stl" scale="0.001 0.001 0.001" />
      </geometry>
    </visual>
  </link>
  <link name="motor21">
    <inertial>
      <mass value="0.540728809253504" />
      <origin rpy="0 0 0" xyz="1.23423e+00 -1.19000e-03  9.48000e-03" />
      <inertia ixx="3.3764241727190205" ixy="-0.9902619308694405" ixz="-1.3417740262060864" iyy="3.009541424873891" iyz="-1.6130806611261326" izz="2.0145905267549797" />
    </inertial>
    <collision name="motor21_collision">
      <origin rpy="0 0 0" xyz="1.23423e+00 -1.19000e-03  9.48000e-03" />
      <geometry>
        <mesh filename="package://robots/human/meshes/collisions/motor21.stl" scale="0.001 0.001 0.001" />
      </geometry>
    </collision>
    <visual name="motor21_visual">
      <origin rpy="0 0 0" xyz="1.23423e+00 -1.19000e-03  9.48000e-03" />
      <geometry>
        <mesh filename="package://robots/human/meshes/visuals/motor21.stl" scale="0.001 0.001 0.001" />
      </geometry>
    </visual>
  </link>
  <link name="motor22">
    <inertial>
      <mass value="0.5407289156587689" />
      <origin rpy="0 0 0" xyz="-1.23423e+00  1.19000e-03  9.48000e-03" />
      <inertia ixx="3.376424839288627" ixy="-0.9902621278823452" ixz="1.3417742924286062" iyy="3.00954202013667" iyz="1.6130809798565893" izz="2.0145909271889835" />
    </inertial>
    <collision name="motor22_collision">
      <origin rpy="0 0 0" xyz="-1.23423e+00  1.19000e-03  9.48000e-03" />
      <geometry>
        <mesh filename="package://robots/human/meshes/collisions/motor22.stl" scale="0.001 0.001 0.001" />
      </geometry>
    </collision>
    <visual name="motor22_visual">
      <origin rpy="0 0 0" xyz="-1.23423e+00  1.19000e-03  9.48000e-03" />
      <geometry>
        <mesh filename="package://robots/human/meshes/visuals/motor22.stl" scale="0.001 0.001 0.001" />
      </geometry>
    </visual>
  </link>
  <link name="motor23">
    <inertial>
      <mass value="0.5407288092534249" />
      <origin rpy="0 0 0" xyz="1.23423e+00 1.19000e-03 9.51000e-03" />
      <inertia ixx="3.376496181162572" ixy="0.9902619308692958" ixz="-1.3417963451103738" iyy="3.0096134333174955" iyz="1.6131067227770552" izz="2.0145905267546853" />
    </inertial>
    <collision name="motor23_collision">
      <origin rpy="0 0 0" xyz="1.23423e+00 1.19000e-03 9.51000e-03" />
      <geometry>
        <mesh filename="package://robots/human/meshes/collisions/motor23.stl" scale="0.001 0.001 0.001" />
      </geometry>
    </collision>
    <visual name="motor23_visual">
      <origin rpy="0 0 0" xyz="1.23423e+00 1.19000e-03 9.51000e-03" />
      <geometry>
        <mesh filename="package://robots/human/meshes/visuals/motor23.stl" scale="0.001 0.001 0.001" />
      </geometry>
    </visual>
  </link>
  <link name="motor17">
    <inertial>
      <mass value="0.5407289156587689" />
      <origin rpy="0 0 0" xyz="-1.19000e-03 -1.23423e+00  9.48000e-03" />
      <inertia ixx="3.0095420201366694" ixy="0.9902621278823456" ixz="-1.6130809798565902" iyy="3.376424839288629" iyz="1.341774292428606" izz="2.014590927188985" />
    </inertial>
    <collision name="motor17_collision">
      <origin rpy="0 0 0" xyz="-1.19000e-03 -1.23423e+00  9.48000e-03" />
      <geometry>
        <mesh filename="package://robots/human/meshes/collisions/motor17.stl" scale="0.001 0.001 0.001" />
      </geometry>
    </collision>
    <visual name="motor17_visual">
      <origin rpy="0 0 0" xyz="-1.19000e-03 -1.23423e+00  9.48000e-03" />
      <geometry>
        <mesh filename="package://robots/human/meshes/visuals/motor17.stl" scale="0.001 0.001 0.001" />
      </geometry>
    </visual>
  </link>
  <link name="dof6_link4">
    <inertial>
      <mass value="0.029253556048299417" />
      <origin rpy="0 0 0" xyz="4.264e-02 -6.000e-05  0.000e+00" />
      <inertia ixx="0.029253976989686226" ixy="1.1626215438336713e-07" ixz="-0.0012473616822221846" iyy="0.0293174136030794" iyz="2.077379146644587e-06" izz="6.385696503560865e-05" />
    </inertial>
    <collision name="dof6_link4_collision">
      <origin rpy="0 0 0" xyz="4.264e-02 -6.000e-05  0.000e+00" />
      <geometry>
        <mesh filename="package://robots/human/meshes/collisions/dof6_link4.stl" scale="0.001 0.001 0.001" />
      </geometry>
    </collision>
    <visual name="dof6_link4_visual">
      <origin rpy="0 0 0" xyz="4.264e-02 -6.000e-05  0.000e+00" />
      <geometry>
        <mesh filename="package://robots/human/meshes/visuals/dof6_link4.stl" scale="0.001 0.001 0.001" />
      </geometry>
    </visual>
  </link>
  <link name="dof6_link5">
    <inertial>
      <mass value="0.029267161202751052" />
      <origin rpy="0 0 0" xyz="6.000e-05 4.262e-02 0.000e+00" />
      <inertia ixx="0.029330975552184543" ixy="-1.0360731338597083e-07" ixz="-1.7800545179101354e-06" iyy="0.029267568334721984" iyz="-0.001247068788576186" izz="6.382844100897486e-05" />
    </inertial>
    <collision name="dof6_link5_collision">
      <origin rpy="0 0 0" xyz="6.000e-05 4.262e-02 0.000e+00" />
      <geometry>
        <mesh filename="package://robots/human/meshes/collisions/dof6_link5.stl" scale="0.001 0.001 0.001" />
      </geometry>
    </collision>
    <visual name="dof6_link5_visual">
      <origin rpy="0 0 0" xyz="6.000e-05 4.262e-02 0.000e+00" />
      <geometry>
        <mesh filename="package://robots/human/meshes/visuals/dof6_link5.stl" scale="0.001 0.001 0.001" />
      </geometry>
    </visual>
  </link>
  <link name="dof6_link1">
    <inertial>
      <mass value="0.03806502884740436" />
      <origin rpy="0 0 0" xyz="0 0 0" />
      <inertia ixx="0.03806670751903605" ixy="-1.361078074833995e-12" ixz="1.3516984396440834e-07" iyy="0.038066707515656516" iyz="3.8329167713316574e-07" izz="1.6786721116758843e-06" />
    </inertial>
    <collision name="dof6_link1_collision">
      <origin rpy="0 0 0" xyz="0 0 0" />
      <geometry>
        <mesh filename="package://robots/human/meshes/collisions/dof6_link1.stl" scale="0.001 0.001 0.001" />
      </geometry>
    </collision>
    <visual name="dof6_link1_visual">
      <origin rpy="0 0 0" xyz="0 0 0" />
      <geometry>
        <mesh filename="package://robots/human/meshes/visuals/dof6_link1.stl" scale="0.001 0.001 0.001" />
      </geometry>
    </visual>
  </link>
  <link name="dof6_link2">
    <inertial>
      <mass value="0.0029963725331776064" />
      <origin rpy="0 0 0" xyz="0 0 0" />
      <inertia ixx="0.002996396804098933" ixy="-1.0714025662895805e-13" ixz="1.064019179894265e-08" iyy="0.0029963968038329066" iyz="3.017164805422385e-08" izz="2.4270959112454043e-08" />
    </inertial>
    <collision name="dof6_link2_collision">
      <origin rpy="0 0 0" xyz="0 0 0" />
      <geometry>
        <mesh filename="package://robots/human/meshes/collisions/dof6_link2.stl" scale="0.001 0.001 0.001" />
      </geometry>
    </collision>
    <visual name="dof6_link2_visual">
      <origin rpy="0 0 0" xyz="0 0 0" />
      <geometry>
        <mesh filename="package://robots/human/meshes/visuals/dof6_link2.stl" scale="0.001 0.001 0.001" />
      </geometry>
    </visual>
  </link>
  <link name="dof6_link3">
    <inertial>
      <mass value="0.015709236754408065" />
      <origin rpy="0 0 0" xyz="0      0      0.01072" />
      <inertia ixx="0.016048786465636584" ixy="3.398942377017531e-12" ixz="5.256991621185631e-08" iyy="0.016048779040639085" iyz="1.6451093000258178e-07" izz="2.606891529664852e-07" />
    </inertial>
    <collision name="dof6_link3_collision">
      <origin rpy="0 0 0" xyz="0      0      0.01072" />
      <geometry>
        <mesh filename="package://robots/human/meshes/collisions/dof6_link3.stl" scale="0.001 0.001 0.001" />
      </geometry>
    </collision>
    <visual name="dof6_link3_visual">
      <origin rpy="0 0 0" xyz="0      0      0.01072" />
      <geometry>
        <mesh filename="package://robots/human/meshes/visuals/dof6_link3.stl" scale="0.001 0.001 0.001" />
      </geometry>
    </visual>
  </link>
  <link name="ankle_left_link1">
    <inertial>
      <mass value="0.03806502884740436" />
      <origin rpy="0 0 0" xyz="0 0 0" />
      <inertia ixx="0.0009714321985240435" ixy="8.862795727140744e-05" ixz="8.312979994612267e-05" iyy="0.0004707703302989443" iyz="-0.0004838840650257426" izz="0.0005327925590752096" />
    </inertial>
    <collision name="ankle_left_link1_collision">
      <origin rpy="0 0 0" xyz="0 0 0" />
      <geometry>
        <mesh filename="package://robots/human/meshes/collisions/ankle_left_link1.stl" scale="0.001 0.001 0.001" />
      </geometry>
    </collision>
    <visual name="ankle_left_link1_visual">
      <origin rpy="0 0 0" xyz="0 0 0" />
      <geometry>
        <mesh filename="package://robots/human/meshes/visuals/ankle_left_link1.stl" scale="0.001 0.001 0.001" />
      </geometry>
    </visual>
  </link>
  <link name="ankle_left_link2">
    <inertial>
      <mass value="0.0029963725331776064" />
      <origin rpy="0 0 0" xyz="0 0 0" />
      <inertia ixx="7.636055437932811e-05" ixy="6.976544741481062e-06" ixz="6.543745185263308e-06" iyy="3.694985338201701e-05" iyz="-3.808999928774074e-05" izz="4.183206964137318e-05" />
    </inertial>
    <collision name="ankle_left_link2_collision">
      <origin rpy="0 0 0" xyz="0 0 0" />
      <geometry>
        <mesh filename="package://robots/human/meshes/collisions/ankle_left_link2.stl" scale="0.001 0.001 0.001" />
      </geometry>
    </collision>
    <visual name="ankle_left_link2_visual">
      <origin rpy="0 0 0" xyz="0 0 0" />
      <geometry>
        <mesh filename="package://robots/human/meshes/visuals/ankle_left_link2.stl" scale="0.001 0.001 0.001" />
      </geometry>
    </visual>
  </link>
  <link name="ankle_right_link1">
    <inertial>
      <mass value="0.03806502884740436" />
      <origin rpy="0 0 0" xyz="0 0 0" />
      <inertia ixx="0.001047013751621923" ixy="-9.335600915223419e-05" ixz="8.485835023115486e-05" iyy="0.0004898413761948577" iyz="0.0005202962640969899" izz="0.0005893030662771736" />
    </inertial>
    <collision name="ankle_right_link1_collision">
      <origin rpy="0 0 0" xyz="0 0 0" />
      <geometry>
        <mesh filename="package://robots/human/meshes/collisions/ankle_right_link1.stl" scale="0.001 0.001 0.001" />
      </geometry>
    </collision>
    <visual name="ankle_right_link1_visual">
      <origin rpy="0 0 0" xyz="0 0 0" />
      <geometry>
        <mesh filename="package://robots/human/meshes/visuals/ankle_right_link1.stl" scale="0.001 0.001 0.001" />
      </geometry>
    </visual>
  </link>
  <link name="ankle_right_link2">
    <inertial>
      <mass value="0.0029963725331776064" />
      <origin rpy="0 0 0" xyz="0 0 0" />
      <inertia ixx="8.231012269898624e-05" ixy="-7.348723752508237e-06" ixz="6.679811825776045e-06" iyy="3.845107273825509e-05" iyz="4.0956265686935105e-05" izz="4.628041860479309e-05" />
    </inertial>
    <collision name="ankle_right_link2_collision">
      <origin rpy="0 0 0" xyz="0 0 0" />
      <geometry>
        <mesh filename="package://robots/human/meshes/collisions/ankle_right_link2.stl" scale="0.001 0.001 0.001" />
      </geometry>
    </collision>
    <visual name="ankle_right_link2_visual">
      <origin rpy="0 0 0" xyz="0 0 0" />
      <geometry>
        <mesh filename="package://robots/human/meshes/visuals/ankle_right_link2.stl" scale="0.001 0.001 0.001" />
      </geometry>
    </visual>
  </link>
  <link name="knee_left_link1">
    <inertial>
      <mass value="0.03806502884740436" />
      <origin rpy="0 0 0" xyz="0 0 0" />
      <inertia ixx="0.008647093942366983" ixy="7.765004450638728e-05" ixz="0.00035440889283178784" iyy="0.008266318059620302" iyz="-0.0018074245005940768" izz="0.00041290657359677375" />
    </inertial>
    <collision name="knee_left_link1_collision">
      <origin rpy="0 0 0" xyz="0 0 0" />
      <geometry>
        <mesh filename="package://robots/human/meshes/collisions/knee_left_link1.stl" scale="0.001 0.001 0.001" />
      </geometry>
    </collision>
    <visual name="knee_left_link1_visual">
      <origin rpy="0 0 0" xyz="0 0 0" />
      <geometry>
        <mesh filename="package://robots/human/meshes/visuals/knee_left_link1.stl" scale="0.001 0.001 0.001" />
      </geometry>
    </visual>
  </link>
  <link name="knee_left_link2">
    <inertial>
      <mass value="0.0029963725331776064" />
      <origin rpy="0 0 0" xyz="0 0 0" />
      <inertia ixx="0.0006805671639529709" ixy="6.112394173972182e-06" ixz="2.7898076112123256e-05" iyy="0.0006505935521915703" iyz="-0.00014227539800594784" izz="3.2394980405461305e-05" />
    </inertial>
    <collision name="knee_left_link2_collision">
      <origin rpy="0 0 0" xyz="0 0 0" />
      <geometry>
        <mesh filename="package://robots/human/meshes/collisions/knee_left_link2.stl" scale="0.001 0.001 0.001" />
      </geometry>
    </collision>
    <visual name="knee_left_link2_visual">
      <origin rpy="0 0 0" xyz="0 0 0" />
      <geometry>
        <mesh filename="package://robots/human/meshes/visuals/knee_left_link2.stl" scale="0.001 0.001 0.001" />
      </geometry>
    </visual>
  </link>
  <link name="knee_right_link1">
    <inertial>
      <mass value="0.03806502884740436" />
      <origin rpy="0 0 0" xyz="0 0 0" />
      <inertia ixx="0.008706071583498612" ixy="-8.319563989643591e-05" ixz="0.0003544173704500436" iyy="0.008266712723611043" iyz="0.0019365531051617538" izz="0.0004714895507376619" />
    </inertial>
    <collision name="knee_right_link1_collision">
      <origin rpy="0 0 0" xyz="0 0 0" />
      <geometry>
        <mesh filename="package://robots/human/meshes/collisions/knee_right_link1.stl" scale="0.001 0.001 0.001" />
      </geometry>
    </collision>
    <visual name="knee_right_link1_visual">
      <origin rpy="0 0 0" xyz="0 0 0" />
      <geometry>
        <mesh filename="package://robots/human/meshes/visuals/knee_right_link1.stl" scale="0.001 0.001 0.001" />
      </geometry>
    </visual>
  </link>
  <link name="knee_right_link2">
    <inertial>
      <mass value="0.0029963725331776064" />
      <origin rpy="0 0 0" xyz="0 0 0" />
      <inertia ixx="0.0006852097187942368" ixy="-6.548927921876891e-06" ixz="2.7898743446504933e-05" iyy="0.000650624619036323" iyz="0.00015244004034801" izz="3.700646840197439e-05" />
    </inertial>
    <collision name="knee_right_link2_collision">
      <origin rpy="0 0 0" xyz="0 0 0" />
      <geometry>
        <mesh filename="package://robots/human/meshes/collisions/knee_right_link2.stl" scale="0.001 0.001 0.001" />
      </geometry>
    </collision>
    <visual name="knee_right_link2_visual">
      <origin rpy="0 0 0" xyz="0 0 0" />
      <geometry>
        <mesh filename="package://robots/human/meshes/visuals/knee_right_link2.stl" scale="0.001 0.001 0.001" />
      </geometry>
    </visual>
  </link>
  <link name="hip_left_link1">
    <inertial>
      <mass value="0.03806502884740436" />
      <origin rpy="0 0 0" xyz="0 0 0" />
      <inertia ixx="0.03099108742490371" ixy="7.66988971473284e-05" ixz="0.000712058122150634" iyy="0.030652211237357358" iyz="-0.003299720232320919" izz="0.0003736570996474743" />
    </inertial>
    <collision name="hip_left_link1_collision">
      <origin rpy="0 0 0" xyz="0 0 0" />
      <geometry>
        <mesh filename="package://robots/human/meshes/collisions/hip_left_link1.stl" scale="0.001 0.001 0.001" />
      </geometry>
    </collision>
    <visual name="hip_left_link1_visual">
      <origin rpy="0 0 0" xyz="0 0 0" />
      <geometry>
        <mesh filename="package://robots/human/meshes/visuals/hip_left_link1.stl" scale="0.001 0.001 0.001" />
      </geometry>
    </visual>
  </link>
  <link name="hip_left_link2">
    <inertial>
      <mass value="0.0029963725331776064" />
      <origin rpy="0 0 0" xyz="0 0 0" />
      <inertia ixx="0.0024394237937736462" ixy="6.0375225159704616e-06" ixz="5.605122244334441e-05" iyy="0.0024127484087481323" iyz="-0.0002597447413197226" izz="2.9305371668927512e-05" />
    </inertial>
    <collision name="hip_left_link2_collision">
      <origin rpy="0 0 0" xyz="0 0 0" />
      <geometry>
        <mesh filename="package://robots/human/meshes/collisions/hip_left_link2.stl" scale="0.001 0.001 0.001" />
      </geometry>
    </collision>
    <visual name="hip_left_link2_visual">
      <origin rpy="0 0 0" xyz="0 0 0" />
      <geometry>
        <mesh filename="package://robots/human/meshes/visuals/hip_left_link2.stl" scale="0.001 0.001 0.001" />
      </geometry>
    </visual>
  </link>
  <link name="hip_right_link1">
    <inertial>
      <mass value="0.03806502884740436" />
      <origin rpy="0 0 0" xyz="0 0 0" />
      <inertia ixx="0.031038242802203464" ixy="-8.162839722989146e-05" ixz="0.0007120581221488894" iyy="0.030652211237337215" iyz="0.0035117959174106234" izz="0.00042081247696724024" />
    </inertial>
    <collision name="hip_right_link1_collision">
      <origin rpy="0 0 0" xyz="0 0 0" />
      <geometry>
        <mesh filename="package://robots/human/meshes/collisions/hip_right_link1.stl" scale="0.001 0.001 0.001" />
      </geometry>
    </collision>
    <visual name="hip_right_link1_visual">
      <origin rpy="0 0 0" xyz="0 0 0" />
      <geometry>
        <mesh filename="package://robots/human/meshes/visuals/hip_right_link1.stl" scale="0.001 0.001 0.001" />
      </geometry>
    </visual>
  </link>
  <link name="hip_right_link2">
    <inertial>
      <mass value="0.0029963725331776064" />
      <origin rpy="0 0 0" xyz="0 0 0" />
      <inertia ixx="0.002443135733094619" ixy="-6.4255589656182875e-06" ixz="5.6051222443207106e-05" iyy="0.002412748408746547" iyz="0.0002764387456853846" izz="3.3017310991474705e-05" />
    </inertial>
    <collision name="hip_right_link2_collision">
      <origin rpy="0 0 0" xyz="0 0 0" />
      <geometry>
        <mesh filename="package://robots/human/meshes/collisions/hip_right_link2.stl" scale="0.001 0.001 0.001" />
      </geometry>
    </collision>
    <visual name="hip_right_link2_visual">
      <origin rpy="0 0 0" xyz="0 0 0" />
      <geometry>
        <mesh filename="package://robots/human/meshes/visuals/hip_right_link2.stl" scale="0.001 0.001 0.001" />
      </geometry>
    </visual>
  </link>
  <link name="spine_link1">
    <inertial>
      <mass value="0.03806502884740436" />
      <origin rpy="0 0 0" xyz="0 0 0" />
      <inertia ixx="0.04040389695045235" ixy="-2.3575906660248277e-06" ixz="0.0007843207784685275" iyy="0.04041875791342068" iyz="0.00012144397380473562" izz="1.7269727881738925e-05" />
    </inertial>
    <collision name="spine_link1_collision">
      <origin rpy="0 0 0" xyz="0 0 0" />
      <geometry>
        <mesh filename="package://robots/human/meshes/collisions/spine_link1.stl" scale="0.001 0.001 0.001" />
      </geometry>
    </collision>
    <visual name="spine_link1_visual">
      <origin rpy="0 0 0" xyz="0 0 0" />
      <geometry>
        <mesh filename="package://robots/human/meshes/visuals/spine_link1.stl" scale="0.001 0.001 0.001" />
      </geometry>
    </visual>
  </link>
  <link name="spine_link2">
    <inertial>
      <mass value="0.0029963725331776064" />
      <origin rpy="0 0 0" xyz="0 0 0" />
      <inertia ixx="0.0031803738147352044" ixy="-1.855829387249871e-07" ixz="6.173953649752266e-05" iyy="0.0031815436281467054" iyz="9.55972971640779e-06" izz="1.2515552325576518e-06" />
    </inertial>
    <collision name="spine_link2_collision">
      <origin rpy="0 0 0" xyz="0 0 0" />
      <geometry>
        <mesh filename="package://robots/human/meshes/collisions/spine_link2.stl" scale="0.001 0.001 0.001" />
      </geometry>
    </collision>
    <visual name="spine_link2_visual">
      <origin rpy="0 0 0" xyz="0 0 0" />
      <geometry>
        <mesh filename="package://robots/human/meshes/visuals/spine_link2.stl" scale="0.001 0.001 0.001" />
      </geometry>
    </visual>
  </link>
  <link name="shoulder_left_link1">
    <inertial>
      <mass value="0.03806502884740436" />
      <origin rpy="0 0 0" xyz="0 0 0" />
      <inertia ixx="0.07557366688379621" ixy="0.00045456876724987483" ixz="0.0035043419382132087" iyy="0.07448835270766202" iyz="-0.009640670367043691" izz="0.0014174604014988406" />
    </inertial>
    <collision name="shoulder_left_link1_collision">
      <origin rpy="0 0 0" xyz="0 0 0" />
      <geometry>
        <mesh filename="package://robots/human/meshes/collisions/shoulder_left_link1.stl" scale="0.001 0.001 0.001" />
      </geometry>
    </collision>
    <visual name="shoulder_left_link1_visual">
      <origin rpy="0 0 0" xyz="0 0 0" />
      <geometry>
        <mesh filename="package://robots/human/meshes/visuals/shoulder_left_link1.stl" scale="0.001 0.001 0.001" />
      </geometry>
    </visual>
  </link>
  <link name="shoulder_left_link2">
    <inertial>
      <mass value="0.0029963725331776064" />
      <origin rpy="0 0 0" xyz="0 0 0" />
      <inertia ixx="0.005948839669546528" ixy="3.578238109547124e-05" ixz="0.0002758519893054131" iyy="0.005863406775215266" iyz="-0.0007588865886594165" izz="0.00011147064615868532" />
    </inertial>
    <collision name="shoulder_left_link2_collision">
      <origin rpy="0 0 0" xyz="0 0 0" />
      <geometry>
        <mesh filename="package://robots/human/meshes/collisions/shoulder_left_link2.stl" scale="0.001 0.001 0.001" />
      </geometry>
    </collision>
    <visual name="shoulder_left_link2_visual">
      <origin rpy="0 0 0" xyz="0 0 0" />
      <geometry>
        <mesh filename="package://robots/human/meshes/visuals/shoulder_left_link2.stl" scale="0.001 0.001 0.001" />
      </geometry>
    </visual>
  </link>
  <link name="shoulder_right_link1">
    <inertial>
      <mass value="0.03806502884740436" />
      <origin rpy="0 0 0" xyz="0 0 0" />
      <inertia ixx="0.07566083279215148" ixy="-0.00047014414446832595" ixz="0.0035043419382073168" iyy="0.07448835270766278" iyz="0.00997099899591451" izz="0.001504626309852232" />
    </inertial>
    <collision name="shoulder_right_link1_collision">
      <origin rpy="0 0 0" xyz="0 0 0" />
      <geometry>
        <mesh filename="package://robots/human/meshes/collisions/shoulder_right_link1.stl" scale="0.001 0.001 0.001" />
      </geometry>
    </collision>
    <visual name="shoulder_right_link1_visual">
      <origin rpy="0 0 0" xyz="0 0 0" />
      <geometry>
        <mesh filename="package://robots/human/meshes/visuals/shoulder_right_link1.stl" scale="0.001 0.001 0.001" />
      </geometry>
    </visual>
  </link>
  <link name="shoulder_right_link2">
    <inertial>
      <mass value="0.0029963725331776064" />
      <origin rpy="0 0 0" xyz="0 0 0" />
      <inertia ixx="0.0059557011258893665" ixy="-3.700843119721519e-05" ixz="0.0002758519893049495" iyy="0.005863406775215328" iyz="0.0007848891337891895" izz="0.000118332102501372" />
    </inertial>
    <collision name="shoulder_right_link2_collision">
      <origin rpy="0 0 0" xyz="0 0 0" />
      <geometry>
        <mesh filename="package://robots/human/meshes/collisions/shoulder_right_link2.stl" scale="0.001 0.001 0.001" />
      </geometry>
    </collision>
    <visual name="shoulder_right_link2_visual">
      <origin rpy="0 0 0" xyz="0 0 0" />
      <geometry>
        <mesh filename="package://robots/human/meshes/visuals/shoulder_right_link2.stl" scale="0.001 0.001 0.001" />
      </geometry>
    </visual>
  </link>
  <link name="elbow_left_link1">
    <inertial>
      <mass value="0.03806502884740436" />
      <origin rpy="0 0 0" xyz="0 0 0" />
      <inertia ixx="0.05102645165717749" ixy="0.0007376489690374443" ixz="0.0038686175730142758" iyy="0.04954040108334068" iyz="-0.009387839179633145" izz="0.002095682085651115" />
    </inertial>
    <collision name="elbow_left_link1_collision">
      <origin rpy="0 0 0" xyz="0 0 0" />
      <geometry>
        <mesh filename="package://robots/human/meshes/collisions/elbow_left_link1.stl" scale="0.001 0.001 0.001" />
      </geometry>
    </collision>
    <visual name="elbow_left_link1_visual">
      <origin rpy="0 0 0" xyz="0 0 0" />
      <geometry>
        <mesh filename="package://robots/human/meshes/visuals/elbow_left_link1.stl" scale="0.001 0.001 0.001" />
      </geometry>
    </visual>
  </link>
  <link name="elbow_left_link2">
    <inertial>
      <mass value="0.0029963725331776064" />
      <origin rpy="0 0 0" xyz="0 0 0" />
      <inertia ixx="0.0040165515904832475" ixy="5.806566228574645e-05" ixz="0.00030452674772998725" iyy="0.0038995738485194183" iyz="-0.0007389844252189366" izz="0.00016485835890536586" />
    </inertial>
    <collision name="elbow_left_link2_collision">
      <origin rpy="0 0 0" xyz="0 0 0" />
      <geometry>
        <mesh filename="package://robots/human/meshes/collisions/elbow_left_link2.stl" scale="0.001 0.001 0.001" />
      </geometry>
    </collision>
    <visual name="elbow_left_link2_visual">
      <origin rpy="0 0 0" xyz="0 0 0" />
      <geometry>
        <mesh filename="package://robots/human/meshes/visuals/elbow_left_link2.stl" scale="0.001 0.001 0.001" />
      </geometry>
    </visual>
  </link>
  <link name="elbow_right_link1">
    <inertial>
      <mass value="0.03806502884740436" />
      <origin rpy="0 0 0" xyz="0 0 0" />
      <inertia ixx="0.05113044935805403" ixy="-0.0007587745716196841" ixz="0.0038686175730165448" iyy="0.04954040108333132" iyz="0.009656698444586921" izz="0.0021996797865378513" />
    </inertial>
    <collision name="elbow_right_link1_collision">
      <origin rpy="0 0 0" xyz="0 0 0" />
      <geometry>
        <mesh filename="package://robots/human/meshes/collisions/elbow_right_link1.stl" scale="0.001 0.001 0.001" />
      </geometry>
    </collision>
    <visual name="elbow_right_link1_visual">
      <origin rpy="0 0 0" xyz="0 0 0" />
      <geometry>
        <mesh filename="package://robots/human/meshes/visuals/elbow_right_link1.stl" scale="0.001 0.001 0.001" />
      </geometry>
    </visual>
  </link>
  <link name="elbow_right_link2">
    <inertial>
      <mass value="0.0029963725331776064" />
      <origin rpy="0 0 0" xyz="0 0 0" />
      <inertia ixx="0.004024737998423967" ixy="-5.972861059396939e-05" ixz="0.0003045267477301657" iyy="0.0038995738485186823" iyz="0.0007601482740636947" izz="0.00017304476684688747" />
    </inertial>
    <collision name="elbow_right_link2_collision">
      <origin rpy="0 0 0" xyz="0 0 0" />
      <geometry>
        <mesh filename="package://robots/human/meshes/collisions/elbow_right_link2.stl" scale="0.001 0.001 0.001" />
      </geometry>
    </collision>
    <visual name="elbow_right_link2_visual">
      <origin rpy="0 0 0" xyz="0 0 0" />
      <geometry>
        <mesh filename="package://robots/human/meshes/visuals/elbow_right_link2.stl" scale="0.001 0.001 0.001" />
      </geometry>
    </visual>
  </link>
</robot>