<sdf version="1.6">
	<model name="human">
		<link name="base">
			<self_collide>false</self_collide>
			<pose frame="">-6.9500252010331e-08 -1.9707701204956554e-07 0.7639152503965678 0.0 -0.0 0.0</pose>
			<inertial>
				<pose frame="">0.0 0.0 0.0 0 0 0</pose>
				<mass>5.670211945411031</mass>
				<inertia>
					<ixx>13.426879502251602</ixx>
					<ixy>-3.887718206911639e-12</ixy>
					<ixz>3.940811655216425e-07</ixz>
					<iyy>13.426879502241684</iyy>
					<iyz>1.1174684337865282e-06</iyz>
					<izz>12.564006179452424</izz>
				</inertia>
			</inertial>
			<collision name="base_collision">
				<geometry>
					<mesh>
						<uri>model://human/meshes/collisions/base.stl</uri>
						<scale>0.001 0.001 0.001</scale>
					</mesh>
				</geometry>
			</collision>
			<visual name="base_visual">
				<geometry>
					<mesh>
						<uri>model://human/meshes/visuals/base.stl</uri>
						<scale>0.001 0.001 0.001</scale>
					</mesh>
				</geometry>
			</visual>
		</link>
		<link name="hip">
			<self_collide>false</self_collide>
			<pose frame="">-0.019384473705082953 -0.003106221167012608 0.9505744894839634 0.0 -0.0 0.0</pose>
			<inertial>
				<pose frame="">0.0 0.0 0.0 0 0 0</pose>
				<mass>43.24409919015801</mass>
				<inertia>
					<ixx>39.338954158435655</ixx>
					<ixy>-0.002514620735701843</ixy>
					<ixz>0.7920766825179428</ixz>
					<iyy>39.325027251694706</iyy>
					<iyz>0.127065516007698</iyz>
					<izz>0.3005991852048205</izz>
				</inertia>
			</inertial>
			<collision name="hip_collision">
				<geometry>
					<mesh>
						<uri>model://human/meshes/collisions/hip.stl</uri>
						<scale>0.001 0.001 0.001</scale>
					</mesh>
				</geometry>
			</collision>
			<visual name="hip_visual">
				<geometry>
					<mesh>
						<uri>model://human/meshes/visuals/hip.stl</uri>
						<scale>0.001 0.001 0.001</scale>
					</mesh>
				</geometry>
			</visual>
		</link>
		<link name="upper_leg_left">
			<self_collide>false</self_collide>
			<pose frame="">-0.013133702874234777 0.10300934162959659 0.7421210878125339 0.0 -0.0 0.0</pose>
			<inertial>
				<pose frame="">0.0 0.0 0.0 0 0 0</pose>
				<mass>63.30402235160809</mass>
				<inertia>
					<ixx>36.57190754572642</ixx>
					<ixy>0.0786067246776424</ixy>
					<ixz>0.6462990522451668</ixz>
					<iyy>35.96736804228855</iyy>
					<iyz>-4.847722704192384</iyz>
					<izz>0.8765201070874777</izz>
				</inertia>
			</inertial>
			<collision name="upper_leg_left_collision">
				<geometry>
					<mesh>
						<uri>model://human/meshes/collisions/upper_leg_left.stl</uri>
						<scale>0.001 0.001 0.001</scale>
					</mesh>
				</geometry>
			</collision>
			<visual name="upper_leg_left_visual">
				<geometry>
					<mesh>
						<uri>model://human/meshes/visuals/upper_leg_left.stl</uri>
						<scale>0.001 0.001 0.001</scale>
					</mesh>
				</geometry>
			</visual>
		</link>
		<link name="lower_leg_left">
			<self_collide>false</self_collide>
			<pose frame="">-0.03675009640078987 0.10833314346490344 0.3187193650741261 0.0 -0.0 0.0</pose>
			<inertial>
				<pose frame="">0.0 0.0 0.0 0 0 0</pose>
				<mass>28.449648630223585</mass>
				<inertia>
					<ixx>3.5618512908284417</ixx>
					<ixy>0.11137748128345827</ixy>
					<ixz>0.3321209674824219</ixz>
					<iyy>3.277808953441893</iyy>
					<iyz>-0.9718967324191882</iyz>
					<izz>0.4199966653173898</izz>
				</inertia>
			</inertial>
			<collision name="lower_leg_left_collision">
				<geometry>
					<mesh>
						<uri>model://human/meshes/collisions/lower_leg_left.stl</uri>
						<scale>0.001 0.001 0.001</scale>
					</mesh>
				</geometry>
			</collision>
			<visual name="lower_leg_left_visual">
				<geometry>
					<mesh>
						<uri>model://human/meshes/visuals/lower_leg_left.stl</uri>
						<scale>0.001 0.001 0.001</scale>
					</mesh>
				</geometry>
			</visual>
		</link>
		<link name="foot_left">
			<self_collide>false</self_collide>
			<pose frame="">-0.0199999866306705 0.11641649512815062 0.10980031721208083 0.0 -0.0 0.0</pose>
			<inertial>
				<pose frame="">0.0 0.0 0.0 0 0 0</pose>
				<mass>0.2795713024331067</mass>
				<inertia>
					<ixx>0.007203954491699386</ixx>
					<ixy>0.0006509337921648627</ixy>
					<ixz>0.0006139398708679091</ixz>
					<iyy>0.003526808635494107</iyy>
					<iyz>-0.0035736391223248043</iyz>
					<izz>0.003943161605729023</izz>
				</inertia>
			</inertial>
			<collision name="foot_left_collision">
				<geometry>
					<mesh>
						<uri>model://human/meshes/collisions/foot_left.stl</uri>
						<scale>0.001 0.001 0.001</scale>
					</mesh>
				</geometry>
			</collision>
			<visual name="foot_left_visual">
				<geometry>
					<mesh>
						<uri>model://human/meshes/visuals/foot_left.stl</uri>
						<scale>0.001 0.001 0.001</scale>
					</mesh>
				</geometry>
			</visual>
		</link>
		<link name="upper_leg_right">
			<self_collide>false</self_collide>
			<pose frame="">-0.013132931632364215 -0.10924060480270813 0.7421068077195524 0.0 -0.0 0.0</pose>
			<inertial>
				<pose frame="">0.0 0.0 0.0 0 0 0</pose>
				<mass>63.30480762272283</mass>
				<inertia>
					<ixx>36.654533662691485</ixx>
					<ixy>-0.08379280764495882</ixy>
					<ixz>0.646254140736353</ixz>
					<iyy>35.966271731076944</iyy>
					<iyz>5.140564976562167</iyz>
					<izz>0.9602361139729543</izz>
				</inertia>
			</inertial>
			<collision name="upper_leg_right_collision">
				<geometry>
					<mesh>
						<uri>model://human/meshes/collisions/upper_leg_right.stl</uri>
						<scale>0.001 0.001 0.001</scale>
					</mesh>
				</geometry>
			</collision>
			<visual name="upper_leg_right_visual">
				<geometry>
					<mesh>
						<uri>model://human/meshes/visuals/upper_leg_right.stl</uri>
						<scale>0.001 0.001 0.001</scale>
					</mesh>
				</geometry>
			</visual>
		</link>
		<link name="lower_leg_right">
			<self_collide>false</self_collide>
			<pose frame="">-0.03765511384393071 -0.11421998983201205 0.32809353837770006 0.0 -0.0 0.0</pose>
			<inertial>
				<pose frame="">0.0 0.0 0.0 0 0 0</pose>
				<mass>27.241031189816738</mass>
				<inertia>
					<ixx>3.5688762186354137</ixx>
					<ixy>-0.11545630015272085</ixy>
					<ixz>0.32998155868610246</ixz>
					<iyy>3.263067799956089</iyy>
					<iyz>1.0124959528503439</iyz>
					<izz>0.440507796966936</izz>
				</inertia>
			</inertial>
			<collision name="lower_leg_right_collision">
				<geometry>
					<mesh>
						<uri>model://human/meshes/collisions/lower_leg_right.stl</uri>
						<scale>0.001 0.001 0.001</scale>
					</mesh>
				</geometry>
			</collision>
			<visual name="lower_leg_right_visual">
				<geometry>
					<mesh>
						<uri>model://human/meshes/visuals/lower_leg_right.stl</uri>
						<scale>0.001 0.001 0.001</scale>
					</mesh>
				</geometry>
			</visual>
		</link>
		<link name="foot_right">
			<self_collide>false</self_collide>
			<pose frame="">-0.01999998663066986 -0.12262702057905658 0.11207083996928616 0.0 -0.0 0.0</pose>
			<inertial>
				<pose frame="">0.0 0.0 0.0 0 0 0</pose>
				<mass>0.2795713024331067</mass>
				<inertia>
					<ixx>0.007759839909093018</ixx>
					<ixy>-0.0006856594548557962</ixy>
					<ixz>0.0006266353224701174</ixz>
					<iyy>0.0036676464565357832</iyy>
					<iyz>0.003842124230428521</iyz>
					<izz>0.004358209202080964</izz>
				</inertia>
			</inertial>
			<collision name="foot_right_collision">
				<geometry>
					<mesh>
						<uri>model://human/meshes/collisions/foot_right.stl</uri>
						<scale>0.001 0.001 0.001</scale>
					</mesh>
				</geometry>
			</collision>
			<visual name="foot_right_visual">
				<geometry>
					<mesh>
						<uri>model://human/meshes/visuals/foot_right.stl</uri>
						<scale>0.001 0.001 0.001</scale>
					</mesh>
				</geometry>
			</visual>
		</link>
		<link name="torso">
			<self_collide>false</self_collide>
			<pose frame="">-0.017136291885993197 -0.00313111200531512 1.6371450924254927 0.0 -0.0 0.0</pose>
			<inertial>
				<pose frame="">0.0 0.0 0.0 0 0 0</pose>
				<mass>37.90394723937322</mass>
				<inertia>
					<ixx>102.1011103005115</ixx>
					<ixy>-0.001971690796654316</ixy>
					<ixz>1.0869837332175591</ixz>
					<iyy>102.15792220015128</iyy>
					<iyz>0.19411618767898478</iyz>
					<izz>0.17722591078345298</izz>
				</inertia>
			</inertial>
			<collision name="torso_collision">
				<geometry>
					<mesh>
						<uri>model://human/meshes/collisions/torso.stl</uri>
						<scale>0.001 0.001 0.001</scale>
					</mesh>
				</geometry>
			</collision>
			<visual name="torso_visual">
				<geometry>
					<mesh>
						<uri>model://human/meshes/visuals/torso.stl</uri>
						<scale>0.001 0.001 0.001</scale>
					</mesh>
				</geometry>
			</visual>
		</link>
		<link name="upper_arm_left">
			<self_collide>false</self_collide>
			<pose frame="">-0.08632147767622846 0.21224200779146 1.17230551318406 0.0 -0.0 0.0</pose>
			<inertial>
				<pose frame="">0.0 0.0 0.0 0 0 0</pose>
				<mass>0.12749203806058093</mass>
				<inertia>
					<ixx>0.18203449514488937</ixx>
					<ixy>0.0023478029049020972</ixy>
					<ixz>0.012810352043252878</ixz>
					<iyy>0.17723110178953327</iyy>
					<iyz>-0.03158328681375136</iyz>
					<izz>0.0067294875823005135</izz>
				</inertia>
			</inertial>
			<collision name="upper_arm_left_collision">
				<geometry>
					<mesh>
						<uri>model://human/meshes/collisions/upper_arm_left.stl</uri>
						<scale>0.001 0.001 0.001</scale>
					</mesh>
				</geometry>
			</collision>
			<visual name="upper_arm_left_visual">
				<geometry>
					<mesh>
						<uri>model://human/meshes/visuals/upper_arm_left.stl</uri>
						<scale>0.001 0.001 0.001</scale>
					</mesh>
				</geometry>
			</visual>
		</link>
		<link name="lower_arm_left">
			<self_collide>false</self_collide>
			<pose frame="">-0.08936259420261383 0.21685336125050608 1.1475501528748333 0.0 -0.0 0.0</pose>
			<inertial>
				<pose frame="">0.0 0.0 0.0 0 0 0</pose>
				<mass>0.016515277572521365</mass>
				<inertia>
					<ixx>0.02252584776365808</ixx>
					<ixy>0.0003200426138108468</ixy>
					<ixz>0.0016936096164630087</ixz>
					<iyy>0.021881095979910607</iyy>
					<iyz>-0.004109828560888341</iyz>
					<izz>0.0009087930467704993</izz>
				</inertia>
			</inertial>
			<collision name="lower_arm_left_collision">
				<geometry>
					<mesh>
						<uri>model://human/meshes/collisions/lower_arm_left.stl</uri>
						<scale>0.001 0.001 0.001</scale>
					</mesh>
				</geometry>
			</collision>
			<visual name="lower_arm_left_visual">
				<geometry>
					<mesh>
						<uri>model://human/meshes/visuals/lower_arm_left.stl</uri>
						<scale>0.001 0.001 0.001</scale>
					</mesh>
				</geometry>
			</visual>
		</link>
		<link name="upper_arm_right">
			<self_collide>false</self_collide>
			<pose frame="">-0.08632147767626734 -0.21845257198789086 1.1723055131839635 0.0 -0.0 0.0</pose>
			<inertial>
				<pose frame="">0.0 0.0 0.0 0 0 0</pose>
				<mass>0.12749203806058088</mass>
				<inertia>
					<ixx>0.18237551746795594</ixx>
					<ixy>-0.002416151840534216</ixy>
					<ixz>0.012810352043256907</ixz>
					<iyy>0.17723110178950618</iyy>
					<iyz>0.032511517597940305</iyz>
					<izz>0.007070509905396119</izz>
				</inertia>
			</inertial>
			<collision name="upper_arm_right_collision">
				<geometry>
					<mesh>
						<uri>model://human/meshes/collisions/upper_arm_right.stl</uri>
						<scale>0.001 0.001 0.001</scale>
					</mesh>
				</geometry>
			</collision>
			<visual name="upper_arm_right_visual">
				<geometry>
					<mesh>
						<uri>model://human/meshes/visuals/upper_arm_right.stl</uri>
						<scale>0.001 0.001 0.001</scale>
					</mesh>
				</geometry>
			</visual>
		</link>
		<link name="lower_arm_right">
			<self_collide>false</self_collide>
			<pose frame="">-0.0893625942026751 -0.22306440406628297 1.1475501528747198 0.0 -0.0 0.0</pose>
			<inertial>
				<pose frame="">0.0 0.0 0.0 0 0 0</pose>
				<mass>0.016515277572521362</mass>
				<inertia>
					<ixx>0.02257097325055043</ixx>
					<ixy>-0.0003292091613496685</ixy>
					<ixz>0.0016936096164640027</ixz>
					<iyy>0.0218810959799065</iyy>
					<iyz>0.0042275410117780885</iyz>
					<izz>0.0009539185336673193</izz>
				</inertia>
			</inertial>
			<collision name="lower_arm_right_collision">
				<geometry>
					<mesh>
						<uri>model://human/meshes/collisions/lower_arm_right.stl</uri>
						<scale>0.001 0.001 0.001</scale>
					</mesh>
				</geometry>
			</collision>
			<visual name="lower_arm_right_visual">
				<geometry>
					<mesh>
						<uri>model://human/meshes/visuals/lower_arm_right.stl</uri>
						<scale>0.001 0.001 0.001</scale>
					</mesh>
				</geometry>
			</visual>
		</link>
		<link name="motor3">
			<self_collide>false</self_collide>
			<pose frame="">-1.4838021873254814 -1.2342394028102621 0.01051655894117484 0.0 -0.0 0.0</pose>
			<inertial>
				<pose frame="">0.0 0.0 0.0 0 0 0</pose>
				<mass>0.5407289156586891</mass>
				<inertia>
					<ixx>0.8239519347007563</ixx>
					<ixy>-0.9902621278821997</ixy>
					<ixz>0.008437545456538848</ixz>
					<iyy>1.1908347538526611</iyy>
					<iyz>0.007018743074075354</iyz>
					<izz>2.0145909271886877</izz>
				</inertia>
			</inertial>
			<collision name="motor3_collision">
				<geometry>
					<mesh>
						<uri>model://human/meshes/collisions/motor3.stl</uri>
						<scale>0.001 0.001 0.001</scale>
					</mesh>
				</geometry>
			</collision>
			<visual name="motor3_visual">
				<geometry>
					<mesh>
						<uri>model://human/meshes/visuals/motor3.stl</uri>
						<scale>0.001 0.001 0.001</scale>
					</mesh>
				</geometry>
			</visual>
		</link>
		<link name="motor2">
			<self_collide>false</self_collide>
			<pose frame="">-1.485334311593426 1.2358101926090346 0.010485803664418522 0.0 -0.0 0.0</pose>
			<inertial>
				<pose frame="">0.0 0.0 0.0 0 0 0</pose>
				<mass>0.5915184316952449</mass>
				<inertia>
					<ixx>0.9036405133260113</ixx>
					<ixy>1.0857914520512877</ixy>
					<ixz>0.009213108679123352</ixz>
					<iyy>1.3053863599243112</iyy>
					<iyz>-0.007665084014776147</iyz>
					<izz>2.2088188733016993</izz>
				</inertia>
			</inertial>
			<collision name="motor2_collision">
				<geometry>
					<mesh>
						<uri>model://human/meshes/collisions/motor2.stl</uri>
						<scale>0.001 0.001 0.001</scale>
					</mesh>
				</geometry>
			</collision>
			<visual name="motor2_visual">
				<geometry>
					<mesh>
						<uri>model://human/meshes/visuals/motor2.stl</uri>
						<scale>0.001 0.001 0.001</scale>
					</mesh>
				</geometry>
			</visual>
		</link>
		<link name="motor0">
			<self_collide>false</self_collide>
			<pose frame="">1.4853343115934643 1.2358101926090335 0.01051419634034889 0.0 -0.0 0.0</pose>
			<inertial>
				<pose frame="">0.0 0.0 0.0 0 0 0</pose>
				<mass>0.5915184316951642</mass>
				<inertia>
					<ixx>0.9036408660165021</ixx>
					<ixy>-1.0857914520511684</ixy>
					<ixz>-0.009237546389943497</ixz>
					<iyy>1.305386712614818</iyy>
					<iyz>-0.007686010628829871</iyz>
					<izz>2.2088188733014675</izz>
				</inertia>
			</inertial>
			<collision name="motor0_collision">
				<geometry>
					<mesh>
						<uri>model://human/meshes/collisions/motor0.stl</uri>
						<scale>0.001 0.001 0.001</scale>
					</mesh>
				</geometry>
			</collision>
			<visual name="motor0_visual">
				<geometry>
					<mesh>
						<uri>model://human/meshes/visuals/motor0.stl</uri>
						<scale>0.001 0.001 0.001</scale>
					</mesh>
				</geometry>
			</visual>
		</link>
		<link name="motor4">
			<self_collide>false</self_collide>
			<pose frame="">-1.2358101829513672 1.485334301546107 0.01051419449950688 0.0 -0.0 0.0</pose>
			<inertial>
				<pose frame="">0.0 0.0 0.0 0 0 0</pose>
				<mass>0.5915182656349381</mass>
				<inertia>
					<ixx>1.3053863288187992</ixx>
					<ixy>1.085791131455688</ixy>
					<ixz>0.007686007040985962</ixz>
					<iyy>0.9036405981034654</iyy>
					<iyz>-0.009237542099685631</iyz>
					<izz>2.2088182216814296</izz>
				</inertia>
			</inertial>
			<collision name="motor4_collision">
				<geometry>
					<mesh>
						<uri>model://human/meshes/collisions/motor4.stl</uri>
						<scale>0.001 0.001 0.001</scale>
					</mesh>
				</geometry>
			</collision>
			<visual name="motor4_visual">
				<geometry>
					<mesh>
						<uri>model://human/meshes/visuals/motor4.stl</uri>
						<scale>0.001 0.001 0.001</scale>
					</mesh>
				</geometry>
			</visual>
		</link>
		<link name="motor5">
			<self_collide>false</self_collide>
			<pose frame="">1.2358101926090344 1.4853343115934126 0.010485803664418505 0.0 -0.0 0.0</pose>
			<inertial>
				<pose frame="">0.0 0.0 0.0 0 0 0</pose>
				<mass>0.5915184316952438</mass>
				<inertia>
					<ixx>1.3053863599242819</ixx>
					<ixy>-1.0857914520512741</ixy>
					<ixz>-0.007665084014776132</ixz>
					<iyy>0.9036405133260096</iyy>
					<iyz>-0.009213108679123314</iyz>
					<izz>2.2088188733016674</izz>
				</inertia>
			</inertial>
			<collision name="motor5_collision">
				<geometry>
					<mesh>
						<uri>model://human/meshes/collisions/motor5.stl</uri>
						<scale>0.001 0.001 0.001</scale>
					</mesh>
				</geometry>
			</collision>
			<visual name="motor5_visual">
				<geometry>
					<mesh>
						<uri>model://human/meshes/visuals/motor5.stl</uri>
						<scale>0.001 0.001 0.001</scale>
					</mesh>
				</geometry>
			</visual>
		</link>
		<link name="motor6">
			<self_collide>false</self_collide>
			<pose frame="">-1.2358101829513677 -1.4853343018224894 0.01048580550527066 0.0 -0.0 0.0</pose>
			<inertial>
				<pose frame="">0.0 0.0 0.0 0 0 0</pose>
				<mass>0.5915182656350185</mass>
				<inertia>
					<ixx>1.3053859761740971</ixx>
					<ixy>-1.0857911314557949</ixy>
					<ixz>0.007665083173063848</ixz>
					<iyy>0.9036402454588066</iyy>
					<iyz>0.009213107668262954</iyz>
					<izz>2.2088182216816317</izz>
				</inertia>
			</inertial>
			<collision name="motor6_collision">
				<geometry>
					<mesh>
						<uri>model://human/meshes/collisions/motor6.stl</uri>
						<scale>0.001 0.001 0.001</scale>
					</mesh>
				</geometry>
			</collision>
			<visual name="motor6_visual">
				<geometry>
					<mesh>
						<uri>model://human/meshes/visuals/motor6.stl</uri>
						<scale>0.001 0.001 0.001</scale>
					</mesh>
				</geometry>
			</visual>
		</link>
		<link name="motor1">
			<self_collide>false</self_collide>
			<pose frame="">1.4853343015460536 -1.2358101829513677 0.010485805505270663 0.0 -0.0 0.0</pose>
			<inertial>
				<pose frame="">0.0 0.0 0.0 0 0 0</pose>
				<mass>0.5915182656350185</mass>
				<inertia>
					<ixx>0.9036402454588068</ixx>
					<ixy>1.0857911314557955</ixy>
					<ixz>-0.009213107668262955</ixz>
					<iyy>1.3053859761740987</iyy>
					<iyz>0.007665083173063846</iyz>
					<izz>2.208818221681633</izz>
				</inertia>
			</inertial>
			<collision name="motor1_collision">
				<geometry>
					<mesh>
						<uri>model://human/meshes/collisions/motor1.stl</uri>
						<scale>0.001 0.001 0.001</scale>
					</mesh>
				</geometry>
			</collision>
			<visual name="motor1_visual">
				<geometry>
					<mesh>
						<uri>model://human/meshes/visuals/motor1.stl</uri>
						<scale>0.001 0.001 0.001</scale>
					</mesh>
				</geometry>
			</visual>
		</link>
		<link name="motor10">
			<self_collide>false</self_collide>
			<pose frame="">-1.483802186329325 1.2342394009707196 1.0104834407810215 0.0 -0.0 0.0</pose>
			<inertial>
				<pose frame="">0.0 0.0 0.0 0 0 0</pose>
				<mass>0.5407288092535038</mass>
				<inertia>
					<ixx>1.3760176002125752</ixx>
					<ixy>0.99026193086944</ixy>
					<ixz>0.8107460717445298</ixz>
					<iyy>1.7429003480577039</iyy>
					<iyz>-0.6743852245854303</iyz>
					<izz>2.0145905267549784</izz>
				</inertia>
			</inertial>
			<collision name="motor10_collision">
				<geometry>
					<mesh>
						<uri>model://human/meshes/collisions/motor10.stl</uri>
						<scale>0.001 0.001 0.001</scale>
					</mesh>
				</geometry>
			</collision>
			<visual name="motor10_visual">
				<geometry>
					<mesh>
						<uri>model://human/meshes/visuals/motor10.stl</uri>
						<scale>0.001 0.001 0.001</scale>
					</mesh>
				</geometry>
			</visual>
		</link>
		<link name="motor8">
			<self_collide>false</self_collide>
			<pose frame="">1.4838021863293247 1.2342394009707207 1.010516559218978 0.0 -0.0 0.0</pose>
			<inertial>
				<pose frame="">0.0 0.0 0.0 0 0 0</pose>
				<mass>0.5407288092534246</mass>
				<inertia>
					<ixx>1.3760537924693779</ixx>
					<ixy>-0.9902619308692957</ixy>
					<ixz>-0.8107721333955696</ixz>
					<iyy>1.7429365403144546</iyy>
					<iyz>-0.6744075434898156</iyz>
					<izz>2.014590526754685</izz>
				</inertia>
			</inertial>
			<collision name="motor8_collision">
				<geometry>
					<mesh>
						<uri>model://human/meshes/collisions/motor8.stl</uri>
						<scale>0.001 0.001 0.001</scale>
					</mesh>
				</geometry>
			</collision>
			<visual name="motor8_visual">
				<geometry>
					<mesh>
						<uri>model://human/meshes/visuals/motor8.stl</uri>
						<scale>0.001 0.001 0.001</scale>
					</mesh>
				</geometry>
			</visual>
		</link>
		<link name="motor12">
			<self_collide>false</self_collide>
			<pose frame="">-1.234239402810263 1.4838021873254785 1.010516558941175 0.0 -0.0 0.0</pose>
			<inertial>
				<pose frame="">0.0 0.0 0.0 0 0 0</pose>
				<mass>0.5407289156586891</mass>
				<inertia>
					<ixx>1.7429368845367943</ixx>
					<ixy>0.9902621278821994</ixy>
					<ixz>0.6744076770188963</ixz>
					<iyy>1.3760540653848898</iyy>
					<iyz>-0.810772293261037</iyz>
					<izz>2.0145909271886873</izz>
				</inertia>
			</inertial>
			<collision name="motor12_collision">
				<geometry>
					<mesh>
						<uri>model://human/meshes/collisions/motor12.stl</uri>
						<scale>0.001 0.001 0.001</scale>
					</mesh>
				</geometry>
			</collision>
			<visual name="motor12_visual">
				<geometry>
					<mesh>
						<uri>model://human/meshes/visuals/motor12.stl</uri>
						<scale>0.001 0.001 0.001</scale>
					</mesh>
				</geometry>
			</visual>
		</link>
		<link name="motor13">
			<self_collide>false</self_collide>
			<pose frame="">1.2342394009707198 1.4838021863293254 1.0104834407810217 0.0 -0.0 0.0</pose>
			<inertial>
				<pose frame="">0.0 0.0 0.0 0 0 0</pose>
				<mass>0.5407288092535051</mass>
				<inertia>
					<ixx>1.7429003480577074</ixx>
					<ixy>-0.9902619308694421</ixy>
					<ixz>-0.6743852245854316</ixz>
					<iyy>1.3760176002125781</iyy>
					<iyz>-0.8107460717445316</iyz>
					<izz>2.0145905267549824</izz>
				</inertia>
			</inertial>
			<collision name="motor13_collision">
				<geometry>
					<mesh>
						<uri>model://human/meshes/collisions/motor13.stl</uri>
						<scale>0.001 0.001 0.001</scale>
					</mesh>
				</geometry>
			</collision>
			<visual name="motor13_visual">
				<geometry>
					<mesh>
						<uri>model://human/meshes/visuals/motor13.stl</uri>
						<scale>0.001 0.001 0.001</scale>
					</mesh>
				</geometry>
			</visual>
		</link>
		<link name="motor14">
			<self_collide>false</self_collide>
			<pose frame="">-1.234239402810262 -1.4838021873254785 1.0104834410588253 0.0 -0.0 0.0</pose>
			<inertial>
				<pose frame="">0.0 0.0 0.0 0 0 0</pose>
				<mass>0.5407289156587678</mass>
				<inertia>
					<ixx>1.742900692880094</ixx>
					<ixy>-0.9902621278823432</ixy>
					<ixz>0.6743853584836851</ixz>
					<iyy>1.3760178737281379</iyy>
					<iyz>0.8107462320519715</iyz>
					<izz>2.0145909271889795</izz>
				</inertia>
			</inertial>
			<collision name="motor14_collision">
				<geometry>
					<mesh>
						<uri>model://human/meshes/collisions/motor14.stl</uri>
						<scale>0.001 0.001 0.001</scale>
					</mesh>
				</geometry>
			</collision>
			<visual name="motor14_visual">
				<geometry>
					<mesh>
						<uri>model://human/meshes/visuals/motor14.stl</uri>
						<scale>0.001 0.001 0.001</scale>
					</mesh>
				</geometry>
			</visual>
		</link>
		<link name="motor15">
			<self_collide>false</self_collide>
			<pose frame="">1.2342394009707207 -1.483802186329324 1.010516559218978 0.0 -0.0 0.0</pose>
			<inertial>
				<pose frame="">0.0 0.0 0.0 0 0 0</pose>
				<mass>0.5407288092534249</mass>
				<inertia>
					<ixx>1.7429365403144548</ixx>
					<ixy>0.9902619308692958</ixy>
					<ixz>-0.6744075434898158</ixz>
					<iyy>1.376053792469379</iyy>
					<iyz>0.81077213339557</iyz>
					<izz>2.0145905267546853</izz>
				</inertia>
			</inertial>
			<collision name="motor15_collision">
				<geometry>
					<mesh>
						<uri>model://human/meshes/collisions/motor15.stl</uri>
						<scale>0.001 0.001 0.001</scale>
					</mesh>
				</geometry>
			</collision>
			<visual name="motor15_visual">
				<geometry>
					<mesh>
						<uri>model://human/meshes/visuals/motor15.stl</uri>
						<scale>0.001 0.001 0.001</scale>
					</mesh>
				</geometry>
			</visual>
		</link>
		<link name="motor9">
			<self_collide>false</self_collide>
			<pose frame="">1.4853343018224885 -1.2358101829513672 1.0104858057327721 0.0 -0.0 0.0</pose>
			<inertial>
				<pose frame="">0.0 0.0 0.0 0 0 0</pose>
				<mass>0.5915182656350185</mass>
				<inertia>
					<ixx>1.5075636020635315</ixx>
					<ixy>1.085791131251597</ixy>
					<ixz>-0.8878154774061241</ixz>
					<iyy>1.909309332296448</iyy>
					<iyz>0.7386693790802477</iyz>
					<izz>2.2088182211992584</izz>
				</inertia>
			</inertial>
			<collision name="motor9_collision">
				<geometry>
					<mesh>
						<uri>model://human/meshes/collisions/motor9.stl</uri>
						<scale>0.001 0.001 0.001</scale>
					</mesh>
				</geometry>
			</collision>
			<visual name="motor9_visual">
				<geometry>
					<mesh>
						<uri>model://human/meshes/visuals/motor9.stl</uri>
						<scale>0.001 0.001 0.001</scale>
					</mesh>
				</geometry>
			</visual>
		</link>
		<link name="motor19">
			<self_collide>false</self_collide>
			<pose frame="">-1.483802187325481 -1.2342394028102615 2.010516558941175 0.0 -0.0 0.0</pose>
			<inertial>
				<pose frame="">0.0 0.0 0.0 0 0 0</pose>
				<mass>0.5407289156586891</mass>
				<inertia>
					<ixx>3.009614027386401</ixx>
					<ixy>-0.9902621278821997</ixy>
					<ixz>1.6131070410655353</ixz>
					<iyy>3.3764968465383065</iyy>
					<iyz>1.3417966109637172</iyz>
					<izz>2.0145909271886877</izz>
				</inertia>
			</inertial>
			<collision name="motor19_collision">
				<geometry>
					<mesh>
						<uri>model://human/meshes/collisions/motor19.stl</uri>
						<scale>0.001 0.001 0.001</scale>
					</mesh>
				</geometry>
			</collision>
			<visual name="motor19_visual">
				<geometry>
					<mesh>
						<uri>model://human/meshes/visuals/motor19.stl</uri>
						<scale>0.001 0.001 0.001</scale>
					</mesh>
				</geometry>
			</visual>
		</link>
		<link name="motor18">
			<self_collide>false</self_collide>
			<pose frame="">-1.483802186329323 1.2342394009707196 2.0104834407810213 0.0 -0.0 0.0</pose>
			<inertial>
				<pose frame="">0.0 0.0 0.0 0 0 0</pose>
				<mass>0.5407288092535049</mass>
				<inertia>
					<ixx>3.009541424873896</ixx>
					<ixy>0.9902619308694421</ixy>
					<ixz>1.6130806611261352</ixz>
					<iyy>3.3764241727190254</iyy>
					<iyz>-1.3417740262060884</iyz>
					<izz>2.0145905267549824</izz>
				</inertia>
			</inertial>
			<collision name="motor18_collision">
				<geometry>
					<mesh>
						<uri>model://human/meshes/collisions/motor18.stl</uri>
						<scale>0.001 0.001 0.001</scale>
					</mesh>
				</geometry>
			</collision>
			<visual name="motor18_visual">
				<geometry>
					<mesh>
						<uri>model://human/meshes/visuals/motor18.stl</uri>
						<scale>0.001 0.001 0.001</scale>
					</mesh>
				</geometry>
			</visual>
		</link>
		<link name="motor16">
			<self_collide>false</self_collide>
			<pose frame="">1.483802186329327 1.2342394009707198 2.010516559218978 0.0 -0.0 0.0</pose>
			<inertial>
				<pose frame="">0.0 0.0 0.0 0 0 0</pose>
				<mass>0.5407288092534246</mass>
				<inertia>
					<ixx>3.0096134333174938</ixx>
					<ixy>-0.9902619308692957</ixy>
					<ixz>-1.6131067227770544</ixz>
					<iyy>3.3764961811625707</iyy>
					<iyz>-1.3417963451103734</iyz>
					<izz>2.014590526754685</izz>
				</inertia>
			</inertial>
			<collision name="motor16_collision">
				<geometry>
					<mesh>
						<uri>model://human/meshes/collisions/motor16.stl</uri>
						<scale>0.001 0.001 0.001</scale>
					</mesh>
				</geometry>
			</collision>
			<visual name="motor16_visual">
				<geometry>
					<mesh>
						<uri>model://human/meshes/visuals/motor16.stl</uri>
						<scale>0.001 0.001 0.001</scale>
					</mesh>
				</geometry>
			</visual>
		</link>
		<link name="motor20">
			<self_collide>false</self_collide>
			<pose frame="">-1.2342394028102615 1.483802187325481 2.010516558941175 0.0 -0.0 0.0</pose>
			<inertial>
				<pose frame="">0.0 0.0 0.0 0 0 0</pose>
				<mass>0.540728915658689</mass>
				<inertia>
					<ixx>3.3764968465383056</ixx>
					<ixy>0.9902621278821991</ixy>
					<ixz>1.3417966109637167</ixz>
					<iyy>3.0096140273864003</iyy>
					<iyz>-1.613107041065535</iyz>
					<izz>2.0145909271886864</izz>
				</inertia>
			</inertial>
			<collision name="motor20_collision">
				<geometry>
					<mesh>
						<uri>model://human/meshes/collisions/motor20.stl</uri>
						<scale>0.001 0.001 0.001</scale>
					</mesh>
				</geometry>
			</collision>
			<visual name="motor20_visual">
				<geometry>
					<mesh>
						<uri>model://human/meshes/visuals/motor20.stl</uri>
						<scale>0.001 0.001 0.001</scale>
					</mesh>
				</geometry>
			</visual>
		</link>
		<link name="motor21">
			<self_collide>false</self_collide>
			<pose frame="">1.2342394009707203 1.483802186329324 2.0104834407810213 0.0 -0.0 0.0</pose>
			<inertial>
				<pose frame="">0.0 0.0 0.0 0 0 0</pose>
				<mass>0.540728809253504</mass>
				<inertia>
					<ixx>3.3764241727190205</ixx>
					<ixy>-0.9902619308694405</ixy>
					<ixz>-1.3417740262060864</ixz>
					<iyy>3.009541424873891</iyy>
					<iyz>-1.6130806611261326</iyz>
					<izz>2.0145905267549797</izz>
				</inertia>
			</inertial>
			<collision name="motor21_collision">
				<geometry>
					<mesh>
						<uri>model://human/meshes/collisions/motor21.stl</uri>
						<scale>0.001 0.001 0.001</scale>
					</mesh>
				</geometry>
			</collision>
			<visual name="motor21_visual">
				<geometry>
					<mesh>
						<uri>model://human/meshes/visuals/motor21.stl</uri>
						<scale>0.001 0.001 0.001</scale>
					</mesh>
				</geometry>
			</visual>
		</link>
		<link name="motor22">
			<self_collide>false</self_collide>
			<pose frame="">-1.2342394028102621 -1.4838021873254774 2.0104834410588244 0.0 -0.0 0.0</pose>
			<inertial>
				<pose frame="">0.0 0.0 0.0 0 0 0</pose>
				<mass>0.5407289156587689</mass>
				<inertia>
					<ixx>3.376424839288627</ixx>
					<ixy>-0.9902621278823452</ixy>
					<ixz>1.3417742924286062</ixz>
					<iyy>3.00954202013667</iyy>
					<iyz>1.6130809798565893</iyz>
					<izz>2.0145909271889835</izz>
				</inertia>
			</inertial>
			<collision name="motor22_collision">
				<geometry>
					<mesh>
						<uri>model://human/meshes/collisions/motor22.stl</uri>
						<scale>0.001 0.001 0.001</scale>
					</mesh>
				</geometry>
			</collision>
			<visual name="motor22_visual">
				<geometry>
					<mesh>
						<uri>model://human/meshes/visuals/motor22.stl</uri>
						<scale>0.001 0.001 0.001</scale>
					</mesh>
				</geometry>
			</visual>
		</link>
		<link name="motor23">
			<self_collide>false</self_collide>
			<pose frame="">1.2342394009707196 -1.4838021863293265 2.0105165592189773 0.0 -0.0 0.0</pose>
			<inertial>
				<pose frame="">0.0 0.0 0.0 0 0 0</pose>
				<mass>0.5407288092534249</mass>
				<inertia>
					<ixx>3.376496181162572</ixx>
					<ixy>0.9902619308692958</ixy>
					<ixz>-1.3417963451103738</ixz>
					<iyy>3.0096134333174955</iyy>
					<iyz>1.6131067227770552</iyz>
					<izz>2.0145905267546853</izz>
				</inertia>
			</inertial>
			<collision name="motor23_collision">
				<geometry>
					<mesh>
						<uri>model://human/meshes/collisions/motor23.stl</uri>
						<scale>0.001 0.001 0.001</scale>
					</mesh>
				</geometry>
			</collision>
			<visual name="motor23_visual">
				<geometry>
					<mesh>
						<uri>model://human/meshes/visuals/motor23.stl</uri>
						<scale>0.001 0.001 0.001</scale>
					</mesh>
				</geometry>
			</visual>
		</link>
		<link name="motor17">
			<self_collide>false</self_collide>
			<pose frame="">1.4838021873254774 -1.2342394028102615 2.0104834410588235 0.0 -0.0 0.0</pose>
			<inertial>
				<pose frame="">0.0 0.0 0.0 0 0 0</pose>
				<mass>0.5407289156587689</mass>
				<inertia>
					<ixx>3.0095420201366694</ixx>
					<ixy>0.9902621278823456</ixy>
					<ixz>-1.6130809798565902</ixz>
					<iyy>3.376424839288629</iyy>
					<iyz>1.341774292428606</iyz>
					<izz>2.014590927188985</izz>
				</inertia>
			</inertial>
			<collision name="motor17_collision">
				<geometry>
					<mesh>
						<uri>model://human/meshes/collisions/motor17.stl</uri>
						<scale>0.001 0.001 0.001</scale>
					</mesh>
				</geometry>
			</collision>
			<visual name="motor17_visual">
				<geometry>
					<mesh>
						<uri>model://human/meshes/visuals/motor17.stl</uri>
						<scale>0.001 0.001 0.001</scale>
					</mesh>
				</geometry>
			</visual>
		</link>
		<link name="6dof_link4">
			<self_collide>false</self_collide>
			<pose frame="">0.042639659949809026 -7.101249734164418e-05 0.9999999999999923 0.0 -0.0 0.0</pose>
			<inertial>
				<pose frame="">0.0 0.0 0.0 0 0 0</pose>
				<mass>0.029253556048299417</mass>
				<inertia>
					<ixx>0.029253976989686226</ixx>
					<ixy>1.1626215438336713e-07</ixy>
					<ixz>-0.0012473616822221846</ixz>
					<iyy>0.0293174136030794</iyy>
					<iyz>2.077379146644587e-06</iyz>
					<izz>6.385696503560865e-05</izz>
				</inertia>
			</inertial>
			<collision name="6dof_link4_collision">
				<geometry>
					<mesh>
						<uri>model://human/meshes/collisions/6dof_link4.stl</uri>
						<scale>0.001 0.001 0.001</scale>
					</mesh>
				</geometry>
			</collision>
			<visual name="6dof_link4_visual">
				<geometry>
					<mesh>
						<uri>model://human/meshes/visuals/6dof_link4.stl</uri>
						<scale>0.001 0.001 0.001</scale>
					</mesh>
				</geometry>
			</visual>
		</link>
		<link name="6dof_link5">
			<self_collide>false</self_collide>
			<pose frame="">6.1008287956425485e-05 0.04260984108746041 0.9999999812294209 0.0 -0.0 0.0</pose>
			<inertial>
				<pose frame="">0.0 0.0 0.0 0 0 0</pose>
				<mass>0.029267161202751052</mass>
				<inertia>
					<ixx>0.029330975552184543</ixx>
					<ixy>-1.0360731338597083e-07</ixy>
					<ixz>-1.7800545179101354e-06</ixz>
					<iyy>0.029267568334721984</iyy>
					<iyz>-0.001247068788576186</iyz>
					<izz>6.382844100897486e-05</izz>
				</inertia>
			</inertial>
			<collision name="6dof_link5_collision">
				<geometry>
					<mesh>
						<uri>model://human/meshes/collisions/6dof_link5.stl</uri>
						<scale>0.001 0.001 0.001</scale>
					</mesh>
				</geometry>
			</collision>
			<visual name="6dof_link5_visual">
				<geometry>
					<mesh>
						<uri>model://human/meshes/visuals/6dof_link5.stl</uri>
						<scale>0.001 0.001 0.001</scale>
					</mesh>
				</geometry>
			</visual>
		</link>
		<link name="6dof_link1">
			<self_collide>false</self_collide>
			<pose frame="">-3.5510243406436533e-06 -1.0069391479243579e-05 0.9999999999999999 0.0 -0.0 0.0</pose>
			<inertial>
				<pose frame="">0.0 0.0 0.0 0 0 0</pose>
				<mass>0.03806502884740436</mass>
				<inertia>
					<ixx>0.03806670751903605</ixx>
					<ixy>-1.361078074833995e-12</ixy>
					<ixz>1.3516984396440834e-07</ixz>
					<iyy>0.038066707515656516</iyy>
					<iyz>3.8329167713316574e-07</iyz>
					<izz>1.6786721116758843e-06</izz>
				</inertia>
			</inertial>
			<collision name="6dof_link1_collision">
				<geometry>
					<mesh>
						<uri>model://human/meshes/collisions/6dof_link1.stl</uri>
						<scale>0.001 0.001 0.001</scale>
					</mesh>
				</geometry>
			</collision>
			<visual name="6dof_link1_visual">
				<geometry>
					<mesh>
						<uri>model://human/meshes/visuals/6dof_link1.stl</uri>
						<scale>0.001 0.001 0.001</scale>
					</mesh>
				</geometry>
			</visual>
		</link>
		<link name="6dof_link2">
			<self_collide>false</self_collide>
			<pose frame="">-3.551024340641647e-06 -1.0069391479245249e-05 0.9999999999999998 0.0 -0.0 0.0</pose>
			<inertial>
				<pose frame="">0.0 0.0 0.0 0 0 0</pose>
				<mass>0.0029963725331776064</mass>
				<inertia>
					<ixx>0.002996396804098933</ixx>
					<ixy>-1.0714025662895805e-13</ixy>
					<ixz>1.064019179894265e-08</ixz>
					<iyy>0.0029963968038329066</iyy>
					<iyz>3.017164805422385e-08</iyz>
					<izz>2.4270959112454043e-08</izz>
				</inertia>
			</inertial>
			<collision name="6dof_link2_collision">
				<geometry>
					<mesh>
						<uri>model://human/meshes/collisions/6dof_link2.stl</uri>
						<scale>0.001 0.001 0.001</scale>
					</mesh>
				</geometry>
			</collision>
			<visual name="6dof_link2_visual">
				<geometry>
					<mesh>
						<uri>model://human/meshes/visuals/6dof_link2.stl</uri>
						<scale>0.001 0.001 0.001</scale>
					</mesh>
				</geometry>
			</visual>
		</link>
		<link name="6dof_link3">
			<self_collide>false</self_collide>
			<pose frame="">-3.3130953811449347e-06 -1.0358420894244247e-05 1.010729363507488 0.0 -0.0 0.0</pose>
			<inertial>
				<pose frame="">0.0 0.0 0.0 0 0 0</pose>
				<mass>0.015709236754408065</mass>
				<inertia>
					<ixx>0.016048786465636584</ixx>
					<ixy>3.398942377017531e-12</ixy>
					<ixz>5.256991621185631e-08</ixz>
					<iyy>0.016048779040639085</iyy>
					<iyz>1.6451093000258178e-07</iyz>
					<izz>2.606891529664852e-07</izz>
				</inertia>
			</inertial>
			<collision name="6dof_link3_collision">
				<geometry>
					<mesh>
						<uri>model://human/meshes/collisions/6dof_link3.stl</uri>
						<scale>0.001 0.001 0.001</scale>
					</mesh>
				</geometry>
			</collision>
			<visual name="6dof_link3_visual">
				<geometry>
					<mesh>
						<uri>model://human/meshes/visuals/6dof_link3.stl</uri>
						<scale>0.001 0.001 0.001</scale>
					</mesh>
				</geometry>
			</visual>
		</link>
		<link name="ankle_left_link1">
			<self_collide>false</self_collide>
			<pose frame="">-0.020000000000005343 0.11641651136884303 0.10919445283931403 0.0 -0.0 0.0</pose>
			<inertial>
				<pose frame="">0.0 0.0 0.0 0 0 0</pose>
				<mass>0.03806502884740436</mass>
				<inertia>
					<ixx>0.0009714321985240435</ixx>
					<ixy>8.862795727140744e-05</ixy>
					<ixz>8.312979994612267e-05</ixz>
					<iyy>0.0004707703302989443</iyy>
					<iyz>-0.0004838840650257426</iyz>
					<izz>0.0005327925590752096</izz>
				</inertia>
			</inertial>
			<collision name="ankle_left_link1_collision">
				<geometry>
					<mesh>
						<uri>model://human/meshes/collisions/ankle_left_link1.stl</uri>
						<scale>0.001 0.001 0.001</scale>
					</mesh>
				</geometry>
			</collision>
			<visual name="ankle_left_link1_visual">
				<geometry>
					<mesh>
						<uri>model://human/meshes/visuals/ankle_left_link1.stl</uri>
						<scale>0.001 0.001 0.001</scale>
					</mesh>
				</geometry>
			</visual>
		</link>
		<link name="ankle_left_link2">
			<self_collide>false</self_collide>
			<pose frame="">-0.020000000000005343 0.11641651136884307 0.10919445283931405 0.0 -0.0 0.0</pose>
			<inertial>
				<pose frame="">0.0 0.0 0.0 0 0 0</pose>
				<mass>0.0029963725331776064</mass>
				<inertia>
					<ixx>7.636055437932811e-05</ixx>
					<ixy>6.976544741481062e-06</ixy>
					<ixz>6.543745185263308e-06</ixz>
					<iyy>3.694985338201701e-05</iyy>
					<iyz>-3.808999928774074e-05</iyz>
					<izz>4.183206964137318e-05</izz>
				</inertia>
			</inertial>
			<collision name="ankle_left_link2_collision">
				<geometry>
					<mesh>
						<uri>model://human/meshes/collisions/ankle_left_link2.stl</uri>
						<scale>0.001 0.001 0.001</scale>
					</mesh>
				</geometry>
			</collision>
			<visual name="ankle_left_link2_visual">
				<geometry>
					<mesh>
						<uri>model://human/meshes/visuals/ankle_left_link2.stl</uri>
						<scale>0.001 0.001 0.001</scale>
					</mesh>
				</geometry>
			</visual>
		</link>
		<link name="ankle_right_link1">
			<self_collide>false</self_collide>
			<pose frame="">-0.020000000000004712 -0.12262700433836411 0.11146497559651965 0.0 -0.0 0.0</pose>
			<inertial>
				<pose frame="">0.0 0.0 0.0 0 0 0</pose>
				<mass>0.03806502884740436</mass>
				<inertia>
					<ixx>0.001047013751621923</ixx>
					<ixy>-9.335600915223419e-05</ixy>
					<ixz>8.485835023115486e-05</ixz>
					<iyy>0.0004898413761948577</iyy>
					<iyz>0.0005202962640969899</iyz>
					<izz>0.0005893030662771736</izz>
				</inertia>
			</inertial>
			<collision name="ankle_right_link1_collision">
				<geometry>
					<mesh>
						<uri>model://human/meshes/collisions/ankle_right_link1.stl</uri>
						<scale>0.001 0.001 0.001</scale>
					</mesh>
				</geometry>
			</collision>
			<visual name="ankle_right_link1_visual">
				<geometry>
					<mesh>
						<uri>model://human/meshes/visuals/ankle_right_link1.stl</uri>
						<scale>0.001 0.001 0.001</scale>
					</mesh>
				</geometry>
			</visual>
		</link>
		<link name="ankle_right_link2">
			<self_collide>false</self_collide>
			<pose frame="">-0.02000000000000471 -0.12262700433836411 0.11146497559651965 0.0 -0.0 0.0</pose>
			<inertial>
				<pose frame="">0.0 0.0 0.0 0 0 0</pose>
				<mass>0.0029963725331776064</mass>
				<inertia>
					<ixx>8.231012269898624e-05</ixx>
					<ixy>-7.348723752508237e-06</ixy>
					<ixz>6.679811825776045e-06</ixz>
					<iyy>3.845107273825509e-05</iyy>
					<iyz>4.0956265686935105e-05</iyz>
					<izz>4.628041860479309e-05</izz>
				</inertia>
			</inertial>
			<collision name="ankle_right_link2_collision">
				<geometry>
					<mesh>
						<uri>model://human/meshes/collisions/ankle_right_link2.stl</uri>
						<scale>0.001 0.001 0.001</scale>
					</mesh>
				</geometry>
			</collision>
			<visual name="ankle_right_link2_visual">
				<geometry>
					<mesh>
						<uri>model://human/meshes/visuals/ankle_right_link2.stl</uri>
						<scale>0.001 0.001 0.001</scale>
					</mesh>
				</geometry>
			</visual>
		</link>
		<link name="knee_left_link1">
			<self_collide>false</self_collide>
			<pose frame="">-0.020000000000000066 0.10199656595253302 0.46553083442094073 0.0 -0.0 0.0</pose>
			<inertial>
				<pose frame="">0.0 0.0 0.0 0 0 0</pose>
				<mass>0.03806502884740436</mass>
				<inertia>
					<ixx>0.008647093942366983</ixx>
					<ixy>7.765004450638728e-05</ixy>
					<ixz>0.00035440889283178784</ixz>
					<iyy>0.008266318059620302</iyy>
					<iyz>-0.0018074245005940768</iyz>
					<izz>0.00041290657359677375</izz>
				</inertia>
			</inertial>
			<collision name="knee_left_link1_collision">
				<geometry>
					<mesh>
						<uri>model://human/meshes/collisions/knee_left_link1.stl</uri>
						<scale>0.001 0.001 0.001</scale>
					</mesh>
				</geometry>
			</collision>
			<visual name="knee_left_link1_visual">
				<geometry>
					<mesh>
						<uri>model://human/meshes/visuals/knee_left_link1.stl</uri>
						<scale>0.001 0.001 0.001</scale>
					</mesh>
				</geometry>
			</visual>
		</link>
		<link name="knee_left_link2">
			<self_collide>false</self_collide>
			<pose frame="">-0.020000000000000063 0.10199656595253302 0.4655308344209406 0.0 -0.0 0.0</pose>
			<inertial>
				<pose frame="">0.0 0.0 0.0 0 0 0</pose>
				<mass>0.0029963725331776064</mass>
				<inertia>
					<ixx>0.0006805671639529709</ixx>
					<ixy>6.112394173972182e-06</ixy>
					<ixz>2.7898076112123256e-05</ixz>
					<iyy>0.0006505935521915703</iyy>
					<iyz>-0.00014227539800594784</iyz>
					<izz>3.2394980405461305e-05</izz>
				</inertia>
			</inertial>
			<collision name="knee_left_link2_collision">
				<geometry>
					<mesh>
						<uri>model://human/meshes/collisions/knee_left_link2.stl</uri>
						<scale>0.001 0.001 0.001</scale>
					</mesh>
				</geometry>
			</collision>
			<visual name="knee_left_link2_visual">
				<geometry>
					<mesh>
						<uri>model://human/meshes/visuals/knee_left_link2.stl</uri>
						<scale>0.001 0.001 0.001</scale>
					</mesh>
				</geometry>
			</visual>
		</link>
		<link name="knee_right_link1">
			<self_collide>false</self_collide>
			<pose frame="">-0.01999999999999949 -0.10928093635493345 0.4655419701254479 0.0 -0.0 0.0</pose>
			<inertial>
				<pose frame="">0.0 0.0 0.0 0 0 0</pose>
				<mass>0.03806502884740436</mass>
				<inertia>
					<ixx>0.008706071583498612</ixx>
					<ixy>-8.319563989643591e-05</ixy>
					<ixz>0.0003544173704500436</ixz>
					<iyy>0.008266712723611043</iyy>
					<iyz>0.0019365531051617538</iyz>
					<izz>0.0004714895507376619</izz>
				</inertia>
			</inertial>
			<collision name="knee_right_link1_collision">
				<geometry>
					<mesh>
						<uri>model://human/meshes/collisions/knee_right_link1.stl</uri>
						<scale>0.001 0.001 0.001</scale>
					</mesh>
				</geometry>
			</collision>
			<visual name="knee_right_link1_visual">
				<geometry>
					<mesh>
						<uri>model://human/meshes/visuals/knee_right_link1.stl</uri>
						<scale>0.001 0.001 0.001</scale>
					</mesh>
				</geometry>
			</visual>
		</link>
		<link name="knee_right_link2">
			<self_collide>false</self_collide>
			<pose frame="">-0.019999999999999494 -0.1092809363549335 0.4655419701254479 0.0 -0.0 0.0</pose>
			<inertial>
				<pose frame="">0.0 0.0 0.0 0 0 0</pose>
				<mass>0.0029963725331776064</mass>
				<inertia>
					<ixx>0.0006852097187942368</ixx>
					<ixy>-6.548927921876891e-06</ixy>
					<ixz>2.7898743446504933e-05</ixz>
					<iyy>0.000650624619036323</iyy>
					<iyz>0.00015244004034801</iyz>
					<izz>3.700646840197439e-05</izz>
				</inertia>
			</inertial>
			<collision name="knee_right_link2_collision">
				<geometry>
					<mesh>
						<uri>model://human/meshes/collisions/knee_right_link2.stl</uri>
						<scale>0.001 0.001 0.001</scale>
					</mesh>
				</geometry>
			</collision>
			<visual name="knee_right_link2_visual">
				<geometry>
					<mesh>
						<uri>model://human/meshes/visuals/knee_right_link2.stl</uri>
						<scale>0.001 0.001 0.001</scale>
					</mesh>
				</geometry>
			</visual>
		</link>
		<link name="hip_left_link1">
			<self_collide>false</self_collide>
			<pose frame="">-0.020852140403154657 0.0966300747580408 0.8970954229409359 0.0 -0.0 0.0</pose>
			<inertial>
				<pose frame="">0.0 0.0 0.0 0 0 0</pose>
				<mass>0.03806502884740436</mass>
				<inertia>
					<ixx>0.03099108742490371</ixx>
					<ixy>7.66988971473284e-05</ixy>
					<ixz>0.000712058122150634</ixz>
					<iyy>0.030652211237357358</iyy>
					<iyz>-0.003299720232320919</iyz>
					<izz>0.0003736570996474743</izz>
				</inertia>
			</inertial>
			<collision name="hip_left_link1_collision">
				<geometry>
					<mesh>
						<uri>model://human/meshes/collisions/hip_left_link1.stl</uri>
						<scale>0.001 0.001 0.001</scale>
					</mesh>
				</geometry>
			</collision>
			<visual name="hip_left_link1_visual">
				<geometry>
					<mesh>
						<uri>model://human/meshes/visuals/hip_left_link1.stl</uri>
						<scale>0.001 0.001 0.001</scale>
					</mesh>
				</geometry>
			</visual>
		</link>
		<link name="hip_left_link2">
			<self_collide>false</self_collide>
			<pose frame="">-0.020852140403154657 0.09663007475804078 0.8970954229409357 0.0 -0.0 0.0</pose>
			<inertial>
				<pose frame="">0.0 0.0 0.0 0 0 0</pose>
				<mass>0.0029963725331776064</mass>
				<inertia>
					<ixx>0.0024394237937736462</ixx>
					<ixy>6.0375225159704616e-06</ixy>
					<ixz>5.605122244334441e-05</ixz>
					<iyy>0.0024127484087481323</iyy>
					<iyz>-0.0002597447413197226</iyz>
					<izz>2.9305371668927512e-05</izz>
				</inertia>
			</inertial>
			<collision name="hip_left_link2_collision">
				<geometry>
					<mesh>
						<uri>model://human/meshes/collisions/hip_left_link2.stl</uri>
						<scale>0.001 0.001 0.001</scale>
					</mesh>
				</geometry>
			</collision>
			<visual name="hip_left_link2_visual">
				<geometry>
					<mesh>
						<uri>model://human/meshes/visuals/hip_left_link2.stl</uri>
						<scale>0.001 0.001 0.001</scale>
					</mesh>
				</geometry>
			</visual>
		</link>
		<link name="hip_right_link1">
			<self_collide>false</self_collide>
			<pose frame="">-0.020852140403110404 -0.10284056772770629 0.8970954229406419 0.0 -0.0 0.0</pose>
			<inertial>
				<pose frame="">0.0 0.0 0.0 0 0 0</pose>
				<mass>0.03806502884740436</mass>
				<inertia>
					<ixx>0.031038242802203464</ixx>
					<ixy>-8.162839722989146e-05</ixy>
					<ixz>0.0007120581221488894</ixz>
					<iyy>0.030652211237337215</iyy>
					<iyz>0.0035117959174106234</iyz>
					<izz>0.00042081247696724024</izz>
				</inertia>
			</inertial>
			<collision name="hip_right_link1_collision">
				<geometry>
					<mesh>
						<uri>model://human/meshes/collisions/hip_right_link1.stl</uri>
						<scale>0.001 0.001 0.001</scale>
					</mesh>
				</geometry>
			</collision>
			<visual name="hip_right_link1_visual">
				<geometry>
					<mesh>
						<uri>model://human/meshes/visuals/hip_right_link1.stl</uri>
						<scale>0.001 0.001 0.001</scale>
					</mesh>
				</geometry>
			</visual>
		</link>
		<link name="hip_right_link2">
			<self_collide>false</self_collide>
			<pose frame="">-0.020852140403110408 -0.10284056772770629 0.8970954229406418 0.0 -0.0 0.0</pose>
			<inertial>
				<pose frame="">0.0 0.0 0.0 0 0 0</pose>
				<mass>0.0029963725331776064</mass>
				<inertia>
					<ixx>0.002443135733094619</ixx>
					<ixy>-6.4255589656182875e-06</ixy>
					<ixz>5.6051222443207106e-05</ixz>
					<iyy>0.002412748408746547</iyy>
					<iyz>0.0002764387456853846</iyz>
					<izz>3.3017310991474705e-05</izz>
				</inertia>
			</inertial>
			<collision name="hip_right_link2_collision">
				<geometry>
					<mesh>
						<uri>model://human/meshes/collisions/hip_right_link2.stl</uri>
						<scale>0.001 0.001 0.001</scale>
					</mesh>
				</geometry>
			</collision>
			<visual name="hip_right_link2_visual">
				<geometry>
					<mesh>
						<uri>model://human/meshes/visuals/hip_right_link2.stl</uri>
						<scale>0.001 0.001 0.001</scale>
					</mesh>
				</geometry>
			</visual>
		</link>
		<link name="spine_link1">
			<self_collide>false</self_collide>
			<pose frame="">-0.019999999999991646 -0.0030967934839573573 1.0302379930054062 0.0 -0.0 0.0</pose>
			<inertial>
				<pose frame="">0.0 0.0 0.0 0 0 0</pose>
				<mass>0.03806502884740436</mass>
				<inertia>
					<ixx>0.04040389695045235</ixx>
					<ixy>-2.3575906660248277e-06</ixy>
					<ixz>0.0007843207784685275</ixz>
					<iyy>0.04041875791342068</iyy>
					<iyz>0.00012144397380473562</iyz>
					<izz>1.7269727881738925e-05</izz>
				</inertia>
			</inertial>
			<collision name="spine_link1_collision">
				<geometry>
					<mesh>
						<uri>model://human/meshes/collisions/spine_link1.stl</uri>
						<scale>0.001 0.001 0.001</scale>
					</mesh>
				</geometry>
			</collision>
			<visual name="spine_link1_visual">
				<geometry>
					<mesh>
						<uri>model://human/meshes/visuals/spine_link1.stl</uri>
						<scale>0.001 0.001 0.001</scale>
					</mesh>
				</geometry>
			</visual>
		</link>
		<link name="spine_link2">
			<self_collide>false</self_collide>
			<pose frame="">-0.01999999999999165 -0.003096793483957363 1.0302379930054064 0.0 -0.0 0.0</pose>
			<inertial>
				<pose frame="">0.0 0.0 0.0 0 0 0</pose>
				<mass>0.0029963725331776064</mass>
				<inertia>
					<ixx>0.0031803738147352044</ixx>
					<ixy>-1.855829387249871e-07</ixy>
					<ixz>6.173953649752266e-05</ixz>
					<iyy>0.0031815436281467054</iyy>
					<iyz>9.55972971640779e-06</iyz>
					<izz>1.2515552325576518e-06</izz>
				</inertia>
			</inertial>
			<collision name="spine_link2_collision">
				<geometry>
					<mesh>
						<uri>model://human/meshes/collisions/spine_link2.stl</uri>
						<scale>0.001 0.001 0.001</scale>
					</mesh>
				</geometry>
			</collision>
			<visual name="spine_link2_visual">
				<geometry>
					<mesh>
						<uri>model://human/meshes/visuals/spine_link2.stl</uri>
						<scale>0.001 0.001 0.001</scale>
					</mesh>
				</geometry>
			</visual>
		</link>
		<link name="shoulder_left_link1">
			<self_collide>false</self_collide>
			<pose frame="">-0.06588496747592551 0.18125378880767987 1.397313892508675 0.0 -0.0 0.0</pose>
			<inertial>
				<pose frame="">0.0 0.0 0.0 0 0 0</pose>
				<mass>0.03806502884740436</mass>
				<inertia>
					<ixx>0.07557366688379621</ixx>
					<ixy>0.00045456876724987483</ixy>
					<ixz>0.0035043419382132087</ixz>
					<iyy>0.07448835270766202</iyy>
					<iyz>-0.009640670367043691</iyz>
					<izz>0.0014174604014988406</izz>
				</inertia>
			</inertial>
			<collision name="shoulder_left_link1_collision">
				<geometry>
					<mesh>
						<uri>model://human/meshes/collisions/shoulder_left_link1.stl</uri>
						<scale>0.001 0.001 0.001</scale>
					</mesh>
				</geometry>
			</collision>
			<visual name="shoulder_left_link1_visual">
				<geometry>
					<mesh>
						<uri>model://human/meshes/visuals/shoulder_left_link1.stl</uri>
						<scale>0.001 0.001 0.001</scale>
					</mesh>
				</geometry>
			</visual>
		</link>
		<link name="shoulder_left_link2">
			<self_collide>false</self_collide>
			<pose frame="">-0.06588496747592551 0.18125378880767987 1.3973138925086748 0.0 -0.0 0.0</pose>
			<inertial>
				<pose frame="">0.0 0.0 0.0 0 0 0</pose>
				<mass>0.0029963725331776064</mass>
				<inertia>
					<ixx>0.005948839669546528</ixx>
					<ixy>3.578238109547124e-05</ixy>
					<ixz>0.0002758519893054131</ixz>
					<iyy>0.005863406775215266</iyy>
					<iyz>-0.0007588865886594165</iyz>
					<izz>0.00011147064615868532</izz>
				</inertia>
			</inertial>
			<collision name="shoulder_left_link2_collision">
				<geometry>
					<mesh>
						<uri>model://human/meshes/collisions/shoulder_left_link2.stl</uri>
						<scale>0.001 0.001 0.001</scale>
					</mesh>
				</geometry>
			</collision>
			<visual name="shoulder_left_link2_visual">
				<geometry>
					<mesh>
						<uri>model://human/meshes/visuals/shoulder_left_link2.stl</uri>
						<scale>0.001 0.001 0.001</scale>
					</mesh>
				</geometry>
			</visual>
		</link>
		<link name="shoulder_right_link1">
			<self_collide>false</self_collide>
			<pose frame="">-0.06588496747581415 -0.18746428177704233 1.3973138925086874 0.0 -0.0 0.0</pose>
			<inertial>
				<pose frame="">0.0 0.0 0.0 0 0 0</pose>
				<mass>0.03806502884740436</mass>
				<inertia>
					<ixx>0.07566083279215148</ixx>
					<ixy>-0.00047014414446832595</ixy>
					<ixz>0.0035043419382073168</ixz>
					<iyy>0.07448835270766278</iyy>
					<iyz>0.00997099899591451</iyz>
					<izz>0.001504626309852232</izz>
				</inertia>
			</inertial>
			<collision name="shoulder_right_link1_collision">
				<geometry>
					<mesh>
						<uri>model://human/meshes/collisions/shoulder_right_link1.stl</uri>
						<scale>0.001 0.001 0.001</scale>
					</mesh>
				</geometry>
			</collision>
			<visual name="shoulder_right_link1_visual">
				<geometry>
					<mesh>
						<uri>model://human/meshes/visuals/shoulder_right_link1.stl</uri>
						<scale>0.001 0.001 0.001</scale>
					</mesh>
				</geometry>
			</visual>
		</link>
		<link name="shoulder_right_link2">
			<self_collide>false</self_collide>
			<pose frame="">-0.06588496747581417 -0.18746428177704225 1.3973138925086874 0.0 -0.0 0.0</pose>
			<inertial>
				<pose frame="">0.0 0.0 0.0 0 0 0</pose>
				<mass>0.0029963725331776064</mass>
				<inertia>
					<ixx>0.0059557011258893665</ixx>
					<ixy>-3.700843119721519e-05</ixy>
					<ixz>0.0002758519893049495</ixz>
					<iyy>0.005863406775215328</iyy>
					<iyz>0.0007848891337891895</iyz>
					<izz>0.000118332102501372</izz>
				</inertia>
			</inertial>
			<collision name="shoulder_right_link2_collision">
				<geometry>
					<mesh>
						<uri>model://human/meshes/collisions/shoulder_right_link2.stl</uri>
						<scale>0.001 0.001 0.001</scale>
					</mesh>
				</geometry>
			</collision>
			<visual name="shoulder_right_link2_visual">
				<geometry>
					<mesh>
						<uri>model://human/meshes/visuals/shoulder_right_link2.stl</uri>
						<scale>0.001 0.001 0.001</scale>
					</mesh>
				</geometry>
			</visual>
		</link>
		<link name="elbow_left_link1">
			<self_collide>false</self_collide>
			<pose frame="">-0.08936282051926747 0.2168536361736183 1.1372940556915747 0.0 -0.0 0.0</pose>
			<inertial>
				<pose frame="">0.0 0.0 0.0 0 0 0</pose>
				<mass>0.03806502884740436</mass>
				<inertia>
					<ixx>0.05102645165717749</ixx>
					<ixy>0.0007376489690374443</ixy>
					<ixz>0.0038686175730142758</ixz>
					<iyy>0.04954040108334068</iyy>
					<iyz>-0.009387839179633145</iyz>
					<izz>0.002095682085651115</izz>
				</inertia>
			</inertial>
			<collision name="elbow_left_link1_collision">
				<geometry>
					<mesh>
						<uri>model://human/meshes/collisions/elbow_left_link1.stl</uri>
						<scale>0.001 0.001 0.001</scale>
					</mesh>
				</geometry>
			</collision>
			<visual name="elbow_left_link1_visual">
				<geometry>
					<mesh>
						<uri>model://human/meshes/visuals/elbow_left_link1.stl</uri>
						<scale>0.001 0.001 0.001</scale>
					</mesh>
				</geometry>
			</visual>
		</link>
		<link name="elbow_left_link2">
			<self_collide>false</self_collide>
			<pose frame="">-0.08936282051926751 0.2168536361736183 1.137294055691575 0.0 -0.0 0.0</pose>
			<inertial>
				<pose frame="">0.0 0.0 0.0 0 0 0</pose>
				<mass>0.0029963725331776064</mass>
				<inertia>
					<ixx>0.0040165515904832475</ixx>
					<ixy>5.806566228574645e-05</ixy>
					<ixz>0.00030452674772998725</ixz>
					<iyy>0.0038995738485194183</iyy>
					<iyz>-0.0007389844252189366</iyz>
					<izz>0.00016485835890536586</izz>
				</inertia>
			</inertial>
			<collision name="elbow_left_link2_collision">
				<geometry>
					<mesh>
						<uri>model://human/meshes/collisions/elbow_left_link2.stl</uri>
						<scale>0.001 0.001 0.001</scale>
					</mesh>
				</geometry>
			</collision>
			<visual name="elbow_left_link2_visual">
				<geometry>
					<mesh>
						<uri>model://human/meshes/visuals/elbow_left_link2.stl</uri>
						<scale>0.001 0.001 0.001</scale>
					</mesh>
				</geometry>
			</visual>
		</link>
		<link name="elbow_right_link1">
			<self_collide>false</self_collide>
			<pose frame="">-0.08936282051932876 -0.22306412914317073 1.137294055691462 0.0 -0.0 0.0</pose>
			<inertial>
				<pose frame="">0.0 0.0 0.0 0 0 0</pose>
				<mass>0.03806502884740436</mass>
				<inertia>
					<ixx>0.05113044935805403</ixx>
					<ixy>-0.0007587745716196841</ixy>
					<ixz>0.0038686175730165448</ixz>
					<iyy>0.04954040108333132</iyy>
					<iyz>0.009656698444586921</iyz>
					<izz>0.0021996797865378513</izz>
				</inertia>
			</inertial>
			<collision name="elbow_right_link1_collision">
				<geometry>
					<mesh>
						<uri>model://human/meshes/collisions/elbow_right_link1.stl</uri>
						<scale>0.001 0.001 0.001</scale>
					</mesh>
				</geometry>
			</collision>
			<visual name="elbow_right_link1_visual">
				<geometry>
					<mesh>
						<uri>model://human/meshes/visuals/elbow_right_link1.stl</uri>
						<scale>0.001 0.001 0.001</scale>
					</mesh>
				</geometry>
			</visual>
		</link>
		<link name="elbow_right_link2">
			<self_collide>false</self_collide>
			<pose frame="">-0.08936282051932876 -0.22306412914317078 1.137294055691462 0.0 -0.0 0.0</pose>
			<inertial>
				<pose frame="">0.0 0.0 0.0 0 0 0</pose>
				<mass>0.0029963725331776064</mass>
				<inertia>
					<ixx>0.004024737998423967</ixx>
					<ixy>-5.972861059396939e-05</ixy>
					<ixz>0.0003045267477301657</ixz>
					<iyy>0.0038995738485186823</iyy>
					<iyz>0.0007601482740636947</iyz>
					<izz>0.00017304476684688747</izz>
				</inertia>
			</inertial>
			<collision name="elbow_right_link2_collision">
				<geometry>
					<mesh>
						<uri>model://human/meshes/collisions/elbow_right_link2.stl</uri>
						<scale>0.001 0.001 0.001</scale>
					</mesh>
				</geometry>
			</collision>
			<visual name="elbow_right_link2_visual">
				<geometry>
					<mesh>
						<uri>model://human/meshes/visuals/elbow_right_link2.stl</uri>
						<scale>0.001 0.001 0.001</scale>
					</mesh>
				</geometry>
			</visual>
		</link>
		<joint name="knee_right_axis0" type="revolute">
			<parent>upper_leg_right</parent>
			<child>knee_right_link1</child>
			<pose frame="">4.662936703425657e-17 -1.7763568394002505e-17 0.0 0 0 0</pose>
			<axis>
				<xyz>1.0 3.2639119953519554e-29 -1.4747584956158427e-14</xyz>
				<limit>
					<lower>-3.141592653589793</lower>
					<upper>3.141592653589793</upper>
				</limit>
				<use_parent_model_frame>0</use_parent_model_frame>
			</axis>
		</joint>
		<joint name="knee_right_axis1" type="revolute">
			<parent>knee_right_link1</parent>
			<child>knee_right_link2</child>
			<pose frame="">2.220446049250313e-18 1.7763568394002505e-17 0.0 0 0 0</pose>
			<axis>
				<xyz>-1.240147949605937e-31 1.0 2.2204460492503186e-15</xyz>
				<limit>
					<lower>-3.141592653589793</lower>
					<upper>3.141592653589793</upper>
				</limit>
				<use_parent_model_frame>0</use_parent_model_frame>
			</axis>
		</joint>
		<joint name="knee_right_axis2" type="revolute">
			<parent>knee_right_link2</parent>
			<child>lower_leg_right</child>
			<pose frame="">0.017655113843931217 0.00493905347707857 0.13744843174774787 0 0 0</pose>
			<axis>
				<xyz>4.379057701014964e-46 -2.2204460492503186e-15 1.0</xyz>
				<limit>
					<lower>-3.141592653589793</lower>
					<upper>3.141592653589793</upper>
				</limit>
				<use_parent_model_frame>0</use_parent_model_frame>
			</axis>
		</joint>
		<joint name="elbow_right_axis0" type="revolute">
			<parent>upper_arm_right</parent>
			<child>elbow_right_link1</child>
			<pose frame="">1.7763568394002505e-17 -7.105427357601002e-17 1.4210854715202004e-16 0 0 0</pose>
			<axis>
				<xyz>1.0 3.24419047272142e-29 -1.4643501547599825e-14</xyz>
				<limit>
					<lower>-3.141592653589793</lower>
					<upper>3.141592653589793</upper>
				</limit>
				<use_parent_model_frame>0</use_parent_model_frame>
			</axis>
		</joint>
		<joint name="elbow_right_axis1" type="revolute">
			<parent>elbow_right_link1</parent>
			<child>elbow_right_link2</child>
			<pose frame="">0.0 0.0 0.0 0 0 0</pose>
			<axis>
				<xyz>5.779299178957124e-32 1.0 2.220446049250313e-15</xyz>
				<limit>
					<lower>-3.141592653589793</lower>
					<upper>3.141592653589793</upper>
				</limit>
				<use_parent_model_frame>0</use_parent_model_frame>
			</axis>
		</joint>
		<joint name="elbow_right_axis2" type="revolute">
			<parent>elbow_right_link2</parent>
			<child>lower_arm_right</child>
			<pose frame="">-2.2631665366645848e-07 2.749231121867979e-07 -0.010256097183257965 0 0 0</pose>
			<axis>
				<xyz>3.2087422526471726e-61 -2.220446049250313e-15 1.0</xyz>
				<limit>
					<lower>-3.141592653589793</lower>
					<upper>3.141592653589793</upper>
				</limit>
				<use_parent_model_frame>0</use_parent_model_frame>
			</axis>
		</joint>
		<joint name="hip_right_axis0" type="revolute">
			<parent>hip</parent>
			<child>hip_right_link1</child>
			<pose frame="">1.021405182655144e-16 0.0 0.0 0 0 0</pose>
			<axis>
				<xyz>1.0 3.2737727566672113e-29 -1.4747584956158436e-14</xyz>
				<limit>
					<lower>-3.141592653589793</lower>
					<upper>3.141592653589793</upper>
				</limit>
				<use_parent_model_frame>0</use_parent_model_frame>
			</axis>
		</joint>
		<joint name="hip_right_axis1" type="revolute">
			<parent>hip_right_link1</parent>
			<child>hip_right_link2</child>
			<pose frame="">0.0 0.0 1.4210854715202004e-16 0 0 0</pose>
			<axis>
				<xyz>-2.6114100700096525e-31 1.0 2.2204460492503127e-15</xyz>
				<limit>
					<lower>-3.141592653589793</lower>
					<upper>3.141592653589793</upper>
				</limit>
				<use_parent_model_frame>0</use_parent_model_frame>
			</axis>
		</joint>
		<joint name="hip_right_axis2" type="revolute">
			<parent>hip_right_link2</parent>
			<child>upper_leg_right</child>
			<pose frame="">-0.007719208770746193 0.00640003707500183 0.15498861522108953 0 0 0</pose>
			<axis>
				<xyz>6.568586551522486e-46 -2.2204460492503127e-15 1.0</xyz>
				<limit>
					<lower>-3.141592653589793</lower>
					<upper>3.141592653589793</upper>
				</limit>
				<use_parent_model_frame>0</use_parent_model_frame>
			</axis>
		</joint>
		<joint name="motor8" type="prismatic">
			<parent>base</parent>
			<child>motor8</child>
			<pose frame="">0.0011978136706753161 -1.2342394009707207 -0.00951655921897796 0 0 0</pose>
			<axis>
				<xyz>0.0 -1.0 0.0</xyz>
				<limit>
					<lower>-1.4</lower>
					<upper>0.0</upper>
				</limit>
				<use_parent_model_frame>0</use_parent_model_frame>
			</axis>
		</joint>
		<joint name="motor9" type="prismatic">
			<parent>base</parent>
			<child>motor9</child>
			<pose frame="">-0.0003343018224884986 1.2358101829513672 -0.00948580573277212 0 0 0</pose>
			<axis>
				<xyz>0.0 -1.0 0.0</xyz>
				<limit>
					<lower>0.0</lower>
					<upper>0.0</upper>
				</limit>
				<use_parent_model_frame>0</use_parent_model_frame>
			</axis>
		</joint>
		<joint name="motor11" type="prismatic">
			<parent>base</parent>
			<child>motor10</child>
			<pose frame="">-0.001197813670675032 -1.2342394009707196 -0.009483440781021528 0 0 0</pose>
			<axis>
				<xyz>0.0 1.0 0.0</xyz>
				<limit>
					<lower>0.0</lower>
					<upper>1.4</upper>
				</limit>
				<use_parent_model_frame>0</use_parent_model_frame>
			</axis>
		</joint>
		<joint name="motor12" type="prismatic">
			<parent>base</parent>
			<child>motor12</child>
			<pose frame="">1.234239402810263 0.001197812674521117 -0.009516558941175077 0 0 0</pose>
			<axis>
				<xyz>1.0 0.0 0.0</xyz>
				<limit>
					<lower>-1.4</lower>
					<upper>0.0</upper>
				</limit>
				<use_parent_model_frame>0</use_parent_model_frame>
			</axis>
		</joint>
		<joint name="motor13" type="prismatic">
			<parent>base</parent>
			<child>motor13</child>
			<pose frame="">-1.2342394009707198 0.0011978136706744635 -0.00948344078102167 0 0 0</pose>
			<axis>
				<xyz>1.0 0.0 0.0</xyz>
				<limit>
					<lower>0.0</lower>
					<upper>1.4</upper>
				</limit>
				<use_parent_model_frame>0</use_parent_model_frame>
			</axis>
		</joint>
		<joint name="motor14" type="prismatic">
			<parent>base</parent>
			<child>motor15</child>
			<pose frame="">-1.2342394009707207 -0.0011978136706756004 -0.00951655921897796 0 0 0</pose>
			<axis>
				<xyz>-1.0 0.0 0.0</xyz>
				<limit>
					<lower>-1.4</lower>
					<upper>0.0</upper>
				</limit>
				<use_parent_model_frame>0</use_parent_model_frame>
			</axis>
		</joint>
		<joint name="motor15" type="prismatic">
			<parent>base</parent>
			<child>motor14</child>
			<pose frame="">1.234239402810262 -0.001197812674521117 -0.009483441058825265 0 0 0</pose>
			<axis>
				<xyz>-1.0 0.0 0.0</xyz>
				<limit>
					<lower>0.0</lower>
					<upper>1.4</upper>
				</limit>
				<use_parent_model_frame>0</use_parent_model_frame>
			</axis>
		</joint>
		<joint name="spine_axis0" type="revolute">
			<parent>hip</parent>
			<child>spine_link1</child>
			<pose frame="">-2.220446049250313e-18 -5.551115123125783e-18 0.0 0 0 0</pose>
			<axis>
				<xyz>1.0 3.244190472721411e-29 -1.4643501547599825e-14</xyz>
				<limit>
					<lower>-3.141592653589793</lower>
					<upper>3.141592653589793</upper>
				</limit>
				<use_parent_model_frame>0</use_parent_model_frame>
			</axis>
		</joint>
		<joint name="spine_axis1" type="revolute">
			<parent>spine_link1</parent>
			<child>spine_link2</child>
			<pose frame="">0.0 0.0 -1.4210854715202004e-16 0 0 0</pose>
			<axis>
				<xyz>7.320043134465789e-32 1.0 2.2204460492503056e-15</xyz>
				<limit>
					<lower>-3.141592653589793</lower>
					<upper>3.141592653589793</upper>
				</limit>
				<use_parent_model_frame>0</use_parent_model_frame>
			</axis>
		</joint>
		<joint name="spine_axis2" type="revolute">
			<parent>spine_link2</parent>
			<child>torso</child>
			<pose frame="">-0.0028637081139984534 3.431852135775682e-05 -0.6069070994200866 0 0 0</pose>
			<axis>
				<xyz>-4.4338983854760635e-60 -2.2204460492503056e-15 1.0</xyz>
				<limit>
					<lower>-3.141592653589793</lower>
					<upper>3.141592653589793</upper>
				</limit>
				<use_parent_model_frame>0</use_parent_model_frame>
			</axis>
		</joint>
		<joint name="ankle_right_axis0" type="revolute">
			<parent>lower_leg_right</parent>
			<child>ankle_right_link1</child>
			<pose frame="">8.881784197001253e-18 0.0 -1.7763568394002505e-17 0 0 0</pose>
			<axis>
				<xyz>1.0 3.273772756667199e-29 -1.4747584956158433e-14</xyz>
				<limit>
					<lower>-3.141592653589793</lower>
					<upper>3.141592653589793</upper>
				</limit>
				<use_parent_model_frame>0</use_parent_model_frame>
			</axis>
		</joint>
		<joint name="ankle_right_axis1" type="revolute">
			<parent>ankle_right_link1</parent>
			<child>ankle_right_link2</child>
			<pose frame="">4.440892098500626e-18 0.0 -1.7763568394002505e-17 0 0 0</pose>
			<axis>
				<xyz>8.489185213302819e-33 1.0 2.2204460492503095e-15</xyz>
				<limit>
					<lower>-3.141592653589793</lower>
					<upper>3.141592653589793</upper>
				</limit>
				<use_parent_model_frame>0</use_parent_model_frame>
			</axis>
		</joint>
		<joint name="ankle_right_axis2" type="revolute">
			<parent>ankle_right_link2</parent>
			<child>foot_right</child>
			<pose frame="">-1.3369334843638115e-08 1.624069247085913e-08 -0.0006058643727665291 0 0 0</pose>
			<axis>
				<xyz>2.91703841149741e-62 -2.2204460492503095e-15 1.0</xyz>
				<limit>
					<lower>-3.141592653589793</lower>
					<upper>3.141592653589793</upper>
				</limit>
				<use_parent_model_frame>0</use_parent_model_frame>
			</axis>
		</joint>
		<joint name="6dof_axis0" type="revolute">
			<parent>base</parent>
			<child>6dof_link1</child>
			<pose frame="">1.0679391398982218e-18 -2.198762005800603e-18 1.4210854715202004e-16 0 0 0</pose>
			<axis>
				<xyz>1.0 -2.6844855317200687e-42 -1.4936788733982073e-64</xyz>
				<limit>
					<lower>-3.141592653589793</lower>
					<upper>3.141592653589793</upper>
				</limit>
				<use_parent_model_frame>0</use_parent_model_frame>
			</axis>
		</joint>
		<joint name="6dof_axis1" type="revolute">
			<parent>6dof_link1</parent>
			<child>6dof_link2</child>
			<pose frame="">-9.38376980286204e-19 -5.269222558279552e-19 2.842170943040401e-16 0 0 0</pose>
			<axis>
				<xyz>2.6844855317200687e-42 1.0 5.564117200781429e-23</xyz>
				<limit>
					<lower>-3.141592653589793</lower>
					<upper>3.141592653589793</upper>
				</limit>
				<use_parent_model_frame>0</use_parent_model_frame>
			</axis>
		</joint>
		<joint name="6dof_axis2" type="revolute">
			<parent>6dof_link2</parent>
			<child>6dof_link3</child>
			<pose frame="">-2.379289594976508e-07 2.890294149984697e-07 -0.010729363507488045 0 0 0</pose>
			<axis>
				<xyz>-3.388310440774361e-71 -5.564117200781429e-23 1.0</xyz>
				<limit>
					<lower>-3.141592653589793</lower>
					<upper>3.141592653589793</upper>
				</limit>
				<use_parent_model_frame>0</use_parent_model_frame>
			</axis>
		</joint>
		<joint name="motor16" type="prismatic">
			<parent>base</parent>
			<child>motor16</child>
			<pose frame="">0.0011978136706730425 -1.2342394009707198 -0.009516559218978102 0 0 0</pose>
			<axis>
				<xyz>0.0 -1.0 0.0</xyz>
				<limit>
					<lower>-1.4</lower>
					<upper>0.0</upper>
				</limit>
				<use_parent_model_frame>0</use_parent_model_frame>
			</axis>
		</joint>
		<joint name="motor17" type="prismatic">
			<parent>base</parent>
			<child>motor17</child>
			<pose frame="">0.0011978126745225382 1.2342394028102615 -0.009483441058823702 0 0 0</pose>
			<axis>
				<xyz>0.0 -1.0 0.0</xyz>
				<limit>
					<lower>0.0</lower>
					<upper>1.4</upper>
				</limit>
				<use_parent_model_frame>0</use_parent_model_frame>
			</axis>
		</joint>
		<joint name="motor18" type="prismatic">
			<parent>base</parent>
			<child>motor19</child>
			<pose frame="">-0.0011978126745191275 1.2342394028102615 -0.009516558941174936 0 0 0</pose>
			<axis>
				<xyz>0.0 1.0 0.0</xyz>
				<limit>
					<lower>-1.4</lower>
					<upper>0.0</upper>
				</limit>
				<use_parent_model_frame>0</use_parent_model_frame>
			</axis>
		</joint>
		<joint name="motor19" type="prismatic">
			<parent>base</parent>
			<child>motor18</child>
			<pose frame="">-0.0011978136706770216 -1.2342394009707196 -0.009483440781021103 0 0 0</pose>
			<axis>
				<xyz>0.0 1.0 0.0</xyz>
				<limit>
					<lower>0.0</lower>
					<upper>1.4</upper>
				</limit>
				<use_parent_model_frame>0</use_parent_model_frame>
			</axis>
		</joint>
		<joint name="motor20" type="prismatic">
			<parent>base</parent>
			<child>motor20</child>
			<pose frame="">1.2342394028102615 0.0011978126745188433 -0.009516558941174936 0 0 0</pose>
			<axis>
				<xyz>1.0 0.0 0.0</xyz>
				<limit>
					<lower>-1.4</lower>
					<upper>0.0</upper>
				</limit>
				<use_parent_model_frame>0</use_parent_model_frame>
			</axis>
		</joint>
		<joint name="motor21" type="prismatic">
			<parent>base</parent>
			<child>motor21</child>
			<pose frame="">-1.2342394009707203 0.0011978136706756004 -0.009483440781021386 0 0 0</pose>
			<axis>
				<xyz>1.0 0.0 0.0</xyz>
				<limit>
					<lower>0.0</lower>
					<upper>1.4</upper>
				</limit>
				<use_parent_model_frame>0</use_parent_model_frame>
			</axis>
		</joint>
		<joint name="motor22" type="prismatic">
			<parent>base</parent>
			<child>motor23</child>
			<pose frame="">-1.2342394009707196 -0.0011978136706733266 -0.009516559218977535 0 0 0</pose>
			<axis>
				<xyz>-1.0 0.0 0.0</xyz>
				<limit>
					<lower>-1.4</lower>
					<upper>0.0</upper>
				</limit>
				<use_parent_model_frame>0</use_parent_model_frame>
			</axis>
		</joint>
		<joint name="motor23" type="prismatic">
			<parent>base</parent>
			<child>motor22</child>
			<pose frame="">1.2342394028102621 -0.001197812674522254 -0.009483441058824553 0 0 0</pose>
			<axis>
				<xyz>-1.0 0.0 0.0</xyz>
				<limit>
					<lower>0.0</lower>
					<upper>1.4</upper>
				</limit>
				<use_parent_model_frame>0</use_parent_model_frame>
			</axis>
		</joint>
		<joint name="6dof_axis3" type="prismatic">
			<parent>6dof_link3</parent>
			<child>6dof_link4</child>
			<pose frame="">-0.04264321097414968 6.09431058623984e-05 7.673861546209083e-15 0 0 0</pose>
			<axis>
				<xyz>-1.0 2.6814997359924824e-41 -4.336808689942018e-19</xyz>
				<limit>
					<lower>-1.0</lower>
					<upper>1.0</upper>
				</limit>
				<use_parent_model_frame>0</use_parent_model_frame>
			</axis>
		</joint>
		<joint name="6dof_axis4" type="prismatic">
			<parent>6dof_link4</parent>
			<child>6dof_link5</child>
			<pose frame="">-6.1008287956425485e-05 -0.042619910478939656 1.8770579117699527e-08 0 0 0</pose>
			<axis>
				<xyz>-2.4477572411455523e-32 1.0 5.56411602478092e-23</xyz>
				<limit>
					<lower>-1.0</lower>
					<upper>1.0</upper>
				</limit>
				<use_parent_model_frame>0</use_parent_model_frame>
			</axis>
		</joint>
		<joint name="6dof_axis5" type="prismatic">
			<parent>6dof_link5</parent>
			<child>hip</child>
			<pose frame="">0.019384473705082953 0.003106221167012608 0.04942551368446473 0 0 0</pose>
			<axis>
				<xyz>0.0 -5.082197683525751e-21 1.0</xyz>
				<limit>
					<lower>-1.0</lower>
					<upper>1.0</upper>
				</limit>
				<use_parent_model_frame>0</use_parent_model_frame>
			</axis>
		</joint>
		<joint name="hip_left_axis0" type="revolute">
			<parent>hip</parent>
			<child>hip_left_link1</child>
			<pose frame="">0.0 0.0 -1.4210854715202004e-16 0 0 0</pose>
			<axis>
				<xyz>1.0 3.244190472721411e-29 -1.4626154312840063e-14</xyz>
				<limit>
					<lower>-3.141592653589793</lower>
					<upper>3.141592653589793</upper>
				</limit>
				<use_parent_model_frame>0</use_parent_model_frame>
			</axis>
		</joint>
		<joint name="hip_left_axis1" type="revolute">
			<parent>hip_left_link1</parent>
			<child>hip_left_link2</child>
			<pose frame="">0.0 1.7763568394002505e-17 1.4210854715202004e-16 0 0 0</pose>
			<axis>
				<xyz>3.4681832456913174e-32 1.0 2.2204460492503044e-15</xyz>
				<limit>
					<lower>-3.141592653589793</lower>
					<upper>3.141592653589793</upper>
				</limit>
				<use_parent_model_frame>0</use_parent_model_frame>
			</axis>
		</joint>
		<joint name="hip_left_axis2" type="revolute">
			<parent>hip_left_link2</parent>
			<child>upper_leg_left</child>
			<pose frame="">-0.007718437528919882 -0.006379266871555789 0.1549743351284019 0 0 0</pose>
			<axis>
				<xyz>-4.6769849197675143e-60 -2.2204460492503044e-15 1.0</xyz>
				<limit>
					<lower>-3.141592653589793</lower>
					<upper>3.141592653589793</upper>
				</limit>
				<use_parent_model_frame>0</use_parent_model_frame>
			</axis>
		</joint>
		<joint name="motor0" type="prismatic">
			<parent>base</parent>
			<child>motor0</child>
			<pose frame="">-0.00033431159346434923 -1.2358101926090335 -0.009514196340348889 0 0 0</pose>
			<axis>
				<xyz>0.0 -1.0 0.0</xyz>
				<limit>
					<lower>-1.4</lower>
					<upper>0.0</upper>
				</limit>
				<use_parent_model_frame>0</use_parent_model_frame>
			</axis>
		</joint>
		<joint name="motor1" type="prismatic">
			<parent>base</parent>
			<child>motor1</child>
			<pose frame="">-0.00033430154605355254 1.2358101829513677 -0.009485805505270662 0 0 0</pose>
			<axis>
				<xyz>0.0 -1.0 0.0</xyz>
				<limit>
					<lower>0.0</lower>
					<upper>1.4</upper>
				</limit>
				<use_parent_model_frame>0</use_parent_model_frame>
			</axis>
		</joint>
		<joint name="motor2" type="prismatic">
			<parent>base</parent>
			<child>motor2</child>
			<pose frame="">0.00033431159342597996 -1.2358101926090346 -0.009485803664418523 0 0 0</pose>
			<axis>
				<xyz>0.0 1.0 0.0</xyz>
				<limit>
					<lower>0.0</lower>
					<upper>1.4</upper>
				</limit>
				<use_parent_model_frame>0</use_parent_model_frame>
			</axis>
		</joint>
		<joint name="motor3" type="prismatic">
			<parent>base</parent>
			<child>motor3</child>
			<pose frame="">-0.0011978126745185592 1.2342394028102621 -0.00951655894117484 0 0 0</pose>
			<axis>
				<xyz>0.0 1.0 0.0</xyz>
				<limit>
					<lower>-1.4</lower>
					<upper>0.0</upper>
				</limit>
				<use_parent_model_frame>0</use_parent_model_frame>
			</axis>
		</joint>
		<joint name="motor4" type="prismatic">
			<parent>base</parent>
			<child>motor5</child>
			<pose frame="">-1.2358101926090344 -0.00033431159341290595 -0.009485803664418506 0 0 0</pose>
			<axis>
				<xyz>1.0 0.0 0.0</xyz>
				<limit>
					<lower>0.0</lower>
					<upper>1.4</upper>
				</limit>
				<use_parent_model_frame>0</use_parent_model_frame>
			</axis>
		</joint>
		<joint name="motor5" type="prismatic">
			<parent>base</parent>
			<child>motor4</child>
			<pose frame="">1.2358101829513672 -0.0003343015461072696 -0.00951419449950688 0 0 0</pose>
			<axis>
				<xyz>1.0 0.0 0.0</xyz>
				<limit>
					<lower>-1.4</lower>
					<upper>0.0</upper>
				</limit>
				<use_parent_model_frame>0</use_parent_model_frame>
			</axis>
		</joint>
		<joint name="motor7" type="prismatic">
			<parent>base</parent>
			<child>motor6</child>
			<pose frame="">1.2358101829513677 0.0003343018224896355 -0.00948580550527066 0 0 0</pose>
			<axis>
				<xyz>-1.0 0.0 0.0</xyz>
				<limit>
					<lower>0.0</lower>
					<upper>1.4</upper>
				</limit>
				<use_parent_model_frame>0</use_parent_model_frame>
			</axis>
		</joint>
		<joint name="ankle_left_axis0" type="revolute">
			<parent>lower_leg_left</parent>
			<child>ankle_left_link1</child>
			<pose frame="">0.0 1.7763568394002505e-17 0.0 0 0 0</pose>
			<axis>
				<xyz>1.0 3.244190472721411e-29 -1.4643501547599815e-14</xyz>
				<limit>
					<lower>-3.141592653589793</lower>
					<upper>3.141592653589793</upper>
				</limit>
				<use_parent_model_frame>0</use_parent_model_frame>
			</axis>
		</joint>
		<joint name="ankle_left_axis1" type="revolute">
			<parent>ankle_left_link1</parent>
			<child>ankle_left_link2</child>
			<pose frame="">0.0 -1.7763568394002505e-17 -1.7763568394002505e-17 0 0 0</pose>
			<axis>
				<xyz>7.320043134456821e-32 1.0 2.2204460492503012e-15</xyz>
				<limit>
					<lower>-3.141592653589793</lower>
					<upper>3.141592653589793</upper>
				</limit>
				<use_parent_model_frame>0</use_parent_model_frame>
			</axis>
		</joint>
		<joint name="ankle_left_axis2" type="revolute">
			<parent>ankle_left_link2</parent>
			<child>foot_left</child>
			<pose frame="">-1.3369334843638115e-08 1.6240692417568427e-08 -0.0006058643727668134 0 0 0</pose>
			<axis>
				<xyz>-4.1033006988396903e-60 -2.2204460492503012e-15 1.0</xyz>
				<limit>
					<lower>-3.141592653589793</lower>
					<upper>3.141592653589793</upper>
				</limit>
				<use_parent_model_frame>0</use_parent_model_frame>
			</axis>
		</joint>
		<joint name="knee_left_axis0" type="revolute">
			<parent>upper_leg_left</parent>
			<child>knee_left_link1</child>
			<pose frame="">0.0 0.0 -7.105427357601002e-17 0 0 0</pose>
			<axis>
				<xyz>1.0 3.244190472721411e-29 -1.4643501547599825e-14</xyz>
				<limit>
					<lower>-3.141592653589793</lower>
					<upper>3.141592653589793</upper>
				</limit>
				<use_parent_model_frame>0</use_parent_model_frame>
			</axis>
		</joint>
		<joint name="knee_left_axis1" type="revolute">
			<parent>knee_left_link1</parent>
			<child>knee_left_link2</child>
			<pose frame="">-4.440892098500626e-18 0.0 0.0 0 0 0</pose>
			<axis>
				<xyz>7.320043134465789e-32 1.0 2.2204460492503056e-15</xyz>
				<limit>
					<lower>-3.141592653589793</lower>
					<upper>3.141592653589793</upper>
				</limit>
				<use_parent_model_frame>0</use_parent_model_frame>
			</axis>
		</joint>
		<joint name="knee_left_axis2" type="revolute">
			<parent>knee_left_link2</parent>
			<child>lower_leg_left</child>
			<pose frame="">0.016750096400789803 -0.006336577512370418 0.14681146934681455 0 0 0</pose>
			<axis>
				<xyz>-4.4338983854760635e-60 -2.2204460492503056e-15 1.0</xyz>
				<limit>
					<lower>-3.141592653589793</lower>
					<upper>3.141592653589793</upper>
				</limit>
				<use_parent_model_frame>0</use_parent_model_frame>
			</axis>
		</joint>
		<joint name="shoulder_left_axis0" type="revolute">
			<parent>torso</parent>
			<child>shoulder_left_link1</child>
			<pose frame="">0.0 3.552713678800501e-17 0.0 0 0 0</pose>
			<axis>
				<xyz>1.0 3.244190472721411e-29 -1.4636562653695914e-14</xyz>
				<limit>
					<lower>-3.141592653589793</lower>
					<upper>3.141592653589793</upper>
				</limit>
				<use_parent_model_frame>0</use_parent_model_frame>
			</axis>
		</joint>
		<joint name="shoulder_left_axis1" type="revolute">
			<parent>shoulder_left_link1</parent>
			<child>shoulder_left_link2</child>
			<pose frame="">-8.881784197001253e-18 3.552713678800501e-17 2.842170943040401e-16 0 0 0</pose>
			<axis>
				<xyz>5.779299178957122e-32 1.0 2.2204460492503068e-15</xyz>
				<limit>
					<lower>-3.141592653589793</lower>
					<upper>3.141592653589793</upper>
				</limit>
				<use_parent_model_frame>0</use_parent_model_frame>
			</axis>
		</joint>
		<joint name="shoulder_left_axis2" type="revolute">
			<parent>shoulder_left_link2</parent>
			<child>upper_arm_left</child>
			<pose frame="">0.020436510200302935 -0.030988218983780094 0.2250083793246148 0 0 0</pose>
			<axis>
				<xyz>3.694915321230053e-61 -2.2204460492503068e-15 1.0</xyz>
				<limit>
					<lower>-3.141592653589793</lower>
					<upper>3.141592653589793</upper>
				</limit>
				<use_parent_model_frame>0</use_parent_model_frame>
			</axis>
		</joint>
		<joint name="elbow_left_axis0" type="revolute">
			<parent>upper_arm_left</parent>
			<child>elbow_left_link1</child>
			<pose frame="">-1.7763568394002505e-17 0.0 2.842170943040401e-16 0 0 0</pose>
			<axis>
				<xyz>1.0 3.244190472721421e-29 -1.4636562653695914e-14</xyz>
				<limit>
					<lower>-3.141592653589793</lower>
					<upper>3.141592653589793</upper>
				</limit>
				<use_parent_model_frame>0</use_parent_model_frame>
			</axis>
		</joint>
		<joint name="elbow_left_axis1" type="revolute">
			<parent>elbow_left_link1</parent>
			<child>elbow_left_link2</child>
			<pose frame="">1.7763568394002505e-17 0.0 1.4210854715202004e-16 0 0 0</pose>
			<axis>
				<xyz>5.779299178957125e-32 1.0 2.220446049250314e-15</xyz>
				<limit>
					<lower>-3.141592653589793</lower>
					<upper>3.141592653589793</upper>
				</limit>
				<use_parent_model_frame>0</use_parent_model_frame>
			</axis>
		</joint>
		<joint name="elbow_left_axis2" type="revolute">
			<parent>elbow_left_link2</parent>
			<child>lower_arm_left</child>
			<pose frame="">-2.2631665366645848e-07 2.74923112222325e-07 -0.010256097183258248 0 0 0</pose>
			<axis>
				<xyz>2.9656557183557155e-61 -2.220446049250314e-15 1.0</xyz>
				<limit>
					<lower>-3.141592653589793</lower>
					<upper>3.141592653589793</upper>
				</limit>
				<use_parent_model_frame>0</use_parent_model_frame>
			</axis>
		</joint>
		<joint name="shoulder_right_axis0" type="revolute">
			<parent>torso</parent>
			<child>shoulder_right_link1</child>
			<pose frame="">8.881784197001253e-18 3.552713678800501e-17 0.0 0 0 0</pose>
			<axis>
				<xyz>1.0 3.24419047272142e-29 -1.4643501547599825e-14</xyz>
				<limit>
					<lower>-3.141592653589793</lower>
					<upper>3.141592653589793</upper>
				</limit>
				<use_parent_model_frame>0</use_parent_model_frame>
			</axis>
		</joint>
		<joint name="shoulder_right_axis1" type="revolute">
			<parent>shoulder_right_link1</parent>
			<child>shoulder_right_link2</child>
			<pose frame="">8.881784197001253e-18 -3.552713678800501e-17 0.0 0 0 0</pose>
			<axis>
				<xyz>5.779299178957126e-32 1.0 2.220446049250313e-15</xyz>
				<limit>
					<lower>-3.141592653589793</lower>
					<upper>3.141592653589793</upper>
				</limit>
				<use_parent_model_frame>0</use_parent_model_frame>
			</axis>
		</joint>
		<joint name="shoulder_right_axis2" type="revolute">
			<parent>shoulder_right_link2</parent>
			<child>upper_arm_right</child>
			<pose frame="">0.02043651020045318 0.03098829021084857 0.2250083793247241 0 0 0</pose>
			<axis>
				<xyz>2.7225691840642585e-61 -2.220446049250313e-15 1.0</xyz>
				<limit>
					<lower>-3.141592653589793</lower>
					<upper>3.141592653589793</upper>
				</limit>
				<use_parent_model_frame>0</use_parent_model_frame>
			</axis>
		</joint>
		<plugin filename="libcardsflow_gazebo_plugin.so" name="cardsflow_gazebo_plugin" />
	</model>
</sdf>