<?xml version="1.0" ?>
<sdf version="1.6">
	<model name="human">
		<link name="base">
			<self_collide>false</self_collide>
			<pose frame="">-6.9500252010331e-08 -1.9707701204956554e-07 0.7639152503965678 0.0 -0.0 0.0</pose>
			<inertial>
				<pose frame="">0.0 0.0 0.0 0 0 0</pose>
				<mass>5.670211945411031</mass>
				<inertia>
					<ixx>13.426879502251602</ixx>
					<ixy>-3.887718206911639e-12</ixy>
					<ixz>3.940811655216425e-07</ixz>
					<iyy>13.426879502241684</iyy>
					<iyz>1.1174684337865282e-06</iyz>
					<izz>12.564006179452424</izz>
				</inertia>
			</inertial>
			<collision name="base_collision">
				<geometry>
					<mesh>
						<uri>model://human/meshes/CAD/base.stl</uri>
						<scale>0.001 0.001 0.001</scale>
					</mesh>
				</geometry>
			</collision>
			<visual name="base_visual">
				<geometry>
					<mesh>
						<uri>model://human/meshes/CAD/base.stl</uri>
						<scale>0.001 0.001 0.001</scale>
					</mesh>
				</geometry>
			</visual>
		</link>
		<link name="hip">
			<self_collide>false</self_collide>
			<pose frame="">-0.019381512328334304 -0.0030912488398242783 0.9505764217875655 0.0 -0.0 0.0</pose>
			<inertial>
				<pose frame="">0.0 0.0 0.0 0 0 0</pose>
				<mass>43.2085372938147</mass>
				<inertia>
					<ixx>39.306856568223495</ixx>
					<ixy>-0.0024988661705189737</ixy>
					<ixz>0.7913062155383684</ixz>
					<iyy>39.2929598946167</iyy>
					<iyz>0.1263770177831837</iyz>
					<izz>0.3005697504957406</izz>
				</inertia>
			</inertial>
			<collision name="hip_collision">
				<geometry>
					<mesh>
						<uri>model://human/meshes/CAD/hip.stl</uri>
						<scale>0.001 0.001 0.001</scale>
					</mesh>
				</geometry>
			</collision>
			<visual name="hip_visual">
				<geometry>
					<mesh>
						<uri>model://human/meshes/CAD/hip.stl</uri>
						<scale>0.001 0.001 0.001</scale>
					</mesh>
				</geometry>
			</visual>
		</link>
		<link name="ankle_right_link1">
			<self_collide>false</self_collide>
			<pose frame="">-0.020000000000004785 -0.12262700433836342 0.11146497559651634 0.0 -0.0 0.0</pose>
			<inertial>
				<pose frame="">0.0 0.0 0.0 0 0 0</pose>
				<mass>0.0697903813480169</mass>
				<inertia>
					<ixx>0.001928218375800401</ixx>
					<ixy>-0.00017116370792682708</ixy>
					<ixz>0.00015558366307660268</ixz>
					<iyy>0.000906669890614203</iyy>
					<iyz>0.0009539379263534232</iyz>
					<izz>0.0010890280679373223</izz>
				</inertia>
			</inertial>
			<collision name="ankle_right_link1_collision">
				<geometry>
					<mesh>
						<uri>model://human/meshes/CAD/ankle_right_link1.stl</uri>
						<scale>0.001 0.001 0.001</scale>
					</mesh>
				</geometry>
			</collision>
			<visual name="ankle_right_link1_visual">
				<geometry>
					<mesh>
						<uri>model://human/meshes/CAD/ankle_right_link1.stl</uri>
						<scale>0.001 0.001 0.001</scale>
					</mesh>
				</geometry>
			</visual>
		</link>
		<link name="ankle_right_link2">
			<self_collide>false</self_collide>
			<pose frame="">-0.020000000000004778 -0.12262700433836346 0.11146497559651647 0.0 -0.0 0.0</pose>
			<inertial>
				<pose frame="">0.0 0.0 0.0 0 0 0</pose>
				<mass>0.04678255835713037</mass>
				<inertia>
					<ixx>0.0012899957695776951</ixx>
					<ixy>-0.00011473609973241874</ixy>
					<ixz>0.00010429233451242779</ixz>
					<iyy>0.0006052215829380134</iyy>
					<iyz>0.0006394528278355242</iyz>
					<izz>0.0007274616668541201</izz>
				</inertia>
			</inertial>
			<collision name="ankle_right_link2_collision">
				<geometry>
					<mesh>
						<uri>model://human/meshes/CAD/ankle_right_link2.stl</uri>
						<scale>0.001 0.001 0.001</scale>
					</mesh>
				</geometry>
			</collision>
			<visual name="ankle_right_link2_visual">
				<geometry>
					<mesh>
						<uri>model://human/meshes/CAD/ankle_right_link2.stl</uri>
						<scale>0.001 0.001 0.001</scale>
					</mesh>
				</geometry>
			</visual>
		</link>
		<link name="knee_right_link1">
			<self_collide>false</self_collide>
			<pose frame="">-0.020430189165163856 -0.10941629950839389 0.4654841277672509 0.0 -0.0 0.0</pose>
			<inertial>
				<pose frame="">0.0 0.0 0.0 0 0 0</pose>
				<mass>0.0697903813480169</mass>
				<inertia>
					<ixx>0.0159690365040413</ixx>
					<ixy>-0.0001560091181370168</ixy>
					<ixz>0.0006637015564045486</ixz>
					<iyy>0.015162641172061099</iyy>
					<iyz>0.0035545323488033824</iyz>
					<izz>0.0008763025911976856</izz>
				</inertia>
			</inertial>
			<collision name="knee_right_link1_collision">
				<geometry>
					<mesh>
						<uri>model://human/meshes/CAD/knee_right_link1.stl</uri>
						<scale>0.001 0.001 0.001</scale>
					</mesh>
				</geometry>
			</collision>
			<visual name="knee_right_link1_visual">
				<geometry>
					<mesh>
						<uri>model://human/meshes/CAD/knee_right_link1.stl</uri>
						<scale>0.001 0.001 0.001</scale>
					</mesh>
				</geometry>
			</visual>
		</link>
		<link name="knee_right_link2">
			<self_collide>false</self_collide>
			<pose frame="">-0.020430189165163842 -0.10941629950839328 0.4654841277672517 0.0 -0.0 0.0</pose>
			<inertial>
				<pose frame="">0.0 0.0 0.0 0 0 0</pose>
				<mass>0.04678255835713034</mass>
				<inertia>
					<ixx>0.010701971757941466</ixx>
					<ixy>-0.00010457752963255267</ixy>
					<ixz>0.00044489879829401986</ixz>
					<iyy>0.010161421098257288</iyy>
					<iyz>0.0023827082447218425</iyz>
					<izz>0.0005848654832913022</izz>
				</inertia>
			</inertial>
			<collision name="knee_right_link2_collision">
				<geometry>
					<mesh>
						<uri>model://human/meshes/CAD/knee_right_link2.stl</uri>
						<scale>0.001 0.001 0.001</scale>
					</mesh>
				</geometry>
			</collision>
			<visual name="knee_right_link2_visual">
				<geometry>
					<mesh>
						<uri>model://human/meshes/CAD/knee_right_link2.stl</uri>
						<scale>0.001 0.001 0.001</scale>
					</mesh>
				</geometry>
			</visual>
		</link>
		<link name="hip_right_link1">
			<self_collide>false</self_collide>
			<pose frame="">-0.02043018916516434 -0.10441629950839153 0.8954841277672511 0.0 -0.0 0.0</pose>
			<inertial>
				<pose frame="">0.0 0.0 0.0 0 0 0</pose>
				<mass>0.0697903813480169</mass>
				<inertia>
					<ixx>0.05673689144009942</ixx>
					<ixy>-0.00014887996467277263</ixy>
					<ixz>0.0012768087543296104</ixz>
					<iyy>0.05600511340126935</iyy>
					<iyz>0.0065256197203666265</iyz>
					<izz>0.000801685298047558</izz>
				</inertia>
			</inertial>
			<collision name="hip_right_link1_collision">
				<geometry>
					<mesh>
						<uri>model://human/meshes/CAD/hip_right_link1.stl</uri>
						<scale>0.001 0.001 0.001</scale>
					</mesh>
				</geometry>
			</collision>
			<visual name="hip_right_link1_visual">
				<geometry>
					<mesh>
						<uri>model://human/meshes/CAD/hip_right_link1.stl</uri>
						<scale>0.001 0.001 0.001</scale>
					</mesh>
				</geometry>
			</visual>
		</link>
		<link name="hip_right_link2">
			<self_collide>false</self_collide>
			<pose frame="">-0.02043018916516435 -0.10441629950838886 0.8954841277672522 0.0 -0.0 0.0</pose>
			<inertial>
				<pose frame="">0.0 0.0 0.0 0 0 0</pose>
				<mass>0.04678255835713034</mass>
				<inertia>
					<ixx>0.03802987161753091</ixx>
					<ixy>-9.979864704821848e-05</ixy>
					<ixz>0.0008558827005466321</ixz>
					<iyy>0.03753933913805758</iyy>
					<iyz>0.004374316051694124</iyz>
					<izz>0.0005348473030804614</izz>
				</inertia>
			</inertial>
			<collision name="hip_right_link2_collision">
				<geometry>
					<mesh>
						<uri>model://human/meshes/CAD/hip_right_link2.stl</uri>
						<scale>0.001 0.001 0.001</scale>
					</mesh>
				</geometry>
			</collision>
			<visual name="hip_right_link2_visual">
				<geometry>
					<mesh>
						<uri>model://human/meshes/CAD/hip_right_link2.stl</uri>
						<scale>0.001 0.001 0.001</scale>
					</mesh>
				</geometry>
			</visual>
		</link>
		<link name="spine_link1">
			<self_collide>false</self_collide>
			<pose frame="">-0.019907935090103 -0.002779095629306678 1.0300189040829888 0.0 -0.0 0.0</pose>
			<inertial>
				<pose frame="">0.0 0.0 0.0 0 0 0</pose>
				<mass>0.06979038134801689</mass>
				<inertia>
					<ixx>0.07405551969754892</ixx>
					<ixy>-3.861226504667932e-06</ixy>
					<ixz>0.0014310901182433991</ixz>
					<iyy>0.07408264041470769</iyy>
					<iyz>0.00019977643461031362</iyz>
					<izz>3.9846029057931386e-05</izz>
				</inertia>
			</inertial>
			<collision name="spine_link1_collision">
				<geometry>
					<mesh>
						<uri>model://human/meshes/CAD/spine_link1.stl</uri>
						<scale>0.001 0.001 0.001</scale>
					</mesh>
				</geometry>
			</collision>
			<visual name="spine_link1_visual">
				<geometry>
					<mesh>
						<uri>model://human/meshes/CAD/spine_link1.stl</uri>
						<scale>0.001 0.001 0.001</scale>
					</mesh>
				</geometry>
			</visual>
		</link>
		<link name="spine_link2">
			<self_collide>false</self_collide>
			<pose frame="">-0.019907935090102996 -0.0027790956293059273 1.03001890408299 0.0 -0.0 0.0</pose>
			<inertial>
				<pose frame="">0.0 0.0 0.0 0 0 0</pose>
				<mass>0.046782558357130355</mass>
				<inertia>
					<ixx>0.0496390607560655</ixx>
					<ixy>-2.5882944152992013e-06</ixy>
					<ixz>0.0009593020653832104</ixz>
					<iyy>0.04965724057552858</iyy>
					<iyz>0.00013391605734218122</iyz>
					<izz>2.4163891242769556e-05</izz>
				</inertia>
			</inertial>
			<collision name="spine_link2_collision">
				<geometry>
					<mesh>
						<uri>model://human/meshes/CAD/spine_link2.stl</uri>
						<scale>0.001 0.001 0.001</scale>
					</mesh>
				</geometry>
			</collision>
			<visual name="spine_link2_visual">
				<geometry>
					<mesh>
						<uri>model://human/meshes/CAD/spine_link2.stl</uri>
						<scale>0.001 0.001 0.001</scale>
					</mesh>
				</geometry>
			</visual>
		</link>
		<link name="shoulder_right_link1">
			<self_collide>false</self_collide>
			<pose frame="">-0.06490793509010408 -0.18277909562930636 1.400018904082991 0.0 -0.0 0.0</pose>
			<inertial>
				<pose frame="">0.0 0.0 0.0 0 0 0</pose>
				<mass>0.06979038134801692</mass>
				<inertia>
					<ixx>0.13913605971412407</ixx>
					<ixy>-0.0008279800806155287</ixy>
					<ixz>0.006342014993973067</ixz>
					<iyy>0.13709851852044003</iyy>
					<iyz>0.017858953045675127</iyz>
					<izz>0.0026372478130823954</izz>
				</inertia>
			</inertial>
			<collision name="shoulder_right_link1_collision">
				<geometry>
					<mesh>
						<uri>model://human/meshes/CAD/shoulder_right_link1.stl</uri>
						<scale>0.001 0.001 0.001</scale>
					</mesh>
				</geometry>
			</collision>
			<visual name="shoulder_right_link1_visual">
				<geometry>
					<mesh>
						<uri>model://human/meshes/CAD/shoulder_right_link1.stl</uri>
						<scale>0.001 0.001 0.001</scale>
					</mesh>
				</geometry>
			</visual>
		</link>
		<link name="shoulder_right_link2">
			<self_collide>false</self_collide>
			<pose frame="">-0.06490793509010326 -0.18277909562930877 1.400018904082993 0.0 -0.0 0.0</pose>
			<inertial>
				<pose frame="">0.0 0.0 0.0 0 0 0</pose>
				<mass>0.04678255835713035</mass>
				<inertia>
					<ixx>0.09326447306118829</ixx>
					<ixy>-0.0005550195555857657</ixy>
					<ixz>0.004251240369039305</ixz>
					<iyy>0.09189864888946964</iyy>
					<iyz>0.011971384837264535</iyz>
					<izz>0.0017652791880929742</izz>
				</inertia>
			</inertial>
			<collision name="shoulder_right_link2_collision">
				<geometry>
					<mesh>
						<uri>model://human/meshes/CAD/shoulder_right_link2.stl</uri>
						<scale>0.001 0.001 0.001</scale>
					</mesh>
				</geometry>
			</collision>
			<visual name="shoulder_right_link2_visual">
				<geometry>
					<mesh>
						<uri>model://human/meshes/CAD/shoulder_right_link2.stl</uri>
						<scale>0.001 0.001 0.001</scale>
					</mesh>
				</geometry>
			</visual>
		</link>
		<link name="elbow_right_link1">
			<self_collide>false</self_collide>
			<pose frame="">-0.09090793509010725 -0.2227790956292402 1.1370189040829808 0.0 -0.0 0.0</pose>
			<inertial>
				<pose frame="">0.0 0.0 0.0 0 0 0</pose>
				<mass>0.0697903813480169</mass>
				<inertia>
					<ixx>0.09370122224598905</ixx>
					<ixy>-0.0014134218513619122</ixy>
					<ixz>0.007213815820120983</ixz>
					<iyy>0.09081425429323578</iyy>
					<iyz>0.01767818576947684</iyz>
					<izz>0.004052145920149098</izz>
				</inertia>
			</inertial>
			<collision name="elbow_right_link1_collision">
				<geometry>
					<mesh>
						<uri>model://human/meshes/CAD/elbow_right_link1.stl</uri>
						<scale>0.001 0.001 0.001</scale>
					</mesh>
				</geometry>
			</collision>
			<visual name="elbow_right_link1_visual">
				<geometry>
					<mesh>
						<uri>model://human/meshes/CAD/elbow_right_link1.stl</uri>
						<scale>0.001 0.001 0.001</scale>
					</mesh>
				</geometry>
			</visual>
		</link>
		<link name="elbow_right_link2">
			<self_collide>false</self_collide>
			<pose frame="">-0.09090793509010647 -0.22277909562924245 1.1370189040829817 0.0 -0.0 0.0</pose>
			<inertial>
				<pose frame="">0.0 0.0 0.0 0 0 0</pose>
				<mass>0.04678255835713035</mass>
				<inertia>
					<ixx>0.0628081566713916</ixx>
					<ixy>-0.0009474585031259583</ixy>
					<ixz>0.004835634267414512</ixz>
					<iyy>0.06087293660071513</iyy>
					<iyz>0.011850211181461755</iyz>
					<izz>0.0027137272691138445</izz>
				</inertia>
			</inertial>
			<collision name="elbow_right_link2_collision">
				<geometry>
					<mesh>
						<uri>model://human/meshes/CAD/elbow_right_link2.stl</uri>
						<scale>0.001 0.001 0.001</scale>
					</mesh>
				</geometry>
			</collision>
			<visual name="elbow_right_link2_visual">
				<geometry>
					<mesh>
						<uri>model://human/meshes/CAD/elbow_right_link2.stl</uri>
						<scale>0.001 0.001 0.001</scale>
					</mesh>
				</geometry>
			</visual>
		</link>
		<link name="wrist_right_link1">
			<self_collide>false</self_collide>
			<pose frame="">-0.0739079350901106 -0.2682790956292396 0.869018904082981 0.0 -0.0 0.0</pose>
			<inertial>
				<pose frame="">0.0 0.0 0.0 0 0 0</pose>
				<mass>0.0697903813480169</mass>
				<inertia>
					<ixx>0.0577399845516863</ixx>
					<ixy>-0.0013838004700198734</ixy>
					<ixz>0.004482454233363379</ixz>
					<iyy>0.05309813623893186</iyy>
					<iyz>0.0162709019871818</iyz>
					<izz>0.005415939157459558</izz>
				</inertia>
			</inertial>
			<collision name="wrist_right_link1_collision">
				<geometry>
					<mesh>
						<uri>model://human/meshes/CAD/wrist_right_link1.stl</uri>
						<scale>0.001 0.001 0.001</scale>
					</mesh>
				</geometry>
			</collision>
			<visual name="wrist_right_link1_visual">
				<geometry>
					<mesh>
						<uri>model://human/meshes/CAD/wrist_right_link1.stl</uri>
						<scale>0.001 0.001 0.001</scale>
					</mesh>
				</geometry>
			</visual>
		</link>
		<link name="wrist_right_link2">
			<self_collide>false</self_collide>
			<pose frame="">-0.0739079350901097 -0.2682790956292419 0.8690189040829844 0.0 -0.0 0.0</pose>
			<inertial>
				<pose frame="">0.0 0.0 0.0 0 0 0</pose>
				<mass>0.046782558357130355</mass>
				<inertia>
					<ixx>0.038702274620982934</ixx>
					<ixy>-0.0009276024144431533</ixy>
					<ixz>0.0030047217496891533</ixz>
					<iyy>0.03559070630194039</iyy>
					<iyz>0.010906867207713283</iyz>
					<izz>0.0036279182432737865</izz>
				</inertia>
			</inertial>
			<collision name="wrist_right_link2_collision">
				<geometry>
					<mesh>
						<uri>model://human/meshes/CAD/wrist_right_link2.stl</uri>
						<scale>0.001 0.001 0.001</scale>
					</mesh>
				</geometry>
			</collision>
			<visual name="wrist_right_link2_visual">
				<geometry>
					<mesh>
						<uri>model://human/meshes/CAD/wrist_right_link2.stl</uri>
						<scale>0.001 0.001 0.001</scale>
					</mesh>
				</geometry>
			</visual>
		</link>
		<link name="shoulder_left_link1">
			<self_collide>false</self_collide>
			<pose frame="">-0.06490793509010417 0.1827790956293065 1.4000189040829911 0.0 -0.0 0.0</pose>
			<inertial>
				<pose frame="">0.0 0.0 0.0 0 0 0</pose>
				<mass>0.06979038134801689</mass>
				<inertia>
					<ixx>0.13913605971412404</ixx>
					<ixy>0.0008279800806155301</ixy>
					<ixz>0.006342014993973072</ixz>
					<iyy>0.13709851852043997</iyy>
					<iyz>-0.017858953045675145</iyz>
					<izz>0.0026372478130823997</izz>
				</inertia>
			</inertial>
			<collision name="shoulder_left_link1_collision">
				<geometry>
					<mesh>
						<uri>model://human/meshes/CAD/shoulder_left_link1.stl</uri>
						<scale>0.001 0.001 0.001</scale>
					</mesh>
				</geometry>
			</collision>
			<visual name="shoulder_left_link1_visual">
				<geometry>
					<mesh>
						<uri>model://human/meshes/CAD/shoulder_left_link1.stl</uri>
						<scale>0.001 0.001 0.001</scale>
					</mesh>
				</geometry>
			</visual>
		</link>
		<link name="shoulder_left_link2">
			<self_collide>false</self_collide>
			<pose frame="">-0.06490793509010334 0.1827790956293089 1.4000189040829925 0.0 -0.0 0.0</pose>
			<inertial>
				<pose frame="">0.0 0.0 0.0 0 0 0</pose>
				<mass>0.04678255835713035</mass>
				<inertia>
					<ixx>0.09326447306118828</ixx>
					<ixy>0.0005550195555857666</ixy>
					<ixz>0.00425124036903931</ixz>
					<iyy>0.09189864888946961</iyy>
					<iyz>-0.011971384837264544</iyz>
					<izz>0.0017652791880929763</izz>
				</inertia>
			</inertial>
			<collision name="shoulder_left_link2_collision">
				<geometry>
					<mesh>
						<uri>model://human/meshes/CAD/shoulder_left_link2.stl</uri>
						<scale>0.001 0.001 0.001</scale>
					</mesh>
				</geometry>
			</collision>
			<visual name="shoulder_left_link2_visual">
				<geometry>
					<mesh>
						<uri>model://human/meshes/CAD/shoulder_left_link2.stl</uri>
						<scale>0.001 0.001 0.001</scale>
					</mesh>
				</geometry>
			</visual>
		</link>
		<link name="elbow_left_link1">
			<self_collide>false</self_collide>
			<pose frame="">-0.09090793509010721 0.22277909562923992 1.1370189040829808 0.0 -0.0 0.0</pose>
			<inertial>
				<pose frame="">0.0 0.0 0.0 0 0 0</pose>
				<mass>0.0697903813480169</mass>
				<inertia>
					<ixx>0.09370122224598904</ixx>
					<ixy>0.0014134218513619091</ixy>
					<ixz>0.007213815820120979</ixz>
					<iyy>0.09081425429323578</iyy>
					<iyz>-0.017678185769476815</iyz>
					<izz>0.0040521459201490855</izz>
				</inertia>
			</inertial>
			<collision name="elbow_left_link1_collision">
				<geometry>
					<mesh>
						<uri>model://human/meshes/CAD/elbow_left_link1.stl</uri>
						<scale>0.001 0.001 0.001</scale>
					</mesh>
				</geometry>
			</collision>
			<visual name="elbow_left_link1_visual">
				<geometry>
					<mesh>
						<uri>model://human/meshes/CAD/elbow_left_link1.stl</uri>
						<scale>0.001 0.001 0.001</scale>
					</mesh>
				</geometry>
			</visual>
		</link>
		<link name="elbow_left_link2">
			<self_collide>false</self_collide>
			<pose frame="">-0.0909079350901065 0.22277909562924225 1.1370189040829817 0.0 -0.0 0.0</pose>
			<inertial>
				<pose frame="">0.0 0.0 0.0 0 0 0</pose>
				<mass>0.04678255835713035</mass>
				<inertia>
					<ixx>0.0628081566713916</ixx>
					<ixy>0.000947458503125958</ixy>
					<ixz>0.0048356342674145125</ixz>
					<iyy>0.06087293660071512</iyy>
					<iyz>-0.011850211181461748</iyz>
					<izz>0.0027137272691138414</izz>
				</inertia>
			</inertial>
			<collision name="elbow_left_link2_collision">
				<geometry>
					<mesh>
						<uri>model://human/meshes/CAD/elbow_left_link2.stl</uri>
						<scale>0.001 0.001 0.001</scale>
					</mesh>
				</geometry>
			</collision>
			<visual name="elbow_left_link2_visual">
				<geometry>
					<mesh>
						<uri>model://human/meshes/CAD/elbow_left_link2.stl</uri>
						<scale>0.001 0.001 0.001</scale>
					</mesh>
				</geometry>
			</visual>
		</link>
		<link name="wrist_left_link1">
			<self_collide>false</self_collide>
			<pose frame="">-0.0739079350901107 0.2682790956292397 0.869018904082981 0.0 -0.0 0.0</pose>
			<inertial>
				<pose frame="">0.0 0.0 0.0 0 0 0</pose>
				<mass>0.06979038134801689</mass>
				<inertia>
					<ixx>0.057739984551686316</ixx>
					<ixy>0.0013838004700198747</ixy>
					<ixz>0.004482454233363383</ixz>
					<iyy>0.053098136238931844</iyy>
					<iyz>-0.016270901987181795</iyz>
					<izz>0.00541593915745956</izz>
				</inertia>
			</inertial>
			<collision name="wrist_left_link1_collision">
				<geometry>
					<mesh>
						<uri>model://human/meshes/CAD/wrist_left_link1.stl</uri>
						<scale>0.001 0.001 0.001</scale>
					</mesh>
				</geometry>
			</collision>
			<visual name="wrist_left_link1_visual">
				<geometry>
					<mesh>
						<uri>model://human/meshes/CAD/wrist_left_link1.stl</uri>
						<scale>0.001 0.001 0.001</scale>
					</mesh>
				</geometry>
			</visual>
		</link>
		<link name="wrist_left_link2">
			<self_collide>false</self_collide>
			<pose frame="">-0.07390793509010976 0.2682790956292419 0.8690189040829841 0.0 -0.0 0.0</pose>
			<inertial>
				<pose frame="">0.0 0.0 0.0 0 0 0</pose>
				<mass>0.04678255835713035</mass>
				<inertia>
					<ixx>0.03870227462098292</ixx>
					<ixy>0.0009276024144431542</ixy>
					<ixz>0.0030047217496891555</ixz>
					<iyy>0.03559070630194038</iyy>
					<iyz>-0.010906867207713283</iyz>
					<izz>0.0036279182432737878</izz>
				</inertia>
			</inertial>
			<collision name="wrist_left_link2_collision">
				<geometry>
					<mesh>
						<uri>model://human/meshes/CAD/wrist_left_link2.stl</uri>
						<scale>0.001 0.001 0.001</scale>
					</mesh>
				</geometry>
			</collision>
			<visual name="wrist_left_link2_visual">
				<geometry>
					<mesh>
						<uri>model://human/meshes/CAD/wrist_left_link2.stl</uri>
						<scale>0.001 0.001 0.001</scale>
					</mesh>
				</geometry>
			</visual>
		</link>
		<link name="knee_left_link1">
			<self_collide>false</self_collide>
			<pose frame="">-0.020430189165163867 0.10941629950839385 0.4654841277672508 0.0 -0.0 0.0</pose>
			<inertial>
				<pose frame="">0.0 0.0 0.0 0 0 0</pose>
				<mass>0.0697903813480169</mass>
				<inertia>
					<ixx>0.015969036504041304</ixx>
					<ixy>0.0001560091181370171</ixy>
					<ixz>0.00066370155640455</ixz>
					<iyy>0.015162641172061104</iyy>
					<iyz>-0.0035545323488033837</iyz>
					<izz>0.000876302591197686</izz>
				</inertia>
			</inertial>
			<collision name="knee_left_link1_collision">
				<geometry>
					<mesh>
						<uri>model://human/meshes/CAD/knee_left_link1.stl</uri>
						<scale>0.001 0.001 0.001</scale>
					</mesh>
				</geometry>
			</collision>
			<visual name="knee_left_link1_visual">
				<geometry>
					<mesh>
						<uri>model://human/meshes/CAD/knee_left_link1.stl</uri>
						<scale>0.001 0.001 0.001</scale>
					</mesh>
				</geometry>
			</visual>
		</link>
		<link name="knee_left_link2">
			<self_collide>false</self_collide>
			<pose frame="">-0.020430189165163874 0.10941629950839339 0.4654841277672519 0.0 -0.0 0.0</pose>
			<inertial>
				<pose frame="">0.0 0.0 0.0 0 0 0</pose>
				<mass>0.04678255835713034</mass>
				<inertia>
					<ixx>0.010701971757941466</ixx>
					<ixy>0.00010457752963255291</ixy>
					<ixz>0.00044489879829402067</ixz>
					<iyy>0.010161421098257288</iyy>
					<iyz>-0.0023827082447218434</iyz>
					<izz>0.0005848654832913028</izz>
				</inertia>
			</inertial>
			<collision name="knee_left_link2_collision">
				<geometry>
					<mesh>
						<uri>model://human/meshes/CAD/knee_left_link2.stl</uri>
						<scale>0.001 0.001 0.001</scale>
					</mesh>
				</geometry>
			</collision>
			<visual name="knee_left_link2_visual">
				<geometry>
					<mesh>
						<uri>model://human/meshes/CAD/knee_left_link2.stl</uri>
						<scale>0.001 0.001 0.001</scale>
					</mesh>
				</geometry>
			</visual>
		</link>
		<link name="foot_left_link1">
			<self_collide>false</self_collide>
			<pose frame="">-0.020000000000004806 0.12262700433836343 0.11146497559651634 0.0 -0.0 0.0</pose>
			<inertial>
				<pose frame="">0.0 0.0 0.0 0 0 0</pose>
				<mass>0.06979038134801688</mass>
				<inertia>
					<ixx>0.0019282183758004019</ixx>
					<ixy>0.00017116370792682727</ixy>
					<ixz>0.0001555836630766028</ixz>
					<iyy>0.000906669890614203</iyy>
					<iyz>-0.000953937926353423</iyz>
					<izz>0.0010890280679373228</izz>
				</inertia>
			</inertial>
			<collision name="foot_left_link1_collision">
				<geometry>
					<mesh>
						<uri>model://human/meshes/CAD/foot_left_link1.stl</uri>
						<scale>0.001 0.001 0.001</scale>
					</mesh>
				</geometry>
			</collision>
			<visual name="foot_left_link1_visual">
				<geometry>
					<mesh>
						<uri>model://human/meshes/CAD/foot_left_link1.stl</uri>
						<scale>0.001 0.001 0.001</scale>
					</mesh>
				</geometry>
			</visual>
		</link>
		<link name="foot_left_link2">
			<self_collide>false</self_collide>
			<pose frame="">-0.020000000000004816 0.12262700433836349 0.11146497559651648 0.0 -0.0 0.0</pose>
			<inertial>
				<pose frame="">0.0 0.0 0.0 0 0 0</pose>
				<mass>0.04678255835713033</mass>
				<inertia>
					<ixx>0.001289995769577694</ixx>
					<ixy>0.00011473609973241884</ixy>
					<ixz>0.00010429233451242786</ixz>
					<iyy>0.0006052215829380127</iyy>
					<iyz>-0.0006394528278355234</iyz>
					<izz>0.0007274616668541196</izz>
				</inertia>
			</inertial>
			<collision name="foot_left_link2_collision">
				<geometry>
					<mesh>
						<uri>model://human/meshes/CAD/foot_left_link2.stl</uri>
						<scale>0.001 0.001 0.001</scale>
					</mesh>
				</geometry>
			</collision>
			<visual name="foot_left_link2_visual">
				<geometry>
					<mesh>
						<uri>model://human/meshes/CAD/foot_left_link2.stl</uri>
						<scale>0.001 0.001 0.001</scale>
					</mesh>
				</geometry>
			</visual>
		</link>
		<link name="hip_left_link1">
			<self_collide>false</self_collide>
			<pose frame="">-0.02043018916516429 0.10441629950839182 0.8954841277672544 0.0 -0.0 0.0</pose>
			<inertial>
				<pose frame="">0.0 0.0 0.0 0 0 0</pose>
				<mass>0.06979038134801693</mass>
				<inertia>
					<ixx>0.056736891440099864</ixx>
					<ixy>0.00014887996467277277</ixy>
					<ixz>0.0012768087543296135</ixz>
					<iyy>0.05600511340126978</iyy>
					<iyz>-0.006525619720366666</iyz>
					<izz>0.0008016852980475612</izz>
				</inertia>
			</inertial>
			<collision name="hip_left_link1_collision">
				<geometry>
					<mesh>
						<uri>model://human/meshes/CAD/hip_left_link1.stl</uri>
						<scale>0.001 0.001 0.001</scale>
					</mesh>
				</geometry>
			</collision>
			<visual name="hip_left_link1_visual">
				<geometry>
					<mesh>
						<uri>model://human/meshes/CAD/hip_left_link1.stl</uri>
						<scale>0.001 0.001 0.001</scale>
					</mesh>
				</geometry>
			</visual>
		</link>
		<link name="hip_left_link2">
			<self_collide>false</self_collide>
			<pose frame="">-0.020430189165164318 0.10441629950839294 0.8954841277672546 0.0 -0.0 0.0</pose>
			<inertial>
				<pose frame="">0.0 0.0 0.0 0 0 0</pose>
				<mass>0.04678255835713036</mass>
				<inertia>
					<ixx>0.03802987161753118</ixx>
					<ixy>9.97986470482225e-05</ixy>
					<ixz>0.0008558827005466322</ixz>
					<iyy>0.037539339138057806</iyy>
					<iyz>-0.00437431605169431</iyz>
					<izz>0.0005348473030805013</izz>
				</inertia>
			</inertial>
			<collision name="hip_left_link2_collision">
				<geometry>
					<mesh>
						<uri>model://human/meshes/CAD/hip_left_link2.stl</uri>
						<scale>0.001 0.001 0.001</scale>
					</mesh>
				</geometry>
			</collision>
			<visual name="hip_left_link2_visual">
				<geometry>
					<mesh>
						<uri>model://human/meshes/CAD/hip_left_link2.stl</uri>
						<scale>0.001 0.001 0.001</scale>
					</mesh>
				</geometry>
			</visual>
		</link>
		<link name="neck_link1">
			<self_collide>false</self_collide>
			<pose frame="">-0.029907935090094085 -0.002779095629307541 1.610018904082992 0.0 -0.0 0.0</pose>
			<inertial>
				<pose frame="">0.0 0.0 0.0 0 0 0</pose>
				<mass>0.06979038134801678</mass>
				<inertia>
					<ixx>0.18092008203249935</ixx>
					<ixy>-5.800767942386944e-06</ixy>
					<ixz>0.0033605702326151956</ixz>
					<iyy>0.18098196943542869</iyy>
					<iyz>0.00031226983799811166</iyz>
					<izz>7.461271482849317e-05</izz>
				</inertia>
			</inertial>
			<collision name="neck_link1_collision">
				<geometry>
					<mesh>
						<uri>model://human/meshes/CAD/neck_link1.stl</uri>
						<scale>0.001 0.001 0.001</scale>
					</mesh>
				</geometry>
			</collision>
			<visual name="neck_link1_visual">
				<geometry>
					<mesh>
						<uri>model://human/meshes/CAD/neck_link1.stl</uri>
						<scale>0.001 0.001 0.001</scale>
					</mesh>
				</geometry>
			</visual>
		</link>
		<link name="neck_link2">
			<self_collide>false</self_collide>
			<pose frame="">-0.029907935090094217 -0.0027790956293068433 1.610018904082992 0.0 -0.0 0.0</pose>
			<inertial>
				<pose frame="">0.0 0.0 0.0 0 0 0</pose>
				<mass>0.04678255835713026</mass>
				<inertia>
					<ixx>0.12127353999488774</ixx>
					<ixy>-3.888426449879759e-06</ixy>
					<ixz>0.0022526896971171717</ixz>
					<iyy>0.12131502495288898</iyy>
					<iyz>0.00020932371534791494</iyz>
					<izz>4.746902978091227e-05</izz>
				</inertia>
			</inertial>
			<collision name="neck_link2_collision">
				<geometry>
					<mesh>
						<uri>model://human/meshes/CAD/neck_link2.stl</uri>
						<scale>0.001 0.001 0.001</scale>
					</mesh>
				</geometry>
			</collision>
			<visual name="neck_link2_visual">
				<geometry>
					<mesh>
						<uri>model://human/meshes/CAD/neck_link2.stl</uri>
						<scale>0.001 0.001 0.001</scale>
					</mesh>
				</geometry>
			</visual>
		</link>
		<link name="lower_leg_right">
			<self_collide>false</self_collide>
			<pose frame="">-0.03766314553006496 -0.11421641144452144 0.3281766056493518 0.0 -0.0 0.0</pose>
			<inertial>
				<pose frame="">0.0 0.0 0.0 0 0 0</pose>
				<mass>27.229177337642792</mass>
				<inertia>
					<ixx>3.568255669775347</ixx>
					<ixy>-0.1154283330711886</ixy>
					<ixz>0.3299525491594697</ixz>
					<iyy>3.2626206557776776</iyy>
					<iyz>1.0123019463474043</iyz>
					<izz>0.44033832679612744</izz>
				</inertia>
			</inertial>
			<collision name="lower_leg_right_collision">
				<geometry>
					<mesh>
						<uri>model://human/meshes/CAD/lower_leg_right.stl</uri>
						<scale>0.001 0.001 0.001</scale>
					</mesh>
				</geometry>
			</collision>
			<visual name="lower_leg_right_visual">
				<geometry>
					<mesh>
						<uri>model://human/meshes/CAD/lower_leg_right.stl</uri>
						<scale>0.001 0.001 0.001</scale>
					</mesh>
				</geometry>
			</visual>
		</link>
		<link name="foot_right">
			<self_collide>false</self_collide>
			<pose frame="">-0.020000016271634193 -0.12262699092302759 0.11085911144948245 0.0 -0.0 0.0</pose>
			<inertial>
				<pose frame="">0.0 0.0 0.0 0 0 0</pose>
				<mass>0.2795712981996832</mass>
				<inertia>
					<ixx>0.007684316815353737</ixx>
					<ixy>-0.0006856602948306438</ixy>
					<ixz>0.0006198609301855931</ixz>
					<iyy>0.0035921261607924013</iyy>
					<iyz>0.0038005815545665714</iyz>
					<izz>0.004358207434789038</izz>
				</inertia>
			</inertial>
			<collision name="foot_right_collision">
				<geometry>
					<mesh>
						<uri>model://human/meshes/CAD/foot_right.stl</uri>
						<scale>0.001 0.001 0.001</scale>
					</mesh>
				</geometry>
			</collision>
			<visual name="foot_right_visual">
				<geometry>
					<mesh>
						<uri>model://human/meshes/CAD/foot_right.stl</uri>
						<scale>0.001 0.001 0.001</scale>
					</mesh>
				</geometry>
			</visual>
		</link>
		<link name="upper_leg_right">
			<self_collide>false</self_collide>
			<pose frame="">-0.013143693382489052 -0.10923367552917064 0.7423935602464685 0.0 -0.0 0.0</pose>
			<inertial>
				<pose frame="">0.0 0.0 0.0 0 0 0</pose>
				<mass>63.392076683096505</mass>
				<inertia>
					<ixx>36.731865846913266</ixx>
					<ixy>-0.08398359476092965</ixy>
					<ixz>0.6479677642584344</ixz>
					<iyy>36.04269469895189</iyy>
					<iyz>5.149228482666458</iyz>
					<izz>0.9612571472477945</izz>
				</inertia>
			</inertial>
			<collision name="upper_leg_right_collision">
				<geometry>
					<mesh>
						<uri>model://human/meshes/CAD/upper_leg_right.stl</uri>
						<scale>0.001 0.001 0.001</scale>
					</mesh>
				</geometry>
			</collision>
			<visual name="upper_leg_right_visual">
				<geometry>
					<mesh>
						<uri>model://human/meshes/CAD/upper_leg_right.stl</uri>
						<scale>0.001 0.001 0.001</scale>
					</mesh>
				</geometry>
			</visual>
		</link>
		<link name="chest">
			<self_collide>false</self_collide>
			<pose frame="">-0.024731104510421355 -0.0029161291616595733 1.3448245022104695 0.0 -0.0 0.0</pose>
			<inertial>
				<pose frame="">0.0 0.0 0.0 0 0 0</pose>
				<mass>2.0895121856353778</mass>
				<inertia>
					<ixx>3.952486745638872</ixx>
					<ixy>-0.00012846394780561098</ixy>
					<ixz>0.07024838957972383</ixz>
					<iyy>3.947484051794809</iyy>
					<iyz>0.008214930472303752</iyz>
					<izz>0.00899176002185508</izz>
				</inertia>
			</inertial>
			<collision name="chest_collision">
				<geometry>
					<mesh>
						<uri>model://human/meshes/CAD/chest.stl</uri>
						<scale>0.001 0.001 0.001</scale>
					</mesh>
				</geometry>
			</collision>
			<visual name="chest_visual">
				<geometry>
					<mesh>
						<uri>model://human/meshes/CAD/chest.stl</uri>
						<scale>0.001 0.001 0.001</scale>
					</mesh>
				</geometry>
			</visual>
		</link>
		<link name="upper_arm_right">
			<self_collide>false</self_collide>
			<pose frame="">-0.0872146024630778 -0.2158929479759101 1.1745802949690574 0.0 -0.0 0.0</pose>
			<inertial>
				<pose frame="">0.0 0.0 0.0 0 0 0</pose>
				<mass>0.11563812960698241</mass>
				<inertia>
					<ixx>0.1659681260672176</ixx>
					<ixy>-0.0021960330754169028</ixy>
					<ixz>0.01174914575159122</ixz>
					<iyy>0.16143014704411274</iyy>
					<iyz>0.029135555349506705</iyz>
					<izz>0.006339245336116775</izz>
				</inertia>
			</inertial>
			<collision name="upper_arm_right_collision">
				<geometry>
					<mesh>
						<uri>model://human/meshes/CAD/upper_arm_right.stl</uri>
						<scale>0.001 0.001 0.001</scale>
					</mesh>
				</geometry>
			</collision>
			<visual name="upper_arm_right_visual">
				<geometry>
					<mesh>
						<uri>model://human/meshes/CAD/upper_arm_right.stl</uri>
						<scale>0.001 0.001 0.001</scale>
					</mesh>
				</geometry>
			</visual>
		</link>
		<link name="lower_arm_right">
			<self_collide>false</self_collide>
			<pose frame="">-0.07635580135651482 -0.2606074457918556 0.9072943878636442 0.0 -0.0 0.0</pose>
			<inertial>
				<pose frame="">0.0 0.0 0.0 0 0 0</pose>
				<mass>0.11563812960698239</mass>
				<inertia>
					<ixx>0.10413035635086126</ixx>
					<ixy>-0.0022876298417135806</ixy>
					<ixz>0.00807549502960945</ixz>
					<iyy>0.0969093286463594</iyy>
					<iyz>0.02712954036071114</iyz>
					<izz>0.008600493016073277</izz>
				</inertia>
			</inertial>
			<collision name="lower_arm_right_collision">
				<geometry>
					<mesh>
						<uri>model://human/meshes/CAD/lower_arm_right.stl</uri>
						<scale>0.001 0.001 0.001</scale>
					</mesh>
				</geometry>
			</collision>
			<visual name="lower_arm_right_visual">
				<geometry>
					<mesh>
						<uri>model://human/meshes/CAD/lower_arm_right.stl</uri>
						<scale>0.001 0.001 0.001</scale>
					</mesh>
				</geometry>
			</visual>
		</link>
		<link name="hand_right">
			<self_collide>false</self_collide>
			<pose frame="">-0.07390821053699402 -0.2580229997934706 0.8690191311766218 0.0 -0.0 0.0</pose>
			<inertial>
				<pose frame="">0.0 0.0 0.0 0 0 0</pose>
				<mass>0.016515273339096425</mass>
				<inertia>
					<ixx>0.013572472574863216</ixx>
					<ixy>-0.00031494651869864033</ixy>
					<ixz>0.0010607371815798481</ixz>
					<iyy>0.012562723115436644</iyy>
					<iyz>0.0037031688885040505</iyz>
					<izz>0.0011904467104510204</izz>
				</inertia>
			</inertial>
			<collision name="hand_right_collision">
				<geometry>
					<mesh>
						<uri>model://human/meshes/CAD/hand_right.stl</uri>
						<scale>0.001 0.001 0.001</scale>
					</mesh>
				</geometry>
			</collision>
			<visual name="hand_right_visual">
				<geometry>
					<mesh>
						<uri>model://human/meshes/CAD/hand_right.stl</uri>
						<scale>0.001 0.001 0.001</scale>
					</mesh>
				</geometry>
			</visual>
		</link>
		<link name="upper_arm_left">
			<self_collide>false</self_collide>
			<pose frame="">-0.08717470546825411 0.21823977123845217 1.1745802559303062 0.0 -0.0 0.0</pose>
			<inertial>
				<pose frame="">0.0 0.0 0.0 0 0 0</pose>
				<mass>0.11563824901099111</mass>
				<inertia>
					<ixx>0.1660621014957003</ixx>
					<ixy>0.002210870816702614</ixy>
					<ixz>0.011743909438453782</ixz>
					<iyy>0.16142946389076454</iyy>
					<iyz>-0.029533246724778164</iyz>
					<izz>0.006432229009918701</izz>
				</inertia>
			</inertial>
			<collision name="upper_arm_left_collision">
				<geometry>
					<mesh>
						<uri>model://human/meshes/CAD/upper_arm_left.stl</uri>
						<scale>0.001 0.001 0.001</scale>
					</mesh>
				</geometry>
			</collision>
			<visual name="upper_arm_left_visual">
				<geometry>
					<mesh>
						<uri>model://human/meshes/CAD/upper_arm_left.stl</uri>
						<scale>0.001 0.001 0.001</scale>
					</mesh>
				</geometry>
			</visual>
		</link>
		<link name="lower_arm_left">
			<self_collide>false</self_collide>
			<pose frame="">-0.07631589802050388 0.2629542698654215 0.9072943480875546 0.0 -0.0 0.0</pose>
			<inertial>
				<pose frame="">0.0 0.0 0.0 0 0 0</pose>
				<mass>0.11563824901099107</mass>
				<inertia>
					<ixx>0.10424523959588604</ixx>
					<ixy>0.002312211025013143</ixy>
					<ixz>0.008071490566386692</ixz>
					<iyy>0.09690873707603764</iyy>
					<iyz>-0.027456192850749433</iyz>
					<izz>0.008714604445452322</izz>
				</inertia>
			</inertial>
			<collision name="lower_arm_left_collision">
				<geometry>
					<mesh>
						<uri>model://human/meshes/CAD/lower_arm_left.stl</uri>
						<scale>0.001 0.001 0.001</scale>
					</mesh>
				</geometry>
			</collision>
			<visual name="lower_arm_left_visual">
				<geometry>
					<mesh>
						<uri>model://human/meshes/CAD/lower_arm_left.stl</uri>
						<scale>0.001 0.001 0.001</scale>
					</mesh>
				</geometry>
			</visual>
		</link>
		<link name="hand_left">
			<self_collide>false</self_collide>
			<pose frame="">-0.07390765964322638 0.2785351914650082 0.8690191311766107 0.0 -0.0 0.0</pose>
			<inertial>
				<pose frame="">0.0 0.0 0.0 0 0 0</pose>
				<mass>0.016515273339096418</mass>
				<inertia>
					<ixx>0.013754239416619135</ixx>
					<ixy>0.0003399814589991392</ixy>
					<ixz>0.001060729267219654</ixz>
					<iyy>0.01256272177058372</iyy>
					<iyz>-0.003997561751552262</iyz>
					<izz>0.0013722122073546446</izz>
				</inertia>
			</inertial>
			<collision name="hand_left_collision">
				<geometry>
					<mesh>
						<uri>model://human/meshes/CAD/hand_left.stl</uri>
						<scale>0.001 0.001 0.001</scale>
					</mesh>
				</geometry>
			</collision>
			<visual name="hand_left_visual">
				<geometry>
					<mesh>
						<uri>model://human/meshes/CAD/hand_left.stl</uri>
						<scale>0.001 0.001 0.001</scale>
					</mesh>
				</geometry>
			</visual>
		</link>
		<link name="upper_leg_left">
			<self_collide>false</self_collide>
			<pose frame="">-0.01313261193600612 0.10302395074266876 0.7422509952926534 0.0 -0.0 0.0</pose>
			<inertial>
				<pose frame="">0.0 0.0 0.0 0 0 0</pose>
				<mass>63.327063452882214</mass>
				<inertia>
					<ixx>36.59708763100575</ixx>
					<ixy>0.07864927483042089</ixy>
					<ixz>0.6465844760015084</ixz>
					<iyy>35.99210955906033</iyy>
					<iyz>-4.850839364633525</iyz>
					<izz>0.8769769602564103</izz>
				</inertia>
			</inertial>
			<collision name="upper_leg_left_collision">
				<geometry>
					<mesh>
						<uri>model://human/meshes/CAD/upper_leg_left.stl</uri>
						<scale>0.001 0.001 0.001</scale>
					</mesh>
				</geometry>
			</collision>
			<visual name="upper_leg_left_visual">
				<geometry>
					<mesh>
						<uri>model://human/meshes/CAD/upper_leg_left.stl</uri>
						<scale>0.001 0.001 0.001</scale>
					</mesh>
				</geometry>
			</visual>
		</link>
		<link name="lower_leg_left">
			<self_collide>false</self_collide>
			<pose frame="">-0.036757247389456314 0.10835573009133771 0.3188134062107464 0.0 -0.0 0.0</pose>
			<inertial>
				<pose frame="">0.0 0.0 0.0 0 0 0</pose>
				<mass>28.437794540823703</mass>
				<inertia>
					<ixx>3.561777041857225</ixx>
					<ixy>0.11136513861545078</ixy>
					<ixz>0.3321020564506139</ixz>
					<iyy>3.2777177543993656</iyy>
					<iyz>-0.9718949476287635</iyz>
					<izz>0.4200171804909315</izz>
				</inertia>
			</inertial>
			<collision name="lower_leg_left_collision">
				<geometry>
					<mesh>
						<uri>model://human/meshes/CAD/lower_leg_left.stl</uri>
						<scale>0.001 0.001 0.001</scale>
					</mesh>
				</geometry>
			</collision>
			<visual name="lower_leg_left_visual">
				<geometry>
					<mesh>
						<uri>model://human/meshes/CAD/lower_leg_left.stl</uri>
						<scale>0.001 0.001 0.001</scale>
					</mesh>
				</geometry>
			</visual>
		</link>
		<link name="foot_left">
			<self_collide>false</self_collide>
			<pose frame="">-0.019999983728375827 0.11678337391546194 0.10993444486070426 0.0 -0.0 0.0</pose>
			<inertial>
				<pose frame="">0.0 0.0 0.0 0 0 0</pose>
				<mass>0.2795712981996832</mass>
				<inertia>
					<ixx>0.0072375160595865885</ixx>
					<ixy>0.0006529850351768169</ixy>
					<ixz>0.0006146897112867678</ixz>
					<iyy>0.0035358522477641806</iyy>
					<iyz>-0.003590489261675837</iyz>
					<izz>0.0039676798641976865</izz>
				</inertia>
			</inertial>
			<collision name="foot_left_collision">
				<geometry>
					<mesh>
						<uri>model://human/meshes/CAD/foot_left.stl</uri>
						<scale>0.001 0.001 0.001</scale>
					</mesh>
				</geometry>
			</collision>
			<visual name="foot_left_visual">
				<geometry>
					<mesh>
						<uri>model://human/meshes/CAD/foot_left.stl</uri>
						<scale>0.001 0.001 0.001</scale>
					</mesh>
				</geometry>
			</visual>
		</link>
		<link name="head">
			<self_collide>false</self_collide>
			<pose frame="">-0.01669789662623107 -0.0031270906408858074 1.6542288225550017 0.0 -0.0 0.0</pose>
			<inertial>
				<pose frame="">0.0 0.0 0.0 0 0 0</pose>
				<mass>35.906365546354735</mass>
				<inertia>
					<ixx>98.401575412207</ixx>
					<ixy>-0.001812539786147447</ixy>
					<ixz>1.0198764831213671</ixz>
					<iyy>98.46428610030586</iyy>
					<iyz>0.185543101788184</iyz>
					<izz>0.16733682760579505</izz>
				</inertia>
			</inertial>
			<collision name="head_collision">
				<geometry>
					<mesh>
						<uri>model://human/meshes/CAD/head.stl</uri>
						<scale>0.001 0.001 0.001</scale>
					</mesh>
				</geometry>
			</collision>
			<visual name="head_visual">
				<geometry>
					<mesh>
						<uri>model://human/meshes/CAD/head.stl</uri>
						<scale>0.001 0.001 0.001</scale>
					</mesh>
				</geometry>
			</visual>
		</link>
		<link name="motor3">
			<self_collide>false</self_collide>
			<pose frame="">-1.4838021873254814 -1.2342394028102621 0.01051655894117484 0.0 -0.0 0.0</pose>
			<inertial>
				<pose frame="">0.0 0.0 0.0 0 0 0</pose>
				<mass>0.5407289156586891</mass>
				<inertia>
					<ixx>0.8239519347007563</ixx>
					<ixy>-0.9902621278821997</ixy>
					<ixz>0.008437545456538848</ixz>
					<iyy>1.1908347538526611</iyy>
					<iyz>0.007018743074075354</iyz>
					<izz>2.0145909271886877</izz>
				</inertia>
			</inertial>
			<collision name="motor3_collision">
				<geometry>
					<mesh>
						<uri>model://human/meshes/CAD/motor3.stl</uri>
						<scale>0.001 0.001 0.001</scale>
					</mesh>
				</geometry>
			</collision>
			<visual name="motor3_visual">
				<geometry>
					<mesh>
						<uri>model://human/meshes/CAD/motor3.stl</uri>
						<scale>0.001 0.001 0.001</scale>
					</mesh>
				</geometry>
			</visual>
		</link>
		<link name="motor2">
			<self_collide>false</self_collide>
			<pose frame="">-1.485334311593426 1.2358101926090346 0.010485803664418522 0.0 -0.0 0.0</pose>
			<inertial>
				<pose frame="">0.0 0.0 0.0 0 0 0</pose>
				<mass>0.5915184316952449</mass>
				<inertia>
					<ixx>0.9036405133260113</ixx>
					<ixy>1.0857914520512877</ixy>
					<ixz>0.009213108679123352</ixz>
					<iyy>1.3053863599243112</iyy>
					<iyz>-0.007665084014776147</iyz>
					<izz>2.2088188733016993</izz>
				</inertia>
			</inertial>
			<collision name="motor2_collision">
				<geometry>
					<mesh>
						<uri>model://human/meshes/CAD/motor2.stl</uri>
						<scale>0.001 0.001 0.001</scale>
					</mesh>
				</geometry>
			</collision>
			<visual name="motor2_visual">
				<geometry>
					<mesh>
						<uri>model://human/meshes/CAD/motor2.stl</uri>
						<scale>0.001 0.001 0.001</scale>
					</mesh>
				</geometry>
			</visual>
		</link>
		<link name="motor0">
			<self_collide>false</self_collide>
			<pose frame="">1.4853343115934643 1.2358101926090335 0.01051419634034889 0.0 -0.0 0.0</pose>
			<inertial>
				<pose frame="">0.0 0.0 0.0 0 0 0</pose>
				<mass>0.5915184316951642</mass>
				<inertia>
					<ixx>0.9036408660165021</ixx>
					<ixy>-1.0857914520511684</ixy>
					<ixz>-0.009237546389943497</ixz>
					<iyy>1.305386712614818</iyy>
					<iyz>-0.007686010628829871</iyz>
					<izz>2.2088188733014675</izz>
				</inertia>
			</inertial>
			<collision name="motor0_collision">
				<geometry>
					<mesh>
						<uri>model://human/meshes/CAD/motor0.stl</uri>
						<scale>0.001 0.001 0.001</scale>
					</mesh>
				</geometry>
			</collision>
			<visual name="motor0_visual">
				<geometry>
					<mesh>
						<uri>model://human/meshes/CAD/motor0.stl</uri>
						<scale>0.001 0.001 0.001</scale>
					</mesh>
				</geometry>
			</visual>
		</link>
		<link name="motor4">
			<self_collide>false</self_collide>
			<pose frame="">-1.2358101829513672 1.485334301546107 0.01051419449950688 0.0 -0.0 0.0</pose>
			<inertial>
				<pose frame="">0.0 0.0 0.0 0 0 0</pose>
				<mass>0.5915182656349381</mass>
				<inertia>
					<ixx>1.3053863288187992</ixx>
					<ixy>1.085791131455688</ixy>
					<ixz>0.007686007040985962</ixz>
					<iyy>0.9036405981034654</iyy>
					<iyz>-0.009237542099685631</iyz>
					<izz>2.2088182216814296</izz>
				</inertia>
			</inertial>
			<collision name="motor4_collision">
				<geometry>
					<mesh>
						<uri>model://human/meshes/CAD/motor4.stl</uri>
						<scale>0.001 0.001 0.001</scale>
					</mesh>
				</geometry>
			</collision>
			<visual name="motor4_visual">
				<geometry>
					<mesh>
						<uri>model://human/meshes/CAD/motor4.stl</uri>
						<scale>0.001 0.001 0.001</scale>
					</mesh>
				</geometry>
			</visual>
		</link>
		<link name="motor5">
			<self_collide>false</self_collide>
			<pose frame="">1.2358101926090344 1.4853343115934126 0.010485803664418505 0.0 -0.0 0.0</pose>
			<inertial>
				<pose frame="">0.0 0.0 0.0 0 0 0</pose>
				<mass>0.5915184316952438</mass>
				<inertia>
					<ixx>1.3053863599242819</ixx>
					<ixy>-1.0857914520512741</ixy>
					<ixz>-0.007665084014776132</ixz>
					<iyy>0.9036405133260096</iyy>
					<iyz>-0.009213108679123314</iyz>
					<izz>2.2088188733016674</izz>
				</inertia>
			</inertial>
			<collision name="motor5_collision">
				<geometry>
					<mesh>
						<uri>model://human/meshes/CAD/motor5.stl</uri>
						<scale>0.001 0.001 0.001</scale>
					</mesh>
				</geometry>
			</collision>
			<visual name="motor5_visual">
				<geometry>
					<mesh>
						<uri>model://human/meshes/CAD/motor5.stl</uri>
						<scale>0.001 0.001 0.001</scale>
					</mesh>
				</geometry>
			</visual>
		</link>
		<link name="motor6">
			<self_collide>false</self_collide>
			<pose frame="">-1.2358101829513677 -1.4853343018224894 0.01048580550527066 0.0 -0.0 0.0</pose>
			<inertial>
				<pose frame="">0.0 0.0 0.0 0 0 0</pose>
				<mass>0.5915182656350185</mass>
				<inertia>
					<ixx>1.3053859761740971</ixx>
					<ixy>-1.0857911314557949</ixy>
					<ixz>0.007665083173063848</ixz>
					<iyy>0.9036402454588066</iyy>
					<iyz>0.009213107668262954</iyz>
					<izz>2.2088182216816317</izz>
				</inertia>
			</inertial>
			<collision name="motor6_collision">
				<geometry>
					<mesh>
						<uri>model://human/meshes/CAD/motor6.stl</uri>
						<scale>0.001 0.001 0.001</scale>
					</mesh>
				</geometry>
			</collision>
			<visual name="motor6_visual">
				<geometry>
					<mesh>
						<uri>model://human/meshes/CAD/motor6.stl</uri>
						<scale>0.001 0.001 0.001</scale>
					</mesh>
				</geometry>
			</visual>
		</link>
		<link name="motor1">
			<self_collide>false</self_collide>
			<pose frame="">1.4853343015460536 -1.2358101829513677 0.010485805505270663 0.0 -0.0 0.0</pose>
			<inertial>
				<pose frame="">0.0 0.0 0.0 0 0 0</pose>
				<mass>0.5915182656350185</mass>
				<inertia>
					<ixx>0.9036402454588068</ixx>
					<ixy>1.0857911314557955</ixy>
					<ixz>-0.009213107668262955</ixz>
					<iyy>1.3053859761740987</iyy>
					<iyz>0.007665083173063846</iyz>
					<izz>2.208818221681633</izz>
				</inertia>
			</inertial>
			<collision name="motor1_collision">
				<geometry>
					<mesh>
						<uri>model://human/meshes/CAD/motor1.stl</uri>
						<scale>0.001 0.001 0.001</scale>
					</mesh>
				</geometry>
			</collision>
			<visual name="motor1_visual">
				<geometry>
					<mesh>
						<uri>model://human/meshes/CAD/motor1.stl</uri>
						<scale>0.001 0.001 0.001</scale>
					</mesh>
				</geometry>
			</visual>
		</link>
		<link name="motor10">
			<self_collide>false</self_collide>
			<pose frame="">-1.483802186329325 1.2342394009707196 1.0104834407810215 0.0 -0.0 0.0</pose>
			<inertial>
				<pose frame="">0.0 0.0 0.0 0 0 0</pose>
				<mass>0.5407288092535038</mass>
				<inertia>
					<ixx>1.3760176002125752</ixx>
					<ixy>0.99026193086944</ixy>
					<ixz>0.8107460717445298</ixz>
					<iyy>1.7429003480577039</iyy>
					<iyz>-0.6743852245854303</iyz>
					<izz>2.0145905267549784</izz>
				</inertia>
			</inertial>
			<collision name="motor10_collision">
				<geometry>
					<mesh>
						<uri>model://human/meshes/CAD/motor10.stl</uri>
						<scale>0.001 0.001 0.001</scale>
					</mesh>
				</geometry>
			</collision>
			<visual name="motor10_visual">
				<geometry>
					<mesh>
						<uri>model://human/meshes/CAD/motor10.stl</uri>
						<scale>0.001 0.001 0.001</scale>
					</mesh>
				</geometry>
			</visual>
		</link>
		<link name="motor8">
			<self_collide>false</self_collide>
			<pose frame="">1.4838021863293247 1.2342394009707207 1.010516559218978 0.0 -0.0 0.0</pose>
			<inertial>
				<pose frame="">0.0 0.0 0.0 0 0 0</pose>
				<mass>0.5407288092534246</mass>
				<inertia>
					<ixx>1.3760537924693779</ixx>
					<ixy>-0.9902619308692957</ixy>
					<ixz>-0.8107721333955696</ixz>
					<iyy>1.7429365403144546</iyy>
					<iyz>-0.6744075434898156</iyz>
					<izz>2.014590526754685</izz>
				</inertia>
			</inertial>
			<collision name="motor8_collision">
				<geometry>
					<mesh>
						<uri>model://human/meshes/CAD/motor8.stl</uri>
						<scale>0.001 0.001 0.001</scale>
					</mesh>
				</geometry>
			</collision>
			<visual name="motor8_visual">
				<geometry>
					<mesh>
						<uri>model://human/meshes/CAD/motor8.stl</uri>
						<scale>0.001 0.001 0.001</scale>
					</mesh>
				</geometry>
			</visual>
		</link>
		<link name="motor12">
			<self_collide>false</self_collide>
			<pose frame="">-1.234239402810263 1.4838021873254785 1.010516558941175 0.0 -0.0 0.0</pose>
			<inertial>
				<pose frame="">0.0 0.0 0.0 0 0 0</pose>
				<mass>0.5407289156586891</mass>
				<inertia>
					<ixx>1.7429368845367943</ixx>
					<ixy>0.9902621278821994</ixy>
					<ixz>0.6744076770188963</ixz>
					<iyy>1.3760540653848898</iyy>
					<iyz>-0.810772293261037</iyz>
					<izz>2.0145909271886873</izz>
				</inertia>
			</inertial>
			<collision name="motor12_collision">
				<geometry>
					<mesh>
						<uri>model://human/meshes/CAD/motor12.stl</uri>
						<scale>0.001 0.001 0.001</scale>
					</mesh>
				</geometry>
			</collision>
			<visual name="motor12_visual">
				<geometry>
					<mesh>
						<uri>model://human/meshes/CAD/motor12.stl</uri>
						<scale>0.001 0.001 0.001</scale>
					</mesh>
				</geometry>
			</visual>
		</link>
		<link name="motor13">
			<self_collide>false</self_collide>
			<pose frame="">1.2342394009707198 1.4838021863293254 1.0104834407810217 0.0 -0.0 0.0</pose>
			<inertial>
				<pose frame="">0.0 0.0 0.0 0 0 0</pose>
				<mass>0.5407288092535051</mass>
				<inertia>
					<ixx>1.7429003480577074</ixx>
					<ixy>-0.9902619308694421</ixy>
					<ixz>-0.6743852245854316</ixz>
					<iyy>1.3760176002125781</iyy>
					<iyz>-0.8107460717445316</iyz>
					<izz>2.0145905267549824</izz>
				</inertia>
			</inertial>
			<collision name="motor13_collision">
				<geometry>
					<mesh>
						<uri>model://human/meshes/CAD/motor13.stl</uri>
						<scale>0.001 0.001 0.001</scale>
					</mesh>
				</geometry>
			</collision>
			<visual name="motor13_visual">
				<geometry>
					<mesh>
						<uri>model://human/meshes/CAD/motor13.stl</uri>
						<scale>0.001 0.001 0.001</scale>
					</mesh>
				</geometry>
			</visual>
		</link>
		<link name="motor14">
			<self_collide>false</self_collide>
			<pose frame="">-1.234239402810262 -1.4838021873254785 1.0104834410588253 0.0 -0.0 0.0</pose>
			<inertial>
				<pose frame="">0.0 0.0 0.0 0 0 0</pose>
				<mass>0.5407289156587678</mass>
				<inertia>
					<ixx>1.742900692880094</ixx>
					<ixy>-0.9902621278823432</ixy>
					<ixz>0.6743853584836851</ixz>
					<iyy>1.3760178737281379</iyy>
					<iyz>0.8107462320519715</iyz>
					<izz>2.0145909271889795</izz>
				</inertia>
			</inertial>
			<collision name="motor14_collision">
				<geometry>
					<mesh>
						<uri>model://human/meshes/CAD/motor14.stl</uri>
						<scale>0.001 0.001 0.001</scale>
					</mesh>
				</geometry>
			</collision>
			<visual name="motor14_visual">
				<geometry>
					<mesh>
						<uri>model://human/meshes/CAD/motor14.stl</uri>
						<scale>0.001 0.001 0.001</scale>
					</mesh>
				</geometry>
			</visual>
		</link>
		<link name="motor15">
			<self_collide>false</self_collide>
			<pose frame="">1.2342394009707207 -1.483802186329324 1.010516559218978 0.0 -0.0 0.0</pose>
			<inertial>
				<pose frame="">0.0 0.0 0.0 0 0 0</pose>
				<mass>0.5407288092534249</mass>
				<inertia>
					<ixx>1.7429365403144548</ixx>
					<ixy>0.9902619308692958</ixy>
					<ixz>-0.6744075434898158</ixz>
					<iyy>1.376053792469379</iyy>
					<iyz>0.81077213339557</iyz>
					<izz>2.0145905267546853</izz>
				</inertia>
			</inertial>
			<collision name="motor15_collision">
				<geometry>
					<mesh>
						<uri>model://human/meshes/CAD/motor15.stl</uri>
						<scale>0.001 0.001 0.001</scale>
					</mesh>
				</geometry>
			</collision>
			<visual name="motor15_visual">
				<geometry>
					<mesh>
						<uri>model://human/meshes/CAD/motor15.stl</uri>
						<scale>0.001 0.001 0.001</scale>
					</mesh>
				</geometry>
			</visual>
		</link>
		<link name="motor9">
			<self_collide>false</self_collide>
			<pose frame="">1.4853343018224885 -1.2358101829513672 1.0104858057327721 0.0 -0.0 0.0</pose>
			<inertial>
				<pose frame="">0.0 0.0 0.0 0 0 0</pose>
				<mass>0.5915182656350185</mass>
				<inertia>
					<ixx>1.5075636020635315</ixx>
					<ixy>1.085791131251597</ixy>
					<ixz>-0.8878154774061241</ixz>
					<iyy>1.909309332296448</iyy>
					<iyz>0.7386693790802477</iyz>
					<izz>2.2088182211992584</izz>
				</inertia>
			</inertial>
			<collision name="motor9_collision">
				<geometry>
					<mesh>
						<uri>model://human/meshes/CAD/motor9.stl</uri>
						<scale>0.001 0.001 0.001</scale>
					</mesh>
				</geometry>
			</collision>
			<visual name="motor9_visual">
				<geometry>
					<mesh>
						<uri>model://human/meshes/CAD/motor9.stl</uri>
						<scale>0.001 0.001 0.001</scale>
					</mesh>
				</geometry>
			</visual>
		</link>
		<link name="motor19">
			<self_collide>false</self_collide>
			<pose frame="">-1.483802187325481 -1.2342394028102615 2.010516558941175 0.0 -0.0 0.0</pose>
			<inertial>
				<pose frame="">0.0 0.0 0.0 0 0 0</pose>
				<mass>0.5407289156586891</mass>
				<inertia>
					<ixx>3.009614027386401</ixx>
					<ixy>-0.9902621278821997</ixy>
					<ixz>1.6131070410655353</ixz>
					<iyy>3.3764968465383065</iyy>
					<iyz>1.3417966109637172</iyz>
					<izz>2.0145909271886877</izz>
				</inertia>
			</inertial>
			<collision name="motor19_collision">
				<geometry>
					<mesh>
						<uri>model://human/meshes/CAD/motor19.stl</uri>
						<scale>0.001 0.001 0.001</scale>
					</mesh>
				</geometry>
			</collision>
			<visual name="motor19_visual">
				<geometry>
					<mesh>
						<uri>model://human/meshes/CAD/motor19.stl</uri>
						<scale>0.001 0.001 0.001</scale>
					</mesh>
				</geometry>
			</visual>
		</link>
		<link name="motor18">
			<self_collide>false</self_collide>
			<pose frame="">-1.483802186329323 1.2342394009707196 2.0104834407810213 0.0 -0.0 0.0</pose>
			<inertial>
				<pose frame="">0.0 0.0 0.0 0 0 0</pose>
				<mass>0.5407288092535049</mass>
				<inertia>
					<ixx>3.009541424873896</ixx>
					<ixy>0.9902619308694421</ixy>
					<ixz>1.6130806611261352</ixz>
					<iyy>3.3764241727190254</iyy>
					<iyz>-1.3417740262060884</iyz>
					<izz>2.0145905267549824</izz>
				</inertia>
			</inertial>
			<collision name="motor18_collision">
				<geometry>
					<mesh>
						<uri>model://human/meshes/CAD/motor18.stl</uri>
						<scale>0.001 0.001 0.001</scale>
					</mesh>
				</geometry>
			</collision>
			<visual name="motor18_visual">
				<geometry>
					<mesh>
						<uri>model://human/meshes/CAD/motor18.stl</uri>
						<scale>0.001 0.001 0.001</scale>
					</mesh>
				</geometry>
			</visual>
		</link>
		<link name="motor16">
			<self_collide>false</self_collide>
			<pose frame="">1.483802186329327 1.2342394009707198 2.010516559218978 0.0 -0.0 0.0</pose>
			<inertial>
				<pose frame="">0.0 0.0 0.0 0 0 0</pose>
				<mass>0.5407288092534246</mass>
				<inertia>
					<ixx>3.0096134333174938</ixx>
					<ixy>-0.9902619308692957</ixy>
					<ixz>-1.6131067227770544</ixz>
					<iyy>3.3764961811625707</iyy>
					<iyz>-1.3417963451103734</iyz>
					<izz>2.014590526754685</izz>
				</inertia>
			</inertial>
			<collision name="motor16_collision">
				<geometry>
					<mesh>
						<uri>model://human/meshes/CAD/motor16.stl</uri>
						<scale>0.001 0.001 0.001</scale>
					</mesh>
				</geometry>
			</collision>
			<visual name="motor16_visual">
				<geometry>
					<mesh>
						<uri>model://human/meshes/CAD/motor16.stl</uri>
						<scale>0.001 0.001 0.001</scale>
					</mesh>
				</geometry>
			</visual>
		</link>
		<link name="motor20">
			<self_collide>false</self_collide>
			<pose frame="">-1.2342394028102615 1.483802187325481 2.010516558941175 0.0 -0.0 0.0</pose>
			<inertial>
				<pose frame="">0.0 0.0 0.0 0 0 0</pose>
				<mass>0.540728915658689</mass>
				<inertia>
					<ixx>3.3764968465383056</ixx>
					<ixy>0.9902621278821991</ixy>
					<ixz>1.3417966109637167</ixz>
					<iyy>3.0096140273864003</iyy>
					<iyz>-1.613107041065535</iyz>
					<izz>2.0145909271886864</izz>
				</inertia>
			</inertial>
			<collision name="motor20_collision">
				<geometry>
					<mesh>
						<uri>model://human/meshes/CAD/motor20.stl</uri>
						<scale>0.001 0.001 0.001</scale>
					</mesh>
				</geometry>
			</collision>
			<visual name="motor20_visual">
				<geometry>
					<mesh>
						<uri>model://human/meshes/CAD/motor20.stl</uri>
						<scale>0.001 0.001 0.001</scale>
					</mesh>
				</geometry>
			</visual>
		</link>
		<link name="motor21">
			<self_collide>false</self_collide>
			<pose frame="">1.2342394009707203 1.483802186329324 2.0104834407810213 0.0 -0.0 0.0</pose>
			<inertial>
				<pose frame="">0.0 0.0 0.0 0 0 0</pose>
				<mass>0.540728809253504</mass>
				<inertia>
					<ixx>3.3764241727190205</ixx>
					<ixy>-0.9902619308694405</ixy>
					<ixz>-1.3417740262060864</ixz>
					<iyy>3.009541424873891</iyy>
					<iyz>-1.6130806611261326</iyz>
					<izz>2.0145905267549797</izz>
				</inertia>
			</inertial>
			<collision name="motor21_collision">
				<geometry>
					<mesh>
						<uri>model://human/meshes/CAD/motor21.stl</uri>
						<scale>0.001 0.001 0.001</scale>
					</mesh>
				</geometry>
			</collision>
			<visual name="motor21_visual">
				<geometry>
					<mesh>
						<uri>model://human/meshes/CAD/motor21.stl</uri>
						<scale>0.001 0.001 0.001</scale>
					</mesh>
				</geometry>
			</visual>
		</link>
		<link name="motor22">
			<self_collide>false</self_collide>
			<pose frame="">-1.2342394028102621 -1.4838021873254774 2.0104834410588244 0.0 -0.0 0.0</pose>
			<inertial>
				<pose frame="">0.0 0.0 0.0 0 0 0</pose>
				<mass>0.5407289156587689</mass>
				<inertia>
					<ixx>3.376424839288627</ixx>
					<ixy>-0.9902621278823452</ixy>
					<ixz>1.3417742924286062</ixz>
					<iyy>3.00954202013667</iyy>
					<iyz>1.6130809798565893</iyz>
					<izz>2.0145909271889835</izz>
				</inertia>
			</inertial>
			<collision name="motor22_collision">
				<geometry>
					<mesh>
						<uri>model://human/meshes/CAD/motor22.stl</uri>
						<scale>0.001 0.001 0.001</scale>
					</mesh>
				</geometry>
			</collision>
			<visual name="motor22_visual">
				<geometry>
					<mesh>
						<uri>model://human/meshes/CAD/motor22.stl</uri>
						<scale>0.001 0.001 0.001</scale>
					</mesh>
				</geometry>
			</visual>
		</link>
		<link name="motor23">
			<self_collide>false</self_collide>
			<pose frame="">1.2342394009707196 -1.4838021863293265 2.0105165592189773 0.0 -0.0 0.0</pose>
			<inertial>
				<pose frame="">0.0 0.0 0.0 0 0 0</pose>
				<mass>0.5407288092534249</mass>
				<inertia>
					<ixx>3.376496181162572</ixx>
					<ixy>0.9902619308692958</ixy>
					<ixz>-1.3417963451103738</ixz>
					<iyy>3.0096134333174955</iyy>
					<iyz>1.6131067227770552</iyz>
					<izz>2.0145905267546853</izz>
				</inertia>
			</inertial>
			<collision name="motor23_collision">
				<geometry>
					<mesh>
						<uri>model://human/meshes/CAD/motor23.stl</uri>
						<scale>0.001 0.001 0.001</scale>
					</mesh>
				</geometry>
			</collision>
			<visual name="motor23_visual">
				<geometry>
					<mesh>
						<uri>model://human/meshes/CAD/motor23.stl</uri>
						<scale>0.001 0.001 0.001</scale>
					</mesh>
				</geometry>
			</visual>
		</link>
		<link name="motor17">
			<self_collide>false</self_collide>
			<pose frame="">1.4838021873254774 -1.2342394028102615 2.0104834410588235 0.0 -0.0 0.0</pose>
			<inertial>
				<pose frame="">0.0 0.0 0.0 0 0 0</pose>
				<mass>0.5407289156587689</mass>
				<inertia>
					<ixx>3.0095420201366694</ixx>
					<ixy>0.9902621278823456</ixy>
					<ixz>-1.6130809798565902</ixz>
					<iyy>3.376424839288629</iyy>
					<iyz>1.341774292428606</iyz>
					<izz>2.014590927188985</izz>
				</inertia>
			</inertial>
			<collision name="motor17_collision">
				<geometry>
					<mesh>
						<uri>model://human/meshes/CAD/motor17.stl</uri>
						<scale>0.001 0.001 0.001</scale>
					</mesh>
				</geometry>
			</collision>
			<visual name="motor17_visual">
				<geometry>
					<mesh>
						<uri>model://human/meshes/CAD/motor17.stl</uri>
						<scale>0.001 0.001 0.001</scale>
					</mesh>
				</geometry>
			</visual>
		</link>
		<link name="6dof_link4">
			<self_collide>false</self_collide>
			<pose frame="">0.042639659949809026 -7.101249734164418e-05 0.9999999999999923 0.0 -0.0 0.0</pose>
			<inertial>
				<pose frame="">0.0 0.0 0.0 0 0 0</pose>
				<mass>0.029253556048299417</mass>
				<inertia>
					<ixx>0.029253976989686226</ixx>
					<ixy>1.1626215438336713e-07</ixy>
					<ixz>-0.0012473616822221846</ixz>
					<iyy>0.0293174136030794</iyy>
					<iyz>2.077379146644587e-06</iyz>
					<izz>6.385696503560865e-05</izz>
				</inertia>
			</inertial>
			<collision name="6dof_link4_collision">
				<geometry>
					<mesh>
						<uri>model://human/meshes/CAD/6dof_link4.stl</uri>
						<scale>0.001 0.001 0.001</scale>
					</mesh>
				</geometry>
			</collision>
			<visual name="6dof_link4_visual">
				<geometry>
					<mesh>
						<uri>model://human/meshes/CAD/6dof_link4.stl</uri>
						<scale>0.001 0.001 0.001</scale>
					</mesh>
				</geometry>
			</visual>
		</link>
		<link name="6dof_link5">
			<self_collide>false</self_collide>
			<pose frame="">6.1008287956425485e-05 0.04260984108746041 0.9999999812294209 0.0 -0.0 0.0</pose>
			<inertial>
				<pose frame="">0.0 0.0 0.0 0 0 0</pose>
				<mass>0.029267161202751052</mass>
				<inertia>
					<ixx>0.029330975552184543</ixx>
					<ixy>-1.0360731338597083e-07</ixy>
					<ixz>-1.7800545179101354e-06</ixz>
					<iyy>0.029267568334721984</iyy>
					<iyz>-0.001247068788576186</iyz>
					<izz>6.382844100897486e-05</izz>
				</inertia>
			</inertial>
			<collision name="6dof_link5_collision">
				<geometry>
					<mesh>
						<uri>model://human/meshes/CAD/6dof_link5.stl</uri>
						<scale>0.001 0.001 0.001</scale>
					</mesh>
				</geometry>
			</collision>
			<visual name="6dof_link5_visual">
				<geometry>
					<mesh>
						<uri>model://human/meshes/CAD/6dof_link5.stl</uri>
						<scale>0.001 0.001 0.001</scale>
					</mesh>
				</geometry>
			</visual>
		</link>
		<link name="6dof_link1">
			<self_collide>false</self_collide>
			<pose frame="">-3.5510243406436533e-06 -1.0069391479243579e-05 0.9999999999999999 0.0 -0.0 0.0</pose>
			<inertial>
				<pose frame="">0.0 0.0 0.0 0 0 0</pose>
				<mass>0.03806502884740436</mass>
				<inertia>
					<ixx>0.03806670751903605</ixx>
					<ixy>-1.361078074833995e-12</ixy>
					<ixz>1.3516984396440834e-07</ixz>
					<iyy>0.038066707515656516</iyy>
					<iyz>3.8329167713316574e-07</iyz>
					<izz>1.6786721116758843e-06</izz>
				</inertia>
			</inertial>
			<collision name="6dof_link1_collision">
				<geometry>
					<mesh>
						<uri>model://human/meshes/CAD/6dof_link1.stl</uri>
						<scale>0.001 0.001 0.001</scale>
					</mesh>
				</geometry>
			</collision>
			<visual name="6dof_link1_visual">
				<geometry>
					<mesh>
						<uri>model://human/meshes/CAD/6dof_link1.stl</uri>
						<scale>0.001 0.001 0.001</scale>
					</mesh>
				</geometry>
			</visual>
		</link>
		<link name="6dof_link2">
			<self_collide>false</self_collide>
			<pose frame="">-3.551024340641647e-06 -1.0069391479245249e-05 0.9999999999999998 0.0 -0.0 0.0</pose>
			<inertial>
				<pose frame="">0.0 0.0 0.0 0 0 0</pose>
				<mass>0.0029963725331776064</mass>
				<inertia>
					<ixx>0.002996396804098933</ixx>
					<ixy>-1.0714025662895805e-13</ixy>
					<ixz>1.064019179894265e-08</ixz>
					<iyy>0.0029963968038329066</iyy>
					<iyz>3.017164805422385e-08</iyz>
					<izz>2.4270959112454043e-08</izz>
				</inertia>
			</inertial>
			<collision name="6dof_link2_collision">
				<geometry>
					<mesh>
						<uri>model://human/meshes/CAD/6dof_link2.stl</uri>
						<scale>0.001 0.001 0.001</scale>
					</mesh>
				</geometry>
			</collision>
			<visual name="6dof_link2_visual">
				<geometry>
					<mesh>
						<uri>model://human/meshes/CAD/6dof_link2.stl</uri>
						<scale>0.001 0.001 0.001</scale>
					</mesh>
				</geometry>
			</visual>
		</link>
		<link name="6dof_link3">
			<self_collide>false</self_collide>
			<pose frame="">-3.3130953811449347e-06 -1.0358420894244247e-05 1.010729363507488 0.0 -0.0 0.0</pose>
			<inertial>
				<pose frame="">0.0 0.0 0.0 0 0 0</pose>
				<mass>0.015709236754408065</mass>
				<inertia>
					<ixx>0.016048786465636584</ixx>
					<ixy>3.398942377017531e-12</ixy>
					<ixz>5.256991621185631e-08</ixz>
					<iyy>0.016048779040639085</iyy>
					<iyz>1.6451093000258178e-07</iyz>
					<izz>2.606891529664852e-07</izz>
				</inertia>
			</inertial>
			<collision name="6dof_link3_collision">
				<geometry>
					<mesh>
						<uri>model://human/meshes/CAD/6dof_link3.stl</uri>
						<scale>0.001 0.001 0.001</scale>
					</mesh>
				</geometry>
			</collision>
			<visual name="6dof_link3_visual">
				<geometry>
					<mesh>
						<uri>model://human/meshes/CAD/6dof_link3.stl</uri>
						<scale>0.001 0.001 0.001</scale>
					</mesh>
				</geometry>
			</visual>
		</link>
		<joint name="foot_left_axis0" type="revolute">
			<parent>lower_leg_left</parent>
			<child>foot_left_link1</child>
			<pose frame="">-4.440892098500626e-18 0.0 3.552713678800501e-17 0 0 0</pose>
			<axis>
				<xyz>-1.249000902703301e-16 1.0000000000000007 -6.123233995736834e-17</xyz>
				<limit>
					<lower>-3.141592653589793</lower>
					<upper>3.141592653589793</upper>
				</limit>
				<use_parent_model_frame>0</use_parent_model_frame>
			</axis>
		</joint>
		<joint name="foot_left_axis2" type="revolute">
			<parent>foot_left_link2</parent>
			<child>foot_left</child>
			<pose frame="">-1.627162899309198e-08 0.005843630422901445 0.0015305307358121922 0 0 0</pose>
			<axis>
				<xyz>1.374594882364021e-14 4.545133944160017e-31 0.9999999999999998</xyz>
				<limit>
					<lower>-3.141592653589793</lower>
					<upper>3.141592653589793</upper>
				</limit>
				<use_parent_model_frame>0</use_parent_model_frame>
			</axis>
		</joint>
		<joint name="foot_left_axis1" type="revolute">
			<parent>foot_left_link1</parent>
			<child>foot_left_link2</child>
			<pose frame="">8.881784197001253e-18 -7.105427357601002e-17 -1.5987211554602254e-16 0 0 0</pose>
			<axis>
				<xyz>1.0 8.326672684688674e-17 -1.374594882364021e-14</xyz>
				<limit>
					<lower>-3.141592653589793</lower>
					<upper>3.141592653589793</upper>
				</limit>
				<use_parent_model_frame>0</use_parent_model_frame>
			</axis>
		</joint>
		<joint name="knee_left_axis0" type="revolute">
			<parent>upper_leg_left</parent>
			<child>knee_left_link1</child>
			<pose frame="">-8.881784197001253e-18 -6.572520305780927e-16 9.237055564881303e-16 0 0 0</pose>
			<axis>
				<xyz>2.7755575615628914e-16 0.9999999999999994 -1.9598976533927307e-17</xyz>
				<limit>
					<lower>-3.141592653589793</lower>
					<upper>3.141592653589793</upper>
				</limit>
				<use_parent_model_frame>0</use_parent_model_frame>
			</axis>
		</joint>
		<joint name="knee_left_axis2" type="revolute">
			<parent>knee_left_link2</parent>
			<child>lower_leg_left</child>
			<pose frame="">0.01632705822429243 0.0010605694170556035 0.14667072155650548 0 0 0</pose>
			<axis>
				<xyz>1.3767600013708993e-14 -2.9170238954269154e-17 0.9999999999999998</xyz>
				<limit>
					<lower>-3.141592653589793</lower>
					<upper>3.141592653589793</upper>
				</limit>
				<use_parent_model_frame>0</use_parent_model_frame>
			</axis>
		</joint>
		<joint name="knee_left_axis1" type="revolute">
			<parent>knee_left_link1</parent>
			<child>knee_left_link2</child>
			<pose frame="">-4.440892098500626e-18 5.151434834260726e-16 -8.526512829121202e-16 0 0 0</pose>
			<axis>
				<xyz>0.9999999999999999 -9.71445146547012e-17 -1.3732071035832395e-14</xyz>
				<limit>
					<lower>-3.141592653589793</lower>
					<upper>3.141592653589793</upper>
				</limit>
				<use_parent_model_frame>0</use_parent_model_frame>
			</axis>
		</joint>
		<joint name="hip_left_axis0" type="revolute">
			<parent>hip</parent>
			<child>upper_leg_left</child>
			<pose frame="">-0.007297577229158183 0.0013923487657230282 0.15323313247460107 0 0 0</pose>
			<axis>
				<xyz>2.914335439641036e-16 0.9999999999999997 2.234323837058118e-15</xyz>
				<limit>
					<lower>-3.141592653589793</lower>
					<upper>3.141592653589793</upper>
				</limit>
				<use_parent_model_frame>0</use_parent_model_frame>
			</axis>
		</joint>
		<joint name="hip_leftt_axis2" type="revolute">
			<parent>hip_left_link2</parent>
			<child>upper_leg_left</child>
			<pose frame="">-0.007297577229158183 0.0013923487657232058 0.15323313247460077 0 0 0</pose>
			<axis>
				<xyz>-1.3809233377132494e-14 2.185554621569933e-15 -1.0</xyz>
				<limit>
					<lower>-3.141592653589793</lower>
					<upper>3.141592653589793</upper>
				</limit>
				<use_parent_model_frame>0</use_parent_model_frame>
			</axis>
		</joint>
		<joint name="hip_left_axis1" type="revolute">
			<parent>hip_left_link1</parent>
			<child>hip_left_link2</child>
			<pose frame="">1.3322676295501878e-17 -1.1546319456101628e-15 -1.4210854715202004e-16 0 0 0</pose>
			<axis>
				<xyz>-1.0 6.106226635438361e-16 1.3732071035832405e-14</xyz>
				<limit>
					<lower>-3.141592653589793</lower>
					<upper>3.141592653589793</upper>
				</limit>
				<use_parent_model_frame>0</use_parent_model_frame>
			</axis>
		</joint>
		<joint name="neck_axis0" type="revolute">
			<parent>chest</parent>
			<child>neck_link1</child>
			<pose frame="">-5.773159728050814e-17 -9.992007221626409e-17 3.126388037344441e-15 0 0 0</pose>
			<axis>
				<xyz>-8.049116928532385e-16 1.0000000000000058 -2.1197893720368402e-15</xyz>
				<limit>
					<lower>-3.141592653589793</lower>
					<upper>3.141592653589793</upper>
				</limit>
				<use_parent_model_frame>0</use_parent_model_frame>
			</axis>
		</joint>
		<joint name="neck_axis2" type="revolute">
			<parent>neck_link2</parent>
			<child>head</child>
			<pose frame="">-0.013210038463863165 0.00034799501157947775 -0.044209918472008954 0 0 0</pose>
			<axis>
				<xyz>1.0103029524088931e-14 2.1688924369418735e-16 -0.9999999999999997</xyz>
				<limit>
					<lower>-3.141592653589793</lower>
					<upper>3.141592653589793</upper>
				</limit>
				<use_parent_model_frame>0</use_parent_model_frame>
			</axis>
		</joint>
		<joint name="neck_axis1" type="revolute">
			<parent>neck_link1</parent>
			<child>neck_link2</child>
			<pose frame="">1.1546319456101628e-16 -7.877032359715485e-16 0.0 0 0 0</pose>
			<axis>
				<xyz>-1.0000000000000022 -5.551115123125783e-17 -1.0186296250935811e-14</xyz>
				<limit>
					<lower>-3.141592653589793</lower>
					<upper>3.141592653589793</upper>
				</limit>
				<use_parent_model_frame>0</use_parent_model_frame>
			</axis>
		</joint>
		<joint name="motor0" type="prismatic">
			<parent>base</parent>
			<child>motor0</child>
			<pose frame="">-0.00033431159346434923 -1.2358101926090335 -0.009514196340348889 0 0 0</pose>
			<axis>
				<xyz>0.0 -1.0 0.0</xyz>
				<limit>
					<lower>-1.4</lower>
					<upper>0.0</upper>
				</limit>
				<use_parent_model_frame>0</use_parent_model_frame>
			</axis>
		</joint>
		<joint name="motor1" type="prismatic">
			<parent>base</parent>
			<child>motor1</child>
			<pose frame="">-0.00033430154605355254 1.2358101829513677 -0.009485805505270662 0 0 0</pose>
			<axis>
				<xyz>0.0 -1.0 0.0</xyz>
				<limit>
					<lower>0.0</lower>
					<upper>1.4</upper>
				</limit>
				<use_parent_model_frame>0</use_parent_model_frame>
			</axis>
		</joint>
		<joint name="motor2" type="prismatic">
			<parent>base</parent>
			<child>motor2</child>
			<pose frame="">0.00033431159342597996 -1.2358101926090346 -0.009485803664418523 0 0 0</pose>
			<axis>
				<xyz>0.0 1.0 0.0</xyz>
				<limit>
					<lower>0.0</lower>
					<upper>1.4</upper>
				</limit>
				<use_parent_model_frame>0</use_parent_model_frame>
			</axis>
		</joint>
		<joint name="motor3" type="prismatic">
			<parent>base</parent>
			<child>motor3</child>
			<pose frame="">-0.0011978126745185592 1.2342394028102621 -0.00951655894117484 0 0 0</pose>
			<axis>
				<xyz>0.0 1.0 0.0</xyz>
				<limit>
					<lower>-1.4</lower>
					<upper>0.0</upper>
				</limit>
				<use_parent_model_frame>0</use_parent_model_frame>
			</axis>
		</joint>
		<joint name="motor4" type="prismatic">
			<parent>base</parent>
			<child>motor5</child>
			<pose frame="">-1.2358101926090344 -0.00033431159341290595 -0.009485803664418506 0 0 0</pose>
			<axis>
				<xyz>1.0 0.0 0.0</xyz>
				<limit>
					<lower>0.0</lower>
					<upper>1.4</upper>
				</limit>
				<use_parent_model_frame>0</use_parent_model_frame>
			</axis>
		</joint>
		<joint name="motor5" type="prismatic">
			<parent>base</parent>
			<child>motor4</child>
			<pose frame="">1.2358101829513672 -0.0003343015461072696 -0.00951419449950688 0 0 0</pose>
			<axis>
				<xyz>1.0 0.0 0.0</xyz>
				<limit>
					<lower>-1.4</lower>
					<upper>0.0</upper>
				</limit>
				<use_parent_model_frame>0</use_parent_model_frame>
			</axis>
		</joint>
		<joint name="motor7" type="prismatic">
			<parent>base</parent>
			<child>motor6</child>
			<pose frame="">1.2358101829513677 0.0003343018224896355 -0.00948580550527066 0 0 0</pose>
			<axis>
				<xyz>-1.0 0.0 0.0</xyz>
				<limit>
					<lower>0.0</lower>
					<upper>1.4</upper>
				</limit>
				<use_parent_model_frame>0</use_parent_model_frame>
			</axis>
		</joint>
		<joint name="foot_right_axis0" type="revolute">
			<parent>lower_leg_right</parent>
			<child>ankle_right_link1</child>
			<pose frame="">4.440892098500626e-18 -4.263256414560601e-16 2.504663143554353e-15 0 0 0</pose>
			<axis>
				<xyz>-1.249000902703301e-16 1.0000000000000007 -2.220446049250304e-15</xyz>
				<limit>
					<lower>-3.141592653589793</lower>
					<upper>3.141592653589793</upper>
				</limit>
				<use_parent_model_frame>0</use_parent_model_frame>
			</axis>
		</joint>
		<joint name="foot_right_axis2" type="revolute">
			<parent>ankle_right_link2</parent>
			<child>foot_right</child>
			<pose frame="">1.6271629417197177e-08 -1.3415335793354189e-08 0.000605864147034012 0 0 0</pose>
			<axis>
				<xyz>-1.3745948823640212e-14 -1.2433742996370134e-30 -0.9999999999999998</xyz>
				<limit>
					<lower>-3.141592653589793</lower>
					<upper>3.141592653589793</upper>
				</limit>
				<use_parent_model_frame>0</use_parent_model_frame>
			</axis>
		</joint>
		<joint name="foot_right_axis1" type="revolute">
			<parent>ankle_right_link1</parent>
			<child>ankle_right_link2</child>
			<pose frame="">0.0 3.552713678800501e-17 -1.4210854715202004e-16 0 0 0</pose>
			<axis>
				<xyz>-1.0 -8.326672684688674e-17 1.374594882364021e-14</xyz>
				<limit>
					<lower>-3.141592653589793</lower>
					<upper>3.141592653589793</upper>
				</limit>
				<use_parent_model_frame>0</use_parent_model_frame>
			</axis>
		</joint>
		<joint name="hip_right_axis0" type="revolute">
			<parent>upper_leg_right</parent>
			<child>hip_right_link1</child>
			<pose frame="">5.329070518200751e-17 -3.019806626980426e-16 3.552713678800501e-15 0 0 0</pose>
			<axis>
				<xyz>-5.551115123125783e-16 1.0 -2.2343238370581185e-15</xyz>
				<limit>
					<lower>-3.141592653589793</lower>
					<upper>3.141592653589793</upper>
				</limit>
				<use_parent_model_frame>0</use_parent_model_frame>
			</axis>
		</joint>
		<joint name="hip_right_axis2" type="revolute">
			<parent>hip_right_link2</parent>
			<child>upper_leg_right</child>
			<pose frame="">-0.0072864957826752905 0.004817376020781889 0.15309056752078348 0 0 0</pose>
			<axis>
				<xyz>-1.3767600013709039e-14 -2.9170238954270855e-17 -1.0</xyz>
				<limit>
					<lower>-3.141592653589793</lower>
					<upper>3.141592653589793</upper>
				</limit>
				<use_parent_model_frame>0</use_parent_model_frame>
			</axis>
		</joint>
		<joint name="hip_right_axis1" type="revolute">
			<parent>hip_right_link1</parent>
			<child>hip_right_link2</child>
			<pose frame="">1.3322676295501878e-17 -2.806643806252396e-15 -1.2789769243681803e-15 0 0 0</pose>
			<axis>
				<xyz>-1.0 -4.163336342344337e-16 1.3732071035832403e-14</xyz>
				<limit>
					<lower>-3.141592653589793</lower>
					<upper>3.141592653589793</upper>
				</limit>
				<use_parent_model_frame>0</use_parent_model_frame>
			</axis>
		</joint>
		<joint name="knee_right_axis0" type="revolute">
			<parent>upper_leg_right</parent>
			<child>knee_right_link1</child>
			<pose frame="">1.7763568394002505e-17 -2.3092638912203257e-16 3.339550858072471e-15 0 0 0</pose>
			<axis>
				<xyz>-5.412337245047638e-16 0.9999999999999994 -2.2343238370581165e-15</xyz>
				<limit>
					<lower>-3.141592653589793</lower>
					<upper>3.141592653589793</upper>
				</limit>
				<use_parent_model_frame>0</use_parent_model_frame>
			</axis>
		</joint>
		<joint name="knee_right_axis2" type="revolute">
			<parent>knee_right_link2</parent>
			<child>lower_leg_right</child>
			<pose frame="">0.017232956364901117 0.0048001119361281396 0.13730752211789998 0 0 0</pose>
			<axis>
				<xyz>-1.3767600013708986e-14 -2.9170238954268686e-17 -0.9999999999999998</xyz>
				<limit>
					<lower>-3.141592653589793</lower>
					<upper>3.141592653589793</upper>
				</limit>
				<use_parent_model_frame>0</use_parent_model_frame>
			</axis>
		</joint>
		<joint name="knee_right_axis1" type="revolute">
			<parent>knee_right_link1</parent>
			<child>knee_right_link2</child>
			<pose frame="">-8.881784197001253e-18 -6.217248937900877e-16 -7.105427357601002e-16 0 0 0</pose>
			<axis>
				<xyz>-0.9999999999999998 -4.3021142204224816e-16 1.3732071035832395e-14</xyz>
				<limit>
					<lower>-3.141592653589793</lower>
					<upper>3.141592653589793</upper>
				</limit>
				<use_parent_model_frame>0</use_parent_model_frame>
			</axis>
		</joint>
		<joint name="spine_axis0" type="revolute">
			<parent>hip</parent>
			<child>spine_link1</child>
			<pose frame="">7.549516567451065e-17 -2.4813484600372247e-16 3.694822225952521e-15 0 0 0</pose>
			<axis>
				<xyz>-8.049116928532385e-16 1.0000000000000056 -2.119789372036819e-15</xyz>
				<limit>
					<lower>-3.141592653589793</lower>
					<upper>3.141592653589793</upper>
				</limit>
				<use_parent_model_frame>0</use_parent_model_frame>
			</axis>
		</joint>
		<joint name="spine_axis2" type="revolute">
			<parent>spine_link2</parent>
			<child>chest</child>
			<pose frame="">0.004823169420318352 0.00013703353235410497 -0.31480559812747916 0 0 0</pose>
			<axis>
				<xyz>-1.3911956592616437e-14 2.1688924369416575e-16 -0.9999999999999997</xyz>
				<limit>
					<lower>-3.141592653589793</lower>
					<upper>3.141592653589793</upper>
				</limit>
				<use_parent_model_frame>0</use_parent_model_frame>
			</axis>
		</joint>
		<joint name="spine_axis1" type="revolute">
			<parent>spine_link1</parent>
			<child>spine_link2</child>
			<pose frame="">-4.440892098500626e-18 -9.942047185518277e-16 -1.2789769243681803e-15 0 0 0</pose>
			<axis>
				<xyz>-1.000000000000003 -1.3877787807814457e-17 1.3894724708050836e-14</xyz>
				<limit>
					<lower>-3.141592653589793</lower>
					<upper>3.141592653589793</upper>
				</limit>
				<use_parent_model_frame>0</use_parent_model_frame>
			</axis>
		</joint>
		<joint name="shoulder_right_axis0" type="revolute">
			<parent>chest</parent>
			<child>shoulder_right_link1</child>
			<pose frame="">3.907985046680551e-16 -3.907985046680551e-15 2.842170943040401e-16 0 0 0</pose>
			<axis>
				<xyz>1.3346308960332177e-14 -2.4821811273056937e-13 1.000000000000005</xyz>
				<limit>
					<lower>-3.141592653589793</lower>
					<upper>3.141592653589793</upper>
				</limit>
				<use_parent_model_frame>0</use_parent_model_frame>
			</axis>
		</joint>
		<joint name="shoulder_right_axis2" type="revolute">
			<parent>shoulder_right_link2</parent>
			<child>upper_arm_right</child>
			<pose frame="">0.022306667372974057 0.03311385234660097 0.2254386091139355 0 0 0</pose>
			<axis>
				<xyz>-2.220446049250313e-16 0.9999999999999999 2.50716114535976e-13</xyz>
				<limit>
					<lower>-3.141592653589793</lower>
					<upper>3.141592653589793</upper>
				</limit>
				<use_parent_model_frame>0</use_parent_model_frame>
			</axis>
		</joint>
		<joint name="shoulder_right_axis1" type="revolute">
			<parent>shoulder_right_link1</parent>
			<child>shoulder_right_link2</child>
			<pose frame="">-5.240252676230739e-16 3.339550858072471e-15 -1.7053025658242404e-15 0 0 0</pose>
			<axis>
				<xyz>-1.0000000000000027 -2.636779683484747e-16 1.4027398200582152e-14</xyz>
				<limit>
					<lower>-3.141592653589793</lower>
					<upper>3.141592653589793</upper>
				</limit>
				<use_parent_model_frame>0</use_parent_model_frame>
			</axis>
		</joint>
		<joint name="elbow_right_axis0" type="revolute">
			<parent>upper_arm_right</parent>
			<child>elbow_right_link1</child>
			<pose frame="">3.375077994860476e-16 -3.446132268436486e-15 -4.263256414560601e-16 0 0 0</pose>
			<axis>
				<xyz>1.3339370066427914e-14 -2.482181127305694e-13 1.000000000000005</xyz>
				<limit>
					<lower>-3.141592653589793</lower>
					<upper>3.141592653589793</upper>
				</limit>
				<use_parent_model_frame>0</use_parent_model_frame>
			</axis>
		</joint>
		<joint name="elbow_right_axis2" type="revolute">
			<parent>elbow_right_link2</parent>
			<child>lower_arm_right</child>
			<pose frame="">-0.01455213373359201 0.03782835016261316 0.22972451621933643 0 0 0</pose>
			<axis>
				<xyz>-2.220446049250313e-16 0.999999999999999 2.50716114535976e-13</xyz>
				<limit>
					<lower>-3.141592653589793</lower>
					<upper>3.141592653589793</upper>
				</limit>
				<use_parent_model_frame>0</use_parent_model_frame>
			</axis>
		</joint>
		<joint name="elbow_right_axis1" type="revolute">
			<parent>elbow_right_link1</parent>
			<child>elbow_right_link2</child>
			<pose frame="">-5.329070518200751e-16 3.0553337637684308e-15 -8.526512829121202e-16 0 0 0</pose>
			<axis>
				<xyz>-1.000000000000001 -2.7755575615628914e-16 1.4020459306677973e-14</xyz>
				<limit>
					<lower>-3.141592653589793</lower>
					<upper>3.141592653589793</upper>
				</limit>
				<use_parent_model_frame>0</use_parent_model_frame>
			</axis>
		</joint>
		<joint name="shoulder_left_axis0" type="revolute">
			<parent>chest</parent>
			<child>shoulder_left_link1</child>
			<pose frame="">3.4638958368304885e-16 2.842170943040401e-15 1.7053025658242404e-15 0 0 0</pose>
			<axis>
				<xyz>-1.3512842414025909e-14 -2.530475828876893e-13 -1.000000000000005</xyz>
				<limit>
					<lower>-3.141592653589793</lower>
					<upper>3.141592653589793</upper>
				</limit>
				<use_parent_model_frame>0</use_parent_model_frame>
			</axis>
		</joint>
		<joint name="shoulder_left_axis2" type="revolute">
			<parent>shoulder_left_link2</parent>
			<child>upper_arm_left</child>
			<pose frame="">0.022266770378150263 -0.03546067560914292 0.22543864815268636 0 0 0</pose>
			<axis>
				<xyz>-2.7755575615628914e-17 1.0000000000000007 -2.507161145359761e-13</xyz>
				<limit>
					<lower>-3.141592653589793</lower>
					<upper>3.141592653589793</upper>
				</limit>
				<use_parent_model_frame>0</use_parent_model_frame>
			</axis>
		</joint>
		<joint name="shoulder_left_axis1" type="revolute">
			<parent>shoulder_left_link1</parent>
			<child>shoulder_left_link2</child>
			<pose frame="">-5.240252676230739e-16 -3.339550858072471e-15 -1.1368683772161603e-15 0 0 0</pose>
			<axis>
				<xyz>1.0000000000000033 1.9236091608336055e-45 -1.402739820058209e-14</xyz>
				<limit>
					<lower>-3.141592653589793</lower>
					<upper>3.141592653589793</upper>
				</limit>
				<use_parent_model_frame>0</use_parent_model_frame>
			</axis>
		</joint>
		<joint name="wrist_right_axis0" type="revolute">
			<parent>lower_arm_right</parent>
			<child>wrist_right_link1</child>
			<pose frame="">3.730349362740526e-16 -3.0908609005564358e-15 2.7000623958883807e-15 0 0 0</pose>
			<axis>
				<xyz>1.335324785423576e-14 -2.4821811273056907e-13 1.000000000000005</xyz>
				<limit>
					<lower>-3.141592653589793</lower>
					<upper>3.141592653589793</upper>
				</limit>
				<use_parent_model_frame>0</use_parent_model_frame>
			</axis>
		</joint>
		<joint name="wrist_right_axis2" type="revolute">
			<parent>wrist_right_link2</parent>
			<child>hand_right</child>
			<pose frame="">2.754468839327728e-07 -0.010256095835771362 -2.2709363818762541e-07 0 0 0</pose>
			<axis>
				<xyz>-1.6653345369377348e-16 0.999999999999999 2.5071611453597603e-13</xyz>
				<limit>
					<lower>-3.141592653589793</lower>
					<upper>3.141592653589793</upper>
				</limit>
				<use_parent_model_frame>0</use_parent_model_frame>
			</axis>
		</joint>
		<joint name="wrist_right_axis1" type="revolute">
			<parent>wrist_right_link1</parent>
			<child>wrist_right_link2</child>
			<pose frame="">-5.861977570020827e-16 3.161915174132446e-15 -3.4106051316484808e-15 0 0 0</pose>
			<axis>
				<xyz>-1.0000000000000007 -1.5265566588595902e-16 1.4034337094485815e-14</xyz>
				<limit>
					<lower>-3.141592653589793</lower>
					<upper>3.141592653589793</upper>
				</limit>
				<use_parent_model_frame>0</use_parent_model_frame>
			</axis>
		</joint>
		<joint name="elbow_left_axis0" type="revolute">
			<parent>upper_arm_left</parent>
			<child>elbow_left_link1</child>
			<pose frame="">2.842170943040401e-16 2.415845301584341e-15 -1.4210854715202004e-16 0 0 0</pose>
			<axis>
				<xyz>-1.3505903520121658e-14 -2.5304758288768926e-13 -1.000000000000005</xyz>
				<limit>
					<lower>-3.141592653589793</lower>
					<upper>3.141592653589793</upper>
				</limit>
				<use_parent_model_frame>0</use_parent_model_frame>
			</axis>
		</joint>
		<joint name="elbow_left_axis2" type="revolute">
			<parent>elbow_left_link2</parent>
			<child>lower_arm_left</child>
			<pose frame="">-0.014592037069603023 -0.040175174236179036 0.229724555995426 0 0 0</pose>
			<axis>
				<xyz>-4.163336342344337e-17 0.9999999999999992 -2.50716114535976e-13</xyz>
				<limit>
					<lower>-3.141592653589793</lower>
					<upper>3.141592653589793</upper>
				</limit>
				<use_parent_model_frame>0</use_parent_model_frame>
			</axis>
		</joint>
		<joint name="ankle_right_axis1" type="revolute">
			<parent>elbow_left_link1</parent>
			<child>elbow_left_link2</child>
			<pose frame="">-4.440892098500626e-16 -3.161915174132446e-15 -7.105427357601002e-16 0 0 0</pose>
			<axis>
				<xyz>1.0000000000000002 5.551115123125783e-17 -1.4020459306678044e-14</xyz>
				<limit>
					<lower>-3.141592653589793</lower>
					<upper>3.141592653589793</upper>
				</limit>
				<use_parent_model_frame>0</use_parent_model_frame>
			</axis>
		</joint>
		<joint name="wrist_left_axis0" type="revolute">
			<parent>lower_arm_left</parent>
			<child>wrist_left_link1</child>
			<pose frame="">5.950795411990839e-16 1.9539925233402757e-15 2.2737367544323206e-15 0 0 0</pose>
			<axis>
				<xyz>-1.351978130792958e-14 -2.5304758288768537e-13 -1.000000000000005</xyz>
				<limit>
					<lower>-3.141592653589793</lower>
					<upper>3.141592653589793</upper>
				</limit>
				<use_parent_model_frame>0</use_parent_model_frame>
			</axis>
		</joint>
		<joint name="wrist_left_axis2" type="revolute">
			<parent>wrist_left_link2</parent>
			<child>hand_left</child>
			<pose frame="">-2.754468837995461e-07 -0.010256095835766211 -2.2709362696105017e-07 0 0 0</pose>
			<axis>
				<xyz>-9.71445146547012e-17 0.9999999999999992 -2.5071611453597593e-13</xyz>
				<limit>
					<lower>-3.141592653589793</lower>
					<upper>3.141592653589793</upper>
				</limit>
				<use_parent_model_frame>0</use_parent_model_frame>
			</axis>
		</joint>
		<joint name="wrist_left_axis1" type="revolute">
			<parent>wrist_left_link1</parent>
			<child>wrist_left_link2</child>
			<pose frame="">-6.128431095930865e-16 -3.0908609005564358e-15 -3.126388037344441e-15 0 0 0</pose>
			<axis>
				<xyz>1.0000000000000007 1.3877787807814457e-17 -1.4034337094485804e-14</xyz>
				<limit>
					<lower>-3.141592653589793</lower>
					<upper>3.141592653589793</upper>
				</limit>
				<use_parent_model_frame>0</use_parent_model_frame>
			</axis>
		</joint>
		<joint name="motor8" type="prismatic">
			<parent>base</parent>
			<child>motor8</child>
			<pose frame="">0.0011978136706753161 -1.2342394009707207 -0.00951655921897796 0 0 0</pose>
			<axis>
				<xyz>0.0 -1.0 0.0</xyz>
				<limit>
					<lower>-1.4</lower>
					<upper>0.0</upper>
				</limit>
				<use_parent_model_frame>0</use_parent_model_frame>
			</axis>
		</joint>
		<joint name="motor9" type="prismatic">
			<parent>base</parent>
			<child>motor9</child>
			<pose frame="">-0.0003343018224884986 1.2358101829513672 -0.00948580573277212 0 0 0</pose>
			<axis>
				<xyz>0.0 -1.0 0.0</xyz>
				<limit>
					<lower>0.0</lower>
					<upper>0.0</upper>
				</limit>
				<use_parent_model_frame>0</use_parent_model_frame>
			</axis>
		</joint>
		<joint name="motor11" type="prismatic">
			<parent>base</parent>
			<child>motor10</child>
			<pose frame="">-0.001197813670675032 -1.2342394009707196 -0.009483440781021528 0 0 0</pose>
			<axis>
				<xyz>0.0 1.0 0.0</xyz>
				<limit>
					<lower>0.0</lower>
					<upper>1.4</upper>
				</limit>
				<use_parent_model_frame>0</use_parent_model_frame>
			</axis>
		</joint>
		<joint name="motor12" type="prismatic">
			<parent>base</parent>
			<child>motor12</child>
			<pose frame="">1.234239402810263 0.001197812674521117 -0.009516558941175077 0 0 0</pose>
			<axis>
				<xyz>1.0 0.0 0.0</xyz>
				<limit>
					<lower>-1.4</lower>
					<upper>0.0</upper>
				</limit>
				<use_parent_model_frame>0</use_parent_model_frame>
			</axis>
		</joint>
		<joint name="motor13" type="prismatic">
			<parent>base</parent>
			<child>motor13</child>
			<pose frame="">-1.2342394009707198 0.0011978136706744635 -0.00948344078102167 0 0 0</pose>
			<axis>
				<xyz>1.0 0.0 0.0</xyz>
				<limit>
					<lower>0.0</lower>
					<upper>1.4</upper>
				</limit>
				<use_parent_model_frame>0</use_parent_model_frame>
			</axis>
		</joint>
		<joint name="motor14" type="prismatic">
			<parent>base</parent>
			<child>motor15</child>
			<pose frame="">-1.2342394009707207 -0.0011978136706756004 -0.00951655921897796 0 0 0</pose>
			<axis>
				<xyz>-1.0 0.0 0.0</xyz>
				<limit>
					<lower>-1.4</lower>
					<upper>0.0</upper>
				</limit>
				<use_parent_model_frame>0</use_parent_model_frame>
			</axis>
		</joint>
		<joint name="motor15" type="prismatic">
			<parent>base</parent>
			<child>motor14</child>
			<pose frame="">1.234239402810262 -0.001197812674521117 -0.009483441058825265 0 0 0</pose>
			<axis>
				<xyz>-1.0 0.0 0.0</xyz>
				<limit>
					<lower>0.0</lower>
					<upper>1.4</upper>
				</limit>
				<use_parent_model_frame>0</use_parent_model_frame>
			</axis>
		</joint>
		<joint name="motor16" type="prismatic">
			<parent>base</parent>
			<child>motor16</child>
			<pose frame="">0.0011978136706730425 -1.2342394009707198 -0.009516559218978102 0 0 0</pose>
			<axis>
				<xyz>0.0 -1.0 0.0</xyz>
				<limit>
					<lower>-1.4</lower>
					<upper>0.0</upper>
				</limit>
				<use_parent_model_frame>0</use_parent_model_frame>
			</axis>
		</joint>
		<joint name="motor17" type="prismatic">
			<parent>base</parent>
			<child>motor17</child>
			<pose frame="">0.0011978126745225382 1.2342394028102615 -0.009483441058823702 0 0 0</pose>
			<axis>
				<xyz>0.0 -1.0 0.0</xyz>
				<limit>
					<lower>0.0</lower>
					<upper>1.4</upper>
				</limit>
				<use_parent_model_frame>0</use_parent_model_frame>
			</axis>
		</joint>
		<joint name="motor18" type="prismatic">
			<parent>base</parent>
			<child>motor19</child>
			<pose frame="">-0.0011978126745191275 1.2342394028102615 -0.009516558941174936 0 0 0</pose>
			<axis>
				<xyz>0.0 1.0 0.0</xyz>
				<limit>
					<lower>-1.4</lower>
					<upper>0.0</upper>
				</limit>
				<use_parent_model_frame>0</use_parent_model_frame>
			</axis>
		</joint>
		<joint name="motor19" type="prismatic">
			<parent>base</parent>
			<child>motor18</child>
			<pose frame="">-0.0011978136706770216 -1.2342394009707196 -0.009483440781021103 0 0 0</pose>
			<axis>
				<xyz>0.0 1.0 0.0</xyz>
				<limit>
					<lower>0.0</lower>
					<upper>1.4</upper>
				</limit>
				<use_parent_model_frame>0</use_parent_model_frame>
			</axis>
		</joint>
		<joint name="motor20" type="prismatic">
			<parent>base</parent>
			<child>motor20</child>
			<pose frame="">1.2342394028102615 0.0011978126745188433 -0.009516558941174936 0 0 0</pose>
			<axis>
				<xyz>1.0 0.0 0.0</xyz>
				<limit>
					<lower>-1.4</lower>
					<upper>0.0</upper>
				</limit>
				<use_parent_model_frame>0</use_parent_model_frame>
			</axis>
		</joint>
		<joint name="motor21" type="prismatic">
			<parent>base</parent>
			<child>motor21</child>
			<pose frame="">-1.2342394009707203 0.0011978136706756004 -0.009483440781021386 0 0 0</pose>
			<axis>
				<xyz>1.0 0.0 0.0</xyz>
				<limit>
					<lower>0.0</lower>
					<upper>1.4</upper>
				</limit>
				<use_parent_model_frame>0</use_parent_model_frame>
			</axis>
		</joint>
		<joint name="motor22" type="prismatic">
			<parent>base</parent>
			<child>motor23</child>
			<pose frame="">-1.2342394009707196 -0.0011978136706733266 -0.009516559218977535 0 0 0</pose>
			<axis>
				<xyz>-1.0 0.0 0.0</xyz>
				<limit>
					<lower>-1.4</lower>
					<upper>0.0</upper>
				</limit>
				<use_parent_model_frame>0</use_parent_model_frame>
			</axis>
		</joint>
		<joint name="motor23" type="prismatic">
			<parent>base</parent>
			<child>motor22</child>
			<pose frame="">1.2342394028102621 -0.001197812674522254 -0.009483441058824553 0 0 0</pose>
			<axis>
				<xyz>-1.0 0.0 0.0</xyz>
				<limit>
					<lower>0.0</lower>
					<upper>1.4</upper>
				</limit>
				<use_parent_model_frame>0</use_parent_model_frame>
			</axis>
		</joint>
		<joint name="6dof_axis0" type="revolute">
			<parent>base</parent>
			<child>6dof_link1</child>
			<pose frame="">1.0679391398982218e-18 -2.198762005800603e-18 1.4210854715202004e-16 0 0 0</pose>
			<axis>
				<xyz>1.0 -2.6844855317200687e-42 -1.4936788733982073e-64</xyz>
				<limit>
					<lower>-3.141592653589793</lower>
					<upper>3.141592653589793</upper>
				</limit>
				<use_parent_model_frame>0</use_parent_model_frame>
			</axis>
		</joint>
		<joint name="6dof_axis1" type="revolute">
			<parent>6dof_link1</parent>
			<child>6dof_link2</child>
			<pose frame="">-9.38376980286204e-19 -5.269222558279552e-19 2.842170943040401e-16 0 0 0</pose>
			<axis>
				<xyz>2.6844855317200687e-42 1.0 5.564117200781429e-23</xyz>
				<limit>
					<lower>-3.141592653589793</lower>
					<upper>3.141592653589793</upper>
				</limit>
				<use_parent_model_frame>0</use_parent_model_frame>
			</axis>
		</joint>
		<joint name="6dof_axis2" type="revolute">
			<parent>6dof_link2</parent>
			<child>6dof_link3</child>
			<pose frame="">-2.379289594976508e-07 2.890294149984697e-07 -0.010729363507488045 0 0 0</pose>
			<axis>
				<xyz>-3.388310440774361e-71 -5.564117200781429e-23 1.0</xyz>
				<limit>
					<lower>-3.141592653589793</lower>
					<upper>3.141592653589793</upper>
				</limit>
				<use_parent_model_frame>0</use_parent_model_frame>
			</axis>
		</joint>
		<joint name="6dof_axis3" type="prismatic">
			<parent>6dof_link3</parent>
			<child>6dof_link4</child>
			<pose frame="">-0.04264321097414968 6.09431058623984e-05 7.673861546209083e-15 0 0 0</pose>
			<axis>
				<xyz>-1.0 2.6814997359924824e-41 -4.336808689942018e-19</xyz>
				<limit>
					<lower>-1.0</lower>
					<upper>1.0</upper>
				</limit>
				<use_parent_model_frame>0</use_parent_model_frame>
			</axis>
		</joint>
		<joint name="6dof_axis4" type="prismatic">
			<parent>6dof_link4</parent>
			<child>6dof_link5</child>
			<pose frame="">-6.1008287956425485e-05 -0.042619910478939656 1.8770579117699527e-08 0 0 0</pose>
			<axis>
				<xyz>-2.4477572411455523e-32 1.0 5.56411602478092e-23</xyz>
				<limit>
					<lower>-1.0</lower>
					<upper>1.0</upper>
				</limit>
				<use_parent_model_frame>0</use_parent_model_frame>
			</axis>
		</joint>
		<joint name="6dof_axis5" type="prismatic">
			<parent>6dof_link5</parent>
			<child>hip</child>
			<pose frame="">0.019381512328334304 0.0030912488398242783 0.04942358138086263 0 0 0</pose>
			<axis>
				<xyz>0.0 -5.082197683525751e-21 1.0</xyz>
				<limit>
					<lower>-1.0</lower>
					<upper>1.0</upper>
				</limit>
				<use_parent_model_frame>0</use_parent_model_frame>
			</axis>
		</joint>
		<plugin filename="libcardsflow_gazebo_plugin.so" name="cardsflow_gazebo_plugin"/>
	</model>
</sdf>
