<?xml version="1.0" ?>
<robot name="roboy_upper_body">
  <joint name="elbow_right_rot1" type="revolute">
    <parent link="elbow_right"/>
    <child link="lower_arm_right"/>
    <origin rpy="0  0  0" xyz="0.02392 -0.00128 -0.21658"/>
    <axis xyz="-0.01118  0.0229   0.99967"/>
    <limit effort="0.0" lower="-1.57079632679" upper="1.57079632679" velocity="0.0"/>
  </joint>
  <joint name="right_wrist_0" type="revolute">
    <parent link="lower_arm_right"/>
    <child link="wrist_right_1"/>
    <origin rpy="0  0  0" xyz="0.01295 -0.00959 -0.40395"/>
    <axis xyz="0.9991  -0.04032 -0.01255"/>
    <limit effort="0.0" lower="-0.523598775598" upper="0.523598775598" velocity="0.0"/>
  </joint>
  <joint name="right_wrist_1" type="revolute">
    <parent link="wrist_right_1"/>
    <child link="right_hand"/>
    <origin rpy="0  0  0" xyz="0.00704  0.02059 -0.08144"/>
    <axis xyz="0.04003  0.99894 -0.02244"/>
    <limit effort="0.0" lower="-0.523598775598" upper="0.523598775598" velocity="0.0"/>
  </joint>
  <joint name="elbow_left_rot1" type="revolute">
    <parent link="elbow_left"/>
    <child link="lower_arm_left"/>
    <origin rpy="0  0  0" xyz="-0.02447 -0.0013  -0.21497"/>
    <axis xyz="-0.01118 -0.0229  -0.99967"/>
    <limit effort="0.0" lower="-1.57079632679" upper="1.57079632679" velocity="0.0"/>
  </joint>
  <joint name="elbow_left_rot0" type="revolute">
    <parent link="upper_arm_left"/>
    <child link="elbow_left"/>
    <origin rpy="0  0  0" xyz="0.00423 -0.01415 -0.42091"/>
    <axis xyz="-0.99863 -0.05074  0.01234"/>
    <limit effort="0.0" lower="0.0" upper="1.57079632679" velocity="0.0"/>
  </joint>
  <joint name="sphere_left_axis0" type="revolute">
    <parent link="torso"/>
    <child link="sphere_left_link1"/>
    <origin rpy="0  0  0" xyz="0.58436  0.01689  0.85454"/>
    <axis xyz="0.99863  0.05074 -0.01234"/>
    <limit effort="0.0" lower="-3.14159265359" upper="3.14159265359" velocity="0.0"/>
  </joint>
  <joint name="sphere_left_axis1" type="revolute">
    <parent link="sphere_left_link1"/>
    <child link="sphere_left_link2"/>
    <origin rpy="0  0  0" xyz="0  0  0"/>
    <axis xyz="-0.05101  0.99844 -0.02231"/>
    <limit effort="0.0" lower="-3.14159265359" upper="3.14159265359" velocity="0.0"/>
  </joint>
  <joint name="sphere_left_axis2" type="revolute">
    <parent link="sphere_left_link2"/>
    <child link="upper_arm_left"/>
    <origin rpy="0  0  0" xyz="0.01098 -0.0026  -0.15154"/>
    <axis xyz="-0.01118 -0.0229  -0.99967"/>
    <limit effort="0.0" lower="-3.14159265359" upper="3.14159265359" velocity="0.0"/>
  </joint>
  <joint name="left_wrist_0" type="revolute">
    <parent link="lower_arm_left"/>
    <child link="wrist_left_1"/>
    <origin rpy="0  0  0" xyz="-0.01734 -0.01003 -0.40292"/>
    <axis xyz="-0.99743 -0.06112  0.03722"/>
    <limit effort="0.0" lower="-0.523598775598" upper="0.523598775598" velocity="0.0"/>
  </joint>
  <joint name="left_wrist_1" type="revolute">
    <parent link="wrist_left_1"/>
    <child link="left_hand"/>
    <origin rpy="0  0  0" xyz="-0.00251 -0.01909 -0.08542"/>
    <axis xyz="-0.06197  0.99783 -0.02217"/>
    <limit effort="0.0" lower="-0.523598775598" upper="0.523598775598" velocity="0.0"/>
  </joint>
  <joint name="sphere_right_axis0" type="revolute">
    <parent link="torso"/>
    <child link="sphere_right_link1"/>
    <origin rpy="0  0  0" xyz="-0.58436  0.01689  0.85454"/>
    <axis xyz="0.05101  0.99844 -0.02231"/>
    <limit effort="0.0" lower="-3.14159265359" upper="3.14159265359" velocity="0.0"/>
  </joint>
  <joint name="sphere_right_axis2" type="revolute">
    <parent link="sphere_right_link2"/>
    <child link="upper_arm_right"/>
    <origin rpy="0  0  0" xyz="-0.01036 -0.00496 -0.15098"/>
    <axis xyz="0.01118 -0.0229  -0.99967"/>
    <limit effort="0.0" lower="-3.14159265359" upper="3.14159265359" velocity="0.0"/>
  </joint>
  <joint name="sphere_right_axis1" type="revolute">
    <parent link="sphere_right_link1"/>
    <child link="sphere_right_link2"/>
    <origin rpy="0  0  0" xyz="0  0  0"/>
    <axis xyz="-0.99863  0.05074 -0.01234"/>
    <limit effort="0.0" lower="-3.14159265359" upper="3.14159265359" velocity="0.0"/>
  </joint>
  <joint name="elbow_right_rot0" type="revolute">
    <parent link="upper_arm_right"/>
    <child link="elbow_right"/>
    <origin rpy="0  0  0" xyz="-0.00443 -0.01192 -0.4254"/>
    <axis xyz="-0.99863  0.05074 -0.01234"/>
    <limit effort="0.0" lower="0.0" upper="1.57079632679" velocity="0.0"/>
  </joint>
  <joint name="left_stick_tip_joint" type="fixed">
    <parent link="left_hand"/>
    <child link="left_stick_tip"/>
    <origin rpy="0  0  0" xyz="-0.01681 -0.51853 -0.22686"/>
    <axis xyz="0  0  0"/>
    <limit effort="0" lower="0" upper="0" velocity="0"/>
  </joint>
  <joint name="sphere_head_axis0" type="revolute">
    <parent link="torso"/>
    <child link="sphere_head_link1"/>
    <origin rpy="0  0  0" xyz="0       0.00152  1.1795"/>
    <axis xyz="0 -1  0"/>
    <limit effort="0.0" lower="-0.523598775598" upper="0.523598775598" velocity="0.0"/>
  </joint>
  <joint name="sphere_head_axis2" type="revolute">
    <parent link="shere_head_link2"/>
    <child link="head"/>
    <origin rpy="0  0  0" xyz="0.00064  0.01352  0.15538"/>
    <axis xyz="0  0  1"/>
    <limit effort="0.0" lower="-0.523598775598" upper="0.523598775598" velocity="0.0"/>
  </joint>
  <joint name="sphere_head_axis1" type="revolute">
    <parent link="sphere_head_link1"/>
    <child link="shere_head_link2"/>
    <origin rpy="0  0  0" xyz="0  0  0"/>
    <axis xyz="-1  0  0"/>
    <limit effort="0.0" lower="-0.523598775598" upper="0.523598775598" velocity="0.0"/>
  </joint>
  <joint name="zed_camera_mount" type="fixed">
    <parent link="head"/>
    <child link="zed_camera"/>
    <origin rpy="0  0  0" xyz="0.02085 -0.17395  0.28852"/>
    <axis xyz="0  0  0"/>
    <limit effort="0" lower="0" upper="0" velocity="0"/>
  </joint>
  <joint name="zed_camera_right" type="fixed">
    <parent link="zed_camera"/>
    <child link="zed_camera_right_lense"/>
    <origin rpy="0  0  0" xyz="-0.14149 -0.02543 -0.00259"/>
    <axis xyz="0  0  0"/>
    <limit effort="0" lower="0" upper="0" velocity="0"/>
  </joint>
  <joint name="zed_camera_left" type="fixed">
    <parent link="zed_camera"/>
    <child link="zed_camera_left_lense"/>
    <origin rpy="0  0  0" xyz="0.09848 -0.02543 -0.00259"/>
    <axis xyz="0  0  0"/>
    <limit effort="0" lower="0" upper="0" velocity="0"/>
  </joint>
  <joint name="right_stick_tip_joint" type="fixed">
    <parent link="right_hand"/>
    <child link="right_stick_tip"/>
    <origin rpy="0  0  0" xyz="0.011   -0.55821 -0.22441"/>
    <axis xyz="0  0  0"/>
    <limit effort="0" lower="0" upper="0" velocity="0"/>
  </joint>
  <joint name="spine_v1_axis0" type="revolute">
    <parent link="spine_link1"/>
    <child link="spine_v1_sphere_link1"/>
    <origin rpy="0  0  0" xyz="0       0       0.05746"/>
    <axis xyz="1  0  0"/>
    <limit effort="0.0" lower="-0.0872664625997" upper="0.0872664625997" velocity="0.0"/>
  </joint>
  <joint name="spine_v1_axis2" type="revolute">
    <parent link="spine_v1_sphere_link2"/>
    <child link="spine_link2"/>
    <origin rpy="0  0  0" xyz="0       0       0.02053"/>
    <axis xyz="0  0  1"/>
    <limit effort="0.0" lower="-0.0872664625997" upper="0.0872664625997" velocity="0.0"/>
  </joint>
  <joint name="spine_v1_axis1" type="revolute">
    <parent link="spine_v1_sphere_link1"/>
    <child link="spine_v1_sphere_link2"/>
    <origin rpy="0  0  0" xyz="0  0  0"/>
    <axis xyz="0 -1  0"/>
    <limit effort="0.0" lower="-0.0872664625997" upper="0.0872664625997" velocity="0.0"/>
  </joint>
  <joint name="spine_v0_axis0" type="revolute">
    <parent link="base"/>
    <child link="spine_v0_sphere_link1"/>
    <origin rpy="0  0  0" xyz="0       0.00152  0.24514"/>
    <axis xyz="1  0  0"/>
    <limit effort="0.0" lower="-0.0872664625997" upper="0.0872664625997" velocity="0.0"/>
  </joint>
  <joint name="spine_v0_axis2" type="revolute">
    <parent link="spine_v0_sphere_link2"/>
    <child link="spine_link1"/>
    <origin rpy="0  0  0" xyz="0       0       0.02053"/>
    <axis xyz="0  0  1"/>
    <limit effort="0.0" lower="-0.0872664625997" upper="0.0872664625997" velocity="0.0"/>
  </joint>
  <joint name="spine_v0_axis1" type="revolute">
    <parent link="spine_v0_sphere_link1"/>
    <child link="spine_v0_sphere_link2"/>
    <origin rpy="0  0  0" xyz="0  0  0"/>
    <axis xyz="0 -1  0"/>
    <limit effort="0.0" lower="-0.0872664625997" upper="0.0872664625997" velocity="0.0"/>
  </joint>
  <joint name="spine_v2_axis0" type="revolute">
    <parent link="spine_link2"/>
    <child link="spine_v2_sphere_link1"/>
    <origin rpy="0  0  0" xyz="0       0       0.05746"/>
    <axis xyz="1  0  0"/>
    <limit effort="0.0" lower="-0.0872664625997" upper="0.0872664625997" velocity="0.0"/>
  </joint>
  <joint name="spine_v2_axis2" type="revolute">
    <parent link="spine_v2_sphere_link2"/>
    <child link="torso"/>
    <origin rpy="0  0  0" xyz="0       0      -0.15845"/>
    <axis xyz="0  0  1"/>
    <limit effort="0.0" lower="-0.0872664625997" upper="0.0872664625997" velocity="0.0"/>
  </joint>
  <joint name="spine_v2_axis1" type="revolute">
    <parent link="spine_v2_sphere_link1"/>
    <child link="spine_v2_sphere_link2"/>
    <origin rpy="0  0  0" xyz="0  0  0"/>
    <axis xyz="0 -1  0"/>
    <limit effort="0.0" lower="-0.0872664625997" upper="0.0872664625997" velocity="0.0"/>
  </joint>
  <link name="right_hand">
    <inertial>
      <mass value="0.20805908239892756"/>
      <origin rpy="0  0  0" xyz="0  0  0"/>
      <inertia ixx="0.007556710984265264" ixy="-0.0038709486823734498" ixz="-0.0027023479542116224" iyy="0.019913740298210598" iyz="-0.007625792387378484" izz="0.018971657099664915"/>
    </inertial>
    <collision name="right_hand_collision">
      <origin rpy="0  0  0" xyz="0.28538 -0.01298  0.05089"/>
      <geometry>
        <mesh filename="package://robots/roboy_upper_body/meshes/CAD/right_hand.stl OR robots/roboy_xylophone/meshes/CAD/right_hand.stl" scale="0.001 0.001 0.001"/>
      </geometry>
    </collision>
    <visual name="right_hand_visual">
      <origin rpy="0  0  0" xyz="0.28538 -0.01298  0.05089"/>
      <geometry>
        <mesh filename="package://robots/roboy_upper_body/meshes/CAD/right_hand.stl OR robots/roboy_xylophone/meshes/CAD/right_hand.stl" scale="0.001 0.001 0.001"/>
      </geometry>
    </visual>
  </link>
  <link name="left_hand">
    <inertial>
      <mass value="0.1865043396217815"/>
      <origin rpy="0  0  0" xyz="0  0  0"/>
      <inertia ixx="0.007424110818204271" ixy="0.0038015046666225495" ixz="-0.0026936612177736836" iyy="0.01767984161209808" iyz="0.007164025065684021" izz="0.016872438514383078"/>
    </inertial>
    <collision name="left_hand_collision">
      <origin rpy="0  0  0" xyz="-0.28548  0.02197  0.04709"/>
      <geometry>
        <mesh filename="package://robots/roboy_upper_body/meshes/CAD/left_hand.stl OR robots/roboy_xylophone/meshes/CAD/left_hand.stl" scale="0.001 0.001 0.001"/>
      </geometry>
    </collision>
    <visual name="left_hand_visual">
      <origin rpy="0  0  0" xyz="-0.28548  0.02197  0.04709"/>
      <geometry>
        <mesh filename="package://robots/roboy_upper_body/meshes/CAD/left_hand.stl OR robots/roboy_xylophone/meshes/CAD/left_hand.stl" scale="0.001 0.001 0.001"/>
      </geometry>
    </visual>
  </link>
  <link name="base">
    <inertial>
      <mass value="0.895619303288162"/>
      <origin rpy="0  0  0" xyz="0  0  0"/>
      <inertia ixx="0.005931451891323691" ixy="1.8900953994598964e-05" ixz="2.0346346378697583e-05" iyy="0.014006546680403489" iyz="7.090642651324585e-06" izz="0.012622053375679834"/>
    </inertial>
    <collision name="base_collision">
      <origin rpy="0  0  0" xyz="0  0  0"/>
      <geometry>
        <mesh filename="package://robots/roboy_arcade_maschine/meshes/CAD/base.stl OR robots/roboy_upper_body/meshes/CAD/base.stl OR robots/yatr/meshes/CAD/base.stl OR robots/roboy_xylophone/meshes/CAD/base.stl OR robots/theClaw/meshes/CAD/base.stl OR robots/msj_platform/meshes/CAD/base.stl OR robots/test_robot/meshes/CAD/base.stl" scale="0.001 0.001 0.001"/>
      </geometry>
    </collision>
    <visual name="base_visual">
      <origin rpy="0  0  0" xyz="0  0  0"/>
      <geometry>
        <mesh filename="package://robots/roboy_arcade_maschine/meshes/CAD/base.stl OR robots/roboy_upper_body/meshes/CAD/base.stl OR robots/yatr/meshes/CAD/base.stl OR robots/roboy_xylophone/meshes/CAD/base.stl OR robots/theClaw/meshes/CAD/base.stl OR robots/msj_platform/meshes/CAD/base.stl OR robots/test_robot/meshes/CAD/base.stl" scale="0.001 0.001 0.001"/>
      </geometry>
    </visual>
  </link>
  <link name="torso">
    <inertial>
      <mass value="19.43689091966361"/>
      <origin rpy="0  0  0" xyz="0  0  0"/>
      <inertia ixx="4.2496697588620815" ixy="-0.001084160317835861" ixz="0.06759492365223052" iyy="4.521931880526116" iyz="-0.013201138112359028" izz="0.36830405233528385"/>
    </inertial>
    <collision name="torso_collision">
      <origin rpy="0  0  0" xyz="0      -0.00152 -0.24268"/>
      <geometry>
        <mesh filename="package://robots/RoboyLeftArm/meshes/CAD/torso.stl OR robots/roboy_upper_body/meshes/CAD/torso.stl OR robots/roboy_xylophone/meshes/CAD/torso.stl" scale="0.001 0.001 0.001"/>
      </geometry>
    </collision>
    <visual name="torso_visual">
      <origin rpy="0  0  0" xyz="0      -0.00152 -0.24268"/>
      <geometry>
        <mesh filename="package://robots/RoboyLeftArm/meshes/CAD/torso.stl OR robots/roboy_upper_body/meshes/CAD/torso.stl OR robots/roboy_xylophone/meshes/CAD/torso.stl" scale="0.001 0.001 0.001"/>
      </geometry>
    </visual>
  </link>
  <link name="elbow_left">
    <inertial>
      <mass value="0.15681537171261786"/>
      <origin rpy="0  0  0" xyz="0  0  0"/>
      <inertia ixx="0.009431757217641386" ixy="-0.00012517065328308802" ixz="-9.8884392130666e-05" iyy="0.0228655991842175" iyz="-0.011162126419118706" izz="0.013542050846467419"/>
    </inertial>
    <collision name="elbow_left_collision">
      <origin rpy="0  0  0" xyz="-0.30711  0.00101 -0.28109"/>
      <geometry>
        <mesh filename="package://robots/roboy_upper_body/meshes/CAD/elbow_left.stl OR robots/roboy_xylophone/meshes/CAD/elbow_left.stl" scale="0.001 0.001 0.001"/>
      </geometry>
    </collision>
    <visual name="elbow_left_visual">
      <origin rpy="0  0  0" xyz="-0.30711  0.00101 -0.28109"/>
      <geometry>
        <mesh filename="package://robots/roboy_upper_body/meshes/CAD/elbow_left.stl OR robots/roboy_xylophone/meshes/CAD/elbow_left.stl" scale="0.001 0.001 0.001"/>
      </geometry>
    </visual>
  </link>
  <link name="elbow_right">
    <inertial>
      <mass value="0.17375098955241783"/>
      <origin rpy="0  0  0" xyz="0  0  0"/>
      <inertia ixx="0.01019961927145588" ixy="0.000132604582364123" ixz="-0.00010416600346268335" iyy="0.025041285344660682" iyz="0.012203668184007482" izz="0.01495186246130606"/>
    </inertial>
    <collision name="elbow_right_collision">
      <origin rpy="0  0  0" xyz="0.3071   0.00103 -0.28009"/>
      <geometry>
        <mesh filename="package://robots/roboy_upper_body/meshes/CAD/elbow_right.stl OR robots/roboy_xylophone/meshes/CAD/elbow_right.stl" scale="0.001 0.001 0.001"/>
      </geometry>
    </collision>
    <visual name="elbow_right_visual">
      <origin rpy="0  0  0" xyz="0.3071   0.00103 -0.28009"/>
      <geometry>
        <mesh filename="package://robots/roboy_upper_body/meshes/CAD/elbow_right.stl OR robots/roboy_xylophone/meshes/CAD/elbow_right.stl" scale="0.001 0.001 0.001"/>
      </geometry>
    </visual>
  </link>
  <link name="sphere_right_link1">
    <inertial>
      <mass value="0.04675596089362313"/>
      <origin rpy="0  0  0" xyz="0  0  0"/>
      <inertia ixx="0.014082487940467327" ixy="0.00012582201998645568" ixz="-0.00023625123995044117" iyy="0.01807003753984725" iyz="0.0074947179360907975" izz="0.004001456143427335"/>
    </inertial>
    <collision name="sphere_right_link1_collision">
      <origin rpy="0  0  0" xyz="0.29218 -0.00921 -0.54861"/>
      <geometry>
        <mesh filename="package://robots/roboy_upper_body/meshes/CAD/sphere_right_link1.stl OR robots/roboy_xylophone/meshes/CAD/sphere_right_link1.stl" scale="0.001 0.001 0.001"/>
      </geometry>
    </collision>
    <visual name="sphere_right_link1_visual">
      <origin rpy="0  0  0" xyz="0.29218 -0.00921 -0.54861"/>
      <geometry>
        <mesh filename="package://robots/roboy_upper_body/meshes/CAD/sphere_right_link1.stl OR robots/roboy_xylophone/meshes/CAD/sphere_right_link1.stl" scale="0.001 0.001 0.001"/>
      </geometry>
    </visual>
  </link>
  <link name="sphere_right_link2">
    <inertial>
      <mass value="0.03133941577358246"/>
      <origin rpy="0  0  0" xyz="0  0  0"/>
      <inertia ixx="0.009437852970646556" ixy="8.433288313845014e-05" ixz="-0.0001583485445123758" iyy="0.012110617225243162" iyz="0.005023535852643668" izz="0.002680779380039669"/>
    </inertial>
    <collision name="sphere_right_link2_collision">
      <origin rpy="0  0  0" xyz="0.29218 -0.00921 -0.54861"/>
      <geometry>
        <mesh filename="package://robots/roboy_upper_body/meshes/CAD/sphere_right_link2.stl OR robots/roboy_xylophone/meshes/CAD/sphere_right_link2.stl" scale="0.001 0.001 0.001"/>
      </geometry>
    </collision>
    <visual name="sphere_right_link2_visual">
      <origin rpy="0  0  0" xyz="0.29218 -0.00921 -0.54861"/>
      <geometry>
        <mesh filename="package://robots/roboy_upper_body/meshes/CAD/sphere_right_link2.stl OR robots/roboy_xylophone/meshes/CAD/sphere_right_link2.stl" scale="0.001 0.001 0.001"/>
      </geometry>
    </visual>
  </link>
  <link name="sphere_left_link1">
    <inertial>
      <mass value="0.046755519327953445"/>
      <origin rpy="0  0  0" xyz="0  0  0"/>
      <inertia ixx="0.014082356273081548" ixy="-0.00012582086921548955" ixz="-0.00023624902092354817" iyy="0.018069870522316265" iyz="-0.00749464968837342" izz="0.004001420718449545"/>
    </inertial>
    <collision name="sphere_left_link1_collision">
      <origin rpy="0  0  0" xyz="-0.29218 -0.00921 -0.54861"/>
      <geometry>
        <mesh filename="package://robots/roboy_upper_body/meshes/CAD/sphere_left_link1.stl OR robots/roboy_xylophone/meshes/CAD/sphere_left_link1.stl" scale="0.001 0.001 0.001"/>
      </geometry>
    </collision>
    <visual name="sphere_left_link1_visual">
      <origin rpy="0  0  0" xyz="-0.29218 -0.00921 -0.54861"/>
      <geometry>
        <mesh filename="package://robots/roboy_upper_body/meshes/CAD/sphere_left_link1.stl OR robots/roboy_xylophone/meshes/CAD/sphere_left_link1.stl" scale="0.001 0.001 0.001"/>
      </geometry>
    </visual>
  </link>
  <link name="sphere_left_link2">
    <inertial>
      <mass value="0.031340208481721574"/>
      <origin rpy="0  0  0" xyz="0  0  0"/>
      <inertia ixx="0.009438092156368896" ixy="-8.433488846064293e-05" ixz="-0.00015835236925662997" iyy="0.012110922096803804" iyz="-0.005023661231281029" izz="0.0026808451877708057"/>
    </inertial>
    <collision name="sphere_left_link2_collision">
      <origin rpy="0  0  0" xyz="-0.29218 -0.00921 -0.54861"/>
      <geometry>
        <mesh filename="package://robots/roboy_upper_body/meshes/CAD/sphere_left_link2.stl OR robots/roboy_xylophone/meshes/CAD/sphere_left_link2.stl" scale="0.001 0.001 0.001"/>
      </geometry>
    </collision>
    <visual name="sphere_left_link2_visual">
      <origin rpy="0  0  0" xyz="-0.29218 -0.00921 -0.54861"/>
      <geometry>
        <mesh filename="package://robots/roboy_upper_body/meshes/CAD/sphere_left_link2.stl OR robots/roboy_xylophone/meshes/CAD/sphere_left_link2.stl" scale="0.001 0.001 0.001"/>
      </geometry>
    </visual>
  </link>
  <link name="wrist_left_1">
    <inertial>
      <mass value="0.012764273069100246"/>
      <origin rpy="0  0  0" xyz="0  0  0"/>
      <inertia ixx="2.9933237342887365e-05" ixy="1.631306266120424e-05" ixz="-2.60614002361967e-06" iyy="0.001058859487958565" iyz="0.00016684286591328335" izz="0.0010339769540120504"/>
    </inertial>
    <collision name="wrist_left_1_collision">
      <origin rpy="0  0  0" xyz="-0.27392  0.00515  0.04709"/>
      <geometry>
        <mesh filename="package://robots/roboy_upper_body/meshes/CAD/wrist_left_1.stl OR robots/roboy_xylophone/meshes/CAD/wrist_left_1.stl" scale="0.001 0.001 0.001"/>
      </geometry>
    </collision>
    <visual name="wrist_left_1_visual">
      <origin rpy="0  0  0" xyz="-0.27392  0.00515  0.04709"/>
      <geometry>
        <mesh filename="package://robots/roboy_upper_body/meshes/CAD/wrist_left_1.stl OR robots/roboy_xylophone/meshes/CAD/wrist_left_1.stl" scale="0.001 0.001 0.001"/>
      </geometry>
    </visual>
  </link>
  <link name="wrist_right_1">
    <inertial>
      <mass value="0.012762562533547092"/>
      <origin rpy="0  0  0" xyz="0  0  0"/>
      <inertia ixx="3.359681833187801e-05" ixy="-1.6206001652051387e-05" ixz="-2.738243211674281e-06" iyy="0.0010832076300652986" iyz="-0.00017947272958513457" izz="0.0010546398751882758"/>
    </inertial>
    <collision name="wrist_right_1_collision">
      <origin rpy="0  0  0" xyz="0.27559  0.00492  0.05063"/>
      <geometry>
        <mesh filename="package://robots/roboy_upper_body/meshes/CAD/wrist_right_1.stl OR robots/roboy_xylophone/meshes/CAD/wrist_right_1.stl" scale="0.001 0.001 0.001"/>
      </geometry>
    </collision>
    <visual name="wrist_right_1_visual">
      <origin rpy="0  0  0" xyz="0.27559  0.00492  0.05063"/>
      <geometry>
        <mesh filename="package://robots/roboy_upper_body/meshes/CAD/wrist_right_1.stl OR robots/roboy_xylophone/meshes/CAD/wrist_right_1.stl" scale="0.001 0.001 0.001"/>
      </geometry>
    </visual>
  </link>
  <link name="upper_arm_left">
    <inertial>
      <mass value="1.180906329908755"/>
      <origin rpy="0  0  0" xyz="0  0  0"/>
      <inertia ixx="0.19249904732344325" ixy="-0.0023063348715913305" ixz="-0.003089318394051035" iyy="0.29973199066407746" iyz="-0.14192245743427573" izz="0.11100085723504015"/>
    </inertial>
    <collision name="upper_arm_left_collision">
      <origin rpy="0  0  0" xyz="-0.29218 -0.00921 -0.54861"/>
      <geometry>
        <mesh filename="package://robots/RoboyLeftArm/meshes/CAD/upper_arm_left.stl OR robots/roboy_upper_body/meshes/CAD/upper_arm_left.stl OR robots/roboy_xylophone/meshes/CAD/upper_arm_left.stl" scale="0.001 0.001 0.001"/>
      </geometry>
    </collision>
    <visual name="upper_arm_left_visual">
      <origin rpy="0  0  0" xyz="-0.29218 -0.00921 -0.54861"/>
      <geometry>
        <mesh filename="package://robots/RoboyLeftArm/meshes/CAD/upper_arm_left.stl OR robots/roboy_upper_body/meshes/CAD/upper_arm_left.stl OR robots/roboy_xylophone/meshes/CAD/upper_arm_left.stl" scale="0.001 0.001 0.001"/>
      </geometry>
    </visual>
  </link>
  <link name="lower_arm_left">
    <inertial>
      <mass value="1.4159186820881702"/>
      <origin rpy="0  0  0" xyz="0  0  0"/>
      <inertia ixx="0.01972474263641184" ixy="0.00048708461746338813" ixz="3.185483018737783e-05" iyy="0.13615185243928085" iyz="-0.03856116577753052" izz="0.1177250109980131"/>
    </inertial>
    <collision name="lower_arm_left_collision">
      <origin rpy="0  0  0" xyz="-0.28834 -0.00155 -0.21497"/>
      <geometry>
        <mesh filename="package://robots/RoboyLeftArm/meshes/CAD/lower_arm_left.stl OR robots/roboy_upper_body/meshes/CAD/lower_arm_left.stl OR robots/roboy_xylophone/meshes/CAD/lower_arm_left.stl" scale="0.001 0.001 0.001"/>
      </geometry>
    </collision>
    <visual name="lower_arm_left_visual">
      <origin rpy="0  0  0" xyz="-0.28834 -0.00155 -0.21497"/>
      <geometry>
        <mesh filename="package://robots/RoboyLeftArm/meshes/CAD/lower_arm_left.stl OR robots/roboy_upper_body/meshes/CAD/lower_arm_left.stl OR robots/roboy_xylophone/meshes/CAD/lower_arm_left.stl" scale="0.001 0.001 0.001"/>
      </geometry>
    </visual>
  </link>
  <link name="lower_arm_right">
    <inertial>
      <mass value="1.3992272098398935"/>
      <origin rpy="0  0  0" xyz="0  0  0"/>
      <inertia ixx="0.01810985648977934" ixy="-0.0005191321679580289" ixz="4.0051155010876476e-05" iyy="0.13328127304385734" iyz="0.03631106564930123" izz="0.11646776713622452"/>
    </inertial>
    <collision name="lower_arm_right_collision">
      <origin rpy="0  0  0" xyz="0.28833 -0.00153 -0.21397"/>
      <geometry>
        <mesh filename="package://robots/roboy_upper_body/meshes/CAD/lower_arm_right.stl OR robots/roboy_xylophone/meshes/CAD/lower_arm_right.stl" scale="0.001 0.001 0.001"/>
      </geometry>
    </collision>
    <visual name="lower_arm_right_visual">
      <origin rpy="0  0  0" xyz="0.28833 -0.00153 -0.21397"/>
      <geometry>
        <mesh filename="package://robots/roboy_upper_body/meshes/CAD/lower_arm_right.stl OR robots/roboy_xylophone/meshes/CAD/lower_arm_right.stl" scale="0.001 0.001 0.001"/>
      </geometry>
    </visual>
  </link>
  <link name="upper_arm_right">
    <inertial>
      <mass value="1.0958327493576097"/>
      <origin rpy="0  0  0" xyz="0  0  0"/>
      <inertia ixx="0.179042496682244" ixy="0.0013739028297246301" ixz="-0.001880249463770289" iyy="0.2781451232700294" iyz="0.13162899491955163" izz="0.1025794118324868"/>
    </inertial>
    <collision name="upper_arm_right_collision">
      <origin rpy="0  0  0" xyz="0.29218 -0.00921 -0.54861"/>
      <geometry>
        <mesh filename="package://robots/roboy_upper_body/meshes/CAD/upper_arm_right.stl OR robots/roboy_xylophone/meshes/CAD/upper_arm_right.stl" scale="0.001 0.001 0.001"/>
      </geometry>
    </collision>
    <visual name="upper_arm_right_visual">
      <origin rpy="0  0  0" xyz="0.29218 -0.00921 -0.54861"/>
      <geometry>
        <mesh filename="package://robots/roboy_upper_body/meshes/CAD/upper_arm_right.stl OR robots/roboy_xylophone/meshes/CAD/upper_arm_right.stl" scale="0.001 0.001 0.001"/>
      </geometry>
    </visual>
  </link>
  <link name="zed_camera_left_lense">
    <inertial>
      <mass value="0.0057554218156879965"/>
      <origin rpy="0  0  0" xyz="0  0  0"/>
      <inertia ixx="0.004846011997714692" ixy="3.881518938735634e-05" ixz="0.0005891027444713397" iyy="0.004793831227370645" iyz="-0.000314480744284707" izz="9.383240644717274e-05"/>
    </inertial>
    <collision name="zed_camera_left_lense_collision">
      <origin rpy="0  0  0" xyz="-0.05998  0.10108 -0.91065"/>
      <geometry>
        <mesh filename="package://robots/roboy_upper_body/meshes/CAD/zed_camera_left_lense.stl OR robots/roboy_xylophone/meshes/CAD/zed_camera_left_lense.stl" scale="0.001 0.001 0.001"/>
      </geometry>
    </collision>
    <visual name="zed_camera_left_lense_visual">
      <origin rpy="0  0  0" xyz="-0.05998  0.10108 -0.91065"/>
      <geometry>
        <mesh filename="package://robots/roboy_upper_body/meshes/CAD/zed_camera_left_lense.stl OR robots/roboy_xylophone/meshes/CAD/zed_camera_left_lense.stl" scale="0.001 0.001 0.001"/>
      </geometry>
    </visual>
  </link>
  <link name="zed_camera_right_lense">
    <inertial>
      <mass value="0.0057554218156880485"/>
      <origin rpy="0  0  0" xyz="0  0  0"/>
      <inertia ixx="0.004846011997551049" ixy="-3.881429332761528e-05" ixz="0.0005891027444611853" iyy="0.004793830279485115" iyz="0.00031447355054664474" izz="9.383145872528843e-05"/>
    </inertial>
    <collision name="zed_camera_right_lense_collision">
      <origin rpy="0  0  0" xyz="0.06     0.10108 -0.91065"/>
      <geometry>
        <mesh filename="package://robots/roboy_upper_body/meshes/CAD/zed_camera_right_lense.stl OR robots/roboy_xylophone/meshes/CAD/zed_camera_right_lense.stl" scale="0.001 0.001 0.001"/>
      </geometry>
    </collision>
    <visual name="zed_camera_right_lense_visual">
      <origin rpy="0  0  0" xyz="0.06     0.10108 -0.91065"/>
      <geometry>
        <mesh filename="package://robots/roboy_upper_body/meshes/CAD/zed_camera_right_lense.stl OR robots/roboy_xylophone/meshes/CAD/zed_camera_right_lense.stl" scale="0.001 0.001 0.001"/>
      </geometry>
    </visual>
  </link>
  <link name="zed_camera">
    <inertial>
      <mass value="0.009633908092012306"/>
      <origin rpy="0  0  0" xyz="0  0  0"/>
      <inertia ixx="0.008084590483556824" ixy="4.052560334214878e-06" ixz="0.0008835532966109025" iyy="0.008001682762379227" iyz="-3.558756214861936e-05" izz="0.00011263547643344076"/>
    </inertial>
    <collision name="zed_camera_collision">
      <origin rpy="0  0  0" xyz="-0.0215   0.10108 -0.91865"/>
      <geometry>
        <mesh filename="package://robots/roboy_upper_body/meshes/CAD/zed_camera.stl OR robots/roboy_xylophone/meshes/CAD/zed_camera.stl" scale="0.001 0.001 0.001"/>
      </geometry>
    </collision>
    <visual name="zed_camera_visual">
      <origin rpy="0  0  0" xyz="-0.0215   0.10108 -0.91865"/>
      <geometry>
        <mesh filename="package://robots/roboy_upper_body/meshes/CAD/zed_camera.stl OR robots/roboy_xylophone/meshes/CAD/zed_camera.stl" scale="0.001 0.001 0.001"/>
      </geometry>
    </visual>
  </link>
  <link name="sphere_head_link1">
    <inertial>
      <mass value="0.023938100802369734"/>
      <origin rpy="0  0  0" xyz="0  0  0"/>
      <inertia ixx="0.012106595625813408" ixy="7.508425305113864e-19" ixz="-2.5904304543214497e-05" iyy="0.012106540189536562" iyz="3.5051683777709287e-16" izz="2.012994235293797e-06"/>
    </inertial>
    <collision name="sphere_head_link1_collision">
      <origin rpy="0  0  0" xyz="0      -0.00152 -0.71109"/>
      <geometry>
        <mesh filename="package://robots/roboy_upper_body/meshes/CAD/sphere_head_link1.stl OR robots/roboy_xylophone/meshes/CAD/sphere_head_link1.stl" scale="0.001 0.001 0.001"/>
      </geometry>
    </collision>
    <visual name="sphere_head_link1_visual">
      <origin rpy="0  0  0" xyz="0      -0.00152 -0.71109"/>
      <geometry>
        <mesh filename="package://robots/roboy_upper_body/meshes/CAD/sphere_head_link1.stl OR robots/roboy_xylophone/meshes/CAD/sphere_head_link1.stl" scale="0.001 0.001 0.001"/>
      </geometry>
    </visual>
  </link>
  <link name="shere_head_link2">
    <inertial>
      <mass value="0.016046417516495697"/>
      <origin rpy="0  0  0" xyz="0  0  0"/>
      <inertia ixx="0.008114981473636663" ixy="5.028583886096394e-19" ixz="-1.7364422082044644e-05" iyy="0.008114944313059423" iyz="2.348427008413978e-16" izz="9.214497104106419e-07"/>
    </inertial>
    <collision name="shere_head_link2_collision">
      <origin rpy="0  0  0" xyz="0      -0.00152 -0.71109"/>
      <geometry>
        <mesh filename="package://robots/roboy_upper_body/meshes/CAD/shere_head_link2.stl OR robots/roboy_xylophone/meshes/CAD/shere_head_link2.stl" scale="0.001 0.001 0.001"/>
      </geometry>
    </collision>
    <visual name="shere_head_link2_visual">
      <origin rpy="0  0  0" xyz="0      -0.00152 -0.71109"/>
      <geometry>
        <mesh filename="package://robots/roboy_upper_body/meshes/CAD/shere_head_link2.stl OR robots/roboy_xylophone/meshes/CAD/shere_head_link2.stl" scale="0.001 0.001 0.001"/>
      </geometry>
    </visual>
  </link>
  <link name="head">
    <inertial>
      <mass value="2.0664381552877646"/>
      <origin rpy="0  0  0" xyz="0  0  0"/>
      <inertia ixx="1.5846048067305147" ixy="-2.8828445995306153e-05" ixz="-0.029442702319180492" iyy="1.5788965104892616" iyz="-0.001288434670190506" izz="0.025550832000819562"/>
    </inertial>
    <collision name="head_collision">
      <origin rpy="0  0  0" xyz="0      -0.00152 -0.71109"/>
      <geometry>
        <mesh filename="package://robots/roboy_arcade_maschine/meshes/CAD/head.stl OR robots/roboy_upper_body/meshes/CAD/head.stl OR robots/roboy_xylophone/meshes/CAD/head.stl" scale="0.001 0.001 0.001"/>
      </geometry>
    </collision>
    <visual name="head_visual">
      <origin rpy="0  0  0" xyz="0      -0.00152 -0.71109"/>
      <geometry>
        <mesh filename="package://robots/roboy_arcade_maschine/meshes/CAD/head.stl OR robots/roboy_upper_body/meshes/CAD/head.stl OR robots/roboy_xylophone/meshes/CAD/head.stl" scale="0.001 0.001 0.001"/>
      </geometry>
    </visual>
  </link>
  <link name="left_stick_tip">
    <inertial>
      <mass value="0.026023156971151304"/>
      <origin rpy="0  0  0" xyz="0  0  0"/>
      <inertia ixx="0.0030555442570330566" ixy="0.0019320978532239466" ixz="-0.0014587537400506567" iyy="0.002962679652716561" iyz="0.0014240795271705236" izz="0.0038662816743842217"/>
    </inertial>
    <collision name="left_stick_tip_collision">
      <origin rpy="0  0  0" xyz="-0.26921  0.27151  0.20213"/>
      <geometry>
        <mesh filename="package://robots/roboy_upper_body/meshes/CAD/left_stick_tip.stl OR robots/roboy_xylophone/meshes/CAD/left_stick_tip.stl" scale="0.001 0.001 0.001"/>
      </geometry>
    </collision>
    <visual name="left_stick_tip_visual">
      <origin rpy="0  0  0" xyz="-0.26921  0.27151  0.20213"/>
      <geometry>
        <mesh filename="package://robots/roboy_upper_body/meshes/CAD/left_stick_tip.stl OR robots/roboy_xylophone/meshes/CAD/left_stick_tip.stl" scale="0.001 0.001 0.001"/>
      </geometry>
    </visual>
  </link>
  <link name="right_stick_tip">
    <inertial>
      <mass value="0.026023156971154107"/>
      <origin rpy="0  0  0" xyz="0  0  0"/>
      <inertia ixx="0.0030548926832994505" ixy="-0.0019522723505767325" ixz="-0.0014588184035582042" iyy="0.003004799357065121" iyz="-0.0014401715227325498" izz="0.0039058346651765483"/>
    </inertial>
    <collision name="right_stick_tip_collision">
      <origin rpy="0  0  0" xyz="0.27209  0.2713   0.20219"/>
      <geometry>
        <mesh filename="package://robots/roboy_upper_body/meshes/CAD/right_stick_tip.stl OR robots/roboy_xylophone/meshes/CAD/right_stick_tip.stl" scale="0.001 0.001 0.001"/>
      </geometry>
    </collision>
    <visual name="right_stick_tip_visual">
      <origin rpy="0  0  0" xyz="0.27209  0.2713   0.20219"/>
      <geometry>
        <mesh filename="package://robots/roboy_upper_body/meshes/CAD/right_stick_tip.stl OR robots/roboy_xylophone/meshes/CAD/right_stick_tip.stl" scale="0.001 0.001 0.001"/>
      </geometry>
    </visual>
  </link>
  <link name="spine_v0_sphere_link1">
    <inertial>
      <mass value="0.006868749968312682"/>
      <origin rpy="0  0  0" xyz="0  0  0"/>
      <inertia ixx="0.00018655788948137772" ixy="-7.318364664277155e-23" ixz="-1.7214511119186968e-06" iyy="0.0001865419827088242" iyz="-5.984795992119985e-21" izz="2.6026557599302e-07"/>
    </inertial>
    <collision name="spine_v0_sphere_link1_collision">
      <origin rpy="0  0  0" xyz="0      -0.00152 -0.16468"/>
      <geometry>
        <mesh filename="package://robots/roboy_upper_body/meshes/CAD/spine_v0_sphere_link1.stl" scale="0.001 0.001 0.001"/>
      </geometry>
    </collision>
    <visual name="spine_v0_sphere_link1_visual">
      <origin rpy="0  0  0" xyz="0      -0.00152 -0.16468"/>
      <geometry>
        <mesh filename="package://robots/roboy_upper_body/meshes/CAD/spine_v0_sphere_link1.stl" scale="0.001 0.001 0.001"/>
      </geometry>
    </visual>
  </link>
  <link name="spine_v0_sphere_link2">
    <inertial>
      <mass value="0.004604326339669925"/>
      <origin rpy="0  0  0" xyz="0  0  0"/>
      <inertia ixx="0.00012500185666920944" ixy="4.404571325722362e-24" ixz="-1.1539395924929318e-06" iyy="0.00012499119389076097" iyz="-4.6837533851373794e-21" izz="1.2104716504802298e-07"/>
    </inertial>
    <collision name="spine_v0_sphere_link2_collision">
      <origin rpy="0  0  0" xyz="0      -0.00152 -0.16468"/>
      <geometry>
        <mesh filename="package://robots/roboy_upper_body/meshes/CAD/spine_v0_sphere_link2.stl" scale="0.001 0.001 0.001"/>
      </geometry>
    </collision>
    <visual name="spine_v0_sphere_link2_visual">
      <origin rpy="0  0  0" xyz="0      -0.00152 -0.16468"/>
      <geometry>
        <mesh filename="package://robots/roboy_upper_body/meshes/CAD/spine_v0_sphere_link2.stl" scale="0.001 0.001 0.001"/>
      </geometry>
    </visual>
  </link>
  <link name="spine_v1_sphere_link1">
    <inertial>
      <mass value="0.006868749968312679"/>
      <origin rpy="0  0  0" xyz="0  0  0"/>
      <inertia ixx="0.0002852394911137051" ixy="-8.131516293641284e-24" ixz="-2.129107729333681e-06" iyy="0.00028522358434115167" iyz="-9.454242944073599e-21" izz="2.602655759930154e-07"/>
    </inertial>
    <collision name="spine_v1_sphere_link1_collision">
      <origin rpy="0  0  0" xyz="0      -0.00152 -0.20368"/>
      <geometry>
        <mesh filename="package://robots/roboy_upper_body/meshes/CAD/spine_v1_sphere_link1.stl" scale="0.001 0.001 0.001"/>
      </geometry>
    </collision>
    <visual name="spine_v1_sphere_link1_visual">
      <origin rpy="0  0  0" xyz="0      -0.00152 -0.20368"/>
      <geometry>
        <mesh filename="package://robots/roboy_upper_body/meshes/CAD/spine_v1_sphere_link1.stl" scale="0.001 0.001 0.001"/>
      </geometry>
    </visual>
  </link>
  <link name="spine_v1_sphere_link2">
    <inertial>
      <mass value="0.004604326339669925"/>
      <origin rpy="0  0  0" xyz="0  0  0"/>
      <inertia ixx="0.00019115105406745567" ixy="-3.6591823321385777e-23" ixz="-1.4272038799078502e-06" iyy="0.00019114039128900715" iyz="-4.4235448637408584e-21" izz="1.2104716504802018e-07"/>
    </inertial>
    <collision name="spine_v1_sphere_link2_collision">
      <origin rpy="0  0  0" xyz="0      -0.00152 -0.20368"/>
      <geometry>
        <mesh filename="package://robots/roboy_upper_body/meshes/CAD/spine_v1_sphere_link2.stl" scale="0.001 0.001 0.001"/>
      </geometry>
    </collision>
    <visual name="spine_v1_sphere_link2_visual">
      <origin rpy="0  0  0" xyz="0      -0.00152 -0.20368"/>
      <geometry>
        <mesh filename="package://robots/roboy_upper_body/meshes/CAD/spine_v1_sphere_link2.stl" scale="0.001 0.001 0.001"/>
      </geometry>
    </visual>
  </link>
  <link name="spine_v2_sphere_link1">
    <inertial>
      <mass value="0.006868749968312682"/>
      <origin rpy="0  0  0" xyz="0  0  0"/>
      <inertia ixx="0.0004048158301496406" ixy="-1.1384122811097798e-22" ixz="-2.5367643467485574e-06" iyy="0.00040479992337708704" iyz="-6.765421556309548e-21" izz="2.6026557599301153e-07"/>
    </inertial>
    <collision name="spine_v2_sphere_link1_collision">
      <origin rpy="0  0  0" xyz="0      -0.00152 -0.24268"/>
      <geometry>
        <mesh filename="package://robots/roboy_upper_body/meshes/CAD/spine_v2_sphere_link1.stl" scale="0.001 0.001 0.001"/>
      </geometry>
    </collision>
    <visual name="spine_v2_sphere_link1_visual">
      <origin rpy="0  0  0" xyz="0      -0.00152 -0.24268"/>
      <geometry>
        <mesh filename="package://robots/roboy_upper_body/meshes/CAD/spine_v2_sphere_link1.stl" scale="0.001 0.001 0.001"/>
      </geometry>
    </visual>
  </link>
  <link name="spine_v2_sphere_link2">
    <inertial>
      <mass value="0.004604326339669924"/>
      <origin rpy="0  0  0" xyz="0  0  0"/>
      <inertia ixx="0.00027130661219097773" ixy="-3.3881317890172014e-23" ixz="-1.7004681673226978e-06" iyy="0.0002712959494125292" iyz="-5.4643789493269424e-21" izz="1.210471650480173e-07"/>
    </inertial>
    <collision name="spine_v2_sphere_link2_collision">
      <origin rpy="0  0  0" xyz="0      -0.00152 -0.24268"/>
      <geometry>
        <mesh filename="package://robots/roboy_upper_body/meshes/CAD/spine_v2_sphere_link2.stl" scale="0.001 0.001 0.001"/>
      </geometry>
    </collision>
    <visual name="spine_v2_sphere_link2_visual">
      <origin rpy="0  0  0" xyz="0      -0.00152 -0.24268"/>
      <geometry>
        <mesh filename="package://robots/roboy_upper_body/meshes/CAD/spine_v2_sphere_link2.stl" scale="0.001 0.001 0.001"/>
      </geometry>
    </visual>
  </link>
  <link name="spine_link1">
    <inertial>
      <mass value="0.02804796014044654"/>
      <origin rpy="0  0  0" xyz="0  0  0"/>
      <inertia ixx="0.0009903562452458544" ixy="3.7433530622864464e-11" ixz="-8.403341501542152e-06" iyy="0.0009902808158141123" iyz="5.321713939381718e-09" izz="2.4706204956731896e-06"/>
    </inertial>
    <collision name="spine_link1_collision">
      <origin rpy="0  0  0" xyz="0      -0.00152 -0.16468"/>
      <geometry>
        <mesh filename="package://robots/roboy_upper_body/meshes/CAD/spine_link1.stl" scale="0.001 0.001 0.001"/>
      </geometry>
    </collision>
    <visual name="spine_link1_visual">
      <origin rpy="0  0  0" xyz="0      -0.00152 -0.16468"/>
      <geometry>
        <mesh filename="package://robots/roboy_upper_body/meshes/CAD/spine_link1.stl" scale="0.001 0.001 0.001"/>
      </geometry>
    </visual>
  </link>
  <link name="spine_link2">
    <inertial>
      <mass value="0.023084394447634406"/>
      <origin rpy="0  0  0" xyz="0  0  0"/>
      <inertia ixx="0.0011507714882796798" ixy="3.849444054000353e-11" ixz="-3.33986085040153e-06" iyy="0.0011507700283837647" iyz="6.561646995943951e-09" izz="2.1587972930588084e-06"/>
    </inertial>
    <collision name="spine_link2_collision">
      <origin rpy="0  0  0" xyz="0      -0.00152 -0.20368"/>
      <geometry>
        <mesh filename="package://robots/roboy_upper_body/meshes/CAD/spine_link2.stl" scale="0.001 0.001 0.001"/>
      </geometry>
    </collision>
    <visual name="spine_link2_visual">
      <origin rpy="0  0  0" xyz="0      -0.00152 -0.20368"/>
      <geometry>
        <mesh filename="package://robots/roboy_upper_body/meshes/CAD/spine_link2.stl" scale="0.001 0.001 0.001"/>
      </geometry>
    </visual>
  </link>
</robot>
