<?xml version="1.0" ?>
<sdf version="1.6">
	<model name="roboy_upper_body">
		<link name="torso">
			<self_collide>false</self_collide>
			<pose frame="">0.0 0.0 0.0 0.0 -0.0 0.0</pose>
			<inertial>
				<pose frame="">0.0 0.0 0.0 0 0 0</pose>
				<mass>20.24152166706708</mass>
				<inertia>
					<ixx>4.343742899078967</ixx>
					<ixy>-0.0010950579291103622</ixy>
					<ixz>0.05287132986599386</ixz>
					<iyy>4.620866749124458</iyy>
					<iyz>-0.013219390676201115</iyz>
					<izz>0.3801436035505532</izz>
				</inertia>
			</inertial>
			<collision name="torso_collision">
				<geometry>
					<mesh>
						<uri>model://roboy_upper_body/meshes/CAD/torso.stl</uri>
						<scale>0.001 0.001 0.001</scale>
					</mesh>
				</geometry>
			</collision>
			<visual name="torso_visual">
				<geometry>
					<mesh>
						<uri>model://roboy_upper_body/meshes/CAD/torso.stl</uri>
						<scale>0.001 0.001 0.001</scale>
					</mesh>
				</geometry>
			</visual>
		</link>
		<link name="right_hand">
			<self_collide>false</self_collide>
			<pose frame="">-0.2698510367085325 -0.0017499434157416084 -0.1302469819688276 0.0 -0.0 0.0</pose>
			<inertial>
				<pose frame="">0.0 0.0 0.0 0 0 0</pose>
				<mass>0.20805908239892756</mass>
				<inertia>
					<ixx>0.007556710984265264</ixx>
					<ixy>-0.0038709486823734498</ixy>
					<ixz>-0.0027023479542116224</ixz>
					<iyy>0.019913740298210598</iyy>
					<iyz>-0.007625792387378484</iyz>
					<izz>0.018971657099664915</izz>
				</inertia>
			</inertial>
			<collision name="right_hand_collision">
				<geometry>
					<mesh>
						<uri>model://roboy_upper_body/meshes/CAD/right_hand.stl</uri>
						<scale>0.001 0.001 0.001</scale>
					</mesh>
				</geometry>
			</collision>
			<visual name="right_hand_visual">
				<geometry>
					<mesh>
						<uri>model://roboy_upper_body/meshes/CAD/right_hand.stl</uri>
						<scale>0.001 0.001 0.001</scale>
					</mesh>
				</geometry>
			</visual>
		</link>
		<link name="left_hand">
			<self_collide>false</self_collide>
			<pose frame="">0.2697594900165811 -0.006792324262862302 -0.1314462184560031 0.0 -0.0 0.0</pose>
			<inertial>
				<pose frame="">0.0 0.0 0.0 0 0 0</pose>
				<mass>0.1865043396217815</mass>
				<inertia>
					<ixx>0.007424110818204271</ixx>
					<ixy>0.0038015046666225495</ixy>
					<ixz>-0.0026936612177736836</ixz>
					<iyy>0.01767984161209808</iyy>
					<iyz>0.007164025065684021</iyz>
					<izz>0.016872438514383078</izz>
				</inertia>
			</inertial>
			<collision name="left_hand_collision">
				<geometry>
					<mesh>
						<uri>model://roboy_upper_body/meshes/CAD/left_hand.stl</uri>
						<scale>0.001 0.001 0.001</scale>
					</mesh>
				</geometry>
			</collision>
			<visual name="left_hand_visual">
				<geometry>
					<mesh>
						<uri>model://roboy_upper_body/meshes/CAD/left_hand.stl</uri>
						<scale>0.001 0.001 0.001</scale>
					</mesh>
				</geometry>
			</visual>
		</link>
		<link name="base">
			<self_collide>false</self_collide>
			<pose frame="">0.0 0.0 0.0 0.0 -0.0 0.0</pose>
			<inertial>
				<pose frame="">0.0 0.0 0.0 0 0 0</pose>
				<mass>0.8908272188970279</mass>
				<inertia>
					<ixx>0.005801295996739818</ixx>
					<ixy>1.8900953728145e-05</ixy>
					<ixz>1.81498952383611e-05</ixz>
					<iyy>0.013876339097366424</iyy>
					<iyz>7.090642088150171e-06</iyz>
					<izz>0.012621867825241497</izz>
				</inertia>
			</inertial>
			<collision name="base_collision">
				<geometry>
					<mesh>
						<uri>model://roboy_upper_body/meshes/CAD/base.stl</uri>
						<scale>0.001 0.001 0.001</scale>
					</mesh>
				</geometry>
			</collision>
			<visual name="base_visual">
				<geometry>
					<mesh>
						<uri>model://roboy_upper_body/meshes/CAD/base.stl</uri>
						<scale>0.001 0.001 0.001</scale>
					</mesh>
				</geometry>
			</visual>
		</link>
		<link name="elbow_left">
			<self_collide>false</self_collide>
			<pose frame="">0.2924609988878703 0.0026742978127753526 0.24368519978311523 0.0 -0.0 0.0</pose>
			<inertial>
				<pose frame="">0.0 0.0 0.0 0 0 0</pose>
				<mass>0.15681537171261786</mass>
				<inertia>
					<ixx>0.009431757217641386</ixx>
					<ixy>-0.00012517065328308802</ixy>
					<ixz>-9.8884392130666e-05</ixz>
					<iyy>0.0228655991842175</iyy>
					<iyz>-0.011162126419118706</iyz>
					<izz>0.013542050846467419</izz>
				</inertia>
			</inertial>
			<collision name="elbow_left_collision">
				<geometry>
					<mesh>
						<uri>model://roboy_upper_body/meshes/CAD/elbow_left.stl</uri>
						<scale>0.001 0.001 0.001</scale>
					</mesh>
				</geometry>
			</collision>
			<visual name="elbow_left_visual">
				<geometry>
					<mesh>
						<uri>model://roboy_upper_body/meshes/CAD/elbow_left.stl</uri>
						<scale>0.001 0.001 0.001</scale>
					</mesh>
				</geometry>
			</visual>
		</link>
		<link name="elbow_right">
			<self_collide>false</self_collide>
			<pose frame="">-0.29205436561642706 0.002562136866253571 0.2407449775865269 0.0 -0.0 0.0</pose>
			<inertial>
				<pose frame="">0.0 0.0 0.0 0 0 0</pose>
				<mass>0.17375098955241783</mass>
				<inertia>
					<ixx>0.01019961927145588</ixx>
					<ixy>0.000132604582364123</ixy>
					<ixz>-0.00010416600346268335</ixz>
					<iyy>0.025041285344660682</iyy>
					<iyz>0.012203668184007482</iyz>
					<izz>0.01495186246130606</izz>
				</inertia>
			</inertial>
			<collision name="elbow_right_collision">
				<geometry>
					<mesh>
						<uri>model://roboy_upper_body/meshes/CAD/elbow_right.stl</uri>
						<scale>0.001 0.001 0.001</scale>
					</mesh>
				</geometry>
			</collision>
			<visual name="elbow_right_visual">
				<geometry>
					<mesh>
						<uri>model://roboy_upper_body/meshes/CAD/elbow_right.stl</uri>
						<scale>0.001 0.001 0.001</scale>
					</mesh>
				</geometry>
			</visual>
		</link>
		<link name="sphere_right_link1">
			<self_collide>false</self_collide>
			<pose frame="">-0.2921799666276168 0.009210203783611735 0.548615244082417 0.0 -0.0 0.0</pose>
			<inertial>
				<pose frame="">0.0 0.0 0.0 0 0 0</pose>
				<mass>0.04675596089362313</mass>
				<inertia>
					<ixx>0.014082487940467327</ixx>
					<ixy>0.00012582201998645568</ixy>
					<ixz>-0.00023625123995044117</ixz>
					<iyy>0.01807003753984725</iyy>
					<iyz>0.0074947179360907975</iyz>
					<izz>0.004001456143427335</izz>
				</inertia>
			</inertial>
			<collision name="sphere_right_link1_collision">
				<geometry>
					<mesh>
						<uri>model://roboy_upper_body/meshes/CAD/sphere_right_link1.stl</uri>
						<scale>0.001 0.001 0.001</scale>
					</mesh>
				</geometry>
			</collision>
			<visual name="sphere_right_link1_visual">
				<geometry>
					<mesh>
						<uri>model://roboy_upper_body/meshes/CAD/sphere_right_link1.stl</uri>
						<scale>0.001 0.001 0.001</scale>
					</mesh>
				</geometry>
			</visual>
		</link>
		<link name="sphere_right_link2">
			<self_collide>false</self_collide>
			<pose frame="">-0.2921801724945091 0.009209908408672508 0.5486152414548352 0.0 -0.0 0.0</pose>
			<inertial>
				<pose frame="">0.0 0.0 0.0 0 0 0</pose>
				<mass>0.03133941577358246</mass>
				<inertia>
					<ixx>0.009437852970646556</ixx>
					<ixy>8.433288313845014e-05</ixy>
					<ixz>-0.0001583485445123758</ixz>
					<iyy>0.012110617225243162</iyy>
					<iyz>0.005023535852643668</iyz>
					<izz>0.002680779380039669</izz>
				</inertia>
			</inertial>
			<collision name="sphere_right_link2_collision">
				<geometry>
					<mesh>
						<uri>model://roboy_upper_body/meshes/CAD/sphere_right_link2.stl</uri>
						<scale>0.001 0.001 0.001</scale>
					</mesh>
				</geometry>
			</collision>
			<visual name="sphere_right_link2_visual">
				<geometry>
					<mesh>
						<uri>model://roboy_upper_body/meshes/CAD/sphere_right_link2.stl</uri>
						<scale>0.001 0.001 0.001</scale>
					</mesh>
				</geometry>
			</visual>
		</link>
		<link name="sphere_left_link1">
			<self_collide>false</self_collide>
			<pose frame="">0.29218005222734156 0.009210203825021935 0.5486152687569047 0.0 -0.0 0.0</pose>
			<inertial>
				<pose frame="">0.0 0.0 0.0 0 0 0</pose>
				<mass>0.046755519327953445</mass>
				<inertia>
					<ixx>0.014082356273081548</ixx>
					<ixy>-0.00012582086921548955</ixy>
					<ixz>-0.00023624902092354817</ixz>
					<iyy>0.018069870522316265</iyy>
					<iyz>-0.00749464968837342</iyz>
					<izz>0.004001420718449545</izz>
				</inertia>
			</inertial>
			<collision name="sphere_left_link1_collision">
				<geometry>
					<mesh>
						<uri>model://roboy_upper_body/meshes/CAD/sphere_left_link1.stl</uri>
						<scale>0.001 0.001 0.001</scale>
					</mesh>
				</geometry>
			</collision>
			<visual name="sphere_left_link1_visual">
				<geometry>
					<mesh>
						<uri>model://roboy_upper_body/meshes/CAD/sphere_left_link1.stl</uri>
						<scale>0.001 0.001 0.001</scale>
					</mesh>
				</geometry>
			</visual>
		</link>
		<link name="sphere_left_link2">
			<self_collide>false</self_collide>
			<pose frame="">0.2921800660285928 0.009209897632250984 0.5486152570091472 0.0 -0.0 0.0</pose>
			<inertial>
				<pose frame="">0.0 0.0 0.0 0 0 0</pose>
				<mass>0.031340208481721574</mass>
				<inertia>
					<ixx>0.009438092156368896</ixx>
					<ixy>-8.433488846064293e-05</ixy>
					<ixz>-0.00015835236925662997</ixz>
					<iyy>0.012110922096803804</iyy>
					<iyz>-0.005023661231281029</iyz>
					<izz>0.0026808451877708057</izz>
				</inertia>
			</inertial>
			<collision name="sphere_left_link2_collision">
				<geometry>
					<mesh>
						<uri>model://roboy_upper_body/meshes/CAD/sphere_left_link2.stl</uri>
						<scale>0.001 0.001 0.001</scale>
					</mesh>
				</geometry>
			</collision>
			<visual name="sphere_left_link2_visual">
				<geometry>
					<mesh>
						<uri>model://roboy_upper_body/meshes/CAD/sphere_left_link2.stl</uri>
						<scale>0.001 0.001 0.001</scale>
					</mesh>
				</geometry>
			</visual>
		</link>
		<link name="wrist_left_1">
			<self_collide>false</self_collide>
			<pose frame="">0.2838291081215929 -0.004517829187733993 -0.0460263795467499 0.0 -0.0 0.0</pose>
			<inertial>
				<pose frame="">0.0 0.0 0.0 0 0 0</pose>
				<mass>0.012764273069100246</mass>
				<inertia>
					<ixx>2.9933237342887365e-05</ixx>
					<ixy>1.631306266120424e-05</ixy>
					<ixz>-2.60614002361967e-06</ixz>
					<iyy>0.001058859487958565</iyy>
					<iyz>0.00016684286591328335</iyz>
					<izz>0.0010339769540120504</izz>
				</inertia>
			</inertial>
			<collision name="wrist_left_1_collision">
				<geometry>
					<mesh>
						<uri>model://roboy_upper_body/meshes/CAD/wrist_left_1.stl</uri>
						<scale>0.001 0.001 0.001</scale>
					</mesh>
				</geometry>
			</collision>
			<visual name="wrist_left_1_visual">
				<geometry>
					<mesh>
						<uri>model://roboy_upper_body/meshes/CAD/wrist_left_1.stl</uri>
						<scale>0.001 0.001 0.001</scale>
					</mesh>
				</geometry>
			</visual>
		</link>
		<link name="wrist_right_1">
			<self_collide>false</self_collide>
			<pose frame="">-0.2866867429541466 -0.004439510879921008 -0.04905987848597987 0.0 -0.0 0.0</pose>
			<inertial>
				<pose frame="">0.0 0.0 0.0 0 0 0</pose>
				<mass>0.012762562533547092</mass>
				<inertia>
					<ixx>3.359681833187801e-05</ixx>
					<ixy>-1.6206001652051387e-05</ixy>
					<ixz>-2.738243211674281e-06</ixz>
					<iyy>0.0010832076300652986</iyy>
					<iyz>-0.00017947272958513457</iyz>
					<izz>0.0010546398751882758</izz>
				</inertia>
			</inertial>
			<collision name="wrist_right_1_collision">
				<geometry>
					<mesh>
						<uri>model://roboy_upper_body/meshes/CAD/wrist_right_1.stl</uri>
						<scale>0.001 0.001 0.001</scale>
					</mesh>
				</geometry>
			</collision>
			<visual name="wrist_right_1_visual">
				<geometry>
					<mesh>
						<uri>model://roboy_upper_body/meshes/CAD/wrist_right_1.stl</uri>
						<scale>0.001 0.001 0.001</scale>
					</mesh>
				</geometry>
			</visual>
		</link>
		<link name="upper_arm_left">
			<self_collide>false</self_collide>
			<pose frame="">0.30316149801185677 0.006609366620456846 0.3970754157042611 0.0 -0.0 0.0</pose>
			<inertial>
				<pose frame="">0.0 0.0 0.0 0 0 0</pose>
				<mass>1.180906329908755</mass>
				<inertia>
					<ixx>0.19249904732344325</ixx>
					<ixy>-0.0023063348715913305</ixy>
					<ixz>-0.003089318394051035</ixz>
					<iyy>0.29973199066407746</iyy>
					<iyz>-0.14192245743427573</iyz>
					<izz>0.11100085723504015</izz>
				</inertia>
			</inertial>
			<collision name="upper_arm_left_collision">
				<geometry>
					<mesh>
						<uri>model://roboy_upper_body/meshes/CAD/upper_arm_left.stl</uri>
						<scale>0.001 0.001 0.001</scale>
					</mesh>
				</geometry>
			</collision>
			<visual name="upper_arm_left_visual">
				<geometry>
					<mesh>
						<uri>model://roboy_upper_body/meshes/CAD/upper_arm_left.stl</uri>
						<scale>0.001 0.001 0.001</scale>
					</mesh>
				</geometry>
			</visual>
		</link>
		<link name="lower_arm_left">
			<self_collide>false</self_collide>
			<pose frame="">0.2867576752988603 -0.0012029774645435035 0.09482915225116281 0.0 -0.0 0.0</pose>
			<inertial>
				<pose frame="">0.0 0.0 0.0 0 0 0</pose>
				<mass>1.4159186820881702</mass>
				<inertia>
					<ixx>0.01972474263641184</ixx>
					<ixy>0.00048708461746338813</ixy>
					<ixz>3.185483018737783e-05</ixz>
					<iyy>0.13615185243928085</iyy>
					<iyz>-0.03856116577753052</iyz>
					<izz>0.1177250109980131</izz>
				</inertia>
			</inertial>
			<collision name="lower_arm_left_collision">
				<geometry>
					<mesh>
						<uri>model://roboy_upper_body/meshes/CAD/lower_arm_left.stl</uri>
						<scale>0.001 0.001 0.001</scale>
					</mesh>
				</geometry>
			</collision>
			<visual name="lower_arm_left_visual">
				<geometry>
					<mesh>
						<uri>model://roboy_upper_body/meshes/CAD/lower_arm_left.stl</uri>
						<scale>0.001 0.001 0.001</scale>
					</mesh>
				</geometry>
			</visual>
		</link>
		<link name="lower_arm_right">
			<self_collide>false</self_collide>
			<pose frame="">-0.28690316197811633 -0.0012971012985662463 0.09028215193184677 0.0 -0.0 0.0</pose>
			<inertial>
				<pose frame="">0.0 0.0 0.0 0 0 0</pose>
				<mass>1.3992272098398935</mass>
				<inertia>
					<ixx>0.01810985648977934</ixx>
					<ixy>-0.0005191321679580289</ixy>
					<ixz>4.0051155010876476e-05</ixz>
					<iyy>0.13328127304385734</iyy>
					<iyz>0.03631106564930123</iyz>
					<izz>0.11646776713622452</izz>
				</inertia>
			</inertial>
			<collision name="lower_arm_right_collision">
				<geometry>
					<mesh>
						<uri>model://roboy_upper_body/meshes/CAD/lower_arm_right.stl</uri>
						<scale>0.001 0.001 0.001</scale>
					</mesh>
				</geometry>
			</collision>
			<visual name="lower_arm_right_visual">
				<geometry>
					<mesh>
						<uri>model://roboy_upper_body/meshes/CAD/lower_arm_right.stl</uri>
						<scale>0.001 0.001 0.001</scale>
					</mesh>
				</geometry>
			</visual>
		</link>
		<link name="upper_arm_right">
			<self_collide>false</self_collide>
			<pose frame="">-0.3025447305327413 0.004242419884484555 0.39763297257341446 0.0 -0.0 0.0</pose>
			<inertial>
				<pose frame="">0.0 0.0 0.0 0 0 0</pose>
				<mass>1.0958327493576097</mass>
				<inertia>
					<ixx>0.179042496682244</ixx>
					<ixy>0.0013739028297246301</ixy>
					<ixz>-0.001880249463770289</ixz>
					<iyy>0.2781451232700294</iyy>
					<iyz>0.13162899491955163</iyz>
					<izz>0.1025794118324868</izz>
				</inertia>
			</inertial>
			<collision name="upper_arm_right_collision">
				<geometry>
					<mesh>
						<uri>model://roboy_upper_body/meshes/CAD/upper_arm_right.stl</uri>
						<scale>0.001 0.001 0.001</scale>
					</mesh>
				</geometry>
			</collision>
			<visual name="upper_arm_right_visual">
				<geometry>
					<mesh>
						<uri>model://roboy_upper_body/meshes/CAD/upper_arm_right.stl</uri>
						<scale>0.001 0.001 0.001</scale>
					</mesh>
				</geometry>
			</visual>
		</link>
		<link name="zed_camera_left_lense">
			<self_collide>false</self_collide>
			<pose frame="">0.05999964724565572 -0.08173913560527492 0.9528625747224352 0.0 -0.0 0.0</pose>
			<inertial>
				<pose frame="">0.0 0.0 0.0 0 0 0</pose>
				<mass>0.0057554218156879965</mass>
				<inertia>
					<ixx>0.004846011997714692</ixx>
					<ixy>3.881518938735634e-05</ixy>
					<ixz>0.0005891027444713397</ixz>
					<iyy>0.004793831227370645</iyy>
					<iyz>-0.000314480744284707</iyz>
					<izz>9.383240644717274e-05</izz>
				</inertia>
			</inertial>
			<collision name="zed_camera_left_lense_collision">
				<geometry>
					<mesh>
						<uri>model://roboy_upper_body/meshes/CAD/zed_camera_left_lense.stl</uri>
						<scale>0.001 0.001 0.001</scale>
					</mesh>
				</geometry>
			</collision>
			<visual name="zed_camera_left_lense_visual">
				<geometry>
					<mesh>
						<uri>model://roboy_upper_body/meshes/CAD/zed_camera_left_lense.stl</uri>
						<scale>0.001 0.001 0.001</scale>
					</mesh>
				</geometry>
			</visual>
		</link>
		<link name="zed_camera_right_lense">
			<self_collide>false</self_collide>
			<pose frame="">-0.06000035275434433 -0.08173913560527538 0.9528625747224347 0.0 -0.0 0.0</pose>
			<inertial>
				<pose frame="">0.0 0.0 0.0 0 0 0</pose>
				<mass>0.0057554218156880485</mass>
				<inertia>
					<ixx>0.004846011997551049</ixx>
					<ixy>-3.881429332761528e-05</ixy>
					<ixz>0.0005891027444611853</ixz>
					<iyy>0.004793830279485115</iyy>
					<iyz>0.00031447355054664474</iyz>
					<izz>9.383145872528843e-05</izz>
				</inertia>
			</inertial>
			<collision name="zed_camera_right_lense_collision">
				<geometry>
					<mesh>
						<uri>model://roboy_upper_body/meshes/CAD/zed_camera_right_lense.stl</uri>
						<scale>0.001 0.001 0.001</scale>
					</mesh>
				</geometry>
			</collision>
			<visual name="zed_camera_right_lense_visual">
				<geometry>
					<mesh>
						<uri>model://roboy_upper_body/meshes/CAD/zed_camera_right_lense.stl</uri>
						<scale>0.001 0.001 0.001</scale>
					</mesh>
				</geometry>
			</visual>
		</link>
		<link name="zed_camera">
			<self_collide>false</self_collide>
			<pose frame="">-3.51796944748628e-07 -0.05630729805909612 0.9474568704182059 0.0 -0.0 0.0</pose>
			<inertial>
				<pose frame="">0.0 0.0 0.0 0 0 0</pose>
				<mass>0.009633908092012306</mass>
				<inertia>
					<ixx>0.008084590483556824</ixx>
					<ixy>4.052560334214878e-06</ixy>
					<ixz>0.0008835532966109025</ixz>
					<iyy>0.008001682762379227</iyy>
					<iyz>-3.558756214861936e-05</iyz>
					<izz>0.00011263547643344076</izz>
				</inertia>
			</inertial>
			<collision name="zed_camera_collision">
				<geometry>
					<mesh>
						<uri>model://roboy_upper_body/meshes/CAD/zed_camera.stl</uri>
						<scale>0.001 0.001 0.001</scale>
					</mesh>
				</geometry>
			</collision>
			<visual name="zed_camera_visual">
				<geometry>
					<mesh>
						<uri>model://roboy_upper_body/meshes/CAD/zed_camera.stl</uri>
						<scale>0.001 0.001 0.001</scale>
					</mesh>
				</geometry>
			</visual>
		</link>
		<link name="sphere_head_link1">
			<self_collide>false</self_collide>
			<pose frame="">-2.0591149070298685e-14 0.0015217810850767161 0.7110989936345878 0.0 -0.0 0.0</pose>
			<inertial>
				<pose frame="">0.0 0.0 0.0 0 0 0</pose>
				<mass>0.023938100802369734</mass>
				<inertia>
					<ixx>0.012106595625813408</ixx>
					<ixy>7.508425305113864e-19</ixy>
					<ixz>-2.5904304543214497e-05</ixz>
					<iyy>0.012106540189536562</iyy>
					<iyz>3.5051683777709287e-16</iyz>
					<izz>2.012994235293797e-06</izz>
				</inertia>
			</inertial>
			<collision name="sphere_head_link1_collision">
				<geometry>
					<mesh>
						<uri>model://roboy_upper_body/meshes/CAD/sphere_head_link1.stl</uri>
						<scale>0.001 0.001 0.001</scale>
					</mesh>
				</geometry>
			</collision>
			<visual name="sphere_head_link1_visual">
				<geometry>
					<mesh>
						<uri>model://roboy_upper_body/meshes/CAD/sphere_head_link1.stl</uri>
						<scale>0.001 0.001 0.001</scale>
					</mesh>
				</geometry>
			</visual>
		</link>
		<link name="shere_head_link2">
			<self_collide>false</self_collide>
			<pose frame="">-2.0576940733084e-14 0.001521781085076725 0.7110989936345874 0.0 -0.0 0.0</pose>
			<inertial>
				<pose frame="">0.0 0.0 0.0 0 0 0</pose>
				<mass>0.016046417516495697</mass>
				<inertia>
					<ixx>0.008114981473636663</ixx>
					<ixy>5.028583886096394e-19</ixy>
					<ixz>-1.7364422082044644e-05</ixz>
					<iyy>0.008114944313059423</iyy>
					<iyz>2.348427008413978e-16</iyz>
					<izz>9.214497104106419e-07</izz>
				</inertia>
			</inertial>
			<collision name="shere_head_link2_collision">
				<geometry>
					<mesh>
						<uri>model://roboy_upper_body/meshes/CAD/shere_head_link2.stl</uri>
						<scale>0.001 0.001 0.001</scale>
					</mesh>
				</geometry>
			</collision>
			<visual name="shere_head_link2_visual">
				<geometry>
					<mesh>
						<uri>model://roboy_upper_body/meshes/CAD/shere_head_link2.stl</uri>
						<scale>0.001 0.001 0.001</scale>
					</mesh>
				</geometry>
			</visual>
		</link>
		<link name="head">
			<self_collide>false</self_collide>
			<pose frame="">0.0006492376358659663 0.015046110821376588 0.8664862621002404 0.0 -0.0 0.0</pose>
			<inertial>
				<pose frame="">0.0 0.0 0.0 0 0 0</pose>
				<mass>2.0664381552877646</mass>
				<inertia>
					<ixx>1.5846048067305147</ixx>
					<ixy>-2.8828445995306153e-05</ixy>
					<ixz>-0.029442702319180492</ixz>
					<iyy>1.5788965104892616</iyy>
					<iyz>-0.001288434670190506</iyz>
					<izz>0.025550832000819562</izz>
				</inertia>
			</inertial>
			<collision name="head_collision">
				<geometry>
					<mesh>
						<uri>model://roboy_upper_body/meshes/CAD/head.stl</uri>
						<scale>0.001 0.001 0.001</scale>
					</mesh>
				</geometry>
			</collision>
			<visual name="head_visual">
				<geometry>
					<mesh>
						<uri>model://roboy_upper_body/meshes/CAD/head.stl</uri>
						<scale>0.001 0.001 0.001</scale>
					</mesh>
				</geometry>
			</visual>
		</link>
		<link name="left_stick_tip">
			<self_collide>false</self_collide>
			<pose frame="">0.2692093428891479 -0.27579017670378486 -0.20327503666285687 0.0 -0.0 0.0</pose>
			<inertial>
				<pose frame="">0.0 0.0 0.0 0 0 0</pose>
				<mass>0.026023156971151304</mass>
				<inertia>
					<ixx>0.0030555442570330566</ixx>
					<ixy>0.0019320978532239466</ixy>
					<ixz>-0.0014587537400506567</ixz>
					<iyy>0.002962679652716561</iyy>
					<iyz>0.0014240795271705236</iyz>
					<izz>0.0038662816743842217</izz>
				</inertia>
			</inertial>
			<collision name="left_stick_tip_collision">
				<geometry>
					<mesh>
						<uri>model://roboy_upper_body/meshes/CAD/left_stick_tip.stl</uri>
						<scale>0.001 0.001 0.001</scale>
					</mesh>
				</geometry>
			</collision>
			<visual name="left_stick_tip_visual">
				<geometry>
					<mesh>
						<uri>model://roboy_upper_body/meshes/CAD/left_stick_tip.stl</uri>
						<scale>0.001 0.001 0.001</scale>
					</mesh>
				</geometry>
			</visual>
		</link>
		<link name="right_stick_tip">
			<self_collide>false</self_collide>
			<pose frame="">-0.272131258246756 -0.2756784841545138 -0.20336496032974374 0.0 -0.0 0.0</pose>
			<inertial>
				<pose frame="">0.0 0.0 0.0 0 0 0</pose>
				<mass>0.026023156971154107</mass>
				<inertia>
					<ixx>0.0030548926832994505</ixx>
					<ixy>-0.0019522723505767325</ixy>
					<ixz>-0.0014588184035582042</ixz>
					<iyy>0.003004799357065121</iyy>
					<iyz>-0.0014401715227325498</iyz>
					<izz>0.0039058346651765483</izz>
				</inertia>
			</inertial>
			<collision name="right_stick_tip_collision">
				<geometry>
					<mesh>
						<uri>model://roboy_upper_body/meshes/CAD/right_stick_tip.stl</uri>
						<scale>0.001 0.001 0.001</scale>
					</mesh>
				</geometry>
			</collision>
			<visual name="right_stick_tip_visual">
				<geometry>
					<mesh>
						<uri>model://roboy_upper_body/meshes/CAD/right_stick_tip.stl</uri>
						<scale>0.001 0.001 0.001</scale>
					</mesh>
				</geometry>
			</visual>
		</link>
		<link name="spine_v0_sphere_link1">
			<self_collide>false</self_collide>
			<pose frame="">0.0 -4.4408920985006264e-17 0.0804511885429319 0.0 -0.0 0.0</pose>
			<inertial>
				<pose frame="">0.0 0.0 0.0 0 0 0</pose>
				<mass>0.006868749968312682</mass>
				<inertia>
					<ixx>0.00018655788948137772</ixx>
					<ixy>-7.318364664277155e-23</ixy>
					<ixz>-1.7214511119186968e-06</ixz>
					<iyy>0.0001865419827088242</iyy>
					<iyz>-5.984795992119985e-21</iyz>
					<izz>2.6026557599302e-07</izz>
				</inertia>
			</inertial>
			<collision name="spine_v0_sphere_link1_collision">
				<geometry>
					<mesh>
						<uri>model://roboy_upper_body/meshes/CAD/spine_v0_sphere_link1.stl</uri>
						<scale>0.001 0.001 0.001</scale>
					</mesh>
				</geometry>
			</collision>
			<visual name="spine_v0_sphere_link1_visual">
				<geometry>
					<mesh>
						<uri>model://roboy_upper_body/meshes/CAD/spine_v0_sphere_link1.stl</uri>
						<scale>0.001 0.001 0.001</scale>
					</mesh>
				</geometry>
			</visual>
		</link>
		<link name="spine_v0_sphere_link2">
			<self_collide>false</self_collide>
			<pose frame="">0.0 -4.4408920985006264e-17 0.0804511885429319 0.0 -0.0 0.0</pose>
			<inertial>
				<pose frame="">0.0 0.0 0.0 0 0 0</pose>
				<mass>0.004604326339669925</mass>
				<inertia>
					<ixx>0.00012500185666920944</ixx>
					<ixy>4.404571325722362e-24</ixy>
					<ixz>-1.1539395924929318e-06</ixz>
					<iyy>0.00012499119389076097</iyy>
					<iyz>-4.6837533851373794e-21</iyz>
					<izz>1.2104716504802298e-07</izz>
				</inertia>
			</inertial>
			<collision name="spine_v0_sphere_link2_collision">
				<geometry>
					<mesh>
						<uri>model://roboy_upper_body/meshes/CAD/spine_v0_sphere_link2.stl</uri>
						<scale>0.001 0.001 0.001</scale>
					</mesh>
				</geometry>
			</collision>
			<visual name="spine_v0_sphere_link2_visual">
				<geometry>
					<mesh>
						<uri>model://roboy_upper_body/meshes/CAD/spine_v0_sphere_link2.stl</uri>
						<scale>0.001 0.001 0.001</scale>
					</mesh>
				</geometry>
			</visual>
		</link>
		<link name="spine_v1_sphere_link1">
			<self_collide>false</self_collide>
			<pose frame="">0.0 -4.4408920985006264e-17 0.11945118854293191 0.0 -0.0 0.0</pose>
			<inertial>
				<pose frame="">0.0 0.0 0.0 0 0 0</pose>
				<mass>0.006868749968312679</mass>
				<inertia>
					<ixx>0.0002852394911137051</ixx>
					<ixy>-8.131516293641284e-24</ixy>
					<ixz>-2.129107729333681e-06</ixz>
					<iyy>0.00028522358434115167</iyy>
					<iyz>-9.454242944073599e-21</iyz>
					<izz>2.602655759930154e-07</izz>
				</inertia>
			</inertial>
			<collision name="spine_v1_sphere_link1_collision">
				<geometry>
					<mesh>
						<uri>model://roboy_upper_body/meshes/CAD/spine_v1_sphere_link1.stl</uri>
						<scale>0.001 0.001 0.001</scale>
					</mesh>
				</geometry>
			</collision>
			<visual name="spine_v1_sphere_link1_visual">
				<geometry>
					<mesh>
						<uri>model://roboy_upper_body/meshes/CAD/spine_v1_sphere_link1.stl</uri>
						<scale>0.001 0.001 0.001</scale>
					</mesh>
				</geometry>
			</visual>
		</link>
		<link name="spine_v1_sphere_link2">
			<self_collide>false</self_collide>
			<pose frame="">0.0 -4.4408920985006264e-17 0.11945118854293191 0.0 -0.0 0.0</pose>
			<inertial>
				<pose frame="">0.0 0.0 0.0 0 0 0</pose>
				<mass>0.004604326339669925</mass>
				<inertia>
					<ixx>0.00019115105406745567</ixx>
					<ixy>-3.6591823321385777e-23</ixy>
					<ixz>-1.4272038799078502e-06</ixz>
					<iyy>0.00019114039128900715</iyy>
					<iyz>-4.4235448637408584e-21</iyz>
					<izz>1.2104716504802018e-07</izz>
				</inertia>
			</inertial>
			<collision name="spine_v1_sphere_link2_collision">
				<geometry>
					<mesh>
						<uri>model://roboy_upper_body/meshes/CAD/spine_v1_sphere_link2.stl</uri>
						<scale>0.001 0.001 0.001</scale>
					</mesh>
				</geometry>
			</collision>
			<visual name="spine_v1_sphere_link2_visual">
				<geometry>
					<mesh>
						<uri>model://roboy_upper_body/meshes/CAD/spine_v1_sphere_link2.stl</uri>
						<scale>0.001 0.001 0.001</scale>
					</mesh>
				</geometry>
			</visual>
		</link>
		<link name="spine_v2_sphere_link1">
			<self_collide>false</self_collide>
			<pose frame="">0.0 -4.4408920985006264e-17 0.15845118854293191 0.0 -0.0 0.0</pose>
			<inertial>
				<pose frame="">0.0 0.0 0.0 0 0 0</pose>
				<mass>0.006868749968312682</mass>
				<inertia>
					<ixx>0.0004048158301496406</ixx>
					<ixy>-1.1384122811097798e-22</ixy>
					<ixz>-2.5367643467485574e-06</ixz>
					<iyy>0.00040479992337708704</iyy>
					<iyz>-6.765421556309548e-21</iyz>
					<izz>2.6026557599301153e-07</izz>
				</inertia>
			</inertial>
			<collision name="spine_v2_sphere_link1_collision">
				<geometry>
					<mesh>
						<uri>model://roboy_upper_body/meshes/CAD/spine_v2_sphere_link1.stl</uri>
						<scale>0.001 0.001 0.001</scale>
					</mesh>
				</geometry>
			</collision>
			<visual name="spine_v2_sphere_link1_visual">
				<geometry>
					<mesh>
						<uri>model://roboy_upper_body/meshes/CAD/spine_v2_sphere_link1.stl</uri>
						<scale>0.001 0.001 0.001</scale>
					</mesh>
				</geometry>
			</visual>
		</link>
		<link name="spine_v2_sphere_link2">
			<self_collide>false</self_collide>
			<pose frame="">0.0 -4.4408920985006264e-17 0.15845118854293191 0.0 -0.0 0.0</pose>
			<inertial>
				<pose frame="">0.0 0.0 0.0 0 0 0</pose>
				<mass>0.004604326339669924</mass>
				<inertia>
					<ixx>0.00027130661219097773</ixx>
					<ixy>-3.3881317890172014e-23</ixy>
					<ixz>-1.7004681673226978e-06</ixz>
					<iyy>0.0002712959494125292</iyy>
					<iyz>-5.4643789493269424e-21</iyz>
					<izz>1.210471650480173e-07</izz>
				</inertia>
			</inertial>
			<collision name="spine_v2_sphere_link2_collision">
				<geometry>
					<mesh>
						<uri>model://roboy_upper_body/meshes/CAD/spine_v2_sphere_link2.stl</uri>
						<scale>0.001 0.001 0.001</scale>
					</mesh>
				</geometry>
			</collision>
			<visual name="spine_v2_sphere_link2_visual">
				<geometry>
					<mesh>
						<uri>model://roboy_upper_body/meshes/CAD/spine_v2_sphere_link2.stl</uri>
						<scale>0.001 0.001 0.001</scale>
					</mesh>
				</geometry>
			</visual>
		</link>
		<link name="spine_link1">
			<self_collide>false</self_collide>
			<pose frame="">0.0 0.0 0.10098971902562745 0.0 -0.0 0.0</pose>
			<inertial>
				<pose frame="">0.0 0.0 0.0 0 0 0</pose>
				<mass>0.02804796014044654</mass>
				<inertia>
					<ixx>0.0009903562452458544</ixx>
					<ixy>3.7433530622864464e-11</ixy>
					<ixz>-8.403341501542152e-06</ixz>
					<iyy>0.0009902808158141123</iyy>
					<iyz>5.321713939381718e-09</iyz>
					<izz>2.4706204956731896e-06</izz>
				</inertia>
			</inertial>
			<collision name="spine_link1_collision">
				<geometry>
					<mesh>
						<uri>model://roboy_upper_body/meshes/CAD/spine_link1.stl</uri>
						<scale>0.001 0.001 0.001</scale>
					</mesh>
				</geometry>
			</collision>
			<visual name="spine_link1_visual">
				<geometry>
					<mesh>
						<uri>model://roboy_upper_body/meshes/CAD/spine_link1.stl</uri>
						<scale>0.001 0.001 0.001</scale>
					</mesh>
				</geometry>
			</visual>
		</link>
		<link name="spine_link2">
			<self_collide>false</self_collide>
			<pose frame="">0.0 0.0 0.13998971902562746 0.0 -0.0 0.0</pose>
			<inertial>
				<pose frame="">0.0 0.0 0.0 0 0 0</pose>
				<mass>0.023084394447634406</mass>
				<inertia>
					<ixx>0.0011507714882796798</ixx>
					<ixy>3.849444054000353e-11</ixy>
					<ixz>-3.33986085040153e-06</ixz>
					<iyy>0.0011507700283837647</iyy>
					<iyz>6.561646995943951e-09</iyz>
					<izz>2.1587972930588084e-06</izz>
				</inertia>
			</inertial>
			<collision name="spine_link2_collision">
				<geometry>
					<mesh>
						<uri>model://roboy_upper_body/meshes/CAD/spine_link2.stl</uri>
						<scale>0.001 0.001 0.001</scale>
					</mesh>
				</geometry>
			</collision>
			<visual name="spine_link2_visual">
				<geometry>
					<mesh>
						<uri>model://roboy_upper_body/meshes/CAD/spine_link2.stl</uri>
						<scale>0.001 0.001 0.001</scale>
					</mesh>
				</geometry>
			</visual>
		</link>
		<joint name="elbow_right_rot1" type="revolute">
			<parent>elbow_right</parent>
			<child>lower_arm_right</child>
			<pose frame="">-0.2883348668957596 0.0015360891183606497 0.21397527898888957 0 0 0</pose>
			<axis>
				<xyz>-0.01118842648953284 0.022909252225335578 0.999674939805517</xyz>
				<limit>
					<lower>-1.5707963267948966</lower>
					<upper>1.5707963267948966</upper>
				</limit>
				<use_parent_model_frame>0</use_parent_model_frame>
			</axis>
		</joint>
		<joint name="right_wrist_0" type="revolute">
			<parent>lower_arm_right</parent>
			<child>wrist_right_1</child>
			<pose frame="">-0.27559235016114986 -0.004919947767474747 -0.05063656162875093 0 0 0</pose>
			<axis>
				<xyz>0.9991077747968851 -0.04032476901588534 -0.012552583169695498</xyz>
				<limit>
					<lower>-0.5235987755982988</lower>
					<upper>0.5235987755982988</upper>
				</limit>
				<use_parent_model_frame>0</use_parent_model_frame>
			</axis>
		</joint>
		<joint name="right_wrist_1" type="revolute">
			<parent>wrist_right_1</parent>
			<child>right_hand</child>
			<pose frame="">-0.2853823473024196 0.012985019351307244 -0.0508975375840698 0 0 0</pose>
			<axis>
				<xyz>0.040036256805536984 0.9989461168065814 -0.022444461634320585</xyz>
				<limit>
					<lower>-0.5235987755982988</lower>
					<upper>0.5235987755982988</upper>
				</limit>
				<use_parent_model_frame>0</use_parent_model_frame>
			</axis>
		</joint>
		<joint name="elbow_left_rot1" type="revolute">
			<parent>elbow_left</parent>
			<child>lower_arm_left</child>
			<pose frame="">0.28834605532224855 0.001558998370584284 0.21497495392869365 0 0 0</pose>
			<axis>
				<xyz>-0.011188426489533955 -0.022909252225335637 -0.9996749398055156</xyz>
				<limit>
					<lower>-1.5707963267948966</lower>
					<upper>1.5707963267948966</upper>
				</limit>
				<use_parent_model_frame>0</use_parent_model_frame>
			</axis>
		</joint>
		<joint name="elbow_left_rot0" type="revolute">
			<parent>upper_arm_left</parent>
			<child>elbow_left</child>
			<pose frame="">0.3071180519392121 -0.0010122596363587378 0.28109532352290045 0 0 0</pose>
			<axis>
				<xyz>-0.9986354432836098 -0.05074429632816577 0.012339684270769044</xyz>
				<limit>
					<lower>0.0</lower>
					<upper>1.5707963267948966</upper>
				</limit>
				<use_parent_model_frame>0</use_parent_model_frame>
			</axis>
		</joint>
		<joint name="sphere_left_axis0" type="revolute">
			<parent>torso</parent>
			<child>sphere_left_link1</child>
			<pose frame="">0.2921800561556862 0.009210036846545868 0.5486152310953598 0 0 0</pose>
			<axis>
				<xyz>0.9986354432836129 0.05074429632816833 -0.012339684270770038</xyz>
				<limit>
					<lower>-3.141592653589793</lower>
					<upper>3.141592653589793</upper>
				</limit>
				<use_parent_model_frame>0</use_parent_model_frame>
			</axis>
		</joint>
		<joint name="sphere_left_axis1" type="revolute">
			<parent>sphere_left_link1</parent>
			<child>sphere_left_link2</child>
			<pose frame="">0.2921800561556861 0.009210036846545854 0.5486152310953598 0 0 0</pose>
			<axis>
				<xyz>-0.05101049431667493 0.9984488883025682 -0.022310242422112825</xyz>
				<limit>
					<lower>-3.141592653589793</lower>
					<upper>3.141592653589793</upper>
				</limit>
				<use_parent_model_frame>0</use_parent_model_frame>
			</axis>
		</joint>
		<joint name="sphere_left_axis2" type="revolute">
			<parent>sphere_left_link2</parent>
			<child>upper_arm_left</child>
			<pose frame="">0.2921800562126946 0.009210035730692257 0.5486152311202934 0 0 0</pose>
			<axis>
				<xyz>-0.01118842648953418 -0.022909252225335505 -0.9996749398055222</xyz>
				<limit>
					<lower>-3.141592653589793</lower>
					<upper>3.141592653589793</upper>
				</limit>
				<use_parent_model_frame>0</use_parent_model_frame>
			</axis>
		</joint>
		<joint name="left_wrist_0" type="revolute">
			<parent>lower_arm_left</parent>
			<child>wrist_left_1</child>
			<pose frame="">0.27392848273438775 -0.005156786822591244 -0.04709370222467522 0 0 0</pose>
			<axis>
				<xyz>-0.9974356911086111 -0.06112686075287341 0.037222963304743374</xyz>
				<limit>
					<lower>-0.5235987755982988</lower>
					<upper>0.5235987755982988</upper>
				</limit>
				<use_parent_model_frame>0</use_parent_model_frame>
			</axis>
		</joint>
		<joint name="left_wrist_1" type="revolute">
			<parent>wrist_left_1</parent>
			<child>left_hand</child>
			<pose frame="">0.2854861827286469 -0.02197699986169134 -0.04709651006426952 0 0 0</pose>
			<axis>
				<xyz>-0.06197857490501217 0.9978311478764739 -0.022173330382833693</xyz>
				<limit>
					<lower>-0.5235987755982988</lower>
					<upper>0.5235987755982988</upper>
				</limit>
				<use_parent_model_frame>0</use_parent_model_frame>
			</axis>
		</joint>
		<joint name="sphere_right_axis0" type="revolute">
			<parent>torso</parent>
			<child>sphere_right_link1</child>
			<pose frame="">-0.2921800562126926 0.009210035730692408 0.5486152311202932 0 0 0</pose>
			<axis>
				<xyz>0.05101049431667341 0.998448888302569 -0.022310242422112804</xyz>
				<limit>
					<lower>-3.141592653589793</lower>
					<upper>3.141592653589793</upper>
				</limit>
				<use_parent_model_frame>0</use_parent_model_frame>
			</axis>
		</joint>
		<joint name="sphere_right_axis2" type="revolute">
			<parent>sphere_right_link2</parent>
			<child>upper_arm_right</child>
			<pose frame="">-0.29218005621269244 0.009210035730692382 0.5486152311202931 0 0 0</pose>
			<axis>
				<xyz>0.011188426489535866 -0.022909252225335328 -0.9996749398055187</xyz>
				<limit>
					<lower>-3.141592653589793</lower>
					<upper>3.141592653589793</upper>
				</limit>
				<use_parent_model_frame>0</use_parent_model_frame>
			</axis>
		</joint>
		<joint name="sphere_right_axis1" type="revolute">
			<parent>sphere_right_link1</parent>
			<child>sphere_right_link2</child>
			<pose frame="">-0.29218005621269255 0.009210035730692394 0.5486152311202929 0 0 0</pose>
			<axis>
				<xyz>-0.9986354432836146 0.050744296328166766 -0.012339684270771867</xyz>
				<limit>
					<lower>-3.141592653589793</lower>
					<upper>3.141592653589793</upper>
				</limit>
				<use_parent_model_frame>0</use_parent_model_frame>
			</axis>
		</joint>
		<joint name="elbow_right_rot0" type="revolute">
			<parent>upper_arm_right</parent>
			<child>elbow_right</child>
			<pose frame="">-0.3071068635127231 -0.0010351688885824096 0.28009564858309577 0 0 0</pose>
			<axis>
				<xyz>-0.9986354432836139 0.050744296328165295 -0.012339684270768765</xyz>
				<limit>
					<lower>0.0</lower>
					<upper>1.5707963267948966</upper>
				</limit>
				<use_parent_model_frame>0</use_parent_model_frame>
			</axis>
		</joint>
		<joint name="left_stick_tip_joint" type="fixed">
			<parent>left_hand</parent>
			<child>left_stick_tip</child>
			<pose frame="">0.2692180834114672 -0.27151644406812997 -0.20213383637111107 0 0 0</pose>
		</joint>
		<joint name="sphere_head_axis0" type="revolute">
			<parent>torso</parent>
			<child>sphere_head_link1</child>
			<pose frame="">-2.0594229279776275e-14 0.0015217810850767124 0.7110989936345876 0 0 0</pose>
			<axis>
				<xyz>2.506675422786485e-16 -1.0000000000000004 8.242631900833768e-15</xyz>
				<limit>
					<lower>-0.5235987755982988</lower>
					<upper>0.5235987755982988</upper>
				</limit>
				<use_parent_model_frame>0</use_parent_model_frame>
			</axis>
		</joint>
		<joint name="sphere_head_axis2" type="revolute">
			<parent>shere_head_link2</parent>
			<child>head</child>
			<pose frame="">-2.0593998807905753e-14 0.0015217810850767055 0.7110989936345874 0 0 0</pose>
			<axis>
				<xyz>-2.4131887955448744e-14 8.24263190083376e-15 1.0</xyz>
				<limit>
					<lower>-0.5235987755982988</lower>
					<upper>0.5235987755982988</upper>
				</limit>
				<use_parent_model_frame>0</use_parent_model_frame>
			</axis>
		</joint>
		<joint name="sphere_head_axis1" type="revolute">
			<parent>sphere_head_link1</parent>
			<child>shere_head_link2</child>
			<pose frame="">-2.059422927977629e-14 0.0015217810850767116 0.7110989936345876 0 0 0</pose>
			<axis>
				<xyz>-1.0000000000000004 -2.506675422788488e-16 -2.413188795544875e-14</xyz>
				<limit>
					<lower>-0.5235987755982988</lower>
					<upper>0.5235987755982988</upper>
				</limit>
				<use_parent_model_frame>0</use_parent_model_frame>
			</axis>
		</joint>
		<joint name="zed_camera_mount" type="fixed">
			<parent>head</parent>
			<child>zed_camera</child>
			<pose frame="">0.0214996482030444 -0.10108118115852564 0.91865350562054 0 0 0</pose>
		</joint>
		<joint name="zed_camera_right" type="fixed">
			<parent>zed_camera</parent>
			<child>zed_camera_right_lense</child>
			<pose frame="">-0.06000035275435545 -0.10108118115852581 0.9106535061032188 0 0 0</pose>
		</joint>
		<joint name="zed_camera_left" type="fixed">
			<parent>zed_camera</parent>
			<child>zed_camera_left_lense</child>
			<pose frame="">0.05998183674147379 -0.10108118115852593 0.9106535059694751 0 0 0</pose>
		</joint>
		<joint name="right_stick_tip_joint" type="fixed">
			<parent>right_hand</parent>
			<child>right_stick_tip</child>
			<pose frame="">-0.27209483887149777 -0.2713033363230461 -0.20219713034171638 0 0 0</pose>
		</joint>
		<joint name="spine_v1_axis0" type="revolute">
			<parent>spine_link1</parent>
			<child>spine_v1_sphere_link1</child>
			<pose frame="">6.81997130289588e-19 0.0015217810850734561 0.20368908021291388 0 0 0</pose>
			<axis>
				<xyz>1.0 -1.0153886588934481e-45 -5.348582902845094e-60</xyz>
				<limit>
					<lower>-0.08726646259971647</lower>
					<upper>0.08726646259971647</upper>
				</limit>
				<use_parent_model_frame>0</use_parent_model_frame>
			</axis>
		</joint>
		<joint name="spine_v1_axis2" type="revolute">
			<parent>spine_v1_sphere_link2</parent>
			<child>spine_link2</child>
			<pose frame="">0.0 0.001521781085073465 0.20368908021291388 0 0 0</pose>
			<axis>
				<xyz>1.2072879321179697e-61 -5.148623695807787e-15 1.0</xyz>
				<limit>
					<lower>-0.08726646259971647</lower>
					<upper>0.08726646259971647</upper>
				</limit>
				<use_parent_model_frame>0</use_parent_model_frame>
			</axis>
		</joint>
		<joint name="spine_v1_axis1" type="revolute">
			<parent>spine_v1_sphere_link1</parent>
			<child>spine_v1_sphere_link2</child>
			<pose frame="">6.81997130289588e-19 0.001521781085073485 0.20368908021291382 0 0 0</pose>
			<axis>
				<xyz>-1.0153886588934481e-45 -1.0 -5.148623695807787e-15</xyz>
				<limit>
					<lower>-0.08726646259971647</lower>
					<upper>0.08726646259971647</upper>
				</limit>
				<use_parent_model_frame>0</use_parent_model_frame>
			</axis>
		</joint>
		<joint name="spine_v0_axis2" type="revolute">
			<parent>spine_v0_sphere_link2</parent>
			<child>spine_link1</child>
			<pose frame="">0.0 0.0015217810850736708 0.16468908021291384 0 0 0</pose>
			<axis>
				<xyz>1.2072879321179697e-61 -5.148623695807787e-15 1.0</xyz>
				<limit>
					<lower>-0.08726646259971647</lower>
					<upper>0.08726646259971647</upper>
				</limit>
				<use_parent_model_frame>0</use_parent_model_frame>
			</axis>
		</joint>
		<joint name="spine_v0_axis1" type="revolute">
			<parent>spine_v0_sphere_link1</parent>
			<child>spine_v0_sphere_link2</child>
			<pose frame="">6.81997130289588e-19 0.0015217810850736908 0.16468908021291384 0 0 0</pose>
			<axis>
				<xyz>-1.0153886588934481e-45 -1.0 -5.148623695807787e-15</xyz>
				<limit>
					<lower>-0.08726646259971647</lower>
					<upper>0.08726646259971647</upper>
				</limit>
				<use_parent_model_frame>0</use_parent_model_frame>
			</axis>
		</joint>
		<joint name="spine_v2_axis0" type="revolute">
			<parent>spine_link2</parent>
			<child>spine_v2_sphere_link1</child>
			<pose frame="">6.81997130289588e-19 0.0015217810850732508 0.24268908021291385 0 0 0</pose>
			<axis>
				<xyz>1.0 -1.0153886588934481e-45 -5.348582902845094e-60</xyz>
				<limit>
					<lower>-0.08726646259971647</lower>
					<upper>0.08726646259971647</upper>
				</limit>
				<use_parent_model_frame>0</use_parent_model_frame>
			</axis>
		</joint>
		<joint name="spine_v2_axis1" type="revolute">
			<parent>spine_v2_sphere_link1</parent>
			<child>spine_v2_sphere_link2</child>
			<pose frame="">6.81997130289588e-19 0.0015217810850732798 0.24268908021291385 0 0 0</pose>
			<axis>
				<xyz>-1.0153886588934481e-45 -1.0 -5.148623695807787e-15</xyz>
				<limit>
					<lower>-0.08726646259971647</lower>
					<upper>0.08726646259971647</upper>
				</limit>
				<use_parent_model_frame>0</use_parent_model_frame>
			</axis>
		</joint>
		<plugin filename="libmusc_plugin.so" name="musc_plugin">
			<myoMuscle name="motor0">
				<link name="torso">
					<viaPoint type="FIXPOINT">0.28894109223784714 -0.010689615277494027 0.57625463538261</viaPoint>
				</link>
				<link name="upper_arm_left">
					<viaPoint type="FIXPOINT">0.31226850562000774 -0.013072711253633797 0.5003948686032897</viaPoint>
				</link>
			</myoMuscle>
			<myoMuscle name="motor1">
				<link name="torso">
					<viaPoint type="FIXPOINT">0.24003539451940256 -0.0255094396635371 0.46729404948318215</viaPoint>
				</link>
				<link name="upper_arm_left">
					<viaPoint type="FIXPOINT">0.27546819010480306 -0.011734715491766893 0.5007760776617289</viaPoint>
				</link>
			</myoMuscle>
			<myoMuscle name="motor2">
				<link name="torso">
					<viaPoint type="FIXPOINT">0.2512180133128362 -0.028667405657345723 0.5145590997255798</viaPoint>
				</link>
				<link name="upper_arm_left">
					<viaPoint type="FIXPOINT">0.3015702535073825 -0.0066824377992425864 0.49736718464472646</viaPoint>
				</link>
			</myoMuscle>
			<myoMuscle name="motor3">
				<link name="torso">
					<viaPoint type="FIXPOINT">0.28063665292590684 -0.028534400330317792 0.5580004259562042</viaPoint>
				</link>
				<link name="upper_arm_left">
					<viaPoint type="FIXPOINT">0.31260720527450264 -0.013577925270544968 0.5004026556937177</viaPoint>
				</link>
			</myoMuscle>
			<myoMuscle name="motor4">
				<link name="torso">
					<viaPoint type="FIXPOINT">0.3033935027253936 5.329351681328665e-15 0.596144953020783</viaPoint>
				</link>
				<link name="upper_arm_left">
					<viaPoint type="FIXPOINT">0.3212116751629781 0.010611443088849376 0.49975201337605385</viaPoint>
				</link>
			</myoMuscle>
			<myoMuscle name="motor5">
				<link name="torso">
					<viaPoint type="FIXPOINT">0.2769871340021271 0.04289909901328503 0.5564042514238003</viaPoint>
				</link>
				<link name="upper_arm_left">
					<viaPoint type="FIXPOINT">0.3103394063946467 0.03081061282964514 0.49941079816612616</viaPoint>
				</link>
			</myoMuscle>
			<myoMuscle name="motor6">
				<link name="torso">
					<viaPoint type="FIXPOINT">0.247561326172623 0.04290640006489306 0.512959790060908</viaPoint>
				</link>
				<link name="upper_arm_left">
					<viaPoint type="FIXPOINT">0.30006919482245964 0.022698386584342298 0.49671067300728683</viaPoint>
				</link>
			</myoMuscle>
			<myoMuscle name="motor7">
				<link name="torso">
					<viaPoint type="FIXPOINT">0.23617466540192175 0.050058161611911685 0.465605498848829</viaPoint>
				</link>
				<link name="upper_arm_left">
					<viaPoint type="FIXPOINT">0.272987251022091 0.0253372668089647 0.4999542769385574</viaPoint>
				</link>
			</myoMuscle>
			<myoMuscle name="motor8">
				<link name="torso">
					<viaPoint type="FIXPOINT">0.2865401700456322 0.026075605770317516 0.576140812491758</viaPoint>
				</link>
				<link name="upper_arm_left">
					<viaPoint type="FIXPOINT">0.3100539495906346 0.03027368315463489 0.4994262976742189</viaPoint>
				</link>
			</myoMuscle>
			<myoMuscle name="motor27">
				<link name="base">
					<viaPoint type="FIXPOINT">-0.19499999851461478 -0.11347765649897372 0.08723717349165262</viaPoint>
				</link>
				<link name="torso">
					<viaPoint type="FIXPOINT">0.13543876459810386 -0.06208086211104811 0.32683191492848634</viaPoint>
				</link>
			</myoMuscle>
			<myoMuscle name="motor28">
				<link name="base">
					<viaPoint type="FIXPOINT">0.1949999985146147 -0.1134776564989737 0.0872371734916526</viaPoint>
				</link>
				<link name="torso">
					<viaPoint type="FIXPOINT">-0.13663898856535112 -0.06000468869766767 0.32502942598649015</viaPoint>
				</link>
			</myoMuscle>
			<myoMuscle name="motor29">
				<link name="base">
					<viaPoint type="FIXPOINT">-0.22500000148538477 0.0015223435010262314 0.08723717349165344</viaPoint>
				</link>
				<link name="torso">
					<viaPoint type="FIXPOINT">-0.15008296104407917 2.500672069228397e-06 0.31561285492544516</viaPoint>
				</link>
			</myoMuscle>
			<myoMuscle name="motor30">
				<link name="base">
					<viaPoint type="FIXPOINT">0.2250000014853848 0.0015223435010263495 0.08723717349165344</viaPoint>
				</link>
				<link name="torso">
					<viaPoint type="FIXPOINT">0.15008296104408234 2.5006720701115108e-06 0.31561285492544544</viaPoint>
				</link>
			</myoMuscle>
			<myoMuscle name="motor31">
				<link name="base">
					<viaPoint type="FIXPOINT">-0.19499999851461464 0.11652234350102626 0.08723717349165426</viaPoint>
				</link>
				<link name="torso">
					<viaPoint type="FIXPOINT">0.11845723973009747 0.06717115764172317 0.29715852041937835</viaPoint>
				</link>
			</myoMuscle>
			<myoMuscle name="motor32">
				<link name="base">
					<viaPoint type="FIXPOINT">0.19499999851461486 0.1165223435010261 0.08723717349165426</viaPoint>
				</link>
				<link name="torso">
					<viaPoint type="FIXPOINT">-0.11544125735968605 0.06857597545288843 0.2934261837171483</viaPoint>
				</link>
			</myoMuscle>
			<myoMuscle name="motor9">
				<link name="upper_arm_left">
					<viaPoint type="FIXPOINT">0.2882929764117162 0.06884747997014054 0.3627318842628646</viaPoint>
				</link>
				<link name="elbow_left">
					<viaPoint type="FIXPOINT">0.28657781935909776 0.037951151442536524 0.24352490038977423</viaPoint>
				</link>
			</myoMuscle>
			<myoMuscle name="motor10">
				<link name="upper_arm_left">
					<viaPoint type="FIXPOINT">0.29404295722370377 -0.059755482288746206 0.3656146858085762</viaPoint>
				</link>
				<link name="elbow_left">
					<viaPoint type="FIXPOINT">0.2903773907336951 -0.034292211694126745 0.2314758782443933</viaPoint>
				</link>
			</myoMuscle>
			<myoMuscle name="motor11">
				<link name="upper_arm_left">
					<viaPoint type="FIXPOINT">0.33808414200087167 0.0005785579049365257 0.3034610678007707</viaPoint>
				</link>
				<link name="elbow_left">
					<viaPoint type="FIXPOINT">0.3273568776263238 -0.006295467181374116 0.2167909749155116</viaPoint>
				</link>
				<link name="lower_arm_left">
					<viaPoint type="FIXPOINT">0.2717053643728731 -0.03612964032343798 0.20801367309799368</viaPoint>
				</link>
			</myoMuscle>
			<myoMuscle name="motor12">
				<link name="upper_arm_left">
					<viaPoint type="FIXPOINT">0.32989533136594534 0.0001624546750455376 0.3035622532117913</viaPoint>
				</link>
				<link name="elbow_left">
					<viaPoint type="FIXPOINT">0.3291984972098265 0.016253264493843338 0.20983255983332177</viaPoint>
				</link>
				<link name="lower_arm_left">
					<viaPoint type="FIXPOINT">0.2678992027797853 0.03583242741036443 0.2069073012593709</viaPoint>
				</link>
			</myoMuscle>
			<myoMuscle name="motor13">
				<link name="torso">
					<viaPoint type="FIXPOINT">-0.2865417124191222 0.027567759775711326 0.5754772798049546</viaPoint>
				</link>
				<link name="upper_arm_right">
					<viaPoint type="FIXPOINT">-0.3100595438038796 0.03028513778074756 0.4999261351441217</viaPoint>
				</link>
			</myoMuscle>
			<myoMuscle name="motor14">
				<link name="torso">
					<viaPoint type="FIXPOINT">-0.2361746654013883 0.051580505123396486 0.4649412915804758</viaPoint>
				</link>
				<link name="upper_arm_right">
					<viaPoint type="FIXPOINT">-0.2729928452353165 0.02534872143508585 0.5224541144084602</viaPoint>
				</link>
			</myoMuscle>
			<myoMuscle name="motor15">
				<link name="torso">
					<viaPoint type="FIXPOINT">-0.2475613261720895 0.04442874357637785 0.5122955827925547</viaPoint>
				</link>
				<link name="upper_arm_right">
					<viaPoint type="FIXPOINT">-0.30007478903570467 0.022709841210454967 0.49721051047718967</viaPoint>
				</link>
			</myoMuscle>
			<myoMuscle name="motor16">
				<link name="torso">
					<viaPoint type="FIXPOINT">-0.276988676375617 0.04439125301867884 0.5557407187369969</viaPoint>
				</link>
				<link name="upper_arm_right">
					<viaPoint type="FIXPOINT">-0.31034500060789244 0.03082206745575866 0.49991063563602894</viaPoint>
				</link>
			</myoMuscle>
			<myoMuscle name="motor17">
				<link name="torso">
					<viaPoint type="FIXPOINT">-0.3100988054292128 0.0015223435010265783 0.5915377063521623</viaPoint>
				</link>
				<link name="upper_arm_right">
					<viaPoint type="FIXPOINT">-0.32137016796163786 0.007630152306875684 0.5003187234483947</viaPoint>
				</link>
			</myoMuscle>
			<myoMuscle name="motor19">
				<link name="torso">
					<viaPoint type="FIXPOINT">-0.28063819529939676 -0.02704224632492396 0.5573368932694007</viaPoint>
				</link>
				<link name="upper_arm_right">
					<viaPoint type="FIXPOINT">-0.31227409983325266 -0.013061256627521112 0.5008947060731925</viaPoint>
				</link>
			</myoMuscle>
			<myoMuscle name="motor20">
				<link name="torso">
					<viaPoint type="FIXPOINT">-0.25121801331230276 -0.027145062145860932 0.5138948924572266</viaPoint>
				</link>
				<link name="upper_arm_right">
					<viaPoint type="FIXPOINT">-0.3015758477206274 -0.006670983173129905 0.49786702211462924</viaPoint>
				</link>
			</myoMuscle>
			<myoMuscle name="motor21">
				<link name="torso">
					<viaPoint type="FIXPOINT">-0.2400353945188691 -0.023987096152052287 0.4666298422148289</viaPoint>
				</link>
				<link name="upper_arm_right">
					<viaPoint type="FIXPOINT">-0.2748962629442564 -0.011907637690732055 0.5012866040968159</viaPoint>
				</link>
			</myoMuscle>
			<myoMuscle name="motor22">
				<link name="torso">
					<viaPoint type="FIXPOINT">-0.28894263461133707 -0.009197461272100206 0.5755911026958066</viaPoint>
				</link>
				<link name="upper_arm_right">
					<viaPoint type="FIXPOINT">-0.31261279948774684 -0.013566470644431502 0.5009024931636205</viaPoint>
				</link>
			</myoMuscle>
			<myoMuscle name="motor23">
				<link name="upper_arm_right">
					<viaPoint type="FIXPOINT">-0.2927179381579887 0.06921363702330818 0.3509999999999996</viaPoint>
				</link>
				<link name="elbow_right">
					<viaPoint type="FIXPOINT">-0.2865778193590986 0.03795115144253663 0.24352490038977484</viaPoint>
				</link>
			</myoMuscle>
			<myoMuscle name="motor24">
				<link name="upper_arm_right">
					<viaPoint type="FIXPOINT">-0.2927151972274971 -0.06087121931746884 0.37527063961360624</viaPoint>
				</link>
				<link name="elbow_right">
					<viaPoint type="FIXPOINT">-0.28895313084001095 -0.03144686483677047 0.23141087334449123</viaPoint>
				</link>
			</myoMuscle>
			<myoMuscle name="motor25">
				<link name="upper_arm_right">
					<viaPoint type="FIXPOINT">-0.33808414200087167 0.0005785579049365926 0.3034610678007715</viaPoint>
				</link>
				<link name="elbow_right">
					<viaPoint type="FIXPOINT">-0.3291984972098272 0.016253264493843442 0.2098325598333225</viaPoint>
				</link>
				<link name="lower_arm_right">
					<viaPoint type="FIXPOINT">-0.30414485272029385 0.037629519155083745 0.2044598038574132</viaPoint>
				</link>
			</myoMuscle>
			<myoMuscle name="motor26">
				<link name="upper_arm_right">
					<viaPoint type="FIXPOINT">-0.329895331365946 0.00016245467504563495 0.3035622532117917</viaPoint>
				</link>
				<link name="elbow_right">
					<viaPoint type="FIXPOINT">-0.3273568776263243 -0.0062954671813740815 0.21679097491551172</viaPoint>
				</link>
				<link name="lower_arm_right">
					<viaPoint type="FIXPOINT">-0.30768343884641763 -0.03433944284239181 0.20586942596149452</viaPoint>
				</link>
			</myoMuscle>
			<myoMuscle name="motor33">
				<link name="torso">
					<viaPoint type="FIXPOINT">-0.046024372034541225 0.052015214059931314 0.674697514155262</viaPoint>
				</link>
				<link name="head">
					<viaPoint type="FIXPOINT">-0.03535533905933377 0.0368776825603552 0.7154975119199973</viaPoint>
				</link>
			</myoMuscle>
			<myoMuscle name="motor34">
				<link name="torso">
					<viaPoint type="FIXPOINT">-0.046000000000006314 0.0015223435010275532 0.6766975121882185</viaPoint>
				</link>
				<link name="head">
					<viaPoint type="FIXPOINT">-6.287761774461335e-15 -0.04847765649897237 0.7154975119199979</viaPoint>
				</link>
			</myoMuscle>
			<myoMuscle name="motor35">
				<link name="torso">
					<viaPoint type="FIXPOINT">-0.0460290385705623 -0.048974867289732 0.6746975141552634</viaPoint>
				</link>
				<link name="head">
					<viaPoint type="FIXPOINT">-0.03535533905933375 -0.03383299555829972 0.7154975119199978</viaPoint>
				</link>
			</myoMuscle>
			<myoMuscle name="motor36">
				<link name="torso">
					<viaPoint type="FIXPOINT">0.04603087891830206 0.05201809336370206 0.6746975141552624</viaPoint>
				</link>
				<link name="head">
					<viaPoint type="FIXPOINT">0.03535533905932116 0.03687768256035521 0.7154975119199974</viaPoint>
				</link>
			</myoMuscle>
			<myoMuscle name="motor37">
				<link name="torso">
					<viaPoint type="FIXPOINT">0.04599999999999385 0.0015223435010275582 0.6746975121882186</viaPoint>
				</link>
				<link name="head">
					<viaPoint type="FIXPOINT">-6.287761774461335e-15 -0.04847765649897237 0.7154975119199979</viaPoint>
				</link>
			</myoMuscle>
			<myoMuscle name="motor38">
				<link name="torso">
					<viaPoint type="FIXPOINT">0.04603508786431375 -0.048975343773744184 0.673697514156121</viaPoint>
				</link>
				<link name="head">
					<viaPoint type="FIXPOINT">0.03535533905932117 -0.03383299555829972 0.7154975119199979</viaPoint>
				</link>
			</myoMuscle>
		</plugin>
	</model>
</sdf>
