<?xml version="1.0" ?>
<sdf version="1.6">
	<model name="biking_legs3">
		<link name="front_part">
			<self_collide>false</self_collide>
			<pose frame="">-0.7163902611040208 0.010388551714715331 0.48643769332085723 0.0 -0.0 0.0</pose>
			<inertial>
				<pose frame="">0.0 0.0 0.0 0 0 0</pose>
				<mass>16.81067246604605</mass>
				<inertia>
					<ixx>6.39949781835294</ixx>
					<ixy>0.1811361598743797</ixy>
					<ixz>4.493581221870604</ixz>
					<iyy>17.853228424407295</iyy>
					<iyz>-0.05387549209623626</iyz>
					<izz>13.91291969470344</izz>
				</inertia>
			</inertial>
			<collision name="front_part_collision">
				<geometry>
					<mesh>
						<uri>model://biking_legs3/meshes/CAD/front_part.stl</uri>
						<scale>0.001 0.001 0.001</scale>
					</mesh>
				</geometry>
			</collision>
			<visual name="front_part_visual">
				<geometry>
					<mesh>
						<uri>model://biking_legs3/meshes/CAD/front_part.stl</uri>
						<scale>0.001 0.001 0.001</scale>
					</mesh>
				</geometry>
			</visual>
		</link>
		<link name="left_wheel">
			<self_collide>false</self_collide>
			<pose frame="">-0.9984258521253281 -0.3500004088111488 0.3156670000000095 0.0 -0.0 0.0</pose>
			<inertial>
				<pose frame="">0.0 0.0 0.0 0 0 0</pose>
				<mass>13.340163929097853</mass>
				<inertia>
					<ixx>3.472638325579821</ixx>
					<ixy>-4.661713033463341</ixy>
					<ixz>4.204420712343591</ixz>
					<iyy>15.643794956041955</iyy>
					<iyz>1.4738690559763468</iyz>
					<izz>15.441547158388762</izz>
				</inertia>
			</inertial>
			<collision name="left_wheel_collision">
				<geometry>
					<mesh>
						<uri>model://biking_legs3/meshes/CAD/left_wheel.stl</uri>
						<scale>0.001 0.001 0.001</scale>
					</mesh>
				</geometry>
			</collision>
			<visual name="left_wheel_visual">
				<geometry>
					<mesh>
						<uri>model://biking_legs3/meshes/CAD/left_wheel.stl</uri>
						<scale>0.001 0.001 0.001</scale>
					</mesh>
				</geometry>
			</visual>
		</link>
		<link name="right_wheel">
			<self_collide>false</self_collide>
			<pose frame="">-0.998425852125328 0.34200026941711825 0.31566700000003983 0.0 -0.0 0.0</pose>
			<inertial>
				<pose frame="">0.0 0.0 0.0 0 0 0</pose>
				<mass>13.340163929097852</mass>
				<inertia>
					<ixx>3.398785818884781</ixx>
					<ixy>4.555157860544104</ixy>
					<ixz>4.204420712343995</ixz>
					<iyy>15.643794956042209</iyy>
					<iyz>-1.4401800727652248</iyz>
					<izz>15.367694651693462</izz>
				</inertia>
			</inertial>
			<collision name="right_wheel_collision">
				<geometry>
					<mesh>
						<uri>model://biking_legs3/meshes/CAD/right_wheel.stl</uri>
						<scale>0.001 0.001 0.001</scale>
					</mesh>
				</geometry>
			</collision>
			<visual name="right_wheel_visual">
				<geometry>
					<mesh>
						<uri>model://biking_legs3/meshes/CAD/right_wheel.stl</uri>
						<scale>0.001 0.001 0.001</scale>
					</mesh>
				</geometry>
			</visual>
		</link>
		<link name="pedal_right">
			<self_collide>false</self_collide>
			<pose frame="">-0.07135058660126174 0.14798929043182094 0.31029664884547375 0.0 -0.0 0.0</pose>
			<inertial>
				<pose frame="">0.0 0.0 0.0 0 0 0</pose>
				<mass>0.9460025886022257</mass>
				<inertia>
					<ixx>0.11242108960928084</ixx>
					<ixy>0.009988957391500707</ixy>
					<ixz>0.02087959052137525</ixz>
					<iyy>0.09631584375868488</iyy>
					<iyz>-0.04344098838830787</iyz>
					<izz>0.026443737094791624</izz>
				</inertia>
			</inertial>
			<collision name="pedal_right_collision">
				<geometry>
					<mesh>
						<uri>model://biking_legs3/meshes/CAD/pedal_right.stl</uri>
						<scale>0.001 0.001 0.001</scale>
					</mesh>
				</geometry>
			</collision>
			<visual name="pedal_right_visual">
				<geometry>
					<mesh>
						<uri>model://biking_legs3/meshes/CAD/pedal_right.stl</uri>
						<scale>0.001 0.001 0.001</scale>
					</mesh>
				</geometry>
			</visual>
		</link>
		<link name="kurbel">
			<self_collide>false</self_collide>
			<pose frame="">0.091460424682622 0.00013171801208978898 0.27329692069878403 0.0 -0.0 0.0</pose>
			<inertial>
				<pose frame="">0.0 0.0 0.0 0 0 0</pose>
				<mass>2.7832708381107922</mass>
				<inertia>
					<ixx>0.22462193157576568</ixx>
					<ixy>0.012645503066186175</ixy>
					<ixz>-0.0659470079837957</ixz>
					<iyy>0.24902902015178635</iyy>
					<iyz>-0.002872706904502147</iyz>
					<izz>0.05576653320505366</izz>
				</inertia>
			</inertial>
			<collision name="kurbel_collision">
				<geometry>
					<mesh>
						<uri>model://biking_legs3/meshes/CAD/kurbel.stl</uri>
						<scale>0.001 0.001 0.001</scale>
					</mesh>
				</geometry>
			</collision>
			<visual name="kurbel_visual">
				<geometry>
					<mesh>
						<uri>model://biking_legs3/meshes/CAD/kurbel.stl</uri>
						<scale>0.001 0.001 0.001</scale>
					</mesh>
				</geometry>
			</visual>
		</link>
		<link name="pedal_left">
			<self_collide>false</self_collide>
			<pose frame="">0.25773773803251093 -0.1492447095543119 0.23951312158329505 0.0 -0.0 0.0</pose>
			<inertial>
				<pose frame="">0.0 0.0 0.0 0 0 0</pose>
				<mass>0.9460025886020178</mass>
				<inertia>
					<ixx>0.07623918960079122</ixx>
					<ixy>0.036388929758889944</ixy>
					<ixz>-0.058482646500784725</ixz>
					<iyy>0.11752556285141141</iyy>
					<iyz>0.033815871219099874</iyz>
					<izz>0.08454136407203965</izz>
				</inertia>
			</inertial>
			<collision name="pedal_left_collision">
				<geometry>
					<mesh>
						<uri>model://biking_legs3/meshes/CAD/pedal_left.stl</uri>
						<scale>0.001 0.001 0.001</scale>
					</mesh>
				</geometry>
			</collision>
			<visual name="pedal_left_visual">
				<geometry>
					<mesh>
						<uri>model://biking_legs3/meshes/CAD/pedal_left.stl</uri>
						<scale>0.001 0.001 0.001</scale>
					</mesh>
				</geometry>
			</visual>
		</link>
		<link name="foot_left">
			<self_collide>false</self_collide>
			<pose frame="">0.2597910692833977 -0.18543468322843137 0.3560201586275424 0.0 -0.0 0.0</pose>
			<inertial>
				<pose frame="">0.0 0.0 0.0 0 0 0</pose>
				<mass>0.729403886395654</mass>
				<inertia>
					<ixx>0.11818620181419005</ixx>
					<ixy>0.03514089461169389</ixy>
					<ixz>-0.06748754854293461</ixz>
					<iyy>0.1423282817931242</iyy>
					<iyz>0.04815560242066072</iyz>
					<izz>0.0748369239453079</izz>
				</inertia>
			</inertial>
			<collision name="foot_left_collision">
				<geometry>
					<mesh>
						<uri>model://biking_legs3/meshes/CAD/foot_left.stl</uri>
						<scale>0.001 0.001 0.001</scale>
					</mesh>
				</geometry>
			</collision>
			<visual name="foot_left_visual">
				<geometry>
					<mesh>
						<uri>model://biking_legs3/meshes/CAD/foot_left.stl</uri>
						<scale>0.001 0.001 0.001</scale>
					</mesh>
				</geometry>
			</visual>
		</link>
		<link name="foot_left_tip">
			<self_collide>false</self_collide>
			<pose frame="">0.24468112339817288 -0.18434874219885328 0.25433217253951174 0.0 -0.0 0.0</pose>
			<inertial>
				<pose frame="">0.0 0.0 0.0 0 0 0</pose>
				<mass>0.2779479616286563</mass>
				<inertia>
					<ixx>0.027611872305661173</ixx>
					<ixy>0.012539263641567022</ixy>
					<ixz>-0.01732105246273539</ixz>
					<iyy>0.034734097425316766</iyy>
					<iyz>0.013039909131628674</iyz>
					<izz>0.026175448327296215</izz>
				</inertia>
			</inertial>
			<collision name="foot_left_tip_collision">
				<geometry>
					<mesh>
						<uri>model://biking_legs3/meshes/CAD/foot_left_tip.stl</uri>
						<scale>0.001 0.001 0.001</scale>
					</mesh>
				</geometry>
			</collision>
			<visual name="foot_left_tip_visual">
				<geometry>
					<mesh>
						<uri>model://biking_legs3/meshes/CAD/foot_left_tip.stl</uri>
						<scale>0.001 0.001 0.001</scale>
					</mesh>
				</geometry>
			</visual>
		</link>
		<link name="foot_right">
			<self_collide>false</self_collide>
			<pose frame="">0.041359349401735565 0.16245001324038627 0.36504337127069597 0.0 -0.0 0.0</pose>
			<inertial>
				<pose frame="">0.0 0.0 0.0 0 0 0</pose>
				<mass>0.7293878596526816</mass>
				<inertia>
					<ixx>0.11697947411928711</ixx>
					<ixy>-0.00490081613742879</ixy>
					<ixz>-0.011050919687831312</ixz>
					<iyy>0.0990906100370107</iyy>
					<iyz>-0.04325216098845854</iyz>
					<izz>0.021140483350197647</izz>
				</inertia>
			</inertial>
			<collision name="foot_right_collision">
				<geometry>
					<mesh>
						<uri>model://biking_legs3/meshes/CAD/foot_right.stl</uri>
						<scale>0.001 0.001 0.001</scale>
					</mesh>
				</geometry>
			</collision>
			<visual name="foot_right_visual">
				<geometry>
					<mesh>
						<uri>model://biking_legs3/meshes/CAD/foot_right.stl</uri>
						<scale>0.001 0.001 0.001</scale>
					</mesh>
				</geometry>
			</visual>
		</link>
		<link name="foot_right_tip">
			<self_collide>false</self_collide>
			<pose frame="">-0.05565898726090951 0.16136609723690573 0.3306471172537158 0.0 -0.0 0.0</pose>
			<inertial>
				<pose frame="">0.0 0.0 0.0 0 0 0</pose>
				<mass>0.2779612390081797</mass>
				<inertia>
					<ixx>0.03771571811307123</ixx>
					<ixy>0.0024882458064649426</ixy>
					<ixz>0.0050883098955195405</ixz>
					<iyy>0.03136346393122479</iyy>
					<iyz>-0.014832123788715661</iyz>
					<izz>0.008284321428814476</izz>
				</inertia>
			</inertial>
			<collision name="foot_right_tip_collision">
				<geometry>
					<mesh>
						<uri>model://biking_legs3/meshes/CAD/foot_right_tip.stl</uri>
						<scale>0.001 0.001 0.001</scale>
					</mesh>
				</geometry>
			</collision>
			<visual name="foot_right_tip_visual">
				<geometry>
					<mesh>
						<uri>model://biking_legs3/meshes/CAD/foot_right_tip.stl</uri>
						<scale>0.001 0.001 0.001</scale>
					</mesh>
				</geometry>
			</visual>
		</link>
		<link name="thigh_right">
			<self_collide>false</self_collide>
			<pose frame="">0.16181156710341493 0.18723360413571244 0.8166255885546688 0.0 -0.0 0.0</pose>
			<inertial>
				<pose frame="">0.0 0.0 0.0 0 0 0</pose>
				<mass>5.562423627088403</mass>
				<inertia>
					<ixx>3.91810241441691</ixx>
					<ixy>-0.17134800367538125</ixy>
					<ixz>-0.7398043022673142</ixz>
					<iyy>3.8862363461644036</iyy>
					<iyz>-0.8516469681074601</iyz>
					<izz>0.3673534634467851</izz>
				</inertia>
			</inertial>
			<collision name="thigh_right_collision">
				<geometry>
					<mesh>
						<uri>model://biking_legs3/meshes/CAD/thigh_right.stl</uri>
						<scale>0.001 0.001 0.001</scale>
					</mesh>
				</geometry>
			</collision>
			<visual name="thigh_right_visual">
				<geometry>
					<mesh>
						<uri>model://biking_legs3/meshes/CAD/thigh_right.stl</uri>
						<scale>0.001 0.001 0.001</scale>
					</mesh>
				</geometry>
			</visual>
		</link>
		<link name="thigh_left">
			<self_collide>false</self_collide>
			<pose frame="">0.16882644513729075 -0.2096165209822111 0.7873513405672172 0.0 -0.0 0.0</pose>
			<inertial>
				<pose frame="">0.0 0.0 0.0 0 0 0</pose>
				<mass>5.562439809619122</mass>
				<inertia>
					<ixx>3.710905561090379</ixx>
					<ixy>0.1987012541707588</ixy>
					<ixz>-0.7472872614202025</ixz>
					<iyy>3.6379483620199986</iyy>
					<iyz>0.9205165620340479</iyz>
					<izz>0.4250811170534895</izz>
				</inertia>
			</inertial>
			<collision name="thigh_left_collision">
				<geometry>
					<mesh>
						<uri>model://biking_legs3/meshes/CAD/thigh_left.stl</uri>
						<scale>0.001 0.001 0.001</scale>
					</mesh>
				</geometry>
			</collision>
			<visual name="thigh_left_visual">
				<geometry>
					<mesh>
						<uri>model://biking_legs3/meshes/CAD/thigh_left.stl</uri>
						<scale>0.001 0.001 0.001</scale>
					</mesh>
				</geometry>
			</visual>
		</link>
		<link name="shin_right">
			<self_collide>false</self_collide>
			<pose frame="">-0.001728365872964016 0.18666359715012928 0.585675889749281 0.0 -0.0 0.0</pose>
			<inertial>
				<pose frame="">0.0 0.0 0.0 0 0 0</pose>
				<mass>5.740441256821058</mass>
				<inertia>
					<ixx>2.2073819771289127</ixx>
					<ixy>0.0019739853158227427</ixy>
					<ixz>0.012562194414091697</ixz>
					<iyy>2.011853680378169</iyy>
					<iyz>-0.6310277068686915</iyz>
					<izz>0.21400493862589307</izz>
				</inertia>
			</inertial>
			<collision name="shin_right_collision">
				<geometry>
					<mesh>
						<uri>model://biking_legs3/meshes/CAD/shin_right.stl</uri>
						<scale>0.001 0.001 0.001</scale>
					</mesh>
				</geometry>
			</collision>
			<visual name="shin_right_visual">
				<geometry>
					<mesh>
						<uri>model://biking_legs3/meshes/CAD/shin_right.stl</uri>
						<scale>0.001 0.001 0.001</scale>
					</mesh>
				</geometry>
			</visual>
		</link>
		<link name="shin_left">
			<self_collide>false</self_collide>
			<pose frame="">0.11194334048518503 -0.20868043520406587 0.521236197522263 0.0 -0.0 0.0</pose>
			<inertial>
				<pose frame="">0.0 0.0 0.0 0 0 0</pose>
				<mass>5.741526758347037</mass>
				<inertia>
					<ixx>1.8380901369652676</ixx>
					<ixy>0.13199619208645033</ixy>
					<ixz>-0.3212683615757792</ixz>
					<iyy>1.6746425056241003</iyy>
					<iyz>0.6272180888670831</iyz>
					<izz>0.346095617992196</izz>
				</inertia>
			</inertial>
			<collision name="shin_left_collision">
				<geometry>
					<mesh>
						<uri>model://biking_legs3/meshes/CAD/shin_left.stl</uri>
						<scale>0.001 0.001 0.001</scale>
					</mesh>
				</geometry>
			</collision>
			<visual name="shin_left_visual">
				<geometry>
					<mesh>
						<uri>model://biking_legs3/meshes/CAD/shin_left.stl</uri>
						<scale>0.001 0.001 0.001</scale>
					</mesh>
				</geometry>
			</visual>
		</link>
		<link name="wheel_back">
			<self_collide>false</self_collide>
			<pose frame="">0.5368974286036902 0.003549955621292267 0.31941587024902457 0.0 -0.0 0.0</pose>
			<inertial>
				<pose frame="">0.0 0.0 0.0 0 0 0</pose>
				<mass>13.34016392909848</mass>
				<inertia>
					<ixx>1.8703933815675218</ixx>
					<ixy>-0.025425846119325014</ixy>
					<ixz>-2.2877521950726827</ixz>
					<iyy>6.2227778893641625</iyy>
					<iyz>-0.015126574150566754</iyz>
					<izz>4.3547634684642125</izz>
				</inertia>
			</inertial>
			<collision name="wheel_back_collision">
				<geometry>
					<mesh>
						<uri>model://biking_legs3/meshes/CAD/wheel_back.stl</uri>
						<scale>0.001 0.001 0.001</scale>
					</mesh>
				</geometry>
			</collision>
			<visual name="wheel_back_visual">
				<geometry>
					<mesh>
						<uri>model://biking_legs3/meshes/CAD/wheel_back.stl</uri>
						<scale>0.001 0.001 0.001</scale>
					</mesh>
				</geometry>
			</visual>
		</link>
		<link name="bike">
			<self_collide>false</self_collide>
			<pose frame="">-1.3108998963673458e-07 2.442664557200658e-07 0.2700101774980866 0.0 -0.0 0.0</pose>
			<inertial>
				<pose frame="">0.0 0.0 0.0 0 0 0</pose>
				<mass>21.81948036328468</mass>
				<inertia>
					<ixx>14.584709871457763</ixx>
					<ixy>0.06346341570899297</ixy>
					<ixz>-3.3597865727113314</ixz>
					<iyy>18.1782667184046</iyy>
					<iyz>0.23232283575453944</iyz>
					<izz>4.19726913050039</izz>
				</inertia>
			</inertial>
			<collision name="bike_collision">
				<geometry>
					<mesh>
						<uri>model://biking_legs3/meshes/CAD/bike.stl</uri>
						<scale>0.001 0.001 0.001</scale>
					</mesh>
				</geometry>
			</collision>
			<visual name="bike_visual">
				<geometry>
					<mesh>
						<uri>model://biking_legs3/meshes/CAD/bike.stl</uri>
						<scale>0.001 0.001 0.001</scale>
					</mesh>
				</geometry>
			</visual>
		</link>
		<joint name="joint_wheel_right" type="revolute">
			<parent>front_part</parent>
			<child>right_wheel</child>
			<pose frame="">4.263256414560601e-16 -0.003999653375198307 5.5067062021407766e-15 0 0 0</pose>
			<axis>
				<xyz>-3.1662288285727846e-30 0.9999999999999998 4.317059530368991e-14</xyz>
				<limit>
					<lower>-3.141592653589793</lower>
					<upper>3.141592653589793</upper>
				</limit>
				<use_parent_model_frame>0</use_parent_model_frame>
			</axis>
		</joint>
		<joint name="joint_wheel_back" type="revolute">
			<parent>bike</parent>
			<child>wheel_back</child>
			<pose frame="">-2.1316282072803005e-16 -0.0689996533751975 3.552713678800501e-16 0 0 0</pose>
			<axis>
				<xyz>6.938893903907228e-17 -1.0 1.27675647831893e-15</xyz>
				<limit>
					<lower>-3.141592653589793</lower>
					<upper>3.141592653589793</upper>
				</limit>
				<use_parent_model_frame>0</use_parent_model_frame>
			</axis>
		</joint>
		<joint name="joint_pedal" type="revolute">
			<parent>bike</parent>
			<child>kurbel</child>
			<pose frame="">0.0010465928955032133 -0.03513164955582009 -2.8968550344465883e-05 0 0 0</pose>
			<axis>
				<xyz>-6.938893903907228e-17 1.0 -1.27675647831893e-15</xyz>
				<limit>
					<lower>-3.141592653589793</lower>
					<upper>3.141592653589793</upper>
				</limit>
				<use_parent_model_frame>0</use_parent_model_frame>
			</axis>
		</joint>
		<joint name="joint_wheel_left" type="revolute">
			<parent>front_part</parent>
			<child>left_wheel</child>
			<pose frame="">5.684341886080802e-16 0.04600034662480176 7.567280135845067e-15 0 0 0</pose>
			<axis>
				<xyz>3.1662288285727846e-30 -0.9999999999999998 -4.317059530368991e-14</xyz>
				<limit>
					<lower>-3.141592653589793</lower>
					<upper>3.141592653589793</upper>
				</limit>
				<use_parent_model_frame>0</use_parent_model_frame>
			</axis>
		</joint>
		<joint name="joint_front" type="revolute">
			<parent>bike</parent>
			<child>front_part</child>
			<pose frame="">-0.23003546775109895 -0.010388307448302651 -0.2052706951041601 0 0 0</pose>
			<axis>
				<xyz>5.345642609144017e-16 -4.084397910750052e-14 1.0</xyz>
				<limit>
					<lower>-0.5235987755982988</lower>
					<upper>0.5235987755982988</upper>
				</limit>
				<use_parent_model_frame>0</use_parent_model_frame>
			</axis>
		</joint>
		<joint name="joint_foot_pedal_left" type="prismatic">
			<parent>pedal_left</parent>
			<child>foot_left_tip</child>
			<pose frame="">0.0016109150593670307 -0.006895967356113459 -0.011509372570013774 0 0 0</pose>
			<axis>
				<xyz>0.27563735580589016 -8.767340729605947e-11 0.9612616959415031</xyz>
				<limit>
					<lower>0.0</lower>
					<upper>0.0</upper>
				</limit>
				<use_parent_model_frame>0</use_parent_model_frame>
			</axis>
		</joint>
		<joint name="joint_foot_pedal_right" type="prismatic">
			<parent>pedal_right</parent>
			<child>foot_right_tip</child>
			<pose frame="">-0.00216774077780598 0.028623193193916735 -0.005295121165318122 0 0 0</pose>
			<axis>
				<xyz>-0.9781476020414878 8.215056525089347e-11 -0.20791168466559432</xyz>
				<limit>
					<lower>0.0</lower>
					<upper>0.0</upper>
				</limit>
				<use_parent_model_frame>0</use_parent_model_frame>
			</axis>
		</joint>
		<joint name="joint_pedal_right" type="revolute">
			<parent>kurbel</parent>
			<child>pedal_right</child>
			<pose frame="">-0.0016119184745433568 0.04199999999672469 -0.001793181174596441 0 0 0</pose>
			<axis>
				<xyz>9.640606092084743e-17 1.000000000000001 -1.9171533957241003e-15</xyz>
				<limit>
					<lower>-3.141592653589793</lower>
					<upper>3.141592653589793</upper>
				</limit>
				<use_parent_model_frame>0</use_parent_model_frame>
			</axis>
		</joint>
		<joint name="joint_pedal_left" type="revolute">
			<parent>kurbel</parent>
			<child>pedal_left</child>
			<pose frame="">0.00032433370177241015 -0.042000000017143435 -0.0013622328721490718 0 0 0</pose>
			<axis>
				<xyz>-9.640606092086124e-17 -1.0 1.917153395724097e-15</xyz>
				<limit>
					<lower>-3.141592653589793</lower>
					<upper>3.141592653589793</upper>
				</limit>
				<use_parent_model_frame>0</use_parent_model_frame>
			</axis>
		</joint>
		<joint name="joint_hip_right" type="revolute">
			<parent>bike</parent>
			<child>thigh_right</child>
			<pose frame="">0.10230160561137897 -0.02190318524668225 0.043628044073678186 0 0 0</pose>
			<axis>
				<xyz>-7.079315732196055e-11 -0.9999999999999996 1.6436650960909208e-10</xyz>
				<limit>
					<lower>0.0</lower>
					<upper>3.141592653589793</upper>
				</limit>
				<use_parent_model_frame>0</use_parent_model_frame>
			</axis>
		</joint>
		<joint name="joint_hip_left" type="revolute">
			<parent>bike</parent>
			<child>thigh_left</child>
			<pose frame="">0.07971123496201074 0.010551247010197572 0.07756928272192426 0 0 0</pose>
			<axis>
				<xyz>-4.0005042474417543e-11 -0.9999999999999998 -3.582135224889594e-10</xyz>
				<limit>
					<lower>-1.5707963267948966</lower>
					<upper>1.5707963267948966</upper>
				</limit>
				<use_parent_model_frame>0</use_parent_model_frame>
			</axis>
		</joint>
		<joint name="joint_knee_left" type="revolute">
			<parent>thigh_left</parent>
			<child>shin_left</child>
			<pose frame="">-0.08268764613262765 0.033665161313934676 0.1257241983764881 0 0 0</pose>
			<axis>
				<xyz>1.0825802292319707e-10 -1.0000000000000244 -2.2053833741226791e-10</xyz>
				<limit>
					<lower>-0.3490658503988659</lower>
					<upper>2.0943951023931953</upper>
				</limit>
				<use_parent_model_frame>0</use_parent_model_frame>
			</axis>
		</joint>
		<joint name="joint_knee_right" type="revolute">
			<parent>thigh_right</parent>
			<child>shin_right</child>
			<pose frame="">-0.01691220715379093 -0.01363317825449471 0.1495524687702752 0 0 0</pose>
			<axis>
				<xyz>1.1186506176715891e-10 1.0000000000000233 -1.4777273066014005e-10</xyz>
				<limit>
					<lower>-0.3490658503988659</lower>
					<upper>2.0943951023931953</upper>
				</limit>
				<use_parent_model_frame>0</use_parent_model_frame>
			</axis>
		</joint>
		<joint name="joint_foot_left" type="revolute">
			<parent>shin_left</parent>
			<child>foot_left</child>
			<pose frame="">-0.024136000860579935 0.02391940942613701 0.009337150669236323 0 0 0</pose>
			<axis>
				<xyz>-9.693625542995522e-12 1.0000000000000009 9.383974011169403e-11</xyz>
				<limit>
					<lower>-1.2217304763960306</lower>
					<upper>1.2217304763960306</upper>
				</limit>
				<use_parent_model_frame>0</use_parent_model_frame>
			</axis>
		</joint>
		<joint name="joint_foot_left_tip" type="fixed">
			<parent>foot_left</parent>
			<child>foot_left_tip</child>
			<pose frame="">0.007252950967189911 -0.0011665315964815193 0.04081834245744958 0 0 0</pose>
		</joint>
		<joint name="joint_foot_right" type="revolute">
			<parent>shin_right</parent>
			<child>foot_right</child>
			<pose frame="">-0.0032238570687124434 0.02408040565121837 0.02568900991304318 0 0 0</pose>
			<axis>
				<xyz>7.410489818547159e-11 0.9999999999999991 4.648592361995051e-11</xyz>
				<limit>
					<lower>-1.2217304763960306</lower>
					<upper>1.2217304763960306</upper>
				</limit>
				<use_parent_model_frame>0</use_parent_model_frame>
			</axis>
		</joint>
		<joint name="joint_foot_right_tip" type="fixed">
			<parent>foot_right</parent>
			<child>foot_right_tip</child>
			<pose frame="">0.03944808962683593 0.001164321660926575 0.012751661723522859 0 0 0</pose>
		</joint>
		<plugin filename="libcardsflow_gazebo_plugin.so" name="cardsflow_gazebo_plugin"/>
	</model>
</sdf>
