<sdf version="1.6">
	<model name="musc-le">
		<link name="base">
			<kinematic>true</kinematic>
			<self_collide>false</self_collide>
			<pose frame="">0.23957826975460578 0.301639778486056 -0.0040404461598430655 0.0 -0.0 0.0</pose>
			<inertial>
				<pose frame="">0.0 0.0 0.0 0 0 0</pose>
				<mass>1.7736941745779755</mass>
				<inertia>
					<ixx>0.26644336870054436</ixx>
					<ixy>-0.12844889813594437</ixy>
					<ixz>0.0007876258706259874</ixz>
					<iyy>0.12328607350226468</iyy>
					<iyz>0.001009493929327395</iyz>
					<izz>0.3889425825854345</izz>
				</inertia>
			</inertial>
			<collision name="base_collision">
				<geometry>
					<mesh>
						<uri>model://musc-le/meshes/collisions/base.dae</uri>
						<scale>0.001 0.001 0.001</scale>
					</mesh>
				</geometry>
			</collision>
			<visual name="base_visual">
				<geometry>
					<mesh>
						<uri>model://musc-le/meshes/visuals/base.dae</uri>
						<scale>0.001 0.001 0.001</scale>
					</mesh>
				</geometry>
			</visual>
		</link>
		<link name="lower_arm">
			<self_collide>false</self_collide>
			<pose frame="">0.23903912786569176 0.3020852713062623 0.26729174484446844 0.0 -0.0 0.0</pose>
			<inertial>
				<pose frame="">0.0 0.0 0.0 0 0 0</pose>
				<mass>2.6629267585832319</mass>
				<inertia>
					<ixx>0.11962789096363666</ixx>
					<ixy>-0.048124291773881854</ixy>
					<ixz>-0.04440482012156901</ixz>
					<iyy>0.09622603986972515</iyy>
					<iyz>-0.056339575354820516</iyz>
					<izz>0.09920838157250772</izz>
				</inertia>
			</inertial>
			<collision name="lower_arm_collision">
				<geometry>
					<mesh>
						<uri>model://musc-le/meshes/collisions/lower_arm.dae</uri>
						<scale>0.001 0.001 0.001</scale>
					</mesh>
				</geometry>
			</collision>
			<visual name="lower_arm_visual">
				<geometry>
					<mesh>
						<uri>model://musc-le/meshes/visuals/lower_arm.dae</uri>
						<scale>0.001 0.001 0.001</scale>
					</mesh>
				</geometry>
			</visual>
		</link>
		<link name="upper_arm">
			<self_collide>false</self_collide>
			<pose frame="">0.24047286580334848 0.2964623740503764 0.5988889249748395 0.0 -0.0 0.0</pose>
			<inertial>
				<pose frame="">0.0 0.0 0.0 0 0 0</pose>
				<mass>0.19546573395199657</mass>
				<inertia>
					<ixx>0.09875572585780393</ixx>
					<ixy>-0.013938850255772264</ixy>
					<ixz>-0.029857585152300914</ixz>
					<iyy>0.09288624160612241</iyy>
					<iyz>-0.036797983975456514</iyz>
					<izz>0.028511074078668243</izz>
				</inertia>
			</inertial>
			<collision name="upper_arm_collision">
				<geometry>
					<mesh>
						<uri>model://musc-le/meshes/collisions/upper_arm.dae</uri>
						<scale>0.001 0.001 0.001</scale>
					</mesh>
				</geometry>
			</collision>
			<visual name="upper_arm_visual">
				<geometry>
					<mesh>
						<uri>model://musc-le/meshes/visuals/upper_arm.dae</uri>
						<scale>0.001 0.001 0.001</scale>
					</mesh>
				</geometry>
			</visual>
		</link>
		<joint name="upper_joint" type="revolute">
			<parent>lower_arm</parent>
			<child>upper_arm</child>
			<pose frame="">-0.004822865803349181 -3.31893305476072e-05 -0.137753391072036 0 0 0</pose>
			<axis>
				<xyz>1.0000000000000002 -8.881784197001256e-16 -9.575673587391985e-16</xyz>
				<limit>
					<!-- <lower>-1.3962634015954636</lower>
					<upper>1.3962634015954636</upper> -->
					<lower>-0.6471975511965976</lower>
					<upper>0.6471975511965976</upper>
				</limit>
				<use_parent_model_frame>0</use_parent_model_frame>
			</axis>
		</joint>
		<joint name="lower_joint" type="revolute">
			<parent>base</parent>
			<child>lower_arm</child>
			<pose frame="">-0.016839127865691774 -8.52713062622712e-05 -0.2296310846758187 0 0 0</pose>
			<axis>
				<xyz>-1.0 2.3876466213831606e-16 7.771561172376107e-16</xyz>
				<limit>
					<lower>-1.0471975511965976</lower>
					<upper>1.0471975511965976</upper>
				</limit>
				<use_parent_model_frame>0</use_parent_model_frame>
			</axis>
		</joint>
		<plugin filename="libcardsflow_gazebo_plugin.so" name="cardsflow_gazebo_plugin">
		</plugin>
	</model>
</sdf>
