<?xml version="1.0" ?>
<sdf version="1.6">
	<model name="musc-le">
		<link name="base">
			<self_collide>false</self_collide>
			<pose frame="">0.23957827048181796 0.30163977793083996 -0.004040448833546772 0.0 -0.0 0.0</pose>
			<inertial>
				<pose frame="">0.0 0.0 0.0 0 0 0</pose>
				<mass>4.577960862900375</mass>
				<inertia>
					<ixx>0.6964975926619872</ixx>
					<ixy>-0.3312447043459656</ixy>
					<ixz>0.004041225606325644</ixz>
					<iyy>0.32525726121367043</iyy>
					<iyz>0.005206949913105313</iyz>
					<izz>1.0200577750904367</izz>
				</inertia>
			</inertial>
			<visual name="base_visual">
				<geometry>
					<mesh>
						<uri>model://musc-le/meshes/CAD/base.stl</uri>
						<scale>0.001 0.001 0.001</scale>
					</mesh>
				</geometry>
			</visual>
		</link>
		<link name="lower_arm">
			<self_collide>false</self_collide>
			<pose frame="">0.23903913120121423 0.302085272994778 0.26729160891484993 0.0 -0.0 0.0</pose>
			<inertial>
				<pose frame="">0.0 0.0 0.0 0 0 0</pose>
				<mass>1.5237445153117568</mass>
				<inertia>
					<ixx>0.27699156924269264</ixx>
					<ixy>-0.1101945872964069</ixy>
					<ixz>-0.0971947396294029</ixz>
					<iyy>0.22475459970967124</iyy>
					<iyz>-0.12275802995208156</iyz>
					<izz>0.22682816814682522</izz>
				</inertia>
			</inertial>
			<visual name="lower_arm_visual">
				<geometry>
					<mesh>
						<uri>model://musc-le/meshes/CAD/lower_arm.stl</uri>
						<scale>0.001 0.001 0.001</scale>
					</mesh>
				</geometry>
			</visual>
		</link>
		<link name="upper_arm">
			<self_collide>false</self_collide>
			<pose frame="">0.24047285530359636 0.2964623750601402 0.598888808820894 0.0 -0.0 0.0</pose>
			<inertial>
				<pose frame="">0.0 0.0 0.0 0 0 0</pose>
				<mass>0.74353549858149</mass>
				<inertia>
					<ixx>0.3432572245813847</ixx>
					<ixy>-0.0530075283202031</ixy>
					<ixz>-0.10709519305695231</ixz>
					<iyy>0.32091666754414694</iyy>
					<iyz>-0.1320144193296374</iyz>
					<izz>0.10845004554797033</izz>
				</inertia>
			</inertial>
			<visual name="upper_arm_visual">
				<geometry>
					<mesh>
						<uri>model://musc-le/meshes/CAD/upper_arm.stl</uri>
						<scale>0.001 0.001 0.001</scale>
					</mesh>
				</geometry>
			</visual>
		</link>
		<joint name="lower_joint" type="revolute">
			<parent>base</parent>
			<child>lower_arm</child>
			<pose frame="">0.22219999999999998 0.30200000000000005 0.03766066016864976 0 0 0</pose>
			<axis>
				<xyz>-1.0 2.3876466213831606e-16 7.771561172376107e-16</xyz>
				<limit>
					<lower>-1.0471975511965976</lower>
					<upper>1.0471975511965976</upper>
				</limit>
				<use_parent_model_frame>0</use_parent_model_frame>
			</axis>
		</joint>
		<joint name="upper_joint" type="revolute">
			<parent>lower_arm</parent>
			<child>upper_arm</child>
			<pose frame="">0.2356499999999993 0.2964291847198288 0.46113553390280354 0 0 0</pose>
			<axis>
				<xyz>1.0000000000000002 -8.881784197001256e-16 -9.575673587391985e-16</xyz>
				<limit>
					<lower>-1.3962634015954636</lower>
					<upper>1.3962634015954636</upper>
				</limit>
				<use_parent_model_frame>0</use_parent_model_frame>
			</axis>
		</joint>
		<plugin filename="libgazebo_ros_muscle_interface.so" name="muscle_interface_plugin"/>
		<muscles>model://musc-le/muscles.osim</muscles>
	</model>
</sdf>
