<robot name="roboy_icecream">
  <joint name="shoulder_left_axis0" type="revolute">
    <parent link="torso" />
    <child link="shoulder_left_link1" />
    <origin rpy="0  0  0" xyz="0.29189  0.01393  0.54489" />
    <axis xyz="-0.99863 -0.05074  0.01234" />
    <limit effort="0.0" lower="-3.14159265359" upper="3.14159265359" velocity="0.0" />
  </joint>
  <joint name="shoulder_left_axis1" type="revolute">
    <parent link="shoulder_left_link1" />
    <child link="shoulder_left_link2" />
    <origin rpy="0  0  0" xyz="0  0  0" />
    <axis xyz="-0.05101  0.99844 -0.02231" />
    <limit effort="0.0" lower="-3.14159265359" upper="3.14159265359" velocity="0.0" />
  </joint>
  <joint name="shoulder_left_axis2" type="revolute">
    <parent link="shoulder_left_link2" />
    <child link="arm_left_upper" />
    <origin rpy="0  0  0" xyz="0  0  0" />
    <axis xyz="-0.01118 -0.0229  -0.99967" />
    <limit effort="0.0" lower="-3.14159265359" upper="3.14159265359" velocity="0.0" />
  </joint>
  <joint name="wrist_left" type="revolute">
    <parent link="arm_left_lower" />
    <child link="hand_left_palm" />
    <origin rpy="0  0  0" xyz="-0.0176  -0.00514 -0.22998" />
    <axis xyz="-0.01118 -0.0229  -0.99967" />
    <limit effort="0.0" lower="-0.872664625997" upper="0.872664625997" velocity="0.0" />
  </joint>
  <joint name="spine" type="revolute">
    <parent link="torso" />
    <child link="bike_back" />
    <origin rpy="0  0  0" xyz="0.00000000e+00  -2.00000000e-05   2.99330000e-01" />
    <axis xyz="0  0 -1" />
    <limit effort="0.0" lower="-3.14" upper="3.14" velocity="0.0" />
  </joint>
  <joint name="wrist_right" type="revolute">
    <parent link="arm_right_lower" />
    <child link="palm_right" />
    <origin rpy="0  0  0" xyz="0.01941 -0.00089 -0.23765" />
    <axis xyz="1.23400000e-02  -2.50000000e-04  -9.99920000e-01" />
    <limit effort="0.0" lower="-2" upper="2" velocity="0.0" />
  </joint>
  <joint name="ice_tray_0" type="prismatic">
    <parent link="bike_front" />
    <child link="ice_left" />
    <origin rpy="0  0  0" xyz="0.23999  0.46633  1.15482" />
    <axis xyz="0       0.5      0.86602" />
    <limit effort="0.0" lower="-3.14" upper="3.14" velocity="0.0" />
  </joint>
  <joint name="ice_tray_1" type="prismatic">
    <parent link="bike_front" />
    <child link="ice_right" />
    <origin rpy="0  0  0" xyz="0       0.46633  1.15482" />
    <axis xyz="0       0.5      0.86602" />
    <limit effort="0.0" lower="-3.14" upper="3.14" velocity="0.0" />
  </joint>
  <joint name="palm_scooper" type="fixed">
    <parent link="palm_right" />
    <child link="scooper" />
    <origin rpy="0  0  0" xyz="-0.01679  0.00896 -0.06231" />
    <axis xyz="0.99863 -0.05074  0.01234" />
    <limit effort="0.0" lower="-1.57079632679" upper="1.57079632679" velocity="0.0" />
  </joint>
  <joint name="shoulder_right_axis0" type="revolute">
    <parent link="torso" />
    <child link="shoulder_right_link1" />
    <origin rpy="0  0  0" xyz="-0.29317  0.00923  0.5481" />
    <axis xyz="1 0 0" />
    <limit effort="0.0" lower="-1.57" upper="1.57" velocity="0.0" />
  </joint>
  <joint name="shoulder_right_axis1" type="revolute">
    <parent link="shoulder_right_link1" />
    <child link="shoulder_right_link2" />
    <origin rpy="0  0  0" xyz="0  0  0" />
    <axis xyz="0 1 0" />
    <limit effort="0.0" lower="-0.2" upper="1.57" velocity="0.0" />
  </joint>
  <joint name="shoulder_right_axis2" type="revolute">
    <parent link="shoulder_right_link2" />
    <child link="arm_right_upper" />
    <origin rpy="0  0  0" xyz="0  0  0" />
    <axis xyz="0 0 1" />
    <limit effort="0.0" lower="-0.3" upper="2.2" velocity="0.0" />
  </joint>
  <joint name="neck_axis0" type="revolute">
    <parent link="torso" />
    <child link="neck_link1" />
    <origin rpy="0  0  0" xyz="0       0.00152  0.71567" />
    <axis xyz="0.12498 -0.99215  0" />
    <limit effort="0.0" lower="-0.523598775598" upper="0.523598775598" velocity="0.0" />
  </joint>
  <joint name="neck_axis2" type="revolute">
    <parent link="neck_link2" />
    <child link="head" />
    <origin rpy="0  0  0" xyz="0  0  0" />
    <axis xyz="0  0  1" />
    <limit effort="0.0" lower="-0.523598775598" upper="0.523598775598" velocity="0.0" />
  </joint>
  <joint name="neck_axis1" type="revolute">
    <parent link="neck_link1" />
    <child link="neck_link2" />
    <origin rpy="0  0  0" xyz="0  0  0" />
    <axis xyz="-0.99215 -0.12498  0" />
    <limit effort="0.0" lower="-0.523598775598" upper="0.523598775598" velocity="0.0" />
  </joint>
  <joint name="bike_steering" type="revolute">
    <parent link="bike_back" />
    <child link="bike_front" />
    <origin rpy="0  0  0" xyz="-0.00193 -1.20232 -0.903" />
    <axis xyz="0  0  1" />
    <limit effort="0.0" lower="-0.523598775598" upper="0.523598775598" velocity="0.0" />
  </joint>
  <joint name="elbow_right" type="revolute">
    <parent link="arm_right_upper" />
    <child link="arm_right_lower" />
    <origin rpy="0  0  0" xyz="-0.013    0.00079 -0.3624" />
    <axis xyz="-0.99863  0.05074 -0.01234" />
    <limit effort="0.0" lower="0.0" upper="2.1" velocity="0.0" />
  </joint>
  <joint name="elbow_left" type="revolute">
    <parent link="arm_left_upper" />
    <child link="arm_left_lower" />
    <origin rpy="0  0  0" xyz="0.01342 -0.00741 -0.36229" />
    <axis xyz="-0.99863 -0.05074  0.01234" />
    <limit effort="0.0" lower="-3.14" upper="3.14" velocity="0.0" />
  </joint>
  <joint name="scooper_target_axis0" type="revolute">
    <parent link="scooper" />
    <child link="sphere_link1" />
    <origin rpy="0  0  0" xyz="0.05602  0.09788  0.00053" />
    <axis xyz="1  0  0" />
    <limit effort="0.0" lower="-3.14159265359" upper="3.14159265359" velocity="0.0" />
  </joint>
  <joint name="scooper_target_axis1" type="revolute">
    <parent link="sphere_link1" />
    <child link="sphere_link2" />
    <origin rpy="0  0  0" xyz="0  0  0" />
    <axis xyz="0  0  1" />
    <limit effort="0.0" lower="-3.14159265359" upper="3.14159265359" velocity="0.0" />
  </joint>
  <joint name="scooper_target_axis2" type="revolute">
    <parent link="sphere_link2" />
    <child link="scooper_target" />
    <origin rpy="0  0  0" xyz="0  0  0" />
    <axis xyz="0 -1  0" />
    <limit effort="0.0" lower="-3.14159265359" upper="3.14159265359" velocity="0.0" />
  </joint>
  <link name="head">
    <inertial>
      <mass value="2.049574035129589" />
      <origin rpy="0  0  0" xyz="0.00051  0.04492  0.14549" />
      <inertia ixx="1.5567369122227759" ixy="-6.313507101682236e-05" ixz="-0.0010119595995300493" iyy="1.5459780882221161" iyz="-0.08466584811454989" izz="0.0305276597273415" />
    </inertial>
    <collision name="head_collision">
      <origin rpy="0  0  0" xyz="0.00051  0.04492  0.14549" />
      <geometry>
        <mesh filename="package://robots/roboy_icecream/meshes/collisions/head.stl" scale="0.001 0.001 0.001" />
      </geometry>
    </collision>
    <visual name="head_visual">
      <origin rpy="0  0  0" xyz="0.00051  0.04492  0.14549" />
      <geometry>
        <mesh filename="package://robots/roboy_icecream/meshes/visuals/head.stl" scale="0.001 0.001 0.001" />
      </geometry>
    </visual>
  </link>
  <link name="torso">
    <inertial>
      <mass value="11.519352383740124" />
      <origin rpy="0  0  0" xyz="0       0.00152  0.29933" />
      <inertia ixx="3.1683367909806135" ixy="-0.0013345135928581463" ixz="0.0006117362846899188" iyy="3.4235938506289556" iyz="0.007981326615620964" izz="0.3205526083913695" />
    </inertial>
    <collision name="torso_collision">
      <origin rpy="0  0  0" xyz="0       0.00152  0.29933" />
      <geometry>
        <mesh filename="package://robots/roboy_icecream/meshes/collisions/torso.stl" scale="0.001 0.001 0.001" />
      </geometry>
    </collision>
    <visual name="torso_visual">
      <origin rpy="0  0  0" xyz="0       0.00152  0.29933" />
      <geometry>
        <mesh filename="package://robots/roboy_icecream/meshes/visuals/torso.stl" scale="0.001 0.001 0.001" />
      </geometry>
    </visual>
  </link>
  <link name="arm_right_upper">
    <inertial>
      <mass value="2.98314384024382" />
      <origin rpy="0  0  0" xyz="0.003   -0.0009  -0.25209" />
      <inertia ixx="0.29217335254578813" ixy="0.007195986428065332" ixz="0.2566402710814884" iyy="0.5430496409097104" iyz="-0.006814109122042475" izz="0.25340978516468865" />
    </inertial>
    <collision name="arm_right_upper_collision">
      <origin rpy="0  0  0" xyz="0.003   -0.0009  -0.25209" />
      <geometry>
        <mesh filename="package://robots/roboy_icecream/meshes/collisions/arm_right_upper.stl" scale="0.001 0.001 0.001" />
      </geometry>
    </collision>
    <visual name="arm_right_upper_visual">
      <origin rpy="0  0  0" xyz="0.003   -0.0009  -0.25209" />
      <geometry>
        <mesh filename="package://robots/roboy_icecream/meshes/visuals/arm_right_upper.stl" scale="0.001 0.001 0.001" />
      </geometry>
    </visual>
  </link>
  <link name="arm_right_lower">
    <inertial>
      <mass value="1.1302413328334573" />
      <origin rpy="0  0  0" xyz="0.0173  -0.00084 -0.07176" />
      <inertia ixx="0.022219542717542003" ixy="0.002996592218549927" ixz="0.0372785797624632" iyy="0.1163548319240196" iyz="-0.0011836911746494123" izz="0.09486696050943741" />
    </inertial>
    <collision name="arm_right_lower_collision">
      <origin rpy="0  0  0" xyz="0.0173  -0.00084 -0.07176" />
      <geometry>
        <mesh filename="package://robots/roboy_icecream/meshes/collisions/arm_right_lower.stl" scale="0.001 0.001 0.001" />
      </geometry>
    </collision>
    <visual name="arm_right_lower_visual">
      <origin rpy="0  0  0" xyz="0.0173  -0.00084 -0.07176" />
      <geometry>
        <mesh filename="package://robots/roboy_icecream/meshes/visuals/arm_right_lower.stl" scale="0.001 0.001 0.001" />
      </geometry>
    </visual>
  </link>
  <link name="arm_left_upper">
    <inertial>
      <mass value="2.9509331504680603" />
      <origin rpy="0  0  0" xyz="-0.00277 -0.00513 -0.25056" />
      <inertia ixx="0.2868739907255441" ixy="-0.007514693307373462" ixz="-0.2514809919638392" iyy="0.5332670230079563" iyz="-0.008125956797189244" izz="0.2488983521756633" />
    </inertial>
    <collision name="arm_left_upper_collision">
      <origin rpy="0  0  0" xyz="-0.00277 -0.00513 -0.25056" />
      <geometry>
        <mesh filename="package://robots/roboy_icecream/meshes/collisions/arm_left_upper.stl" scale="0.001 0.001 0.001" />
      </geometry>
    </collision>
    <visual name="arm_left_upper_visual">
      <origin rpy="0  0  0" xyz="-0.00277 -0.00513 -0.25056" />
      <geometry>
        <mesh filename="package://robots/roboy_icecream/meshes/visuals/arm_left_upper.stl" scale="0.001 0.001 0.001" />
      </geometry>
    </visual>
  </link>
  <link name="arm_left_lower">
    <inertial>
      <mass value="1.1243588187932434" />
      <origin rpy="0  0  0" xyz="-0.01667 -0.00163 -0.06929" />
      <inertia ixx="0.021374786122984858" ixy="-0.0015898087419065898" ixz="-0.036788545045946835" iyy="0.11493725443881088" iyz="-0.0006916112821282024" izz="0.09416325302496205" />
    </inertial>
    <collision name="arm_left_lower_collision">
      <origin rpy="0  0  0" xyz="-0.01667 -0.00163 -0.06929" />
      <geometry>
        <mesh filename="package://robots/roboy_icecream/meshes/collisions/arm_left_lower.stl" scale="0.001 0.001 0.001" />
      </geometry>
    </collision>
    <visual name="arm_left_lower_visual">
      <origin rpy="0  0  0" xyz="-0.01667 -0.00163 -0.06929" />
      <geometry>
        <mesh filename="package://robots/roboy_icecream/meshes/visuals/arm_left_lower.stl" scale="0.001 0.001 0.001" />
      </geometry>
    </visual>
  </link>
  <link name="scooper">
    <inertial>
      <mass value="0.7580597506144706" />
      <origin rpy="0  0  0" xyz="0.04349  0.03466  0.0005" />
      <inertia ixx="0.013692103324101404" ixy="0.010237583534781294" ixz="-0.022429276909648008" iyy="0.061198863439589676" iyz="0.004549464608273051" izz="0.055163579175912116" />
    </inertial>
    <collision name="scooper_collision">
      <origin rpy="0  0  0" xyz="0.04349  0.03466  0.0005" />
      <geometry>
        <mesh filename="package://robots/roboy_icecream/meshes/collisions/scooper.stl" scale="0.001 0.001 0.001" />
      </geometry>
    </collision>
    <visual name="scooper_visual">
      <origin rpy="0  0  0" xyz="0.04349  0.03466  0.0005" />
      <geometry>
        <mesh filename="package://robots/roboy_icecream/meshes/visuals/scooper.stl" scale="0.001 0.001 0.001" />
      </geometry>
    </visual>
  </link>
  <link name="shoulder_left_link1">
    <inertial>
      <mass value="0.09036188404972216" />
      <origin rpy="0  0  0" xyz="0  0  0" />
      <inertia ixx="0.02685378687433716" ixy="-0.00036759420957439013" ixz="-0.01437212697441521" iyy="0.03453525279236198" iyz="-0.0006862058794001133" izz="0.0077236593139688075" />
    </inertial>
    <collision name="shoulder_left_link1_collision">
      <origin rpy="0  0  0" xyz="0  0  0" />
      <geometry>
        <mesh filename="package://robots/roboy_icecream/meshes/collisions/shoulder_left_link1.stl" scale="0.001 0.001 0.001" />
      </geometry>
    </collision>
    <visual name="shoulder_left_link1_visual">
      <origin rpy="0  0  0" xyz="0  0  0" />
      <geometry>
        <mesh filename="package://robots/roboy_icecream/meshes/visuals/shoulder_left_link1.stl" scale="0.001 0.001 0.001" />
      </geometry>
    </visual>
  </link>
  <link name="shoulder_left_link2">
    <inertial>
      <mass value="0.00711317010884494" />
      <origin rpy="0  0  0" xyz="0  0  0" />
      <inertia ixx="0.0021134396605301214" ixy="-2.893679789213243e-05" ixz="-0.0011313551510286908" iyy="0.00271811459643765" iyz="-5.401772354685746e-05" izz="0.000607540702812908" />
    </inertial>
    <collision name="shoulder_left_link2_collision">
      <origin rpy="0  0  0" xyz="0  0  0" />
      <geometry>
        <mesh filename="package://robots/roboy_icecream/meshes/collisions/shoulder_left_link2.stl" scale="0.001 0.001 0.001" />
      </geometry>
    </collision>
    <visual name="shoulder_left_link2_visual">
      <origin rpy="0  0  0" xyz="0  0  0" />
      <geometry>
        <mesh filename="package://robots/roboy_icecream/meshes/visuals/shoulder_left_link2.stl" scale="0.001 0.001 0.001" />
      </geometry>
    </visual>
  </link>
  <link name="shoulder_right_link1">
    <inertial>
      <mass value="0.09036760208789225" />
      <origin rpy="0  0  0" xyz="0  0  0" />
      <inertia ixx="0.02716277857038176" ixy="0.00024465659548951447" ixz="0.014521126966952602" iyy="0.03492224741539772" iyz="-0.00045739786268846115" izz="0.0077819738648302085" />
    </inertial>
    <collision name="shoulder_right_link1_collision">
      <origin rpy="0  0  0" xyz="0  0  0" />
      <geometry>
        <mesh filename="package://robots/roboy_icecream/meshes/collisions/shoulder_right_link1.stl" scale="0.001 0.001 0.001" />
      </geometry>
    </collision>
    <visual name="shoulder_right_link1_visual">
      <origin rpy="0  0  0" xyz="0  0  0" />
      <geometry>
        <mesh filename="package://robots/roboy_icecream/meshes/visuals/shoulder_right_link1.stl" scale="0.001 0.001 0.001" />
      </geometry>
    </visual>
  </link>
  <link name="shoulder_right_link2">
    <inertial>
      <mass value="0.007113171768782596" />
      <origin rpy="0  0  0" xyz="0  0  0" />
      <inertia ixx="0.002137629132340016" ixy="1.9257030781476826e-05" ixz="0.0011430126664005362" iyy="0.002748406222637266" iyz="-3.600199406508284e-05" izz="0.0006120927174830887" />
    </inertial>
    <collision name="shoulder_right_link2_collision">
      <origin rpy="0  0  0" xyz="0  0  0" />
      <geometry>
        <mesh filename="package://robots/roboy_icecream/meshes/collisions/shoulder_right_link2.stl" scale="0.001 0.001 0.001" />
      </geometry>
    </collision>
    <visual name="shoulder_right_link2_visual">
      <origin rpy="0  0  0" xyz="0  0  0" />
      <geometry>
        <mesh filename="package://robots/roboy_icecream/meshes/visuals/shoulder_right_link2.stl" scale="0.001 0.001 0.001" />
      </geometry>
    </visual>
  </link>
  <link name="neck_link1">
    <inertial>
      <mass value="0.017038665636260372" />
      <origin rpy="0  0  0" xyz="0  0  0" />
      <inertia ixx="0.008728267843512112" ixy="3.905246324887799e-15" ixz="1.836596576210159e-12" iyy="0.008728228385076956" iyz="-1.855689641317778e-05" izz="1.150229285457388e-06" />
    </inertial>
    <collision name="neck_link1_collision">
      <origin rpy="0  0  0" xyz="0  0  0" />
      <geometry>
        <mesh filename="package://robots/roboy_icecream/meshes/collisions/neck_link1.stl" scale="0.001 0.001 0.001" />
      </geometry>
    </collision>
    <visual name="neck_link1_visual">
      <origin rpy="0  0  0" xyz="0  0  0" />
      <geometry>
        <mesh filename="package://robots/roboy_icecream/meshes/visuals/neck_link1.stl" scale="0.001 0.001 0.001" />
      </geometry>
    </visual>
  </link>
  <link name="neck_link2">
    <inertial>
      <mass value="0.011421521917888835" />
      <origin rpy="0  0  0" xyz="0  0  0" />
      <inertia ixx="0.005850573477666747" ixy="2.21885727293928e-15" ixz="1.0435059226432398e-12" iyy="0.005850547027508899" iyz="-1.243923713466404e-05" izz="5.28219512713884e-07" />
    </inertial>
    <collision name="neck_link2_collision">
      <origin rpy="0  0  0" xyz="0  0  0" />
      <geometry>
        <mesh filename="package://robots/roboy_icecream/meshes/collisions/neck_link2.stl" scale="0.001 0.001 0.001" />
      </geometry>
    </collision>
    <visual name="neck_link2_visual">
      <origin rpy="0  0  0" xyz="0  0  0" />
      <geometry>
        <mesh filename="package://robots/roboy_icecream/meshes/visuals/neck_link2.stl" scale="0.001 0.001 0.001" />
      </geometry>
    </visual>
  </link>
  <link name="palm_right">
    <inertial>
      <mass value="0.7882639457851198" />
      <origin rpy="0  0  0" xyz="-0.01106  0.00102 -0.04596" />
      <inertia ixx="0.008882464779298594" ixy="0.002363342940582432" ixz="-0.02305626798602713" iyy="0.07823341343786185" iyz="0.0007601334927642789" izz="0.07061858030661425" />
    </inertial>
    <collision name="palm_right_collision">
      <origin rpy="0  0  0" xyz="-0.01106  0.00102 -0.04596" />
      <geometry>
        <mesh filename="package://robots/roboy_icecream/meshes/collisions/palm_right.stl" scale="0.001 0.001 0.001" />
      </geometry>
    </collision>
    <visual name="palm_right_visual">
      <origin rpy="0  0  0" xyz="-0.01106  0.00102 -0.04596" />
      <geometry>
        <mesh filename="package://robots/roboy_icecream/meshes/visuals/palm_right.stl" scale="0.001 0.001 0.001" />
      </geometry>
    </visual>
  </link>
  <link name="bike_back">
    <inertial>
      <mass value="12.95134492036292" />
      <origin rpy="0  0  0" xyz="-1.10000000e-04  -3.61240000e-01  -8.56840000e-01" />
      <inertia ixx="8.442264729699302" ixy="0.05546017500224689" ixz="-0.0017735467712802575" iyy="4.264300775944789" iyz="-2.9995137524469553" izz="4.303003496245288" />
    </inertial>
    <collision name="bike_back_collision">
      <origin rpy="0  0  0" xyz="-1.10000000e-04  -3.61240000e-01  -8.56840000e-01" />
      <geometry>
        <mesh filename="package://robots/roboy_icecream/meshes/collisions/bike_back.stl" scale="0.001 0.001 0.001" />
      </geometry>
    </collision>
    <visual name="bike_back_visual">
      <origin rpy="0  0  0" xyz="-1.10000000e-04  -3.61240000e-01  -8.56840000e-01" />
      <geometry>
        <mesh filename="package://robots/roboy_icecream/meshes/visuals/bike_back.stl" scale="0.001 0.001 0.001" />
      </geometry>
    </visual>
  </link>
  <link name="bike_front">
    <inertial>
      <mass value="1286.0735575666731" />
      <origin rpy="0  0  0" xyz="0.00155  0.33304  0.68923" />
      <inertia ixx="1309.930820530021" ixy="1.0887808321170818" ixz="0.8803936253774313" iyy="143.49238189135068" iyz="-26.118381241082727" izz="1223.7503807159978" />
    </inertial>
    <collision name="bike_front_collision">
      <origin rpy="0  0  0" xyz="0.00155  0.33304  0.68923" />
      <geometry>
        <mesh filename="package://robots/roboy_icecream/meshes/collisions/bike_front.stl" scale="0.001 0.001 0.001" />
      </geometry>
    </collision>
    <visual name="bike_front_visual">
      <origin rpy="0  0  0" xyz="0.00155  0.33304  0.68923" />
      <geometry>
        <mesh filename="package://robots/roboy_icecream/meshes/visuals/bike_front.stl" scale="0.001 0.001 0.001" />
      </geometry>
    </visual>
  </link>
  <link name="ice_right">
    <inertial>
      <mass value="223.724999999968" />
      <origin rpy="0  0  0" xyz="-0.12     0.14318 -0.227" />
      <inertia ixx="107.50798517446542" ixy="-16.173051463053042" ixz="8.843293061360113" iyy="29.83437223173023" iyz="44.31003474165655" izz="86.47467008535332" />
    </inertial>
    <collision name="ice_right_collision">
      <origin rpy="0  0  0" xyz="-0.12     0.14318 -0.227" />
      <geometry>
        <mesh filename="package://robots/roboy_icecream/meshes/collisions/ice_right.stl" scale="0.001 0.001 0.001" />
      </geometry>
    </collision>
    <visual name="ice_right_visual">
      <origin rpy="0  0  0" xyz="-0.12     0.14318 -0.227" />
      <geometry>
        <mesh filename="package://robots/roboy_icecream/meshes/visuals/ice_right.stl" scale="0.001 0.001 0.001" />
      </geometry>
    </visual>
  </link>
  <link name="ice_left">
    <inertial>
      <mass value="223.72499999997825" />
      <origin rpy="0  0  0" xyz="-0.12     0.14318 -0.227" />
      <inertia ixx="107.507985174471" ixy="15.658441357276965" ixz="-8.561908439038996" iyy="29.62603911829324" iyz="44.31003474165986" izz="86.26633697191619" />
    </inertial>
    <collision name="ice_left_collision">
      <origin rpy="0  0  0" xyz="-0.12     0.14318 -0.227" />
      <geometry>
        <mesh filename="package://robots/roboy_icecream/meshes/collisions/ice_left.stl" scale="0.001 0.001 0.001" />
      </geometry>
    </collision>
    <visual name="ice_left_visual">
      <origin rpy="0  0  0" xyz="-0.12     0.14318 -0.227" />
      <geometry>
        <mesh filename="package://robots/roboy_icecream/meshes/visuals/ice_left.stl" scale="0.001 0.001 0.001" />
      </geometry>
    </visual>
  </link>
  <link name="sphere_link1">
    <inertial>
      <mass value="0.03806502884740437" />
      <origin rpy="0  0  0" xyz="0  0  0" />
      <inertia ixx="0.0010062089373846016" ixy="0.001092855165572789" ixz="-0.0010718032633825062" iyy="0.002826703060752499" iyz="0.0005021701343070357" izz="0.002846239882598381" />
    </inertial>
    <collision name="sphere_link1_collision">
      <origin rpy="0  0  0" xyz="0  0  0" />
      <geometry>
        <mesh filename="package://robots/roboy_icecream/meshes/collisions/sphere_link1.stl" scale="0.001 0.001 0.001" />
      </geometry>
    </collision>
    <visual name="sphere_link1_visual">
      <origin rpy="0  0  0" xyz="0  0  0" />
      <geometry>
        <mesh filename="package://robots/roboy_icecream/meshes/visuals/sphere_link1.stl" scale="0.001 0.001 0.001" />
      </geometry>
    </visual>
  </link>
  <link name="sphere_link2">
    <inertial>
      <mass value="0.002996372533177606" />
      <origin rpy="0  0  0" xyz="0  0  0" />
      <inertia ixx="7.90980819281183e-05" ixy="8.602649991389302e-05" ixz="-8.436935309424981e-05" iyy="0.000222402284059119" iyz="3.952942748189496e-05" izz="0.00022394016799450896" />
    </inertial>
    <collision name="sphere_link2_collision">
      <origin rpy="0  0  0" xyz="0  0  0" />
      <geometry>
        <mesh filename="package://robots/roboy_icecream/meshes/collisions/sphere_link2.stl" scale="0.001 0.001 0.001" />
      </geometry>
    </collision>
    <visual name="sphere_link2_visual">
      <origin rpy="0  0  0" xyz="0  0  0" />
      <geometry>
        <mesh filename="package://robots/roboy_icecream/meshes/visuals/sphere_link2.stl" scale="0.001 0.001 0.001" />
      </geometry>
    </visual>
  </link>
  <link name="scooper_target">
    <inertial>
      <mass value="0.016515273283131564" />
      <origin rpy="0  0  0" xyz="0      -0.01025  0" />
      <inertia ixx="0.0003989982154093399" ixy="0.0004322273359439155" ixz="-0.0004650239554019727" iyy="0.0012259626816557765" iyz="0.00019861032284747138" izz="0.001197329326628685" />
    </inertial>
    <collision name="scooper_target_collision">
      <origin rpy="0  0  0" xyz="0      -0.01025  0" />
      <geometry>
        <mesh filename="package://robots/roboy_icecream/meshes/collisions/scooper_target.stl" scale="0.001 0.001 0.001" />
      </geometry>
    </collision>
    <visual name="scooper_target_visual">
      <origin rpy="0  0  0" xyz="0      -0.01025  0" />
      <geometry>
        <mesh filename="package://robots/roboy_icecream/meshes/visuals/scooper_target.stl" scale="0.001 0.001 0.001" />
      </geometry>
    </visual>
  </link>
  <link name="hand_left_palm">
    <inertial>
      <mass value="0.7882346365046045" />
      <origin rpy="0  0  0" xyz="1.11200000e-02  -1.00000000e-05  -4.59600000e-02" />
      <inertia ixx="0.008113474185192206" ixy="-0.00029901562047566046" ixz="0.022056824895233845" iyy="0.07800995452095558" iyz="7.36231408105441e-05" izz="0.07100673255042295" />
    </inertial>
    <collision name="hand_left_palm_collision">
      <origin rpy="0  0  0" xyz="1.11200000e-02  -1.00000000e-05  -4.59600000e-02" />
      <geometry>
        <mesh filename="package://robots/roboy_icecream/meshes/collisions/hand_left_palm.stl" scale="0.001 0.001 0.001" />
      </geometry>
    </collision>
    <visual name="hand_left_palm_visual">
      <origin rpy="0  0  0" xyz="1.11200000e-02  -1.00000000e-05  -4.59600000e-02" />
      <geometry>
        <mesh filename="package://robots/roboy_icecream/meshes/visuals/hand_left_palm.stl" scale="0.001 0.001 0.001" />
      </geometry>
    </visual>
  </link>
</robot>
