<?xml version="1.0" ?>
<sdf version="1.6">
	<model name="roboy_icecream">
		<link name="head">
			<self_collide>false</self_collide>
			<pose frame="">0.0005102180295681447 0.046445898229311826 0.8561776624188784 0.0 -0.0 0.0</pose>
			<inertial>
				<pose frame="">0.0 0.0 0.0 0 0 0</pose>
				<mass>2.049574035129534</mass>
				<inertia>
					<ixx>1.5391376142687194</ixx>
					<ixy>-6.313507101661185e-05</ixy>
					<ixz>-0.0010067309324671512</ixz>
					<iyy>1.5283787902680595</iyy>
					<iyz>-0.08418987485585369</iyz>
					<izz>0.030527659727340513</izz>
				</inertia>
			</inertial>
			<collision name="head_collision">
				<geometry>
					<mesh>
						<uri>model://roboy_icecream/meshes/CAD/head.stl</uri>
						<scale>0.001 0.001 0.001</scale>
					</mesh>
				</geometry>
			</collision>
			<visual name="head_visual">
				<geometry>
					<mesh>
						<uri>model://roboy_icecream/meshes/CAD/head.stl</uri>
						<scale>0.001 0.001 0.001</scale>
					</mesh>
				</geometry>
			</visual>
		</link>
		<link name="torso">
			<self_collide>false</self_collide>
			<pose frame="">-5.35255132199797e-05 -0.00020638163411974033 0.50876963867826 0.0 -0.0 0.0</pose>
			<inertial>
				<pose frame="">0.0 0.0 0.0 0 0 0</pose>
				<mass>11.588247145877938</mass>
				<inertia>
					<ixx>3.185978255602341</ixx>
					<ixy>-0.0011911816708613787</ixy>
					<ixz>0.0004984982415414905</ixz>
					<iyy>3.4400774592858085</iyy>
					<iyz>0.012190127058455498</iyz>
					<izz>0.32178508230654973</izz>
				</inertia>
			</inertial>
			<collision name="torso_collision">
				<geometry>
					<mesh>
						<uri>model://roboy_icecream/meshes/CAD/torso.stl</uri>
						<scale>0.001 0.001 0.001</scale>
					</mesh>
				</geometry>
			</collision>
			<visual name="torso_visual">
				<geometry>
					<mesh>
						<uri>model://roboy_icecream/meshes/CAD/torso.stl</uri>
						<scale>0.001 0.001 0.001</scale>
					</mesh>
				</geometry>
			</visual>
		</link>
		<link name="arm_right_palm">
			<self_collide>false</self_collide>
			<pose frame="">-0.6375555744206083 -0.246773796558467 0.13554097790837938 0.0 -0.0 0.0</pose>
			<inertial>
				<pose frame="">0.0 0.0 0.0 0 0 0</pose>
				<mass>0.808000531384317</mass>
				<inertia>
					<ixx>0.06503830374218557</ixx>
					<ixy>-0.12733108249741354</ixy>
					<ixz>0.06955734554180544</ixz>
					<iyy>0.3440972969271582</iyy>
					<iyz>0.02707665325632976</iyz>
					<izz>0.37851555642003903</izz>
				</inertia>
			</inertial>
			<collision name="arm_right_palm_collision">
				<geometry>
					<mesh>
						<uri>model://roboy_icecream/meshes/CAD/arm_right_palm.stl</uri>
						<scale>0.001 0.001 0.001</scale>
					</mesh>
				</geometry>
			</collision>
			<visual name="arm_right_palm_visual">
				<geometry>
					<mesh>
						<uri>model://roboy_icecream/meshes/CAD/arm_right_palm.stl</uri>
						<scale>0.001 0.001 0.001</scale>
					</mesh>
				</geometry>
			</visual>
		</link>
		<link name="arm_left_palm">
			<self_collide>false</self_collide>
			<pose frame="">0.6359469314832924 -0.24454698645113265 0.13488841925691009 0.0 -0.0 0.0</pose>
			<inertial>
				<pose frame="">0.0 0.0 0.0 0 0 0</pose>
				<mass>0.8080005307682467</mass>
				<inertia>
					<ixx>0.06400764902654467</ixx>
					<ixy>0.12586409233705415</ixy>
					<ixz>-0.06904914366800062</ixz>
					<iyy>0.3422930834799709</iyy>
					<iyz>0.026705627916892908</iyz>
					<izz>0.3759718202225812</izz>
				</inertia>
			</inertial>
			<collision name="arm_left_palm_collision">
				<geometry>
					<mesh>
						<uri>model://roboy_icecream/meshes/CAD/arm_left_palm.stl</uri>
						<scale>0.001 0.001 0.001</scale>
					</mesh>
				</geometry>
			</collision>
			<visual name="arm_left_palm_visual">
				<geometry>
					<mesh>
						<uri>model://roboy_icecream/meshes/CAD/arm_left_palm.stl</uri>
						<scale>0.001 0.001 0.001</scale>
					</mesh>
				</geometry>
			</visual>
		</link>
		<link name="arm_left_upper">
			<self_collide>false</self_collide>
			<pose frame="">0.3969479092585928 -0.0687557995598089 0.4162724221525472 0.0 -0.0 0.0</pose>
			<inertial>
				<pose frame="">0.0 0.0 0.0 0 0 0</pose>
				<mass>3.61016053265677</mass>
				<inertia>
					<ixx>0.6657608027976193</ixx>
					<ixy>0.10618783603266536</ixy>
					<ixz>-0.5842967867016309</ixz>
					<iyy>1.2223244262765716</iyy>
					<iyz>0.09362757641835977</iyz>
					<izz>0.6045786995275301</izz>
				</inertia>
			</inertial>
			<collision name="arm_left_upper_collision">
				<geometry>
					<mesh>
						<uri>model://roboy_icecream/meshes/CAD/arm_left_upper.stl</uri>
						<scale>0.001 0.001 0.001</scale>
					</mesh>
				</geometry>
			</collision>
			<visual name="arm_left_upper_visual">
				<geometry>
					<mesh>
						<uri>model://roboy_icecream/meshes/CAD/arm_left_upper.stl</uri>
						<scale>0.001 0.001 0.001</scale>
					</mesh>
				</geometry>
			</visual>
		</link>
		<link name="arm_right_upper">
			<self_collide>false</self_collide>
			<pose frame="">-0.39854121357397604 -0.06972333359820547 0.4159618073011953 0.0 -0.0 0.0</pose>
			<inertial>
				<pose frame="">0.0 0.0 0.0 0 0 0</pose>
				<mass>3.610090019482572</mass>
				<inertia>
					<ixx>0.66530768898862</ixx>
					<ixy>-0.10797177256512458</ixy>
					<ixz>0.5862253452514635</ixz>
					<iyy>1.2259650298836027</iyy>
					<iyz>0.09500256552716907</iyz>
					<izz>0.6096204827738396</izz>
				</inertia>
			</inertial>
			<collision name="arm_right_upper_collision">
				<geometry>
					<mesh>
						<uri>model://roboy_icecream/meshes/CAD/arm_right_upper.stl</uri>
						<scale>0.001 0.001 0.001</scale>
					</mesh>
				</geometry>
			</collision>
			<visual name="arm_right_upper_visual">
				<geometry>
					<mesh>
						<uri>model://roboy_icecream/meshes/CAD/arm_right_upper.stl</uri>
						<scale>0.001 0.001 0.001</scale>
					</mesh>
				</geometry>
			</visual>
		</link>
		<link name="arm_left_lower">
			<self_collide>false</self_collide>
			<pose frame="">0.5370118902949388 -0.178782733329587 0.24127190937071333 0.0 -0.0 0.0</pose>
			<inertial>
				<pose frame="">0.0 0.0 0.0 0 0 0</pose>
				<mass>7.274099416132657</mass>
				<inertia>
					<ixx>0.6824865040581906</ixx>
					<ixy>0.7057047294505986</ixy>
					<ixz>-0.9308804872196925</ixz>
					<iyy>2.5509906797486974</iyy>
					<iyz>0.30447448192314946</iyz>
					<izz>2.351200457091422</izz>
				</inertia>
			</inertial>
			<collision name="arm_left_lower_collision">
				<geometry>
					<mesh>
						<uri>model://roboy_icecream/meshes/CAD/arm_left_lower.stl</uri>
						<scale>0.001 0.001 0.001</scale>
					</mesh>
				</geometry>
			</collision>
			<visual name="arm_left_lower_visual">
				<geometry>
					<mesh>
						<uri>model://roboy_icecream/meshes/CAD/arm_left_lower.stl</uri>
						<scale>0.001 0.001 0.001</scale>
					</mesh>
				</geometry>
			</visual>
		</link>
		<link name="arm_right_lower">
			<self_collide>false</self_collide>
			<pose frame="">-0.5385846651599526 -0.18098143715678475 0.24196868697070045 0.0 -0.0 0.0</pose>
			<inertial>
				<pose frame="">0.0 0.0 0.0 0 0 0</pose>
				<mass>7.2740976072296055</mass>
				<inertia>
					<ixx>0.690512096677852</ixx>
					<ixy>-0.716299861565448</ixy>
					<ixz>0.9364740527049602</ixz>
					<iyy>2.565534702863339</iyy>
					<iyz>0.30933175817827113</iyz>
					<izz>2.3691261645369357</izz>
				</inertia>
			</inertial>
			<collision name="arm_right_lower_collision">
				<geometry>
					<mesh>
						<uri>model://roboy_icecream/meshes/CAD/arm_right_lower.stl</uri>
						<scale>0.001 0.001 0.001</scale>
					</mesh>
				</geometry>
			</collision>
			<visual name="arm_right_lower_visual">
				<geometry>
					<mesh>
						<uri>model://roboy_icecream/meshes/CAD/arm_right_lower.stl</uri>
						<scale>0.001 0.001 0.001</scale>
					</mesh>
				</geometry>
			</visual>
		</link>
		<link name="shoulder_left_link1">
			<self_collide>false</self_collide>
			<pose frame="">0.2918943672417947 0.013936393619393582 0.5448918362217308 0.0 -0.0 0.0</pose>
			<inertial>
				<pose frame="">0.0 0.0 0.0 0 0 0</pose>
				<mass>0.09036359201900478</mass>
				<inertia>
					<ixx>0.026854235531623766</ixx>
					<ixy>-0.00036759500737930086</ixy>
					<ixz>-0.014372406819918018</ixz>
					<iyy>0.034535872662129895</iyy>
					<iyz>-0.0006862054947928941</iyz>
					<izz>0.007723830113048254</izz>
				</inertia>
			</inertial>
			<collision name="shoulder_left_link1_collision">
				<geometry>
					<mesh>
						<uri>model://roboy_icecream/meshes/CAD/shoulder_left_link1.stl</uri>
						<scale>0.001 0.001 0.001</scale>
					</mesh>
				</geometry>
			</collision>
			<visual name="shoulder_left_link1_visual">
				<geometry>
					<mesh>
						<uri>model://roboy_icecream/meshes/CAD/shoulder_left_link1.stl</uri>
						<scale>0.001 0.001 0.001</scale>
					</mesh>
				</geometry>
			</visual>
		</link>
		<link name="shoulder_left_link2">
			<self_collide>false</self_collide>
			<pose frame="">0.2918943623808747 0.013936393384462419 0.5448918357909863 0.0 -0.0 0.0</pose>
			<inertial>
				<pose frame="">0.0 0.0 0.0 0 0 0</pose>
				<mass>0.007113170038864662</mass>
				<inertia>
					<ixx>0.002113434852236192</ixx>
					<ixy>-2.893605321299586e-05</ixy>
					<ixz>-0.0011313557762622297</ixz>
					<iyy>0.0027181118918378614</iyy>
					<iyz>-5.401618252193771e-05</iyz>
					<izz>0.0006075426550467592</izz>
				</inertia>
			</inertial>
			<collision name="shoulder_left_link2_collision">
				<geometry>
					<mesh>
						<uri>model://roboy_icecream/meshes/CAD/shoulder_left_link2.stl</uri>
						<scale>0.001 0.001 0.001</scale>
					</mesh>
				</geometry>
			</collision>
			<visual name="shoulder_left_link2_visual">
				<geometry>
					<mesh>
						<uri>model://roboy_icecream/meshes/CAD/shoulder_left_link2.stl</uri>
						<scale>0.001 0.001 0.001</scale>
					</mesh>
				</geometry>
			</visual>
		</link>
		<link name="hand_left_index_link1">
			<self_collide>false</self_collide>
			<pose frame="">0.7020945590519045 -0.3257722239676183 0.0763121062335839 0.0 -0.0 0.0</pose>
			<inertial>
				<pose frame="">0.0 0.0 0.0 0 0 0</pose>
				<mass>0.030810600216883144</mass>
				<inertia>
					<ixx>0.0034511301347674543</ixx>
					<ixy>0.00704741252805683</ixy>
					<ixz>-0.0016503707008156728</ixz>
					<iyy>0.015368863454936434</iyy>
					<iyz>0.0007657743886956809</iyz>
					<izz>0.0184592001516197</izz>
				</inertia>
			</inertial>
			<collision name="hand_left_index_link1_collision">
				<geometry>
					<mesh>
						<uri>model://roboy_icecream/meshes/CAD/hand_left_index_link1.stl</uri>
						<scale>0.001 0.001 0.001</scale>
					</mesh>
				</geometry>
			</collision>
			<visual name="hand_left_index_link1_visual">
				<geometry>
					<mesh>
						<uri>model://roboy_icecream/meshes/CAD/hand_left_index_link1.stl</uri>
						<scale>0.001 0.001 0.001</scale>
					</mesh>
				</geometry>
			</visual>
		</link>
		<link name="hand_left_index_link0">
			<self_collide>false</self_collide>
			<pose frame="">0.6813873765209756 -0.30793269611963214 0.09899240078649851 0.0 -0.0 0.0</pose>
			<inertial>
				<pose frame="">0.0 0.0 0.0 0 0 0</pose>
				<mass>0.05584900095770278</mass>
				<inertia>
					<ixx>0.005850484085961011</ixx>
					<ixy>0.01172071137349797</ixy>
					<ixz>-0.003764090047569177</ixz>
					<iyy>0.02648515087867046</iyy>
					<iyz>0.0016999571512312794</iyz>
					<izz>0.03123241202358822</izz>
				</inertia>
			</inertial>
			<collision name="hand_left_index_link0_collision">
				<geometry>
					<mesh>
						<uri>model://roboy_icecream/meshes/CAD/hand_left_index_link0.stl</uri>
						<scale>0.001 0.001 0.001</scale>
					</mesh>
				</geometry>
			</collision>
			<visual name="hand_left_index_link0_visual">
				<geometry>
					<mesh>
						<uri>model://roboy_icecream/meshes/CAD/hand_left_index_link0.stl</uri>
						<scale>0.001 0.001 0.001</scale>
					</mesh>
				</geometry>
			</visual>
		</link>
		<link name="hand_left_index_link2">
			<self_collide>false</self_collide>
			<pose frame="">0.7167599123101651 -0.33846917194165493 0.06014904547064845 0.0 -0.0 0.0</pose>
			<inertial>
				<pose frame="">0.0 0.0 0.0 0 0 0</pose>
				<mass>0.030337235888829715</mass>
				<inertia>
					<ixx>0.003586860390106042</ixx>
					<ixy>0.007360006720784233</ixy>
					<ixz>-0.0013076307207537396</ixz>
					<iyy>0.01569667077023572</iyy>
					<iyz>0.0006174739980112076</iyz>
					<izz>0.01906229503362434</izz>
				</inertia>
			</inertial>
			<collision name="hand_left_index_link2_collision">
				<geometry>
					<mesh>
						<uri>model://roboy_icecream/meshes/CAD/hand_left_index_link2.stl</uri>
						<scale>0.001 0.001 0.001</scale>
					</mesh>
				</geometry>
			</collision>
			<visual name="hand_left_index_link2_visual">
				<geometry>
					<mesh>
						<uri>model://roboy_icecream/meshes/CAD/hand_left_index_link2.stl</uri>
						<scale>0.001 0.001 0.001</scale>
					</mesh>
				</geometry>
			</visual>
		</link>
		<link name="hand_left_middle_link1">
			<self_collide>false</self_collide>
			<pose frame="">0.698437812356798 -0.271420158619049 0.04026810273649299 0.0 -0.0 0.0</pose>
			<inertial>
				<pose frame="">0.0 0.0 0.0 0 0 0</pose>
				<mass>0.03081073881990825</mass>
				<inertia>
					<ixx>0.0023216116713991944</ixx>
					<ixy>0.0058410485509295</ixy>
					<ixz>-0.000866095087917645</ixz>
					<iyy>0.015081765106218416</iyy>
					<iyz>0.00033660304946568</iyz>
					<izz>0.01730131313421421</izz>
				</inertia>
			</inertial>
			<collision name="hand_left_middle_link1_collision">
				<geometry>
					<mesh>
						<uri>model://roboy_icecream/meshes/CAD/hand_left_middle_link1.stl</uri>
						<scale>0.001 0.001 0.001</scale>
					</mesh>
				</geometry>
			</collision>
			<visual name="hand_left_middle_link1_visual">
				<geometry>
					<mesh>
						<uri>model://roboy_icecream/meshes/CAD/hand_left_middle_link1.stl</uri>
						<scale>0.001 0.001 0.001</scale>
					</mesh>
				</geometry>
			</visual>
		</link>
		<link name="hand_left_middle_link0">
			<self_collide>false</self_collide>
			<pose frame="">0.6780397787920346 -0.25870278632898713 0.06641222995506792 0.0 -0.0 0.0</pose>
			<inertial>
				<pose frame="">0.0 0.0 0.0 0 0 0</pose>
				<mass>0.055831334816546646</mass>
				<inertia>
					<ixx>0.003990392798151444</ixx>
					<ixy>0.009795111643438202</ixy>
					<ixz>-0.002510649350790885</ixz>
					<iyy>0.02592273738131162</iyy>
					<iyz>0.000957197587437346</iyz>
					<izz>0.02940988044619106</izz>
				</inertia>
			</inertial>
			<collision name="hand_left_middle_link0_collision">
				<geometry>
					<mesh>
						<uri>model://roboy_icecream/meshes/CAD/hand_left_middle_link0.stl</uri>
						<scale>0.001 0.001 0.001</scale>
					</mesh>
				</geometry>
			</collision>
			<visual name="hand_left_middle_link0_visual">
				<geometry>
					<mesh>
						<uri>model://roboy_icecream/meshes/CAD/hand_left_middle_link0.stl</uri>
						<scale>0.001 0.001 0.001</scale>
					</mesh>
				</geometry>
			</visual>
		</link>
		<link name="hand_left_middle_link2">
			<self_collide>false</self_collide>
			<pose frame="">0.712882304056937 -0.28047502772467686 0.021644247987551095 0.0 -0.0 0.0</pose>
			<inertial>
				<pose frame="">0.0 0.0 0.0 0 0 0</pose>
				<mass>0.03033633396737544</mass>
				<inertia>
					<ixx>0.0024023025129959875</ixx>
					<ixy>0.006065766877878605</ixy>
					<ixz>-0.00046779128674052803</ixz>
					<iyy>0.015432594252539332</iyy>
					<iyz>0.0001840461061177695</iyz>
					<izz>0.017804605454145028</izz>
				</inertia>
			</inertial>
			<collision name="hand_left_middle_link2_collision">
				<geometry>
					<mesh>
						<uri>model://roboy_icecream/meshes/CAD/hand_left_middle_link2.stl</uri>
						<scale>0.001 0.001 0.001</scale>
					</mesh>
				</geometry>
			</collision>
			<visual name="hand_left_middle_link2_visual">
				<geometry>
					<mesh>
						<uri>model://roboy_icecream/meshes/CAD/hand_left_middle_link2.stl</uri>
						<scale>0.001 0.001 0.001</scale>
					</mesh>
				</geometry>
			</visual>
		</link>
		<link name="hand_left_ring_link1">
			<self_collide>false</self_collide>
			<pose frame="">0.7046840830829593 -0.3015305180787642 0.05242403848715782 0.0 -0.0 0.0</pose>
			<inertial>
				<pose frame="">0.0 0.0 0.0 0 0 0</pose>
				<mass>0.030810597058291516</mass>
				<inertia>
					<ixx>0.0028878479321763884</ixx>
					<ixy>0.006547040722103612</ixy>
					<ixz>-0.0011377849324884202</ixz>
					<iyy>0.015386400595745685</iyy>
					<iyz>0.0004868656667721309</iyz>
					<izz>0.018102852748695396</izz>
				</inertia>
			</inertial>
			<collision name="hand_left_ring_link1_collision">
				<geometry>
					<mesh>
						<uri>model://roboy_icecream/meshes/CAD/hand_left_ring_link1.stl</uri>
						<scale>0.001 0.001 0.001</scale>
					</mesh>
				</geometry>
			</collision>
			<visual name="hand_left_ring_link1_visual">
				<geometry>
					<mesh>
						<uri>model://roboy_icecream/meshes/CAD/hand_left_ring_link1.stl</uri>
						<scale>0.001 0.001 0.001</scale>
					</mesh>
				</geometry>
			</visual>
		</link>
		<link name="hand_left_ring_link0">
			<self_collide>false</self_collide>
			<pose frame="">0.6840551034817947 -0.28619254692810164 0.07693059851654294 0.0 -0.0 0.0</pose>
			<inertial>
				<pose frame="">0.0 0.0 0.0 0 0 0</pose>
				<mass>0.055852824780270094</mass>
				<inertia>
					<ixx>0.004912713257115162</ixx>
					<ixy>0.010936457002691365</ixy>
					<ixz>-0.002935974703750103</ixz>
					<iyy>0.02647415594214936</iyy>
					<iyz>0.00122739936571454</iyz>
					<izz>0.030716042356195104</izz>
				</inertia>
			</inertial>
			<collision name="hand_left_ring_link0_collision">
				<geometry>
					<mesh>
						<uri>model://roboy_icecream/meshes/CAD/hand_left_ring_link0.stl</uri>
						<scale>0.001 0.001 0.001</scale>
					</mesh>
				</geometry>
			</collision>
			<visual name="hand_left_ring_link0_visual">
				<geometry>
					<mesh>
						<uri>model://roboy_icecream/meshes/CAD/hand_left_ring_link0.stl</uri>
						<scale>0.001 0.001 0.001</scale>
					</mesh>
				</geometry>
			</visual>
		</link>
		<link name="hand_left_ring_link2">
			<self_collide>false</self_collide>
			<pose frame="">0.7192932791552032 -0.3124483767472179 0.03496338434348094 0.0 -0.0 0.0</pose>
			<inertial>
				<pose frame="">0.0 0.0 0.0 0 0 0</pose>
				<mass>0.030336320395881453</mass>
				<inertia>
					<ixx>0.0030002724624192223</ixx>
					<ixy>0.006817998963166919</ixy>
					<ixz>-0.000762638873829703</ixz>
					<iyy>0.015733943217686466</iyy>
					<iyz>0.00033126659962878633</iyz>
					<izz>0.01865825048858876</izz>
				</inertia>
			</inertial>
			<collision name="hand_left_ring_link2_collision">
				<geometry>
					<mesh>
						<uri>model://roboy_icecream/meshes/CAD/hand_left_ring_link2.stl</uri>
						<scale>0.001 0.001 0.001</scale>
					</mesh>
				</geometry>
			</collision>
			<visual name="hand_left_ring_link2_visual">
				<geometry>
					<mesh>
						<uri>model://roboy_icecream/meshes/CAD/hand_left_ring_link2.stl</uri>
						<scale>0.001 0.001 0.001</scale>
					</mesh>
				</geometry>
			</visual>
		</link>
		<link name="hand_left_little_link1">
			<self_collide>false</self_collide>
			<pose frame="">0.678886505595801 -0.23584828760818466 0.050234561466954486 0.0 -0.0 0.0</pose>
			<inertial>
				<pose frame="">0.0 0.0 0.0 0 0 0</pose>
				<mass>0.030811374120953198</mass>
				<inertia>
					<ixx>0.00179348115877289</ixx>
					<ixy>0.004933570621796022</ixy>
					<ixz>-0.0010503199170717274</ixz>
					<iyy>0.014280187058384875</iyy>
					<iyz>0.0003649193333483215</iyz>
					<izz>0.01591596231946317</izz>
				</inertia>
			</inertial>
			<collision name="hand_left_little_link1_collision">
				<geometry>
					<mesh>
						<uri>model://roboy_icecream/meshes/CAD/hand_left_little_link1.stl</uri>
						<scale>0.001 0.001 0.001</scale>
					</mesh>
				</geometry>
			</collision>
			<visual name="hand_left_little_link1_visual">
				<geometry>
					<mesh>
						<uri>model://roboy_icecream/meshes/CAD/hand_left_little_link1.stl</uri>
						<scale>0.001 0.001 0.001</scale>
					</mesh>
				</geometry>
			</visual>
		</link>
		<link name="hand_left_little_link2">
			<self_collide>false</self_collide>
			<pose frame="">0.6931804165794234 -0.24375096137054328 0.030981303555461265 0.0 -0.0 0.0</pose>
			<inertial>
				<pose frame="">0.0 0.0 0.0 0 0 0</pose>
				<mass>0.030336908642256268</mass>
				<inertia>
					<ixx>0.0018332243932410027</ixx>
					<ixy>0.005125973131916176</ixy>
					<ixz>-0.000651208498818426</ixz>
					<iyy>0.014607431938702656</iyy>
					<iyz>0.00022899355944009834</iyz>
					<izz>0.016380511329908105</izz>
				</inertia>
			</inertial>
			<collision name="hand_left_little_link2_collision">
				<geometry>
					<mesh>
						<uri>model://roboy_icecream/meshes/CAD/hand_left_little_link2.stl</uri>
						<scale>0.001 0.001 0.001</scale>
					</mesh>
				</geometry>
			</collision>
			<visual name="hand_left_little_link2_visual">
				<geometry>
					<mesh>
						<uri>model://roboy_icecream/meshes/CAD/hand_left_little_link2.stl</uri>
						<scale>0.001 0.001 0.001</scale>
					</mesh>
				</geometry>
			</visual>
		</link>
		<link name="hand_left_little_link0">
			<self_collide>false</self_collide>
			<pose frame="">0.6645346260783664 -0.22755225617382555 0.0702645870440505 0.0 -0.0 0.0</pose>
			<inertial>
				<pose frame="">0.0 0.0 0.0 0 0 0</pose>
				<mass>0.0308113741209532</mass>
				<inertia>
					<ixx>0.001749396724272586</ixx>
					<ixy>0.004659415135832687</ixy>
					<ixz>-0.00143822541281211</ixz>
					<iyy>0.01376049108729013</iyy>
					<iyz>0.0004925132378942396</iyz>
					<izz>0.015203449187173522</izz>
				</inertia>
			</inertial>
			<collision name="hand_left_little_link0_collision">
				<geometry>
					<mesh>
						<uri>model://roboy_icecream/meshes/CAD/hand_left_little_link0.stl</uri>
						<scale>0.001 0.001 0.001</scale>
					</mesh>
				</geometry>
			</collision>
			<visual name="hand_left_little_link0_visual">
				<geometry>
					<mesh>
						<uri>model://roboy_icecream/meshes/CAD/hand_left_little_link0.stl</uri>
						<scale>0.001 0.001 0.001</scale>
					</mesh>
				</geometry>
			</visual>
		</link>
		<link name="hand_left_thumb_link2">
			<self_collide>false</self_collide>
			<pose frame="">0.6304882644220328 -0.3385812853857143 0.1824737897952272 0.0 -0.0 0.0</pose>
			<inertial>
				<pose frame="">0.0 0.0 0.0 0 0 0</pose>
				<mass>0.030335989064583388</mass>
				<inertia>
					<ixx>0.004489354729882424</ixx>
					<ixy>0.006475836840804122</ixy>
					<ixz>-0.0034902262588540085</ixz>
					<iyy>0.013070313974085463</iyy>
					<iyz>0.0018745190424383962</iyz>
					<izz>0.015538224678982204</izz>
				</inertia>
			</inertial>
			<collision name="hand_left_thumb_link2_collision">
				<geometry>
					<mesh>
						<uri>model://roboy_icecream/meshes/CAD/hand_left_thumb_link2.stl</uri>
						<scale>0.001 0.001 0.001</scale>
					</mesh>
				</geometry>
			</collision>
			<visual name="hand_left_thumb_link2_visual">
				<geometry>
					<mesh>
						<uri>model://roboy_icecream/meshes/CAD/hand_left_thumb_link2.stl</uri>
						<scale>0.001 0.001 0.001</scale>
					</mesh>
				</geometry>
			</visual>
		</link>
		<link name="hand_left_thumb_link0">
			<self_collide>false</self_collide>
			<pose frame="">0.620713433278994 -0.2809930285193407 0.15489885949022678 0.0 -0.0 0.0</pose>
			<inertial>
				<pose frame="">0.0 0.0 0.0 0 0 0</pose>
				<mass>0.11643461952857805</mass>
				<inertia>
					<ixx>0.012010971087731106</ixx>
					<ixy>0.020311272292729367</ixy>
					<ixz>-0.01119416942676441</ixz>
					<iyy>0.04766696219825403</iyy>
					<iyz>0.005072105048872104</iyz>
					<izz>0.05407479296997607</izz>
				</inertia>
			</inertial>
			<collision name="hand_left_thumb_link0_collision">
				<geometry>
					<mesh>
						<uri>model://roboy_icecream/meshes/CAD/hand_left_thumb_link0.stl</uri>
						<scale>0.001 0.001 0.001</scale>
					</mesh>
				</geometry>
			</collision>
			<visual name="hand_left_thumb_link0_visual">
				<geometry>
					<mesh>
						<uri>model://roboy_icecream/meshes/CAD/hand_left_thumb_link0.stl</uri>
						<scale>0.001 0.001 0.001</scale>
					</mesh>
				</geometry>
			</visual>
		</link>
		<link name="hand_left_thumb_link1">
			<self_collide>false</self_collide>
			<pose frame="">0.6293984798480997 -0.3179669192839179 0.16796199317794436 0.0 -0.0 0.0</pose>
			<inertial>
				<pose frame="">0.0 0.0 0.0 0 0 0</pose>
				<mass>0.030824527684383127</mass>
				<inertia>
					<ixx>0.003987762221169893</ixx>
					<ixy>0.006168319217634503</ixy>
					<ixz>-0.003258510059016605</ixz>
					<iyy>0.013080989170821395</iyy>
					<iyz>0.001646568112932092</iyz>
					<izz>0.015328002628701421</izz>
				</inertia>
			</inertial>
			<collision name="hand_left_thumb_link1_collision">
				<geometry>
					<mesh>
						<uri>model://roboy_icecream/meshes/CAD/hand_left_thumb_link1.stl</uri>
						<scale>0.001 0.001 0.001</scale>
					</mesh>
				</geometry>
			</collision>
			<visual name="hand_left_thumb_link1_visual">
				<geometry>
					<mesh>
						<uri>model://roboy_icecream/meshes/CAD/hand_left_thumb_link1.stl</uri>
						<scale>0.001 0.001 0.001</scale>
					</mesh>
				</geometry>
			</visual>
		</link>
		<link name="shoulder_right_link1">
			<self_collide>false</self_collide>
			<pose frame="">-0.2930642609023861 0.01109383220250954 0.5468414984574267 0.0 -0.0 0.0</pose>
			<inertial>
				<pose frame="">0.0 0.0 0.0 0 0 0</pose>
				<mass>0.0903636656787565</mass>
				<inertia>
					<ixx>0.027040168124669237</ixx>
					<ixy>0.000293790868091621</ixy>
					<ixz>0.014481653914279803</ixz>
					<iyy>0.034790080309606335</iyy>
					<iyz>-0.0005481973067788913</iyz>
					<izz>0.007779246454693213</izz>
				</inertia>
			</inertial>
			<collision name="shoulder_right_link1_collision">
				<geometry>
					<mesh>
						<uri>model://roboy_icecream/meshes/CAD/shoulder_right_link1.stl</uri>
						<scale>0.001 0.001 0.001</scale>
					</mesh>
				</geometry>
			</collision>
			<visual name="shoulder_right_link1_visual">
				<geometry>
					<mesh>
						<uri>model://roboy_icecream/meshes/CAD/shoulder_right_link1.stl</uri>
						<scale>0.001 0.001 0.001</scale>
					</mesh>
				</geometry>
			</visual>
		</link>
		<link name="shoulder_right_link2">
			<self_collide>false</self_collide>
			<pose frame="">-0.2930642607647908 0.011093832147498362 0.5468414985002678 0.0 -0.0 0.0</pose>
			<inertial>
				<pose frame="">0.0 0.0 0.0 0 0 0</pose>
				<mass>0.007113171718499355</mass>
				<inertia>
					<ixx>0.0021280697191938397</ixx>
					<ixy>2.3126384559716274e-05</ixy>
					<ixz>0.001139954762194572</ixz>
					<iyy>0.0027381208465940333</iyy>
					<iyz>-4.315253847256294e-05</iyz>
					<izz>0.0006119045398845659</izz>
				</inertia>
			</inertial>
			<collision name="shoulder_right_link2_collision">
				<geometry>
					<mesh>
						<uri>model://roboy_icecream/meshes/CAD/shoulder_right_link2.stl</uri>
						<scale>0.001 0.001 0.001</scale>
					</mesh>
				</geometry>
			</collision>
			<visual name="shoulder_right_link2_visual">
				<geometry>
					<mesh>
						<uri>model://roboy_icecream/meshes/CAD/shoulder_right_link2.stl</uri>
						<scale>0.001 0.001 0.001</scale>
					</mesh>
				</geometry>
			</visual>
		</link>
		<link name="hand_right_index_link1">
			<self_collide>false</self_collide>
			<pose frame="">-0.7037693692645931 -0.3283650341593377 0.07713046627894897 0.0 -0.0 0.0</pose>
			<inertial>
				<pose frame="">0.0 0.0 0.0 0 0 0</pose>
				<mass>0.030810558444194565</mass>
				<inertia>
					<ixx>0.0035072507344217152</ixx>
					<ixy>-0.0071204350465617966</ixy>
					<ixz>0.0016720515259752472</ixz>
					<iyy>0.015445256555300177</iyy>
					<iyz>0.0007801490441516711</iyz>
					<izz>0.018583976783639176</izz>
				</inertia>
			</inertial>
			<collision name="hand_right_index_link1_collision">
				<geometry>
					<mesh>
						<uri>model://roboy_icecream/meshes/CAD/hand_right_index_link1.stl</uri>
						<scale>0.001 0.001 0.001</scale>
					</mesh>
				</geometry>
			</collision>
			<visual name="hand_right_index_link1_visual">
				<geometry>
					<mesh>
						<uri>model://roboy_icecream/meshes/CAD/hand_right_index_link1.stl</uri>
						<scale>0.001 0.001 0.001</scale>
					</mesh>
				</geometry>
			</visual>
		</link>
		<link name="hand_right_index_link0">
			<self_collide>false</self_collide>
			<pose frame="">-0.6830622488186304 -0.3104491740515724 0.09975053866888989 0.0 -0.0 0.0</pose>
			<inertial>
				<pose frame="">0.0 0.0 0.0 0 0 0</pose>
				<mass>0.055849025991352434</mass>
				<inertia>
					<ixx>0.005945810791770005</ixx>
					<ixy>-0.01184552057290769</ixy>
					<ixz>0.0038022735904499026</ixz>
					<iyy>0.026621208219618615</iyy>
					<iyz>0.0017270154221905132</iyz>
					<izz>0.031446965489201936</izz>
				</inertia>
			</inertial>
			<collision name="hand_right_index_link0_collision">
				<geometry>
					<mesh>
						<uri>model://roboy_icecream/meshes/CAD/hand_right_index_link0.stl</uri>
						<scale>0.001 0.001 0.001</scale>
					</mesh>
				</geometry>
			</collision>
			<visual name="hand_right_index_link0_visual">
				<geometry>
					<mesh>
						<uri>model://roboy_icecream/meshes/CAD/hand_right_index_link0.stl</uri>
						<scale>0.001 0.001 0.001</scale>
					</mesh>
				</geometry>
			</visual>
		</link>
		<link name="hand_right_index_link2">
			<self_collide>false</self_collide>
			<pose frame="">-0.7184346914498597 -0.3411382463969471 0.06102754345800903 0.0 -0.0 0.0</pose>
			<inertial>
				<pose frame="">0.0 0.0 0.0 0 0 0</pose>
				<mass>0.030337239357465576</mass>
				<inertia>
					<ixx>0.003645119335322973</ixx>
					<ixy>-0.007435377980429817</ixy>
					<ixz>0.0013298343469472684</ixz>
					<iyy>0.015772821451874083</iyy>
					<iyz>0.0006314361372726552</iyz>
					<izz>0.019190245490028755</izz>
				</inertia>
			</inertial>
			<collision name="hand_right_index_link2_collision">
				<geometry>
					<mesh>
						<uri>model://roboy_icecream/meshes/CAD/hand_right_index_link2.stl</uri>
						<scale>0.001 0.001 0.001</scale>
					</mesh>
				</geometry>
			</collision>
			<visual name="hand_right_index_link2_visual">
				<geometry>
					<mesh>
						<uri>model://roboy_icecream/meshes/CAD/hand_right_index_link2.stl</uri>
						<scale>0.001 0.001 0.001</scale>
					</mesh>
				</geometry>
			</visual>
		</link>
		<link name="hand_right_middle_link1">
			<self_collide>false</self_collide>
			<pose frame="">-0.7063789070011799 -0.30413980357991177 0.053219004793249 0.0 -0.0 0.0</pose>
			<inertial>
				<pose frame="">0.0 0.0 0.0 0 0 0</pose>
				<mass>0.030811264606209133</mass>
				<inertia>
					<ixx>0.002939191131302322</ixx>
					<ixy>-0.006619718350449587</ixy>
					<ixz>0.001157849436377739</ixz>
					<iyy>0.015463006739638623</iyy>
					<iyz>0.0004985403906268279</iyz>
					<izz>0.018225623477612574</izz>
				</inertia>
			</inertial>
			<collision name="hand_right_middle_link1_collision">
				<geometry>
					<mesh>
						<uri>model://roboy_icecream/meshes/CAD/hand_right_middle_link1.stl</uri>
						<scale>0.001 0.001 0.001</scale>
					</mesh>
				</geometry>
			</collision>
			<visual name="hand_right_middle_link1_visual">
				<geometry>
					<mesh>
						<uri>model://roboy_icecream/meshes/CAD/hand_right_middle_link1.stl</uri>
						<scale>0.001 0.001 0.001</scale>
					</mesh>
				</geometry>
			</visual>
		</link>
		<link name="hand_right_middle_link0">
			<self_collide>false</self_collide>
			<pose frame="">-0.6857445062228748 -0.2887213708636444 0.077671107624789 0.0 -0.0 0.0</pose>
			<inertial>
				<pose frame="">0.0 0.0 0.0 0 0 0</pose>
				<mass>0.05585161472558298</mass>
				<inertia>
					<ixx>0.005000202753105266</ixx>
					<ixy>-0.011060081908975509</ixy>
					<ixz>0.0029715327739198026</ixz>
					<iyy>0.026609233849449226</iyy>
					<iyz>0.0012501800330037103</iyz>
					<izz>0.03092583573792408</izz>
				</inertia>
			</inertial>
			<collision name="hand_right_middle_link0_collision">
				<geometry>
					<mesh>
						<uri>model://roboy_icecream/meshes/CAD/hand_right_middle_link0.stl</uri>
						<scale>0.001 0.001 0.001</scale>
					</mesh>
				</geometry>
			</collision>
			<visual name="hand_right_middle_link0_visual">
				<geometry>
					<mesh>
						<uri>model://roboy_icecream/meshes/CAD/hand_right_middle_link0.stl</uri>
						<scale>0.001 0.001 0.001</scale>
					</mesh>
				</geometry>
			</visual>
		</link>
		<link name="hand_right_middle_link2">
			<self_collide>false</self_collide>
			<pose frame="">-0.7209932778212658 -0.3151385491756735 0.03581258868831539 0.0 -0.0 0.0</pose>
			<inertial>
				<pose frame="">0.0 0.0 0.0 0 0 0</pose>
				<mass>0.030337290984439002</mass>
				<inertia>
					<ixx>0.003053405593881536</ixx>
					<ixy>-0.00689316243196015</ixy>
					<ixz>0.0007830400926682598</ixz>
					<iyy>0.01581052518162795</iyy>
					<iyz>0.0003422487813389571</iyz>
					<izz>0.018784316433487946</izz>
				</inertia>
			</inertial>
			<collision name="hand_right_middle_link2_collision">
				<geometry>
					<mesh>
						<uri>model://roboy_icecream/meshes/CAD/hand_right_middle_link2.stl</uri>
						<scale>0.001 0.001 0.001</scale>
					</mesh>
				</geometry>
			</collision>
			<visual name="hand_right_middle_link2_visual">
				<geometry>
					<mesh>
						<uri>model://roboy_icecream/meshes/CAD/hand_right_middle_link2.stl</uri>
						<scale>0.001 0.001 0.001</scale>
					</mesh>
				</geometry>
			</visual>
		</link>
		<link name="hand_right_ring_link1">
			<self_collide>false</self_collide>
			<pose frame="">-0.700152470060429 -0.27404344603502184 0.041038039348278266 0.0 -0.0 0.0</pose>
			<inertial>
				<pose frame="">0.0 0.0 0.0 0 0 0</pose>
				<mass>0.030812212494644456</mass>
				<inertia>
					<ixx>0.00236774083964393</ixx>
					<ixy>-0.0059122608699693595</ixy>
					<ixz>0.0008848743263874944</ixz>
					<iyy>0.015158306207734604</iyy>
					<iyz>0.00034637516515007396</iyz>
					<izz>0.017420121126692802</izz>
				</inertia>
			</inertial>
			<collision name="hand_right_ring_link1_collision">
				<geometry>
					<mesh>
						<uri>model://roboy_icecream/meshes/CAD/hand_right_ring_link1.stl</uri>
						<scale>0.001 0.001 0.001</scale>
					</mesh>
				</geometry>
			</collision>
			<visual name="hand_right_ring_link1_visual">
				<geometry>
					<mesh>
						<uri>model://roboy_icecream/meshes/CAD/hand_right_ring_link1.stl</uri>
						<scale>0.001 0.001 0.001</scale>
					</mesh>
				</geometry>
			</visual>
		</link>
		<link name="hand_right_ring_link0">
			<self_collide>false</self_collide>
			<pose frame="">-0.679742436320942 -0.26124012597773416 0.06713232179974515 0.0 -0.0 0.0</pose>
			<inertial>
				<pose frame="">0.0 0.0 0.0 0 0 0</pose>
				<mass>0.05584221000563182</mass>
				<inertia>
					<ixx>0.004070225351954381</ixx>
					<ixy>-0.009917967651783929</ixy>
					<ixz>0.0025447965369207364</ixz>
					<iyy>0.026062353555057434</iyy>
					<iyz>0.0009773030682929283</iyz>
					<izz>0.029618491318602096</izz>
				</inertia>
			</inertial>
			<collision name="hand_right_ring_link0_collision">
				<geometry>
					<mesh>
						<uri>model://roboy_icecream/meshes/CAD/hand_right_ring_link0.stl</uri>
						<scale>0.001 0.001 0.001</scale>
					</mesh>
				</geometry>
			</collision>
			<visual name="hand_right_ring_link0_visual">
				<geometry>
					<mesh>
						<uri>model://roboy_icecream/meshes/CAD/hand_right_ring_link0.stl</uri>
						<scale>0.001 0.001 0.001</scale>
					</mesh>
				</geometry>
			</visual>
		</link>
		<link name="hand_right_ring_link2">
			<self_collide>false</self_collide>
			<pose frame="">-0.7146072264679332 -0.2831828604247662 0.022462127067744635 0.0 -0.0 0.0</pose>
			<inertial>
				<pose frame="">0.0 0.0 0.0 0 0 0</pose>
				<mass>0.030337283421022952</mass>
				<inertia>
					<ixx>0.002449767656350394</ixx>
					<ixy>-0.006139318759877515</ixy>
					<ixz>0.00048666827942469215</ixz>
					<iyy>0.015508823191480852</iyy>
					<iyz>0.0001928556041489041</iyz>
					<izz>0.017926109824250795</izz>
				</inertia>
			</inertial>
			<collision name="hand_right_ring_link2_collision">
				<geometry>
					<mesh>
						<uri>model://roboy_icecream/meshes/CAD/hand_right_ring_link2.stl</uri>
						<scale>0.001 0.001 0.001</scale>
					</mesh>
				</geometry>
			</collision>
			<visual name="hand_right_ring_link2_visual">
				<geometry>
					<mesh>
						<uri>model://roboy_icecream/meshes/CAD/hand_right_ring_link2.stl</uri>
						<scale>0.001 0.001 0.001</scale>
					</mesh>
				</geometry>
			</visual>
		</link>
		<link name="hand_right_little_link1">
			<self_collide>false</self_collide>
			<pose frame="">-0.680055216139201 -0.2394631894480969 0.05099931963157623 0.0 -0.0 0.0</pose>
			<inertial>
				<pose frame="">0.0 0.0 0.0 0 0 0</pose>
				<mass>0.03081334642928593</mass>
				<inertia>
					<ixx>0.0018489247838932678</ixx>
					<ixy>-0.005018129585007925</ixy>
					<ixz>0.001068221948277107</ixz>
					<iyy>0.01433242463455071</iyy>
					<iyz>0.00037618095773073775</iyz>
					<izz>0.016018862934095872</izz>
				</inertia>
			</inertial>
			<collision name="hand_right_little_link1_collision">
				<geometry>
					<mesh>
						<uri>model://roboy_icecream/meshes/CAD/hand_right_little_link1.stl</uri>
						<scale>0.001 0.001 0.001</scale>
					</mesh>
				</geometry>
			</collision>
			<visual name="hand_right_little_link1_visual">
				<geometry>
					<mesh>
						<uri>model://roboy_icecream/meshes/CAD/hand_right_little_link1.stl</uri>
						<scale>0.001 0.001 0.001</scale>
					</mesh>
				</geometry>
			</visual>
		</link>
		<link name="hand_right_little_link2">
			<self_collide>false</self_collide>
			<pose frame="">-0.6943624765061505 -0.24745207688774798 0.03178976312425073 0.0 -0.0 0.0</pose>
			<inertial>
				<pose frame="">0.0 0.0 0.0 0 0 0</pose>
				<mass>0.030337208280612742</mass>
				<inertia>
					<ixx>0.0018899272174508306</ixx>
					<ixy>-0.005212708443420999</ixy>
					<ixz>0.0006693537263261418</ixz>
					<iyy>0.014658815788712764</iyy>
					<iyz>0.00023854251180179675</iyz>
					<izz>0.016485518418885167</izz>
				</inertia>
			</inertial>
			<collision name="hand_right_little_link2_collision">
				<geometry>
					<mesh>
						<uri>model://roboy_icecream/meshes/CAD/hand_right_little_link2.stl</uri>
						<scale>0.001 0.001 0.001</scale>
					</mesh>
				</geometry>
			</collision>
			<visual name="hand_right_little_link2_visual">
				<geometry>
					<mesh>
						<uri>model://roboy_icecream/meshes/CAD/hand_right_little_link2.stl</uri>
						<scale>0.001 0.001 0.001</scale>
					</mesh>
				</geometry>
			</visual>
		</link>
		<link name="hand_right_little_link0">
			<self_collide>false</self_collide>
			<pose frame="">-0.6656906341061404 -0.23107917166829567 0.07098355180300933 0.0 -0.0 0.0</pose>
			<inertial>
				<pose frame="">0.0 0.0 0.0 0 0 0</pose>
				<mass>0.030813346429285904</mass>
				<inertia>
					<ixx>0.0018024797811134192</ixx>
					<ixy>-0.0047401639074196224</ixy>
					<ixz>0.0014555682729818352</ixz>
					<iyy>0.013811884220583995</iyy>
					<iyz>0.0005052999897348896</iyz>
					<izz>0.01530164803286701</izz>
				</inertia>
			</inertial>
			<collision name="hand_right_little_link0_collision">
				<geometry>
					<mesh>
						<uri>model://roboy_icecream/meshes/CAD/hand_right_little_link0.stl</uri>
						<scale>0.001 0.001 0.001</scale>
					</mesh>
				</geometry>
			</collision>
			<visual name="hand_right_little_link0_visual">
				<geometry>
					<mesh>
						<uri>model://roboy_icecream/meshes/CAD/hand_right_little_link0.stl</uri>
						<scale>0.001 0.001 0.001</scale>
					</mesh>
				</geometry>
			</visual>
		</link>
		<link name="hand_right_thumb_link2">
			<self_collide>false</self_collide>
			<pose frame="">-0.6319964120599696 -0.34092694271003043 0.18295523410249778 0.0 -0.0 0.0</pose>
			<inertial>
				<pose frame="">0.0 0.0 0.0 0 0 0</pose>
				<mass>0.03033682887568179</mass>
				<inertia>
					<ixx>0.004543229582451049</ixx>
					<ixy>-0.006536565989199835</ixy>
					<ixz>0.0035079481650778406</ixz>
					<iyy>0.013133948563062964</iyy>
					<iyz>0.001892560305091098</iyz>
					<izz>0.015644977580895513</izz>
				</inertia>
			</inertial>
			<collision name="hand_right_thumb_link2_collision">
				<geometry>
					<mesh>
						<uri>model://roboy_icecream/meshes/CAD/hand_right_thumb_link2.stl</uri>
						<scale>0.001 0.001 0.001</scale>
					</mesh>
				</geometry>
			</collision>
			<visual name="hand_right_thumb_link2_visual">
				<geometry>
					<mesh>
						<uri>model://roboy_icecream/meshes/CAD/hand_right_thumb_link2.stl</uri>
						<scale>0.001 0.001 0.001</scale>
					</mesh>
				</geometry>
			</visual>
		</link>
		<link name="hand_right_thumb_link0">
			<self_collide>false</self_collide>
			<pose frame="">-0.6224494756034741 -0.2832453158803033 0.1555028854328001 0.0 -0.0 0.0</pose>
			<inertial>
				<pose frame="">0.0 0.0 0.0 0 0 0</pose>
				<mass>0.1164302811950376</mass>
				<inertia>
					<ixx>0.012180292998475242</ixx>
					<ixy>-0.020530575408297363</ixy>
					<ixz>0.011268842893541058</ixz>
					<iyy>0.04793835906321091</iyy>
					<iyz>0.0051324796033435744</iyz>
					<izz>0.05447208777524261</izz>
				</inertia>
			</inertial>
			<collision name="hand_right_thumb_link0_collision">
				<geometry>
					<mesh>
						<uri>model://roboy_icecream/meshes/CAD/hand_right_thumb_link0.stl</uri>
						<scale>0.001 0.001 0.001</scale>
					</mesh>
				</geometry>
			</collision>
			<visual name="hand_right_thumb_link0_visual">
				<geometry>
					<mesh>
						<uri>model://roboy_icecream/meshes/CAD/hand_right_thumb_link0.stl</uri>
						<scale>0.001 0.001 0.001</scale>
					</mesh>
				</geometry>
			</visual>
		</link>
		<link name="hand_right_thumb_link1">
			<self_collide>false</self_collide>
			<pose frame="">-0.6311334804099267 -0.32020049685849045 0.16856918302155652 0.0 -0.0 0.0</pose>
			<inertial>
				<pose frame="">0.0 0.0 0.0 0 0 0</pose>
				<mass>0.030826015044524157</mass>
				<inertia>
					<ixx>0.004038458480931994</ixx>
					<ixy>-0.00622949056761934</ixy>
					<ixz>0.0032796814746576994</ixz>
					<iyy>0.013156211759920598</iyy>
					<iyz>0.0016643157095675765</iyz>
					<izz>0.015441124884069424</izz>
				</inertia>
			</inertial>
			<collision name="hand_right_thumb_link1_collision">
				<geometry>
					<mesh>
						<uri>model://roboy_icecream/meshes/CAD/hand_right_thumb_link1.stl</uri>
						<scale>0.001 0.001 0.001</scale>
					</mesh>
				</geometry>
			</collision>
			<visual name="hand_right_thumb_link1_visual">
				<geometry>
					<mesh>
						<uri>model://roboy_icecream/meshes/CAD/hand_right_thumb_link1.stl</uri>
						<scale>0.001 0.001 0.001</scale>
					</mesh>
				</geometry>
			</visual>
		</link>
		<link name="wrist_left_link1">
			<self_collide>false</self_collide>
			<pose frame="">0.5942108195309044 -0.2236565034089869 0.17010688138927252 0.0 -0.0 0.0</pose>
			<inertial>
				<pose frame="">0.0 0.0 0.0 0 0 0</pose>
				<mass>0.09036359201900472</mass>
				<inertia>
					<ixx>0.007142072740240583</ixx>
					<ixy>0.012009241334079995</ixy>
					<ixz>-0.009133893090562301</ixz>
					<iyy>0.03452804847042273</iyy>
					<iyz>0.003437928970663017</iyz>
					<izz>0.03643344436611846</izz>
				</inertia>
			</inertial>
			<collision name="wrist_left_link1_collision">
				<geometry>
					<mesh>
						<uri>model://roboy_icecream/meshes/CAD/wrist_left_link1.stl</uri>
						<scale>0.001 0.001 0.001</scale>
					</mesh>
				</geometry>
			</collision>
			<visual name="wrist_left_link1_visual">
				<geometry>
					<mesh>
						<uri>model://roboy_icecream/meshes/CAD/wrist_left_link1.stl</uri>
						<scale>0.001 0.001 0.001</scale>
					</mesh>
				</geometry>
			</visual>
		</link>
		<link name="wrist_left_link2">
			<self_collide>false</self_collide>
			<pose frame="">0.5942108146699845 -0.2236565036439179 0.1701068809585281 0.0 -0.0 0.0</pose>
			<inertial>
				<pose frame="">0.0 0.0 0.0 0 0 0</pose>
				<mass>0.007113170038864663</mass>
				<inertia>
					<ixx>0.0005617483559744007</ixx>
					<ixy>0.0009453339904655011</ixy>
					<ixz>-0.0007189945919846204</ixz>
					<iyy>0.0027174959746702906</iyy>
					<iyz>0.0002706241835602648</iyz>
					<izz>0.0028674834293350975</izz>
				</inertia>
			</inertial>
			<collision name="wrist_left_link2_collision">
				<geometry>
					<mesh>
						<uri>model://roboy_icecream/meshes/CAD/wrist_left_link2.stl</uri>
						<scale>0.001 0.001 0.001</scale>
					</mesh>
				</geometry>
			</collision>
			<visual name="wrist_left_link2_visual">
				<geometry>
					<mesh>
						<uri>model://roboy_icecream/meshes/CAD/wrist_left_link2.stl</uri>
						<scale>0.001 0.001 0.001</scale>
					</mesh>
				</geometry>
			</visual>
		</link>
		<link name="wrist_right_link1">
			<self_collide>false</self_collide>
			<pose frame="">-0.5930631014104508 -0.22373453929325607 0.17416876963064573 0.0 -0.0 0.0</pose>
			<inertial>
				<pose frame="">0.0 0.0 0.0 0 0 0</pose>
				<mass>0.09036366567875652</mass>
				<inertia>
					<ixx>0.0072715987658836185</ixx>
					<ixy>-0.011990237304993493</ixy>
					<ixz>0.00933394050640124</ixz>
					<iyy>0.03453130742684939</iyy>
					<iyz>0.0035212524165199165</iyz>
					<izz>0.03631349431910831</izz>
				</inertia>
			</inertial>
			<collision name="wrist_right_link1_collision">
				<geometry>
					<mesh>
						<uri>model://roboy_icecream/meshes/CAD/wrist_right_link1.stl</uri>
						<scale>0.001 0.001 0.001</scale>
					</mesh>
				</geometry>
			</collision>
			<visual name="wrist_right_link1_visual">
				<geometry>
					<mesh>
						<uri>model://roboy_icecream/meshes/CAD/wrist_right_link1.stl</uri>
						<scale>0.001 0.001 0.001</scale>
					</mesh>
				</geometry>
			</visual>
		</link>
		<link name="wrist_right_link2">
			<self_collide>false</self_collide>
			<pose frame="">-0.5930631010671759 -0.2237345393051499 0.1741687696304079 0.0 -0.0 0.0</pose>
			<inertial>
				<pose frame="">0.0 0.0 0.0 0 0 0</pose>
				<mass>0.0071131715008991465</mass>
				<inertia>
					<ixx>0.0005719439353585403</ixx>
					<ixy>-0.0009438374771676792</ixy>
					<ixz>0.000734741326217683</ixz>
					<iyy>0.002717750892693173</iyy>
					<iyz>0.0002771830043615346</iyz>
					<izz>0.0028580395908096223</izz>
				</inertia>
			</inertial>
			<collision name="wrist_right_link2_collision">
				<geometry>
					<mesh>
						<uri>model://roboy_icecream/meshes/CAD/wrist_right_link2.stl</uri>
						<scale>0.001 0.001 0.001</scale>
					</mesh>
				</geometry>
			</collision>
			<visual name="wrist_right_link2_visual">
				<geometry>
					<mesh>
						<uri>model://roboy_icecream/meshes/CAD/wrist_right_link2.stl</uri>
						<scale>0.001 0.001 0.001</scale>
					</mesh>
				</geometry>
			</visual>
		</link>
		<link name="zed_camera_left_lense">
			<self_collide>false</self_collide>
			<pose frame="">0.060224029002958875 -0.06914536611449576 0.9247742812708074 0.0 -0.0 0.0</pose>
			<inertial>
				<pose frame="">0.0 0.0 0.0 0 0 0</pose>
				<mass>0.005755421856391889</mass>
				<inertia>
					<ixx>0.004949985508986997</ixx>
					<ixy>2.3967379469334992e-05</ixy>
					<ixz>-0.00032054048486266214</ixz>
					<iyy>0.004943160949602587</iyy>
					<iyz>0.00036806516895399434</iyz>
					<izz>4.8783846074335874e-05</izz>
				</inertia>
			</inertial>
			<collision name="zed_camera_left_lense_collision">
				<geometry>
					<mesh>
						<uri>model://roboy_icecream/meshes/CAD/zed_camera_left_lense.stl</uri>
						<scale>0.001 0.001 0.001</scale>
					</mesh>
				</geometry>
			</collision>
			<visual name="zed_camera_left_lense_visual">
				<geometry>
					<mesh>
						<uri>model://roboy_icecream/meshes/CAD/zed_camera_left_lense.stl</uri>
						<scale>0.001 0.001 0.001</scale>
					</mesh>
				</geometry>
			</visual>
		</link>
		<link name="zed_camera_right_lense">
			<self_collide>false</self_collide>
			<pose frame="">-0.05977745584801775 -0.06952236314727905 0.924774281233249 0.0 -0.0 0.0</pose>
			<inertial>
				<pose frame="">0.0 0.0 0.0 0 0 0</pose>
				<mass>0.005755421855125979</mass>
				<inertia>
					<ixx>0.004950286385593239</ixx>
					<ixy>-2.3918213389687756e-05</ixy>
					<ixz>0.00031816335310091417</ixz>
					<iyy>0.004942852518457872</iyy>
					<iyz>0.00037007172279470996</iyz>
					<izz>4.877629449989437e-05</izz>
				</inertia>
			</inertial>
			<collision name="zed_camera_right_lense_collision">
				<geometry>
					<mesh>
						<uri>model://roboy_icecream/meshes/CAD/zed_camera_right_lense.stl</uri>
						<scale>0.001 0.001 0.001</scale>
					</mesh>
				</geometry>
			</collision>
			<visual name="zed_camera_right_lense_visual">
				<geometry>
					<mesh>
						<uri>model://roboy_icecream/meshes/CAD/zed_camera_right_lense.stl</uri>
						<scale>0.001 0.001 0.001</scale>
					</mesh>
				</geometry>
			</visual>
		</link>
		<link name="zed_camera">
			<self_collide>false</self_collide>
			<pose frame="">0.0042444847902519045 -0.057938621286605034 0.9221942136470952 0.0 -0.0 0.0</pose>
			<inertial>
				<pose frame="">0.0 0.0 0.0 0 0 0</pose>
				<mass>0.009633907989226696</mass>
				<inertia>
					<ixx>0.008225718793064217</ixx>
					<ixy>2.436533895216616e-06</ixy>
					<ixz>-3.772847951396886e-05</ixz>
					<iyy>0.008208224332339191</iyy>
					<iyz>0.0005146961428966748</iyz>
					<izz>4.725323656366557e-05</izz>
				</inertia>
			</inertial>
			<collision name="zed_camera_collision">
				<geometry>
					<mesh>
						<uri>model://roboy_icecream/meshes/CAD/zed_camera.stl</uri>
						<scale>0.001 0.001 0.001</scale>
					</mesh>
				</geometry>
			</collision>
			<visual name="zed_camera_visual">
				<geometry>
					<mesh>
						<uri>model://roboy_icecream/meshes/CAD/zed_camera.stl</uri>
						<scale>0.001 0.001 0.001</scale>
					</mesh>
				</geometry>
			</visual>
		</link>
		<link name="neck_link1">
			<self_collide>false</self_collide>
			<pose frame="">-1.506123290725299e-10 0.0015217809344427139 0.7106779292283452 0.0 -0.0 0.0</pose>
			<inertial>
				<pose frame="">0.0 0.0 0.0 0 0 0</pose>
				<mass>0.017038665636260365</mass>
				<inertia>
					<ixx>0.008606751840759286</ixx>
					<ixy>3.905246557991266e-15</ixy>
					<ixz>1.8237653762187555e-12</ixz>
					<iyy>0.008606712382324128</iyy>
					<iyz>-1.8427250830609723e-05</iyz>
					<izz>1.1502292854573858e-06</izz>
				</inertia>
			</inertial>
			<collision name="neck_link1_collision">
				<geometry>
					<mesh>
						<uri>model://roboy_icecream/meshes/CAD/neck_link1.stl</uri>
						<scale>0.001 0.001 0.001</scale>
					</mesh>
				</geometry>
			</collision>
			<visual name="neck_link1_visual">
				<geometry>
					<mesh>
						<uri>model://roboy_icecream/meshes/CAD/neck_link1.stl</uri>
						<scale>0.001 0.001 0.001</scale>
					</mesh>
				</geometry>
			</visual>
		</link>
		<link name="neck_link2">
			<self_collide>false</self_collide>
			<pose frame="">-1.2765957595970417e-10 0.0015217809573941916 0.7106779292283448 0.0 -0.0 0.0</pose>
			<inertial>
				<pose frame="">0.0 0.0 0.0 0 0 0</pose>
				<mass>0.011421521917888835</mass>
				<inertia>
					<ixx>0.005769117704166386</ixx>
					<ixy>2.2188573474781793e-15</ixy>
					<ixz>1.0362156174781311e-12</ixz>
					<iyy>0.005769091254008538</iyy>
					<iyz>-1.2352331861868672e-05</iyz>
					<izz>5.282195127138846e-07</izz>
				</inertia>
			</inertial>
			<collision name="neck_link2_collision">
				<geometry>
					<mesh>
						<uri>model://roboy_icecream/meshes/CAD/neck_link2.stl</uri>
						<scale>0.001 0.001 0.001</scale>
					</mesh>
				</geometry>
			</collision>
			<visual name="neck_link2_visual">
				<geometry>
					<mesh>
						<uri>model://roboy_icecream/meshes/CAD/neck_link2.stl</uri>
						<scale>0.001 0.001 0.001</scale>
					</mesh>
				</geometry>
			</visual>
		</link>
		<joint name="elbow_right" type="revolute">
			<parent>arm_right_lower</parent>
			<child>arm_right_upper</child>
			<pose frame="">-0.06347250519359897 -0.059734055806697856 -0.07348713064301259 0 0 0</pose>
			<axis>
				<xyz>0.048932268751824236 0.826658752653104 -0.5605719755185908</xyz>
				<limit>
					<lower>0.0</lower>
					<upper>0.0</upper>
				</limit>
				<use_parent_model_frame>0</use_parent_model_frame>
			</axis>
		</joint>
		<joint name="zed_camera_mount" type="fixed">
			<parent>head</parent>
			<child>zed_camera</child>
			<pose frame="">0.017437654685091123 0.001405588958414743 0.008052233827783938 0 0 0</pose>
		</joint>
		<joint name="zed_camera_right" type="fixed">
			<parent>zed_camera</parent>
			<child>zed_camera_right_lense</child>
			<pose frame="">-3.477806617303791e-05 0.011070006217811663 -0.002353014092106349 0 0 0</pose>
		</joint>
		<joint name="zed_camera_left" type="fixed">
			<parent>zed_camera</parent>
			<child>zed_camera_left_lense</child>
			<pose frame="">-5.4665509118771995e-05 0.011069943702269302 -0.002353014260490625 0 0 0</pose>
		</joint>
		<joint name="wrist_right_axis0" type="revolute">
			<parent>arm_right_lower</parent>
			<child>wrist_right_link1</child>
			<pose frame="">1.3765976802915247e-10 -7.151108150083019e-11 -2.516387098694395e-13 0 0 0</pose>
			<axis>
				<xyz>0.04893226875182534 0.8266587526531013 -0.5605719755185936</xyz>
				<limit>
					<lower>-3.141592653589793</lower>
					<upper>3.141592653589793</upper>
				</limit>
				<use_parent_model_frame>0</use_parent_model_frame>
			</axis>
		</joint>
		<joint name="wrist_right_axis1" type="revolute">
			<parent>wrist_right_link1</parent>
			<child>wrist_right_link2</child>
			<pose frame="">-2.056162884400692e-10 -5.963745053350067e-11 -3.552713678800501e-17 0 0 0</pose>
			<axis>
				<xyz>0.823951413592291 -0.350636056294613 -0.4451498894366088</xyz>
				<limit>
					<lower>-3.141592653589793</lower>
					<upper>3.141592653589793</upper>
				</limit>
				<use_parent_model_frame>0</use_parent_model_frame>
			</axis>
		</joint>
		<joint name="neck_axis0" type="revolute">
			<parent>torso</parent>
			<child>neck_link1</child>
			<pose frame="">1.5061504134737904e-10 1.506148417096398e-10 0.0 0 0 0</pose>
			<axis>
				<xyz>0.12498691257369461 -0.9921583904222635 6.724690979212185e-15</xyz>
				<limit>
					<lower>-0.5235987755982988</lower>
					<upper>0.5235987755982988</upper>
				</limit>
				<use_parent_model_frame>0</use_parent_model_frame>
			</axis>
		</joint>
		<joint name="neck_axis2" type="revolute">
			<parent>neck_link2</parent>
			<child>head</child>
			<pose frame="">-0.0005102180295654335 -0.04492411714425427 -0.14549973319053336 0 0 0</pose>
			<axis>
				<xyz>-2.4972812708040394e-14 3.631896132047499e-15 1.0</xyz>
				<limit>
					<lower>-0.5235987755982988</lower>
					<upper>0.5235987755982988</upper>
				</limit>
				<use_parent_model_frame>0</use_parent_model_frame>
			</axis>
		</joint>
		<joint name="neck_axis1" type="revolute">
			<parent>neck_link1</parent>
			<child>neck_link2</child>
			<pose frame="">1.276622840242204e-10 1.2766342372128037e-10 2.842170943040401e-16 0 0 0</pose>
			<axis>
				<xyz>-0.9921583904222635 -0.12498691257369461 -2.432304617639304e-14</xyz>
				<limit>
					<lower>-0.5235987755982988</lower>
					<upper>0.5235987755982988</upper>
				</limit>
				<use_parent_model_frame>0</use_parent_model_frame>
			</axis>
		</joint>
		<joint name="hand_left_little_joint1" type="revolute">
			<parent>hand_left_little_link0</parent>
			<child>hand_left_little_link1</child>
			<pose frame="">-0.006783253127031656 0.00915137835256651 0.00909276138854513 0 0 0</pose>
			<axis>
				<xyz>0.12702537302227537 -0.8798641087300457 0.45793417079011445</xyz>
				<limit>
					<lower>0.0</lower>
					<upper>0.0</upper>
				</limit>
				<use_parent_model_frame>0</use_parent_model_frame>
			</axis>
		</joint>
		<joint name="hand_left_little_joint2" type="revolute">
			<parent>hand_left_little_link1</parent>
			<child>hand_left_little_link2</child>
			<pose frame="">-0.00672528467667604 0.008758020728807842 0.0083159938394166 0 0 0</pose>
			<axis>
				<xyz>0.12702537302227657 -0.8798641087300475 0.4579341707901138</xyz>
				<limit>
					<lower>0.0</lower>
					<upper>0.0</upper>
				</limit>
				<use_parent_model_frame>0</use_parent_model_frame>
			</axis>
		</joint>
		<joint name="hand_left_thumb_joint1" type="revolute">
			<parent>hand_left_thumb_link0</parent>
			<child>hand_left_thumb_link1</child>
			<pose frame="">-0.00554731969662079 0.010385447221051898 -0.008626954865342177 0 0 0</pose>
			<axis>
				<xyz>0.8239514135922791 0.35063605629459854 0.44514988943663386</xyz>
				<limit>
					<lower>0.0</lower>
					<upper>0.0</upper>
				</limit>
				<use_parent_model_frame>0</use_parent_model_frame>
			</axis>
		</joint>
		<joint name="hand_left_thumb_joint2" type="revolute">
			<parent>hand_left_thumb_link1</parent>
			<child>hand_left_thumb_link2</child>
			<pose frame="">-0.005406062853686535 0.009489153951051392 -0.008586137613613936 0 0 0</pose>
			<axis>
				<xyz>-0.8239514135922789 -0.350636056294598 -0.4451498894366351</xyz>
				<limit>
					<lower>0.0</lower>
					<upper>0.0</upper>
				</limit>
				<use_parent_model_frame>0</use_parent_model_frame>
			</axis>
		</joint>
		<joint name="hand_right_thumb_joint1" type="revolute">
			<parent>hand_right_thumb_link0</parent>
			<child>hand_right_thumb_link1</child>
			<pose frame="">-0.002302618910469079 0.013706585742585986 -0.004390237862403588 0 0 0</pose>
			<axis>
				<xyz>0.8239514135922897 -0.3506360562946327 -0.44514988943659817</xyz>
				<limit>
					<lower>0.0</lower>
					<upper>0.0</upper>
				</limit>
				<use_parent_model_frame>0</use_parent_model_frame>
			</axis>
		</joint>
		<joint name="hand_right_thumb_joint2" type="revolute">
			<parent>hand_right_thumb_link1</parent>
			<child>hand_right_thumb_link2</child>
			<pose frame="">-0.0027531238186532647 0.012957435827960708 -0.004179160085389242 0 0 0</pose>
			<axis>
				<xyz>-0.82395141359229 0.3506360562946326 0.4451498894365984</xyz>
				<limit>
					<lower>0.0</lower>
					<upper>0.0</upper>
				</limit>
				<use_parent_model_frame>0</use_parent_model_frame>
			</axis>
		</joint>
		<joint name="shoulder_left_axis0" type="revolute">
			<parent>torso</parent>
			<child>shoulder_left_link1</child>
			<pose frame="">-4.860963365160842e-09 -1.5044763213012403e-10 5.4201620969251966e-12 0 0 0</pose>
			<axis>
				<xyz>0.8239514135922348 0.35063605629465305 0.445149889436685</xyz>
				<limit>
					<lower>-3.141592653589793</lower>
					<upper>3.141592653589793</upper>
				</limit>
				<use_parent_model_frame>0</use_parent_model_frame>
			</axis>
		</joint>
		<joint name="shoulder_left_axis1" type="revolute">
			<parent>shoulder_left_link1</parent>
			<child>shoulder_left_link2</child>
			<pose frame="">-6.320277634586091e-14 8.447477384265767e-11 4.3615351330572595e-10 0 0 0</pose>
			<axis>
				<xyz>0.048932268751815826 -0.8266587526531001 0.5605719755185947</xyz>
				<limit>
					<lower>-3.141592653589793</lower>
					<upper>3.141592653589793</upper>
				</limit>
				<use_parent_model_frame>0</use_parent_model_frame>
			</axis>
		</joint>
		<joint name="shoulder_left_axis2" type="revolute">
			<parent>shoulder_left_link2</parent>
			<child>arm_left_upper</child>
			<pose frame="">-0.1050535468777813 0.08269219302874609 0.12861941407459263 0 0 0</pose>
			<axis>
				<xyz>0.564543799110472 -0.4401018776240088 -0.6982840655476376</xyz>
				<limit>
					<lower>-3.141592653589793</lower>
					<upper>3.141592653589793</upper>
				</limit>
				<use_parent_model_frame>0</use_parent_model_frame>
			</axis>
		</joint>
		<joint name="hand_right_little_joint1" type="revolute">
			<parent>hand_right_little_link0</parent>
			<child>hand_right_little_link1</child>
			<pose frame="">0.005576947707723861 0.0007926802518630893 0.013442246792434621 0 0 0</pose>
			<axis>
				<xyz>0.12702537442599368 0.8798641095453656 -0.4579341688342087</xyz>
				<limit>
					<lower>0.0</lower>
					<upper>0.0</upper>
				</limit>
				<use_parent_model_frame>0</use_parent_model_frame>
			</axis>
		</joint>
		<joint name="hand_right_little_joint2" type="revolute">
			<parent>hand_right_little_link1</parent>
			<child>hand_right_little_link2</child>
			<pose frame="">0.005519626111717599 0.00039754995263020733 0.012667571225857243 0 0 0</pose>
			<axis>
				<xyz>0.12702537442599324 0.8798641095453656 -0.4579341688342094</xyz>
				<limit>
					<lower>0.0</lower>
					<upper>0.0</upper>
				</limit>
				<use_parent_model_frame>0</use_parent_model_frame>
			</axis>
		</joint>
		<joint name="shoulder_right_axis0" type="revolute">
			<parent>torso</parent>
			<child>shoulder_right_link1</child>
			<pose frame="">1.376389491269947e-10 -7.152252567976802e-11 -2.2659207843389595e-13 0 0 0</pose>
			<axis>
				<xyz>-0.8239514135922378 0.3506360562946562 0.44514988943668027</xyz>
				<limit>
					<lower>-3.141592653589793</lower>
					<upper>3.141592653589793</upper>
				</limit>
				<use_parent_model_frame>0</use_parent_model_frame>
			</axis>
		</joint>
		<joint name="shoulder_right_axis1" type="revolute">
			<parent>shoulder_right_link1</parent>
			<child>shoulder_right_link2</child>
			<pose frame="">6.320277634586091e-14 -1.6520109724638134e-11 -4.3078784983663355e-11 0 0 0</pose>
			<axis>
				<xyz>0.048932268751817644 0.8266587526530976 -0.5605719755186003</xyz>
				<limit>
					<lower>-3.141592653589793</lower>
					<upper>3.141592653589793</upper>
				</limit>
				<use_parent_model_frame>0</use_parent_model_frame>
			</axis>
		</joint>
		<joint name="shoulder_right_axis2" type="revolute">
			<parent>shoulder_right_link2</parent>
			<child>arm_right_upper</child>
			<pose frame="">0.10547695280924842 0.08081716572918377 0.13087969115599365 0 0 0</pose>
			<axis>
				<xyz>-0.5645437991104694 -0.44010187762401454 -0.6982840655476372</xyz>
				<limit>
					<lower>-3.141592653589793</lower>
					<upper>3.141592653589793</upper>
				</limit>
				<use_parent_model_frame>0</use_parent_model_frame>
			</axis>
		</joint>
		<joint name="hand_left_ring_joint1" type="revolute">
			<parent>hand_left_ring_link0</parent>
			<child>hand_left_ring_link1</child>
			<pose frame="">-0.006580487917874223 0.010530963644602665 0.007630699202666493 0 0 0</pose>
			<axis>
				<xyz>0.048932270186756735 -0.8266587537717577 0.5605719737436896</xyz>
				<limit>
					<lower>0.0</lower>
					<upper>0.0</upper>
				</limit>
				<use_parent_model_frame>0</use_parent_model_frame>
			</axis>
		</joint>
		<joint name="hand_left_ring_joint2" type="revolute">
			<parent>hand_left_ring_link1</parent>
			<child>hand_left_ring_link2</child>
			<pose frame="">-0.00651399095552705 0.010047506859281548 0.006907939478808287 0 0 0</pose>
			<axis>
				<xyz>0.04893227018675697 -0.8266587537717556 0.5605719737436894</xyz>
				<limit>
					<lower>0.0</lower>
					<upper>0.0</upper>
				</limit>
				<use_parent_model_frame>0</use_parent_model_frame>
			</axis>
		</joint>
		<joint name="hand_left_middle_joint1" type="revolute">
			<parent>hand_left_middle_link0</parent>
			<child>hand_left_middle_link1</child>
			<pose frame="">-0.006725562081695244 0.009689852027568833 0.008561881375150557 0 0 0</pose>
			<axis>
				<xyz>0.09794930082119462 -0.8618704725531147 0.49757936352878035</xyz>
				<limit>
					<lower>0.0</lower>
					<upper>0.0</upper>
				</limit>
				<use_parent_model_frame>0</use_parent_model_frame>
			</axis>
		</joint>
		<joint name="hand_left_middle_joint2" type="revolute">
			<parent>hand_left_middle_link1</parent>
			<child>hand_left_middle_link2</child>
			<pose frame="">-0.0066635501534133825 0.009261958069227276 0.007804274436405163 0 0 0</pose>
			<axis>
				<xyz>0.09794930082119535 -0.8618704725531143 0.49757936352878024</xyz>
				<limit>
					<lower>0.0</lower>
					<upper>0.0</upper>
				</limit>
				<use_parent_model_frame>0</use_parent_model_frame>
			</axis>
		</joint>
		<joint name="hand_right_index_joint0" type="revolute">
			<parent>arm_right_palm</parent>
			<child>hand_right_index_link0</child>
			<pose frame="">0.01117192927158925 0.008775224553004186 0.019107804119841417 0 0 0</pose>
			<axis>
				<xyz>-0.0004571659885742185 0.7851556617927034 -0.6192982946481612</xyz>
				<limit>
					<lower>0.0</lower>
					<upper>0.0</upper>
				</limit>
				<use_parent_model_frame>0</use_parent_model_frame>
			</axis>
		</joint>
		<joint name="hand_right_middle_joint0" type="revolute">
			<parent>arm_right_palm</parent>
			<child>hand_right_middle_link0</child>
			<pose frame="">0.010878608598128068 0.006939934514382849 0.02001062848035576 0 0 0</pose>
			<axis>
				<xyz>0.04893227162172448 0.8266587548903904 -0.5605719719688159</xyz>
				<limit>
					<lower>0.0</lower>
					<upper>0.0</upper>
				</limit>
				<use_parent_model_frame>0</use_parent_model_frame>
			</axis>
		</joint>
		<joint name="hand_right_ring_joint0" type="revolute">
			<parent>arm_right_palm</parent>
			<child>hand_right_ring_link0</child>
			<pose frame="">0.010486676469139127 0.005056535423802373 0.02077058058187099 0 0 0</pose>
			<axis>
				<xyz>0.09794930223986442 0.8618704734843621 -0.4975793616364782</xyz>
				<limit>
					<lower>0.0</lower>
					<upper>0.0</upper>
				</limit>
				<use_parent_model_frame>0</use_parent_model_frame>
			</axis>
		</joint>
		<joint name="hand_right_little_joint0" type="revolute">
			<parent>arm_right_palm</parent>
			<child>hand_right_little_link0</child>
			<pose frame="">0.005551542562736813 0.0006167073890361507 0.013533833528704502 0 0 0</pose>
			<axis>
				<xyz>0.1270253744259705 0.8798641095453655 -0.4579341688342145</xyz>
				<limit>
					<lower>0.0</lower>
					<upper>0.0</upper>
				</limit>
				<use_parent_model_frame>0</use_parent_model_frame>
			</axis>
		</joint>
		<joint name="hand_right_thumb_joint0" type="revolute">
			<parent>arm_right_palm</parent>
			<child>hand_right_thumb_link0</child>
			<pose frame="">0.005031812720187006 0.019005814710372278 -0.005740446872674046 0 0 0</pose>
			<axis>
				<xyz>0.5645437991104548 0.44010187762403513 0.698284065547635</xyz>
				<limit>
					<lower>0.0</lower>
					<upper>0.0</upper>
				</limit>
				<use_parent_model_frame>0</use_parent_model_frame>
			</axis>
		</joint>
		<joint name="hand_right_index_joint1" type="revolute">
			<parent>hand_right_index_link0</parent>
			<child>hand_right_index_link1</child>
			<pose frame="">0.006379269094215232 0.0038374734385426025 0.012530339931035953 0 0 0</pose>
			<axis>
				<xyz>-0.00045716598854308706 0.7851556617927065 -0.6192982946481643</xyz>
				<limit>
					<lower>0.0</lower>
					<upper>0.0</upper>
				</limit>
				<use_parent_model_frame>0</use_parent_model_frame>
			</axis>
		</joint>
		<joint name="hand_right_index_joint2" type="revolute">
			<parent>hand_right_index_link1</parent>
			<child>hand_right_index_link2</child>
			<pose frame="">0.006311447176464071 0.003299072362865303 0.011848212384543403 0 0 0</pose>
			<axis>
				<xyz>-0.00045716598854293245 0.7851556617927031 -0.6192982946481616</xyz>
				<limit>
					<lower>0.0</lower>
					<upper>0.0</upper>
				</limit>
				<use_parent_model_frame>0</use_parent_model_frame>
			</axis>
		</joint>
		<joint name="hand_right_ring_joint1" type="revolute">
			<parent>hand_right_ring_link0</parent>
			<child>hand_right_ring_link1</child>
			<pose frame="">0.005795516107246641 0.0015020766721620404 0.013288448288379655 0 0 0</pose>
			<axis>
				<xyz>0.09794930223988946 0.8618704734843619 -0.49757936163647376</xyz>
				<limit>
					<lower>0.0</lower>
					<upper>0.0</upper>
				</limit>
				<use_parent_model_frame>0</use_parent_model_frame>
			</axis>
		</joint>
		<joint name="hand_right_ring_joint2" type="revolute">
			<parent>hand_right_ring_link1</parent>
			<child>hand_right_ring_link2</child>
			<pose frame="">0.005733973962649515 0.001072541007593877 0.012532656784602239 0 0 0</pose>
			<axis>
				<xyz>0.0979493022398894 0.861870473484362 -0.4975793616364738</xyz>
				<limit>
					<lower>0.0</lower>
					<upper>0.0</upper>
				</limit>
				<use_parent_model_frame>0</use_parent_model_frame>
			</axis>
		</joint>
		<joint name="elbow_left" type="revolute">
			<parent>arm_left_upper</parent>
			<child>arm_left_lower</child>
			<pose frame="">-0.07662424485700015 0.05077723036548429 0.10119287135500188 0 0 0</pose>
			<axis>
				<xyz>0.04893226875181594 -0.8266587526531017 0.5605719755185943</xyz>
				<limit>
					<lower>0.0</lower>
					<upper>0.0</upper>
				</limit>
				<use_parent_model_frame>0</use_parent_model_frame>
			</axis>
		</joint>
		<joint name="hand_right_middle_joint1" type="revolute">
			<parent>hand_right_middle_link0</parent>
			<child>hand_right_middle_link1</child>
			<pose frame="">0.0061158775116469145 0.002677782061949081 0.012955862847028383 0 0 0</pose>
			<axis>
				<xyz>0.04893227162175261 0.8266587548903902 -0.5605719719688139</xyz>
				<limit>
					<lower>0.0</lower>
					<upper>0.0</upper>
				</limit>
				<use_parent_model_frame>0</use_parent_model_frame>
			</axis>
		</joint>
		<joint name="hand_right_middle_joint2" type="revolute">
			<parent>hand_right_middle_link1</parent>
			<child>hand_right_middle_link2</child>
			<pose frame="">0.0060496625105142246 0.0021925461970707617 0.012234922008449525 0 0 0</pose>
			<axis>
				<xyz>0.04893227162175252 0.8266587548903902 -0.5605719719688139</xyz>
				<limit>
					<lower>0.0</lower>
					<upper>0.0</upper>
				</limit>
				<use_parent_model_frame>0</use_parent_model_frame>
			</axis>
		</joint>
		<joint name="wrist_left_axis0" type="revolute">
			<parent>arm_left_lower</parent>
			<child>wrist_left_link1</child>
			<pose frame="">-4.860946916096509e-09 -1.5044435031086323e-10 5.400764280238946e-12 0 0 0</pose>
			<axis>
				<xyz>0.8239514135922501 0.35063605629463523 0.44514988943665923</xyz>
				<limit>
					<lower>-3.141592653589793</lower>
					<upper>3.141592653589793</upper>
				</limit>
				<use_parent_model_frame>0</use_parent_model_frame>
			</axis>
		</joint>
		<joint name="wrist_left_axis1" type="revolute">
			<parent>wrist_left_link1</parent>
			<child>wrist_left_link2</child>
			<pose frame="">-6.338041202980094e-14 8.447464949767891e-11 4.3615344225145236e-10 0 0 0</pose>
			<axis>
				<xyz>0.04893226875178856 -0.8266587526530951 0.5605719755186038</xyz>
				<limit>
					<lower>-3.141592653589793</lower>
					<upper>3.141592653589793</upper>
				</limit>
				<use_parent_model_frame>0</use_parent_model_frame>
			</axis>
		</joint>
		<joint name="hand_left_middle_joint0" type="revolute">
			<parent>arm_left_palm</parent>
			<child>hand_left_middle_link0</child>
			<pose frame="">-0.011438517559809186 0.013416445692411755 0.01594441090851702 0 0 0</pose>
			<axis>
				<xyz>-0.0979493008211963 0.8618704725531149 -0.4975793635287829</xyz>
				<limit>
					<lower>0.0</lower>
					<upper>0.0</upper>
				</limit>
				<use_parent_model_frame>0</use_parent_model_frame>
			</axis>
		</joint>
		<joint name="hand_left_iring_joint0" type="revolute">
			<parent>arm_left_palm</parent>
			<child>hand_left_ring_link0</child>
			<pose frame="">-0.011353534171067423 0.01495624331070406 0.01457494996804705 0 0 0</pose>
			<axis>
				<xyz>0.0489322701867574 -0.8266587537717556 0.5605719737436912</xyz>
				<limit>
					<lower>0.0</lower>
					<upper>0.0</upper>
				</limit>
				<use_parent_model_frame>0</use_parent_model_frame>
			</axis>
		</joint>
		<joint name="hand_left_little_joint0" type="revolute">
			<parent>arm_left_palm</parent>
			<child>hand_left_index_link0</child>
			<pose frame="">-0.011167490912478968 0.016388848422477908 0.013102491155630443 0 0 0</pose>
			<axis>
				<xyz>0.00045716742891926314 0.7851556604951944 -0.6192982962920992</xyz>
				<limit>
					<lower>0.0</lower>
					<upper>0.0</upper>
				</limit>
				<use_parent_model_frame>0</use_parent_model_frame>
			</axis>
		</joint>
		<joint name="hand_left_index_joint0" type="revolute">
			<parent>arm_left_palm</parent>
			<child>hand_left_little_link0</child>
			<pose frame="">-0.007340793876031455 0.008166978172304162 0.009102988697151674 0 0 0</pose>
			<axis>
				<xyz>-0.12702537302227587 0.8798641087300467 -0.45793417079011645</xyz>
				<limit>
					<lower>0.0</lower>
					<upper>0.0</upper>
				</limit>
				<use_parent_model_frame>0</use_parent_model_frame>
			</axis>
		</joint>
		<joint name="hand_left_thumb_joint0" type="revolute">
			<parent>arm_left_palm</parent>
			<child>hand_left_thumb_link0</child>
			<pose frame="">0.0001101181978571475 0.015071155644260693 -0.011991445427988285 0 0 0</pose>
			<axis>
				<xyz>-0.5645437991104691 0.4401018776240249 0.6982840655476247</xyz>
				<limit>
					<lower>0.0</lower>
					<upper>0.0</upper>
				</limit>
				<use_parent_model_frame>0</use_parent_model_frame>
			</axis>
		</joint>
		<joint name="hand_left_index_joint1" type="revolute">
			<parent>hand_left_index_link0</parent>
			<child>hand_left_index_link1</child>
			<pose frame="">-0.006374938536653474 0.011296249392186972 0.006647179030050996 0 0 0</pose>
			<axis>
				<xyz>-0.00045716742892075446 -0.7851556604951987 0.619298296292098</xyz>
				<limit>
					<lower>0.0</lower>
					<upper>0.0</upper>
				</limit>
				<use_parent_model_frame>0</use_parent_model_frame>
			</axis>
		</joint>
		<joint name="hand_left_index_joint2" type="revolute">
			<parent>hand_left_index_link1</parent>
			<child>hand_left_index_link2</child>
			<pose frame="">-0.006307101975253602 0.010760099567161561 0.005963259636935137 0 0 0</pose>
			<axis>
				<xyz>-0.00045716742892005363 -0.785155660495197 0.6192982962920985</xyz>
				<limit>
					<lower>0.0</lower>
					<upper>0.0</upper>
				</limit>
				<use_parent_model_frame>0</use_parent_model_frame>
			</axis>
		</joint>
		<plugin filename="libcardsflow_gazebo_plugin.so" name="cardsflow_gazebo_plugin"/>
	</model>
</sdf>
