<?xml version="1.0" ?>
<sdf version="1.6">
	<model name="roboy_icecream">
		<link name="head">
			<self_collide>false</self_collide>
			<pose frame="">0.0005102180295681447 0.046445898229311826 0.8561776624188784 0.0 -0.0 0.0</pose>
			<inertial>
				<pose frame="">0.0 0.0 0.0 0 0 0</pose>
				<mass>2.049574035129534</mass>
				<inertia>
					<ixx>1.5391376142687194</ixx>
					<ixy>-6.313507101661185e-05</ixy>
					<ixz>-0.0010067309324671512</ixz>
					<iyy>1.5283787902680595</iyy>
					<iyz>-0.08418987485585369</iyz>
					<izz>0.030527659727340513</izz>
				</inertia>
			</inertial>
			<collision name="head_collision">
				<geometry>
					<mesh>
						<uri>model://roboy_icecream/meshes/CAD/head.stl</uri>
						<scale>0.001 0.001 0.001</scale>
					</mesh>
				</geometry>
			</collision>
			<visual name="head_visual">
				<geometry>
					<mesh>
						<uri>model://roboy_icecream/meshes/CAD/head.stl</uri>
						<scale>0.001 0.001 0.001</scale>
					</mesh>
				</geometry>
			</visual>
		</link>
		<link name="torso">
			<self_collide>false</self_collide>
			<pose frame="">-5.35255132199797e-05 -0.00020638163411974033 0.50876963867826 0.0 -0.0 0.0</pose>
			<inertial>
				<pose frame="">0.0 0.0 0.0 0 0 0</pose>
				<mass>11.588247145877938</mass>
				<inertia>
					<ixx>3.185978255602341</ixx>
					<ixy>-0.0011911816708613787</ixy>
					<ixz>0.0004984982415414905</ixz>
					<iyy>3.4400774592858085</iyy>
					<iyz>0.012190127058455498</iyz>
					<izz>0.32178508230654973</izz>
				</inertia>
			</inertial>
			<collision name="torso_collision">
				<geometry>
					<mesh>
						<uri>model://roboy_icecream/meshes/CAD/torso.stl</uri>
						<scale>0.001 0.001 0.001</scale>
					</mesh>
				</geometry>
			</collision>
			<visual name="torso_visual">
				<geometry>
					<mesh>
						<uri>model://roboy_icecream/meshes/CAD/torso.stl</uri>
						<scale>0.001 0.001 0.001</scale>
					</mesh>
				</geometry>
			</visual>
		</link>
		<link name="arm_right_palm">
			<self_collide>false</self_collide>
			<pose frame="">-0.6365181212163202 -0.24546068220999054 0.13580281334054448 0.0 -0.0 0.0</pose>
			<inertial>
				<pose frame="">0.0 0.0 0.0 0 0 0</pose>
				<mass>0.8282095215922115</mass>
				<inertia>
					<ixx>0.0661946117604509</ixx>
					<ixy>-0.12962226714696207</ixy>
					<ixz>0.0712983381114466</ixz>
					<iyy>0.3517025518507078</iyy>
					<iyz>0.02764516635495088</iyz>
					<izz>0.38637148134193516</izz>
				</inertia>
			</inertial>
			<collision name="arm_right_palm_collision">
				<geometry>
					<mesh>
						<uri>model://roboy_icecream/meshes/CAD/arm_right_palm.stl</uri>
						<scale>0.001 0.001 0.001</scale>
					</mesh>
				</geometry>
			</collision>
			<visual name="arm_right_palm_visual">
				<geometry>
					<mesh>
						<uri>model://roboy_icecream/meshes/CAD/arm_right_palm.stl</uri>
						<scale>0.001 0.001 0.001</scale>
					</mesh>
				</geometry>
			</visual>
		</link>
		<link name="arm_left_palm">
			<self_collide>false</self_collide>
			<pose frame="">0.6350256678969189 -0.24411296270711078 0.13562763623248386 0.0 -0.0 0.0</pose>
			<inertial>
				<pose frame="">0.0 0.0 0.0 0 0 0</pose>
				<mass>0.8282095209764669</mass>
				<inertia>
					<ixx>0.0655988221350774</ixx>
					<ixy>0.12860536600994235</ixy>
					<ixz>-0.07104600140860999</ixz>
					<iyy>0.3500765608989561</iyy>
					<iyz>0.02746258118643204</iyz>
					<izz>0.38424301915365505</izz>
				</inertia>
			</inertial>
			<collision name="arm_left_palm_collision">
				<geometry>
					<mesh>
						<uri>model://roboy_icecream/meshes/CAD/arm_left_palm.stl</uri>
						<scale>0.001 0.001 0.001</scale>
					</mesh>
				</geometry>
			</collision>
			<visual name="arm_left_palm_visual">
				<geometry>
					<mesh>
						<uri>model://roboy_icecream/meshes/CAD/arm_left_palm.stl</uri>
						<scale>0.001 0.001 0.001</scale>
					</mesh>
				</geometry>
			</visual>
		</link>
		<link name="arm_left_lower">
			<self_collide>false</self_collide>
			<pose frame="">0.5370118902949388 -0.178782733329587 0.24127190937071333 0.0 -0.0 0.0</pose>
			<inertial>
				<pose frame="">0.0 0.0 0.0 0 0 0</pose>
				<mass>7.274099416132657</mass>
				<inertia>
					<ixx>0.6824865040581906</ixx>
					<ixy>0.7057047294505986</ixy>
					<ixz>-0.9308804872196925</ixz>
					<iyy>2.5509906797486974</iyy>
					<iyz>0.30447448192314946</iyz>
					<izz>2.351200457091422</izz>
				</inertia>
			</inertial>
			<collision name="arm_left_lower_collision">
				<geometry>
					<mesh>
						<uri>model://roboy_icecream/meshes/CAD/arm_left_lower.stl</uri>
						<scale>0.001 0.001 0.001</scale>
					</mesh>
				</geometry>
			</collision>
			<visual name="arm_left_lower_visual">
				<geometry>
					<mesh>
						<uri>model://roboy_icecream/meshes/CAD/arm_left_lower.stl</uri>
						<scale>0.001 0.001 0.001</scale>
					</mesh>
				</geometry>
			</visual>
		</link>
		<link name="arm_right_lower">
			<self_collide>false</self_collide>
			<pose frame="">-0.5385357330723867 -0.1801547814650695 0.24140811707085838 0.0 -0.0 0.0</pose>
			<inertial>
				<pose frame="">0.0 0.0 0.0 0 0 0</pose>
				<mass>7.274097607229658</mass>
				<inertia>
					<ixx>0.6863706054863414</ixx>
					<ixy>-0.7129978887226184</ixy>
					<ixz>0.93419250142361</ixz>
					<iyy>2.563180998092053</iyy>
					<iyz>0.30714278319398663</iyz>
					<izz>2.3665717797438286</izz>
				</inertia>
			</inertial>
			<collision name="arm_right_lower_collision">
				<geometry>
					<mesh>
						<uri>model://roboy_icecream/meshes/CAD/arm_right_lower.stl</uri>
						<scale>0.001 0.001 0.001</scale>
					</mesh>
				</geometry>
			</collision>
			<visual name="arm_right_lower_visual">
				<geometry>
					<mesh>
						<uri>model://roboy_icecream/meshes/CAD/arm_right_lower.stl</uri>
						<scale>0.001 0.001 0.001</scale>
					</mesh>
				</geometry>
			</visual>
		</link>
		<link name="arm_right_upper">
			<self_collide>false</self_collide>
			<pose frame="">-0.3986822074961964 -0.06979898649008576 0.4161292585094858 0.0 -0.0 0.0</pose>
			<inertial>
				<pose frame="">0.0 0.0 0.0 0 0 0</pose>
				<mass>3.6102108682251886</mass>
				<inertia>
					<ixx>0.6659592094028193</ixx>
					<ixy>-0.10807312345866366</ixy>
					<ixz>0.5866982058586321</ixz>
					<iyy>1.2269443470429406</iyy>
					<iyz>0.095160406460662</iyz>
					<izz>0.6099749301169597</izz>
				</inertia>
			</inertial>
			<collision name="arm_right_upper_collision">
				<geometry>
					<mesh>
						<uri>model://roboy_icecream/meshes/CAD/arm_right_upper.stl</uri>
						<scale>0.001 0.001 0.001</scale>
					</mesh>
				</geometry>
			</collision>
			<visual name="arm_right_upper_visual">
				<geometry>
					<mesh>
						<uri>model://roboy_icecream/meshes/CAD/arm_right_upper.stl</uri>
						<scale>0.001 0.001 0.001</scale>
					</mesh>
				</geometry>
			</visual>
		</link>
		<link name="arm_left_upper">
			<self_collide>false</self_collide>
			<pose frame="">0.39707679790899975 -0.06856305043531624 0.4162526518458033 0.0 -0.0 0.0</pose>
			<inertial>
				<pose frame="">0.0 0.0 0.0 0 0 0</pose>
				<mass>3.6101133714243976</mass>
				<inertia>
					<ixx>0.6656756139152729</ixx>
					<ixy>0.10597092436689769</ixy>
					<ixz>-0.5844987825773871</ixz>
					<iyy>1.222531164650921</iyy>
					<iyz>0.09327874259346725</iyz>
					<izz>0.6048570295297873</izz>
				</inertia>
			</inertial>
			<collision name="arm_left_upper_collision">
				<geometry>
					<mesh>
						<uri>model://roboy_icecream/meshes/CAD/arm_left_upper.stl</uri>
						<scale>0.001 0.001 0.001</scale>
					</mesh>
				</geometry>
			</collision>
			<visual name="arm_left_upper_visual">
				<geometry>
					<mesh>
						<uri>model://roboy_icecream/meshes/CAD/arm_left_upper.stl</uri>
						<scale>0.001 0.001 0.001</scale>
					</mesh>
				</geometry>
			</visual>
		</link>
		<link name="shoulder_left_link1">
			<self_collide>false</self_collide>
			<pose frame="">0.2918943672417947 0.013936393619393582 0.5448918362217308 0.0 -0.0 0.0</pose>
			<inertial>
				<pose frame="">0.0 0.0 0.0 0 0 0</pose>
				<mass>0.09036359201900478</mass>
				<inertia>
					<ixx>0.026854235531623766</ixx>
					<ixy>-0.00036759500737930086</ixy>
					<ixz>-0.014372406819918018</ixz>
					<iyy>0.034535872662129895</iyy>
					<iyz>-0.0006862054947928941</iyz>
					<izz>0.007723830113048254</izz>
				</inertia>
			</inertial>
			<collision name="shoulder_left_link1_collision">
				<geometry>
					<mesh>
						<uri>model://roboy_icecream/meshes/CAD/shoulder_left_link1.stl</uri>
						<scale>0.001 0.001 0.001</scale>
					</mesh>
				</geometry>
			</collision>
			<visual name="shoulder_left_link1_visual">
				<geometry>
					<mesh>
						<uri>model://roboy_icecream/meshes/CAD/shoulder_left_link1.stl</uri>
						<scale>0.001 0.001 0.001</scale>
					</mesh>
				</geometry>
			</visual>
		</link>
		<link name="shoulder_left_link2">
			<self_collide>false</self_collide>
			<pose frame="">0.2918943623808747 0.013936393384462419 0.5448918357909863 0.0 -0.0 0.0</pose>
			<inertial>
				<pose frame="">0.0 0.0 0.0 0 0 0</pose>
				<mass>0.007113170038864662</mass>
				<inertia>
					<ixx>0.002113434852236192</ixx>
					<ixy>-2.893605321299586e-05</ixy>
					<ixz>-0.0011313557762622297</ixz>
					<iyy>0.0027181118918378614</iyy>
					<iyz>-5.401618252193771e-05</iyz>
					<izz>0.0006075426550467592</izz>
				</inertia>
			</inertial>
			<collision name="shoulder_left_link2_collision">
				<geometry>
					<mesh>
						<uri>model://roboy_icecream/meshes/CAD/shoulder_left_link2.stl</uri>
						<scale>0.001 0.001 0.001</scale>
					</mesh>
				</geometry>
			</collision>
			<visual name="shoulder_left_link2_visual">
				<geometry>
					<mesh>
						<uri>model://roboy_icecream/meshes/CAD/shoulder_left_link2.stl</uri>
						<scale>0.001 0.001 0.001</scale>
					</mesh>
				</geometry>
			</visual>
		</link>
		<link name="hand_left_index_link1">
			<self_collide>false</self_collide>
			<pose frame="">0.7020945590519045 -0.3257722239676183 0.0763121062335839 0.0 -0.0 0.0</pose>
			<inertial>
				<pose frame="">0.0 0.0 0.0 0 0 0</pose>
				<mass>0.030810600216883144</mass>
				<inertia>
					<ixx>0.0034511301347674543</ixx>
					<ixy>0.00704741252805683</ixy>
					<ixz>-0.0016503707008156728</ixz>
					<iyy>0.015368863454936434</iyy>
					<iyz>0.0007657743886956809</iyz>
					<izz>0.0184592001516197</izz>
				</inertia>
			</inertial>
			<collision name="hand_left_index_link1_collision">
				<geometry>
					<mesh>
						<uri>model://roboy_icecream/meshes/CAD/hand_left_index_link1.stl</uri>
						<scale>0.001 0.001 0.001</scale>
					</mesh>
				</geometry>
			</collision>
			<visual name="hand_left_index_link1_visual">
				<geometry>
					<mesh>
						<uri>model://roboy_icecream/meshes/CAD/hand_left_index_link1.stl</uri>
						<scale>0.001 0.001 0.001</scale>
					</mesh>
				</geometry>
			</visual>
		</link>
		<link name="hand_left_index_link0">
			<self_collide>false</self_collide>
			<pose frame="">0.6813873765209756 -0.30793269611963214 0.09899240078649851 0.0 -0.0 0.0</pose>
			<inertial>
				<pose frame="">0.0 0.0 0.0 0 0 0</pose>
				<mass>0.05584900095770278</mass>
				<inertia>
					<ixx>0.005850484085961011</ixx>
					<ixy>0.01172071137349797</ixy>
					<ixz>-0.003764090047569177</ixz>
					<iyy>0.02648515087867046</iyy>
					<iyz>0.0016999571512312794</iyz>
					<izz>0.03123241202358822</izz>
				</inertia>
			</inertial>
			<collision name="hand_left_index_link0_collision">
				<geometry>
					<mesh>
						<uri>model://roboy_icecream/meshes/CAD/hand_left_index_link0.stl</uri>
						<scale>0.001 0.001 0.001</scale>
					</mesh>
				</geometry>
			</collision>
			<visual name="hand_left_index_link0_visual">
				<geometry>
					<mesh>
						<uri>model://roboy_icecream/meshes/CAD/hand_left_index_link0.stl</uri>
						<scale>0.001 0.001 0.001</scale>
					</mesh>
				</geometry>
			</visual>
		</link>
		<link name="hand_left_index_link2">
			<self_collide>false</self_collide>
			<pose frame="">0.7167599123101651 -0.33846917194165493 0.06014904547064845 0.0 -0.0 0.0</pose>
			<inertial>
				<pose frame="">0.0 0.0 0.0 0 0 0</pose>
				<mass>0.030337235888829715</mass>
				<inertia>
					<ixx>0.003586860390106042</ixx>
					<ixy>0.007360006720784233</ixy>
					<ixz>-0.0013076307207537396</ixz>
					<iyy>0.01569667077023572</iyy>
					<iyz>0.0006174739980112076</iyz>
					<izz>0.01906229503362434</izz>
				</inertia>
			</inertial>
			<collision name="hand_left_index_link2_collision">
				<geometry>
					<mesh>
						<uri>model://roboy_icecream/meshes/CAD/hand_left_index_link2.stl</uri>
						<scale>0.001 0.001 0.001</scale>
					</mesh>
				</geometry>
			</collision>
			<visual name="hand_left_index_link2_visual">
				<geometry>
					<mesh>
						<uri>model://roboy_icecream/meshes/CAD/hand_left_index_link2.stl</uri>
						<scale>0.001 0.001 0.001</scale>
					</mesh>
				</geometry>
			</visual>
		</link>
		<link name="hand_left_middle_link1">
			<self_collide>false</self_collide>
			<pose frame="">0.698437812356798 -0.271420158619049 0.04026810273649299 0.0 -0.0 0.0</pose>
			<inertial>
				<pose frame="">0.0 0.0 0.0 0 0 0</pose>
				<mass>0.03081073881990825</mass>
				<inertia>
					<ixx>0.0023216116713991944</ixx>
					<ixy>0.0058410485509295</ixy>
					<ixz>-0.000866095087917645</ixz>
					<iyy>0.015081765106218416</iyy>
					<iyz>0.00033660304946568</iyz>
					<izz>0.01730131313421421</izz>
				</inertia>
			</inertial>
			<collision name="hand_left_middle_link1_collision">
				<geometry>
					<mesh>
						<uri>model://roboy_icecream/meshes/CAD/hand_left_middle_link1.stl</uri>
						<scale>0.001 0.001 0.001</scale>
					</mesh>
				</geometry>
			</collision>
			<visual name="hand_left_middle_link1_visual">
				<geometry>
					<mesh>
						<uri>model://roboy_icecream/meshes/CAD/hand_left_middle_link1.stl</uri>
						<scale>0.001 0.001 0.001</scale>
					</mesh>
				</geometry>
			</visual>
		</link>
		<link name="hand_left_middle_link0">
			<self_collide>false</self_collide>
			<pose frame="">0.6780397787920346 -0.25870278632898713 0.06641222995506792 0.0 -0.0 0.0</pose>
			<inertial>
				<pose frame="">0.0 0.0 0.0 0 0 0</pose>
				<mass>0.055831334816546646</mass>
				<inertia>
					<ixx>0.003990392798151444</ixx>
					<ixy>0.009795111643438202</ixy>
					<ixz>-0.002510649350790885</ixz>
					<iyy>0.02592273738131162</iyy>
					<iyz>0.000957197587437346</iyz>
					<izz>0.02940988044619106</izz>
				</inertia>
			</inertial>
			<collision name="hand_left_middle_link0_collision">
				<geometry>
					<mesh>
						<uri>model://roboy_icecream/meshes/CAD/hand_left_middle_link0.stl</uri>
						<scale>0.001 0.001 0.001</scale>
					</mesh>
				</geometry>
			</collision>
			<visual name="hand_left_middle_link0_visual">
				<geometry>
					<mesh>
						<uri>model://roboy_icecream/meshes/CAD/hand_left_middle_link0.stl</uri>
						<scale>0.001 0.001 0.001</scale>
					</mesh>
				</geometry>
			</visual>
		</link>
		<link name="hand_left_middle_link2">
			<self_collide>false</self_collide>
			<pose frame="">0.712882304056937 -0.28047502772467686 0.021644247987551095 0.0 -0.0 0.0</pose>
			<inertial>
				<pose frame="">0.0 0.0 0.0 0 0 0</pose>
				<mass>0.03033633396737544</mass>
				<inertia>
					<ixx>0.0024023025129959875</ixx>
					<ixy>0.006065766877878605</ixy>
					<ixz>-0.00046779128674052803</ixz>
					<iyy>0.015432594252539332</iyy>
					<iyz>0.0001840461061177695</iyz>
					<izz>0.017804605454145028</izz>
				</inertia>
			</inertial>
			<collision name="hand_left_middle_link2_collision">
				<geometry>
					<mesh>
						<uri>model://roboy_icecream/meshes/CAD/hand_left_middle_link2.stl</uri>
						<scale>0.001 0.001 0.001</scale>
					</mesh>
				</geometry>
			</collision>
			<visual name="hand_left_middle_link2_visual">
				<geometry>
					<mesh>
						<uri>model://roboy_icecream/meshes/CAD/hand_left_middle_link2.stl</uri>
						<scale>0.001 0.001 0.001</scale>
					</mesh>
				</geometry>
			</visual>
		</link>
		<link name="hand_left_ring_link1">
			<self_collide>false</self_collide>
			<pose frame="">0.7046840830829593 -0.3015305180787642 0.05242403848715782 0.0 -0.0 0.0</pose>
			<inertial>
				<pose frame="">0.0 0.0 0.0 0 0 0</pose>
				<mass>0.030810597058291516</mass>
				<inertia>
					<ixx>0.0028878479321763884</ixx>
					<ixy>0.006547040722103612</ixy>
					<ixz>-0.0011377849324884202</ixz>
					<iyy>0.015386400595745685</iyy>
					<iyz>0.0004868656667721309</iyz>
					<izz>0.018102852748695396</izz>
				</inertia>
			</inertial>
			<collision name="hand_left_ring_link1_collision">
				<geometry>
					<mesh>
						<uri>model://roboy_icecream/meshes/CAD/hand_left_ring_link1.stl</uri>
						<scale>0.001 0.001 0.001</scale>
					</mesh>
				</geometry>
			</collision>
			<visual name="hand_left_ring_link1_visual">
				<geometry>
					<mesh>
						<uri>model://roboy_icecream/meshes/CAD/hand_left_ring_link1.stl</uri>
						<scale>0.001 0.001 0.001</scale>
					</mesh>
				</geometry>
			</visual>
		</link>
		<link name="hand_left_ring_link0">
			<self_collide>false</self_collide>
			<pose frame="">0.6840551034817947 -0.28619254692810164 0.07693059851654294 0.0 -0.0 0.0</pose>
			<inertial>
				<pose frame="">0.0 0.0 0.0 0 0 0</pose>
				<mass>0.055852824780270094</mass>
				<inertia>
					<ixx>0.004912713257115162</ixx>
					<ixy>0.010936457002691365</ixy>
					<ixz>-0.002935974703750103</ixz>
					<iyy>0.02647415594214936</iyy>
					<iyz>0.00122739936571454</iyz>
					<izz>0.030716042356195104</izz>
				</inertia>
			</inertial>
			<collision name="hand_left_ring_link0_collision">
				<geometry>
					<mesh>
						<uri>model://roboy_icecream/meshes/CAD/hand_left_ring_link0.stl</uri>
						<scale>0.001 0.001 0.001</scale>
					</mesh>
				</geometry>
			</collision>
			<visual name="hand_left_ring_link0_visual">
				<geometry>
					<mesh>
						<uri>model://roboy_icecream/meshes/CAD/hand_left_ring_link0.stl</uri>
						<scale>0.001 0.001 0.001</scale>
					</mesh>
				</geometry>
			</visual>
		</link>
		<link name="hand_left_ring_link2">
			<self_collide>false</self_collide>
			<pose frame="">0.7192932791552032 -0.3124483767472179 0.03496338434348094 0.0 -0.0 0.0</pose>
			<inertial>
				<pose frame="">0.0 0.0 0.0 0 0 0</pose>
				<mass>0.030336320395881453</mass>
				<inertia>
					<ixx>0.0030002724624192223</ixx>
					<ixy>0.006817998963166919</ixy>
					<ixz>-0.000762638873829703</ixz>
					<iyy>0.015733943217686466</iyy>
					<iyz>0.00033126659962878633</iyz>
					<izz>0.01865825048858876</izz>
				</inertia>
			</inertial>
			<collision name="hand_left_ring_link2_collision">
				<geometry>
					<mesh>
						<uri>model://roboy_icecream/meshes/CAD/hand_left_ring_link2.stl</uri>
						<scale>0.001 0.001 0.001</scale>
					</mesh>
				</geometry>
			</collision>
			<visual name="hand_left_ring_link2_visual">
				<geometry>
					<mesh>
						<uri>model://roboy_icecream/meshes/CAD/hand_left_ring_link2.stl</uri>
						<scale>0.001 0.001 0.001</scale>
					</mesh>
				</geometry>
			</visual>
		</link>
		<link name="hand_left_little_link1">
			<self_collide>false</self_collide>
			<pose frame="">0.678886505595801 -0.23584828760818466 0.050234561466954486 0.0 -0.0 0.0</pose>
			<inertial>
				<pose frame="">0.0 0.0 0.0 0 0 0</pose>
				<mass>0.030811374120953198</mass>
				<inertia>
					<ixx>0.00179348115877289</ixx>
					<ixy>0.004933570621796022</ixy>
					<ixz>-0.0010503199170717274</ixz>
					<iyy>0.014280187058384875</iyy>
					<iyz>0.0003649193333483215</iyz>
					<izz>0.01591596231946317</izz>
				</inertia>
			</inertial>
			<collision name="hand_left_little_link1_collision">
				<geometry>
					<mesh>
						<uri>model://roboy_icecream/meshes/CAD/hand_left_little_link1.stl</uri>
						<scale>0.001 0.001 0.001</scale>
					</mesh>
				</geometry>
			</collision>
			<visual name="hand_left_little_link1_visual">
				<geometry>
					<mesh>
						<uri>model://roboy_icecream/meshes/CAD/hand_left_little_link1.stl</uri>
						<scale>0.001 0.001 0.001</scale>
					</mesh>
				</geometry>
			</visual>
		</link>
		<link name="hand_left_little_link2">
			<self_collide>false</self_collide>
			<pose frame="">0.6931804165794234 -0.24375096137054328 0.030981303555461265 0.0 -0.0 0.0</pose>
			<inertial>
				<pose frame="">0.0 0.0 0.0 0 0 0</pose>
				<mass>0.030336908642256268</mass>
				<inertia>
					<ixx>0.0018332243932410027</ixx>
					<ixy>0.005125973131916176</ixy>
					<ixz>-0.000651208498818426</ixz>
					<iyy>0.014607431938702656</iyy>
					<iyz>0.00022899355944009834</iyz>
					<izz>0.016380511329908105</izz>
				</inertia>
			</inertial>
			<collision name="hand_left_little_link2_collision">
				<geometry>
					<mesh>
						<uri>model://roboy_icecream/meshes/CAD/hand_left_little_link2.stl</uri>
						<scale>0.001 0.001 0.001</scale>
					</mesh>
				</geometry>
			</collision>
			<visual name="hand_left_little_link2_visual">
				<geometry>
					<mesh>
						<uri>model://roboy_icecream/meshes/CAD/hand_left_little_link2.stl</uri>
						<scale>0.001 0.001 0.001</scale>
					</mesh>
				</geometry>
			</visual>
		</link>
		<link name="hand_left_little_link0">
			<self_collide>false</self_collide>
			<pose frame="">0.6645346260783664 -0.22755225617382555 0.0702645870440505 0.0 -0.0 0.0</pose>
			<inertial>
				<pose frame="">0.0 0.0 0.0 0 0 0</pose>
				<mass>0.0308113741209532</mass>
				<inertia>
					<ixx>0.001749396724272586</ixx>
					<ixy>0.004659415135832687</ixy>
					<ixz>-0.00143822541281211</ixz>
					<iyy>0.01376049108729013</iyy>
					<iyz>0.0004925132378942396</iyz>
					<izz>0.015203449187173522</izz>
				</inertia>
			</inertial>
			<collision name="hand_left_little_link0_collision">
				<geometry>
					<mesh>
						<uri>model://roboy_icecream/meshes/CAD/hand_left_little_link0.stl</uri>
						<scale>0.001 0.001 0.001</scale>
					</mesh>
				</geometry>
			</collision>
			<visual name="hand_left_little_link0_visual">
				<geometry>
					<mesh>
						<uri>model://roboy_icecream/meshes/CAD/hand_left_little_link0.stl</uri>
						<scale>0.001 0.001 0.001</scale>
					</mesh>
				</geometry>
			</visual>
		</link>
		<link name="hand_left_thumb_link2">
			<self_collide>false</self_collide>
			<pose frame="">0.6304882644220328 -0.3385812853857143 0.1824737897952272 0.0 -0.0 0.0</pose>
			<inertial>
				<pose frame="">0.0 0.0 0.0 0 0 0</pose>
				<mass>0.030335989064583388</mass>
				<inertia>
					<ixx>0.004489354729882424</ixx>
					<ixy>0.006475836840804122</ixy>
					<ixz>-0.0034902262588540085</ixz>
					<iyy>0.013070313974085463</iyy>
					<iyz>0.0018745190424383962</iyz>
					<izz>0.015538224678982204</izz>
				</inertia>
			</inertial>
			<collision name="hand_left_thumb_link2_collision">
				<geometry>
					<mesh>
						<uri>model://roboy_icecream/meshes/CAD/hand_left_thumb_link2.stl</uri>
						<scale>0.001 0.001 0.001</scale>
					</mesh>
				</geometry>
			</collision>
			<visual name="hand_left_thumb_link2_visual">
				<geometry>
					<mesh>
						<uri>model://roboy_icecream/meshes/CAD/hand_left_thumb_link2.stl</uri>
						<scale>0.001 0.001 0.001</scale>
					</mesh>
				</geometry>
			</visual>
		</link>
		<link name="hand_left_thumb_link0">
			<self_collide>false</self_collide>
			<pose frame="">0.620713433278994 -0.2809930285193407 0.15489885949022678 0.0 -0.0 0.0</pose>
			<inertial>
				<pose frame="">0.0 0.0 0.0 0 0 0</pose>
				<mass>0.11643461952857805</mass>
				<inertia>
					<ixx>0.012010971087731106</ixx>
					<ixy>0.020311272292729367</ixy>
					<ixz>-0.01119416942676441</ixz>
					<iyy>0.04766696219825403</iyy>
					<iyz>0.005072105048872104</iyz>
					<izz>0.05407479296997607</izz>
				</inertia>
			</inertial>
			<collision name="hand_left_thumb_link0_collision">
				<geometry>
					<mesh>
						<uri>model://roboy_icecream/meshes/CAD/hand_left_thumb_link0.stl</uri>
						<scale>0.001 0.001 0.001</scale>
					</mesh>
				</geometry>
			</collision>
			<visual name="hand_left_thumb_link0_visual">
				<geometry>
					<mesh>
						<uri>model://roboy_icecream/meshes/CAD/hand_left_thumb_link0.stl</uri>
						<scale>0.001 0.001 0.001</scale>
					</mesh>
				</geometry>
			</visual>
		</link>
		<link name="hand_left_thumb_link1">
			<self_collide>false</self_collide>
			<pose frame="">0.6293984798480997 -0.3179669192839179 0.16796199317794436 0.0 -0.0 0.0</pose>
			<inertial>
				<pose frame="">0.0 0.0 0.0 0 0 0</pose>
				<mass>0.030824527684383127</mass>
				<inertia>
					<ixx>0.003987762221169893</ixx>
					<ixy>0.006168319217634503</ixy>
					<ixz>-0.003258510059016605</ixz>
					<iyy>0.013080989170821395</iyy>
					<iyz>0.001646568112932092</iyz>
					<izz>0.015328002628701421</izz>
				</inertia>
			</inertial>
			<collision name="hand_left_thumb_link1_collision">
				<geometry>
					<mesh>
						<uri>model://roboy_icecream/meshes/CAD/hand_left_thumb_link1.stl</uri>
						<scale>0.001 0.001 0.001</scale>
					</mesh>
				</geometry>
			</collision>
			<visual name="hand_left_thumb_link1_visual">
				<geometry>
					<mesh>
						<uri>model://roboy_icecream/meshes/CAD/hand_left_thumb_link1.stl</uri>
						<scale>0.001 0.001 0.001</scale>
					</mesh>
				</geometry>
			</visual>
		</link>
		<link name="shoulder_right_link1">
			<self_collide>false</self_collide>
			<pose frame="">-0.2930642609023861 0.01109383220250954 0.5468414984574267 0.0 -0.0 0.0</pose>
			<inertial>
				<pose frame="">0.0 0.0 0.0 0 0 0</pose>
				<mass>0.0903636656787565</mass>
				<inertia>
					<ixx>0.027040168124669237</ixx>
					<ixy>0.000293790868091621</ixy>
					<ixz>0.014481653914279803</ixz>
					<iyy>0.034790080309606335</iyy>
					<iyz>-0.0005481973067788913</iyz>
					<izz>0.007779246454693213</izz>
				</inertia>
			</inertial>
			<collision name="shoulder_right_link1_collision">
				<geometry>
					<mesh>
						<uri>model://roboy_icecream/meshes/CAD/shoulder_right_link1.stl</uri>
						<scale>0.001 0.001 0.001</scale>
					</mesh>
				</geometry>
			</collision>
			<visual name="shoulder_right_link1_visual">
				<geometry>
					<mesh>
						<uri>model://roboy_icecream/meshes/CAD/shoulder_right_link1.stl</uri>
						<scale>0.001 0.001 0.001</scale>
					</mesh>
				</geometry>
			</visual>
		</link>
		<link name="shoulder_right_link2">
			<self_collide>false</self_collide>
			<pose frame="">-0.2930642607647908 0.011093832147498362 0.5468414985002678 0.0 -0.0 0.0</pose>
			<inertial>
				<pose frame="">0.0 0.0 0.0 0 0 0</pose>
				<mass>0.007113171718499355</mass>
				<inertia>
					<ixx>0.0021280697191938397</ixx>
					<ixy>2.3126384559716274e-05</ixy>
					<ixz>0.001139954762194572</ixz>
					<iyy>0.0027381208465940333</iyy>
					<iyz>-4.315253847256294e-05</iyz>
					<izz>0.0006119045398845659</izz>
				</inertia>
			</inertial>
			<collision name="shoulder_right_link2_collision">
				<geometry>
					<mesh>
						<uri>model://roboy_icecream/meshes/CAD/shoulder_right_link2.stl</uri>
						<scale>0.001 0.001 0.001</scale>
					</mesh>
				</geometry>
			</collision>
			<visual name="shoulder_right_link2_visual">
				<geometry>
					<mesh>
						<uri>model://roboy_icecream/meshes/CAD/shoulder_right_link2.stl</uri>
						<scale>0.001 0.001 0.001</scale>
					</mesh>
				</geometry>
			</visual>
		</link>
		<link name="hand_right_index_link1">
			<self_collide>false</self_collide>
			<pose frame="">-0.7037204369955756 -0.32753837540215996 0.07656989430036208 0.0 -0.0 0.0</pose>
			<inertial>
				<pose frame="">0.0 0.0 0.0 0 0 0</pose>
				<mass>0.03081055844419456</mass>
				<inertia>
					<ixx>0.003487890352932283</ixx>
					<ixy>-0.007102016362192534</ixy>
					<ixz>0.0016597809092071792</ixz>
					<iyy>0.01544047993947751</iyy>
					<iyz>0.0007725274545538454</iyz>
					<izz>0.018565149068801235</izz>
				</inertia>
			</inertial>
			<collision name="hand_right_index_link1_collision">
				<geometry>
					<mesh>
						<uri>model://roboy_icecream/meshes/CAD/hand_right_index_link1.stl</uri>
						<scale>0.001 0.001 0.001</scale>
					</mesh>
				</geometry>
			</collision>
			<visual name="hand_right_index_link1_visual">
				<geometry>
					<mesh>
						<uri>model://roboy_icecream/meshes/CAD/hand_right_index_link1.stl</uri>
						<scale>0.001 0.001 0.001</scale>
					</mesh>
				</geometry>
			</visual>
		</link>
		<link name="hand_right_index_link0">
			<self_collide>false</self_collide>
			<pose frame="">-0.6830133165319692 -0.30962251499635096 0.09918996648819473 0.0 -0.0 0.0</pose>
			<inertial>
				<pose frame="">0.0 0.0 0.0 0 0 0</pose>
				<mass>0.055849025991352386</mass>
				<inertia>
					<ixx>0.005910954971622043</ixx>
					<ixy>-0.011813138765539905</ixy>
					<ixz>0.003780617627846769</ixz>
					<iyy>0.026611246675515243</iyy>
					<iyz>0.001712716660396027</iyz>
					<izz>0.0314146047398684</izz>
				</inertia>
			</inertial>
			<collision name="hand_right_index_link0_collision">
				<geometry>
					<mesh>
						<uri>model://roboy_icecream/meshes/CAD/hand_right_index_link0.stl</uri>
						<scale>0.001 0.001 0.001</scale>
					</mesh>
				</geometry>
			</collision>
			<visual name="hand_right_index_link0_visual">
				<geometry>
					<mesh>
						<uri>model://roboy_icecream/meshes/CAD/hand_right_index_link0.stl</uri>
						<scale>0.001 0.001 0.001</scale>
					</mesh>
				</geometry>
			</visual>
		</link>
		<link name="hand_right_index_link2">
			<self_collide>false</self_collide>
			<pose frame="">-0.7183857589997648 -0.3403115845806918 0.060466969405007336 0.0 -0.0 0.0</pose>
			<inertial>
				<pose frame="">0.0 0.0 0.0 0 0 0</pose>
				<mass>0.030337239357465594</mass>
				<inertia>
					<ixx>0.0036259634757035077</ixx>
					<ixy>-0.007416855570412547</ixy>
					<ixz>0.0013175267826576343</ixz>
					<iyy>0.015768622389916814</iyy>
					<iyz>0.0006241182734527755</iyz>
					<izz>0.019171022874612993</izz>
				</inertia>
			</inertial>
			<collision name="hand_right_index_link2_collision">
				<geometry>
					<mesh>
						<uri>model://roboy_icecream/meshes/CAD/hand_right_index_link2.stl</uri>
						<scale>0.001 0.001 0.001</scale>
					</mesh>
				</geometry>
			</collision>
			<visual name="hand_right_index_link2_visual">
				<geometry>
					<mesh>
						<uri>model://roboy_icecream/meshes/CAD/hand_right_index_link2.stl</uri>
						<scale>0.001 0.001 0.001</scale>
					</mesh>
				</geometry>
			</visual>
		</link>
		<link name="hand_right_middle_link1">
			<self_collide>false</self_collide>
			<pose frame="">-0.7063299747321682 -0.3033131448228975 0.05265843281477369 0.0 -0.0 0.0</pose>
			<inertial>
				<pose frame="">0.0 0.0 0.0 0 0 0</pose>
				<mass>0.030811264606209175</mass>
				<inertia>
					<ixx>0.002921890353018262</ixx>
					<ixy>-0.006601269301490266</ixy>
					<ixz>0.0011455695170896456</ixz>
					<iyy>0.015459048139963464</iyy>
					<iyz>0.000491946077387649</iyz>
					<izz>0.01820802151532692</izz>
				</inertia>
			</inertial>
			<collision name="hand_right_middle_link1_collision">
				<geometry>
					<mesh>
						<uri>model://roboy_icecream/meshes/CAD/hand_right_middle_link1.stl</uri>
						<scale>0.001 0.001 0.001</scale>
					</mesh>
				</geometry>
			</collision>
			<visual name="hand_right_middle_link1_visual">
				<geometry>
					<mesh>
						<uri>model://roboy_icecream/meshes/CAD/hand_right_middle_link1.stl</uri>
						<scale>0.001 0.001 0.001</scale>
					</mesh>
				</geometry>
			</visual>
		</link>
		<link name="hand_right_middle_link0">
			<self_collide>false</self_collide>
			<pose frame="">-0.6856955739403583 -0.28789471187841814 0.0771105354915583 0.0 -0.0 0.0</pose>
			<inertial>
				<pose frame="">0.0 0.0 0.0 0 0 0</pose>
				<mass>0.05585161472558283</mass>
				<inertia>
					<ixx>0.00496873423176196</ixx>
					<ixy>-0.011027634138397127</ixy>
					<ixz>0.002949852169187388</ixz>
					<iyy>0.026600639744633784</iyy>
					<iyz>0.0012375802915924664</iyz>
					<izz>0.030895465179533513</izz>
				</inertia>
			</inertial>
			<collision name="hand_right_middle_link0_collision">
				<geometry>
					<mesh>
						<uri>model://roboy_icecream/meshes/CAD/hand_right_middle_link0.stl</uri>
						<scale>0.001 0.001 0.001</scale>
					</mesh>
				</geometry>
			</collision>
			<visual name="hand_right_middle_link0_visual">
				<geometry>
					<mesh>
						<uri>model://roboy_icecream/meshes/CAD/hand_right_middle_link0.stl</uri>
						<scale>0.001 0.001 0.001</scale>
					</mesh>
				</geometry>
			</visual>
		</link>
		<link name="hand_right_middle_link2">
			<self_collide>false</self_collide>
			<pose frame="">-0.7209443453557448 -0.31431188709883406 0.035252014458607296 0.0 -0.0 0.0</pose>
			<inertial>
				<pose frame="">0.0 0.0 0.0 0 0 0</pose>
				<mass>0.030337290984439005</mass>
				<inertia>
					<ixx>0.0030364113932621357</ixx>
					<ixy>-0.006874614426467703</ixy>
					<ixz>0.0007707264303232884</ixz>
					<iyy>0.015807176137030948</iyy>
					<iyz>0.0003360054154606287</iyz>
					<izz>0.01876639026125421</izz>
				</inertia>
			</inertial>
			<collision name="hand_right_middle_link2_collision">
				<geometry>
					<mesh>
						<uri>model://roboy_icecream/meshes/CAD/hand_right_middle_link2.stl</uri>
						<scale>0.001 0.001 0.001</scale>
					</mesh>
				</geometry>
			</collision>
			<visual name="hand_right_middle_link2_visual">
				<geometry>
					<mesh>
						<uri>model://roboy_icecream/meshes/CAD/hand_right_middle_link2.stl</uri>
						<scale>0.001 0.001 0.001</scale>
					</mesh>
				</geometry>
			</visual>
		</link>
		<link name="hand_right_ring_link1">
			<self_collide>false</self_collide>
			<pose frame="">-0.7001035377914323 -0.2732167872782044 0.04047746736993554 0.0 -0.0 0.0</pose>
			<inertial>
				<pose frame="">0.0 0.0 0.0 0 0 0</pose>
				<mass>0.03081221249464445</mass>
				<inertia>
					<ixx>0.0023523934994350753</ixx>
					<ixy>-0.005894015224783085</ixy>
					<ixz>0.0008727199405940064</ixz>
					<iyy>0.015154787052158959</iyy>
					<iyz>0.0003406107508784914</iyz>
					<izz>0.017404070578013534</izz>
				</inertia>
			</inertial>
			<collision name="hand_right_ring_link1_collision">
				<geometry>
					<mesh>
						<uri>model://roboy_icecream/meshes/CAD/hand_right_ring_link1.stl</uri>
						<scale>0.001 0.001 0.001</scale>
					</mesh>
				</geometry>
			</collision>
			<visual name="hand_right_ring_link1_visual">
				<geometry>
					<mesh>
						<uri>model://roboy_icecream/meshes/CAD/hand_right_ring_link1.stl</uri>
						<scale>0.001 0.001 0.001</scale>
					</mesh>
				</geometry>
			</visual>
		</link>
		<link name="hand_right_ring_link0">
			<self_collide>false</self_collide>
			<pose frame="">-0.6796935040625266 -0.26041346739971577 0.06657174994264967 0.0 -0.0 0.0</pose>
			<inertial>
				<pose frame="">0.0 0.0 0.0 0 0 0</pose>
				<mass>0.05584221000563185</mass>
				<inertia>
					<ixx>0.004041959121354937</ixx>
					<ixy>-0.009885877491479903</ixy>
					<ixz>0.0025233362556488204</ixz>
					<iyy>0.02605445349783983</iyy>
					<iyz>0.0009660522000718278</iyz>
					<izz>0.029590695864225518</izz>
				</inertia>
			</inertial>
			<collision name="hand_right_ring_link0_collision">
				<geometry>
					<mesh>
						<uri>model://roboy_icecream/meshes/CAD/hand_right_ring_link0.stl</uri>
						<scale>0.001 0.001 0.001</scale>
					</mesh>
				</geometry>
			</collision>
			<visual name="hand_right_ring_link0_visual">
				<geometry>
					<mesh>
						<uri>model://roboy_icecream/meshes/CAD/hand_right_ring_link0.stl</uri>
						<scale>0.001 0.001 0.001</scale>
					</mesh>
				</geometry>
			</visual>
		</link>
		<link name="hand_right_ring_link2">
			<self_collide>false</self_collide>
			<pose frame="">-0.7145582939959024 -0.2823561982379167 0.021901552763436378 0.0 -0.0 0.0</pose>
			<inertial>
				<pose frame="">0.0 0.0 0.0 0 0 0</pose>
				<mass>0.03033728342102297</mass>
				<inertia>
					<ixx>0.0024348303424036287</ixx>
					<ixy>-0.006120978351049311</ixy>
					<ixz>0.0004744830423066903</ixz>
					<iyy>0.015505947188096662</iyy>
					<iyz>0.00018749049346415797</iyz>
					<izz>0.017909805418616795</izz>
				</inertia>
			</inertial>
			<collision name="hand_right_ring_link2_collision">
				<geometry>
					<mesh>
						<uri>model://roboy_icecream/meshes/CAD/hand_right_ring_link2.stl</uri>
						<scale>0.001 0.001 0.001</scale>
					</mesh>
				</geometry>
			</collision>
			<visual name="hand_right_ring_link2_visual">
				<geometry>
					<mesh>
						<uri>model://roboy_icecream/meshes/CAD/hand_right_ring_link2.stl</uri>
						<scale>0.001 0.001 0.001</scale>
					</mesh>
				</geometry>
			</visual>
		</link>
		<link name="hand_right_little_link1">
			<self_collide>false</self_collide>
			<pose frame="">-0.6800062838702111 -0.23863653069141005 0.05043874765332246 0.0 -0.0 0.0</pose>
			<inertial>
				<pose frame="">0.0 0.0 0.0 0 0 0</pose>
				<mass>0.030813346429285935</mass>
				<inertia>
					<ixx>0.0018349944195851756</ixx>
					<ixy>-0.005000447327031727</ixy>
					<ixz>0.0010563992377378227</ixz>
					<iyy>0.014328621829065606</iyy>
					<iyz>0.00037075990454327873</iyz>
					<izz>0.016004634063737276</izz>
				</inertia>
			</inertial>
			<collision name="hand_right_little_link1_collision">
				<geometry>
					<mesh>
						<uri>model://roboy_icecream/meshes/CAD/hand_right_little_link1.stl</uri>
						<scale>0.001 0.001 0.001</scale>
					</mesh>
				</geometry>
			</collision>
			<visual name="hand_right_little_link1_visual">
				<geometry>
					<mesh>
						<uri>model://roboy_icecream/meshes/CAD/hand_right_little_link1.stl</uri>
						<scale>0.001 0.001 0.001</scale>
					</mesh>
				</geometry>
			</visual>
		</link>
		<link name="hand_right_little_link2">
			<self_collide>false</self_collide>
			<pose frame="">-0.6943135440346941 -0.24662541471060945 0.0312291888265279 0.0 -0.0 0.0</pose>
			<inertial>
				<pose frame="">0.0 0.0 0.0 0 0 0</pose>
				<mass>0.030337208280612718</mass>
				<inertia>
					<ixx>0.0018764648293865638</ixx>
					<ixy>-0.005194928827042238</ixy>
					<ixz>0.000657498957335279</ixz>
					<iyy>0.014655682643788385</iyy>
					<iyz>0.00023355113394838158</iyz>
					<izz>0.016471066301404092</izz>
				</inertia>
			</inertial>
			<collision name="hand_right_little_link2_collision">
				<geometry>
					<mesh>
						<uri>model://roboy_icecream/meshes/CAD/hand_right_little_link2.stl</uri>
						<scale>0.001 0.001 0.001</scale>
					</mesh>
				</geometry>
			</collision>
			<visual name="hand_right_little_link2_visual">
				<geometry>
					<mesh>
						<uri>model://roboy_icecream/meshes/CAD/hand_right_little_link2.stl</uri>
						<scale>0.001 0.001 0.001</scale>
					</mesh>
				</geometry>
			</visual>
		</link>
		<link name="hand_right_little_link0">
			<self_collide>false</self_collide>
			<pose frame="">-0.66564170183715 -0.23025251291160845 0.07042297982475552 0.0 -0.0 0.0</pose>
			<inertial>
				<pose frame="">0.0 0.0 0.0 0 0 0</pose>
				<mass>0.030813346429285876</mass>
				<inertia>
					<ixx>0.0017882861550421773</ixx>
					<ixy>-0.004722860186980029</ixy>
					<ixz>0.0014439635517168121</ixz>
					<iyy>0.013807434352765378</iyy>
					<iyz>0.0004995147137035542</iyz>
					<izz>0.01528788959684641</izz>
				</inertia>
			</inertial>
			<collision name="hand_right_little_link0_collision">
				<geometry>
					<mesh>
						<uri>model://roboy_icecream/meshes/CAD/hand_right_little_link0.stl</uri>
						<scale>0.001 0.001 0.001</scale>
					</mesh>
				</geometry>
			</collision>
			<visual name="hand_right_little_link0_visual">
				<geometry>
					<mesh>
						<uri>model://roboy_icecream/meshes/CAD/hand_right_little_link0.stl</uri>
						<scale>0.001 0.001 0.001</scale>
					</mesh>
				</geometry>
			</visual>
		</link>
		<link name="hand_right_thumb_link2">
			<self_collide>false</self_collide>
			<pose frame="">-0.6319474800748438 -0.3401002887489989 0.18239466537626342 0.0 -0.0 0.0</pose>
			<inertial>
				<pose frame="">0.0 0.0 0.0 0 0 0</pose>
				<mass>0.030336828875681794</mass>
				<inertia>
					<ixx>0.004519937375184502</ixx>
					<ixy>-0.006520211696922715</ixy>
					<ixz>0.0034969296296000225</ixz>
					<iyy>0.013125859123179363</iyy>
					<iyz>0.0018821883187037185</iyz>
					<izz>0.01562602226908504</izz>
				</inertia>
			</inertial>
			<collision name="hand_right_thumb_link2_collision">
				<geometry>
					<mesh>
						<uri>model://roboy_icecream/meshes/CAD/hand_right_thumb_link2.stl</uri>
						<scale>0.001 0.001 0.001</scale>
					</mesh>
				</geometry>
			</collision>
			<visual name="hand_right_thumb_link2_visual">
				<geometry>
					<mesh>
						<uri>model://roboy_icecream/meshes/CAD/hand_right_thumb_link2.stl</uri>
						<scale>0.001 0.001 0.001</scale>
					</mesh>
				</geometry>
			</visual>
		</link>
		<link name="hand_right_thumb_link0">
			<self_collide>false</self_collide>
			<pose frame="">-0.6224005433457507 -0.28241865731395566 0.15494231358361882 0.0 -0.0 0.0</pose>
			<inertial>
				<pose frame="">0.0 0.0 0.0 0 0 0</pose>
				<mass>0.11643028119503748</mass>
				<inertia>
					<ixx>0.01210558689434495</ixx>
					<ixy>-0.02046905681324226</ixy>
					<ixz>0.011227334393199851</ixz>
					<iyy>0.047911004901844335</iyy>
					<iyz>0.005099079962223717</iyz>
					<izz>0.05441055151567785</izz>
				</inertia>
			</inertial>
			<collision name="hand_right_thumb_link0_collision">
				<geometry>
					<mesh>
						<uri>model://roboy_icecream/meshes/CAD/hand_right_thumb_link0.stl</uri>
						<scale>0.001 0.001 0.001</scale>
					</mesh>
				</geometry>
			</collision>
			<visual name="hand_right_thumb_link0_visual">
				<geometry>
					<mesh>
						<uri>model://roboy_icecream/meshes/CAD/hand_right_thumb_link0.stl</uri>
						<scale>0.001 0.001 0.001</scale>
					</mesh>
				</geometry>
			</visual>
		</link>
		<link name="hand_right_thumb_link1">
			<self_collide>false</self_collide>
			<pose frame="">-0.631084547941073 -0.3193738347253496 0.16800860875366944 0.0 -0.0 0.0</pose>
			<inertial>
				<pose frame="">0.0 0.0 0.0 0 0 0</pose>
				<mass>0.030826015044524206</mass>
				<inertia>
					<ixx>0.004016344425998898</ixx>
					<ixy>-0.006212925977100383</ixy>
					<ixz>0.0032685219854530325</ixz>
					<iyy>0.013148491746803192</iyy>
					<iyz>0.0016545013256702252</iyz>
					<izz>0.015422923031666879</izz>
				</inertia>
			</inertial>
			<collision name="hand_right_thumb_link1_collision">
				<geometry>
					<mesh>
						<uri>model://roboy_icecream/meshes/CAD/hand_right_thumb_link1.stl</uri>
						<scale>0.001 0.001 0.001</scale>
					</mesh>
				</geometry>
			</collision>
			<visual name="hand_right_thumb_link1_visual">
				<geometry>
					<mesh>
						<uri>model://roboy_icecream/meshes/CAD/hand_right_thumb_link1.stl</uri>
						<scale>0.001 0.001 0.001</scale>
					</mesh>
				</geometry>
			</visual>
		</link>
		<link name="wrist_left_link1">
			<self_collide>false</self_collide>
			<pose frame="">0.5942108195309044 -0.2236565034089869 0.17010688138927252 0.0 -0.0 0.0</pose>
			<inertial>
				<pose frame="">0.0 0.0 0.0 0 0 0</pose>
				<mass>0.09036359201900472</mass>
				<inertia>
					<ixx>0.007142072740240583</ixx>
					<ixy>0.012009241334079995</ixy>
					<ixz>-0.009133893090562301</ixz>
					<iyy>0.03452804847042273</iyy>
					<iyz>0.003437928970663017</iyz>
					<izz>0.03643344436611846</izz>
				</inertia>
			</inertial>
			<collision name="wrist_left_link1_collision">
				<geometry>
					<mesh>
						<uri>model://roboy_icecream/meshes/CAD/wrist_left_link1.stl</uri>
						<scale>0.001 0.001 0.001</scale>
					</mesh>
				</geometry>
			</collision>
			<visual name="wrist_left_link1_visual">
				<geometry>
					<mesh>
						<uri>model://roboy_icecream/meshes/CAD/wrist_left_link1.stl</uri>
						<scale>0.001 0.001 0.001</scale>
					</mesh>
				</geometry>
			</visual>
		</link>
		<link name="wrist_left_link2">
			<self_collide>false</self_collide>
			<pose frame="">0.5942108146699845 -0.2236565036439179 0.1701068809585281 0.0 -0.0 0.0</pose>
			<inertial>
				<pose frame="">0.0 0.0 0.0 0 0 0</pose>
				<mass>0.007113170038864663</mass>
				<inertia>
					<ixx>0.0005617483559744007</ixx>
					<ixy>0.0009453339904655011</ixy>
					<ixz>-0.0007189945919846204</ixz>
					<iyy>0.0027174959746702906</iyy>
					<iyz>0.0002706241835602648</iyz>
					<izz>0.0028674834293350975</izz>
				</inertia>
			</inertial>
			<collision name="wrist_left_link2_collision">
				<geometry>
					<mesh>
						<uri>model://roboy_icecream/meshes/CAD/wrist_left_link2.stl</uri>
						<scale>0.001 0.001 0.001</scale>
					</mesh>
				</geometry>
			</collision>
			<visual name="wrist_left_link2_visual">
				<geometry>
					<mesh>
						<uri>model://roboy_icecream/meshes/CAD/wrist_left_link2.stl</uri>
						<scale>0.001 0.001 0.001</scale>
					</mesh>
				</geometry>
			</visual>
		</link>
		<link name="wrist_right_link1">
			<self_collide>false</self_collide>
			<pose frame="">-0.5930141691416991 -0.22290788054060323 0.17360819765512767 0.0 -0.0 0.0</pose>
			<inertial>
				<pose frame="">0.0 0.0 0.0 0 0 0</pose>
				<mass>0.09036366567875653</mass>
				<inertia>
					<ixx>0.007220617854987555</ixx>
					<ixy>-0.011944949910045135</ixy>
					<ixz>0.009303131050973029</ixz>
					<iyy>0.03450844618993165</iyy>
					<iyz>0.0034969505500438724</iyz>
					<izz>0.036274885691354085</izz>
				</inertia>
			</inertial>
			<collision name="wrist_right_link1_collision">
				<geometry>
					<mesh>
						<uri>model://roboy_icecream/meshes/CAD/wrist_right_link1.stl</uri>
						<scale>0.001 0.001 0.001</scale>
					</mesh>
				</geometry>
			</collision>
			<visual name="wrist_right_link1_visual">
				<geometry>
					<mesh>
						<uri>model://roboy_icecream/meshes/CAD/wrist_right_link1.stl</uri>
						<scale>0.001 0.001 0.001</scale>
					</mesh>
				</geometry>
			</visual>
		</link>
		<link name="wrist_right_link2">
			<self_collide>false</self_collide>
			<pose frame="">-0.5930141687984242 -0.22290788055249702 0.1736081976548898 0.0 -0.0 0.0</pose>
			<inertial>
				<pose frame="">0.0 0.0 0.0 0 0 0</pose>
				<mass>0.0071131715008991465</mass>
				<inertia>
					<ixx>0.0005679308626288725</ixx>
					<ixy>-0.0009402725818693869</ixy>
					<ixz>0.0007323160932599408</ixz>
					<iyy>0.0027159513209551807</iyy>
					<iyz>0.00027527003034989196</iyz>
					<izz>0.0028550004291226926</izz>
				</inertia>
			</inertial>
			<collision name="wrist_right_link2_collision">
				<geometry>
					<mesh>
						<uri>model://roboy_icecream/meshes/CAD/wrist_right_link2.stl</uri>
						<scale>0.001 0.001 0.001</scale>
					</mesh>
				</geometry>
			</collision>
			<visual name="wrist_right_link2_visual">
				<geometry>
					<mesh>
						<uri>model://roboy_icecream/meshes/CAD/wrist_right_link2.stl</uri>
						<scale>0.001 0.001 0.001</scale>
					</mesh>
				</geometry>
			</visual>
		</link>
		<link name="zed_camera_left_lense">
			<self_collide>false</self_collide>
			<pose frame="">0.060224029002958875 -0.06914536611449576 0.9247742812708074 0.0 -0.0 0.0</pose>
			<inertial>
				<pose frame="">0.0 0.0 0.0 0 0 0</pose>
				<mass>0.005755421856391889</mass>
				<inertia>
					<ixx>0.004949985508986997</ixx>
					<ixy>2.3967379469334992e-05</ixy>
					<ixz>-0.00032054048486266214</ixz>
					<iyy>0.004943160949602587</iyy>
					<iyz>0.00036806516895399434</iyz>
					<izz>4.8783846074335874e-05</izz>
				</inertia>
			</inertial>
			<collision name="zed_camera_left_lense_collision">
				<geometry>
					<mesh>
						<uri>model://roboy_icecream/meshes/CAD/zed_camera_left_lense.stl</uri>
						<scale>0.001 0.001 0.001</scale>
					</mesh>
				</geometry>
			</collision>
			<visual name="zed_camera_left_lense_visual">
				<geometry>
					<mesh>
						<uri>model://roboy_icecream/meshes/CAD/zed_camera_left_lense.stl</uri>
						<scale>0.001 0.001 0.001</scale>
					</mesh>
				</geometry>
			</visual>
		</link>
		<link name="zed_camera_right_lense">
			<self_collide>false</self_collide>
			<pose frame="">-0.05977745584801775 -0.06952236314727905 0.924774281233249 0.0 -0.0 0.0</pose>
			<inertial>
				<pose frame="">0.0 0.0 0.0 0 0 0</pose>
				<mass>0.005755421855125979</mass>
				<inertia>
					<ixx>0.004950286385593239</ixx>
					<ixy>-2.3918213389687756e-05</ixy>
					<ixz>0.00031816335310091417</ixz>
					<iyy>0.004942852518457872</iyy>
					<iyz>0.00037007172279470996</iyz>
					<izz>4.877629449989437e-05</izz>
				</inertia>
			</inertial>
			<collision name="zed_camera_right_lense_collision">
				<geometry>
					<mesh>
						<uri>model://roboy_icecream/meshes/CAD/zed_camera_right_lense.stl</uri>
						<scale>0.001 0.001 0.001</scale>
					</mesh>
				</geometry>
			</collision>
			<visual name="zed_camera_right_lense_visual">
				<geometry>
					<mesh>
						<uri>model://roboy_icecream/meshes/CAD/zed_camera_right_lense.stl</uri>
						<scale>0.001 0.001 0.001</scale>
					</mesh>
				</geometry>
			</visual>
		</link>
		<link name="zed_camera">
			<self_collide>false</self_collide>
			<pose frame="">0.0042444847902519045 -0.057938621286605034 0.9221942136470952 0.0 -0.0 0.0</pose>
			<inertial>
				<pose frame="">0.0 0.0 0.0 0 0 0</pose>
				<mass>0.009633907989226696</mass>
				<inertia>
					<ixx>0.008225718793064217</ixx>
					<ixy>2.436533895216616e-06</ixy>
					<ixz>-3.772847951396886e-05</ixz>
					<iyy>0.008208224332339191</iyy>
					<iyz>0.0005146961428966748</iyz>
					<izz>4.725323656366557e-05</izz>
				</inertia>
			</inertial>
			<collision name="zed_camera_collision">
				<geometry>
					<mesh>
						<uri>model://roboy_icecream/meshes/CAD/zed_camera.stl</uri>
						<scale>0.001 0.001 0.001</scale>
					</mesh>
				</geometry>
			</collision>
			<visual name="zed_camera_visual">
				<geometry>
					<mesh>
						<uri>model://roboy_icecream/meshes/CAD/zed_camera.stl</uri>
						<scale>0.001 0.001 0.001</scale>
					</mesh>
				</geometry>
			</visual>
		</link>
		<link name="neck_link1">
			<self_collide>false</self_collide>
			<pose frame="">-1.506123290725299e-10 0.0015217809344427139 0.7106779292283452 0.0 -0.0 0.0</pose>
			<inertial>
				<pose frame="">0.0 0.0 0.0 0 0 0</pose>
				<mass>0.017038665636260365</mass>
				<inertia>
					<ixx>0.008606751840759286</ixx>
					<ixy>3.905246557991266e-15</ixy>
					<ixz>1.8237653762187555e-12</ixz>
					<iyy>0.008606712382324128</iyy>
					<iyz>-1.8427250830609723e-05</iyz>
					<izz>1.1502292854573858e-06</izz>
				</inertia>
			</inertial>
			<collision name="neck_link1_collision">
				<geometry>
					<mesh>
						<uri>model://roboy_icecream/meshes/CAD/neck_link1.stl</uri>
						<scale>0.001 0.001 0.001</scale>
					</mesh>
				</geometry>
			</collision>
			<visual name="neck_link1_visual">
				<geometry>
					<mesh>
						<uri>model://roboy_icecream/meshes/CAD/neck_link1.stl</uri>
						<scale>0.001 0.001 0.001</scale>
					</mesh>
				</geometry>
			</visual>
		</link>
		<link name="neck_link2">
			<self_collide>false</self_collide>
			<pose frame="">-1.2765957595970417e-10 0.0015217809573941916 0.7106779292283448 0.0 -0.0 0.0</pose>
			<inertial>
				<pose frame="">0.0 0.0 0.0 0 0 0</pose>
				<mass>0.011421521917888835</mass>
				<inertia>
					<ixx>0.005769117704166386</ixx>
					<ixy>2.2188573474781793e-15</ixy>
					<ixz>1.0362156174781311e-12</ixz>
					<iyy>0.005769091254008538</iyy>
					<iyz>-1.2352331861868672e-05</iyz>
					<izz>5.282195127138846e-07</izz>
				</inertia>
			</inertial>
			<collision name="neck_link2_collision">
				<geometry>
					<mesh>
						<uri>model://roboy_icecream/meshes/CAD/neck_link2.stl</uri>
						<scale>0.001 0.001 0.001</scale>
					</mesh>
				</geometry>
			</collision>
			<visual name="neck_link2_visual">
				<geometry>
					<mesh>
						<uri>model://roboy_icecream/meshes/CAD/neck_link2.stl</uri>
						<scale>0.001 0.001 0.001</scale>
					</mesh>
				</geometry>
			</visual>
		</link>
		<joint name="elbow_left" type="revolute">
			<parent>arm_left_upper</parent>
			<child>arm_left_lower</child>
			<pose frame="">-0.07662424485700015 0.05077723036548429 0.10119287135500188 0 0 0</pose>
			<axis>
				<xyz>0.04893226875181594 -0.8266587526531017 0.5605719755185943</xyz>
				<limit>
					<lower>0.0</lower>
					<upper>0.0</upper>
				</limit>
				<use_parent_model_frame>0</use_parent_model_frame>
			</axis>
		</joint>
		<joint name="shoulder_left_axis0" type="revolute">
			<parent>torso</parent>
			<child>shoulder_left_link1</child>
			<pose frame="">-4.860963365160842e-09 -1.5044763213012403e-10 5.4201620969251966e-12 0 0 0</pose>
			<axis>
				<xyz>0.8239514135922348 0.35063605629465305 0.445149889436685</xyz>
				<limit>
					<lower>-3.141592653589793</lower>
					<upper>3.141592653589793</upper>
				</limit>
				<use_parent_model_frame>0</use_parent_model_frame>
			</axis>
		</joint>
		<joint name="shoulder_left_axis1" type="revolute">
			<parent>shoulder_left_link1</parent>
			<child>shoulder_left_link2</child>
			<pose frame="">-6.320277634586091e-14 8.447477384265767e-11 4.3615351330572595e-10 0 0 0</pose>
			<axis>
				<xyz>0.048932268751815826 -0.8266587526531001 0.5605719755185947</xyz>
				<limit>
					<lower>-3.141592653589793</lower>
					<upper>3.141592653589793</upper>
				</limit>
				<use_parent_model_frame>0</use_parent_model_frame>
			</axis>
		</joint>
		<joint name="shoulder_left_axis2" type="revolute">
			<parent>shoulder_left_link2</parent>
			<child>arm_left_upper</child>
			<pose frame="">-0.10518243552818823 0.08249944390425343 0.12863918438133654 0 0 0</pose>
			<axis>
				<xyz>0.564543799110472 -0.4401018776240088 -0.6982840655476376</xyz>
				<limit>
					<lower>-3.141592653589793</lower>
					<upper>3.141592653589793</upper>
				</limit>
				<use_parent_model_frame>0</use_parent_model_frame>
			</axis>
		</joint>
		<joint name="hand_left_middle_joint0" type="revolute">
			<parent>arm_left_palm</parent>
			<child>hand_left_middle_link0</child>
			<pose frame="">-0.011438517559809186 0.013416445692411755 0.01594441090851702 0 0 0</pose>
			<axis>
				<xyz>-0.0979493008211963 0.8618704725531149 -0.4975793635287829</xyz>
				<limit>
					<lower>0.0</lower>
					<upper>0.0</upper>
				</limit>
				<use_parent_model_frame>0</use_parent_model_frame>
			</axis>
		</joint>
		<joint name="hand_left_iring_joint0" type="revolute">
			<parent>arm_left_palm</parent>
			<child>hand_left_ring_link0</child>
			<pose frame="">-0.011353534171067423 0.01495624331070406 0.01457494996804705 0 0 0</pose>
			<axis>
				<xyz>0.0489322701867574 -0.8266587537717556 0.5605719737436912</xyz>
				<limit>
					<lower>0.0</lower>
					<upper>0.0</upper>
				</limit>
				<use_parent_model_frame>0</use_parent_model_frame>
			</axis>
		</joint>
		<joint name="hand_left_little_joint0" type="revolute">
			<parent>arm_left_palm</parent>
			<child>hand_left_index_link0</child>
			<pose frame="">-0.011167490912478968 0.016388848422477908 0.013102491155630443 0 0 0</pose>
			<axis>
				<xyz>0.00045716742891926314 0.7851556604951944 -0.6192982962920992</xyz>
				<limit>
					<lower>0.0</lower>
					<upper>0.0</upper>
				</limit>
				<use_parent_model_frame>0</use_parent_model_frame>
			</axis>
		</joint>
		<joint name="hand_left_index_joint0" type="revolute">
			<parent>arm_left_palm</parent>
			<child>hand_left_little_link0</child>
			<pose frame="">-0.007340793876031455 0.008166978172304162 0.009102988697151674 0 0 0</pose>
			<axis>
				<xyz>-0.12702537302227587 0.8798641087300467 -0.45793417079011645</xyz>
				<limit>
					<lower>0.0</lower>
					<upper>0.0</upper>
				</limit>
				<use_parent_model_frame>0</use_parent_model_frame>
			</axis>
		</joint>
		<joint name="hand_left_thumb_joint0" type="revolute">
			<parent>arm_left_palm</parent>
			<child>hand_left_thumb_link0</child>
			<pose frame="">0.0001101181978571475 0.015071155644260693 -0.011991445427988285 0 0 0</pose>
			<axis>
				<xyz>-0.5645437991104691 0.4401018776240249 0.6982840655476247</xyz>
				<limit>
					<lower>0.0</lower>
					<upper>0.0</upper>
				</limit>
				<use_parent_model_frame>0</use_parent_model_frame>
			</axis>
		</joint>
		<joint name="hand_left_index_joint1" type="revolute">
			<parent>hand_left_index_link0</parent>
			<child>hand_left_index_link1</child>
			<pose frame="">-0.006374938536653474 0.011296249392186972 0.006647179030050996 0 0 0</pose>
			<axis>
				<xyz>-0.00045716742892075446 -0.7851556604951987 0.619298296292098</xyz>
				<limit>
					<lower>0.0</lower>
					<upper>0.0</upper>
				</limit>
				<use_parent_model_frame>0</use_parent_model_frame>
			</axis>
		</joint>
		<joint name="hand_left_index_joint2" type="revolute">
			<parent>hand_left_index_link1</parent>
			<child>hand_left_index_link2</child>
			<pose frame="">-0.006307101975253602 0.010760099567161561 0.005963259636935137 0 0 0</pose>
			<axis>
				<xyz>-0.00045716742892005363 -0.785155660495197 0.6192982962920985</xyz>
				<limit>
					<lower>0.0</lower>
					<upper>0.0</upper>
				</limit>
				<use_parent_model_frame>0</use_parent_model_frame>
			</axis>
		</joint>
		<joint name="hand_left_middle_joint1" type="revolute">
			<parent>hand_left_middle_link0</parent>
			<child>hand_left_middle_link1</child>
			<pose frame="">-0.006725562081695244 0.009689852027568833 0.008561881375150557 0 0 0</pose>
			<axis>
				<xyz>0.09794930082119462 -0.8618704725531147 0.49757936352878035</xyz>
				<limit>
					<lower>0.0</lower>
					<upper>0.0</upper>
				</limit>
				<use_parent_model_frame>0</use_parent_model_frame>
			</axis>
		</joint>
		<joint name="hand_left_middle_joint2" type="revolute">
			<parent>hand_left_middle_link1</parent>
			<child>hand_left_middle_link2</child>
			<pose frame="">-0.0066635501534133825 0.009261958069227276 0.007804274436405163 0 0 0</pose>
			<axis>
				<xyz>0.09794930082119535 -0.8618704725531143 0.49757936352878024</xyz>
				<limit>
					<lower>0.0</lower>
					<upper>0.0</upper>
				</limit>
				<use_parent_model_frame>0</use_parent_model_frame>
			</axis>
		</joint>
		<joint name="hand_left_ring_joint1" type="revolute">
			<parent>hand_left_ring_link0</parent>
			<child>hand_left_ring_link1</child>
			<pose frame="">-0.006580487917874223 0.010530963644602665 0.007630699202666493 0 0 0</pose>
			<axis>
				<xyz>0.048932270186756735 -0.8266587537717577 0.5605719737436896</xyz>
				<limit>
					<lower>0.0</lower>
					<upper>0.0</upper>
				</limit>
				<use_parent_model_frame>0</use_parent_model_frame>
			</axis>
		</joint>
		<joint name="hand_left_ring_joint2" type="revolute">
			<parent>hand_left_ring_link1</parent>
			<child>hand_left_ring_link2</child>
			<pose frame="">-0.00651399095552705 0.010047506859281548 0.006907939478808287 0 0 0</pose>
			<axis>
				<xyz>0.04893227018675697 -0.8266587537717556 0.5605719737436894</xyz>
				<limit>
					<lower>0.0</lower>
					<upper>0.0</upper>
				</limit>
				<use_parent_model_frame>0</use_parent_model_frame>
			</axis>
		</joint>
		<joint name="hand_left_thumb_joint1" type="revolute">
			<parent>hand_left_thumb_link0</parent>
			<child>hand_left_thumb_link1</child>
			<pose frame="">-0.00554731969662079 0.010385447221051898 -0.008626954865342177 0 0 0</pose>
			<axis>
				<xyz>0.8239514135922791 0.35063605629459854 0.44514988943663386</xyz>
				<limit>
					<lower>0.0</lower>
					<upper>0.0</upper>
				</limit>
				<use_parent_model_frame>0</use_parent_model_frame>
			</axis>
		</joint>
		<joint name="hand_left_thumb_joint2" type="revolute">
			<parent>hand_left_thumb_link1</parent>
			<child>hand_left_thumb_link2</child>
			<pose frame="">-0.005406062853686535 0.009489153951051392 -0.008586137613613936 0 0 0</pose>
			<axis>
				<xyz>-0.8239514135922789 -0.350636056294598 -0.4451498894366351</xyz>
				<limit>
					<lower>0.0</lower>
					<upper>0.0</upper>
				</limit>
				<use_parent_model_frame>0</use_parent_model_frame>
			</axis>
		</joint>
		<joint name="elbow_right" type="revolute">
			<parent>arm_right_upper</parent>
			<child>arm_right_lower</child>
			<pose frame="">0.07652201430481136 0.050697392060166 0.1010665595873241 0 0 0</pose>
			<axis>
				<xyz>0.0489322687518245 0.8266587526531025 -0.5605719755185898</xyz>
				<limit>
					<lower>0.0</lower>
					<upper>0.0</upper>
				</limit>
				<use_parent_model_frame>0</use_parent_model_frame>
			</axis>
		</joint>
		<joint name="hand_left_little_joint1" type="revolute">
			<parent>hand_left_little_link0</parent>
			<child>hand_left_little_link1</child>
			<pose frame="">-0.006783253127031656 0.00915137835256651 0.00909276138854513 0 0 0</pose>
			<axis>
				<xyz>0.12702537302227537 -0.8798641087300457 0.45793417079011445</xyz>
				<limit>
					<lower>0.0</lower>
					<upper>0.0</upper>
				</limit>
				<use_parent_model_frame>0</use_parent_model_frame>
			</axis>
		</joint>
		<joint name="hand_left_little_joint2" type="revolute">
			<parent>hand_left_little_link1</parent>
			<child>hand_left_little_link2</child>
			<pose frame="">-0.00672528467667604 0.008758020728807842 0.0083159938394166 0 0 0</pose>
			<axis>
				<xyz>0.12702537302227657 -0.8798641087300475 0.4579341707901138</xyz>
				<limit>
					<lower>0.0</lower>
					<upper>0.0</upper>
				</limit>
				<use_parent_model_frame>0</use_parent_model_frame>
			</axis>
		</joint>
		<joint name="shoulder_right_axis0" type="revolute">
			<parent>torso</parent>
			<child>shoulder_right_link1</child>
			<pose frame="">1.376389491269947e-10 -7.152252567976802e-11 -2.2659207843389595e-13 0 0 0</pose>
			<axis>
				<xyz>-0.8239514135922378 0.3506360562946562 0.44514988943668027</xyz>
				<limit>
					<lower>-3.141592653589793</lower>
					<upper>3.141592653589793</upper>
				</limit>
				<use_parent_model_frame>0</use_parent_model_frame>
			</axis>
		</joint>
		<joint name="shoulder_right_axis1" type="revolute">
			<parent>shoulder_right_link1</parent>
			<child>shoulder_right_link2</child>
			<pose frame="">6.320277634586091e-14 -1.6520109724638134e-11 -4.3078784983663355e-11 0 0 0</pose>
			<axis>
				<xyz>0.048932268751817644 0.8266587526530976 -0.5605719755186003</xyz>
				<limit>
					<lower>-3.141592653589793</lower>
					<upper>3.141592653589793</upper>
				</limit>
				<use_parent_model_frame>0</use_parent_model_frame>
			</axis>
		</joint>
		<joint name="shoulder_right_axis2" type="revolute">
			<parent>shoulder_right_link2</parent>
			<child>arm_right_upper</child>
			<pose frame="">0.10561794673146878 0.08089281862106404 0.13071223994770315 0 0 0</pose>
			<axis>
				<xyz>-0.5645437991104694 -0.44010187762401454 -0.6982840655476372</xyz>
				<limit>
					<lower>-3.141592653589793</lower>
					<upper>3.141592653589793</upper>
				</limit>
				<use_parent_model_frame>0</use_parent_model_frame>
			</axis>
		</joint>
		<joint name="hand_right_index_joint1" type="revolute">
			<parent>hand_right_index_link0</parent>
			<child>hand_right_index_link1</child>
			<pose frame="">0.0063792690939499155 0.003837473434017511 0.012530339934104191 0 0 0</pose>
			<axis>
				<xyz>-0.00045716598854398055 0.7851556617927069 -0.6192982946481638</xyz>
				<limit>
					<lower>0.0</lower>
					<upper>0.0</upper>
				</limit>
				<use_parent_model_frame>0</use_parent_model_frame>
			</axis>
		</joint>
		<joint name="hand_right_index_joint2" type="revolute">
			<parent>hand_right_index_link1</parent>
			<child>hand_right_index_link2</child>
			<pose frame="">0.006311446995120776 0.0032990692992627404 0.011848214462026885 0 0 0</pose>
			<axis>
				<xyz>-0.00045716598854382594 0.7851556617927035 -0.6192982946481611</xyz>
				<limit>
					<lower>0.0</lower>
					<upper>0.0</upper>
				</limit>
				<use_parent_model_frame>0</use_parent_model_frame>
			</axis>
		</joint>
		<joint name="hand_right_index_joint0" type="revolute">
			<parent>arm_right_palm</parent>
			<child>hand_right_index_link0</child>
			<pose frame="">0.01117192925368002 0.008775224250435585 0.019107804325018202 0 0 0</pose>
			<axis>
				<xyz>-0.0004571659885751067 0.7851556617927038 -0.6192982946481608</xyz>
				<limit>
					<lower>0.0</lower>
					<upper>0.0</upper>
				</limit>
				<use_parent_model_frame>0</use_parent_model_frame>
			</axis>
		</joint>
		<joint name="hand_right_middle_joint0" type="revolute">
			<parent>arm_right_palm</parent>
			<child>hand_right_middle_link0</child>
			<pose frame="">0.01087860858436386 0.0069399342818095636 0.020010628638068174 0 0 0</pose>
			<axis>
				<xyz>0.04893227162172353 0.8266587548903909 -0.5605719719688155</xyz>
				<limit>
					<lower>0.0</lower>
					<upper>0.0</upper>
				</limit>
				<use_parent_model_frame>0</use_parent_model_frame>
			</axis>
		</joint>
		<joint name="hand_right_ring_joint0" type="revolute">
			<parent>arm_right_palm</parent>
			<child>hand_right_ring_link0</child>
			<pose frame="">0.010486676479475961 0.005056535598436938 0.020770580463448134 0 0 0</pose>
			<axis>
				<xyz>0.09794930223986344 0.8618704734843625 -0.4975793616364777</xyz>
				<limit>
					<lower>0.0</lower>
					<upper>0.0</upper>
				</limit>
				<use_parent_model_frame>0</use_parent_model_frame>
			</axis>
		</joint>
		<joint name="hand_right_little_joint0" type="revolute">
			<parent>arm_right_palm</parent>
			<child>hand_right_little_link0</child>
			<pose frame="">0.005551542562498639 0.0006167073850018667 0.013533833531439984 0 0 0</pose>
			<axis>
				<xyz>0.1270253744259695 0.8798641095453661 -0.45793416883421406</xyz>
				<limit>
					<lower>0.0</lower>
					<upper>0.0</upper>
				</limit>
				<use_parent_model_frame>0</use_parent_model_frame>
			</axis>
		</joint>
		<joint name="hand_right_thumb_joint0" type="revolute">
			<parent>arm_right_palm</parent>
			<child>hand_right_thumb_link0</child>
			<pose frame="">0.005031812731215268 0.019005814896677364 -0.00574044699901119 0 0 0</pose>
			<axis>
				<xyz>0.5645437991104543 0.44010187762403535 0.6982840655476352</xyz>
				<limit>
					<lower>0.0</lower>
					<upper>0.0</upper>
				</limit>
				<use_parent_model_frame>0</use_parent_model_frame>
			</axis>
		</joint>
		<joint name="hand_right_middle_joint1" type="revolute">
			<parent>hand_right_middle_link0</parent>
			<child>hand_right_middle_link1</child>
			<pose frame="">0.006115877511387424 0.0026777820575878053 0.012955862849985325 0 0 0</pose>
			<axis>
				<xyz>0.04893227162175166 0.8266587548903906 -0.5605719719688135</xyz>
				<limit>
					<lower>0.0</lower>
					<upper>0.0</upper>
				</limit>
				<use_parent_model_frame>0</use_parent_model_frame>
			</axis>
		</joint>
		<joint name="hand_right_middle_joint2" type="revolute">
			<parent>hand_right_middle_link1</parent>
			<child>hand_right_middle_link2</child>
			<pose frame="">0.006049662313745472 0.0021925428728843243 0.01223492426263947 0 0 0</pose>
			<axis>
				<xyz>0.04893227162175153 0.8266587548903906 -0.5605719719688134</xyz>
				<limit>
					<lower>0.0</lower>
					<upper>0.0</upper>
				</limit>
				<use_parent_model_frame>0</use_parent_model_frame>
			</axis>
		</joint>
		<joint name="hand_right_ring_joint1" type="revolute">
			<parent>hand_right_ring_link0</parent>
			<child>hand_right_ring_link1</child>
			<pose frame="">0.0057955161070019304 0.001502076667997443 0.013288448291203948 0 0 0</pose>
			<axis>
				<xyz>0.09794930223988853 0.8618704734843623 -0.49757936163647326</xyz>
				<limit>
					<lower>0.0</lower>
					<upper>0.0</upper>
				</limit>
				<use_parent_model_frame>0</use_parent_model_frame>
			</axis>
		</joint>
		<joint name="hand_right_ring_joint2" type="revolute">
			<parent>hand_right_ring_link1</parent>
			<child>hand_right_ring_link2</child>
			<pose frame="">0.005733973759371054 0.0010725375733973053 0.012532659113392346 0 0 0</pose>
			<axis>
				<xyz>0.09794930223988832 0.8618704734843624 -0.49757936163647326</xyz>
				<limit>
					<lower>0.0</lower>
					<upper>0.0</upper>
				</limit>
				<use_parent_model_frame>0</use_parent_model_frame>
			</axis>
		</joint>
		<joint name="hand_right_little_joint1" type="revolute">
			<parent>hand_right_little_link0</parent>
			<child>hand_right_little_link1</child>
			<pose frame="">0.005576947707485829 0.0007926802478293738 0.013442246795170362 0 0 0</pose>
			<axis>
				<xyz>0.12702537442599268 0.8798641095453661 -0.4579341688342081</xyz>
				<limit>
					<lower>0.0</lower>
					<upper>0.0</upper>
				</limit>
				<use_parent_model_frame>0</use_parent_model_frame>
			</axis>
		</joint>
		<joint name="hand_right_little_joint2" type="revolute">
			<parent>hand_right_little_link1</parent>
			<child>hand_right_little_link2</child>
			<pose frame="">0.005519625909013257 0.00039754652814465884 0.012667573548061806 0 0 0</pose>
			<axis>
				<xyz>0.12702537442599218 0.879864109545366 -0.4579341688342089</xyz>
				<limit>
					<lower>0.0</lower>
					<upper>0.0</upper>
				</limit>
				<use_parent_model_frame>0</use_parent_model_frame>
			</axis>
		</joint>
		<joint name="hand_right_thumb_joint1" type="revolute">
			<parent>hand_right_thumb_link0</parent>
			<child>hand_right_thumb_link1</child>
			<pose frame="">-0.002302619110570774 0.013706582362097883 -0.0043902355700346975 0 0 0</pose>
			<axis>
				<xyz>0.8239514135922902 -0.35063605629463146 -0.4451498894365984</xyz>
				<limit>
					<lower>0.0</lower>
					<upper>0.0</upper>
				</limit>
				<use_parent_model_frame>0</use_parent_model_frame>
			</axis>
		</joint>
		<joint name="hand_right_thumb_joint2" type="revolute">
			<parent>hand_right_thumb_link1</parent>
			<child>hand_right_thumb_link2</child>
			<pose frame="">-0.0027531235350269157 0.012957440619581888 -0.004179163334673142 0 0 0</pose>
			<axis>
				<xyz>-0.8239514135922904 0.35063605629463146 0.4451498894365986</xyz>
				<limit>
					<lower>0.0</lower>
					<upper>0.0</upper>
				</limit>
				<use_parent_model_frame>0</use_parent_model_frame>
			</axis>
		</joint>
		<joint name="wrist_left_axis0" type="revolute">
			<parent>arm_left_lower</parent>
			<child>wrist_left_link1</child>
			<pose frame="">-4.860946916096509e-09 -1.5044435031086323e-10 5.400764280238946e-12 0 0 0</pose>
			<axis>
				<xyz>0.8239514135922501 0.35063605629463523 0.44514988943665923</xyz>
				<limit>
					<lower>-3.141592653589793</lower>
					<upper>3.141592653589793</upper>
				</limit>
				<use_parent_model_frame>0</use_parent_model_frame>
			</axis>
		</joint>
		<joint name="wrist_left_axis1" type="revolute">
			<parent>wrist_left_link1</parent>
			<child>wrist_left_link2</child>
			<pose frame="">-6.338041202980094e-14 8.447464949767891e-11 4.3615344225145236e-10 0 0 0</pose>
			<axis>
				<xyz>0.04893226875178856 -0.8266587526530951 0.5605719755186038</xyz>
				<limit>
					<lower>-3.141592653589793</lower>
					<upper>3.141592653589793</upper>
				</limit>
				<use_parent_model_frame>0</use_parent_model_frame>
			</axis>
		</joint>
		<joint name="wrist_left_axis2" type="revolute">
			<parent>wrist_left_link2</parent>
			<child>arm_left_palm</child>
			<pose frame="">-0.04081485322699806 0.020456459147667694 0.03447924516219771 0 0 0</pose>
			<axis>
				<xyz>0.5645437991104696 -0.4401018776240264 -0.6982840655476245</xyz>
				<limit>
					<lower>-3.141592653589793</lower>
					<upper>3.141592653589793</upper>
				</limit>
				<use_parent_model_frame>0</use_parent_model_frame>
			</axis>
		</joint>
		<joint name="wrist_right_axis0" type="revolute">
			<parent>arm_right_lower</parent>
			<child>wrist_right_link1</child>
			<pose frame="">1.3766005224624678e-10 -7.151093939228304e-11 -2.517452912798035e-13 0 0 0</pose>
			<axis>
				<xyz>0.048932268751824375 0.8266587526531017 -0.5605719755185931</xyz>
				<limit>
					<lower>-3.141592653589793</lower>
					<upper>3.141592653589793</upper>
				</limit>
				<use_parent_model_frame>0</use_parent_model_frame>
			</axis>
		</joint>
		<joint name="wrist_right_axis1" type="revolute">
			<parent>wrist_right_link1</parent>
			<child>wrist_right_link2</child>
			<pose frame="">-2.056162173857956e-10 -5.96373794792271e-11 0.0 0 0 0</pose>
			<axis>
				<xyz>0.8239514135922914 -0.3506360562946118 -0.44514988943660905</xyz>
				<limit>
					<lower>-3.141592653589793</lower>
					<upper>3.141592653589793</upper>
				</limit>
				<use_parent_model_frame>0</use_parent_model_frame>
			</axis>
		</joint>
		<joint name="wrist_right_axis2" type="revolute">
			<parent>wrist_right_link2</parent>
			<child>arm_right_palm</child>
			<pose frame="">0.043503952212279914 0.022552801597856133 0.037805384314345325 0 0 0</pose>
			<axis>
				<xyz>-0.5645437991104563 -0.4401018776240779 -0.6982840655476061</xyz>
				<limit>
					<lower>-3.141592653589793</lower>
					<upper>3.141592653589793</upper>
				</limit>
				<use_parent_model_frame>0</use_parent_model_frame>
			</axis>
		</joint>
		<joint name="zed_camera_mount" type="fixed">
			<parent>head</parent>
			<child>zed_camera</child>
			<pose frame="">0.017437654685091123 0.001405588958414743 0.008052233827783938 0 0 0</pose>
		</joint>
		<joint name="zed_camera_right" type="fixed">
			<parent>zed_camera</parent>
			<child>zed_camera_right_lense</child>
			<pose frame="">-3.477806617303791e-05 0.011070006217811663 -0.002353014092106349 0 0 0</pose>
		</joint>
		<joint name="zed_camera_left" type="fixed">
			<parent>zed_camera</parent>
			<child>zed_camera_left_lense</child>
			<pose frame="">-5.4665509118771995e-05 0.011069943702269302 -0.002353014260490625 0 0 0</pose>
		</joint>
		<joint name="neck_axis0" type="revolute">
			<parent>torso</parent>
			<child>neck_link1</child>
			<pose frame="">1.5061504134737904e-10 1.506148417096398e-10 0.0 0 0 0</pose>
			<axis>
				<xyz>0.12498691257369461 -0.9921583904222635 6.724690979212185e-15</xyz>
				<limit>
					<lower>-0.5235987755982988</lower>
					<upper>0.5235987755982988</upper>
				</limit>
				<use_parent_model_frame>0</use_parent_model_frame>
			</axis>
		</joint>
		<joint name="neck_axis2" type="revolute">
			<parent>neck_link2</parent>
			<child>head</child>
			<pose frame="">-0.0005102180295654335 -0.04492411714425427 -0.14549973319053336 0 0 0</pose>
			<axis>
				<xyz>-2.4972812708040394e-14 3.631896132047499e-15 1.0</xyz>
				<limit>
					<lower>-0.5235987755982988</lower>
					<upper>0.5235987755982988</upper>
				</limit>
				<use_parent_model_frame>0</use_parent_model_frame>
			</axis>
		</joint>
		<joint name="neck_axis1" type="revolute">
			<parent>neck_link1</parent>
			<child>neck_link2</child>
			<pose frame="">1.276622840242204e-10 1.2766342372128037e-10 2.842170943040401e-16 0 0 0</pose>
			<axis>
				<xyz>-0.9921583904222635 -0.12498691257369461 -2.432304617639304e-14</xyz>
				<limit>
					<lower>-0.5235987755982988</lower>
					<upper>0.5235987755982988</upper>
				</limit>
				<use_parent_model_frame>0</use_parent_model_frame>
			</axis>
		</joint>
		<plugin filename="libcardsflow_gazebo_plugin.so" name="cardsflow_gazebo_plugin"/>
	</model>
</sdf>
