<robot name="roboy_icecream">
  <joint name="spine" type="revolute">
    <parent link="torso" />
    <child link="bike_back" />
    <origin rpy="0 0 0" xyz="0.0000e+00 -2.0000e-05  2.9933e-01" />
    <axis xyz="0  0 -1" />
    <limit effort="0.0" lower="0.0" upper="0.0" velocity="0.0" />
  </joint>
  <joint name="zed_pico_attachement" type="revolute">
    <parent link="zed_mini" />
    <child link="pico_flexx" />
    <origin rpy="0 0 0" xyz="0.0576  -0.00665 -0.01668" />
    <axis xyz="0 0 0" />
    <limit effort="0" lower="0" upper="0" velocity="0" />
  </joint>
  <joint name="zed_mini_attachement" type="revolute">
    <parent link="torso" />
    <child link="zed_mini" />
    <origin rpy="0 0 0" xyz="0.00047 -0.10882  0.42356" />
    <axis xyz="0 0 0" />
    <limit effort="0" lower="0" upper="0" velocity="0" />
  </joint>
  <joint name="zed_camera_right" type="revolute">
    <parent link="zed_camera" />
    <child link="zed_camera_right_lense" />
    <origin rpy="0 0 0" xyz="-0.08149 -0.00191 -0.00782" />
    <axis xyz="0 0 0" />
    <limit effort="0" lower="0" upper="0" velocity="0" />
  </joint>
  <joint name="zed_camera_left" type="revolute">
    <parent link="zed_camera" />
    <child link="zed_camera_left_lense" />
    <origin rpy="0 0 0" xyz="0.03848 -0.00154 -0.00782" />
    <axis xyz="0 0 0" />
    <limit effort="0" lower="0" upper="0" velocity="0" />
  </joint>
  <joint name="neck_axis0" type="revolute">
    <parent link="torso" />
    <child link="neck_link1" />
    <origin rpy="0 0 0" xyz="0      0.00152 0.71567" />
    <axis xyz="0.12498 -0.99215  0" />
    <limit effort="0.0" lower="-0.523598775598" upper="0.523598775598" velocity="0.0" />
  </joint>
  <joint name="neck_axis2" type="revolute">
    <parent link="neck_link2" />
    <child link="head" />
    <origin rpy="0 0 0" xyz="0 0 0" />
    <axis xyz="0 0 1" />
    <limit effort="0.0" lower="-0.523598775598" upper="0.523598775598" velocity="0.0" />
  </joint>
  <joint name="neck_axis1" type="revolute">
    <parent link="neck_link1" />
    <child link="neck_link2" />
    <origin rpy="0 0 0" xyz="0 0 0" />
    <axis xyz="-0.99215 -0.12498  0" />
    <limit effort="0.0" lower="-0.523598775598" upper="0.523598775598" velocity="0.0" />
  </joint>
  <joint name="zed_camera_mount" type="revolute">
    <parent link="head" />
    <child link="zed_camera" />
    <origin rpy="0 0 0" xyz="0.02168 -0.05805  0.21956" />
    <axis xyz="0 0 0" />
    <limit effort="0" lower="0" upper="0" velocity="0" />
  </joint>
  <joint name="shoulder_right_axis0" type="revolute">
    <parent link="torso" />
    <child link="shoulder_right_link1" />
    <origin rpy="0 0 0" xyz="-0.29317  0.00923  0.5481" />
    <axis xyz="1 0 0" />
    <limit effort="0.0" lower="-3.14159265359" upper="3.14159265359" velocity="0.0" />
  </joint>
  <joint name="shoulder_right_axis1" type="revolute">
    <parent link="shoulder_right_link1" />
    <child link="shoulder_right_link2" />
    <origin rpy="0 0 0" xyz="0 0 0" />
    <axis xyz="0 1 0" />
    <limit effort="0.0" lower="-3.14159265359" upper="3.14159265359" velocity="0.0" />
  </joint>
  <joint name="shoulder_right_axis2" type="revolute">
    <parent link="shoulder_right_link2" />
    <child link="arm_right_upper" />
    <origin rpy="0 0 0" xyz="0 0 0" />
    <axis xyz="0 0 1" />
    <limit effort="0.0" lower="-3.14159265359" upper="3.14159265359" velocity="0.0" />
  </joint>
  <joint name="shoulder_left_axis0" type="revolute">
    <parent link="torso" />
    <child link="shoulder_left_link1" />
    <origin rpy="0 0 0" xyz="0.29189 0.01393 0.54489" />
    <axis xyz="1 0 0" />
    <limit effort="0.0" lower="-3.14159265359" upper="3.14159265359" velocity="0.0" />
  </joint>
  <joint name="shoulder_left_axis1" type="revolute">
    <parent link="shoulder_left_link1" />
    <child link="shoulder_left_link2" />
    <origin rpy="0 0 0" xyz="0 0 0" />
    <axis xyz="0 1 0" />
    <limit effort="0.0" lower="-3.14159265359" upper="3.14159265359" velocity="0.0" />
  </joint>
  <joint name="shoulder_left_axis2" type="revolute">
    <parent link="shoulder_left_link2" />
    <child link="arm_left_upper" />
    <origin rpy="0 0 0" xyz="0 0 0" />
    <axis xyz="0 0 1" />
    <limit effort="0.0" lower="-3.14159265359" upper="3.14159265359" velocity="0.0" />
  </joint>
  <joint name="bike_steering" type="revolute">
    <parent link="bike_back" />
    <child link="bike_front" />
    <origin rpy="0 0 0" xyz="-0.00193 -1.20232 -0.903" />
    <axis xyz="0 0 1" />
    <limit effort="0.0" lower="-0.523598775598" upper="0.523598775598" velocity="0.0" />
  </joint>
  <joint name="elbow_right" type="revolute">
    <parent link="arm_right_upper" />
    <child link="arm_right_lower" />
    <origin rpy="0 0 0" xyz="-0.013    0.00079 -0.3624" />
    <axis xyz="-0.99863  0.05074 -0.01234" />
    <limit effort="0.0" lower="0.0" upper="1.91986217719" velocity="0.0" />
  </joint>
  <joint name="elbow_left" type="revolute">
    <parent link="arm_left_upper" />
    <child link="arm_left_lower" />
    <origin rpy="0 0 0" xyz="0.01342 -0.00741 -0.36229" />
    <axis xyz="-0.99863 -0.05074  0.01234" />
    <limit effort="0.0" lower="0.0" upper="0.0" velocity="0.0" />
  </joint>
  <link name="head">
    <inertial>
      <mass value="0.20495740351295888" />
      <origin rpy="0 0 0" xyz="0.00051 0.04492 0.14549" />
      <inertia ixx="0.1556736912222776" ixy="-6.313507101682236e-06" ixz="-0.00010119595995300494" iyy="0.15459780882221164" iyz="-0.00846658481145499" izz="0.0030527659727341504" />
    </inertial>
    <collision name="head_collision">
      <origin rpy="0 0 0" xyz="0.00051 0.04492 0.14549" />
      <geometry>
        <mesh filename="package://robots/roboy_icecream/meshes/collisions/head.stl" scale="0.001 0.001 0.001" />
      </geometry>
    </collision>
    <visual name="head_visual">
      <origin rpy="0 0 0" xyz="0.00051 0.04492 0.14549" />
      <geometry>
        <mesh filename="package://robots/roboy_icecream/meshes/visuals/head.stl" scale="0.001 0.001 0.001" />
      </geometry>
    </visual>
  </link>
  <link name="torso">
    <inertial>
      <mass value="1.1519352383740125" />
      <origin rpy="0 0 0" xyz="0      0.00152 0.29933" />
      <inertia ixx="0.31683367909806137" ixy="-0.00013345135928581465" ixz="6.117362846899187e-05" iyy="0.3423593850628956" iyz="0.0007981326615620965" izz="0.03205526083913695" />
    </inertial>
    <collision name="torso_collision">
      <origin rpy="0 0 0" xyz="0      0.00152 0.29933" />
      <geometry>
        <mesh filename="package://robots/roboy_icecream/meshes/collisions/torso.stl" scale="0.001 0.001 0.001" />
      </geometry>
    </collision>
    <visual name="torso_visual">
      <origin rpy="0 0 0" xyz="0      0.00152 0.29933" />
      <geometry>
        <mesh filename="package://robots/roboy_icecream/meshes/visuals/torso.stl" scale="0.001 0.001 0.001" />
      </geometry>
    </visual>
  </link>
  <link name="arm_right_upper">
    <inertial>
      <mass value="0.30382570619625904" />
      <origin rpy="0 0 0" xyz="0.00259 -0.00087 -0.24874" />
      <inertia ixx="0.03049623206630643" ixy="0.0007371558107975156" ixz="0.02649409699991024" iyy="0.05611966012683304" iyz="-0.0007087184318262786" izz="0.02589050836629296" />
    </inertial>
    <collision name="arm_right_upper_collision">
      <origin rpy="0 0 0" xyz="0.00259 -0.00087 -0.24874" />
      <geometry>
        <mesh filename="package://robots/roboy_icecream/meshes/collisions/arm_right_upper.stl" scale="0.001 0.001 0.001" />
      </geometry>
    </collision>
    <visual name="arm_right_upper_visual">
      <origin rpy="0 0 0" xyz="0.00259 -0.00087 -0.24874" />
      <geometry>
        <mesh filename="package://robots/roboy_icecream/meshes/visuals/arm_right_upper.stl" scale="0.001 0.001 0.001" />
      </geometry>
    </visual>
  </link>
  <link name="arm_right_lower">
    <inertial>
      <mass value="0.26996310025843295" />
      <origin rpy="0 0 0" xyz="0.02208  0.01162 -0.15801" />
      <inertia ixx="0.002571663931061366" ixy="0.0016461138635503918" ixz="0.0022023955316728245" iyy="0.02418617692367755" iyz="2.0140739726766566e-05" izz="0.022081325924676896" />
    </inertial>
    <collision name="arm_right_lower_collision">
      <origin rpy="0 0 0" xyz="0.02208  0.01162 -0.15801" />
      <geometry>
        <mesh filename="package://robots/roboy_icecream/meshes/collisions/arm_right_lower.stl" scale="0.001 0.001 0.001" />
      </geometry>
    </collision>
    <visual name="arm_right_lower_visual">
      <origin rpy="0 0 0" xyz="0.02208  0.01162 -0.15801" />
      <geometry>
        <mesh filename="package://robots/roboy_icecream/meshes/visuals/arm_right_lower.stl" scale="0.001 0.001 0.001" />
      </geometry>
    </visual>
  </link>
  <link name="arm_left_upper">
    <inertial>
      <mass value="0.3010990375097506" />
      <origin rpy="0 0 0" xyz="-0.00234 -0.00504 -0.2468" />
      <inertia ixx="0.030095352612167777" ixy="-0.0007764334680049139" ixz="-0.026048562145339373" iyy="0.055307965864145874" iyz="-0.0008516321854404289" izz="0.025477903124651775" />
    </inertial>
    <collision name="arm_left_upper_collision">
      <origin rpy="0 0 0" xyz="-0.00234 -0.00504 -0.2468" />
      <geometry>
        <mesh filename="package://robots/roboy_icecream/meshes/collisions/arm_left_upper.stl" scale="0.001 0.001 0.001" />
      </geometry>
    </collision>
    <visual name="arm_left_upper_visual">
      <origin rpy="0 0 0" xyz="-0.00234 -0.00504 -0.2468" />
      <geometry>
        <mesh filename="package://robots/roboy_icecream/meshes/visuals/arm_left_upper.stl" scale="0.001 0.001 0.001" />
      </geometry>
    </visual>
  </link>
  <link name="arm_left_lower">
    <inertial>
      <mass value="0.11243588187932435" />
      <origin rpy="0 0 0" xyz="-0.01667 -0.00163 -0.06929" />
      <inertia ixx="0.0021374786122984857" ixy="-0.000158980874190659" ixz="-0.003678854504594684" iyy="0.011493725443881088" iyz="-6.916112821282024e-05" izz="0.009416325302496205" />
    </inertial>
    <collision name="arm_left_lower_collision">
      <origin rpy="0 0 0" xyz="-0.01667 -0.00163 -0.06929" />
      <geometry>
        <mesh filename="package://robots/roboy_icecream/meshes/collisions/arm_left_lower.stl" scale="0.001 0.001 0.001" />
      </geometry>
    </collision>
    <visual name="arm_left_lower_visual">
      <origin rpy="0 0 0" xyz="-0.01667 -0.00163 -0.06929" />
      <geometry>
        <mesh filename="package://robots/roboy_icecream/meshes/visuals/arm_left_lower.stl" scale="0.001 0.001 0.001" />
      </geometry>
    </visual>
  </link>
  <link name="shoulder_left_link1">
    <inertial>
      <mass value="0.009036188404972216" />
      <origin rpy="0 0 0" xyz="0 0 0" />
      <inertia ixx="0.0026853786874337163" ixy="-3.675942095743902e-05" ixz="-0.0014372126974415212" iyy="0.003453525279236198" iyz="-6.862058794001134e-05" izz="0.0007723659313968807" />
    </inertial>
    <collision name="shoulder_left_link1_collision">
      <origin rpy="0 0 0" xyz="0 0 0" />
      <geometry>
        <mesh filename="package://robots/roboy_icecream/meshes/collisions/shoulder_left_link1.stl" scale="0.001 0.001 0.001" />
      </geometry>
    </collision>
    <visual name="shoulder_left_link1_visual">
      <origin rpy="0 0 0" xyz="0 0 0" />
      <geometry>
        <mesh filename="package://robots/roboy_icecream/meshes/visuals/shoulder_left_link1.stl" scale="0.001 0.001 0.001" />
      </geometry>
    </visual>
  </link>
  <link name="shoulder_left_link2">
    <inertial>
      <mass value="0.0007113170108844941" />
      <origin rpy="0 0 0" xyz="0 0 0" />
      <inertia ixx="0.00021134396605301215" ixy="-2.8936797892132433e-06" ixz="-0.00011313551510286908" iyy="0.000271811459643765" iyz="-5.401772354685746e-06" izz="6.07540702812908e-05" />
    </inertial>
    <collision name="shoulder_left_link2_collision">
      <origin rpy="0 0 0" xyz="0 0 0" />
      <geometry>
        <mesh filename="package://robots/roboy_icecream/meshes/collisions/shoulder_left_link2.stl" scale="0.001 0.001 0.001" />
      </geometry>
    </collision>
    <visual name="shoulder_left_link2_visual">
      <origin rpy="0 0 0" xyz="0 0 0" />
      <geometry>
        <mesh filename="package://robots/roboy_icecream/meshes/visuals/shoulder_left_link2.stl" scale="0.001 0.001 0.001" />
      </geometry>
    </visual>
  </link>
  <link name="shoulder_right_link1">
    <inertial>
      <mass value="0.009036760208789225" />
      <origin rpy="0 0 0" xyz="0 0 0" />
      <inertia ixx="0.002716277857038176" ixy="2.4465659548951448e-05" ixz="0.0014521126966952603" iyy="0.0034922247415397722" iyz="-4.5739786268846117e-05" izz="0.0007781973864830209" />
    </inertial>
    <collision name="shoulder_right_link1_collision">
      <origin rpy="0 0 0" xyz="0 0 0" />
      <geometry>
        <mesh filename="package://robots/roboy_icecream/meshes/collisions/shoulder_right_link1.stl" scale="0.001 0.001 0.001" />
      </geometry>
    </collision>
    <visual name="shoulder_right_link1_visual">
      <origin rpy="0 0 0" xyz="0 0 0" />
      <geometry>
        <mesh filename="package://robots/roboy_icecream/meshes/visuals/shoulder_right_link1.stl" scale="0.001 0.001 0.001" />
      </geometry>
    </visual>
  </link>
  <link name="shoulder_right_link2">
    <inertial>
      <mass value="0.0007113171768782597" />
      <origin rpy="0 0 0" xyz="0 0 0" />
      <inertia ixx="0.0002137629132340016" ixy="1.9257030781476827e-06" ixz="0.00011430126664005363" iyy="0.0002748406222637266" iyz="-3.6001994065082846e-06" izz="6.120927174830888e-05" />
    </inertial>
    <collision name="shoulder_right_link2_collision">
      <origin rpy="0 0 0" xyz="0 0 0" />
      <geometry>
        <mesh filename="package://robots/roboy_icecream/meshes/collisions/shoulder_right_link2.stl" scale="0.001 0.001 0.001" />
      </geometry>
    </collision>
    <visual name="shoulder_right_link2_visual">
      <origin rpy="0 0 0" xyz="0 0 0" />
      <geometry>
        <mesh filename="package://robots/roboy_icecream/meshes/visuals/shoulder_right_link2.stl" scale="0.001 0.001 0.001" />
      </geometry>
    </visual>
  </link>
  <link name="zed_camera_left_lense">
    <inertial>
      <mass value="0.0005755421856391891" />
      <origin rpy="0 0 0" xyz="5.000e-05 -1.107e-02  2.350e-03" />
      <inertia ixx="0.0005003354055639959" ixy="2.3967379469334977e-06" ixz="-3.222735583266803e-05" iyy="0.0004996529496255549" iyz="3.70054972711012e-05" izz="4.878384607433585e-06" />
    </inertial>
    <collision name="zed_camera_left_lense_collision">
      <origin rpy="0 0 0" xyz="5.000e-05 -1.107e-02  2.350e-03" />
      <geometry>
        <mesh filename="package://robots/roboy_icecream/meshes/collisions/zed_camera_left_lense.stl" scale="0.001 0.001 0.001" />
      </geometry>
    </collision>
    <visual name="zed_camera_left_lense_visual">
      <origin rpy="0 0 0" xyz="5.000e-05 -1.107e-02  2.350e-03" />
      <geometry>
        <mesh filename="package://robots/roboy_icecream/meshes/visuals/zed_camera_left_lense.stl" scale="0.001 0.001 0.001" />
      </geometry>
    </visual>
  </link>
  <link name="zed_camera_right_lense">
    <inertial>
      <mass value="0.0005755421855125974" />
      <origin rpy="0 0 0" xyz="3.000e-05 -1.107e-02  2.350e-03" />
      <inertia ixx="0.0005003654932232295" ixy="-2.391821338968771e-06" ixz="3.1988357548007145e-05" iyy="0.0004996221065096928" iyz="3.720723754360987e-05" izz="4.877629449989427e-06" />
    </inertial>
    <collision name="zed_camera_right_lense_collision">
      <origin rpy="0 0 0" xyz="3.000e-05 -1.107e-02  2.350e-03" />
      <geometry>
        <mesh filename="package://robots/roboy_icecream/meshes/collisions/zed_camera_right_lense.stl" scale="0.001 0.001 0.001" />
      </geometry>
    </collision>
    <visual name="zed_camera_right_lense_visual">
      <origin rpy="0 0 0" xyz="3.000e-05 -1.107e-02  2.350e-03" />
      <geometry>
        <mesh filename="package://robots/roboy_icecream/meshes/visuals/zed_camera_right_lense.stl" scale="0.001 0.001 0.001" />
      </geometry>
    </visual>
  </link>
  <link name="zed_camera">
    <inertial>
      <mass value="0.0009633907989226702" />
      <origin rpy="0 0 0" xyz="-0.01743 -0.0014  -0.00805" />
      <inertia ixx="0.0008314802982788687" ixy="2.436533895216603e-07" ixz="-3.793293439362343e-06" iyy="0.0008297308522063661" iyz="5.174870196291635e-05" izz="4.725323656366554e-06" />
    </inertial>
    <collision name="zed_camera_collision">
      <origin rpy="0 0 0" xyz="-0.01743 -0.0014  -0.00805" />
      <geometry>
        <mesh filename="package://robots/roboy_icecream/meshes/collisions/zed_camera.stl" scale="0.001 0.001 0.001" />
      </geometry>
    </collision>
    <visual name="zed_camera_visual">
      <origin rpy="0 0 0" xyz="-0.01743 -0.0014  -0.00805" />
      <geometry>
        <mesh filename="package://robots/roboy_icecream/meshes/visuals/zed_camera.stl" scale="0.001 0.001 0.001" />
      </geometry>
    </visual>
  </link>
  <link name="neck_link1">
    <inertial>
      <mass value="0.0017038665636260374" />
      <origin rpy="0 0 0" xyz="0 0 0" />
      <inertia ixx="0.0008728267843512113" ixy="3.9052463248877987e-16" ixz="1.836596576210159e-13" iyy="0.0008728228385076957" iyz="-1.855689641317778e-06" izz="1.1502292854573882e-07" />
    </inertial>
    <collision name="neck_link1_collision">
      <origin rpy="0 0 0" xyz="0 0 0" />
      <geometry>
        <mesh filename="package://robots/roboy_icecream/meshes/collisions/neck_link1.stl" scale="0.001 0.001 0.001" />
      </geometry>
    </collision>
    <visual name="neck_link1_visual">
      <origin rpy="0 0 0" xyz="0 0 0" />
      <geometry>
        <mesh filename="package://robots/roboy_icecream/meshes/visuals/neck_link1.stl" scale="0.001 0.001 0.001" />
      </geometry>
    </visual>
  </link>
  <link name="neck_link2">
    <inertial>
      <mass value="0.0011421521917888836" />
      <origin rpy="0 0 0" xyz="0 0 0" />
      <inertia ixx="0.0005850573477666747" ixy="2.21885727293928e-16" ixz="1.0435059226432399e-13" iyy="0.0005850547027508899" iyz="-1.243923713466404e-06" izz="5.28219512713884e-08" />
    </inertial>
    <collision name="neck_link2_collision">
      <origin rpy="0 0 0" xyz="0 0 0" />
      <geometry>
        <mesh filename="package://robots/roboy_icecream/meshes/collisions/neck_link2.stl" scale="0.001 0.001 0.001" />
      </geometry>
    </collision>
    <visual name="neck_link2_visual">
      <origin rpy="0 0 0" xyz="0 0 0" />
      <geometry>
        <mesh filename="package://robots/roboy_icecream/meshes/visuals/neck_link2.stl" scale="0.001 0.001 0.001" />
      </geometry>
    </visual>
  </link>
  <link name="bike_back">
    <inertial>
      <mass value="1.2951344920362922" />
      <origin rpy="0 0 0" xyz="-1.1000e-04 -3.6124e-01 -8.5684e-01" />
      <inertia ixx="0.8442264729699303" ixy="0.005546017500224689" ixz="-0.00017735467712802575" iyy="0.42643007759447893" iyz="-0.29995137524469556" izz="0.4303003496245288" />
    </inertial>
    <collision name="bike_back_collision">
      <origin rpy="0 0 0" xyz="-1.1000e-04 -3.6124e-01 -8.5684e-01" />
      <geometry>
        <mesh filename="package://robots/roboy_icecream/meshes/collisions/bike_back.stl" scale="0.001 0.001 0.001" />
      </geometry>
    </collision>
    <visual name="bike_back_visual">
      <origin rpy="0 0 0" xyz="-1.1000e-04 -3.6124e-01 -8.5684e-01" />
      <geometry>
        <mesh filename="package://robots/roboy_icecream/meshes/visuals/bike_back.stl" scale="0.001 0.001 0.001" />
      </geometry>
    </visual>
  </link>
  <link name="bike_front">
    <inertial>
      <mass value="63.7307664696775" />
      <origin rpy="0 0 0" xyz="0.00314 0.09182 0.46868" />
      <inertia ixx="97.29796056018368" ixy="0.18846553118688075" ixz="0.05000139261544522" iyy="6.576697684911534" iyz="-15.1057167024435" izz="93.78235037267204" />
    </inertial>
    <collision name="bike_front_collision">
      <origin rpy="0 0 0" xyz="0.00314 0.09182 0.46868" />
      <geometry>
        <mesh filename="package://robots/roboy_icecream/meshes/collisions/bike_front.stl" scale="0.001 0.001 0.001" />
      </geometry>
    </collision>
    <visual name="bike_front_visual">
      <origin rpy="0 0 0" xyz="0.00314 0.09182 0.46868" />
      <geometry>
        <mesh filename="package://robots/roboy_icecream/meshes/visuals/bike_front.stl" scale="0.001 0.001 0.001" />
      </geometry>
    </visual>
  </link>
  <link name="zed_mini">
    <inertial>
      <mass value="0.043618915158257776" />
      <origin rpy="0 0 0" xyz="-0.00149 -0.00964 -0.03" />
      <inertia ixx="0.00737257003290057" ixy="-6.039631699136496e-06" ixz="1.7504257606619555e-05" iyy="0.006813337441384371" iyz="0.0020337006242750425" izz="0.0006694076484380283" />
    </inertial>
    <collision name="zed_mini_collision">
      <origin rpy="0 0 0" xyz="-0.00149 -0.00964 -0.03" />
      <geometry>
        <mesh filename="package://robots/roboy_icecream/meshes/collisions/zed_mini.stl" scale="0.001 0.001 0.001" />
      </geometry>
    </collision>
    <visual name="zed_mini_visual">
      <origin rpy="0 0 0" xyz="-0.00149 -0.00964 -0.03" />
      <geometry>
        <mesh filename="package://robots/roboy_icecream/meshes/visuals/zed_mini.stl" scale="0.001 0.001 0.001" />
      </geometry>
    </visual>
  </link>
  <link name="pico_flexx">
    <inertial>
      <mass value="0.0015436810520105988" />
      <origin rpy="0 0 0" xyz="-0.0417  -0.00221  0.00831" />
      <inertia ixx="0.0002875421261491332" ixy="2.9660169029790847e-06" ixz="-1.0489308848843665e-05" iyy="0.00026725118905498264" iyz="7.543345735127459e-05" izz="2.2486643967097435e-05" />
    </inertial>
    <collision name="pico_flexx_collision">
      <origin rpy="0 0 0" xyz="-0.0417  -0.00221  0.00831" />
      <geometry>
        <mesh filename="package://robots/roboy_icecream/meshes/collisions/pico_flexx.stl" scale="0.001 0.001 0.001" />
      </geometry>
    </collision>
    <visual name="pico_flexx_visual">
      <origin rpy="0 0 0" xyz="-0.0417  -0.00221  0.00831" />
      <geometry>
        <mesh filename="package://robots/roboy_icecream/meshes/visuals/pico_flexx.stl" scale="0.001 0.001 0.001" />
      </geometry>
    </visual>
  </link>
</robot>