<?xml version="1.0" ?>
<sdf version="1.6">
	<model name="roboy_icecream">
		<link name="head">
			<self_collide>false</self_collide>
			<pose frame="">0.0005102180295691139 0.046445898229309404 0.8611776443142852 0.0 -0.0 0.0</pose>
			<inertial>
				<pose frame="">0.0 0.0 0.0 0 0 0</pose>
				<mass>2.049574035129589</mass>
				<inertia>
					<ixx>1.5567369122227759</ixx>
					<ixy>-6.313507101682236e-05</ixy>
					<ixz>-0.0010119595995300493</ixz>
					<iyy>1.5459780882221161</iyy>
					<iyz>-0.08466584811454989</iyz>
					<izz>0.0305276597273415</izz>
				</inertia>
			</inertial>
			<collision name="head_collision">
				<geometry>
					<mesh>
						<uri>model://roboy_icecream/meshes/CAD/head.stl</uri>
						<scale>0.001 0.001 0.001</scale>
					</mesh>
				</geometry>
			</collision>
			<visual name="head_visual">
				<geometry>
					<mesh>
						<uri>model://roboy_icecream/meshes/CAD/head.stl</uri>
						<scale>0.001 0.001 0.001</scale>
					</mesh>
				</geometry>
			</visual>
		</link>
		<link name="torso">
			<self_collide>false</self_collide>
			<pose frame="">1.5654144647214706e-16 0.001521781085073083 0.2993372744464763 0.0 -0.0 0.0</pose>
			<inertial>
				<pose frame="">0.0 0.0 0.0 0 0 0</pose>
				<mass>11.519352383740124</mass>
				<inertia>
					<ixx>3.1683367909806135</ixx>
					<ixy>-0.0013345135928581463</ixy>
					<ixz>0.0006117362846899188</ixz>
					<iyy>3.4235938506289556</iyy>
					<iyz>0.007981326615620964</iyz>
					<izz>0.3205526083913695</izz>
				</inertia>
			</inertial>
			<collision name="torso_collision">
				<geometry>
					<mesh>
						<uri>model://roboy_icecream/meshes/CAD/torso.stl</uri>
						<scale>0.001 0.001 0.001</scale>
					</mesh>
				</geometry>
			</collision>
			<visual name="torso_visual">
				<geometry>
					<mesh>
						<uri>model://roboy_icecream/meshes/CAD/torso.stl</uri>
						<scale>0.001 0.001 0.001</scale>
					</mesh>
				</geometry>
			</visual>
		</link>
		<link name="arm_left_upper">
			<self_collide>false</self_collide>
			<pose frame="">0.29034236558261844 0.010490653909552923 0.3942197017362756 0.0 -0.0 0.0</pose>
			<inertial>
				<pose frame="">0.0 0.0 0.0 0 0 0</pose>
				<mass>1.3691221550399004</mass>
				<inertia>
					<ixx>0.217115005899122</ixx>
					<ixy>-0.004144117377137277</ixy>
					<ixz>-0.15676308059945898</ixz>
					<iyy>0.3318459096201609</iyy>
					<iyz>-0.005726829922313238</iyz>
					<izz>0.11645518058255042</izz>
				</inertia>
			</inertial>
			<collision name="arm_left_upper_collision">
				<geometry>
					<mesh>
						<uri>model://roboy_icecream/meshes/CAD/arm_left_upper.stl</uri>
						<scale>0.001 0.001 0.001</scale>
					</mesh>
				</geometry>
			</collision>
			<visual name="arm_left_upper_visual">
				<geometry>
					<mesh>
						<uri>model://roboy_icecream/meshes/CAD/arm_left_upper.stl</uri>
						<scale>0.001 0.001 0.001</scale>
					</mesh>
				</geometry>
			</visual>
		</link>
		<link name="palm_right">
			<self_collide>false</self_collide>
			<pose frame="">-0.29382955224475543 0.006571272251648853 -0.09988710802380311 0.0 -0.0 0.0</pose>
			<inertial>
				<pose frame="">0.0 0.0 0.0 0 0 0</pose>
				<mass>0.8992408456547932</mass>
				<inertia>
					<ixx>0.010369176573027682</ixx>
					<ixy>0.0018070430079445627</ixy>
					<ixz>-0.026407913123279843</ixz>
					<iyy>0.08749715761785029</iyy>
					<iyz>0.0005216008397877933</iyz>
					<izz>0.07848478303556808</izz>
				</inertia>
			</inertial>
			<collision name="palm_right_collision">
				<geometry>
					<mesh>
						<uri>model://roboy_icecream/meshes/CAD/palm_right.stl</uri>
						<scale>0.001 0.001 0.001</scale>
					</mesh>
				</geometry>
			</collision>
			<visual name="palm_right_visual">
				<geometry>
					<mesh>
						<uri>model://roboy_icecream/meshes/CAD/palm_right.stl</uri>
						<scale>0.001 0.001 0.001</scale>
					</mesh>
				</geometry>
			</visual>
		</link>
		<link name="scooper">
			<self_collide>false</self_collide>
			<pose frame="">-0.2658485122892276 -0.029442582609777668 -0.11354443580525199 0.0 -0.0 0.0</pose>
			<inertial>
				<pose frame="">0.0 0.0 0.0 0 0 0</pose>
				<mass>0.6635862444211911</mass>
				<inertia>
					<ixx>0.010376054570135662</ixx>
					<ixy>-0.005251521933909247</ixy>
					<ixz>-0.020030680115057504</ixz>
					<iyy>0.055541091736384</iyy>
					<iyz>-0.0022205744568801655</iyz>
					<izz>0.04870870606527029</izz>
				</inertia>
			</inertial>
			<collision name="scooper_collision">
				<geometry>
					<mesh>
						<uri>model://roboy_icecream/meshes/CAD/scooper.stl</uri>
						<scale>0.001 0.001 0.001</scale>
					</mesh>
				</geometry>
			</collision>
			<visual name="scooper_visual">
				<geometry>
					<mesh>
						<uri>model://roboy_icecream/meshes/CAD/scooper.stl</uri>
						<scale>0.001 0.001 0.001</scale>
					</mesh>
				</geometry>
			</visual>
		</link>
		<link name="arm_right_upper">
			<self_collide>false</self_collide>
			<pose frame="">-0.29016453811576326 0.008325343188540873 0.29600783937746117 0.0 -0.0 0.0</pose>
			<inertial>
				<pose frame="">0.0 0.0 0.0 0 0 0</pose>
				<mass>2.98314384024382</mass>
				<inertia>
					<ixx>0.29217335254578813</ixx>
					<ixy>0.007195986428065332</ixy>
					<ixz>0.2566402710814884</ixz>
					<iyy>0.5430496409097104</iyy>
					<iyz>-0.006814109122042475</iyz>
					<izz>0.25340978516468865</izz>
				</inertia>
			</inertial>
			<collision name="arm_right_upper_collision">
				<geometry>
					<mesh>
						<uri>model://roboy_icecream/meshes/CAD/arm_right_upper.stl</uri>
						<scale>0.001 0.001 0.001</scale>
					</mesh>
				</geometry>
			</collision>
			<visual name="arm_right_upper_visual">
				<geometry>
					<mesh>
						<uri>model://roboy_icecream/meshes/CAD/arm_right_upper.stl</uri>
						<scale>0.001 0.001 0.001</scale>
					</mesh>
				</geometry>
			</visual>
		</link>
		<link name="arm_right_lower">
			<self_collide>false</self_collide>
			<pose frame="">-0.2891991226870085 0.009183753318322416 0.1451851425430673 0.0 -0.0 0.0</pose>
			<inertial>
				<pose frame="">0.0 0.0 0.0 0 0 0</pose>
				<mass>0.8498742157982011</mass>
				<inertia>
					<ixx>0.021387357764080524</ixx>
					<ixy>0.0022525419150179844</ixy>
					<ixz>0.03572288586998189</ixz>
					<iyy>0.09230453919802804</iyy>
					<iyz>-0.0011339797417804385</iyz>
					<izz>0.07140549493608427</izz>
				</inertia>
			</inertial>
			<collision name="arm_right_lower_collision">
				<geometry>
					<mesh>
						<uri>model://roboy_icecream/meshes/CAD/arm_right_lower.stl</uri>
						<scale>0.001 0.001 0.001</scale>
					</mesh>
				</geometry>
			</collision>
			<visual name="arm_right_lower_visual">
				<geometry>
					<mesh>
						<uri>model://roboy_icecream/meshes/CAD/arm_right_lower.stl</uri>
						<scale>0.001 0.001 0.001</scale>
					</mesh>
				</geometry>
			</visual>
		</link>
		<link name="arm_left_lower">
			<self_collide>false</self_collide>
			<pose frame="">0.28677400916437257 0.0054367442344862476 0.14306804983545288 0.0 -0.0 0.0</pose>
			<inertial>
				<pose frame="">0.0 0.0 0.0 0 0 0</pose>
				<mass>0.8439804961388786</mass>
				<inertia>
					<ixx>0.020514091583918363</ixx>
					<ixy>-0.0013169517855746492</ixy>
					<ixz>-0.03462704886345511</ixz>
					<iyy>0.0898041726976201</iyy>
					<iyz>-0.0006481363976846151</iyz>
					<izz>0.06968780706038735</izz>
				</inertia>
			</inertial>
			<collision name="arm_left_lower_collision">
				<geometry>
					<mesh>
						<uri>model://roboy_icecream/meshes/CAD/arm_left_lower.stl</uri>
						<scale>0.001 0.001 0.001</scale>
					</mesh>
				</geometry>
			</collision>
			<visual name="arm_left_lower_visual">
				<geometry>
					<mesh>
						<uri>model://roboy_icecream/meshes/CAD/arm_left_lower.stl</uri>
						<scale>0.001 0.001 0.001</scale>
					</mesh>
				</geometry>
			</visual>
		</link>
		<link name="shoulder_left_link1">
			<self_collide>false</self_collide>
			<pose frame="">0.29189388396936844 0.013936649708446084 0.5448924278024039 0.0 -0.0 0.0</pose>
			<inertial>
				<pose frame="">0.0 0.0 0.0 0 0 0</pose>
				<mass>0.09036188404972216</mass>
				<inertia>
					<ixx>0.02685378687433716</ixx>
					<ixy>-0.00036759420957439013</ixy>
					<ixz>-0.01437212697441521</ixz>
					<iyy>0.03453525279236198</iyy>
					<iyz>-0.0006862058794001133</iyz>
					<izz>0.0077236593139688075</izz>
				</inertia>
			</inertial>
			<collision name="shoulder_left_link1_collision">
				<geometry>
					<mesh>
						<uri>model://roboy_icecream/meshes/CAD/shoulder_left_link1.stl</uri>
						<scale>0.001 0.001 0.001</scale>
					</mesh>
				</geometry>
			</collision>
			<visual name="shoulder_left_link1_visual">
				<geometry>
					<mesh>
						<uri>model://roboy_icecream/meshes/CAD/shoulder_left_link1.stl</uri>
						<scale>0.001 0.001 0.001</scale>
					</mesh>
				</geometry>
			</visual>
		</link>
		<link name="shoulder_left_link2">
			<self_collide>false</self_collide>
			<pose frame="">0.29189387258386296 0.013936775290985024 0.5448924436270218 0.0 -0.0 0.0</pose>
			<inertial>
				<pose frame="">0.0 0.0 0.0 0 0 0</pose>
				<mass>0.00711317010884494</mass>
				<inertia>
					<ixx>0.0021134396605301214</ixx>
					<ixy>-2.893679789213243e-05</ixy>
					<ixz>-0.0011313551510286908</ixz>
					<iyy>0.00271811459643765</iyy>
					<iyz>-5.401772354685746e-05</iyz>
					<izz>0.000607540702812908</izz>
				</inertia>
			</inertial>
			<collision name="shoulder_left_link2_collision">
				<geometry>
					<mesh>
						<uri>model://roboy_icecream/meshes/CAD/shoulder_left_link2.stl</uri>
						<scale>0.001 0.001 0.001</scale>
					</mesh>
				</geometry>
			</collision>
			<visual name="shoulder_left_link2_visual">
				<geometry>
					<mesh>
						<uri>model://roboy_icecream/meshes/CAD/shoulder_left_link2.stl</uri>
						<scale>0.001 0.001 0.001</scale>
					</mesh>
				</geometry>
			</visual>
		</link>
		<link name="shoulder_right_link1">
			<self_collide>false</self_collide>
			<pose frame="">-0.29317381623663624 0.009234619138342707 0.5481032586387985 0.0 -0.0 0.0</pose>
			<inertial>
				<pose frame="">0.0 0.0 0.0 0 0 0</pose>
				<mass>0.09036760208789225</mass>
				<inertia>
					<ixx>0.02716277857038176</ixx>
					<ixy>0.00024465659548951447</ixy>
					<ixz>0.014521126966952602</ixz>
					<iyy>0.03492224741539772</iyy>
					<iyz>-0.00045739786268846115</iyz>
					<izz>0.0077819738648302085</izz>
				</inertia>
			</inertial>
			<collision name="shoulder_right_link1_collision">
				<geometry>
					<mesh>
						<uri>model://roboy_icecream/meshes/CAD/shoulder_right_link1.stl</uri>
						<scale>0.001 0.001 0.001</scale>
					</mesh>
				</geometry>
			</collision>
			<visual name="shoulder_right_link1_visual">
				<geometry>
					<mesh>
						<uri>model://roboy_icecream/meshes/CAD/shoulder_right_link1.stl</uri>
						<scale>0.001 0.001 0.001</scale>
					</mesh>
				</geometry>
			</visual>
		</link>
		<link name="shoulder_right_link2">
			<self_collide>false</self_collide>
			<pose frame="">-0.2931738685724693 0.009234231768945902 0.5481033912318385 0.0 -0.0 0.0</pose>
			<inertial>
				<pose frame="">0.0 0.0 0.0 0 0 0</pose>
				<mass>0.007113171768782596</mass>
				<inertia>
					<ixx>0.002137629132340016</ixx>
					<ixy>1.9257030781476826e-05</ixy>
					<ixz>0.0011430126664005362</ixz>
					<iyy>0.002748406222637266</iyy>
					<iyz>-3.600199406508284e-05</iyz>
					<izz>0.0006120927174830887</izz>
				</inertia>
			</inertial>
			<collision name="shoulder_right_link2_collision">
				<geometry>
					<mesh>
						<uri>model://roboy_icecream/meshes/CAD/shoulder_right_link2.stl</uri>
						<scale>0.001 0.001 0.001</scale>
					</mesh>
				</geometry>
			</collision>
			<visual name="shoulder_right_link2_visual">
				<geometry>
					<mesh>
						<uri>model://roboy_icecream/meshes/CAD/shoulder_right_link2.stl</uri>
						<scale>0.001 0.001 0.001</scale>
					</mesh>
				</geometry>
			</visual>
		</link>
		<link name="zed_camera_left_lense">
			<self_collide>false</self_collide>
			<pose frame="">0.060224029002958875 -0.06914536611449566 0.9297742812708069 0.0 -0.0 0.0</pose>
			<inertial>
				<pose frame="">0.0 0.0 0.0 0 0 0</pose>
				<mass>0.005755421856391891</mass>
				<inertia>
					<ixx>0.005003354055639959</ixx>
					<ixy>2.3967379469334976e-05</ixy>
					<ixz>-0.0003222735583266803</ixz>
					<iyy>0.004996529496255549</iyy>
					<iyz>0.000370054972711012</iyz>
					<izz>4.878384607433584e-05</izz>
				</inertia>
			</inertial>
			<collision name="zed_camera_left_lense_collision">
				<geometry>
					<mesh>
						<uri>model://roboy_icecream/meshes/CAD/zed_camera_left_lense.stl</uri>
						<scale>0.001 0.001 0.001</scale>
					</mesh>
				</geometry>
			</collision>
			<visual name="zed_camera_left_lense_visual">
				<geometry>
					<mesh>
						<uri>model://roboy_icecream/meshes/CAD/zed_camera_left_lense.stl</uri>
						<scale>0.001 0.001 0.001</scale>
					</mesh>
				</geometry>
			</visual>
		</link>
		<link name="zed_camera_right_lense">
			<self_collide>false</self_collide>
			<pose frame="">-0.05977745584801778 -0.06952236314727904 0.9297742812332496 0.0 -0.0 0.0</pose>
			<inertial>
				<pose frame="">0.0 0.0 0.0 0 0 0</pose>
				<mass>0.0057554218551259745</mass>
				<inertia>
					<ixx>0.0050036549322322954</ixx>
					<ixy>-2.391821338968771e-05</ixy>
					<ixz>0.00031988357548007145</ixz>
					<iyy>0.004996221065096928</iyy>
					<iyz>0.00037207237543609864</iyz>
					<izz>4.877629449989427e-05</izz>
				</inertia>
			</inertial>
			<collision name="zed_camera_right_lense_collision">
				<geometry>
					<mesh>
						<uri>model://roboy_icecream/meshes/CAD/zed_camera_right_lense.stl</uri>
						<scale>0.001 0.001 0.001</scale>
					</mesh>
				</geometry>
			</collision>
			<visual name="zed_camera_right_lense_visual">
				<geometry>
					<mesh>
						<uri>model://roboy_icecream/meshes/CAD/zed_camera_right_lense.stl</uri>
						<scale>0.001 0.001 0.001</scale>
					</mesh>
				</geometry>
			</visual>
		</link>
		<link name="zed_camera">
			<self_collide>false</self_collide>
			<pose frame="">0.004244484790251953 -0.057938621286604985 0.9271942136470953 0.0 -0.0 0.0</pose>
			<inertial>
				<pose frame="">0.0 0.0 0.0 0 0 0</pose>
				<mass>0.009633907989226701</mass>
				<inertia>
					<ixx>0.008314802982788687</ixx>
					<ixy>2.4365338952166025e-06</ixy>
					<ixz>-3.793293439362343e-05</ixz>
					<iyy>0.008297308522063661</iyy>
					<iyz>0.0005174870196291635</iyz>
					<izz>4.725323656366554e-05</izz>
				</inertia>
			</inertial>
			<collision name="zed_camera_collision">
				<geometry>
					<mesh>
						<uri>model://roboy_icecream/meshes/CAD/zed_camera.stl</uri>
						<scale>0.001 0.001 0.001</scale>
					</mesh>
				</geometry>
			</collision>
			<visual name="zed_camera_visual">
				<geometry>
					<mesh>
						<uri>model://roboy_icecream/meshes/CAD/zed_camera.stl</uri>
						<scale>0.001 0.001 0.001</scale>
					</mesh>
				</geometry>
			</visual>
		</link>
		<link name="neck_link1">
			<self_collide>false</self_collide>
			<pose frame="">-1.506123287543706e-10 0.0015217809344427158 0.7156779292283452 0.0 -0.0 0.0</pose>
			<inertial>
				<pose frame="">0.0 0.0 0.0 0 0 0</pose>
				<mass>0.017038665636260372</mass>
				<inertia>
					<ixx>0.008728267843512112</ixx>
					<ixy>3.905246324887799e-15</ixy>
					<ixz>1.836596576210159e-12</ixz>
					<iyy>0.008728228385076956</iyy>
					<iyz>-1.855689641317778e-05</iyz>
					<izz>1.150229285457388e-06</izz>
				</inertia>
			</inertial>
			<collision name="neck_link1_collision">
				<geometry>
					<mesh>
						<uri>model://roboy_icecream/meshes/CAD/neck_link1.stl</uri>
						<scale>0.001 0.001 0.001</scale>
					</mesh>
				</geometry>
			</collision>
			<visual name="neck_link1_visual">
				<geometry>
					<mesh>
						<uri>model://roboy_icecream/meshes/CAD/neck_link1.stl</uri>
						<scale>0.001 0.001 0.001</scale>
					</mesh>
				</geometry>
			</visual>
		</link>
		<link name="neck_link2">
			<self_collide>false</self_collide>
			<pose frame="">-1.2765957254235939e-10 0.0015217809573941732 0.7156779292283448 0.0 -0.0 0.0</pose>
			<inertial>
				<pose frame="">0.0 0.0 0.0 0 0 0</pose>
				<mass>0.011421521917888835</mass>
				<inertia>
					<ixx>0.005850573477666747</ixx>
					<ixy>2.21885727293928e-15</ixy>
					<ixz>1.0435059226432398e-12</ixz>
					<iyy>0.005850547027508899</iyy>
					<iyz>-1.243923713466404e-05</iyz>
					<izz>5.28219512713884e-07</izz>
				</inertia>
			</inertial>
			<collision name="neck_link2_collision">
				<geometry>
					<mesh>
						<uri>model://roboy_icecream/meshes/CAD/neck_link2.stl</uri>
						<scale>0.001 0.001 0.001</scale>
					</mesh>
				</geometry>
			</collision>
			<visual name="neck_link2_visual">
				<geometry>
					<mesh>
						<uri>model://roboy_icecream/meshes/CAD/neck_link2.stl</uri>
						<scale>0.001 0.001 0.001</scale>
					</mesh>
				</geometry>
			</visual>
		</link>
		<link name="hand_left_index_link1">
			<self_collide>false</self_collide>
			<pose frame="">0.2971479598973614 -0.03884098082845614 -0.20552842966579854 0.0 -0.0 0.0</pose>
			<inertial>
				<pose frame="">0.0 0.0 0.0 0 0 0</pose>
				<mass>0.03082114844612854</mass>
				<inertia>
					<ixx>0.0013506736158124097</ixx>
					<ixy>0.00035574185821337756</ixy>
					<ixz>0.0018823430933638905</ixz>
					<iyy>0.00402525778232642</iyy>
					<iyz>-0.0002461253603596658</iyz>
					<izz>0.0027690587409003845</izz>
				</inertia>
			</inertial>
			<collision name="hand_left_index_link1_collision">
				<geometry>
					<mesh>
						<uri>model://roboy_icecream/meshes/CAD/hand_left_index_link1.stl</uri>
						<scale>0.001 0.001 0.001</scale>
					</mesh>
				</geometry>
			</collision>
			<visual name="hand_left_index_link1_visual">
				<geometry>
					<mesh>
						<uri>model://roboy_icecream/meshes/CAD/hand_left_index_link1.stl</uri>
						<scale>0.001 0.001 0.001</scale>
					</mesh>
				</geometry>
			</visual>
		</link>
		<link name="hand_left_index_link0">
			<self_collide>false</self_collide>
			<pose frame="">0.2966759875543271 -0.03502630502423044 -0.1702206578192666 0.0 -0.0 0.0</pose>
			<inertial>
				<pose frame="">0.0 0.0 0.0 0 0 0</pose>
				<mass>0.055847004295896535</mass>
				<inertia>
					<ixx>0.0016968623738106985</ixx>
					<ixy>0.0005803560665375444</ixy>
					<ixz>0.0028203231292233525</ixz>
					<iyy>0.006543320907678163</iyy>
					<iyz>-0.0003338227071256052</iyz>
					<izz>0.004986012986514024</izz>
				</inertia>
			</inertial>
			<collision name="hand_left_index_link0_collision">
				<geometry>
					<mesh>
						<uri>model://roboy_icecream/meshes/CAD/hand_left_index_link0.stl</uri>
						<scale>0.001 0.001 0.001</scale>
					</mesh>
				</geometry>
			</collision>
			<visual name="hand_left_index_link0_visual">
				<geometry>
					<mesh>
						<uri>model://roboy_icecream/meshes/CAD/hand_left_index_link0.stl</uri>
						<scale>0.001 0.001 0.001</scale>
					</mesh>
				</geometry>
			</visual>
		</link>
		<link name="hand_left_index_link2">
			<self_collide>false</self_collide>
			<pose frame="">0.2974051015174091 -0.041544115802312716 -0.2306282591309828 0.0 -0.0 0.0</pose>
			<inertial>
				<pose frame="">0.0 0.0 0.0 0 0 0</pose>
				<mass>0.030336883534763357</mass>
				<inertia>
					<ixx>0.0016678389395295746</ixx>
					<ixy>0.0003748404234898155</ixy>
					<ixz>0.0020807791562173317</ixz>
					<iyy>0.004298522941010195</iyy>
					<iyz>-0.0002907279895584694</iyz>
					<izz>0.0027367715171087593</izz>
				</inertia>
			</inertial>
			<collision name="hand_left_index_link2_collision">
				<geometry>
					<mesh>
						<uri>model://roboy_icecream/meshes/CAD/hand_left_index_link2.stl</uri>
						<scale>0.001 0.001 0.001</scale>
					</mesh>
				</geometry>
			</collision>
			<visual name="hand_left_index_link2_visual">
				<geometry>
					<mesh>
						<uri>model://roboy_icecream/meshes/CAD/hand_left_index_link2.stl</uri>
						<scale>0.001 0.001 0.001</scale>
					</mesh>
				</geometry>
			</visual>
		</link>
		<link name="hand_left_middle_link1">
			<self_collide>false</self_collide>
			<pose frame="">0.2938252332963292 0.026390672049435626 -0.20616918497911013 0.0 -0.0 0.0</pose>
			<inertial>
				<pose frame="">0.0 0.0 0.0 0 0 0</pose>
				<mass>0.030820004367657278</mass>
				<inertia>
					<ixx>0.0013337232136177556</ixx>
					<ixy>-0.0002389710943883319</ixy>
					<ixz>0.0018670214279997194</ixz>
					<iyy>0.003972724404502232</iyy>
					<iyz>0.0001677404324723132</iyz>
					<izz>0.0026833998759867345</izz>
				</inertia>
			</inertial>
			<collision name="hand_left_middle_link1_collision">
				<geometry>
					<mesh>
						<uri>model://roboy_icecream/meshes/CAD/hand_left_middle_link1.stl</uri>
						<scale>0.001 0.001 0.001</scale>
					</mesh>
				</geometry>
			</collision>
			<visual name="hand_left_middle_link1_visual">
				<geometry>
					<mesh>
						<uri>model://roboy_icecream/meshes/CAD/hand_left_middle_link1.stl</uri>
						<scale>0.001 0.001 0.001</scale>
					</mesh>
				</geometry>
			</visual>
		</link>
		<link name="hand_left_middle_link0">
			<self_collide>false</self_collide>
			<pose frame="">0.2936690086933319 0.024025459506623416 -0.1707326742015799 0.0 -0.0 0.0</pose>
			<inertial>
				<pose frame="">0.0 0.0 0.0 0 0 0</pose>
				<mass>0.0558468603238006</mass>
				<inertia>
					<ixx>0.001670328224928711</ixx>
					<ixy>-0.0003940067152760033</ixy>
					<ixz>0.0028000585790016706</ixz>
					<iyy>0.006453977405822308</iyy>
					<iyz>0.0002295862973307584</iyz>
					<izz>0.004850523434996301</izz>
				</inertia>
			</inertial>
			<collision name="hand_left_middle_link0_collision">
				<geometry>
					<mesh>
						<uri>model://roboy_icecream/meshes/CAD/hand_left_middle_link0.stl</uri>
						<scale>0.001 0.001 0.001</scale>
					</mesh>
				</geometry>
			</collision>
			<visual name="hand_left_middle_link0_visual">
				<geometry>
					<mesh>
						<uri>model://roboy_icecream/meshes/CAD/hand_left_middle_link0.stl</uri>
						<scale>0.001 0.001 0.001</scale>
					</mesh>
				</geometry>
			</visual>
		</link>
		<link name="hand_left_middle_link2">
			<self_collide>false</self_collide>
			<pose frame="">0.29385816652228236 0.02808104797252826 -0.23135951619595652 0.0 -0.0 0.0</pose>
			<inertial>
				<pose frame="">0.0 0.0 0.0 0 0 0</pose>
				<mass>0.030336897738926852</mass>
				<inertia>
					<ixx>0.0016496499283931443</ixx>
					<ixy>-0.0002503210943605508</ixy>
					<ixz>0.002062477662272456</ixz>
					<iyy>0.0042451556521400455</iyy>
					<iyz>0.00019712546707711148</iyz>
					<izz>0.002644708495990919</izz>
				</inertia>
			</inertial>
			<collision name="hand_left_middle_link2_collision">
				<geometry>
					<mesh>
						<uri>model://roboy_icecream/meshes/CAD/hand_left_middle_link2.stl</uri>
						<scale>0.001 0.001 0.001</scale>
					</mesh>
				</geometry>
			</collision>
			<visual name="hand_left_middle_link2_visual">
				<geometry>
					<mesh>
						<uri>model://roboy_icecream/meshes/CAD/hand_left_middle_link2.stl</uri>
						<scale>0.001 0.001 0.001</scale>
					</mesh>
				</geometry>
			</visual>
		</link>
		<link name="hand_left_ring_link1">
			<self_collide>false</self_collide>
			<pose frame="">0.29536536101799366 -0.0057602830741271685 -0.21374200133641025 0.0 -0.0 0.0</pose>
			<inertial>
				<pose frame="">0.0 0.0 0.0 0 0 0</pose>
				<mass>0.03081993119277091</mass>
				<inertia>
					<ixx>0.0014112820155915667</ixx>
					<ixy>5.245327758269151e-05</ixy>
					<ixz>0.0019457430065403234</ixz>
					<iyy>0.004098689500416491</iyy>
					<iyz>-3.796221348763909e-05</iyz>
					<izz>0.002690915115347253</izz>
				</inertia>
			</inertial>
			<collision name="hand_left_ring_link1_collision">
				<geometry>
					<mesh>
						<uri>model://roboy_icecream/meshes/CAD/hand_left_ring_link1.stl</uri>
						<scale>0.001 0.001 0.001</scale>
					</mesh>
				</geometry>
			</collision>
			<visual name="hand_left_ring_link1_visual">
				<geometry>
					<mesh>
						<uri>model://roboy_icecream/meshes/CAD/hand_left_ring_link1.stl</uri>
						<scale>0.001 0.001 0.001</scale>
					</mesh>
				</geometry>
			</visual>
		</link>
		<link name="hand_left_ring_link0">
			<self_collide>false</self_collide>
			<pose frame="">0.29505285429724465 -0.005032514310069098 -0.1782351319545955 0.0 -0.0 0.0</pose>
			<inertial>
				<pose frame="">0.0 0.0 0.0 0 0 0</pose>
				<mass>0.05584692310229074</mass>
				<inertia>
					<ixx>0.00178572225628388</ixx>
					<ixy>8.294499358650277e-05</ixy>
					<ixz>0.002936914933848032</ixz>
					<iyy>0.006645725819071824</iyy>
					<iyz>-5.026839756016698e-05</iyz>
					<izz>0.004865176517705526</izz>
				</inertia>
			</inertial>
			<collision name="hand_left_ring_link0_collision">
				<geometry>
					<mesh>
						<uri>model://roboy_icecream/meshes/CAD/hand_left_ring_link0.stl</uri>
						<scale>0.001 0.001 0.001</scale>
					</mesh>
				</geometry>
			</collision>
			<visual name="hand_left_ring_link0_visual">
				<geometry>
					<mesh>
						<uri>model://roboy_icecream/meshes/CAD/hand_left_ring_link0.stl</uri>
						<scale>0.001 0.001 0.001</scale>
					</mesh>
				</geometry>
			</visual>
		</link>
		<link name="hand_left_ring_link2">
			<self_collide>false</self_collide>
			<pose frame="">0.29550938870619414 -0.006268557857029145 -0.23898339782045808 0.0 -0.0 0.0</pose>
			<inertial>
				<pose frame="">0.0 0.0 0.0 0 0 0</pose>
				<mass>0.030336893063835017</mass>
				<inertia>
					<ixx>0.0017357054051199924</ixx>
					<ixy>5.6210973744788156e-05</ixy>
					<ixz>0.002142417433743111</ixz>
					<iyy>0.004383465572290613</iyy>
					<iyz>-4.546259407263495e-05</iyz>
					<izz>0.0026514996601857102</izz>
				</inertia>
			</inertial>
			<collision name="hand_left_ring_link2_collision">
				<geometry>
					<mesh>
						<uri>model://roboy_icecream/meshes/CAD/hand_left_ring_link2.stl</uri>
						<scale>0.001 0.001 0.001</scale>
					</mesh>
				</geometry>
			</collision>
			<visual name="hand_left_ring_link2_visual">
				<geometry>
					<mesh>
						<uri>model://roboy_icecream/meshes/CAD/hand_left_ring_link2.stl</uri>
						<scale>0.001 0.001 0.001</scale>
					</mesh>
				</geometry>
			</visual>
		</link>
		<link name="hand_left_little_link1">
			<self_collide>false</self_collide>
			<pose frame="">0.29373686965404366 0.05193897993585741 -0.17309020893063257 0.0 -0.0 0.0</pose>
			<inertial>
				<pose frame="">0.0 0.0 0.0 0 0 0</pose>
				<mass>0.030820040312614812</mass>
				<inertia>
					<ixx>0.0010087484294714997</ixx>
					<ixy>-0.0004701886939661864</ixy>
					<ixz>0.001566996663163643</ixz>
					<iyy>0.003584468317934688</iyy>
					<iyz>0.0002771661559553228</iyz>
					<izz>0.0027434868879326496</izz>
				</inertia>
			</inertial>
			<collision name="hand_left_little_link1_collision">
				<geometry>
					<mesh>
						<uri>model://roboy_icecream/meshes/CAD/hand_left_little_link1.stl</uri>
						<scale>0.001 0.001 0.001</scale>
					</mesh>
				</geometry>
			</collision>
			<visual name="hand_left_little_link1_visual">
				<geometry>
					<mesh>
						<uri>model://roboy_icecream/meshes/CAD/hand_left_little_link1.stl</uri>
						<scale>0.001 0.001 0.001</scale>
					</mesh>
				</geometry>
			</visual>
		</link>
		<link name="hand_left_little_link2">
			<self_collide>false</self_collide>
			<pose frame="">0.2937045327700305 0.054943454636082335 -0.1981581038080974 0.0 -0.0 0.0</pose>
			<inertial>
				<pose frame="">0.0 0.0 0.0 0 0 0</pose>
				<mass>0.030336899812493857</mass>
				<inertia>
					<ixx>0.0012846784486993765</ixx>
					<ixy>-0.0004895375812775043</ixy>
					<ixz>0.0017655649799509616</ixz>
					<iyy>0.0038097819365074865</iyy>
					<iyz>0.00033035284298611213</iyz>
					<izz>0.0027096346628702073</izz>
				</inertia>
			</inertial>
			<collision name="hand_left_little_link2_collision">
				<geometry>
					<mesh>
						<uri>model://roboy_icecream/meshes/CAD/hand_left_little_link2.stl</uri>
						<scale>0.001 0.001 0.001</scale>
					</mesh>
				</geometry>
			</collision>
			<visual name="hand_left_little_link2_visual">
				<geometry>
					<mesh>
						<uri>model://roboy_icecream/meshes/CAD/hand_left_little_link2.stl</uri>
						<scale>0.001 0.001 0.001</scale>
					</mesh>
				</geometry>
			</visual>
		</link>
		<link name="hand_left_little_link0">
			<self_collide>false</self_collide>
			<pose frame="">0.294211967081785 0.048866339880860775 -0.14727673057052215 0.0 -0.0 0.0</pose>
			<inertial>
				<pose frame="">0.0 0.0 0.0 0 0 0</pose>
				<mass>0.030820040312614823</mass>
				<inertia>
					<ixx>0.000744327168425882</ixx>
					<ixy>-0.0004430876647832726</ixy>
					<ixz>0.0013354642065628846</ixz>
					<iyy>0.0033382022625346093</iyy>
					<iyz>0.00022189799176596702</iyz>
					<izz>0.002742549789706377</izz>
				</inertia>
			</inertial>
			<collision name="hand_left_little_link0_collision">
				<geometry>
					<mesh>
						<uri>model://roboy_icecream/meshes/CAD/hand_left_little_link0.stl</uri>
						<scale>0.001 0.001 0.001</scale>
					</mesh>
				</geometry>
			</collision>
			<visual name="hand_left_little_link0_visual">
				<geometry>
					<mesh>
						<uri>model://roboy_icecream/meshes/CAD/hand_left_little_link0.stl</uri>
						<scale>0.001 0.001 0.001</scale>
					</mesh>
				</geometry>
			</visual>
		</link>
		<link name="hand_left_thumb_link2">
			<self_collide>false</self_collide>
			<pose frame="">0.2855460663700445 -0.10366173356143069 -0.09495930783680757 0.0 -0.0 0.0</pose>
			<inertial>
				<pose frame="">0.0 0.0 0.0 0 0 0</pose>
				<mass>0.030336616654663515</mass>
				<inertia>
					<ixx>0.0006011041076284333</ixx>
					<ixy>0.0008980153703551927</ixy>
					<ixz>0.0008226100598619451</ixz>
					<iyy>0.0027482165015080703</iyy>
					<iyz>-0.00029867704538988154</iyz>
					<izz>0.002801447223794131</izz>
				</inertia>
			</inertial>
			<collision name="hand_left_thumb_link2_collision">
				<geometry>
					<mesh>
						<uri>model://roboy_icecream/meshes/CAD/hand_left_thumb_link2.stl</uri>
						<scale>0.001 0.001 0.001</scale>
					</mesh>
				</geometry>
			</collision>
			<visual name="hand_left_thumb_link2_visual">
				<geometry>
					<mesh>
						<uri>model://roboy_icecream/meshes/CAD/hand_left_thumb_link2.stl</uri>
						<scale>0.001 0.001 0.001</scale>
					</mesh>
				</geometry>
			</visual>
		</link>
		<link name="hand_left_thumb_link0">
			<self_collide>false</self_collide>
			<pose frame="">0.28230221018940993 -0.03996163594312155 -0.08477229576644303 0.0 -0.0 0.0</pose>
			<inertial>
				<pose frame="">0.0 0.0 0.0 0 0 0</pose>
				<mass>0.1164335559017092</mass>
				<inertia>
					<ixx>0.001048341188553048</ixx>
					<ixy>0.0013142170689855565</ixy>
					<ixz>0.0027864738744887855</ixz>
					<iyy>0.010126980572968564</iyy>
					<iyz>-0.00039706895568323994</iyz>
					<izz>0.009485909375986189</izz>
				</inertia>
			</inertial>
			<collision name="hand_left_thumb_link0_collision">
				<geometry>
					<mesh>
						<uri>model://roboy_icecream/meshes/CAD/hand_left_thumb_link0.stl</uri>
						<scale>0.001 0.001 0.001</scale>
					</mesh>
				</geometry>
			</collision>
			<visual name="hand_left_thumb_link0_visual">
				<geometry>
					<mesh>
						<uri>model://roboy_icecream/meshes/CAD/hand_left_thumb_link0.stl</uri>
						<scale>0.001 0.001 0.001</scale>
					</mesh>
				</geometry>
			</visual>
		</link>
		<link name="hand_left_thumb_link1">
			<self_collide>false</self_collide>
			<pose frame="">0.28410959831484095 -0.07847451913565916 -0.09595433493103192 0.0 -0.0 0.0</pose>
			<inertial>
				<pose frame="">0.0 0.0 0.0 0 0 0</pose>
				<mass>0.030821292278110753</mass>
				<inertia>
					<ixx>0.00047548952221584316</ixx>
					<ixy>0.0006872096447305894</ixy>
					<ixz>0.0008402345881578621</ixz>
					<iyy>0.002772757165271583</iyy>
					<iyz>-0.00023202605778512093</iyz>
					<izz>0.0026798688049792228</izz>
				</inertia>
			</inertial>
			<collision name="hand_left_thumb_link1_collision">
				<geometry>
					<mesh>
						<uri>model://roboy_icecream/meshes/CAD/hand_left_thumb_link1.stl</uri>
						<scale>0.001 0.001 0.001</scale>
					</mesh>
				</geometry>
			</collision>
			<visual name="hand_left_thumb_link1_visual">
				<geometry>
					<mesh>
						<uri>model://roboy_icecream/meshes/CAD/hand_left_thumb_link1.stl</uri>
						<scale>0.001 0.001 0.001</scale>
					</mesh>
				</geometry>
			</visual>
		</link>
		<link name="hand_left_palm">
			<self_collide>false</self_collide>
			<pose frame="">0.29683323797713995 0.0012636555104292735 -0.0933367071439152 0.0 -0.0 0.0</pose>
			<inertial>
				<pose frame="">0.0 0.0 0.0 0 0 0</pose>
				<mass>0.7882346365046045</mass>
				<inertia>
					<ixx>0.0081096320267064</ixx>
					<ixy>-0.0002731207331240032</ixy>
					<ixz>0.02190407003885087</ixz>
					<iyy>0.07706855844459774</iyy>
					<iyz>6.61299443477153e-05</iyz>
					<izz>0.07006875804131098</izz>
				</inertia>
			</inertial>
			<collision name="hand_left_palm_collision">
				<geometry>
					<mesh>
						<uri>model://roboy_icecream/meshes/CAD/hand_left_palm.stl</uri>
						<scale>0.001 0.001 0.001</scale>
					</mesh>
				</geometry>
			</collision>
			<visual name="hand_left_palm_visual">
				<geometry>
					<mesh>
						<uri>model://roboy_icecream/meshes/CAD/hand_left_palm.stl</uri>
						<scale>0.001 0.001 0.001</scale>
					</mesh>
				</geometry>
			</visual>
		</link>
		<link name="hand_right_index_link1">
			<self_collide>false</self_collide>
			<pose frame="">-0.29802794504366953 -0.027796507109106396 -0.2109667853007439 0.0 -0.0 0.0</pose>
			<inertial>
				<pose frame="">0.0 0.0 0.0 0 0 0</pose>
				<mass>0.030819928523728248</mass>
				<inertia>
					<ixx>0.0013977458286006696</ixx>
					<ixy>-0.0002553354576600338</ixy>
					<ixz>-0.0019377941748036566</ixz>
					<iyy>0.004111052095786885</iyy>
					<iyz>-0.00018079768215800238</iyz>
					<izz>0.0027624047605117746</izz>
				</inertia>
			</inertial>
			<collision name="hand_right_index_link1_collision">
				<geometry>
					<mesh>
						<uri>model://roboy_icecream/meshes/CAD/hand_right_index_link1.stl</uri>
						<scale>0.001 0.001 0.001</scale>
					</mesh>
				</geometry>
			</collision>
			<visual name="hand_right_index_link1_visual">
				<geometry>
					<mesh>
						<uri>model://roboy_icecream/meshes/CAD/hand_right_index_link1.stl</uri>
						<scale>0.001 0.001 0.001</scale>
					</mesh>
				</geometry>
			</visual>
		</link>
		<link name="hand_right_index_link0">
			<self_collide>false</self_collide>
			<pose frame="">-0.29759239670810833 -0.024683600914382688 -0.17559035856943858 0.0 -0.0 0.0</pose>
			<inertial>
				<pose frame="">0.0 0.0 0.0 0 0 0</pose>
				<mass>0.055846903810612934</mass>
				<inertia>
					<ixx>0.001766072770735144</ixx>
					<ixy>-0.00041025436120509896</ixy>
					<ixz>-0.0029182630289464623</ixz>
					<iyy>0.006677459725239644</iyy>
					<iyz>-0.00024272953746762662</iyz>
					<izz>0.004981894254499964</izz>
				</inertia>
			</inertial>
			<collision name="hand_right_index_link0_collision">
				<geometry>
					<mesh>
						<uri>model://roboy_icecream/meshes/CAD/hand_right_index_link0.stl</uri>
						<scale>0.001 0.001 0.001</scale>
					</mesh>
				</geometry>
			</collision>
			<visual name="hand_right_index_link0_visual">
				<geometry>
					<mesh>
						<uri>model://roboy_icecream/meshes/CAD/hand_right_index_link0.stl</uri>
						<scale>0.001 0.001 0.001</scale>
					</mesh>
				</geometry>
			</visual>
		</link>
		<link name="hand_right_index_link2">
			<self_collide>false</self_collide>
			<pose frame="">-0.2982603266809658 -0.03002577090957189 -0.23611369838086715 0.0 -0.0 0.0</pose>
			<inertial>
				<pose frame="">0.0 0.0 0.0 0 0 0</pose>
				<mass>0.030337118821034063</mass>
				<inertia>
					<ixx>0.0017205173247171082</ixx>
					<ixy>-0.000271699245726833</ixy>
					<ixz>-0.002136415839814085</ixz>
					<iyy>0.004391691407268722</iyy>
					<iyz>-0.0002151258376139562</iyz>
					<izz>0.002727239027173174</izz>
				</inertia>
			</inertial>
			<collision name="hand_right_index_link2_collision">
				<geometry>
					<mesh>
						<uri>model://roboy_icecream/meshes/CAD/hand_right_index_link2.stl</uri>
						<scale>0.001 0.001 0.001</scale>
					</mesh>
				</geometry>
			</collision>
			<visual name="hand_right_index_link2_visual">
				<geometry>
					<mesh>
						<uri>model://roboy_icecream/meshes/CAD/hand_right_index_link2.stl</uri>
						<scale>0.001 0.001 0.001</scale>
					</mesh>
				</geometry>
			</visual>
		</link>
		<link name="hand_right_middle_link1">
			<self_collide>false</self_collide>
			<pose frame="">-0.29624539656807103 0.005461026157536197 -0.2184623961108496 0.0 -0.0 0.0</pose>
			<inertial>
				<pose frame="">0.0 0.0 0.0 0 0 0</pose>
				<mass>0.03081999922495932</mass>
				<inertia>
					<ixx>0.0014740599178146795</ixx>
					<ixy>4.984400271790671e-05</ixy>
					<ixz>-0.0019946422371137865</ixz>
					<iyy>0.004177623272432178</iyy>
					<iyz>3.6770465224776334e-05</iyz>
					<izz>0.0027068632483079826</izz>
				</inertia>
			</inertial>
			<collision name="hand_right_middle_link1_collision">
				<geometry>
					<mesh>
						<uri>model://roboy_icecream/meshes/CAD/hand_right_middle_link1.stl</uri>
						<scale>0.001 0.001 0.001</scale>
					</mesh>
				</geometry>
			</collision>
			<visual name="hand_right_middle_link1_visual">
				<geometry>
					<mesh>
						<uri>model://roboy_icecream/meshes/CAD/hand_right_middle_link1.stl</uri>
						<scale>0.001 0.001 0.001</scale>
					</mesh>
				</geometry>
			</visual>
		</link>
		<link name="hand_right_middle_link0">
			<self_collide>false</self_collide>
			<pose frame="">-0.29596859363737676 0.00548337074375845 -0.18294767211577437 0.0 -0.0 0.0</pose>
			<inertial>
				<pose frame="">0.0 0.0 0.0 0 0 0</pose>
				<mass>0.05584691839812723</mass>
				<inertia>
					<ixx>0.0018810433416202661</ixx>
					<ixy>9.061393615603216e-05</ixy>
					<ixz>-0.00302391410715677</ixz>
					<iyy>0.006771011052083513</iyy>
					<iyz>5.6025893298785325e-05</iyz>
					<izz>0.004895662524913588</izz>
				</inertia>
			</inertial>
			<collision name="hand_right_middle_link0_collision">
				<geometry>
					<mesh>
						<uri>model://roboy_icecream/meshes/CAD/hand_right_middle_link0.stl</uri>
						<scale>0.001 0.001 0.001</scale>
					</mesh>
				</geometry>
			</collision>
			<visual name="hand_right_middle_link0_visual">
				<geometry>
					<mesh>
						<uri>model://roboy_icecream/meshes/CAD/hand_right_middle_link0.stl</uri>
						<scale>0.001 0.001 0.001</scale>
					</mesh>
				</geometry>
			</visual>
		</link>
		<link name="hand_right_middle_link2">
			<self_collide>false</self_collide>
			<pose frame="">-0.2963649175669183 0.005428620032126386 -0.24370863962939374 0.0 -0.0 0.0</pose>
			<inertial>
				<pose frame="">0.0 0.0 0.0 0 0 0</pose>
				<mass>0.03033711977138813</mass>
				<inertia>
					<ixx>0.0018046174545846868</ixx>
					<ixy>4.879367390909935e-05</ixy>
					<ixz>-0.0021911228261474007</ixz>
					<iyy>0.004468060975187511</iyy>
					<iyz>4.013313706123027e-05</iyz>
					<izz>0.0026665859924333425</izz>
				</inertia>
			</inertial>
			<collision name="hand_right_middle_link2_collision">
				<geometry>
					<mesh>
						<uri>model://roboy_icecream/meshes/CAD/hand_right_middle_link2.stl</uri>
						<scale>0.001 0.001 0.001</scale>
					</mesh>
				</geometry>
			</collision>
			<visual name="hand_right_middle_link2_visual">
				<geometry>
					<mesh>
						<uri>model://roboy_icecream/meshes/CAD/hand_right_middle_link2.stl</uri>
						<scale>0.001 0.001 0.001</scale>
					</mesh>
				</geometry>
			</visual>
		</link>
		<link name="hand_right_ring_link1">
			<self_collide>false</self_collide>
			<pose frame="">-0.29472287318656065 0.03743410441310239 -0.21019630851099544 0.0 -0.0 0.0</pose>
			<inertial>
				<pose frame="">0.0 0.0 0.0 0 0 0</pose>
				<mass>0.030820066243951855</mass>
				<inertia>
					<ixx>0.0014071270291391123</ixx>
					<ixy>0.0003400131091907865</ixy>
					<ixz>-0.0019093079755440642</ixz>
					<iyy>0.0040406898427808305</iyy>
					<iyz>0.00024257594870687497</iyz>
					<izz>0.002721413672851783</izz>
				</inertia>
			</inertial>
			<collision name="hand_right_ring_link1_collision">
				<geometry>
					<mesh>
						<uri>model://roboy_icecream/meshes/CAD/hand_right_ring_link1.stl</uri>
						<scale>0.001 0.001 0.001</scale>
					</mesh>
				</geometry>
			</collision>
			<visual name="hand_right_ring_link1_visual">
				<geometry>
					<mesh>
						<uri>model://roboy_icecream/meshes/CAD/hand_right_ring_link1.stl</uri>
						<scale>0.001 0.001 0.001</scale>
					</mesh>
				</geometry>
			</visual>
		</link>
		<link name="hand_right_ring_link0">
			<self_collide>false</self_collide>
			<pose frame="">-0.2946014898999604 0.034365529768459115 -0.17481324052208055 0.0 -0.0 0.0</pose>
			<inertial>
				<pose frame="">0.0 0.0 0.0 0 0 0</pose>
				<mass>0.05584580375610117</mass>
				<inertia>
					<ixx>0.0017827582709774538</ixx>
					<ixy>0.0005653662651931412</ixy>
					<ixz>-0.0028760223514491976</ixz>
					<iyy>0.006563206429323276</iyy>
					<iyz>0.00033617810587686936</iyz>
					<izz>0.004914810757074774</izz>
				</inertia>
			</inertial>
			<collision name="hand_right_ring_link0_collision">
				<geometry>
					<mesh>
						<uri>model://roboy_icecream/meshes/CAD/hand_right_ring_link0.stl</uri>
						<scale>0.001 0.001 0.001</scale>
					</mesh>
				</geometry>
			</collision>
			<visual name="hand_right_ring_link0_visual">
				<geometry>
					<mesh>
						<uri>model://roboy_icecream/meshes/CAD/hand_right_ring_link0.stl</uri>
						<scale>0.001 0.001 0.001</scale>
					</mesh>
				</geometry>
			</visual>
		</link>
		<link name="hand_right_ring_link2">
			<self_collide>false</self_collide>
			<pose frame="">-0.2947318848901617 0.03959898310746472 -0.23534994025120148 0.0 -0.0 0.0</pose>
			<inertial>
				<pose frame="">0.0 0.0 0.0 0 0 0</pose>
				<mass>0.03033711666638585</mass>
				<inertia>
					<ixx>0.0017298128118504268</ixx>
					<ixy>0.0003540530144456865</ixy>
					<ixz>-0.002104307339454547</ixz>
					<iyy>0.004317291065922902</iyy>
					<iyz>0.00028277520697666636</iyz>
					<izz>0.002683982874848568</izz>
				</inertia>
			</inertial>
			<collision name="hand_right_ring_link2_collision">
				<geometry>
					<mesh>
						<uri>model://roboy_icecream/meshes/CAD/hand_right_ring_link2.stl</uri>
						<scale>0.001 0.001 0.001</scale>
					</mesh>
				</geometry>
			</collision>
			<visual name="hand_right_ring_link2_visual">
				<geometry>
					<mesh>
						<uri>model://roboy_icecream/meshes/CAD/hand_right_ring_link2.stl</uri>
						<scale>0.001 0.001 0.001</scale>
					</mesh>
				</geometry>
			</visual>
		</link>
		<link name="hand_right_little_link1">
			<self_collide>false</self_collide>
			<pose frame="">-0.2939195087344591 0.061396990981062105 -0.17666954111873093 0.0 -0.0 0.0</pose>
			<inertial>
				<pose frame="">0.0 0.0 0.0 0 0 0</pose>
				<mass>0.030820092306724695</mass>
				<inertia>
					<ixx>0.0010803711361580645</ixx>
					<ixy>0.0005561581051304459</ixy>
					<ixz>-0.0016003966666588358</ixz>
					<iyy>0.0036263616987721905</iyy>
					<iyz>0.00033441192132689065</iyz>
					<izz>0.00277984096625541</izz>
				</inertia>
			</inertial>
			<collision name="hand_right_little_link1_collision">
				<geometry>
					<mesh>
						<uri>model://roboy_icecream/meshes/CAD/hand_right_little_link1.stl</uri>
						<scale>0.001 0.001 0.001</scale>
					</mesh>
				</geometry>
			</collision>
			<visual name="hand_right_little_link1_visual">
				<geometry>
					<mesh>
						<uri>model://roboy_icecream/meshes/CAD/hand_right_little_link1.stl</uri>
						<scale>0.001 0.001 0.001</scale>
					</mesh>
				</geometry>
			</visual>
		</link>
		<link name="hand_right_little_link2">
			<self_collide>false</self_collide>
			<pose frame="">-0.2938636962845659 0.06487342392522413 -0.20167594061949243 0.0 -0.0 0.0</pose>
			<inertial>
				<pose frame="">0.0 0.0 0.0 0 0 0</pose>
				<mass>0.03033711516204795</mass>
				<inertia>
					<ixx>0.0013634555356794866</ixx>
					<ixy>0.0005783319800132448</ixy>
					<ixz>-0.0017978980783896223</ixz>
					<iyy>0.0038553192923023076</iyy>
					<iyz>0.00039698519067466847</iyz>
					<izz>0.002748591813507502</izz>
				</inertia>
			</inertial>
			<collision name="hand_right_little_link2_collision">
				<geometry>
					<mesh>
						<uri>model://roboy_icecream/meshes/CAD/hand_right_little_link2.stl</uri>
						<scale>0.001 0.001 0.001</scale>
					</mesh>
				</geometry>
			</collision>
			<visual name="hand_right_little_link2_visual">
				<geometry>
					<mesh>
						<uri>model://roboy_icecream/meshes/CAD/hand_right_little_link2.stl</uri>
						<scale>0.001 0.001 0.001</scale>
					</mesh>
				</geometry>
			</visual>
		</link>
		<link name="hand_right_little_link0">
			<self_collide>false</self_collide>
			<pose frame="">-0.29441848832812845 0.057839071590573436 -0.15091891534281981 0.0 -0.0 0.0</pose>
			<inertial>
				<pose frame="">0.0 0.0 0.0 0 0 0</pose>
				<mass>0.030820092306724688</mass>
				<inertia>
					<ixx>0.0008073100475423453</ixx>
					<ixy>0.0005248177263750359</ixy>
					<ixz>-0.001369452289262568</ixz>
					<iyy>0.0033754233018467527</iyy>
					<iyz>0.00026913594351672416</iyz>
					<izz>0.002775813900668565</izz>
				</inertia>
			</inertial>
			<collision name="hand_right_little_link0_collision">
				<geometry>
					<mesh>
						<uri>model://roboy_icecream/meshes/CAD/hand_right_little_link0.stl</uri>
						<scale>0.001 0.001 0.001</scale>
					</mesh>
				</geometry>
			</collision>
			<visual name="hand_right_little_link0_visual">
				<geometry>
					<mesh>
						<uri>model://roboy_icecream/meshes/CAD/hand_right_little_link0.stl</uri>
						<scale>0.001 0.001 0.001</scale>
					</mesh>
				</geometry>
			</visual>
		</link>
		<link name="hand_right_thumb_link2">
			<self_collide>false</self_collide>
			<pose frame="">-0.2863161602770125 -0.09471307201731476 -0.10191416118121753 0.0 -0.0 0.0</pose>
			<inertial>
				<pose frame="">0.0 0.0 0.0 0 0 0</pose>
				<mass>0.03033691470620726</mass>
				<inertia>
					<ixx>0.000588794649234034</ixx>
					<ixy>-0.0008227165744112494</ixy>
					<ixz>-0.0008852497664979485</ixz>
					<iyy>0.0028031477134868783</iyy>
					<iyz>-0.0002929023321585444</iyz>
					<izz>0.002760979773798425</izz>
				</inertia>
			</inertial>
			<collision name="hand_right_thumb_link2_collision">
				<geometry>
					<mesh>
						<uri>model://roboy_icecream/meshes/CAD/hand_right_thumb_link2.stl</uri>
						<scale>0.001 0.001 0.001</scale>
					</mesh>
				</geometry>
			</collision>
			<visual name="hand_right_thumb_link2_visual">
				<geometry>
					<mesh>
						<uri>model://roboy_icecream/meshes/CAD/hand_right_thumb_link2.stl</uri>
						<scale>0.001 0.001 0.001</scale>
					</mesh>
				</geometry>
			</visual>
		</link>
		<link name="hand_right_thumb_link0">
			<self_collide>false</self_collide>
			<pose frame="">-0.2833744409590411 -0.031245490313719728 -0.09028614142258572 0.0 -0.0 0.0</pose>
			<inertial>
				<pose frame="">0.0 0.0 0.0 0 0 0</pose>
				<mass>0.1164329483581609</mass>
				<inertia>
					<ixx>0.0010884578373616318</ixx>
					<ixy>-0.001031623811453484</ixy>
					<ixz>-0.002979013350833632</ixz>
					<iyy>0.010310061011896889</iyy>
					<iyz>-0.00033131217496780836</iyz>
					<izz>0.009484091782943398</izz>
				</inertia>
			</inertial>
			<collision name="hand_right_thumb_link0_collision">
				<geometry>
					<mesh>
						<uri>model://roboy_icecream/meshes/CAD/hand_right_thumb_link0.stl</uri>
						<scale>0.001 0.001 0.001</scale>
					</mesh>
				</geometry>
			</collision>
			<visual name="hand_right_thumb_link0_visual">
				<geometry>
					<mesh>
						<uri>model://roboy_icecream/meshes/CAD/hand_right_thumb_link0.stl</uri>
						<scale>0.001 0.001 0.001</scale>
					</mesh>
				</geometry>
			</visual>
		</link>
		<link name="hand_right_thumb_link1">
			<self_collide>false</self_collide>
			<pose frame="">-0.28518126210600175 -0.06949389686738094 -0.10234034214719438 0.0 -0.0 0.0</pose>
			<inertial>
				<pose frame="">0.0 0.0 0.0 0 0 0</pose>
				<mass>0.030820279205615926</mass>
				<inertia>
					<ixx>0.00047354686435865923</ixx>
					<ixy>-0.0006108457794926406</ixy>
					<ixz>-0.0008995080597354184</ixz>
					<iyy>0.0028304983226064926</iyy>
					<iyz>-0.00021916236474813633</iyz>
					<izz>0.0026576333055511924</izz>
				</inertia>
			</inertial>
			<collision name="hand_right_thumb_link1_collision">
				<geometry>
					<mesh>
						<uri>model://roboy_icecream/meshes/CAD/hand_right_thumb_link1.stl</uri>
						<scale>0.001 0.001 0.001</scale>
					</mesh>
				</geometry>
			</collision>
			<visual name="hand_right_thumb_link1_visual">
				<geometry>
					<mesh>
						<uri>model://roboy_icecream/meshes/CAD/hand_right_thumb_link1.stl</uri>
						<scale>0.001 0.001 0.001</scale>
					</mesh>
				</geometry>
			</visual>
		</link>
		<link name="bike_back">
			<self_collide>false</self_collide>
			<pose frame="">-0.00011016712007182441 -0.36126275744903424 -0.5575062332679439 0.0 -0.0 0.0</pose>
			<inertial>
				<pose frame="">0.0 0.0 0.0 0 0 0</pose>
				<mass>12.95134492036292</mass>
				<inertia>
					<ixx>8.442264729699302</ixx>
					<ixy>0.05546017500224689</ixy>
					<ixz>-0.0017735467712802575</ixz>
					<iyy>4.264300775944789</iyy>
					<iyz>-2.9995137524469553</iyz>
					<izz>4.303003496245288</izz>
				</inertia>
			</inertial>
			<collision name="bike_back_collision">
				<geometry>
					<mesh>
						<uri>model://roboy_icecream/meshes/CAD/bike_back.stl</uri>
						<scale>0.001 0.001 0.001</scale>
					</mesh>
				</geometry>
			</collision>
			<visual name="bike_back_visual">
				<geometry>
					<mesh>
						<uri>model://roboy_icecream/meshes/CAD/bike_back.stl</uri>
						<scale>0.001 0.001 0.001</scale>
					</mesh>
				</geometry>
			</visual>
		</link>
		<link name="bike_front">
			<self_collide>false</self_collide>
			<pose frame="">-0.00037820010342195663 -0.8693054887433815 0.08557190035773946 0.0 -0.0 0.0</pose>
			<inertial>
				<pose frame="">0.0 0.0 0.0 0 0 0</pose>
				<mass>1286.0735575666731</mass>
				<inertia>
					<ixx>1309.930820530021</ixx>
					<ixy>1.0887808321170818</ixy>
					<ixz>0.8803936253774313</ixz>
					<iyy>143.49238189135068</iyy>
					<iyz>-26.118381241082727</iyz>
					<izz>1223.7503807159978</izz>
				</inertia>
			</inertial>
			<collision name="bike_front_collision">
				<geometry>
					<mesh>
						<uri>model://roboy_icecream/meshes/CAD/bike_front.stl</uri>
						<scale>0.001 0.001 0.001</scale>
					</mesh>
				</geometry>
			</collision>
			<visual name="bike_front_visual">
				<geometry>
					<mesh>
						<uri>model://roboy_icecream/meshes/CAD/bike_front.stl</uri>
						<scale>0.001 0.001 0.001</scale>
					</mesh>
				</geometry>
			</visual>
		</link>
		<link name="ice_right">
			<self_collide>false</self_collide>
			<pose frame="">-0.12194000366371936 -0.5928314675817741 0.3241554270570625 0.0 -0.0 0.0</pose>
			<inertial>
				<pose frame="">0.0 0.0 0.0 0 0 0</pose>
				<mass>223.724999999968</mass>
				<inertia>
					<ixx>107.50798517446542</ixx>
					<ixy>-16.173051463053042</ixy>
					<ixz>8.843293061360113</ixz>
					<iyy>29.83437223173023</iyy>
					<iyz>44.31003474165655</iyz>
					<izz>86.47467008535332</izz>
				</inertia>
			</inertial>
			<collision name="ice_right_collision">
				<geometry>
					<mesh>
						<uri>model://roboy_icecream/meshes/CAD/ice_right.stl</uri>
						<scale>0.001 0.001 0.001</scale>
					</mesh>
				</geometry>
			</collision>
			<visual name="ice_right_visual">
				<geometry>
					<mesh>
						<uri>model://roboy_icecream/meshes/CAD/ice_right.stl</uri>
						<scale>0.001 0.001 0.001</scale>
					</mesh>
				</geometry>
			</visual>
		</link>
		<link name="ice_left">
			<self_collide>false</self_collide>
			<pose frame="">0.11805999633626757 -0.59283146758177 0.3241554270570744 0.0 -0.0 0.0</pose>
			<inertial>
				<pose frame="">0.0 0.0 0.0 0 0 0</pose>
				<mass>223.72499999997825</mass>
				<inertia>
					<ixx>107.507985174471</ixx>
					<ixy>15.658441357276965</ixy>
					<ixz>-8.561908439038996</ixz>
					<iyy>29.62603911829324</iyy>
					<iyz>44.31003474165986</iyz>
					<izz>86.26633697191619</izz>
				</inertia>
			</inertial>
			<collision name="ice_left_collision">
				<geometry>
					<mesh>
						<uri>model://roboy_icecream/meshes/CAD/ice_left.stl</uri>
						<scale>0.001 0.001 0.001</scale>
					</mesh>
				</geometry>
			</collision>
			<visual name="ice_left_visual">
				<geometry>
					<mesh>
						<uri>model://roboy_icecream/meshes/CAD/ice_left.stl</uri>
						<scale>0.001 0.001 0.001</scale>
					</mesh>
				</geometry>
			</visual>
		</link>
		<link name="sphere_link1">
			<self_collide>false</self_collide>
			<pose frame="">-0.2653954527924725 -0.018887866786133602 -0.11379744618355032 0.0 -0.0 0.0</pose>
			<inertial>
				<pose frame="">0.0 0.0 0.0 0 0 0</pose>
				<mass>0.0380636073185614</mass>
				<inertia>
					<ixx>0.000508176230091826</ixx>
					<ixy>-0.00019080350019897474</ixy>
					<ixz>-0.0011495713660317828</ixz>
					<iyy>0.003175597480686683</iyy>
					<iyz>-8.181357510811029e-05</iyz>
					<izz>0.0026962584186364146</izz>
				</inertia>
			</inertial>
			<collision name="sphere_link1_collision">
				<geometry>
					<mesh>
						<uri>model://roboy_icecream/meshes/CAD/sphere_link1.stl</uri>
						<scale>0.001 0.001 0.001</scale>
					</mesh>
				</geometry>
			</collision>
			<visual name="sphere_link1_visual">
				<geometry>
					<mesh>
						<uri>model://roboy_icecream/meshes/CAD/sphere_link1.stl</uri>
						<scale>0.001 0.001 0.001</scale>
					</mesh>
				</geometry>
			</visual>
		</link>
		<link name="sphere_link2">
			<self_collide>false</self_collide>
			<pose frame="">-0.2653953537818476 -0.0188878785462205 -0.11379734678037905 0.0 -0.0 0.0</pose>
			<inertial>
				<pose frame="">0.0 0.0 0.0 0 0 0</pose>
				<mass>0.002996372533076606</mass>
				<inertia>
					<ixx>3.9895765680050054e-05</ixx>
					<ixy>-1.5020082023172697e-05</ixy>
					<ixz>-9.049430715461394e-05</ixz>
					<iyy>0.00024987538582296455</iyy>
					<iyz>-6.44037455179304e-06</iyz>
					<izz>0.00021214181428445342</izz>
				</inertia>
			</inertial>
			<collision name="sphere_link2_collision">
				<geometry>
					<mesh>
						<uri>model://roboy_icecream/meshes/CAD/sphere_link2.stl</uri>
						<scale>0.001 0.001 0.001</scale>
					</mesh>
				</geometry>
			</collision>
			<visual name="sphere_link2_visual">
				<geometry>
					<mesh>
						<uri>model://roboy_icecream/meshes/CAD/sphere_link2.stl</uri>
						<scale>0.001 0.001 0.001</scale>
					</mesh>
				</geometry>
			</visual>
		</link>
		<link name="zed_mini">
			<self_collide>false</self_collide>
			<pose frame="">-0.001019700980953229 -0.11846878800848305 0.3935576598835387 0.0 -0.0 0.0</pose>
			<inertial>
				<pose frame="">0.0 0.0 0.0 0 0 0</pose>
				<mass>0.4361891515825777</mass>
				<inertia>
					<ixx>0.07372570032900569</ixx>
					<ixy>-6.0396316991364956e-05</ixy>
					<ixz>0.00017504257606619554</ixz>
					<iyy>0.0681333744138437</iyy>
					<iyz>0.020337006242750425</iyz>
					<izz>0.006694076484380283</izz>
				</inertia>
			</inertial>
			<collision name="zed_mini_collision">
				<geometry>
					<mesh>
						<uri>model://roboy_icecream/meshes/CAD/zed_mini.stl</uri>
						<scale>0.001 0.001 0.001</scale>
					</mesh>
				</geometry>
			</collision>
			<visual name="zed_mini_visual">
				<geometry>
					<mesh>
						<uri>model://roboy_icecream/meshes/CAD/zed_mini.stl</uri>
						<scale>0.001 0.001 0.001</scale>
					</mesh>
				</geometry>
			</visual>
		</link>
		<link name="pico_flexx">
			<self_collide>false</self_collide>
			<pose frame="">0.01636582286047142 -0.11769402429443933 0.41518622532478316 0.0 -0.0 0.0</pose>
			<inertial>
				<pose frame="">0.0 0.0 0.0 0 0 0</pose>
				<mass>0.015436810520105988</mass>
				<inertia>
					<ixx>0.002875421261491332</ixx>
					<ixy>2.9660169029790846e-05</ixy>
					<ixz>-0.00010489308848843664</ixz>
					<iyy>0.0026725118905498264</iyy>
					<iyz>0.0007543345735127458</iyz>
					<izz>0.00022486643967097432</izz>
				</inertia>
			</inertial>
			<collision name="pico_flexx_collision">
				<geometry>
					<mesh>
						<uri>model://roboy_icecream/meshes/CAD/pico_flexx.stl</uri>
						<scale>0.001 0.001 0.001</scale>
					</mesh>
				</geometry>
			</collision>
			<visual name="pico_flexx_visual">
				<geometry>
					<mesh>
						<uri>model://roboy_icecream/meshes/CAD/pico_flexx.stl</uri>
						<scale>0.001 0.001 0.001</scale>
					</mesh>
				</geometry>
			</visual>
		</link>
		<joint name="wrist_left" type="revolute">
			<parent>arm_left_lower</parent>
			<child>hand_left_palm</child>
			<pose frame="">-0.01112032529696716 1.708013181114576e-05 0.04596644048323206 0 0 0</pose>
			<axis>
				<xyz>-0.011188426489531155 -0.022909252225327765 -0.9996749398055007</xyz>
				<limit>
					<lower>-0.8726646259971648</lower>
					<upper>0.8726646259971648</upper>
				</limit>
				<use_parent_model_frame>0</use_parent_model_frame>
			</axis>
		</joint>
		<joint name="spine" type="revolute">
			<parent>torso</parent>
			<child>bike_back</child>
			<pose frame="">0.00011016712009334052 0.36124080296251676 0.8568435077144142 0 0 0</pose>
			<axis>
				<xyz>8.881784197001363e-16 -8.242182021273602e-15 -1.0000000000000013</xyz>
				<limit>
					<lower>0.0</lower>
					<upper>0.0</upper>
				</limit>
				<use_parent_model_frame>0</use_parent_model_frame>
			</axis>
		</joint>
		<joint name="wrist_right" type="revolute">
			<parent>arm_right_lower</parent>
			<child>palm_right</child>
			<pose frame="">0.007063975929724222 0.002562951319765832 0.04792469067486671 0 0 0</pose>
			<axis>
				<xyz>0.012342838793137056 -0.00025121261310204554 -0.999923792707598</xyz>
				<limit>
					<lower>-0.8726646259971648</lower>
					<upper>0.8726646259971648</upper>
				</limit>
				<use_parent_model_frame>0</use_parent_model_frame>
			</axis>
		</joint>
		<joint name="ice_tray_0" type="prismatic">
			<parent>bike_front</parent>
			<child>ice_left</child>
			<pose frame="">0.12000000000001469 -0.14318103339883018 0.22700317547303428 0 0 0</pose>
			<axis>
				<xyz>-3.6150825819961146e-14 0.4999999999999186 0.8660254037845042</xyz>
				<limit>
					<lower>0.0</lower>
					<upper>0.0</upper>
				</limit>
				<use_parent_model_frame>0</use_parent_model_frame>
			</axis>
		</joint>
		<joint name="ice_tray_1" type="prismatic">
			<parent>bike_front</parent>
			<child>ice_right</child>
			<pose frame="">0.11999999999997707 -0.14318103339884153 0.22700317547304713 0 0 0</pose>
			<axis>
				<xyz>-3.6150825819961146e-14 0.4999999999999186 0.8660254037845042</xyz>
				<limit>
					<lower>0.0</lower>
					<upper>0.0</upper>
				</limit>
				<use_parent_model_frame>0</use_parent_model_frame>
			</axis>
		</joint>
		<joint name="zed_pico_attachement" type="fixed">
			<parent>zed_mini</parent>
			<child>pico_flexx</child>
			<pose frame="">0.04170918832895287 0.0022156345492233775 -0.008311850212956173 0 0 0</pose>
		</joint>
		<joint name="zed_mini_attachement" type="fixed">
			<parent>torso</parent>
			<child>zed_mini</child>
			<pose frame="">0.0014947135695966053 0.00964539826326817 0.03000459728702701 0 0 0</pose>
		</joint>
		<joint name="shoulder_left_axis0" type="revolute">
			<parent>torso</parent>
			<child>shoulder_left_link1</child>
			<pose frame="">-1.1385505445105081e-08 1.2559192860583934e-07 1.4254478415409721e-08 0 0 0</pose>
			<axis>
				<xyz>-0.9986354432836135 -0.05074429632816786 0.012339684270767625</xyz>
				<limit>
					<lower>-3.141592653589793</lower>
					<upper>3.141592653589793</upper>
				</limit>
				<use_parent_model_frame>0</use_parent_model_frame>
			</axis>
		</joint>
		<joint name="shoulder_left_axis1" type="revolute">
			<parent>shoulder_left_link1</parent>
			<child>shoulder_left_link2</child>
			<pose frame="">-3.552713678800501e-17 9.389691246752819e-12 -1.5701394318057283e-09 0 0 0</pose>
			<axis>
				<xyz>-0.05101049431667528 0.998448888302568 -0.022310242422104942</xyz>
				<limit>
					<lower>-3.141592653589793</lower>
					<upper>3.141592653589793</upper>
				</limit>
				<use_parent_model_frame>0</use_parent_model_frame>
			</axis>
		</joint>
		<joint name="shoulder_left_axis2" type="revolute">
			<parent>shoulder_left_link2</parent>
			<child>arm_left_upper</child>
			<pose frame="">0.001551507001244481 0.0034461213908218015 0.15067274032060687 0 0 0</pose>
			<axis>
				<xyz>-0.011188426489531611 -0.022909252225327616 -0.9996749398055182</xyz>
				<limit>
					<lower>-3.141592653589793</lower>
					<upper>3.141592653589793</upper>
				</limit>
				<use_parent_model_frame>0</use_parent_model_frame>
			</axis>
		</joint>
		<joint name="shoulder_right_axis0" type="revolute">
			<parent>torso</parent>
			<child>shoulder_right_link1</child>
			<pose frame="">-5.233583294739219e-08 -3.8736939575012564e-07 1.3259304864732258e-07 0 0 0</pose>
			<axis>
				<xyz>0.9986354432836153 -0.050744296328168695 0.012339684270770077</xyz>
				<limit>
					<lower>-3.141592653589793</lower>
					<upper>3.141592653589793</upper>
				</limit>
				<use_parent_model_frame>0</use_parent_model_frame>
			</axis>
		</joint>
		<joint name="shoulder_right_axis1" type="revolute">
			<parent>shoulder_right_link1</parent>
			<child>shoulder_right_link2</child>
			<pose frame="">1.4210854715202004e-16 1.0502709812953982e-15 8.668621376273222e-15 0 0 0</pose>
			<axis>
				<xyz>-0.050743529127072876 -0.9987116467140966 -0.0003754588500051825</xyz>
				<limit>
					<lower>-3.141592653589793</lower>
					<upper>3.141592653589793</upper>
				</limit>
				<use_parent_model_frame>0</use_parent_model_frame>
			</axis>
		</joint>
		<joint name="shoulder_right_axis2" type="revolute">
			<parent>shoulder_right_link2</parent>
			<child>arm_right_upper</child>
			<pose frame="">-0.0030093304567061453 0.0009088885804061042 0.2520955518543853 0 0 0</pose>
			<axis>
				<xyz>0.01234283879313641 -0.00025121261310212685 -0.9999237927075992</xyz>
				<limit>
					<lower>-3.141592653589793</lower>
					<upper>3.141592653589793</upper>
				</limit>
				<use_parent_model_frame>0</use_parent_model_frame>
			</axis>
		</joint>
		<joint name="neck_axis0" type="revolute">
			<parent>torso</parent>
			<child>neck_link1</child>
			<pose frame="">1.5061504170881626e-10 1.5061483921163798e-10 0.0 0 0 0</pose>
			<axis>
				<xyz>0.12498691257369461 -0.9921583904222635 6.724690979212187e-15</xyz>
				<limit>
					<lower>-0.5235987755982988</lower>
					<upper>0.5235987755982988</upper>
				</limit>
				<use_parent_model_frame>0</use_parent_model_frame>
			</axis>
		</joint>
		<joint name="neck_axis2" type="revolute">
			<parent>neck_link2</parent>
			<child>head</child>
			<pose frame="">-0.0005102180295663994 -0.04492411714425187 -0.14549971508594026 0 0 0</pose>
			<axis>
				<xyz>-2.4972812708040394e-14 3.6318961320475e-15 1.0</xyz>
				<limit>
					<lower>-0.5235987755982988</lower>
					<upper>0.5235987755982988</upper>
				</limit>
				<use_parent_model_frame>0</use_parent_model_frame>
			</axis>
		</joint>
		<joint name="neck_axis1" type="revolute">
			<parent>neck_link1</parent>
			<child>neck_link2</child>
			<pose frame="">1.2766228137374175e-10 1.27663441207293e-10 2.842170943040401e-16 0 0 0</pose>
			<axis>
				<xyz>-0.9921583904222635 -0.12498691257369464 -2.432304617639304e-14</xyz>
				<limit>
					<lower>-0.5235987755982988</lower>
					<upper>0.5235987755982988</upper>
				</limit>
				<use_parent_model_frame>0</use_parent_model_frame>
			</axis>
		</joint>
		<joint name="zed_camera_mount" type="fixed">
			<parent>head</parent>
			<child>zed_camera</child>
			<pose frame="">0.01743765468509108 0.001405588958414743 0.008052233827783653 0 0 0</pose>
		</joint>
		<joint name="zed_camera_right" type="fixed">
			<parent>zed_camera</parent>
			<child>zed_camera_right_lense</child>
			<pose frame="">-3.4778066173002385e-05 0.011070006217811717 -0.0023530140921069176 0 0 0</pose>
		</joint>
		<joint name="zed_camera_left" type="fixed">
			<parent>zed_camera</parent>
			<child>zed_camera_left_lense</child>
			<pose frame="">-5.466550911876311e-05 0.011069943702269311 -0.0023530142604900562 0 0 0</pose>
		</joint>
		<joint name="hand_left_middle_joint0" type="revolute">
			<parent>hand_left_palm</parent>
			<child>hand_left_middle_link0</child>
			<pose frame="">0.0024996188065917126 0.003366445998302492 0.02339552328463553 0 0 0</pose>
			<axis>
				<xyz>-0.04984124836444067 0.9966461617361063 0.06490206667093681</xyz>
				<limit>
					<lower>0.0</lower>
					<upper>0.0</upper>
				</limit>
				<use_parent_model_frame>0</use_parent_model_frame>
			</axis>
		</joint>
		<joint name="hand_left_ring_joint0" type="revolute">
			<parent>hand_left_palm</parent>
			<child>hand_left_ring_link0</child>
			<pose frame="">0.0023920456206226247 0.00539304639657504 0.023024428609077798 0 0 0</pose>
			<axis>
				<xyz>0.05101049428823881 -0.9984488883607987 0.022310239881113112</xyz>
				<limit>
					<lower>0.0</lower>
					<upper>0.0</upper>
				</limit>
				<use_parent_model_frame>0</use_parent_model_frame>
			</axis>
		</joint>
		<joint name="hand_left_little_joint0" type="revolute">
			<parent>hand_left_palm</parent>
			<child>hand_left_index_link0</child>
			<pose frame="">0.0022843435978567683 0.007379525511929841 0.022477894600925055 0 0 0</pose>
			<axis>
				<xyz>-0.05179151960618612 0.9926528159491245 -0.10935275709900355</xyz>
				<limit>
					<lower>0.0</lower>
					<upper>0.0</upper>
				</limit>
				<use_parent_model_frame>0</use_parent_model_frame>
			</axis>
		</joint>
		<joint name="hand_left_index_joint0" type="revolute">
			<parent>hand_left_palm</parent>
			<child>hand_left_little_link0</child>
			<pose frame="">0.0009191094691312785 0.0023712916305741773 0.014032276916130897 0 0 0</pose>
			<axis>
				<xyz>-0.04895693572932445 0.9919204043249638 0.1170347381241684</xyz>
				<limit>
					<lower>0.0</lower>
					<upper>0.0</upper>
				</limit>
				<use_parent_model_frame>0</use_parent_model_frame>
			</axis>
		</joint>
		<joint name="hand_left_thumb_joint0" type="revolute">
			<parent>hand_left_palm</parent>
			<child>hand_left_thumb_link0</child>
			<pose frame="">-0.0009610644949361458 0.01910681682879142 -0.00223062454306584 0 0 0</pose>
			<axis>
				<xyz>0.011188426489532242 0.022909252225326558 0.999674939805514</xyz>
				<limit>
					<lower>0.0</lower>
					<upper>0.0</upper>
				</limit>
				<use_parent_model_frame>0</use_parent_model_frame>
			</axis>
		</joint>
		<joint name="hand_left_index_joint1" type="revolute">
			<parent>hand_left_index_link0</parent>
			<child>hand_left_index_link1</child>
			<pose frame="">0.0015082819655487256 0.006300915604268438 0.013053510400089863 0 0 0</pose>
			<axis>
				<xyz>0.05179151960618249 -0.992652815949127 0.10935275709900215</xyz>
				<limit>
					<lower>0.0</lower>
					<upper>0.0</upper>
				</limit>
				<use_parent_model_frame>0</use_parent_model_frame>
			</axis>
		</joint>
		<joint name="hand_left_index_joint2" type="revolute">
			<parent>hand_left_index_link1</parent>
			<child>hand_left_index_link2</child>
			<pose frame="">0.0010743509351733849 0.006197774837368879 0.012305785590810955 0 0 0</pose>
			<axis>
				<xyz>0.051791519606184194 -0.9926528159491258 0.10935275709900279</xyz>
				<limit>
					<lower>0.0</lower>
					<upper>0.0</upper>
				</limit>
				<use_parent_model_frame>0</use_parent_model_frame>
			</axis>
		</joint>
		<joint name="hand_left_middle_joint1" type="revolute">
			<parent>hand_left_middle_link0</parent>
			<child>hand_left_middle_link1</child>
			<pose frame="">0.0016392752510748921 0.003939997311892931 0.013933588838560738 0 0 0</pose>
			<axis>
				<xyz>0.04984124836443789 -0.9966461617361048 -0.06490206667093751</xyz>
				<limit>
					<lower>0.0</lower>
					<upper>0.0</upper>
				</limit>
				<use_parent_model_frame>0</use_parent_model_frame>
			</axis>
		</joint>
		<joint name="hand_left_middle_joint2" type="revolute">
			<parent>hand_left_middle_link1</parent>
			<child>hand_left_middle_link2</child>
			<pose frame="">0.0011984655373087705 0.003968614147025913 0.013183966303175332 0 0 0</pose>
			<axis>
				<xyz>0.049841248364438526 -0.9966461617361044 -0.06490206667093776</xyz>
				<limit>
					<lower>0.0</lower>
					<upper>0.0</upper>
				</limit>
				<use_parent_model_frame>0</use_parent_model_frame>
			</axis>
		</joint>
		<joint name="hand_left_little_joint1" type="revolute">
			<parent>hand_left_little_link0</parent>
			<child>hand_left_little_link1</child>
			<pose frame="">0.0016788522750078628 0.0032054233921840238 0.01411603295007561 0 0 0</pose>
			<axis>
				<xyz>0.04895693572932328 -0.9919204043249622 -0.11703473812416906</xyz>
				<limit>
					<lower>0.0</lower>
					<upper>0.0</upper>
				</limit>
				<use_parent_model_frame>0</use_parent_model_frame>
			</axis>
		</joint>
		<joint name="hand_left_little_joint2" type="revolute">
			<parent>hand_left_little_link1</parent>
			<child>hand_left_little_link2</child>
			<pose frame="">0.0012360917311109176 0.0032735887480437854 0.013370449458288398 0 0 0</pose>
			<axis>
				<xyz>0.048956935729323296 -0.9919204043249632 -0.1170347381241711</xyz>
				<limit>
					<lower>0.0</lower>
					<upper>0.0</upper>
				</limit>
				<use_parent_model_frame>0</use_parent_model_frame>
			</axis>
		</joint>
		<joint name="hand_left_ring_joint1" type="revolute">
			<parent>hand_left_ring_link0</parent>
			<child>hand_left_ring_link1</child>
			<pose frame="">0.001573511011660571 0.005139821462327263 0.013544810162432554 0 0 0</pose>
			<axis>
				<xyz>0.051010494288236556 -0.9984488883607989 0.022310239881111537</xyz>
				<limit>
					<lower>0.0</lower>
					<upper>0.0</upper>
				</limit>
				<use_parent_model_frame>0</use_parent_model_frame>
			</axis>
		</joint>
		<joint name="hand_left_ring_joint2" type="revolute">
			<parent>hand_left_ring_link1</parent>
			<child>hand_left_ring_link2</child>
			<pose frame="">0.001136034766500842 0.005102378251627781 0.01279354268497066 0 0 0</pose>
			<axis>
				<xyz>0.05101049428823774 -0.9984488883607977 0.022310239881112373</xyz>
				<limit>
					<lower>0.0</lower>
					<upper>0.0</upper>
				</limit>
				<use_parent_model_frame>0</use_parent_model_frame>
			</axis>
		</joint>
		<joint name="hand_right_index_joint1" type="revolute">
			<parent>hand_right_index_link0</parent>
			<child>hand_right_index_link1</child>
			<pose frame="">-0.0020155492683139897 -0.0034466777598363006 0.014014938001170095 0 0 0</pose>
			<axis>
				<xyz>0.051626183941509786 0.9948893529790515 -0.08677506819671307</xyz>
				<limit>
					<lower>0.0</lower>
					<upper>0.0</upper>
				</limit>
				<use_parent_model_frame>0</use_parent_model_frame>
			</axis>
		</joint>
		<joint name="hand_right_index_joint2" type="revolute">
			<parent>hand_right_index_link1</parent>
			<child>hand_right_index_link2</child>
			<pose frame="">-0.0015810436413474349 -0.0035367948741371925 0.01326625072013087 0 0 0</pose>
			<axis>
				<xyz>0.0516261839415094 0.9948893529790476 -0.08677506819671245</xyz>
				<limit>
					<lower>0.0</lower>
					<upper>0.0</upper>
				</limit>
				<use_parent_model_frame>0</use_parent_model_frame>
			</axis>
		</joint>
		<joint name="hand_left_thumb_joint1" type="revolute">
			<parent>hand_left_thumb_link0</parent>
			<child>hand_left_thumb_link1</child>
			<pose frame="">-0.00542379677180211 0.013452382519349033 0.0014179778625461382 0 0 0</pose>
			<axis>
				<xyz>0.9986354432836054 0.05074429632816911 -0.012339684270769659</xyz>
				<limit>
					<lower>0.0</lower>
					<upper>0.0</upper>
				</limit>
				<use_parent_model_frame>0</use_parent_model_frame>
			</axis>
		</joint>
		<joint name="hand_left_thumb_joint2" type="revolute">
			<parent>hand_left_thumb_link1</parent>
			<child>hand_left_thumb_link2</child>
			<pose frame="">-0.005583923746935966 0.012677388634436753 0.0010036340555087619 0 0 0</pose>
			<axis>
				<xyz>-0.9986354432836059 -0.050744296328168355 0.0123396842707689</xyz>
				<limit>
					<lower>0.0</lower>
					<upper>0.0</upper>
				</limit>
				<use_parent_model_frame>0</use_parent_model_frame>
			</axis>
		</joint>
		<joint name="hand_right_index_joint0" type="revolute">
			<parent>palm_right</parent>
			<child>hand_right_index_link0</child>
			<pose frame="">-0.0028131391641338156 -0.0027806004298206633 0.02347834522841847 0 0 0</pose>
			<axis>
				<xyz>0.05162618394148187 0.9948893529790475 -0.08677506819672998</xyz>
				<limit>
					<lower>0.0</lower>
					<upper>0.0</upper>
				</limit>
				<use_parent_model_frame>0</use_parent_model_frame>
			</axis>
		</joint>
		<joint name="hand_right_middle_joint0" type="revolute">
			<parent>palm_right</parent>
			<child>hand_right_middle_link0</child>
			<pose frame="">-0.002912317796690651 -0.004816071540397454 0.023134424316041055 0 0 0</pose>
			<axis>
				<xyz>0.05074352906433636 0.9987116467153601 0.0003754639332382525</xyz>
				<limit>
					<lower>0.0</lower>
					<upper>0.0</upper>
				</limit>
				<use_parent_model_frame>0</use_parent_model_frame>
			</axis>
		</joint>
		<joint name="hand_right_ring_joint0" type="revolute">
			<parent>palm_right</parent>
			<child>hand_right_ring_link0</child>
			<pose frame="">-0.003007421184327228 -0.006814058582345273 0.022613944133882544 0 0 0</pose>
			<axis>
				<xyz>0.04947468535373819 0.9949331417803167 0.087523133492076</xyz>
				<limit>
					<lower>0.0</lower>
					<upper>0.0</upper>
				</limit>
				<use_parent_model_frame>0</use_parent_model_frame>
			</axis>
		</joint>
		<joint name="hand_right_little_joint0" type="revolute">
			<parent>palm_right</parent>
			<child>hand_right_little_link0</child>
			<pose frame="">-0.0021666110399336702 -0.006707951777146972 0.012830029429174524 0 0 0</pose>
			<axis>
				<xyz>0.04853190544031668 0.989027215659634 0.13953429986515434</xyz>
				<limit>
					<lower>0.0</lower>
					<upper>0.0</upper>
				</limit>
				<use_parent_model_frame>0</use_parent_model_frame>
			</axis>
		</joint>
		<joint name="hand_right_thumb_joint0" type="revolute">
			<parent>palm_right</parent>
			<child>hand_right_thumb_link0</child>
			<pose frame="">0.0009215301773278739 0.019151208397902072 0.007204123085534277 0 0 0</pose>
			<axis>
				<xyz>-0.012342838793178245 0.00025121261308564666 0.9999237927075988</xyz>
				<limit>
					<lower>0.0</lower>
					<upper>0.0</upper>
				</limit>
				<use_parent_model_frame>0</use_parent_model_frame>
			</axis>
		</joint>
		<joint name="hand_right_middle_joint1" type="revolute">
			<parent>hand_right_middle_link0</parent>
			<child>hand_right_middle_link1</child>
			<pose frame="">-0.002072476496508848 -0.0046552244996650146 0.01365263394758987 0 0 0</pose>
			<axis>
				<xyz>0.050743529064361775 0.9987116467153562 0.0003754639332559508</xyz>
				<limit>
					<lower>0.0</lower>
					<upper>0.0</upper>
				</limit>
				<use_parent_model_frame>0</use_parent_model_frame>
			</axis>
		</joint>
		<joint name="hand_right_middle_joint2" type="revolute">
			<parent>hand_right_middle_link1</parent>
			<child>hand_right_middle_link2</child>
			<pose frame="">-0.0016345793887148474 -0.004679285325599778 0.012900840076042712 0 0 0</pose>
			<axis>
				<xyz>0.05074352906436002 0.9987116467153562 0.0003754639332559343</xyz>
				<limit>
					<lower>0.0</lower>
					<upper>0.0</upper>
				</limit>
				<use_parent_model_frame>0</use_parent_model_frame>
			</axis>
		</joint>
		<joint name="hand_right_ring_joint1" type="revolute">
			<parent>hand_right_ring_link0</parent>
			<child>hand_right_ring_link1</child>
			<pose frame="">-0.0021262859651396226 -0.0058276992009931175 0.013186268019979153 0 0 0</pose>
			<axis>
				<xyz>0.04947468535376103 0.9949331417803101 0.08752313349209379</xyz>
				<limit>
					<lower>0.0</lower>
					<upper>0.0</upper>
				</limit>
				<use_parent_model_frame>0</use_parent_model_frame>
			</axis>
		</joint>
		<joint name="hand_right_ring_joint2" type="revolute">
			<parent>hand_right_ring_link1</parent>
			<child>hand_right_ring_link2</child>
			<pose frame="">-0.001685068018602145 -0.0057857013208338645 0.012437286116995629 0 0 0</pose>
			<axis>
				<xyz>0.04947468535376001 0.9949331417803088 0.08752313349209333</xyz>
				<limit>
					<lower>0.0</lower>
					<upper>0.0</upper>
				</limit>
				<use_parent_model_frame>0</use_parent_model_frame>
			</axis>
		</joint>
		<joint name="hand_right_thumb_joint1" type="revolute">
			<parent>hand_right_thumb_link0</parent>
			<child>hand_right_thumb_link1</child>
			<pose frame="">-0.004070531171370248 0.013899911090302917 0.001611451875300638 0 0 0</pose>
			<axis>
				<xyz>0.998635443283618 -0.050744296328192696 0.012339684270811722</xyz>
				<limit>
					<lower>0.0</lower>
					<upper>0.0</upper>
				</limit>
				<use_parent_model_frame>0</use_parent_model_frame>
			</axis>
		</joint>
		<joint name="hand_right_thumb_joint2" type="revolute">
			<parent>hand_right_thumb_link1</parent>
			<child>hand_right_thumb_link2</child>
			<pose frame="">-0.004304896529828177 0.013155120640487308 0.0011748919950105474 0 0 0</pose>
			<axis>
				<xyz>-0.9986354432836205 0.0507442963281923 -0.012339684270811844</xyz>
				<limit>
					<lower>0.0</lower>
					<upper>0.0</upper>
				</limit>
				<use_parent_model_frame>0</use_parent_model_frame>
			</axis>
		</joint>
		<joint name="hand_right_little_joint1" type="revolute">
			<parent>hand_right_little_link0</parent>
			<child>hand_right_little_link1</child>
			<pose frame="">-0.002156904658419734 -0.006510146331037001 0.012857936267698414 0 0 0</pose>
			<axis>
				<xyz>0.04853190544033895 0.9890272156596233 0.13953429986517193</xyz>
				<limit>
					<lower>0.0</lower>
					<upper>0.0</upper>
				</limit>
				<use_parent_model_frame>0</use_parent_model_frame>
			</axis>
		</joint>
		<joint name="hand_right_little_joint2" type="revolute">
			<parent>hand_right_little_link1</parent>
			<child>hand_right_little_link2</child>
			<pose frame="">-0.0017137375142284484 -0.006428659881749974 0.012113709971122972 0 0 0</pose>
			<axis>
				<xyz>0.04853190544033771 0.9890272156596251 0.13953429986517096</xyz>
				<limit>
					<lower>0.0</lower>
					<upper>0.0</upper>
				</limit>
				<use_parent_model_frame>0</use_parent_model_frame>
			</axis>
		</joint>
		<joint name="bike_steering" type="revolute">
			<parent>bike_back</parent>
			<child>bike_front</child>
			<pose frame="">-0.0015563171980319164 -0.33304325820437686 -0.6892346279284436 0 0 0</pose>
			<axis>
				<xyz>-1.8044974943364984e-16 -9.570458378672299e-08 0.9999999999999957</xyz>
				<limit>
					<lower>-0.5235987755982988</lower>
					<upper>0.5235987755982988</upper>
				</limit>
				<use_parent_model_frame>0</use_parent_model_frame>
			</axis>
		</joint>
		<joint name="elbow_left" type="revolute">
			<parent>arm_right_upper</parent>
			<child>arm_right_lower</child>
			<pose frame="">-0.016980052934313258 0.0008475095989118042 0.04051070712681227 0 0 0</pose>
			<axis>
				<xyz>-0.9986354432836136 0.050744296328171457 -0.012339684270769206</xyz>
				<limit>
					<lower>0.0</lower>
					<upper>1.9198621771937625</upper>
				</limit>
				<use_parent_model_frame>0</use_parent_model_frame>
			</axis>
		</joint>
		<joint name="scooper_axis0" type="revolute">
			<parent>palm_right</parent>
			<child>sphere_link1</child>
			<pose frame="">9.901062504980018e-08 -1.1760062330612441e-08 9.940317404755206e-08 0 0 0</pose>
			<axis>
				<xyz>0.050743529127074125 0.998711646714098 0.0003754588500069938</xyz>
				<limit>
					<lower>-3.141592653589793</lower>
					<upper>3.141592653589793</upper>
				</limit>
				<use_parent_model_frame>0</use_parent_model_frame>
			</axis>
		</joint>
		<joint name="scooper_axis1" type="revolute">
			<parent>sphere_link1</parent>
			<child>sphere_link2</child>
			<pose frame="">7.105427357601002e-17 2.446487457063995e-14 2.7888802378583933e-15 0 0 0</pose>
			<axis>
				<xyz>-0.9986354432836139 0.0507442963281716 -0.01233968427077307</xyz>
				<limit>
					<lower>-3.141592653589793</lower>
					<upper>3.141592653589793</upper>
				</limit>
				<use_parent_model_frame>0</use_parent_model_frame>
			</axis>
		</joint>
		<joint name="scooper_axis2" type="revolute">
			<parent>sphere_link2</parent>
			<child>scooper</child>
			<pose frame="">0.00045315850738010256 0.010554704063581631 -0.00025291097512425865 0 0 0</pose>
			<axis>
				<xyz>-0.012342838793139613 0.00025121261310145394 0.9999237927075986</xyz>
				<limit>
					<lower>-3.141592653589793</lower>
					<upper>3.141592653589793</upper>
				</limit>
				<use_parent_model_frame>0</use_parent_model_frame>
			</axis>
		</joint>
		<plugin filename="libcardsflow_gazebo_plugin.so" name="cardsflow_gazebo_plugin"/>
	</model>
</sdf>
