<?xml version="1.0" ?>
<sdf version="1.6">
	<model name="roboy_icecream">
		<link name="head">
			<self_collide>false</self_collide>
			<pose frame="">0.0005102180295691139 0.046445898229309404 0.8611776443142852 0.0 -0.0 0.0</pose>
			<inertial>
				<pose frame="">0.0 0.0 0.0 0 0 0</pose>
				<mass>2.049574035129589</mass>
				<inertia>
					<ixx>1.5567369122227759</ixx>
					<ixy>-6.313507101682236e-05</ixy>
					<ixz>-0.0010119595995300493</ixz>
					<iyy>1.5459780882221161</iyy>
					<iyz>-0.08466584811454989</iyz>
					<izz>0.0305276597273415</izz>
				</inertia>
			</inertial>
			<collision name="head_collision">
				<geometry>
					<mesh>
						<uri>model://roboy_icecream/meshes/CAD/head.stl</uri>
						<scale>0.001 0.001 0.001</scale>
					</mesh>
				</geometry>
			</collision>
			<visual name="head_visual">
				<geometry>
					<mesh>
						<uri>model://roboy_icecream/meshes/CAD/head.stl</uri>
						<scale>0.001 0.001 0.001</scale>
					</mesh>
				</geometry>
			</visual>
		</link>
		<link name="torso">
			<self_collide>false</self_collide>
			<pose frame="">1.5654144647214706e-16 0.001521781085073083 0.2993372744464763 0.0 -0.0 0.0</pose>
			<inertial>
				<pose frame="">0.0 0.0 0.0 0 0 0</pose>
				<mass>11.519352383740124</mass>
				<inertia>
					<ixx>3.1683367909806135</ixx>
					<ixy>-0.0013345135928581463</ixy>
					<ixz>0.0006117362846899188</ixz>
					<iyy>3.4235938506289556</iyy>
					<iyz>0.007981326615620964</iyz>
					<izz>0.3205526083913695</izz>
				</inertia>
			</inertial>
			<collision name="torso_collision">
				<geometry>
					<mesh>
						<uri>model://roboy_icecream/meshes/CAD/torso.stl</uri>
						<scale>0.001 0.001 0.001</scale>
					</mesh>
				</geometry>
			</collision>
			<visual name="torso_visual">
				<geometry>
					<mesh>
						<uri>model://roboy_icecream/meshes/CAD/torso.stl</uri>
						<scale>0.001 0.001 0.001</scale>
					</mesh>
				</geometry>
			</visual>
		</link>
		<link name="arm_left_upper">
			<self_collide>false</self_collide>
			<pose frame="">0.2902733064983893 0.010367603841951184 0.38864919769909423 0.0 -0.0 0.0</pose>
			<inertial>
				<pose frame="">0.0 0.0 0.0 0 0 0</pose>
				<mass>1.4300137594014342</mass>
				<inertia>
					<ixx>0.22136793263459453</ixx>
					<ixy>-0.004278111043210982</ixy>
					<ixz>-0.16139389085280778</ixz>
					<iyy>0.3411783307451333</iyy>
					<iyz>-0.005848933309680587</iyz>
					<izz>0.12155271588973547</izz>
				</inertia>
			</inertial>
			<collision name="arm_left_upper_collision">
				<geometry>
					<mesh>
						<uri>model://roboy_icecream/meshes/CAD/arm_left_upper.stl</uri>
						<scale>0.001 0.001 0.001</scale>
					</mesh>
				</geometry>
			</collision>
			<visual name="arm_left_upper_visual">
				<geometry>
					<mesh>
						<uri>model://roboy_icecream/meshes/CAD/arm_left_upper.stl</uri>
						<scale>0.001 0.001 0.001</scale>
					</mesh>
				</geometry>
			</visual>
		</link>
		<link name="palm_right">
			<self_collide>false</self_collide>
			<pose frame="">-0.29382955224475543 0.006571272251648853 -0.09988710802380311 0.0 -0.0 0.0</pose>
			<inertial>
				<pose frame="">0.0 0.0 0.0 0 0 0</pose>
				<mass>0.8992408456547932</mass>
				<inertia>
					<ixx>0.010369176573027682</ixx>
					<ixy>0.0018070430079445627</ixy>
					<ixz>-0.026407913123279843</ixz>
					<iyy>0.08749715761785029</iyy>
					<iyz>0.0005216008397877933</iyz>
					<izz>0.07848478303556808</izz>
				</inertia>
			</inertial>
			<collision name="palm_right_collision">
				<geometry>
					<mesh>
						<uri>model://roboy_icecream/meshes/CAD/palm_right.stl</uri>
						<scale>0.001 0.001 0.001</scale>
					</mesh>
				</geometry>
			</collision>
			<visual name="palm_right_visual">
				<geometry>
					<mesh>
						<uri>model://roboy_icecream/meshes/CAD/palm_right.stl</uri>
						<scale>0.001 0.001 0.001</scale>
					</mesh>
				</geometry>
			</visual>
		</link>
		<link name="scooper">
			<self_collide>false</self_collide>
			<pose frame="">-0.26970685642394704 -0.10374496234737031 -0.11382924822380462 0.0 -0.0 0.0</pose>
			<inertial>
				<pose frame="">0.0 0.0 0.0 0 0 0</pose>
				<mass>0.6635862444211904</mass>
				<inertia>
					<ixx>0.010376054570135643</ixx>
					<ixy>-0.005251521933909232</ixy>
					<ixz>-0.020030680115057476</ixz>
					<iyy>0.05554109173638395</iyy>
					<iyz>-0.0022205744568801577</iyz>
					<izz>0.04870870606527024</izz>
				</inertia>
			</inertial>
			<collision name="scooper_collision">
				<geometry>
					<mesh>
						<uri>model://roboy_icecream/meshes/CAD/scooper.stl</uri>
						<scale>0.001 0.001 0.001</scale>
					</mesh>
				</geometry>
			</collision>
			<visual name="scooper_visual">
				<geometry>
					<mesh>
						<uri>model://roboy_icecream/meshes/CAD/scooper.stl</uri>
						<scale>0.001 0.001 0.001</scale>
					</mesh>
				</geometry>
			</visual>
		</link>
		<link name="arm_right_upper">
			<self_collide>false</self_collide>
			<pose frame="">-0.29016453811576326 0.008325343188540873 0.29600783937746117 0.0 -0.0 0.0</pose>
			<inertial>
				<pose frame="">0.0 0.0 0.0 0 0 0</pose>
				<mass>2.98314384024382</mass>
				<inertia>
					<ixx>0.29217335254578813</ixx>
					<ixy>0.007195986428065332</ixy>
					<ixz>0.2566402710814884</ixz>
					<iyy>0.5430496409097104</iyy>
					<iyz>-0.006814109122042475</iyz>
					<izz>0.25340978516468865</izz>
				</inertia>
			</inertial>
			<collision name="arm_right_upper_collision">
				<geometry>
					<mesh>
						<uri>model://roboy_icecream/meshes/CAD/arm_right_upper.stl</uri>
						<scale>0.001 0.001 0.001</scale>
					</mesh>
				</geometry>
			</collision>
			<visual name="arm_right_upper_visual">
				<geometry>
					<mesh>
						<uri>model://roboy_icecream/meshes/CAD/arm_right_upper.stl</uri>
						<scale>0.001 0.001 0.001</scale>
					</mesh>
				</geometry>
			</visual>
		</link>
		<link name="arm_right_lower">
			<self_collide>false</self_collide>
			<pose frame="">-0.2891991226870085 0.009183753318322416 0.1451851425430673 0.0 -0.0 0.0</pose>
			<inertial>
				<pose frame="">0.0 0.0 0.0 0 0 0</pose>
				<mass>0.8498742157982011</mass>
				<inertia>
					<ixx>0.021387357764080524</ixx>
					<ixy>0.0022525419150179844</ixy>
					<ixz>0.03572288586998189</ixz>
					<iyy>0.09230453919802804</iyy>
					<iyz>-0.0011339797417804385</iyz>
					<izz>0.07140549493608427</izz>
				</inertia>
			</inertial>
			<collision name="arm_right_lower_collision">
				<geometry>
					<mesh>
						<uri>model://roboy_icecream/meshes/CAD/arm_right_lower.stl</uri>
						<scale>0.001 0.001 0.001</scale>
					</mesh>
				</geometry>
			</collision>
			<visual name="arm_right_lower_visual">
				<geometry>
					<mesh>
						<uri>model://roboy_icecream/meshes/CAD/arm_right_lower.stl</uri>
						<scale>0.001 0.001 0.001</scale>
					</mesh>
				</geometry>
			</visual>
		</link>
		<link name="shoulder_left_link1">
			<self_collide>false</self_collide>
			<pose frame="">0.29189388396936844 0.013936649708446084 0.5448924278024039 0.0 -0.0 0.0</pose>
			<inertial>
				<pose frame="">0.0 0.0 0.0 0 0 0</pose>
				<mass>0.09036188404972216</mass>
				<inertia>
					<ixx>0.02685378687433716</ixx>
					<ixy>-0.00036759420957439013</ixy>
					<ixz>-0.01437212697441521</ixz>
					<iyy>0.03453525279236198</iyy>
					<iyz>-0.0006862058794001133</iyz>
					<izz>0.0077236593139688075</izz>
				</inertia>
			</inertial>
			<collision name="shoulder_left_link1_collision">
				<geometry>
					<mesh>
						<uri>model://roboy_icecream/meshes/CAD/shoulder_left_link1.stl</uri>
						<scale>0.001 0.001 0.001</scale>
					</mesh>
				</geometry>
			</collision>
			<visual name="shoulder_left_link1_visual">
				<geometry>
					<mesh>
						<uri>model://roboy_icecream/meshes/CAD/shoulder_left_link1.stl</uri>
						<scale>0.001 0.001 0.001</scale>
					</mesh>
				</geometry>
			</visual>
		</link>
		<link name="shoulder_left_link2">
			<self_collide>false</self_collide>
			<pose frame="">0.29189387258386296 0.013936775290985024 0.5448924436270218 0.0 -0.0 0.0</pose>
			<inertial>
				<pose frame="">0.0 0.0 0.0 0 0 0</pose>
				<mass>0.00711317010884494</mass>
				<inertia>
					<ixx>0.0021134396605301214</ixx>
					<ixy>-2.893679789213243e-05</ixy>
					<ixz>-0.0011313551510286908</ixz>
					<iyy>0.00271811459643765</iyy>
					<iyz>-5.401772354685746e-05</iyz>
					<izz>0.000607540702812908</izz>
				</inertia>
			</inertial>
			<collision name="shoulder_left_link2_collision">
				<geometry>
					<mesh>
						<uri>model://roboy_icecream/meshes/CAD/shoulder_left_link2.stl</uri>
						<scale>0.001 0.001 0.001</scale>
					</mesh>
				</geometry>
			</collision>
			<visual name="shoulder_left_link2_visual">
				<geometry>
					<mesh>
						<uri>model://roboy_icecream/meshes/CAD/shoulder_left_link2.stl</uri>
						<scale>0.001 0.001 0.001</scale>
					</mesh>
				</geometry>
			</visual>
		</link>
		<link name="shoulder_right_link1">
			<self_collide>false</self_collide>
			<pose frame="">-0.29317381623663624 0.009234619138342707 0.5481032586387985 0.0 -0.0 0.0</pose>
			<inertial>
				<pose frame="">0.0 0.0 0.0 0 0 0</pose>
				<mass>0.09036760208789225</mass>
				<inertia>
					<ixx>0.02716277857038176</ixx>
					<ixy>0.00024465659548951447</ixy>
					<ixz>0.014521126966952602</ixz>
					<iyy>0.03492224741539772</iyy>
					<iyz>-0.00045739786268846115</iyz>
					<izz>0.0077819738648302085</izz>
				</inertia>
			</inertial>
			<collision name="shoulder_right_link1_collision">
				<geometry>
					<mesh>
						<uri>model://roboy_icecream/meshes/CAD/shoulder_right_link1.stl</uri>
						<scale>0.001 0.001 0.001</scale>
					</mesh>
				</geometry>
			</collision>
			<visual name="shoulder_right_link1_visual">
				<geometry>
					<mesh>
						<uri>model://roboy_icecream/meshes/CAD/shoulder_right_link1.stl</uri>
						<scale>0.001 0.001 0.001</scale>
					</mesh>
				</geometry>
			</visual>
		</link>
		<link name="shoulder_right_link2">
			<self_collide>false</self_collide>
			<pose frame="">-0.2931738685724693 0.009234231768945902 0.5481033912318385 0.0 -0.0 0.0</pose>
			<inertial>
				<pose frame="">0.0 0.0 0.0 0 0 0</pose>
				<mass>0.007113171768782596</mass>
				<inertia>
					<ixx>0.002137629132340016</ixx>
					<ixy>1.9257030781476826e-05</ixy>
					<ixz>0.0011430126664005362</ixz>
					<iyy>0.002748406222637266</iyy>
					<iyz>-3.600199406508284e-05</iyz>
					<izz>0.0006120927174830887</izz>
				</inertia>
			</inertial>
			<collision name="shoulder_right_link2_collision">
				<geometry>
					<mesh>
						<uri>model://roboy_icecream/meshes/CAD/shoulder_right_link2.stl</uri>
						<scale>0.001 0.001 0.001</scale>
					</mesh>
				</geometry>
			</collision>
			<visual name="shoulder_right_link2_visual">
				<geometry>
					<mesh>
						<uri>model://roboy_icecream/meshes/CAD/shoulder_right_link2.stl</uri>
						<scale>0.001 0.001 0.001</scale>
					</mesh>
				</geometry>
			</visual>
		</link>
		<link name="zed_camera_left_lense">
			<self_collide>false</self_collide>
			<pose frame="">0.060224029002958875 -0.06914536611449566 0.9297742812708069 0.0 -0.0 0.0</pose>
			<inertial>
				<pose frame="">0.0 0.0 0.0 0 0 0</pose>
				<mass>0.005755421856391891</mass>
				<inertia>
					<ixx>0.005003354055639959</ixx>
					<ixy>2.3967379469334976e-05</ixy>
					<ixz>-0.0003222735583266803</ixz>
					<iyy>0.004996529496255549</iyy>
					<iyz>0.000370054972711012</iyz>
					<izz>4.878384607433584e-05</izz>
				</inertia>
			</inertial>
			<collision name="zed_camera_left_lense_collision">
				<geometry>
					<mesh>
						<uri>model://roboy_icecream/meshes/CAD/zed_camera_left_lense.stl</uri>
						<scale>0.001 0.001 0.001</scale>
					</mesh>
				</geometry>
			</collision>
			<visual name="zed_camera_left_lense_visual">
				<geometry>
					<mesh>
						<uri>model://roboy_icecream/meshes/CAD/zed_camera_left_lense.stl</uri>
						<scale>0.001 0.001 0.001</scale>
					</mesh>
				</geometry>
			</visual>
		</link>
		<link name="zed_camera_right_lense">
			<self_collide>false</self_collide>
			<pose frame="">-0.05977745584801778 -0.06952236314727904 0.9297742812332496 0.0 -0.0 0.0</pose>
			<inertial>
				<pose frame="">0.0 0.0 0.0 0 0 0</pose>
				<mass>0.0057554218551259745</mass>
				<inertia>
					<ixx>0.0050036549322322954</ixx>
					<ixy>-2.391821338968771e-05</ixy>
					<ixz>0.00031988357548007145</ixz>
					<iyy>0.004996221065096928</iyy>
					<iyz>0.00037207237543609864</iyz>
					<izz>4.877629449989427e-05</izz>
				</inertia>
			</inertial>
			<collision name="zed_camera_right_lense_collision">
				<geometry>
					<mesh>
						<uri>model://roboy_icecream/meshes/CAD/zed_camera_right_lense.stl</uri>
						<scale>0.001 0.001 0.001</scale>
					</mesh>
				</geometry>
			</collision>
			<visual name="zed_camera_right_lense_visual">
				<geometry>
					<mesh>
						<uri>model://roboy_icecream/meshes/CAD/zed_camera_right_lense.stl</uri>
						<scale>0.001 0.001 0.001</scale>
					</mesh>
				</geometry>
			</visual>
		</link>
		<link name="zed_camera">
			<self_collide>false</self_collide>
			<pose frame="">0.004244484790251953 -0.057938621286604985 0.9271942136470953 0.0 -0.0 0.0</pose>
			<inertial>
				<pose frame="">0.0 0.0 0.0 0 0 0</pose>
				<mass>0.009633907989226701</mass>
				<inertia>
					<ixx>0.008314802982788687</ixx>
					<ixy>2.4365338952166025e-06</ixy>
					<ixz>-3.793293439362343e-05</ixz>
					<iyy>0.008297308522063661</iyy>
					<iyz>0.0005174870196291635</iyz>
					<izz>4.725323656366554e-05</izz>
				</inertia>
			</inertial>
			<collision name="zed_camera_collision">
				<geometry>
					<mesh>
						<uri>model://roboy_icecream/meshes/CAD/zed_camera.stl</uri>
						<scale>0.001 0.001 0.001</scale>
					</mesh>
				</geometry>
			</collision>
			<visual name="zed_camera_visual">
				<geometry>
					<mesh>
						<uri>model://roboy_icecream/meshes/CAD/zed_camera.stl</uri>
						<scale>0.001 0.001 0.001</scale>
					</mesh>
				</geometry>
			</visual>
		</link>
		<link name="neck_link1">
			<self_collide>false</self_collide>
			<pose frame="">-1.506123287543706e-10 0.0015217809344427158 0.7156779292283452 0.0 -0.0 0.0</pose>
			<inertial>
				<pose frame="">0.0 0.0 0.0 0 0 0</pose>
				<mass>0.017038665636260372</mass>
				<inertia>
					<ixx>0.008728267843512112</ixx>
					<ixy>3.905246324887799e-15</ixy>
					<ixz>1.836596576210159e-12</ixz>
					<iyy>0.008728228385076956</iyy>
					<iyz>-1.855689641317778e-05</iyz>
					<izz>1.150229285457388e-06</izz>
				</inertia>
			</inertial>
			<collision name="neck_link1_collision">
				<geometry>
					<mesh>
						<uri>model://roboy_icecream/meshes/CAD/neck_link1.stl</uri>
						<scale>0.001 0.001 0.001</scale>
					</mesh>
				</geometry>
			</collision>
			<visual name="neck_link1_visual">
				<geometry>
					<mesh>
						<uri>model://roboy_icecream/meshes/CAD/neck_link1.stl</uri>
						<scale>0.001 0.001 0.001</scale>
					</mesh>
				</geometry>
			</visual>
		</link>
		<link name="neck_link2">
			<self_collide>false</self_collide>
			<pose frame="">-1.2765957254235939e-10 0.0015217809573941732 0.7156779292283448 0.0 -0.0 0.0</pose>
			<inertial>
				<pose frame="">0.0 0.0 0.0 0 0 0</pose>
				<mass>0.011421521917888835</mass>
				<inertia>
					<ixx>0.005850573477666747</ixx>
					<ixy>2.21885727293928e-15</ixy>
					<ixz>1.0435059226432398e-12</ixz>
					<iyy>0.005850547027508899</iyy>
					<iyz>-1.243923713466404e-05</iyz>
					<izz>5.28219512713884e-07</izz>
				</inertia>
			</inertial>
			<collision name="neck_link2_collision">
				<geometry>
					<mesh>
						<uri>model://roboy_icecream/meshes/CAD/neck_link2.stl</uri>
						<scale>0.001 0.001 0.001</scale>
					</mesh>
				</geometry>
			</collision>
			<visual name="neck_link2_visual">
				<geometry>
					<mesh>
						<uri>model://roboy_icecream/meshes/CAD/neck_link2.stl</uri>
						<scale>0.001 0.001 0.001</scale>
					</mesh>
				</geometry>
			</visual>
		</link>
		<link name="arm_left_lower">
			<self_collide>false</self_collide>
			<pose frame="">0.28793889509258513 0.005904317336569164 0.19200443185171015 0.0 -0.0 0.0</pose>
			<inertial>
				<pose frame="">0.0 0.0 0.0 0 0 0</pose>
				<mass>0.3583670066670842</mass>
				<inertia>
					<ixx>0.014847245203761506</ixx>
					<ixy>-0.0006096893660512493</ixy>
					<ixz>-0.019830115787726584</ixz>
					<iyy>0.04454622179764293</iyy>
					<iyz>-0.00044362528293157553</iyz>
					<izz>0.029768178595056972</izz>
				</inertia>
			</inertial>
			<collision name="arm_left_lower_collision">
				<geometry>
					<mesh>
						<uri>model://roboy_icecream/meshes/CAD/arm_left_lower.stl</uri>
						<scale>0.001 0.001 0.001</scale>
					</mesh>
				</geometry>
			</collision>
			<visual name="arm_left_lower_visual">
				<geometry>
					<mesh>
						<uri>model://roboy_icecream/meshes/CAD/arm_left_lower.stl</uri>
						<scale>0.001 0.001 0.001</scale>
					</mesh>
				</geometry>
			</visual>
		</link>
		<link name="hand_left_index_link1">
			<self_collide>false</self_collide>
			<pose frame="">0.2971479598973615 -0.03884098082845617 -0.16552842967458203 0.0 -0.0 0.0</pose>
			<inertial>
				<pose frame="">0.0 0.0 0.0 0 0 0</pose>
				<mass>0.03082114844612854</mass>
				<inertia>
					<ixx>0.0008932176739645928</ixx>
					<ixy>0.00035574185821337777</ixy>
					<ixz>0.001516005437985013</ixz>
					<iyy>0.0035678018404786023</iyy>
					<iyz>-0.00019824041491286757</iyz>
					<izz>0.0027690587409003845</izz>
				</inertia>
			</inertial>
			<collision name="hand_left_index_link1_collision">
				<geometry>
					<mesh>
						<uri>model://roboy_icecream/meshes/CAD/hand_left_index_link1.stl</uri>
						<scale>0.001 0.001 0.001</scale>
					</mesh>
				</geometry>
			</collision>
			<visual name="hand_left_index_link1_visual">
				<geometry>
					<mesh>
						<uri>model://roboy_icecream/meshes/CAD/hand_left_index_link1.stl</uri>
						<scale>0.001 0.001 0.001</scale>
					</mesh>
				</geometry>
			</visual>
		</link>
		<link name="hand_left_index_link0">
			<self_collide>false</self_collide>
			<pose frame="">0.29667598755432717 -0.0350263050242304 -0.13022065942663696 0.0 -0.0 0.0</pose>
			<inertial>
				<pose frame="">0.0 0.0 0.0 0 0 0</pose>
				<mass>0.05584700429589652</mass>
				<inertia>
					<ixx>0.001025712445445168</ixx>
					<ixy>0.000580356066537544</ixy>
					<ixz>0.00215758449653426</ixz>
					<iyy>0.005872170979312627</iyy>
					<iyz>-0.00025557813569510225</iyz>
					<izz>0.004986012986514019</izz>
				</inertia>
			</inertial>
			<collision name="hand_left_index_link0_collision">
				<geometry>
					<mesh>
						<uri>model://roboy_icecream/meshes/CAD/hand_left_index_link0.stl</uri>
						<scale>0.001 0.001 0.001</scale>
					</mesh>
				</geometry>
			</collision>
			<visual name="hand_left_index_link0_visual">
				<geometry>
					<mesh>
						<uri>model://roboy_icecream/meshes/CAD/hand_left_index_link0.stl</uri>
						<scale>0.001 0.001 0.001</scale>
					</mesh>
				</geometry>
			</visual>
		</link>
		<link name="hand_left_index_link2">
			<self_collide>false</self_collide>
			<pose frame="">0.29740510151740923 -0.04154411580231275 -0.19062867438591935 0.0 -0.0 0.0</pose>
			<inertial>
				<pose frame="">0.0 0.0 0.0 0 0 0</pose>
				<mass>0.03033688353476337</mass>
				<inertia>
					<ixx>0.0011566487315707702</ixx>
					<ixy>0.0003748404234898154</ixy>
					<ixz>0.0017198816525882457</ixz>
					<iyy>0.0037873327330513904</iyy>
					<iyz>-0.0002403147061042356</iyz>
					<izz>0.002736771517108759</izz>
				</inertia>
			</inertial>
			<collision name="hand_left_index_link2_collision">
				<geometry>
					<mesh>
						<uri>model://roboy_icecream/meshes/CAD/hand_left_index_link2.stl</uri>
						<scale>0.001 0.001 0.001</scale>
					</mesh>
				</geometry>
			</collision>
			<visual name="hand_left_index_link2_visual">
				<geometry>
					<mesh>
						<uri>model://roboy_icecream/meshes/CAD/hand_left_index_link2.stl</uri>
						<scale>0.001 0.001 0.001</scale>
					</mesh>
				</geometry>
			</visual>
		</link>
		<link name="hand_left_middle_link1">
			<self_collide>false</self_collide>
			<pose frame="">0.2938252332963292 0.02639067204943565 -0.16616918499201613 0.0 -0.0 0.0</pose>
			<inertial>
				<pose frame="">0.0 0.0 0.0 0 0 0</pose>
				<mass>0.030820004367657278</mass>
				<inertia>
					<ixx>0.0008747044059193931</ixx>
					<ixy>-0.0002389710943883316</ixy>
					<ixz>0.0015047936289420154</ixz>
					<iyy>0.003513705596803869</iyy>
					<iyz>0.00013520600734865512</iyz>
					<izz>0.0026833998759867336</izz>
				</inertia>
			</inertial>
			<collision name="hand_left_middle_link1_collision">
				<geometry>
					<mesh>
						<uri>model://roboy_icecream/meshes/CAD/hand_left_middle_link1.stl</uri>
						<scale>0.001 0.001 0.001</scale>
					</mesh>
				</geometry>
			</collision>
			<visual name="hand_left_middle_link1_visual">
				<geometry>
					<mesh>
						<uri>model://roboy_icecream/meshes/CAD/hand_left_middle_link1.stl</uri>
						<scale>0.001 0.001 0.001</scale>
					</mesh>
				</geometry>
			</visual>
		</link>
		<link name="hand_left_middle_link0">
			<self_collide>false</self_collide>
			<pose frame="">0.2936690086933322 0.024025459506623426 -0.1307326759341471 0.0 -0.0 0.0</pose>
			<inertial>
				<pose frame="">0.0 0.0 0.0 0 0 0</pose>
				<mass>0.05584686032380059</mass>
				<inertia>
					<ixx>0.000996892463699574</ixx>
					<ixy>-0.00039400671527600305</ixy>
					<ixz>0.0021440388661896985</ixz>
					<iyy>0.00578054164459317</iyy>
					<iyz>0.00017591643575483155</iyz>
					<izz>0.004850523434996299</izz>
				</inertia>
			</inertial>
			<collision name="hand_left_middle_link0_collision">
				<geometry>
					<mesh>
						<uri>model://roboy_icecream/meshes/CAD/hand_left_middle_link0.stl</uri>
						<scale>0.001 0.001 0.001</scale>
					</mesh>
				</geometry>
			</collision>
			<visual name="hand_left_middle_link0_visual">
				<geometry>
					<mesh>
						<uri>model://roboy_icecream/meshes/CAD/hand_left_middle_link0.stl</uri>
						<scale>0.001 0.001 0.001</scale>
					</mesh>
				</geometry>
			</visual>
		</link>
		<link name="hand_left_middle_link2">
			<self_collide>false</self_collide>
			<pose frame="">0.29385816652228264 0.02808104797252826 -0.19135993042834315 0.0 -0.0 0.0</pose>
			<inertial>
				<pose frame="">0.0 0.0 0.0 0 0 0</pose>
				<mass>0.03033689773892686</mass>
				<inertia>
					<ixx>0.0011366847513535425</ixx>
					<ixy>-0.00025032109436055064</ixy>
					<ixz>0.0017058841636331385</ixz>
					<iyy>0.0037321904751004453</iyy>
					<iyz>0.00016304943896977924</iyz>
					<izz>0.0026447084959909197</izz>
				</inertia>
			</inertial>
			<collision name="hand_left_middle_link2_collision">
				<geometry>
					<mesh>
						<uri>model://roboy_icecream/meshes/CAD/hand_left_middle_link2.stl</uri>
						<scale>0.001 0.001 0.001</scale>
					</mesh>
				</geometry>
			</collision>
			<visual name="hand_left_middle_link2_visual">
				<geometry>
					<mesh>
						<uri>model://roboy_icecream/meshes/CAD/hand_left_middle_link2.stl</uri>
						<scale>0.001 0.001 0.001</scale>
					</mesh>
				</geometry>
			</visual>
		</link>
		<link name="hand_left_ring_link1">
			<self_collide>false</self_collide>
			<pose frame="">0.295365361017994 -0.005760283074127264 -0.17374200134723589 0.0 -0.0 0.0</pose>
			<inertial>
				<pose frame="">0.0 0.0 0.0 0 0 0</pose>
				<mass>0.030819931192770916</mass>
				<inertia>
					<ixx>0.0009335928034219096</ixx>
					<ixy>5.245327758269168e-05</ixy>
					<ixz>0.0015816174023096765</ixz>
					<iyy>0.003621000288246831</iyy>
					<iyz>-3.0860952365898016e-05</iyz>
					<izz>0.0026909151153472503</izz>
				</inertia>
			</inertial>
			<collision name="hand_left_ring_link1_collision">
				<geometry>
					<mesh>
						<uri>model://roboy_icecream/meshes/CAD/hand_left_ring_link1.stl</uri>
						<scale>0.001 0.001 0.001</scale>
					</mesh>
				</geometry>
			</collision>
			<visual name="hand_left_ring_link1_visual">
				<geometry>
					<mesh>
						<uri>model://roboy_icecream/meshes/CAD/hand_left_ring_link1.stl</uri>
						<scale>0.001 0.001 0.001</scale>
					</mesh>
				</geometry>
			</visual>
		</link>
		<link name="hand_left_ring_link0">
			<self_collide>false</self_collide>
			<pose frame="">0.29505285429724476 -0.005032514310069151 -0.13823513362613282 0.0 -0.0 0.0</pose>
			<inertial>
				<pose frame="">0.0 0.0 0.0 0 0 0</pose>
				<mass>0.05584692310229072</mass>
				<inertia>
					<ixx>0.0010787666032993776</ixx>
					<ixy>8.294499358650299e-05</ixy>
					<ixz>0.0022778031437028032</ixz>
					<iyy>0.005938770166087321</iyy>
					<iyz>-3.902637950295652e-05</iyz>
					<izz>0.004865176517705527</izz>
				</inertia>
			</inertial>
			<collision name="hand_left_ring_link0_collision">
				<geometry>
					<mesh>
						<uri>model://roboy_icecream/meshes/CAD/hand_left_ring_link0.stl</uri>
						<scale>0.001 0.001 0.001</scale>
					</mesh>
				</geometry>
			</collision>
			<visual name="hand_left_ring_link0_visual">
				<geometry>
					<mesh>
						<uri>model://roboy_icecream/meshes/CAD/hand_left_ring_link0.stl</uri>
						<scale>0.001 0.001 0.001</scale>
					</mesh>
				</geometry>
			</visual>
		</link>
		<link name="hand_left_ring_link2">
			<self_collide>false</self_collide>
			<pose frame="">0.29550938870619403 -0.006268557857029139 -0.19898381255389277 0.0 -0.0 0.0</pose>
			<inertial>
				<pose frame="">0.0 0.0 0.0 0 0 0</pose>
				<mass>0.03033689306383503</mass>
				<inertia>
					<ixx>0.0012042373177309125</ixx>
					<ixy>5.6210973744788285e-05</ixy>
					<ixz>0.0017838202467825711</ixz>
					<iyy>0.0038519974849015306</iyy>
					<iyz>-3.785577242926262e-05</iyz>
					<izz>0.0026514996601857085</izz>
				</inertia>
			</inertial>
			<collision name="hand_left_ring_link2_collision">
				<geometry>
					<mesh>
						<uri>model://roboy_icecream/meshes/CAD/hand_left_ring_link2.stl</uri>
						<scale>0.001 0.001 0.001</scale>
					</mesh>
				</geometry>
			</collision>
			<visual name="hand_left_ring_link2_visual">
				<geometry>
					<mesh>
						<uri>model://roboy_icecream/meshes/CAD/hand_left_ring_link2.stl</uri>
						<scale>0.001 0.001 0.001</scale>
					</mesh>
				</geometry>
			</visual>
		</link>
		<link name="hand_left_little_link1">
			<self_collide>false</self_collide>
			<pose frame="">0.2937368696540432 0.0519389799358573 -0.1330902089447986 0.0 -0.0 0.0</pose>
			<inertial>
				<pose frame="">0.0 0.0 0.0 0 0 0</pose>
				<mass>0.030820040312614833</mass>
				<inertia>
					<ixx>0.0006312887164636588</ixx>
					<ixy>-0.00047018869396618667</ixy>
					<ixz>0.0012048773764738406</ixz>
					<iyy>0.00320700860492685</iyy>
					<iyz>0.00021313569771587733</iyz>
					<izz>0.002743486887932652</izz>
				</inertia>
			</inertial>
			<collision name="hand_left_little_link1_collision">
				<geometry>
					<mesh>
						<uri>model://roboy_icecream/meshes/CAD/hand_left_little_link1.stl</uri>
						<scale>0.001 0.001 0.001</scale>
					</mesh>
				</geometry>
			</collision>
			<visual name="hand_left_little_link1_visual">
				<geometry>
					<mesh>
						<uri>model://roboy_icecream/meshes/CAD/hand_left_little_link1.stl</uri>
						<scale>0.001 0.001 0.001</scale>
					</mesh>
				</geometry>
			</visual>
		</link>
		<link name="hand_left_little_link2">
			<self_collide>false</self_collide>
			<pose frame="">0.2937045327700304 0.05494345463608231 -0.1581585177307273 0.0 -0.0 0.0</pose>
			<inertial>
				<pose frame="">0.0 0.0 0.0 0 0 0</pose>
				<mass>0.03033689981249384</mass>
				<inertia>
					<ixx>0.0008522923084657836</ixx>
					<ixy>-0.0004895375812775036</ixy>
					<ixz>0.0014091578924985248</ixz>
					<iyy>0.0033773957962738898</iyy>
					<iyz>0.000263679589915299</iyz>
					<izz>0.002709634662870204</izz>
				</inertia>
			</inertial>
			<collision name="hand_left_little_link2_collision">
				<geometry>
					<mesh>
						<uri>model://roboy_icecream/meshes/CAD/hand_left_little_link2.stl</uri>
						<scale>0.001 0.001 0.001</scale>
					</mesh>
				</geometry>
			</collision>
			<visual name="hand_left_little_link2_visual">
				<geometry>
					<mesh>
						<uri>model://roboy_icecream/meshes/CAD/hand_left_little_link2.stl</uri>
						<scale>0.001 0.001 0.001</scale>
					</mesh>
				</geometry>
			</visual>
		</link>
		<link name="hand_left_little_link0">
			<self_collide>false</self_collide>
			<pose frame="">0.2942119670817848 0.048866339880860775 -0.10727673058468849 0.0 -0.0 0.0</pose>
			<inertial>
				<pose frame="">0.0 0.0 0.0 0 0 0</pose>
				<mass>0.030820040312614795</mass>
				<inertia>
					<ixx>0.0004305132509339729</ixx>
					<ixy>-0.0004430876647832715</ixy>
					<ixz>0.0009727592189978553</ixz>
					<iyy>0.003024388345042694</iyy>
					<iyz>0.0001616554891423087</iyz>
					<izz>0.002742549789706371</izz>
				</inertia>
			</inertial>
			<collision name="hand_left_little_link0_collision">
				<geometry>
					<mesh>
						<uri>model://roboy_icecream/meshes/CAD/hand_left_little_link0.stl</uri>
						<scale>0.001 0.001 0.001</scale>
					</mesh>
				</geometry>
			</collision>
			<visual name="hand_left_little_link0_visual">
				<geometry>
					<mesh>
						<uri>model://roboy_icecream/meshes/CAD/hand_left_little_link0.stl</uri>
						<scale>0.001 0.001 0.001</scale>
					</mesh>
				</geometry>
			</visual>
		</link>
		<link name="hand_left_thumb_link2">
			<self_collide>false</self_collide>
			<pose frame="">0.2855460663700442 -0.1036617335614306 -0.054959771992047046 0.0 -0.0 0.0</pose>
			<inertial>
				<pose frame="">0.0 0.0 0.0 0 0 0</pose>
				<mass>0.030336616654663518</mass>
				<inertia>
					<ixx>0.0004191804904979078</ixx>
					<ixy>0.0008980153703551927</ixy>
					<ixz>0.00047610597705451227</ixz>
					<iyy>0.0025662928843775443</iyy>
					<iyz>-0.00017288573484392002</iyz>
					<izz>0.0028014472237941307</izz>
				</inertia>
			</inertial>
			<collision name="hand_left_thumb_link2_collision">
				<geometry>
					<mesh>
						<uri>model://roboy_icecream/meshes/CAD/hand_left_thumb_link2.stl</uri>
						<scale>0.001 0.001 0.001</scale>
					</mesh>
				</geometry>
			</collision>
			<visual name="hand_left_thumb_link2_visual">
				<geometry>
					<mesh>
						<uri>model://roboy_icecream/meshes/CAD/hand_left_thumb_link2.stl</uri>
						<scale>0.001 0.001 0.001</scale>
					</mesh>
				</geometry>
			</visual>
		</link>
		<link name="hand_left_thumb_link0">
			<self_collide>false</self_collide>
			<pose frame="">0.2823022101894099 -0.03996163594312154 -0.04477229201422508 0.0 -0.0 0.0</pose>
			<inertial>
				<pose frame="">0.0 0.0 0.0 0 0 0</pose>
				<mass>0.11643355590170919</mass>
				<inertia>
					<ixx>0.0004450077650240487</ixx>
					<ixy>0.0013142170689855565</ixy>
					<ixz>0.0014716959909715467</ixz>
					<iyy>0.009523647149439561</iyy>
					<iyz>-0.00021095395824155614</iyz>
					<izz>0.009485909375986182</izz>
				</inertia>
			</inertial>
			<collision name="hand_left_thumb_link0_collision">
				<geometry>
					<mesh>
						<uri>model://roboy_icecream/meshes/CAD/hand_left_thumb_link0.stl</uri>
						<scale>0.001 0.001 0.001</scale>
					</mesh>
				</geometry>
			</collision>
			<visual name="hand_left_thumb_link0_visual">
				<geometry>
					<mesh>
						<uri>model://roboy_icecream/meshes/CAD/hand_left_thumb_link0.stl</uri>
						<scale>0.001 0.001 0.001</scale>
					</mesh>
				</geometry>
			</visual>
		</link>
		<link name="hand_left_thumb_link1">
			<self_collide>false</self_collide>
			<pose frame="">0.28410959831484106 -0.07847451913565917 -0.05595428087794943 0.0 -0.0 0.0</pose>
			<inertial>
				<pose frame="">0.0 0.0 0.0 0 0 0</pose>
				<mass>0.030821292278110746</mass>
				<inertia>
					<ixx>0.00028820898139731566</ixx>
					<ixy>0.0006872096447305892</ixy>
					<ixz>0.0004899700627339388</ixz>
					<iyy>0.0025854766244530563</iyy>
					<iyz>-0.00013527874489616224</iyz>
					<izz>0.0026798688049792228</izz>
				</inertia>
			</inertial>
			<collision name="hand_left_thumb_link1_collision">
				<geometry>
					<mesh>
						<uri>model://roboy_icecream/meshes/CAD/hand_left_thumb_link1.stl</uri>
						<scale>0.001 0.001 0.001</scale>
					</mesh>
				</geometry>
			</collision>
			<visual name="hand_left_thumb_link1_visual">
				<geometry>
					<mesh>
						<uri>model://roboy_icecream/meshes/CAD/hand_left_thumb_link1.stl</uri>
						<scale>0.001 0.001 0.001</scale>
					</mesh>
				</geometry>
			</visual>
		</link>
		<link name="hand_left_palm">
			<self_collide>false</self_collide>
			<pose frame="">0.29683323797713995 0.001263655510429225 -0.05333670716634607 0.0 -0.0 0.0</pose>
			<inertial>
				<pose frame="">0.0 0.0 0.0 0 0 0</pose>
				<mass>0.7882346365046049</mass>
				<inertia>
					<ixx>0.0034851094075635703</ixx>
					<ixy>-0.00027312073312400634</ixy>
					<ixz>0.012545100456026788</ixz>
					<iyy>0.07244403582545497</iyy>
					<iyz>2.6287662648162566e-05</iyz>
					<izz>0.07006875804131105</izz>
				</inertia>
			</inertial>
			<collision name="hand_left_palm_collision">
				<geometry>
					<mesh>
						<uri>model://roboy_icecream/meshes/CAD/hand_left_palm.stl</uri>
						<scale>0.001 0.001 0.001</scale>
					</mesh>
				</geometry>
			</collision>
			<visual name="hand_left_palm_visual">
				<geometry>
					<mesh>
						<uri>model://roboy_icecream/meshes/CAD/hand_left_palm.stl</uri>
						<scale>0.001 0.001 0.001</scale>
					</mesh>
				</geometry>
			</visual>
		</link>
		<link name="hand_right_index_link1">
			<self_collide>false</self_collide>
			<pose frame="">-0.29802794504366953 -0.027796507109106396 -0.2109667853007439 0.0 -0.0 0.0</pose>
			<inertial>
				<pose frame="">0.0 0.0 0.0 0 0 0</pose>
				<mass>0.030819928523728248</mass>
				<inertia>
					<ixx>0.0013977458286006696</ixx>
					<ixy>-0.0002553354576600338</ixy>
					<ixz>-0.0019377941748036566</ixz>
					<iyy>0.004111052095786885</iyy>
					<iyz>-0.00018079768215800238</iyz>
					<izz>0.0027624047605117746</izz>
				</inertia>
			</inertial>
			<collision name="hand_right_index_link1_collision">
				<geometry>
					<mesh>
						<uri>model://roboy_icecream/meshes/CAD/hand_right_index_link1.stl</uri>
						<scale>0.001 0.001 0.001</scale>
					</mesh>
				</geometry>
			</collision>
			<visual name="hand_right_index_link1_visual">
				<geometry>
					<mesh>
						<uri>model://roboy_icecream/meshes/CAD/hand_right_index_link1.stl</uri>
						<scale>0.001 0.001 0.001</scale>
					</mesh>
				</geometry>
			</visual>
		</link>
		<link name="hand_right_index_link0">
			<self_collide>false</self_collide>
			<pose frame="">-0.29759239670810833 -0.024683600914382688 -0.17559035856943858 0.0 -0.0 0.0</pose>
			<inertial>
				<pose frame="">0.0 0.0 0.0 0 0 0</pose>
				<mass>0.055846903810612934</mass>
				<inertia>
					<ixx>0.001766072770735144</ixx>
					<ixy>-0.00041025436120509896</ixy>
					<ixz>-0.0029182630289464623</ixz>
					<iyy>0.006677459725239644</iyy>
					<iyz>-0.00024272953746762662</iyz>
					<izz>0.004981894254499964</izz>
				</inertia>
			</inertial>
			<collision name="hand_right_index_link0_collision">
				<geometry>
					<mesh>
						<uri>model://roboy_icecream/meshes/CAD/hand_right_index_link0.stl</uri>
						<scale>0.001 0.001 0.001</scale>
					</mesh>
				</geometry>
			</collision>
			<visual name="hand_right_index_link0_visual">
				<geometry>
					<mesh>
						<uri>model://roboy_icecream/meshes/CAD/hand_right_index_link0.stl</uri>
						<scale>0.001 0.001 0.001</scale>
					</mesh>
				</geometry>
			</visual>
		</link>
		<link name="hand_right_index_link2">
			<self_collide>false</self_collide>
			<pose frame="">-0.2982603266809658 -0.03002577090957189 -0.23611369838086715 0.0 -0.0 0.0</pose>
			<inertial>
				<pose frame="">0.0 0.0 0.0 0 0 0</pose>
				<mass>0.030337118821034063</mass>
				<inertia>
					<ixx>0.0017205173247171082</ixx>
					<ixy>-0.000271699245726833</ixy>
					<ixz>-0.002136415839814085</ixz>
					<iyy>0.004391691407268722</iyy>
					<iyz>-0.0002151258376139562</iyz>
					<izz>0.002727239027173174</izz>
				</inertia>
			</inertial>
			<collision name="hand_right_index_link2_collision">
				<geometry>
					<mesh>
						<uri>model://roboy_icecream/meshes/CAD/hand_right_index_link2.stl</uri>
						<scale>0.001 0.001 0.001</scale>
					</mesh>
				</geometry>
			</collision>
			<visual name="hand_right_index_link2_visual">
				<geometry>
					<mesh>
						<uri>model://roboy_icecream/meshes/CAD/hand_right_index_link2.stl</uri>
						<scale>0.001 0.001 0.001</scale>
					</mesh>
				</geometry>
			</visual>
		</link>
		<link name="hand_right_middle_link1">
			<self_collide>false</self_collide>
			<pose frame="">-0.29624539656807103 0.005461026157536197 -0.2184623961108496 0.0 -0.0 0.0</pose>
			<inertial>
				<pose frame="">0.0 0.0 0.0 0 0 0</pose>
				<mass>0.03081999922495932</mass>
				<inertia>
					<ixx>0.0014740599178146795</ixx>
					<ixy>4.984400271790671e-05</ixy>
					<ixz>-0.0019946422371137865</ixz>
					<iyy>0.004177623272432178</iyy>
					<iyz>3.6770465224776334e-05</iyz>
					<izz>0.0027068632483079826</izz>
				</inertia>
			</inertial>
			<collision name="hand_right_middle_link1_collision">
				<geometry>
					<mesh>
						<uri>model://roboy_icecream/meshes/CAD/hand_right_middle_link1.stl</uri>
						<scale>0.001 0.001 0.001</scale>
					</mesh>
				</geometry>
			</collision>
			<visual name="hand_right_middle_link1_visual">
				<geometry>
					<mesh>
						<uri>model://roboy_icecream/meshes/CAD/hand_right_middle_link1.stl</uri>
						<scale>0.001 0.001 0.001</scale>
					</mesh>
				</geometry>
			</visual>
		</link>
		<link name="hand_right_middle_link0">
			<self_collide>false</self_collide>
			<pose frame="">-0.29596859363737676 0.00548337074375845 -0.18294767211577437 0.0 -0.0 0.0</pose>
			<inertial>
				<pose frame="">0.0 0.0 0.0 0 0 0</pose>
				<mass>0.05584691839812723</mass>
				<inertia>
					<ixx>0.0018810433416202661</ixx>
					<ixy>9.061393615603216e-05</ixy>
					<ixz>-0.00302391410715677</ixz>
					<iyy>0.006771011052083513</iyy>
					<iyz>5.6025893298785325e-05</iyz>
					<izz>0.004895662524913588</izz>
				</inertia>
			</inertial>
			<collision name="hand_right_middle_link0_collision">
				<geometry>
					<mesh>
						<uri>model://roboy_icecream/meshes/CAD/hand_right_middle_link0.stl</uri>
						<scale>0.001 0.001 0.001</scale>
					</mesh>
				</geometry>
			</collision>
			<visual name="hand_right_middle_link0_visual">
				<geometry>
					<mesh>
						<uri>model://roboy_icecream/meshes/CAD/hand_right_middle_link0.stl</uri>
						<scale>0.001 0.001 0.001</scale>
					</mesh>
				</geometry>
			</visual>
		</link>
		<link name="hand_right_middle_link2">
			<self_collide>false</self_collide>
			<pose frame="">-0.2963649175669183 0.005428620032126386 -0.24370863962939374 0.0 -0.0 0.0</pose>
			<inertial>
				<pose frame="">0.0 0.0 0.0 0 0 0</pose>
				<mass>0.03033711977138813</mass>
				<inertia>
					<ixx>0.0018046174545846868</ixx>
					<ixy>4.879367390909935e-05</ixy>
					<ixz>-0.0021911228261474007</ixz>
					<iyy>0.004468060975187511</iyy>
					<iyz>4.013313706123027e-05</iyz>
					<izz>0.0026665859924333425</izz>
				</inertia>
			</inertial>
			<collision name="hand_right_middle_link2_collision">
				<geometry>
					<mesh>
						<uri>model://roboy_icecream/meshes/CAD/hand_right_middle_link2.stl</uri>
						<scale>0.001 0.001 0.001</scale>
					</mesh>
				</geometry>
			</collision>
			<visual name="hand_right_middle_link2_visual">
				<geometry>
					<mesh>
						<uri>model://roboy_icecream/meshes/CAD/hand_right_middle_link2.stl</uri>
						<scale>0.001 0.001 0.001</scale>
					</mesh>
				</geometry>
			</visual>
		</link>
		<link name="hand_right_ring_link1">
			<self_collide>false</self_collide>
			<pose frame="">-0.29472287318656065 0.03743410441310239 -0.21019630851099544 0.0 -0.0 0.0</pose>
			<inertial>
				<pose frame="">0.0 0.0 0.0 0 0 0</pose>
				<mass>0.030820066243951855</mass>
				<inertia>
					<ixx>0.0014071270291391123</ixx>
					<ixy>0.0003400131091907865</ixy>
					<ixz>-0.0019093079755440642</ixz>
					<iyy>0.0040406898427808305</iyy>
					<iyz>0.00024257594870687497</iyz>
					<izz>0.002721413672851783</izz>
				</inertia>
			</inertial>
			<collision name="hand_right_ring_link1_collision">
				<geometry>
					<mesh>
						<uri>model://roboy_icecream/meshes/CAD/hand_right_ring_link1.stl</uri>
						<scale>0.001 0.001 0.001</scale>
					</mesh>
				</geometry>
			</collision>
			<visual name="hand_right_ring_link1_visual">
				<geometry>
					<mesh>
						<uri>model://roboy_icecream/meshes/CAD/hand_right_ring_link1.stl</uri>
						<scale>0.001 0.001 0.001</scale>
					</mesh>
				</geometry>
			</visual>
		</link>
		<link name="hand_right_ring_link0">
			<self_collide>false</self_collide>
			<pose frame="">-0.2946014898999604 0.034365529768459115 -0.17481324052208055 0.0 -0.0 0.0</pose>
			<inertial>
				<pose frame="">0.0 0.0 0.0 0 0 0</pose>
				<mass>0.05584580375610117</mass>
				<inertia>
					<ixx>0.0017827582709774538</ixx>
					<ixy>0.0005653662651931412</ixy>
					<ixz>-0.0028760223514491976</ixz>
					<iyy>0.006563206429323276</iyy>
					<iyz>0.00033617810587686936</iyz>
					<izz>0.004914810757074774</izz>
				</inertia>
			</inertial>
			<collision name="hand_right_ring_link0_collision">
				<geometry>
					<mesh>
						<uri>model://roboy_icecream/meshes/CAD/hand_right_ring_link0.stl</uri>
						<scale>0.001 0.001 0.001</scale>
					</mesh>
				</geometry>
			</collision>
			<visual name="hand_right_ring_link0_visual">
				<geometry>
					<mesh>
						<uri>model://roboy_icecream/meshes/CAD/hand_right_ring_link0.stl</uri>
						<scale>0.001 0.001 0.001</scale>
					</mesh>
				</geometry>
			</visual>
		</link>
		<link name="hand_right_ring_link2">
			<self_collide>false</self_collide>
			<pose frame="">-0.2947318848901617 0.03959898310746472 -0.23534994025120148 0.0 -0.0 0.0</pose>
			<inertial>
				<pose frame="">0.0 0.0 0.0 0 0 0</pose>
				<mass>0.03033711666638585</mass>
				<inertia>
					<ixx>0.0017298128118504268</ixx>
					<ixy>0.0003540530144456865</ixy>
					<ixz>-0.002104307339454547</ixz>
					<iyy>0.004317291065922902</iyy>
					<iyz>0.00028277520697666636</iyz>
					<izz>0.002683982874848568</izz>
				</inertia>
			</inertial>
			<collision name="hand_right_ring_link2_collision">
				<geometry>
					<mesh>
						<uri>model://roboy_icecream/meshes/CAD/hand_right_ring_link2.stl</uri>
						<scale>0.001 0.001 0.001</scale>
					</mesh>
				</geometry>
			</collision>
			<visual name="hand_right_ring_link2_visual">
				<geometry>
					<mesh>
						<uri>model://roboy_icecream/meshes/CAD/hand_right_ring_link2.stl</uri>
						<scale>0.001 0.001 0.001</scale>
					</mesh>
				</geometry>
			</visual>
		</link>
		<link name="hand_right_little_link1">
			<self_collide>false</self_collide>
			<pose frame="">-0.2939195087344591 0.061396990981062105 -0.17666954111873093 0.0 -0.0 0.0</pose>
			<inertial>
				<pose frame="">0.0 0.0 0.0 0 0 0</pose>
				<mass>0.030820092306724695</mass>
				<inertia>
					<ixx>0.0010803711361580645</ixx>
					<ixy>0.0005561581051304459</ixy>
					<ixz>-0.0016003966666588358</ixz>
					<iyy>0.0036263616987721905</iyy>
					<iyz>0.00033441192132689065</iyz>
					<izz>0.00277984096625541</izz>
				</inertia>
			</inertial>
			<collision name="hand_right_little_link1_collision">
				<geometry>
					<mesh>
						<uri>model://roboy_icecream/meshes/CAD/hand_right_little_link1.stl</uri>
						<scale>0.001 0.001 0.001</scale>
					</mesh>
				</geometry>
			</collision>
			<visual name="hand_right_little_link1_visual">
				<geometry>
					<mesh>
						<uri>model://roboy_icecream/meshes/CAD/hand_right_little_link1.stl</uri>
						<scale>0.001 0.001 0.001</scale>
					</mesh>
				</geometry>
			</visual>
		</link>
		<link name="hand_right_little_link2">
			<self_collide>false</self_collide>
			<pose frame="">-0.2938636962845659 0.06487342392522413 -0.20167594061949243 0.0 -0.0 0.0</pose>
			<inertial>
				<pose frame="">0.0 0.0 0.0 0 0 0</pose>
				<mass>0.03033711516204795</mass>
				<inertia>
					<ixx>0.0013634555356794866</ixx>
					<ixy>0.0005783319800132448</ixy>
					<ixz>-0.0017978980783896223</ixz>
					<iyy>0.0038553192923023076</iyy>
					<iyz>0.00039698519067466847</iyz>
					<izz>0.002748591813507502</izz>
				</inertia>
			</inertial>
			<collision name="hand_right_little_link2_collision">
				<geometry>
					<mesh>
						<uri>model://roboy_icecream/meshes/CAD/hand_right_little_link2.stl</uri>
						<scale>0.001 0.001 0.001</scale>
					</mesh>
				</geometry>
			</collision>
			<visual name="hand_right_little_link2_visual">
				<geometry>
					<mesh>
						<uri>model://roboy_icecream/meshes/CAD/hand_right_little_link2.stl</uri>
						<scale>0.001 0.001 0.001</scale>
					</mesh>
				</geometry>
			</visual>
		</link>
		<link name="hand_right_little_link0">
			<self_collide>false</self_collide>
			<pose frame="">-0.29441848832812845 0.057839071590573436 -0.15091891534281981 0.0 -0.0 0.0</pose>
			<inertial>
				<pose frame="">0.0 0.0 0.0 0 0 0</pose>
				<mass>0.030820092306724688</mass>
				<inertia>
					<ixx>0.0008073100475423453</ixx>
					<ixy>0.0005248177263750359</ixy>
					<ixz>-0.001369452289262568</ixz>
					<iyy>0.0033754233018467527</iyy>
					<iyz>0.00026913594351672416</iyz>
					<izz>0.002775813900668565</izz>
				</inertia>
			</inertial>
			<collision name="hand_right_little_link0_collision">
				<geometry>
					<mesh>
						<uri>model://roboy_icecream/meshes/CAD/hand_right_little_link0.stl</uri>
						<scale>0.001 0.001 0.001</scale>
					</mesh>
				</geometry>
			</collision>
			<visual name="hand_right_little_link0_visual">
				<geometry>
					<mesh>
						<uri>model://roboy_icecream/meshes/CAD/hand_right_little_link0.stl</uri>
						<scale>0.001 0.001 0.001</scale>
					</mesh>
				</geometry>
			</visual>
		</link>
		<link name="hand_right_thumb_link2">
			<self_collide>false</self_collide>
			<pose frame="">-0.2863161602770125 -0.09471307201731476 -0.10191416118121753 0.0 -0.0 0.0</pose>
			<inertial>
				<pose frame="">0.0 0.0 0.0 0 0 0</pose>
				<mass>0.03033691470620726</mass>
				<inertia>
					<ixx>0.000588794649234034</ixx>
					<ixy>-0.0008227165744112494</ixy>
					<ixz>-0.0008852497664979485</ixz>
					<iyy>0.0028031477134868783</iyy>
					<iyz>-0.0002929023321585444</iyz>
					<izz>0.002760979773798425</izz>
				</inertia>
			</inertial>
			<collision name="hand_right_thumb_link2_collision">
				<geometry>
					<mesh>
						<uri>model://roboy_icecream/meshes/CAD/hand_right_thumb_link2.stl</uri>
						<scale>0.001 0.001 0.001</scale>
					</mesh>
				</geometry>
			</collision>
			<visual name="hand_right_thumb_link2_visual">
				<geometry>
					<mesh>
						<uri>model://roboy_icecream/meshes/CAD/hand_right_thumb_link2.stl</uri>
						<scale>0.001 0.001 0.001</scale>
					</mesh>
				</geometry>
			</visual>
		</link>
		<link name="hand_right_thumb_link0">
			<self_collide>false</self_collide>
			<pose frame="">-0.2833744409590411 -0.031245490313719728 -0.09028614142258572 0.0 -0.0 0.0</pose>
			<inertial>
				<pose frame="">0.0 0.0 0.0 0 0 0</pose>
				<mass>0.1164329483581609</mass>
				<inertia>
					<ixx>0.0010884578373616318</ixx>
					<ixy>-0.001031623811453484</ixy>
					<ixz>-0.002979013350833632</ixz>
					<iyy>0.010310061011896889</iyy>
					<iyz>-0.00033131217496780836</iyz>
					<izz>0.009484091782943398</izz>
				</inertia>
			</inertial>
			<collision name="hand_right_thumb_link0_collision">
				<geometry>
					<mesh>
						<uri>model://roboy_icecream/meshes/CAD/hand_right_thumb_link0.stl</uri>
						<scale>0.001 0.001 0.001</scale>
					</mesh>
				</geometry>
			</collision>
			<visual name="hand_right_thumb_link0_visual">
				<geometry>
					<mesh>
						<uri>model://roboy_icecream/meshes/CAD/hand_right_thumb_link0.stl</uri>
						<scale>0.001 0.001 0.001</scale>
					</mesh>
				</geometry>
			</visual>
		</link>
		<link name="hand_right_thumb_link1">
			<self_collide>false</self_collide>
			<pose frame="">-0.28518126210600175 -0.06949389686738094 -0.10234034214719438 0.0 -0.0 0.0</pose>
			<inertial>
				<pose frame="">0.0 0.0 0.0 0 0 0</pose>
				<mass>0.030820279205615926</mass>
				<inertia>
					<ixx>0.00047354686435865923</ixx>
					<ixy>-0.0006108457794926406</ixy>
					<ixz>-0.0008995080597354184</ixz>
					<iyy>0.0028304983226064926</iyy>
					<iyz>-0.00021916236474813633</iyz>
					<izz>0.0026576333055511924</izz>
				</inertia>
			</inertial>
			<collision name="hand_right_thumb_link1_collision">
				<geometry>
					<mesh>
						<uri>model://roboy_icecream/meshes/CAD/hand_right_thumb_link1.stl</uri>
						<scale>0.001 0.001 0.001</scale>
					</mesh>
				</geometry>
			</collision>
			<visual name="hand_right_thumb_link1_visual">
				<geometry>
					<mesh>
						<uri>model://roboy_icecream/meshes/CAD/hand_right_thumb_link1.stl</uri>
						<scale>0.001 0.001 0.001</scale>
					</mesh>
				</geometry>
			</visual>
		</link>
		<link name="bike_back">
			<self_collide>false</self_collide>
			<pose frame="">-0.00011016712007182441 -0.36126275744903424 -0.5575062332679439 0.0 -0.0 0.0</pose>
			<inertial>
				<pose frame="">0.0 0.0 0.0 0 0 0</pose>
				<mass>12.95134492036292</mass>
				<inertia>
					<ixx>8.442264729699302</ixx>
					<ixy>0.05546017500224689</ixy>
					<ixz>-0.0017735467712802575</ixz>
					<iyy>4.264300775944789</iyy>
					<iyz>-2.9995137524469553</iyz>
					<izz>4.303003496245288</izz>
				</inertia>
			</inertial>
			<collision name="bike_back_collision">
				<geometry>
					<mesh>
						<uri>model://roboy_icecream/meshes/CAD/bike_back.stl</uri>
						<scale>0.001 0.001 0.001</scale>
					</mesh>
				</geometry>
			</collision>
			<visual name="bike_back_visual">
				<geometry>
					<mesh>
						<uri>model://roboy_icecream/meshes/CAD/bike_back.stl</uri>
						<scale>0.001 0.001 0.001</scale>
					</mesh>
				</geometry>
			</visual>
		</link>
		<link name="bike_front">
			<self_collide>false</self_collide>
			<pose frame="">-0.00037820010342195663 -0.8693054887433815 0.08557190035773946 0.0 -0.0 0.0</pose>
			<inertial>
				<pose frame="">0.0 0.0 0.0 0 0 0</pose>
				<mass>1286.0735575666731</mass>
				<inertia>
					<ixx>1309.930820530021</ixx>
					<ixy>1.0887808321170818</ixy>
					<ixz>0.8803936253774313</ixz>
					<iyy>143.49238189135068</iyy>
					<iyz>-26.118381241082727</iyz>
					<izz>1223.7503807159978</izz>
				</inertia>
			</inertial>
			<collision name="bike_front_collision">
				<geometry>
					<mesh>
						<uri>model://roboy_icecream/meshes/CAD/bike_front.stl</uri>
						<scale>0.001 0.001 0.001</scale>
					</mesh>
				</geometry>
			</collision>
			<visual name="bike_front_visual">
				<geometry>
					<mesh>
						<uri>model://roboy_icecream/meshes/CAD/bike_front.stl</uri>
						<scale>0.001 0.001 0.001</scale>
					</mesh>
				</geometry>
			</visual>
		</link>
		<link name="ice_right">
			<self_collide>false</self_collide>
			<pose frame="">-0.0019400036637423396 -0.7360125009806154 0.5511586025301096 0.0 -0.0 0.0</pose>
			<inertial>
				<pose frame="">0.0 0.0 0.0 0 0 0</pose>
				<mass>223.72499999996805</mass>
				<inertia>
					<ixx>107.50798517446542</ixx>
					<ixy>-16.17305146305305</ixy>
					<ixz>8.843293061360116</ixz>
					<iyy>29.834372231730242</iyy>
					<iyz>44.31003474165655</iyz>
					<izz>86.47467008535332</izz>
				</inertia>
			</inertial>
			<collision name="ice_right_collision">
				<geometry>
					<mesh>
						<uri>model://roboy_icecream/meshes/CAD/ice_right.stl</uri>
						<scale>0.001 0.001 0.001</scale>
					</mesh>
				</geometry>
			</collision>
			<visual name="ice_right_visual">
				<geometry>
					<mesh>
						<uri>model://roboy_icecream/meshes/CAD/ice_right.stl</uri>
						<scale>0.001 0.001 0.001</scale>
					</mesh>
				</geometry>
			</visual>
		</link>
		<link name="ice_left">
			<self_collide>false</self_collide>
			<pose frame="">0.23805999633628205 -0.7360125009806001 0.5511586025301086 0.0 -0.0 0.0</pose>
			<inertial>
				<pose frame="">0.0 0.0 0.0 0 0 0</pose>
				<mass>223.7249999999783</mass>
				<inertia>
					<ixx>107.50798517447103</ixx>
					<ixy>15.658441357276967</ixy>
					<ixz>-8.561908439038998</ixz>
					<iyy>29.62603911829325</iyy>
					<iyz>44.31003474165987</iyz>
					<izz>86.26633697191618</izz>
				</inertia>
			</inertial>
			<collision name="ice_left_collision">
				<geometry>
					<mesh>
						<uri>model://roboy_icecream/meshes/CAD/ice_left.stl</uri>
						<scale>0.001 0.001 0.001</scale>
					</mesh>
				</geometry>
			</collision>
			<visual name="ice_left_visual">
				<geometry>
					<mesh>
						<uri>model://roboy_icecream/meshes/CAD/ice_left.stl</uri>
						<scale>0.001 0.001 0.001</scale>
					</mesh>
				</geometry>
			</visual>
		</link>
		<link name="sphere_link1">
			<self_collide>false</self_collide>
			<pose frame="">-0.2653954527924725 -0.018887866786133602 -0.11379744618355032 0.0 -0.0 0.0</pose>
			<inertial>
				<pose frame="">0.0 0.0 0.0 0 0 0</pose>
				<mass>0.0380636073185614</mass>
				<inertia>
					<ixx>0.000508176230091826</ixx>
					<ixy>-0.00019080350019897474</ixy>
					<ixz>-0.0011495713660317828</ixz>
					<iyy>0.003175597480686683</iyy>
					<iyz>-8.181357510811029e-05</iyz>
					<izz>0.0026962584186364146</izz>
				</inertia>
			</inertial>
			<collision name="sphere_link1_collision">
				<geometry>
					<mesh>
						<uri>model://roboy_icecream/meshes/CAD/sphere_link1.stl</uri>
						<scale>0.001 0.001 0.001</scale>
					</mesh>
				</geometry>
			</collision>
			<visual name="sphere_link1_visual">
				<geometry>
					<mesh>
						<uri>model://roboy_icecream/meshes/CAD/sphere_link1.stl</uri>
						<scale>0.001 0.001 0.001</scale>
					</mesh>
				</geometry>
			</visual>
		</link>
		<link name="sphere_link2">
			<self_collide>false</self_collide>
			<pose frame="">-0.2653953537818476 -0.0188878785462205 -0.11379734678037905 0.0 -0.0 0.0</pose>
			<inertial>
				<pose frame="">0.0 0.0 0.0 0 0 0</pose>
				<mass>0.002996372533076606</mass>
				<inertia>
					<ixx>3.9895765680050054e-05</ixx>
					<ixy>-1.5020082023172697e-05</ixy>
					<ixz>-9.049430715461394e-05</ixz>
					<iyy>0.00024987538582296455</iyy>
					<iyz>-6.44037455179304e-06</iyz>
					<izz>0.00021214181428445342</izz>
				</inertia>
			</inertial>
			<collision name="sphere_link2_collision">
				<geometry>
					<mesh>
						<uri>model://roboy_icecream/meshes/CAD/sphere_link2.stl</uri>
						<scale>0.001 0.001 0.001</scale>
					</mesh>
				</geometry>
			</collision>
			<visual name="sphere_link2_visual">
				<geometry>
					<mesh>
						<uri>model://roboy_icecream/meshes/CAD/sphere_link2.stl</uri>
						<scale>0.001 0.001 0.001</scale>
					</mesh>
				</geometry>
			</visual>
		</link>
		<link name="zed_mini">
			<self_collide>false</self_collide>
			<pose frame="">0.02322501301146375 -0.1232733897452168 0.3935501389320271 0.0 -0.0 0.0</pose>
			<inertial>
				<pose frame="">0.0 0.0 0.0 0 0 0</pose>
				<mass>0.4361891515825779</mass>
				<inertia>
					<ixx>0.07372570032900573</ixx>
					<ixy>-6.039631699136602e-05</ixy>
					<ixz>0.00017504257606619738</ixz>
					<iyy>0.06813337441384375</iyy>
					<iyz>0.02033700624275044</iyz>
					<izz>0.006694076484380289</izz>
				</inertia>
			</inertial>
			<collision name="zed_mini_collision">
				<geometry>
					<mesh>
						<uri>model://roboy_icecream/meshes/CAD/zed_mini.stl</uri>
						<scale>0.001 0.001 0.001</scale>
					</mesh>
				</geometry>
			</collision>
			<visual name="zed_mini_visual">
				<geometry>
					<mesh>
						<uri>model://roboy_icecream/meshes/CAD/zed_mini.stl</uri>
						<scale>0.001 0.001 0.001</scale>
					</mesh>
				</geometry>
			</visual>
		</link>
		<link name="pico_flexx">
			<self_collide>false</self_collide>
			<pose frame="">0.02323201118942608 -0.11973304071251835 0.4151631471592666 0.0 -0.0 0.0</pose>
			<inertial>
				<pose frame="">0.0 0.0 0.0 0 0 0</pose>
				<mass>0.015436810520105725</mass>
				<inertia>
					<ixx>0.002875421255626839</ixx>
					<ixy>2.9660158239676395e-05</ixy>
					<ixz>-0.00010489305253890309</ixz>
					<iyy>0.0026725118873622</iyy>
					<iyz>0.000754334562869831</iyz>
					<izz>0.0002248664301355404</izz>
				</inertia>
			</inertial>
			<collision name="pico_flexx_collision">
				<geometry>
					<mesh>
						<uri>model://roboy_icecream/meshes/CAD/pico_flexx.stl</uri>
						<scale>0.001 0.001 0.001</scale>
					</mesh>
				</geometry>
			</collision>
			<visual name="pico_flexx_visual">
				<geometry>
					<mesh>
						<uri>model://roboy_icecream/meshes/CAD/pico_flexx.stl</uri>
						<scale>0.001 0.001 0.001</scale>
					</mesh>
				</geometry>
			</visual>
		</link>
		<joint name="shoulder_left_axis0" type="revolute">
			<parent>torso</parent>
			<child>shoulder_left_link1</child>
			<pose frame="">-1.1385505445105081e-08 1.2559192860583934e-07 1.4254478415409721e-08 0 0 0</pose>
			<axis>
				<xyz>-0.9986354432836135 -0.05074429632816786 0.012339684270767625</xyz>
				<limit>
					<lower>-3.141592653589793</lower>
					<upper>3.141592653589793</upper>
				</limit>
				<use_parent_model_frame>0</use_parent_model_frame>
			</axis>
		</joint>
		<joint name="shoulder_left_axis1" type="revolute">
			<parent>shoulder_left_link1</parent>
			<child>shoulder_left_link2</child>
			<pose frame="">-3.552713678800501e-17 9.389691246752819e-12 -1.5701394318057283e-09 0 0 0</pose>
			<axis>
				<xyz>-0.05101049431667528 0.998448888302568 -0.022310242422104942</xyz>
				<limit>
					<lower>-3.141592653589793</lower>
					<upper>3.141592653589793</upper>
				</limit>
				<use_parent_model_frame>0</use_parent_model_frame>
			</axis>
		</joint>
		<joint name="shoulder_left_axis2" type="revolute">
			<parent>shoulder_left_link2</parent>
			<child>arm_left_upper</child>
			<pose frame="">0.0016205660854736337 0.003569171458423541 0.15624324435778825 0 0 0</pose>
			<axis>
				<xyz>-0.011188426489531611 -0.022909252225327616 -0.9996749398055182</xyz>
				<limit>
					<lower>-3.141592653589793</lower>
					<upper>3.141592653589793</upper>
				</limit>
				<use_parent_model_frame>0</use_parent_model_frame>
			</axis>
		</joint>
		<joint name="wrist_left" type="revolute">
			<parent>arm_left_lower</parent>
			<child>hand_left_palm</child>
			<pose frame="">-0.011120325296967196 1.7080131811189892e-05 0.045966440505662974 0 0 0</pose>
			<axis>
				<xyz>-0.011188426489531153 -0.02290925222532776 -0.9996749398055007</xyz>
				<limit>
					<lower>-0.8726646259971648</lower>
					<upper>0.8726646259971648</upper>
				</limit>
				<use_parent_model_frame>0</use_parent_model_frame>
			</axis>
		</joint>
		<joint name="spine" type="revolute">
			<parent>torso</parent>
			<child>bike_back</child>
			<pose frame="">0.00011016712009334052 0.36124080296251676 0.8568435077144142 0 0 0</pose>
			<axis>
				<xyz>8.881784197001363e-16 -8.242182021273602e-15 -1.0000000000000013</xyz>
				<limit>
					<lower>0.0</lower>
					<upper>0.0</upper>
				</limit>
				<use_parent_model_frame>0</use_parent_model_frame>
			</axis>
		</joint>
		<joint name="wrist_right" type="revolute">
			<parent>arm_right_lower</parent>
			<child>palm_right</child>
			<pose frame="">0.007063975929724222 0.002562951319765832 0.04792469067486671 0 0 0</pose>
			<axis>
				<xyz>0.012342838793137056 -0.00025121261310204554 -0.999923792707598</xyz>
				<limit>
					<lower>-0.8726646259971648</lower>
					<upper>0.8726646259971648</upper>
				</limit>
				<use_parent_model_frame>0</use_parent_model_frame>
			</axis>
		</joint>
		<joint name="ice_tray_0" type="prismatic">
			<parent>bike_front</parent>
			<child>ice_left</child>
			<pose frame="">2.1316282072803005e-16 0.0 0.0 0 0 0</pose>
			<axis>
				<xyz>-3.6150825819961146e-14 0.4999999999999186 0.8660254037845042</xyz>
				<limit>
					<lower>0.0</lower>
					<upper>0.0</upper>
				</limit>
				<use_parent_model_frame>0</use_parent_model_frame>
			</axis>
		</joint>
		<joint name="ice_tray_1" type="prismatic">
			<parent>bike_front</parent>
			<child>ice_right</child>
			<pose frame="">4.3853809472693685e-17 -1.4210854715202004e-16 0.0 0 0 0</pose>
			<axis>
				<xyz>-3.6150825819961146e-14 0.4999999999999186 0.8660254037845042</xyz>
				<limit>
					<lower>0.0</lower>
					<upper>0.0</upper>
				</limit>
				<use_parent_model_frame>0</use_parent_model_frame>
			</axis>
		</joint>
		<joint name="zed_pico_attachement" type="fixed">
			<parent>zed_mini</parent>
			<child>pico_flexx</child>
			<pose frame="">0.034842999999998216 0.004254650967302407 -0.008288772047439608 0 0 0</pose>
		</joint>
		<joint name="zed_mini_attachement" type="fixed">
			<parent>torso</parent>
			<child>zed_mini</child>
			<pose frame="">-0.022750000422820375 0.014450000000001921 0.03001211823853858 0 0 0</pose>
		</joint>
		<joint name="zed_camera_mount" type="fixed">
			<parent>head</parent>
			<child>zed_camera</child>
			<pose frame="">0.01743765468509108 0.001405588958414743 0.008052233827783653 0 0 0</pose>
		</joint>
		<joint name="zed_camera_right" type="fixed">
			<parent>zed_camera</parent>
			<child>zed_camera_right_lense</child>
			<pose frame="">-3.4778066173002385e-05 0.011070006217811717 -0.0023530140921069176 0 0 0</pose>
		</joint>
		<joint name="zed_camera_left" type="fixed">
			<parent>zed_camera</parent>
			<child>zed_camera_left_lense</child>
			<pose frame="">-5.466550911876311e-05 0.011069943702269311 -0.0023530142604900562 0 0 0</pose>
		</joint>
		<joint name="shoulder_right_axis0" type="revolute">
			<parent>torso</parent>
			<child>shoulder_right_link1</child>
			<pose frame="">-5.233583294739219e-08 -3.8736939575012564e-07 1.3259304864732258e-07 0 0 0</pose>
			<axis>
				<xyz>0.9986354432836153 -0.050744296328168695 0.012339684270770077</xyz>
				<limit>
					<lower>-3.141592653589793</lower>
					<upper>3.141592653589793</upper>
				</limit>
				<use_parent_model_frame>0</use_parent_model_frame>
			</axis>
		</joint>
		<joint name="shoulder_right_axis1" type="revolute">
			<parent>shoulder_right_link1</parent>
			<child>shoulder_right_link2</child>
			<pose frame="">1.4210854715202004e-16 1.0502709812953982e-15 8.668621376273222e-15 0 0 0</pose>
			<axis>
				<xyz>-0.050743529127072876 -0.9987116467140966 -0.0003754588500051825</xyz>
				<limit>
					<lower>-3.141592653589793</lower>
					<upper>3.141592653589793</upper>
				</limit>
				<use_parent_model_frame>0</use_parent_model_frame>
			</axis>
		</joint>
		<joint name="shoulder_right_axis2" type="revolute">
			<parent>shoulder_right_link2</parent>
			<child>arm_right_upper</child>
			<pose frame="">-0.0030093304567061453 0.0009088885804061042 0.2520955518543853 0 0 0</pose>
			<axis>
				<xyz>0.01234283879313641 -0.00025121261310212685 -0.9999237927075992</xyz>
				<limit>
					<lower>-3.141592653589793</lower>
					<upper>3.141592653589793</upper>
				</limit>
				<use_parent_model_frame>0</use_parent_model_frame>
			</axis>
		</joint>
		<joint name="neck_axis0" type="revolute">
			<parent>torso</parent>
			<child>neck_link1</child>
			<pose frame="">1.5061504170881626e-10 1.5061483921163798e-10 0.0 0 0 0</pose>
			<axis>
				<xyz>0.12498691257369461 -0.9921583904222635 6.724690979212187e-15</xyz>
				<limit>
					<lower>-0.5235987755982988</lower>
					<upper>0.5235987755982988</upper>
				</limit>
				<use_parent_model_frame>0</use_parent_model_frame>
			</axis>
		</joint>
		<joint name="neck_axis2" type="revolute">
			<parent>neck_link2</parent>
			<child>head</child>
			<pose frame="">-0.0005102180295663994 -0.04492411714425187 -0.14549971508594026 0 0 0</pose>
			<axis>
				<xyz>-2.4972812708040394e-14 3.6318961320475e-15 1.0</xyz>
				<limit>
					<lower>-0.5235987755982988</lower>
					<upper>0.5235987755982988</upper>
				</limit>
				<use_parent_model_frame>0</use_parent_model_frame>
			</axis>
		</joint>
		<joint name="neck_axis1" type="revolute">
			<parent>neck_link1</parent>
			<child>neck_link2</child>
			<pose frame="">1.2766228137374175e-10 1.27663441207293e-10 2.842170943040401e-16 0 0 0</pose>
			<axis>
				<xyz>-0.9921583904222635 -0.12498691257369464 -2.432304617639304e-14</xyz>
				<limit>
					<lower>-0.5235987755982988</lower>
					<upper>0.5235987755982988</upper>
				</limit>
				<use_parent_model_frame>0</use_parent_model_frame>
			</axis>
		</joint>
		<joint name="elbow_left" type="revolute">
			<parent>arm_left_upper</parent>
			<child>arm_left_lower</child>
			<pose frame="">0.010635797633733013 0.0017715390858970025 0.05741836417496831 0 0 0</pose>
			<axis>
				<xyz>-0.9986354432836128 -0.050744296328168986 0.012339684270766831</xyz>
				<limit>
					<lower>0.0</lower>
					<upper>0.0</upper>
				</limit>
				<use_parent_model_frame>0</use_parent_model_frame>
			</axis>
		</joint>
		<joint name="hand_right_index_joint0" type="revolute">
			<parent>palm_right</parent>
			<child>hand_right_index_link0</child>
			<pose frame="">-0.0028131391641338156 -0.0027806004298206633 0.02347834522841847 0 0 0</pose>
			<axis>
				<xyz>0.05162618394148187 0.9948893529790475 -0.08677506819672998</xyz>
				<limit>
					<lower>0.0</lower>
					<upper>0.0</upper>
				</limit>
				<use_parent_model_frame>0</use_parent_model_frame>
			</axis>
		</joint>
		<joint name="hand_right_middle_joint0" type="revolute">
			<parent>palm_right</parent>
			<child>hand_right_middle_link0</child>
			<pose frame="">-0.002912317796690651 -0.004816071540397454 0.023134424316041055 0 0 0</pose>
			<axis>
				<xyz>0.05074352906433636 0.9987116467153601 0.0003754639332382525</xyz>
				<limit>
					<lower>0.0</lower>
					<upper>0.0</upper>
				</limit>
				<use_parent_model_frame>0</use_parent_model_frame>
			</axis>
		</joint>
		<joint name="hand_right_ring_joint0" type="revolute">
			<parent>palm_right</parent>
			<child>hand_right_ring_link0</child>
			<pose frame="">-0.003007421184327228 -0.006814058582345273 0.022613944133882544 0 0 0</pose>
			<axis>
				<xyz>0.04947468535373819 0.9949331417803167 0.087523133492076</xyz>
				<limit>
					<lower>0.0</lower>
					<upper>0.0</upper>
				</limit>
				<use_parent_model_frame>0</use_parent_model_frame>
			</axis>
		</joint>
		<joint name="hand_right_little_joint0" type="revolute">
			<parent>palm_right</parent>
			<child>hand_right_little_link0</child>
			<pose frame="">-0.0021666110399336702 -0.006707951777146972 0.012830029429174524 0 0 0</pose>
			<axis>
				<xyz>0.04853190544031668 0.989027215659634 0.13953429986515434</xyz>
				<limit>
					<lower>0.0</lower>
					<upper>0.0</upper>
				</limit>
				<use_parent_model_frame>0</use_parent_model_frame>
			</axis>
		</joint>
		<joint name="hand_right_thumb_joint0" type="revolute">
			<parent>palm_right</parent>
			<child>hand_right_thumb_link0</child>
			<pose frame="">0.0009215301773278739 0.019151208397902072 0.007204123085534277 0 0 0</pose>
			<axis>
				<xyz>-0.012342838793178245 0.00025121261308564666 0.9999237927075988</xyz>
				<limit>
					<lower>0.0</lower>
					<upper>0.0</upper>
				</limit>
				<use_parent_model_frame>0</use_parent_model_frame>
			</axis>
		</joint>
		<joint name="hand_right_index_joint1" type="revolute">
			<parent>hand_right_index_link0</parent>
			<child>hand_right_index_link1</child>
			<pose frame="">-0.0020155492683139897 -0.0034466777598363006 0.014014938001170095 0 0 0</pose>
			<axis>
				<xyz>0.051626183941509786 0.9948893529790515 -0.08677506819671307</xyz>
				<limit>
					<lower>0.0</lower>
					<upper>0.0</upper>
				</limit>
				<use_parent_model_frame>0</use_parent_model_frame>
			</axis>
		</joint>
		<joint name="hand_right_index_joint2" type="revolute">
			<parent>hand_right_index_link1</parent>
			<child>hand_right_index_link2</child>
			<pose frame="">-0.0015810436413474349 -0.0035367948741371925 0.01326625072013087 0 0 0</pose>
			<axis>
				<xyz>0.0516261839415094 0.9948893529790476 -0.08677506819671245</xyz>
				<limit>
					<lower>0.0</lower>
					<upper>0.0</upper>
				</limit>
				<use_parent_model_frame>0</use_parent_model_frame>
			</axis>
		</joint>
		<joint name="hand_right_middle_joint1" type="revolute">
			<parent>hand_right_middle_link0</parent>
			<child>hand_right_middle_link1</child>
			<pose frame="">-0.002072476496508848 -0.0046552244996650146 0.01365263394758987 0 0 0</pose>
			<axis>
				<xyz>0.050743529064361775 0.9987116467153562 0.0003754639332559508</xyz>
				<limit>
					<lower>0.0</lower>
					<upper>0.0</upper>
				</limit>
				<use_parent_model_frame>0</use_parent_model_frame>
			</axis>
		</joint>
		<joint name="hand_right_middle_joint2" type="revolute">
			<parent>hand_right_middle_link1</parent>
			<child>hand_right_middle_link2</child>
			<pose frame="">-0.0016345793887148474 -0.004679285325599778 0.012900840076042712 0 0 0</pose>
			<axis>
				<xyz>0.05074352906436002 0.9987116467153562 0.0003754639332559343</xyz>
				<limit>
					<lower>0.0</lower>
					<upper>0.0</upper>
				</limit>
				<use_parent_model_frame>0</use_parent_model_frame>
			</axis>
		</joint>
		<joint name="hand_right_ring_joint1" type="revolute">
			<parent>hand_right_ring_link0</parent>
			<child>hand_right_ring_link1</child>
			<pose frame="">-0.0021262859651396226 -0.0058276992009931175 0.013186268019979153 0 0 0</pose>
			<axis>
				<xyz>0.04947468535376103 0.9949331417803101 0.08752313349209379</xyz>
				<limit>
					<lower>0.0</lower>
					<upper>0.0</upper>
				</limit>
				<use_parent_model_frame>0</use_parent_model_frame>
			</axis>
		</joint>
		<joint name="hand_right_ring_joint2" type="revolute">
			<parent>hand_right_ring_link1</parent>
			<child>hand_right_ring_link2</child>
			<pose frame="">-0.001685068018602145 -0.0057857013208338645 0.012437286116995629 0 0 0</pose>
			<axis>
				<xyz>0.04947468535376001 0.9949331417803088 0.08752313349209333</xyz>
				<limit>
					<lower>0.0</lower>
					<upper>0.0</upper>
				</limit>
				<use_parent_model_frame>0</use_parent_model_frame>
			</axis>
		</joint>
		<joint name="hand_right_little_joint1" type="revolute">
			<parent>hand_right_little_link0</parent>
			<child>hand_right_little_link1</child>
			<pose frame="">-0.002156904658419734 -0.006510146331037001 0.012857936267698414 0 0 0</pose>
			<axis>
				<xyz>0.04853190544033895 0.9890272156596233 0.13953429986517193</xyz>
				<limit>
					<lower>0.0</lower>
					<upper>0.0</upper>
				</limit>
				<use_parent_model_frame>0</use_parent_model_frame>
			</axis>
		</joint>
		<joint name="hand_right_little_joint2" type="revolute">
			<parent>hand_right_little_link1</parent>
			<child>hand_right_little_link2</child>
			<pose frame="">-0.0017137375142284484 -0.006428659881749974 0.012113709971122972 0 0 0</pose>
			<axis>
				<xyz>0.04853190544033771 0.9890272156596251 0.13953429986517096</xyz>
				<limit>
					<lower>0.0</lower>
					<upper>0.0</upper>
				</limit>
				<use_parent_model_frame>0</use_parent_model_frame>
			</axis>
		</joint>
		<joint name="hand_right_thumb_joint1" type="revolute">
			<parent>hand_right_thumb_link0</parent>
			<child>hand_right_thumb_link1</child>
			<pose frame="">-0.004070531171370248 0.013899911090302917 0.001611451875300638 0 0 0</pose>
			<axis>
				<xyz>0.998635443283618 -0.050744296328192696 0.012339684270811722</xyz>
				<limit>
					<lower>0.0</lower>
					<upper>0.0</upper>
				</limit>
				<use_parent_model_frame>0</use_parent_model_frame>
			</axis>
		</joint>
		<joint name="hand_right_thumb_joint2" type="revolute">
			<parent>hand_right_thumb_link1</parent>
			<child>hand_right_thumb_link2</child>
			<pose frame="">-0.004304896529828177 0.013155120640487308 0.0011748919950105474 0 0 0</pose>
			<axis>
				<xyz>-0.9986354432836205 0.0507442963281923 -0.012339684270811844</xyz>
				<limit>
					<lower>0.0</lower>
					<upper>0.0</upper>
				</limit>
				<use_parent_model_frame>0</use_parent_model_frame>
			</axis>
		</joint>
		<joint name="bike_steering" type="revolute">
			<parent>bike_back</parent>
			<child>bike_front</child>
			<pose frame="">-0.0015563171980319164 -0.33304325820437686 -0.6892346279284436 0 0 0</pose>
			<axis>
				<xyz>-1.8044974943364984e-16 -9.570458378672299e-08 0.9999999999999957</xyz>
				<limit>
					<lower>-0.5235987755982988</lower>
					<upper>0.5235987755982988</upper>
				</limit>
				<use_parent_model_frame>0</use_parent_model_frame>
			</axis>
		</joint>
		<joint name="hand_left_thumb_joint1" type="revolute">
			<parent>hand_left_thumb_link0</parent>
			<child>hand_left_thumb_link1</child>
			<pose frame="">-0.005423796771802181 0.013452382519349087 0.0014179238094636838 0 0 0</pose>
			<axis>
				<xyz>0.9986354432836053 0.05074429632816909 -0.012339684270769659</xyz>
				<limit>
					<lower>0.0</lower>
					<upper>0.0</upper>
				</limit>
				<use_parent_model_frame>0</use_parent_model_frame>
			</axis>
		</joint>
		<joint name="hand_left_thumb_joint2" type="revolute">
			<parent>hand_left_thumb_link1</parent>
			<child>hand_left_thumb_link2</child>
			<pose frame="">-0.005583923746935646 0.012677388634436682 0.00100409821074825 0 0 0</pose>
			<axis>
				<xyz>-0.9986354432836058 -0.05074429632816833 0.0123396842707689</xyz>
				<limit>
					<lower>0.0</lower>
					<upper>0.0</upper>
				</limit>
				<use_parent_model_frame>0</use_parent_model_frame>
			</axis>
		</joint>
		<joint name="hand_left_little_joint1" type="revolute">
			<parent>hand_left_little_link0</parent>
			<child>hand_left_little_link1</child>
			<pose frame="">0.001678852275008076 0.0032054233921840858 0.014116032964241647 0 0 0</pose>
			<axis>
				<xyz>0.048956935729323275 -0.9919204043249621 -0.11703473812416904</xyz>
				<limit>
					<lower>0.0</lower>
					<upper>0.0</upper>
				</limit>
				<use_parent_model_frame>0</use_parent_model_frame>
			</axis>
		</joint>
		<joint name="hand_left_little_joint2" type="revolute">
			<parent>hand_left_little_link1</parent>
			<child>hand_left_little_link2</child>
			<pose frame="">0.0012360917311110243 0.0032735887480437945 0.013370863380918294 0 0 0</pose>
			<axis>
				<xyz>0.048956935729323275 -0.9919204043249631 -0.11703473812417109</xyz>
				<limit>
					<lower>0.0</lower>
					<upper>0.0</upper>
				</limit>
				<use_parent_model_frame>0</use_parent_model_frame>
			</axis>
		</joint>
		<joint name="hand_left_middle_joint0" type="revolute">
			<parent>hand_left_palm</parent>
			<child>hand_left_middle_link0</child>
			<pose frame="">0.002499618806591428 0.00336644599830247 0.023395525017202736 0 0 0</pose>
			<axis>
				<xyz>-0.04984124836444066 0.9966461617361062 0.06490206667093681</xyz>
				<limit>
					<lower>0.0</lower>
					<upper>0.0</upper>
				</limit>
				<use_parent_model_frame>0</use_parent_model_frame>
			</axis>
		</joint>
		<joint name="hand_left_ring_joint0" type="revolute">
			<parent>hand_left_palm</parent>
			<child>hand_left_ring_link0</child>
			<pose frame="">0.002392045620622554 0.005393046396575082 0.023024430280615144 0 0 0</pose>
			<axis>
				<xyz>0.051010494288238804 -0.9984488883607986 0.022310239881113105</xyz>
				<limit>
					<lower>0.0</lower>
					<upper>0.0</upper>
				</limit>
				<use_parent_model_frame>0</use_parent_model_frame>
			</axis>
		</joint>
		<joint name="hand_left_little_joint0" type="revolute">
			<parent>hand_left_palm</parent>
			<child>hand_left_index_link0</child>
			<pose frame="">0.0022843435978567327 0.00737952551192981 0.022477896208295434 0 0 0</pose>
			<axis>
				<xyz>-0.051791519606186116 0.9926528159491244 -0.10935275709900355</xyz>
				<limit>
					<lower>0.0</lower>
					<upper>0.0</upper>
				</limit>
				<use_parent_model_frame>0</use_parent_model_frame>
			</axis>
		</joint>
		<joint name="hand_left_index_joint0" type="revolute">
			<parent>hand_left_palm</parent>
			<child>hand_left_little_link0</child>
			<pose frame="">0.0009191094691314917 0.0023712916305741504 0.014032276930297254 0 0 0</pose>
			<axis>
				<xyz>-0.04895693572932444 0.9919204043249636 0.1170347381241684</xyz>
				<limit>
					<lower>0.0</lower>
					<upper>0.0</upper>
				</limit>
				<use_parent_model_frame>0</use_parent_model_frame>
			</axis>
		</joint>
		<joint name="hand_left_thumb_joint0" type="revolute">
			<parent>hand_left_palm</parent>
			<child>hand_left_thumb_link0</child>
			<pose frame="">-0.0009610644949359682 0.019106816828791413 -0.0022306282952837897 0 0 0</pose>
			<axis>
				<xyz>0.011188426489532242 0.02290925222532655 0.999674939805514</xyz>
				<limit>
					<lower>0.0</lower>
					<upper>0.0</upper>
				</limit>
				<use_parent_model_frame>0</use_parent_model_frame>
			</axis>
		</joint>
		<joint name="hand_left_index_joint1" type="revolute">
			<parent>hand_left_index_link0</parent>
			<child>hand_left_index_link1</child>
			<pose frame="">0.001508281965548548 0.006300915604268478 0.013053510408873379 0 0 0</pose>
			<axis>
				<xyz>0.05179151960618249 -0.992652815949127 0.10935275709900213</xyz>
				<limit>
					<lower>0.0</lower>
					<upper>0.0</upper>
				</limit>
				<use_parent_model_frame>0</use_parent_model_frame>
			</axis>
		</joint>
		<joint name="hand_left_index_joint2" type="revolute">
			<parent>hand_left_index_link1</parent>
			<child>hand_left_index_link2</child>
			<pose frame="">0.0010743509351732428 0.006197774837368906 0.012306200845747597 0 0 0</pose>
			<axis>
				<xyz>0.05179151960618418 -0.9926528159491258 0.10935275709900277</xyz>
				<limit>
					<lower>0.0</lower>
					<upper>0.0</upper>
				</limit>
				<use_parent_model_frame>0</use_parent_model_frame>
			</axis>
		</joint>
		<joint name="hand_left_middle_joint1" type="revolute">
			<parent>hand_left_middle_link0</parent>
			<child>hand_left_middle_link1</child>
			<pose frame="">0.0016392752510749275 0.003939997311892896 0.0139335888514667 0 0 0</pose>
			<axis>
				<xyz>0.04984124836443787 -0.9966461617361048 -0.06490206667093751</xyz>
				<limit>
					<lower>0.0</lower>
					<upper>0.0</upper>
				</limit>
				<use_parent_model_frame>0</use_parent_model_frame>
			</axis>
		</joint>
		<joint name="hand_left_middle_joint2" type="revolute">
			<parent>hand_left_middle_link1</parent>
			<child>hand_left_middle_link2</child>
			<pose frame="">0.0011984655373084507 0.0039686141470258954 0.013184380535562 0 0 0</pose>
			<axis>
				<xyz>0.04984124836443851 -0.9966461617361043 -0.06490206667093773</xyz>
				<limit>
					<lower>0.0</lower>
					<upper>0.0</upper>
				</limit>
				<use_parent_model_frame>0</use_parent_model_frame>
			</axis>
		</joint>
		<joint name="hand_left_ring_joint1" type="revolute">
			<parent>hand_left_ring_link0</parent>
			<child>hand_left_ring_link1</child>
			<pose frame="">0.0015735110116603223 0.005139821462327344 0.01354481017325817 0 0 0</pose>
			<axis>
				<xyz>0.051010494288236535 -0.9984488883607988 0.022310239881111527</xyz>
				<limit>
					<lower>0.0</lower>
					<upper>0.0</upper>
				</limit>
				<use_parent_model_frame>0</use_parent_model_frame>
			</axis>
		</joint>
		<joint name="hand_left_ring_joint2" type="revolute">
			<parent>hand_left_ring_link1</parent>
			<child>hand_left_ring_link2</child>
			<pose frame="">0.0011360347665007708 0.0051023782516277484 0.012793957418405456 0 0 0</pose>
			<axis>
				<xyz>0.05101049428823773 -0.9984488883607975 0.02231023988111236</xyz>
				<limit>
					<lower>0.0</lower>
					<upper>0.0</upper>
				</limit>
				<use_parent_model_frame>0</use_parent_model_frame>
			</axis>
		</joint>
		<joint name="elbow_right" type="revolute">
			<parent>arm_right_upper</parent>
			<child>arm_right_lower</child>
			<pose frame="">-0.016980052934313258 0.0008475095989118042 0.04051070712681227 0 0 0</pose>
			<axis>
				<xyz>-0.9986354432836136 0.050744296328171457 -0.012339684270769206</xyz>
				<limit>
					<lower>0.0</lower>
					<upper>1.9198621771937625</upper>
				</limit>
				<use_parent_model_frame>0</use_parent_model_frame>
			</axis>
		</joint>
		<joint name="scooper_axis0" type="revolute">
			<parent>palm_right</parent>
			<child>sphere_link1</child>
			<pose frame="">9.901062504980018e-08 -1.1760062330612441e-08 9.940317404755206e-08 0 0 0</pose>
			<axis>
				<xyz>0.050743529127074125 0.998711646714098 0.0003754588500069938</xyz>
				<limit>
					<lower>-3.141592653589793</lower>
					<upper>3.141592653589793</upper>
				</limit>
				<use_parent_model_frame>0</use_parent_model_frame>
			</axis>
		</joint>
		<joint name="scooper_axis1" type="revolute">
			<parent>sphere_link1</parent>
			<child>sphere_link2</child>
			<pose frame="">7.105427357601002e-17 2.446487457063995e-14 2.7888802378583933e-15 0 0 0</pose>
			<axis>
				<xyz>-0.9986354432836139 0.0507442963281716 -0.01233968427077307</xyz>
				<limit>
					<lower>-3.141592653589793</lower>
					<upper>3.141592653589793</upper>
				</limit>
				<use_parent_model_frame>0</use_parent_model_frame>
			</axis>
		</joint>
		<joint name="scooper_axis2" type="revolute">
			<parent>sphere_link2</parent>
			<child>scooper</child>
			<pose frame="">0.0043115026420995056 0.08485708380117427 3.190144342836376e-05 0 0 0</pose>
			<axis>
				<xyz>-0.012342838793139613 0.00025121261310145394 0.9999237927075986</xyz>
				<limit>
					<lower>-3.141592653589793</lower>
					<upper>3.141592653589793</upper>
				</limit>
				<use_parent_model_frame>0</use_parent_model_frame>
			</axis>
		</joint>
		<plugin filename="libcardsflow_gazebo_plugin.so" name="cardsflow_gazebo_plugin"/>
	</model>
</sdf>
