<?xml version="1.0" ?>
<sdf version="1.6">
	<model name="roboy_icecream">
		<link name="head">
			<self_collide>false</self_collide>
			<pose frame="">0.0005102180295681476 0.04644589822931183 0.8561776624188784 0.0 -0.0 0.0</pose>
			<inertial>
				<pose frame="">0.0 0.0 0.0 0 0 0</pose>
				<mass>2.049574035129544</mass>
				<inertia>
					<ixx>1.5391376142687254</ixx>
					<ixy>-6.31350710166865e-05</ixy>
					<ixz>-0.0010067309324672444</ixz>
					<iyy>1.5283787902680657</iyy>
					<iyz>-0.08418987485585483</iyz>
					<izz>0.030527659727341366</izz>
				</inertia>
			</inertial>
			<collision name="head_collision">
				<geometry>
					<mesh>
						<uri>model://roboy_icecream/meshes/CAD/head.stl</uri>
						<scale>0.001 0.001 0.001</scale>
					</mesh>
				</geometry>
			</collision>
			<visual name="head_visual">
				<geometry>
					<mesh>
						<uri>model://roboy_icecream/meshes/CAD/head.stl</uri>
						<scale>0.001 0.001 0.001</scale>
					</mesh>
				</geometry>
			</visual>
		</link>
		<link name="torso">
			<self_collide>false</self_collide>
			<pose frame="">-5.35255132199797e-05 -0.00020638163411973998 0.50876963867826 0.0 -0.0 0.0</pose>
			<inertial>
				<pose frame="">0.0 0.0 0.0 0 0 0</pose>
				<mass>11.588247145877936</mass>
				<inertia>
					<ixx>3.1859782556023406</ixx>
					<ixy>-0.001191181670861379</ixy>
					<ixz>0.0004984982415414905</ixz>
					<iyy>3.4400774592858085</iyy>
					<iyz>0.01219012705845549</iyz>
					<izz>0.32178508230654973</izz>
				</inertia>
			</inertial>
			<collision name="torso_collision">
				<geometry>
					<mesh>
						<uri>model://roboy_icecream/meshes/CAD/torso.stl</uri>
						<scale>0.001 0.001 0.001</scale>
					</mesh>
				</geometry>
			</collision>
			<visual name="torso_visual">
				<geometry>
					<mesh>
						<uri>model://roboy_icecream/meshes/CAD/torso.stl</uri>
						<scale>0.001 0.001 0.001</scale>
					</mesh>
				</geometry>
			</visual>
		</link>
		<link name="arm_left_lower">
			<self_collide>false</self_collide>
			<pose frame="">0.5370118768504009 -0.17878250619837036 0.24127175534900333 0.0 -0.0 0.0</pose>
			<inertial>
				<pose frame="">0.0 0.0 0.0 0 0 0</pose>
				<mass>7.274099416132553</mass>
				<inertia>
					<ixx>0.6824865040540118</ixx>
					<ixy>0.7057047294472619</ixy>
					<ixz>-0.9308804872173747</ixz>
					<iyy>2.5509906797462913</iyy>
					<iyz>0.3044744819209398</iyz>
					<izz>2.35120045708884</izz>
				</inertia>
			</inertial>
			<collision name="arm_left_lower_collision">
				<geometry>
					<mesh>
						<uri>model://roboy_icecream/meshes/CAD/arm_left_lower.stl</uri>
						<scale>0.001 0.001 0.001</scale>
					</mesh>
				</geometry>
			</collision>
			<visual name="arm_left_lower_visual">
				<geometry>
					<mesh>
						<uri>model://roboy_icecream/meshes/CAD/arm_left_lower.stl</uri>
						<scale>0.001 0.001 0.001</scale>
					</mesh>
				</geometry>
			</visual>
		</link>
		<link name="arm_left_palm (1)">
			<self_collide>false</self_collide>
			<pose frame="">0.6359469314832951 -0.24454698645113343 0.1348884192569091 0.0 -0.0 0.0</pose>
			<inertial>
				<pose frame="">0.0 0.0 0.0 0 0 0</pose>
				<mass>0.8080005307682491</mass>
				<inertia>
					<ixx>0.06400764902654485</ixx>
					<ixy>0.1258640923370552</ixy>
					<ixz>-0.06904914366800075</ixz>
					<iyy>0.3422930834799746</iyy>
					<iyz>0.026705627916892877</iyz>
					<izz>0.37597182022258535</izz>
				</inertia>
			</inertial>
			<collision name="arm_left_palm (1)_collision">
				<geometry>
					<mesh>
						<uri>model://roboy_icecream/meshes/CAD/arm_left_palm (1).stl</uri>
						<scale>0.001 0.001 0.001</scale>
					</mesh>
				</geometry>
			</collision>
			<visual name="arm_left_palm (1)_visual">
				<geometry>
					<mesh>
						<uri>model://roboy_icecream/meshes/CAD/arm_left_palm (1).stl</uri>
						<scale>0.001 0.001 0.001</scale>
					</mesh>
				</geometry>
			</visual>
		</link>
		<link name="arm_right_palm">
			<self_collide>false</self_collide>
			<pose frame="">-0.6375555744206083 -0.246773796558467 0.13554097790837938 0.0 -0.0 0.0</pose>
			<inertial>
				<pose frame="">0.0 0.0 0.0 0 0 0</pose>
				<mass>0.808000531384317</mass>
				<inertia>
					<ixx>0.06503830374218557</ixx>
					<ixy>-0.12733108249741354</ixy>
					<ixz>0.06955734554180544</ixz>
					<iyy>0.3440972969271582</iyy>
					<iyz>0.02707665325632976</iyz>
					<izz>0.37851555642003903</izz>
				</inertia>
			</inertial>
			<collision name="arm_right_palm_collision">
				<geometry>
					<mesh>
						<uri>model://roboy_icecream/meshes/CAD/arm_right_palm.stl</uri>
						<scale>0.001 0.001 0.001</scale>
					</mesh>
				</geometry>
			</collision>
			<visual name="arm_right_palm_visual">
				<geometry>
					<mesh>
						<uri>model://roboy_icecream/meshes/CAD/arm_right_palm.stl</uri>
						<scale>0.001 0.001 0.001</scale>
					</mesh>
				</geometry>
			</visual>
		</link>
		<link name="arm_right_lower">
			<self_collide>false</self_collide>
			<pose frame="">-0.5385846651599526 -0.18098143715678475 0.24196868697070045 0.0 -0.0 0.0</pose>
			<inertial>
				<pose frame="">0.0 0.0 0.0 0 0 0</pose>
				<mass>7.2740976072296055</mass>
				<inertia>
					<ixx>0.690512096677852</ixx>
					<ixy>-0.716299861565448</ixy>
					<ixz>0.9364740527049602</ixz>
					<iyy>2.565534702863339</iyy>
					<iyz>0.30933175817827113</iyz>
					<izz>2.3691261645369357</izz>
				</inertia>
			</inertial>
			<collision name="arm_right_lower_collision">
				<geometry>
					<mesh>
						<uri>model://roboy_icecream/meshes/CAD/arm_right_lower.stl</uri>
						<scale>0.001 0.001 0.001</scale>
					</mesh>
				</geometry>
			</collision>
			<visual name="arm_right_lower_visual">
				<geometry>
					<mesh>
						<uri>model://roboy_icecream/meshes/CAD/arm_right_lower.stl</uri>
						<scale>0.001 0.001 0.001</scale>
					</mesh>
				</geometry>
			</visual>
		</link>
		<link name="arm_left_upper">
			<self_collide>false</self_collide>
			<pose frame="">0.40564551581889086 -0.0756025172958533 0.40562448932447825 0.0 -0.0 0.0</pose>
			<inertial>
				<pose frame="">0.0 0.0 0.0 0 0 0</pose>
				<mass>3.332387331782339</mass>
				<inertia>
					<ixx>0.5834564080291924</ixx>
					<ixy>0.1072741049186716</ixy>
					<ixz>-0.5400829387946827</ixz>
					<iyy>1.1162868235790058</iyy>
					<iyz>0.09565169256835752</iyz>
					<izz>0.580700227737085</izz>
				</inertia>
			</inertial>
			<collision name="arm_left_upper_collision">
				<geometry>
					<mesh>
						<uri>model://roboy_icecream/meshes/CAD/arm_left_upper.stl</uri>
						<scale>0.001 0.001 0.001</scale>
					</mesh>
				</geometry>
			</collision>
			<visual name="arm_left_upper_visual">
				<geometry>
					<mesh>
						<uri>model://roboy_icecream/meshes/CAD/arm_left_upper.stl</uri>
						<scale>0.001 0.001 0.001</scale>
					</mesh>
				</geometry>
			</visual>
		</link>
		<link name="shoulder_left_link1">
			<self_collide>false</self_collide>
			<pose frame="">0.2918943672417947 0.013936393619393582 0.5448918362217308 0.0 -0.0 0.0</pose>
			<inertial>
				<pose frame="">0.0 0.0 0.0 0 0 0</pose>
				<mass>0.09036359201900478</mass>
				<inertia>
					<ixx>0.026854235531623766</ixx>
					<ixy>-0.00036759500737930086</ixy>
					<ixz>-0.014372406819918018</ixz>
					<iyy>0.034535872662129895</iyy>
					<iyz>-0.0006862054947928941</iyz>
					<izz>0.007723830113048254</izz>
				</inertia>
			</inertial>
			<collision name="shoulder_left_link1_collision">
				<geometry>
					<mesh>
						<uri>model://roboy_icecream/meshes/CAD/shoulder_left_link1.stl</uri>
						<scale>0.001 0.001 0.001</scale>
					</mesh>
				</geometry>
			</collision>
			<visual name="shoulder_left_link1_visual">
				<geometry>
					<mesh>
						<uri>model://roboy_icecream/meshes/CAD/shoulder_left_link1.stl</uri>
						<scale>0.001 0.001 0.001</scale>
					</mesh>
				</geometry>
			</visual>
		</link>
		<link name="shoulder_left_link2">
			<self_collide>false</self_collide>
			<pose frame="">0.2918943623808747 0.013936393384462419 0.5448918357909863 0.0 -0.0 0.0</pose>
			<inertial>
				<pose frame="">0.0 0.0 0.0 0 0 0</pose>
				<mass>0.007113170038864662</mass>
				<inertia>
					<ixx>0.002113434852236192</ixx>
					<ixy>-2.893605321299586e-05</ixy>
					<ixz>-0.0011313557762622297</ixz>
					<iyy>0.0027181118918378614</iyy>
					<iyz>-5.401618252193771e-05</iyz>
					<izz>0.0006075426550467592</izz>
				</inertia>
			</inertial>
			<collision name="shoulder_left_link2_collision">
				<geometry>
					<mesh>
						<uri>model://roboy_icecream/meshes/CAD/shoulder_left_link2.stl</uri>
						<scale>0.001 0.001 0.001</scale>
					</mesh>
				</geometry>
			</collision>
			<visual name="shoulder_left_link2_visual">
				<geometry>
					<mesh>
						<uri>model://roboy_icecream/meshes/CAD/shoulder_left_link2.stl</uri>
						<scale>0.001 0.001 0.001</scale>
					</mesh>
				</geometry>
			</visual>
		</link>
		<link name="hand_left_index_link1">
			<self_collide>false</self_collide>
			<pose frame="">0.7020945590519067 -0.3257722239676192 0.07631210623358395 0.0 -0.0 0.0</pose>
			<inertial>
				<pose frame="">0.0 0.0 0.0 0 0 0</pose>
				<mass>0.030810600216883127</mass>
				<inertia>
					<ixx>0.003451130134767462</ixx>
					<ixy>0.007047412528056845</ixy>
					<ixz>-0.0016503707008156752</ixz>
					<iyy>0.01536886345493646</iyy>
					<iyz>0.0007657743886956822</iyz>
					<izz>0.018459200151619736</izz>
				</inertia>
			</inertial>
			<collision name="hand_left_index_link1_collision">
				<geometry>
					<mesh>
						<uri>model://roboy_icecream/meshes/CAD/hand_left_index_link1.stl</uri>
						<scale>0.001 0.001 0.001</scale>
					</mesh>
				</geometry>
			</collision>
			<visual name="hand_left_index_link1_visual">
				<geometry>
					<mesh>
						<uri>model://roboy_icecream/meshes/CAD/hand_left_index_link1.stl</uri>
						<scale>0.001 0.001 0.001</scale>
					</mesh>
				</geometry>
			</visual>
		</link>
		<link name="hand_left_index_link0">
			<self_collide>false</self_collide>
			<pose frame="">0.6813873765209766 -0.30793269611963325 0.0989924007864984 0.0 -0.0 0.0</pose>
			<inertial>
				<pose frame="">0.0 0.0 0.0 0 0 0</pose>
				<mass>0.05584900095770272</mass>
				<inertia>
					<ixx>0.005850484085961029</ixx>
					<ixy>0.011720711373498002</ixy>
					<ixz>-0.0037640900475691724</ixz>
					<iyy>0.02648515087867049</iyy>
					<iyz>0.0016999571512312788</iyz>
					<izz>0.031232412023588268</izz>
				</inertia>
			</inertial>
			<collision name="hand_left_index_link0_collision">
				<geometry>
					<mesh>
						<uri>model://roboy_icecream/meshes/CAD/hand_left_index_link0.stl</uri>
						<scale>0.001 0.001 0.001</scale>
					</mesh>
				</geometry>
			</collision>
			<visual name="hand_left_index_link0_visual">
				<geometry>
					<mesh>
						<uri>model://roboy_icecream/meshes/CAD/hand_left_index_link0.stl</uri>
						<scale>0.001 0.001 0.001</scale>
					</mesh>
				</geometry>
			</visual>
		</link>
		<link name="hand_left_index_link2">
			<self_collide>false</self_collide>
			<pose frame="">0.7167599123101644 -0.33846917194165477 0.060149045470648206 0.0 -0.0 0.0</pose>
			<inertial>
				<pose frame="">0.0 0.0 0.0 0 0 0</pose>
				<mass>0.03033723588882973</mass>
				<inertia>
					<ixx>0.003586860390106059</ixx>
					<ixy>0.007360006720784269</ixy>
					<ixz>-0.001307630720753741</ixz>
					<iyy>0.01569667077023579</iyy>
					<iyz>0.0006174739980112084</iyz>
					<izz>0.019062295033624426</izz>
				</inertia>
			</inertial>
			<collision name="hand_left_index_link2_collision">
				<geometry>
					<mesh>
						<uri>model://roboy_icecream/meshes/CAD/hand_left_index_link2.stl</uri>
						<scale>0.001 0.001 0.001</scale>
					</mesh>
				</geometry>
			</collision>
			<visual name="hand_left_index_link2_visual">
				<geometry>
					<mesh>
						<uri>model://roboy_icecream/meshes/CAD/hand_left_index_link2.stl</uri>
						<scale>0.001 0.001 0.001</scale>
					</mesh>
				</geometry>
			</visual>
		</link>
		<link name="hand_left_middle_link1">
			<self_collide>false</self_collide>
			<pose frame="">0.6984378123567987 -0.27142015861904967 0.04026810273649315 0.0 -0.0 0.0</pose>
			<inertial>
				<pose frame="">0.0 0.0 0.0 0 0 0</pose>
				<mass>0.030810738819908257</mass>
				<inertia>
					<ixx>0.0023216116713992026</ixx>
					<ixy>0.005841048550929517</ixy>
					<ixz>-0.0008660950879176442</ixz>
					<iyy>0.015081765106218456</iyy>
					<iyz>0.0003366030494656799</iyz>
					<izz>0.017301313134214256</izz>
				</inertia>
			</inertial>
			<collision name="hand_left_middle_link1_collision">
				<geometry>
					<mesh>
						<uri>model://roboy_icecream/meshes/CAD/hand_left_middle_link1.stl</uri>
						<scale>0.001 0.001 0.001</scale>
					</mesh>
				</geometry>
			</collision>
			<visual name="hand_left_middle_link1_visual">
				<geometry>
					<mesh>
						<uri>model://roboy_icecream/meshes/CAD/hand_left_middle_link1.stl</uri>
						<scale>0.001 0.001 0.001</scale>
					</mesh>
				</geometry>
			</visual>
		</link>
		<link name="hand_left_middle_link0">
			<self_collide>false</self_collide>
			<pose frame="">0.6780397787920355 -0.2587027863289873 0.06641222995506742 0.0 -0.0 0.0</pose>
			<inertial>
				<pose frame="">0.0 0.0 0.0 0 0 0</pose>
				<mass>0.05583133481654662</mass>
				<inertia>
					<ixx>0.0039903927981514474</ixx>
					<ixy>0.009795111643438223</ixy>
					<ixz>-0.0025106493507908757</ixz>
					<iyy>0.02592273738131168</iyy>
					<iyz>0.0009571975874373423</iyz>
					<izz>0.029409880446191132</izz>
				</inertia>
			</inertial>
			<collision name="hand_left_middle_link0_collision">
				<geometry>
					<mesh>
						<uri>model://roboy_icecream/meshes/CAD/hand_left_middle_link0.stl</uri>
						<scale>0.001 0.001 0.001</scale>
					</mesh>
				</geometry>
			</collision>
			<visual name="hand_left_middle_link0_visual">
				<geometry>
					<mesh>
						<uri>model://roboy_icecream/meshes/CAD/hand_left_middle_link0.stl</uri>
						<scale>0.001 0.001 0.001</scale>
					</mesh>
				</geometry>
			</visual>
		</link>
		<link name="hand_left_middle_link2">
			<self_collide>false</self_collide>
			<pose frame="">0.7128823040569381 -0.28047502772467753 0.021644247987551088 0.0 -0.0 0.0</pose>
			<inertial>
				<pose frame="">0.0 0.0 0.0 0 0 0</pose>
				<mass>0.030336333967375433</mass>
				<inertia>
					<ixx>0.0024023025129959997</ixx>
					<ixy>0.006065766877878629</ixy>
					<ixz>-0.0004677912867405291</ixz>
					<iyy>0.015432594252539377</iyy>
					<iyz>0.00018404610611777008</iyz>
					<izz>0.017804605454145087</izz>
				</inertia>
			</inertial>
			<collision name="hand_left_middle_link2_collision">
				<geometry>
					<mesh>
						<uri>model://roboy_icecream/meshes/CAD/hand_left_middle_link2.stl</uri>
						<scale>0.001 0.001 0.001</scale>
					</mesh>
				</geometry>
			</collision>
			<visual name="hand_left_middle_link2_visual">
				<geometry>
					<mesh>
						<uri>model://roboy_icecream/meshes/CAD/hand_left_middle_link2.stl</uri>
						<scale>0.001 0.001 0.001</scale>
					</mesh>
				</geometry>
			</visual>
		</link>
		<link name="hand_left_ring_link1">
			<self_collide>false</self_collide>
			<pose frame="">0.7046840830829589 -0.3015305180787639 0.05242403848715771 0.0 -0.0 0.0</pose>
			<inertial>
				<pose frame="">0.0 0.0 0.0 0 0 0</pose>
				<mass>0.030810597058291506</mass>
				<inertia>
					<ixx>0.002887847932176398</ixx>
					<ixy>0.006547040722103637</ixy>
					<ixz>-0.0011377849324884183</ixz>
					<iyy>0.015386400595745742</iyy>
					<iyz>0.00048686566677213014</iyz>
					<izz>0.018102852748695462</izz>
				</inertia>
			</inertial>
			<collision name="hand_left_ring_link1_collision">
				<geometry>
					<mesh>
						<uri>model://roboy_icecream/meshes/CAD/hand_left_ring_link1.stl</uri>
						<scale>0.001 0.001 0.001</scale>
					</mesh>
				</geometry>
			</collision>
			<visual name="hand_left_ring_link1_visual">
				<geometry>
					<mesh>
						<uri>model://roboy_icecream/meshes/CAD/hand_left_ring_link1.stl</uri>
						<scale>0.001 0.001 0.001</scale>
					</mesh>
				</geometry>
			</visual>
		</link>
		<link name="hand_left_ring_link0">
			<self_collide>false</self_collide>
			<pose frame="">0.6840551034817963 -0.28619254692810264 0.07693059851654221 0.0 -0.0 0.0</pose>
			<inertial>
				<pose frame="">0.0 0.0 0.0 0 0 0</pose>
				<mass>0.05585282478027009</mass>
				<inertia>
					<ixx>0.004912713257115179</ixx>
					<ixy>0.010936457002691413</ixy>
					<ixz>-0.002935974703750085</ixz>
					<iyy>0.026474155942149465</iyy>
					<iyz>0.0012273993657145334</iyz>
					<izz>0.030716042356195232</izz>
				</inertia>
			</inertial>
			<collision name="hand_left_ring_link0_collision">
				<geometry>
					<mesh>
						<uri>model://roboy_icecream/meshes/CAD/hand_left_ring_link0.stl</uri>
						<scale>0.001 0.001 0.001</scale>
					</mesh>
				</geometry>
			</collision>
			<visual name="hand_left_ring_link0_visual">
				<geometry>
					<mesh>
						<uri>model://roboy_icecream/meshes/CAD/hand_left_ring_link0.stl</uri>
						<scale>0.001 0.001 0.001</scale>
					</mesh>
				</geometry>
			</visual>
		</link>
		<link name="hand_left_ring_link2">
			<self_collide>false</self_collide>
			<pose frame="">0.7192932791552058 -0.3124483767472195 0.03496338434348071 0.0 -0.0 0.0</pose>
			<inertial>
				<pose frame="">0.0 0.0 0.0 0 0 0</pose>
				<mass>0.030336320395881484</mass>
				<inertia>
					<ixx>0.0030002724624192457</ixx>
					<ixy>0.006817998963166964</ixy>
					<ixz>-0.000762638873829699</ixz>
					<iyy>0.01573394321768655</iyy>
					<iyz>0.0003312665996287851</iyz>
					<izz>0.01865825048858887</izz>
				</inertia>
			</inertial>
			<collision name="hand_left_ring_link2_collision">
				<geometry>
					<mesh>
						<uri>model://roboy_icecream/meshes/CAD/hand_left_ring_link2.stl</uri>
						<scale>0.001 0.001 0.001</scale>
					</mesh>
				</geometry>
			</collision>
			<visual name="hand_left_ring_link2_visual">
				<geometry>
					<mesh>
						<uri>model://roboy_icecream/meshes/CAD/hand_left_ring_link2.stl</uri>
						<scale>0.001 0.001 0.001</scale>
					</mesh>
				</geometry>
			</visual>
		</link>
		<link name="hand_left_little_link1">
			<self_collide>false</self_collide>
			<pose frame="">0.6788865055958021 -0.2358482876081846 0.050234561466954146 0.0 -0.0 0.0</pose>
			<inertial>
				<pose frame="">0.0 0.0 0.0 0 0 0</pose>
				<mass>0.030811374120953236</mass>
				<inertia>
					<ixx>0.0017934811587729017</ixx>
					<ixy>0.00493357062179606</ixy>
					<ixz>-0.001050319917071721</ixz>
					<iyy>0.014280187058384986</iyy>
					<iyz>0.00036491933334831917</iyz>
					<izz>0.015915962319463295</izz>
				</inertia>
			</inertial>
			<collision name="hand_left_little_link1_collision">
				<geometry>
					<mesh>
						<uri>model://roboy_icecream/meshes/CAD/hand_left_little_link1.stl</uri>
						<scale>0.001 0.001 0.001</scale>
					</mesh>
				</geometry>
			</collision>
			<visual name="hand_left_little_link1_visual">
				<geometry>
					<mesh>
						<uri>model://roboy_icecream/meshes/CAD/hand_left_little_link1.stl</uri>
						<scale>0.001 0.001 0.001</scale>
					</mesh>
				</geometry>
			</visual>
		</link>
		<link name="hand_left_little_link2">
			<self_collide>false</self_collide>
			<pose frame="">0.693180416579427 -0.24375096137054422 0.030981303555460853 0.0 -0.0 0.0</pose>
			<inertial>
				<pose frame="">0.0 0.0 0.0 0 0 0</pose>
				<mass>0.030336908642256282</mass>
				<inertia>
					<ixx>0.0018332243932410082</ixx>
					<ixy>0.0051259731319162</ixy>
					<ixz>-0.0006512084988184184</ixz>
					<iyy>0.014607431938702741</iyy>
					<iyz>0.00022899355944009533</iyz>
					<izz>0.016380511329908202</izz>
				</inertia>
			</inertial>
			<collision name="hand_left_little_link2_collision">
				<geometry>
					<mesh>
						<uri>model://roboy_icecream/meshes/CAD/hand_left_little_link2.stl</uri>
						<scale>0.001 0.001 0.001</scale>
					</mesh>
				</geometry>
			</collision>
			<visual name="hand_left_little_link2_visual">
				<geometry>
					<mesh>
						<uri>model://roboy_icecream/meshes/CAD/hand_left_little_link2.stl</uri>
						<scale>0.001 0.001 0.001</scale>
					</mesh>
				</geometry>
			</visual>
		</link>
		<link name="hand_left_little_link0">
			<self_collide>false</self_collide>
			<pose frame="">0.6645346260783673 -0.22755225617382585 0.07026458704405023 0.0 -0.0 0.0</pose>
			<inertial>
				<pose frame="">0.0 0.0 0.0 0 0 0</pose>
				<mass>0.030811374120953236</mass>
				<inertia>
					<ixx>0.0017493967242725962</ixx>
					<ixy>0.004659415135832722</ixy>
					<ixz>-0.0014382254128121113</ixz>
					<iyy>0.013760491087290237</iyy>
					<iyz>0.0004925132378942398</iyz>
					<izz>0.015203449187173642</izz>
				</inertia>
			</inertial>
			<collision name="hand_left_little_link0_collision">
				<geometry>
					<mesh>
						<uri>model://roboy_icecream/meshes/CAD/hand_left_little_link0.stl</uri>
						<scale>0.001 0.001 0.001</scale>
					</mesh>
				</geometry>
			</collision>
			<visual name="hand_left_little_link0_visual">
				<geometry>
					<mesh>
						<uri>model://roboy_icecream/meshes/CAD/hand_left_little_link0.stl</uri>
						<scale>0.001 0.001 0.001</scale>
					</mesh>
				</geometry>
			</visual>
		</link>
		<link name="hand_left_thumb_link2">
			<self_collide>false</self_collide>
			<pose frame="">0.6304882644220383 -0.3385812853857167 0.18247378979522716 0.0 -0.0 0.0</pose>
			<inertial>
				<pose frame="">0.0 0.0 0.0 0 0 0</pose>
				<mass>0.03033598906458339</mass>
				<inertia>
					<ixx>0.004489354729882437</ixx>
					<ixy>0.006475836840804171</ixy>
					<ixz>-0.0034902262588540085</ixz>
					<iyy>0.013070313974085562</iyy>
					<iyz>0.0018745190424383933</iyz>
					<izz>0.015538224678982335</izz>
				</inertia>
			</inertial>
			<collision name="hand_left_thumb_link2_collision">
				<geometry>
					<mesh>
						<uri>model://roboy_icecream/meshes/CAD/hand_left_thumb_link2.stl</uri>
						<scale>0.001 0.001 0.001</scale>
					</mesh>
				</geometry>
			</collision>
			<visual name="hand_left_thumb_link2_visual">
				<geometry>
					<mesh>
						<uri>model://roboy_icecream/meshes/CAD/hand_left_thumb_link2.stl</uri>
						<scale>0.001 0.001 0.001</scale>
					</mesh>
				</geometry>
			</visual>
		</link>
		<link name="hand_left_thumb_link0">
			<self_collide>false</self_collide>
			<pose frame="">0.6207134332789955 -0.2809930285193415 0.15489885949022625 0.0 -0.0 0.0</pose>
			<inertial>
				<pose frame="">0.0 0.0 0.0 0 0 0</pose>
				<mass>0.11643461952857809</mass>
				<inertia>
					<ixx>0.01201097108773117</ixx>
					<ixy>0.020311272292729526</ixy>
					<ixz>-0.011194169426764428</ixz>
					<iyy>0.047666962198254365</iyy>
					<iyz>0.0050721050488721124</iyz>
					<izz>0.05407479296997649</izz>
				</inertia>
			</inertial>
			<collision name="hand_left_thumb_link0_collision">
				<geometry>
					<mesh>
						<uri>model://roboy_icecream/meshes/CAD/hand_left_thumb_link0.stl</uri>
						<scale>0.001 0.001 0.001</scale>
					</mesh>
				</geometry>
			</collision>
			<visual name="hand_left_thumb_link0_visual">
				<geometry>
					<mesh>
						<uri>model://roboy_icecream/meshes/CAD/hand_left_thumb_link0.stl</uri>
						<scale>0.001 0.001 0.001</scale>
					</mesh>
				</geometry>
			</visual>
		</link>
		<link name="hand_left_thumb_link1">
			<self_collide>false</self_collide>
			<pose frame="">0.6293984798481008 -0.3179669192839186 0.1679619931779431 0.0 -0.0 0.0</pose>
			<inertial>
				<pose frame="">0.0 0.0 0.0 0 0 0</pose>
				<mass>0.030824527684383148</mass>
				<inertia>
					<ixx>0.003987762221169906</ixx>
					<ixy>0.006168319217634545</ixy>
					<ixz>-0.0032585100590166016</ixz>
					<iyy>0.013080989170821471</iyy>
					<iyz>0.0016465681129320903</iyz>
					<izz>0.01532800262870153</izz>
				</inertia>
			</inertial>
			<collision name="hand_left_thumb_link1_collision">
				<geometry>
					<mesh>
						<uri>model://roboy_icecream/meshes/CAD/hand_left_thumb_link1.stl</uri>
						<scale>0.001 0.001 0.001</scale>
					</mesh>
				</geometry>
			</collision>
			<visual name="hand_left_thumb_link1_visual">
				<geometry>
					<mesh>
						<uri>model://roboy_icecream/meshes/CAD/hand_left_thumb_link1.stl</uri>
						<scale>0.001 0.001 0.001</scale>
					</mesh>
				</geometry>
			</visual>
		</link>
		<link name="shoulder_right_link1">
			<self_collide>false</self_collide>
			<pose frame="">-0.2930642609023861 0.01109383220250954 0.5468414984574267 0.0 -0.0 0.0</pose>
			<inertial>
				<pose frame="">0.0 0.0 0.0 0 0 0</pose>
				<mass>0.0903636656787565</mass>
				<inertia>
					<ixx>0.027040168124669237</ixx>
					<ixy>0.000293790868091621</ixy>
					<ixz>0.014481653914279803</ixz>
					<iyy>0.034790080309606335</iyy>
					<iyz>-0.0005481973067788913</iyz>
					<izz>0.007779246454693213</izz>
				</inertia>
			</inertial>
			<collision name="shoulder_right_link1_collision">
				<geometry>
					<mesh>
						<uri>model://roboy_icecream/meshes/CAD/shoulder_right_link1.stl</uri>
						<scale>0.001 0.001 0.001</scale>
					</mesh>
				</geometry>
			</collision>
			<visual name="shoulder_right_link1_visual">
				<geometry>
					<mesh>
						<uri>model://roboy_icecream/meshes/CAD/shoulder_right_link1.stl</uri>
						<scale>0.001 0.001 0.001</scale>
					</mesh>
				</geometry>
			</visual>
		</link>
		<link name="shoulder_right_link2">
			<self_collide>false</self_collide>
			<pose frame="">-0.2930642607647908 0.011093832147498362 0.5468414985002678 0.0 -0.0 0.0</pose>
			<inertial>
				<pose frame="">0.0 0.0 0.0 0 0 0</pose>
				<mass>0.007113171718499355</mass>
				<inertia>
					<ixx>0.0021280697191938397</ixx>
					<ixy>2.3126384559716274e-05</ixy>
					<ixz>0.001139954762194572</ixz>
					<iyy>0.0027381208465940333</iyy>
					<iyz>-4.315253847256294e-05</iyz>
					<izz>0.0006119045398845659</izz>
				</inertia>
			</inertial>
			<collision name="shoulder_right_link2_collision">
				<geometry>
					<mesh>
						<uri>model://roboy_icecream/meshes/CAD/shoulder_right_link2.stl</uri>
						<scale>0.001 0.001 0.001</scale>
					</mesh>
				</geometry>
			</collision>
			<visual name="shoulder_right_link2_visual">
				<geometry>
					<mesh>
						<uri>model://roboy_icecream/meshes/CAD/shoulder_right_link2.stl</uri>
						<scale>0.001 0.001 0.001</scale>
					</mesh>
				</geometry>
			</visual>
		</link>
		<link name="arm_right_upper">
			<self_collide>false</self_collide>
			<pose frame="">-0.3996144779889579 -0.07054454294075384 0.414629719979367 0.0 -0.0 0.0</pose>
			<inertial>
				<pose frame="">0.0 0.0 0.0 0 0 0</pose>
				<mass>3.5708839559758894</mass>
				<inertia>
					<ixx>0.653986309295724</ixx>
					<ixy>-0.108031122363589</ixy>
					<ixz>0.5798899912570349</ixz>
					<iyy>1.211097308090235</iyy>
					<iyz>0.09510999027876081</iyz>
					<izz>0.6060702538844687</izz>
				</inertia>
			</inertial>
			<collision name="arm_right_upper_collision">
				<geometry>
					<mesh>
						<uri>model://roboy_icecream/meshes/CAD/arm_right_upper.stl</uri>
						<scale>0.001 0.001 0.001</scale>
					</mesh>
				</geometry>
			</collision>
			<visual name="arm_right_upper_visual">
				<geometry>
					<mesh>
						<uri>model://roboy_icecream/meshes/CAD/arm_right_upper.stl</uri>
						<scale>0.001 0.001 0.001</scale>
					</mesh>
				</geometry>
			</visual>
		</link>
		<link name="hand_right_index_link1">
			<self_collide>false</self_collide>
			<pose frame="">-0.7037693692645931 -0.3283650341593377 0.07713046627894897 0.0 -0.0 0.0</pose>
			<inertial>
				<pose frame="">0.0 0.0 0.0 0 0 0</pose>
				<mass>0.030810558444194565</mass>
				<inertia>
					<ixx>0.0035072507344217152</ixx>
					<ixy>-0.0071204350465617966</ixy>
					<ixz>0.0016720515259752472</ixz>
					<iyy>0.015445256555300177</iyy>
					<iyz>0.0007801490441516711</iyz>
					<izz>0.018583976783639176</izz>
				</inertia>
			</inertial>
			<collision name="hand_right_index_link1_collision">
				<geometry>
					<mesh>
						<uri>model://roboy_icecream/meshes/CAD/hand_right_index_link1.stl</uri>
						<scale>0.001 0.001 0.001</scale>
					</mesh>
				</geometry>
			</collision>
			<visual name="hand_right_index_link1_visual">
				<geometry>
					<mesh>
						<uri>model://roboy_icecream/meshes/CAD/hand_right_index_link1.stl</uri>
						<scale>0.001 0.001 0.001</scale>
					</mesh>
				</geometry>
			</visual>
		</link>
		<link name="hand_right_index_link0">
			<self_collide>false</self_collide>
			<pose frame="">-0.6830622488186304 -0.3104491740515724 0.09975053866888989 0.0 -0.0 0.0</pose>
			<inertial>
				<pose frame="">0.0 0.0 0.0 0 0 0</pose>
				<mass>0.055849025991352434</mass>
				<inertia>
					<ixx>0.005945810791770005</ixx>
					<ixy>-0.01184552057290769</ixy>
					<ixz>0.0038022735904499026</ixz>
					<iyy>0.026621208219618615</iyy>
					<iyz>0.0017270154221905132</iyz>
					<izz>0.031446965489201936</izz>
				</inertia>
			</inertial>
			<collision name="hand_right_index_link0_collision">
				<geometry>
					<mesh>
						<uri>model://roboy_icecream/meshes/CAD/hand_right_index_link0.stl</uri>
						<scale>0.001 0.001 0.001</scale>
					</mesh>
				</geometry>
			</collision>
			<visual name="hand_right_index_link0_visual">
				<geometry>
					<mesh>
						<uri>model://roboy_icecream/meshes/CAD/hand_right_index_link0.stl</uri>
						<scale>0.001 0.001 0.001</scale>
					</mesh>
				</geometry>
			</visual>
		</link>
		<link name="hand_right_index_link2">
			<self_collide>false</self_collide>
			<pose frame="">-0.7184346914498597 -0.3411382463969471 0.06102754345800903 0.0 -0.0 0.0</pose>
			<inertial>
				<pose frame="">0.0 0.0 0.0 0 0 0</pose>
				<mass>0.030337239357465576</mass>
				<inertia>
					<ixx>0.003645119335322973</ixx>
					<ixy>-0.007435377980429817</ixy>
					<ixz>0.0013298343469472684</ixz>
					<iyy>0.015772821451874083</iyy>
					<iyz>0.0006314361372726552</iyz>
					<izz>0.019190245490028755</izz>
				</inertia>
			</inertial>
			<collision name="hand_right_index_link2_collision">
				<geometry>
					<mesh>
						<uri>model://roboy_icecream/meshes/CAD/hand_right_index_link2.stl</uri>
						<scale>0.001 0.001 0.001</scale>
					</mesh>
				</geometry>
			</collision>
			<visual name="hand_right_index_link2_visual">
				<geometry>
					<mesh>
						<uri>model://roboy_icecream/meshes/CAD/hand_right_index_link2.stl</uri>
						<scale>0.001 0.001 0.001</scale>
					</mesh>
				</geometry>
			</visual>
		</link>
		<link name="hand_right_middle_link1">
			<self_collide>false</self_collide>
			<pose frame="">-0.7063789070011799 -0.30413980357991177 0.053219004793249 0.0 -0.0 0.0</pose>
			<inertial>
				<pose frame="">0.0 0.0 0.0 0 0 0</pose>
				<mass>0.030811264606209133</mass>
				<inertia>
					<ixx>0.002939191131302322</ixx>
					<ixy>-0.006619718350449587</ixy>
					<ixz>0.001157849436377739</ixz>
					<iyy>0.015463006739638623</iyy>
					<iyz>0.0004985403906268279</iyz>
					<izz>0.018225623477612574</izz>
				</inertia>
			</inertial>
			<collision name="hand_right_middle_link1_collision">
				<geometry>
					<mesh>
						<uri>model://roboy_icecream/meshes/CAD/hand_right_middle_link1.stl</uri>
						<scale>0.001 0.001 0.001</scale>
					</mesh>
				</geometry>
			</collision>
			<visual name="hand_right_middle_link1_visual">
				<geometry>
					<mesh>
						<uri>model://roboy_icecream/meshes/CAD/hand_right_middle_link1.stl</uri>
						<scale>0.001 0.001 0.001</scale>
					</mesh>
				</geometry>
			</visual>
		</link>
		<link name="hand_right_middle_link0">
			<self_collide>false</self_collide>
			<pose frame="">-0.6857445062228748 -0.2887213708636444 0.077671107624789 0.0 -0.0 0.0</pose>
			<inertial>
				<pose frame="">0.0 0.0 0.0 0 0 0</pose>
				<mass>0.05585161472558298</mass>
				<inertia>
					<ixx>0.005000202753105266</ixx>
					<ixy>-0.011060081908975509</ixy>
					<ixz>0.0029715327739198026</ixz>
					<iyy>0.026609233849449226</iyy>
					<iyz>0.0012501800330037103</iyz>
					<izz>0.03092583573792408</izz>
				</inertia>
			</inertial>
			<collision name="hand_right_middle_link0_collision">
				<geometry>
					<mesh>
						<uri>model://roboy_icecream/meshes/CAD/hand_right_middle_link0.stl</uri>
						<scale>0.001 0.001 0.001</scale>
					</mesh>
				</geometry>
			</collision>
			<visual name="hand_right_middle_link0_visual">
				<geometry>
					<mesh>
						<uri>model://roboy_icecream/meshes/CAD/hand_right_middle_link0.stl</uri>
						<scale>0.001 0.001 0.001</scale>
					</mesh>
				</geometry>
			</visual>
		</link>
		<link name="hand_right_middle_link2">
			<self_collide>false</self_collide>
			<pose frame="">-0.7209932778212658 -0.3151385491756735 0.03581258868831539 0.0 -0.0 0.0</pose>
			<inertial>
				<pose frame="">0.0 0.0 0.0 0 0 0</pose>
				<mass>0.030337290984439002</mass>
				<inertia>
					<ixx>0.003053405593881536</ixx>
					<ixy>-0.00689316243196015</ixy>
					<ixz>0.0007830400926682598</ixz>
					<iyy>0.01581052518162795</iyy>
					<iyz>0.0003422487813389571</iyz>
					<izz>0.018784316433487946</izz>
				</inertia>
			</inertial>
			<collision name="hand_right_middle_link2_collision">
				<geometry>
					<mesh>
						<uri>model://roboy_icecream/meshes/CAD/hand_right_middle_link2.stl</uri>
						<scale>0.001 0.001 0.001</scale>
					</mesh>
				</geometry>
			</collision>
			<visual name="hand_right_middle_link2_visual">
				<geometry>
					<mesh>
						<uri>model://roboy_icecream/meshes/CAD/hand_right_middle_link2.stl</uri>
						<scale>0.001 0.001 0.001</scale>
					</mesh>
				</geometry>
			</visual>
		</link>
		<link name="hand_right_ring_link1">
			<self_collide>false</self_collide>
			<pose frame="">-0.700152470060429 -0.27404344603502184 0.041038039348278266 0.0 -0.0 0.0</pose>
			<inertial>
				<pose frame="">0.0 0.0 0.0 0 0 0</pose>
				<mass>0.030812212494644456</mass>
				<inertia>
					<ixx>0.00236774083964393</ixx>
					<ixy>-0.0059122608699693595</ixy>
					<ixz>0.0008848743263874944</ixz>
					<iyy>0.015158306207734604</iyy>
					<iyz>0.00034637516515007396</iyz>
					<izz>0.017420121126692802</izz>
				</inertia>
			</inertial>
			<collision name="hand_right_ring_link1_collision">
				<geometry>
					<mesh>
						<uri>model://roboy_icecream/meshes/CAD/hand_right_ring_link1.stl</uri>
						<scale>0.001 0.001 0.001</scale>
					</mesh>
				</geometry>
			</collision>
			<visual name="hand_right_ring_link1_visual">
				<geometry>
					<mesh>
						<uri>model://roboy_icecream/meshes/CAD/hand_right_ring_link1.stl</uri>
						<scale>0.001 0.001 0.001</scale>
					</mesh>
				</geometry>
			</visual>
		</link>
		<link name="hand_right_ring_link0">
			<self_collide>false</self_collide>
			<pose frame="">-0.679742436320942 -0.26124012597773416 0.06713232179974515 0.0 -0.0 0.0</pose>
			<inertial>
				<pose frame="">0.0 0.0 0.0 0 0 0</pose>
				<mass>0.05584221000563182</mass>
				<inertia>
					<ixx>0.004070225351954381</ixx>
					<ixy>-0.009917967651783929</ixy>
					<ixz>0.0025447965369207364</ixz>
					<iyy>0.026062353555057434</iyy>
					<iyz>0.0009773030682929283</iyz>
					<izz>0.029618491318602096</izz>
				</inertia>
			</inertial>
			<collision name="hand_right_ring_link0_collision">
				<geometry>
					<mesh>
						<uri>model://roboy_icecream/meshes/CAD/hand_right_ring_link0.stl</uri>
						<scale>0.001 0.001 0.001</scale>
					</mesh>
				</geometry>
			</collision>
			<visual name="hand_right_ring_link0_visual">
				<geometry>
					<mesh>
						<uri>model://roboy_icecream/meshes/CAD/hand_right_ring_link0.stl</uri>
						<scale>0.001 0.001 0.001</scale>
					</mesh>
				</geometry>
			</visual>
		</link>
		<link name="hand_right_ring_link2">
			<self_collide>false</self_collide>
			<pose frame="">-0.7146072264679332 -0.2831828604247662 0.022462127067744635 0.0 -0.0 0.0</pose>
			<inertial>
				<pose frame="">0.0 0.0 0.0 0 0 0</pose>
				<mass>0.030337283421022952</mass>
				<inertia>
					<ixx>0.002449767656350394</ixx>
					<ixy>-0.006139318759877515</ixy>
					<ixz>0.00048666827942469215</ixz>
					<iyy>0.015508823191480852</iyy>
					<iyz>0.0001928556041489041</iyz>
					<izz>0.017926109824250795</izz>
				</inertia>
			</inertial>
			<collision name="hand_right_ring_link2_collision">
				<geometry>
					<mesh>
						<uri>model://roboy_icecream/meshes/CAD/hand_right_ring_link2.stl</uri>
						<scale>0.001 0.001 0.001</scale>
					</mesh>
				</geometry>
			</collision>
			<visual name="hand_right_ring_link2_visual">
				<geometry>
					<mesh>
						<uri>model://roboy_icecream/meshes/CAD/hand_right_ring_link2.stl</uri>
						<scale>0.001 0.001 0.001</scale>
					</mesh>
				</geometry>
			</visual>
		</link>
		<link name="hand_right_little_link1">
			<self_collide>false</self_collide>
			<pose frame="">-0.680055216139201 -0.2394631894480969 0.05099931963157623 0.0 -0.0 0.0</pose>
			<inertial>
				<pose frame="">0.0 0.0 0.0 0 0 0</pose>
				<mass>0.03081334642928593</mass>
				<inertia>
					<ixx>0.0018489247838932678</ixx>
					<ixy>-0.005018129585007925</ixy>
					<ixz>0.001068221948277107</ixz>
					<iyy>0.01433242463455071</iyy>
					<iyz>0.00037618095773073775</iyz>
					<izz>0.016018862934095872</izz>
				</inertia>
			</inertial>
			<collision name="hand_right_little_link1_collision">
				<geometry>
					<mesh>
						<uri>model://roboy_icecream/meshes/CAD/hand_right_little_link1.stl</uri>
						<scale>0.001 0.001 0.001</scale>
					</mesh>
				</geometry>
			</collision>
			<visual name="hand_right_little_link1_visual">
				<geometry>
					<mesh>
						<uri>model://roboy_icecream/meshes/CAD/hand_right_little_link1.stl</uri>
						<scale>0.001 0.001 0.001</scale>
					</mesh>
				</geometry>
			</visual>
		</link>
		<link name="hand_right_little_link2">
			<self_collide>false</self_collide>
			<pose frame="">-0.6943624765061505 -0.24745207688774798 0.03178976312425073 0.0 -0.0 0.0</pose>
			<inertial>
				<pose frame="">0.0 0.0 0.0 0 0 0</pose>
				<mass>0.030337208280612742</mass>
				<inertia>
					<ixx>0.0018899272174508306</ixx>
					<ixy>-0.005212708443420999</ixy>
					<ixz>0.0006693537263261418</ixz>
					<iyy>0.014658815788712764</iyy>
					<iyz>0.00023854251180179675</iyz>
					<izz>0.016485518418885167</izz>
				</inertia>
			</inertial>
			<collision name="hand_right_little_link2_collision">
				<geometry>
					<mesh>
						<uri>model://roboy_icecream/meshes/CAD/hand_right_little_link2.stl</uri>
						<scale>0.001 0.001 0.001</scale>
					</mesh>
				</geometry>
			</collision>
			<visual name="hand_right_little_link2_visual">
				<geometry>
					<mesh>
						<uri>model://roboy_icecream/meshes/CAD/hand_right_little_link2.stl</uri>
						<scale>0.001 0.001 0.001</scale>
					</mesh>
				</geometry>
			</visual>
		</link>
		<link name="hand_right_little_link0">
			<self_collide>false</self_collide>
			<pose frame="">-0.6656906341061404 -0.23107917166829567 0.07098355180300933 0.0 -0.0 0.0</pose>
			<inertial>
				<pose frame="">0.0 0.0 0.0 0 0 0</pose>
				<mass>0.030813346429285904</mass>
				<inertia>
					<ixx>0.0018024797811134192</ixx>
					<ixy>-0.0047401639074196224</ixy>
					<ixz>0.0014555682729818352</ixz>
					<iyy>0.013811884220583995</iyy>
					<iyz>0.0005052999897348896</iyz>
					<izz>0.01530164803286701</izz>
				</inertia>
			</inertial>
			<collision name="hand_right_little_link0_collision">
				<geometry>
					<mesh>
						<uri>model://roboy_icecream/meshes/CAD/hand_right_little_link0.stl</uri>
						<scale>0.001 0.001 0.001</scale>
					</mesh>
				</geometry>
			</collision>
			<visual name="hand_right_little_link0_visual">
				<geometry>
					<mesh>
						<uri>model://roboy_icecream/meshes/CAD/hand_right_little_link0.stl</uri>
						<scale>0.001 0.001 0.001</scale>
					</mesh>
				</geometry>
			</visual>
		</link>
		<link name="hand_right_thumb_link2">
			<self_collide>false</self_collide>
			<pose frame="">-0.6319964120599696 -0.34092694271003043 0.18295523410249778 0.0 -0.0 0.0</pose>
			<inertial>
				<pose frame="">0.0 0.0 0.0 0 0 0</pose>
				<mass>0.03033682887568179</mass>
				<inertia>
					<ixx>0.004543229582451049</ixx>
					<ixy>-0.006536565989199835</ixy>
					<ixz>0.0035079481650778406</ixz>
					<iyy>0.013133948563062964</iyy>
					<iyz>0.001892560305091098</iyz>
					<izz>0.015644977580895513</izz>
				</inertia>
			</inertial>
			<collision name="hand_right_thumb_link2_collision">
				<geometry>
					<mesh>
						<uri>model://roboy_icecream/meshes/CAD/hand_right_thumb_link2.stl</uri>
						<scale>0.001 0.001 0.001</scale>
					</mesh>
				</geometry>
			</collision>
			<visual name="hand_right_thumb_link2_visual">
				<geometry>
					<mesh>
						<uri>model://roboy_icecream/meshes/CAD/hand_right_thumb_link2.stl</uri>
						<scale>0.001 0.001 0.001</scale>
					</mesh>
				</geometry>
			</visual>
		</link>
		<link name="hand_right_thumb_link0">
			<self_collide>false</self_collide>
			<pose frame="">-0.6224494756034741 -0.2832453158803033 0.1555028854328001 0.0 -0.0 0.0</pose>
			<inertial>
				<pose frame="">0.0 0.0 0.0 0 0 0</pose>
				<mass>0.1164302811950376</mass>
				<inertia>
					<ixx>0.012180292998475242</ixx>
					<ixy>-0.020530575408297363</ixy>
					<ixz>0.011268842893541058</ixz>
					<iyy>0.04793835906321091</iyy>
					<iyz>0.0051324796033435744</iyz>
					<izz>0.05447208777524261</izz>
				</inertia>
			</inertial>
			<collision name="hand_right_thumb_link0_collision">
				<geometry>
					<mesh>
						<uri>model://roboy_icecream/meshes/CAD/hand_right_thumb_link0.stl</uri>
						<scale>0.001 0.001 0.001</scale>
					</mesh>
				</geometry>
			</collision>
			<visual name="hand_right_thumb_link0_visual">
				<geometry>
					<mesh>
						<uri>model://roboy_icecream/meshes/CAD/hand_right_thumb_link0.stl</uri>
						<scale>0.001 0.001 0.001</scale>
					</mesh>
				</geometry>
			</visual>
		</link>
		<link name="hand_right_thumb_link1">
			<self_collide>false</self_collide>
			<pose frame="">-0.6311334804099267 -0.32020049685849045 0.16856918302155652 0.0 -0.0 0.0</pose>
			<inertial>
				<pose frame="">0.0 0.0 0.0 0 0 0</pose>
				<mass>0.030826015044524157</mass>
				<inertia>
					<ixx>0.004038458480931994</ixx>
					<ixy>-0.00622949056761934</ixy>
					<ixz>0.0032796814746576994</ixz>
					<iyy>0.013156211759920598</iyy>
					<iyz>0.0016643157095675765</iyz>
					<izz>0.015441124884069424</izz>
				</inertia>
			</inertial>
			<collision name="hand_right_thumb_link1_collision">
				<geometry>
					<mesh>
						<uri>model://roboy_icecream/meshes/CAD/hand_right_thumb_link1.stl</uri>
						<scale>0.001 0.001 0.001</scale>
					</mesh>
				</geometry>
			</collision>
			<visual name="hand_right_thumb_link1_visual">
				<geometry>
					<mesh>
						<uri>model://roboy_icecream/meshes/CAD/hand_right_thumb_link1.stl</uri>
						<scale>0.001 0.001 0.001</scale>
					</mesh>
				</geometry>
			</visual>
		</link>
		<link name="wrist_left_link1">
			<self_collide>false</self_collide>
			<pose frame="">0.594210819530907 -0.22365650340898757 0.17010688138927169 0.0 -0.0 0.0</pose>
			<inertial>
				<pose frame="">0.0 0.0 0.0 0 0 0</pose>
				<mass>0.09036359201900475</mass>
				<inertia>
					<ixx>0.007142072740240585</ixx>
					<ixy>0.012009241334080092</ixy>
					<ixz>-0.009133893090562301</ixz>
					<iyy>0.03452804847042301</iyy>
					<iyz>0.00343792897066301</iyz>
					<izz>0.03643344436611878</izz>
				</inertia>
			</inertial>
			<collision name="wrist_left_link1_collision">
				<geometry>
					<mesh>
						<uri>model://roboy_icecream/meshes/CAD/wrist_left_link1.stl</uri>
						<scale>0.001 0.001 0.001</scale>
					</mesh>
				</geometry>
			</collision>
			<visual name="wrist_left_link1_visual">
				<geometry>
					<mesh>
						<uri>model://roboy_icecream/meshes/CAD/wrist_left_link1.stl</uri>
						<scale>0.001 0.001 0.001</scale>
					</mesh>
				</geometry>
			</visual>
		</link>
		<link name="wrist_left_link2">
			<self_collide>false</self_collide>
			<pose frame="">0.594210814669987 -0.22365650364391873 0.17010688095852708 0.0 -0.0 0.0</pose>
			<inertial>
				<pose frame="">0.0 0.0 0.0 0 0 0</pose>
				<mass>0.007113170038864664</mass>
				<inertia>
					<ixx>0.000561748355974401</ixx>
					<ixy>0.0009453339904655092</ixy>
					<ixz>-0.0007189945919846199</ixz>
					<iyy>0.0027174959746703127</iyy>
					<iyz>0.00027062418356026434</iyz>
					<izz>0.0028674834293351253</izz>
				</inertia>
			</inertial>
			<collision name="wrist_left_link2_collision">
				<geometry>
					<mesh>
						<uri>model://roboy_icecream/meshes/CAD/wrist_left_link2.stl</uri>
						<scale>0.001 0.001 0.001</scale>
					</mesh>
				</geometry>
			</collision>
			<visual name="wrist_left_link2_visual">
				<geometry>
					<mesh>
						<uri>model://roboy_icecream/meshes/CAD/wrist_left_link2.stl</uri>
						<scale>0.001 0.001 0.001</scale>
					</mesh>
				</geometry>
			</visual>
		</link>
		<link name="wrist_right_link1">
			<self_collide>false</self_collide>
			<pose frame="">-0.5930631014104508 -0.22373453929325607 0.17416876963064573 0.0 -0.0 0.0</pose>
			<inertial>
				<pose frame="">0.0 0.0 0.0 0 0 0</pose>
				<mass>0.09036366567875652</mass>
				<inertia>
					<ixx>0.0072715987658836185</ixx>
					<ixy>-0.011990237304993493</ixy>
					<ixz>0.00933394050640124</ixz>
					<iyy>0.03453130742684939</iyy>
					<iyz>0.0035212524165199165</iyz>
					<izz>0.03631349431910831</izz>
				</inertia>
			</inertial>
			<collision name="wrist_right_link1_collision">
				<geometry>
					<mesh>
						<uri>model://roboy_icecream/meshes/CAD/wrist_right_link1.stl</uri>
						<scale>0.001 0.001 0.001</scale>
					</mesh>
				</geometry>
			</collision>
			<visual name="wrist_right_link1_visual">
				<geometry>
					<mesh>
						<uri>model://roboy_icecream/meshes/CAD/wrist_right_link1.stl</uri>
						<scale>0.001 0.001 0.001</scale>
					</mesh>
				</geometry>
			</visual>
		</link>
		<link name="wrist_right_link2">
			<self_collide>false</self_collide>
			<pose frame="">-0.5930631010671759 -0.2237345393051499 0.1741687696304079 0.0 -0.0 0.0</pose>
			<inertial>
				<pose frame="">0.0 0.0 0.0 0 0 0</pose>
				<mass>0.0071131715008991465</mass>
				<inertia>
					<ixx>0.0005719439353585403</ixx>
					<ixy>-0.0009438374771676792</ixy>
					<ixz>0.000734741326217683</ixz>
					<iyy>0.002717750892693173</iyy>
					<iyz>0.0002771830043615346</iyz>
					<izz>0.0028580395908096223</izz>
				</inertia>
			</inertial>
			<collision name="wrist_right_link2_collision">
				<geometry>
					<mesh>
						<uri>model://roboy_icecream/meshes/CAD/wrist_right_link2.stl</uri>
						<scale>0.001 0.001 0.001</scale>
					</mesh>
				</geometry>
			</collision>
			<visual name="wrist_right_link2_visual">
				<geometry>
					<mesh>
						<uri>model://roboy_icecream/meshes/CAD/wrist_right_link2.stl</uri>
						<scale>0.001 0.001 0.001</scale>
					</mesh>
				</geometry>
			</visual>
		</link>
		<link name="zed_camera_left_lense">
			<self_collide>false</self_collide>
			<pose frame="">0.060224029002958875 -0.06914536611449576 0.9247742812708074 0.0 -0.0 0.0</pose>
			<inertial>
				<pose frame="">0.0 0.0 0.0 0 0 0</pose>
				<mass>0.005755421856391889</mass>
				<inertia>
					<ixx>0.004949985508986997</ixx>
					<ixy>2.3967379469334992e-05</ixy>
					<ixz>-0.00032054048486266214</ixz>
					<iyy>0.004943160949602587</iyy>
					<iyz>0.00036806516895399434</iyz>
					<izz>4.8783846074335874e-05</izz>
				</inertia>
			</inertial>
			<collision name="zed_camera_left_lense_collision">
				<geometry>
					<mesh>
						<uri>model://roboy_icecream/meshes/CAD/zed_camera_left_lense.stl</uri>
						<scale>0.001 0.001 0.001</scale>
					</mesh>
				</geometry>
			</collision>
			<visual name="zed_camera_left_lense_visual">
				<geometry>
					<mesh>
						<uri>model://roboy_icecream/meshes/CAD/zed_camera_left_lense.stl</uri>
						<scale>0.001 0.001 0.001</scale>
					</mesh>
				</geometry>
			</visual>
		</link>
		<link name="zed_camera_right_lense">
			<self_collide>false</self_collide>
			<pose frame="">-0.05977745584801775 -0.06952236314727905 0.924774281233249 0.0 -0.0 0.0</pose>
			<inertial>
				<pose frame="">0.0 0.0 0.0 0 0 0</pose>
				<mass>0.005755421855125979</mass>
				<inertia>
					<ixx>0.004950286385593239</ixx>
					<ixy>-2.3918213389687756e-05</ixy>
					<ixz>0.00031816335310091417</ixz>
					<iyy>0.004942852518457872</iyy>
					<iyz>0.00037007172279470996</iyz>
					<izz>4.877629449989437e-05</izz>
				</inertia>
			</inertial>
			<collision name="zed_camera_right_lense_collision">
				<geometry>
					<mesh>
						<uri>model://roboy_icecream/meshes/CAD/zed_camera_right_lense.stl</uri>
						<scale>0.001 0.001 0.001</scale>
					</mesh>
				</geometry>
			</collision>
			<visual name="zed_camera_right_lense_visual">
				<geometry>
					<mesh>
						<uri>model://roboy_icecream/meshes/CAD/zed_camera_right_lense.stl</uri>
						<scale>0.001 0.001 0.001</scale>
					</mesh>
				</geometry>
			</visual>
		</link>
		<link name="zed_camera">
			<self_collide>false</self_collide>
			<pose frame="">0.0042444847902519045 -0.057938621286605034 0.9221942136470952 0.0 -0.0 0.0</pose>
			<inertial>
				<pose frame="">0.0 0.0 0.0 0 0 0</pose>
				<mass>0.009633907989226696</mass>
				<inertia>
					<ixx>0.008225718793064217</ixx>
					<ixy>2.436533895216616e-06</ixy>
					<ixz>-3.772847951396886e-05</ixz>
					<iyy>0.008208224332339191</iyy>
					<iyz>0.0005146961428966748</iyz>
					<izz>4.725323656366557e-05</izz>
				</inertia>
			</inertial>
			<collision name="zed_camera_collision">
				<geometry>
					<mesh>
						<uri>model://roboy_icecream/meshes/CAD/zed_camera.stl</uri>
						<scale>0.001 0.001 0.001</scale>
					</mesh>
				</geometry>
			</collision>
			<visual name="zed_camera_visual">
				<geometry>
					<mesh>
						<uri>model://roboy_icecream/meshes/CAD/zed_camera.stl</uri>
						<scale>0.001 0.001 0.001</scale>
					</mesh>
				</geometry>
			</visual>
		</link>
		<link name="neck_link1">
			<self_collide>false</self_collide>
			<pose frame="">-1.506123290725299e-10 0.0015217809344427139 0.7106779292283452 0.0 -0.0 0.0</pose>
			<inertial>
				<pose frame="">0.0 0.0 0.0 0 0 0</pose>
				<mass>0.017038665636260365</mass>
				<inertia>
					<ixx>0.008606751840759286</ixx>
					<ixy>3.905246557991266e-15</ixy>
					<ixz>1.8237653762187555e-12</ixz>
					<iyy>0.008606712382324128</iyy>
					<iyz>-1.8427250830609723e-05</iyz>
					<izz>1.1502292854573858e-06</izz>
				</inertia>
			</inertial>
			<collision name="neck_link1_collision">
				<geometry>
					<mesh>
						<uri>model://roboy_icecream/meshes/CAD/neck_link1.stl</uri>
						<scale>0.001 0.001 0.001</scale>
					</mesh>
				</geometry>
			</collision>
			<visual name="neck_link1_visual">
				<geometry>
					<mesh>
						<uri>model://roboy_icecream/meshes/CAD/neck_link1.stl</uri>
						<scale>0.001 0.001 0.001</scale>
					</mesh>
				</geometry>
			</visual>
		</link>
		<link name="neck_link2">
			<self_collide>false</self_collide>
			<pose frame="">-1.2765957595970417e-10 0.0015217809573941916 0.7106779292283448 0.0 -0.0 0.0</pose>
			<inertial>
				<pose frame="">0.0 0.0 0.0 0 0 0</pose>
				<mass>0.011421521917888835</mass>
				<inertia>
					<ixx>0.005769117704166386</ixx>
					<ixy>2.2188573474781793e-15</ixy>
					<ixz>1.0362156174781311e-12</ixz>
					<iyy>0.005769091254008538</iyy>
					<iyz>-1.2352331861868672e-05</iyz>
					<izz>5.282195127138846e-07</izz>
				</inertia>
			</inertial>
			<collision name="neck_link2_collision">
				<geometry>
					<mesh>
						<uri>model://roboy_icecream/meshes/CAD/neck_link2.stl</uri>
						<scale>0.001 0.001 0.001</scale>
					</mesh>
				</geometry>
			</collision>
			<visual name="neck_link2_visual">
				<geometry>
					<mesh>
						<uri>model://roboy_icecream/meshes/CAD/neck_link2.stl</uri>
						<scale>0.001 0.001 0.001</scale>
					</mesh>
				</geometry>
			</visual>
		</link>
		<joint name="wrist_right_axis0" type="revolute">
			<parent>arm_right_lower</parent>
			<child>wrist_right_link1</child>
			<pose frame="">1.3765976802915247e-10 -7.151108150083019e-11 -2.516387098694395e-13 0 0 0</pose>
			<axis>
				<xyz>0.04893226875182534 0.8266587526531013 -0.5605719755185936</xyz>
				<limit>
					<lower>-3.141592653589793</lower>
					<upper>3.141592653589793</upper>
				</limit>
				<use_parent_model_frame>0</use_parent_model_frame>
			</axis>
		</joint>
		<joint name="wrist_right_axis1" type="revolute">
			<parent>wrist_right_link1</parent>
			<child>wrist_right_link2</child>
			<pose frame="">-2.056162884400692e-10 -5.963745053350067e-11 -3.552713678800501e-17 0 0 0</pose>
			<axis>
				<xyz>0.823951413592291 -0.350636056294613 -0.4451498894366088</xyz>
				<limit>
					<lower>-3.141592653589793</lower>
					<upper>3.141592653589793</upper>
				</limit>
				<use_parent_model_frame>0</use_parent_model_frame>
			</axis>
		</joint>
		<joint name="zed_camera_mount" type="fixed">
			<parent>head</parent>
			<child>zed_camera</child>
			<pose frame="">0.017437654685091123 0.001405588958414743 0.008052233827783938 0 0 0</pose>
		</joint>
		<joint name="neck_axis0" type="revolute">
			<parent>torso</parent>
			<child>neck_link1</child>
			<pose frame="">1.5061504134737904e-10 1.506148417096398e-10 0.0 0 0 0</pose>
			<axis>
				<xyz>0.12498691257369461 -0.9921583904222635 6.724690979212185e-15</xyz>
				<limit>
					<lower>-0.5235987755982988</lower>
					<upper>0.5235987755982988</upper>
				</limit>
				<use_parent_model_frame>0</use_parent_model_frame>
			</axis>
		</joint>
		<joint name="neck_axis2" type="revolute">
			<parent>neck_link2</parent>
			<child>head</child>
			<pose frame="">-0.0005102180295654365 -0.04492411714425428 -0.14549973319053336 0 0 0</pose>
			<axis>
				<xyz>-2.4972812708040394e-14 3.631896132047499e-15 1.0</xyz>
				<limit>
					<lower>-0.5235987755982988</lower>
					<upper>0.5235987755982988</upper>
				</limit>
				<use_parent_model_frame>0</use_parent_model_frame>
			</axis>
		</joint>
		<joint name="neck_axis1" type="revolute">
			<parent>neck_link1</parent>
			<child>neck_link2</child>
			<pose frame="">1.276622840242204e-10 1.2766342372128037e-10 2.842170943040401e-16 0 0 0</pose>
			<axis>
				<xyz>-0.9921583904222635 -0.12498691257369461 -2.432304617639304e-14</xyz>
				<limit>
					<lower>-0.5235987755982988</lower>
					<upper>0.5235987755982988</upper>
				</limit>
				<use_parent_model_frame>0</use_parent_model_frame>
			</axis>
		</joint>
		<joint name="zed_camera_right" type="fixed">
			<parent>zed_camera</parent>
			<child>zed_camera_right_lense</child>
			<pose frame="">-3.477806617303791e-05 0.011070006217811663 -0.002353014092106349 0 0 0</pose>
		</joint>
		<joint name="zed_camera_left" type="fixed">
			<parent>zed_camera</parent>
			<child>zed_camera_left_lense</child>
			<pose frame="">-5.4665509118771995e-05 0.011069943702269302 -0.002353014260490625 0 0 0</pose>
		</joint>
		<joint name="shoulder_right_axis0" type="revolute">
			<parent>torso</parent>
			<child>shoulder_right_link1</child>
			<pose frame="">1.376389491269947e-10 -7.152252567976802e-11 -2.2659207843389595e-13 0 0 0</pose>
			<axis>
				<xyz>-0.8239514135922378 0.3506360562946562 0.44514988943668027</xyz>
				<limit>
					<lower>-3.141592653589793</lower>
					<upper>3.141592653589793</upper>
				</limit>
				<use_parent_model_frame>0</use_parent_model_frame>
			</axis>
		</joint>
		<joint name="shoulder_right_axis1" type="revolute">
			<parent>shoulder_right_link1</parent>
			<child>shoulder_right_link2</child>
			<pose frame="">6.320277634586091e-14 -1.6520109724638134e-11 -4.3078784983663355e-11 0 0 0</pose>
			<axis>
				<xyz>0.048932268751817644 0.8266587526530976 -0.5605719755186003</xyz>
				<limit>
					<lower>-3.141592653589793</lower>
					<upper>3.141592653589793</upper>
				</limit>
				<use_parent_model_frame>0</use_parent_model_frame>
			</axis>
		</joint>
		<joint name="hand_left_thumb_joint1" type="revolute">
			<parent>hand_left_thumb_link0</parent>
			<child>hand_left_thumb_link1</child>
			<pose frame="">-0.005547319696619936 0.010385447221051471 -0.008626954865341787 0 0 0</pose>
			<axis>
				<xyz>0.8239514135922824 0.3506360562946 0.44514988943663436</xyz>
				<limit>
					<lower>0.0</lower>
					<upper>0.0</upper>
				</limit>
				<use_parent_model_frame>0</use_parent_model_frame>
			</axis>
		</joint>
		<joint name="hand_left_thumb_joint2" type="revolute">
			<parent>hand_left_thumb_link1</parent>
			<child>hand_left_thumb_link2</child>
			<pose frame="">-0.00540606285369023 0.009489153951052813 -0.008586137613614753 0 0 0</pose>
			<axis>
				<xyz>-0.8239514135922825 -0.35063605629459965 -0.4451498894366354</xyz>
				<limit>
					<lower>0.0</lower>
					<upper>0.0</upper>
				</limit>
				<use_parent_model_frame>0</use_parent_model_frame>
			</axis>
		</joint>
		<joint name="hand_left_little_joint1" type="revolute">
			<parent>hand_left_little_link0</parent>
			<child>hand_left_little_link1</child>
			<pose frame="">-0.006783253127030378 0.009151378352565765 0.009092761388545121 0 0 0</pose>
			<axis>
				<xyz>0.12702537302227565 -0.8798641087300474 0.45793417079011295</xyz>
				<limit>
					<lower>0.0</lower>
					<upper>0.0</upper>
				</limit>
				<use_parent_model_frame>0</use_parent_model_frame>
			</axis>
		</joint>
		<joint name="hand_left_little_joint2" type="revolute">
			<parent>hand_left_little_link1</parent>
			<child>hand_left_little_link2</child>
			<pose frame="">-0.006725284676677319 0.00875802072880795 0.008315993839416431 0 0 0</pose>
			<axis>
				<xyz>0.1270253730222765 -0.8798641087300486 0.45793417079011245</xyz>
				<limit>
					<lower>0.0</lower>
					<upper>0.0</upper>
				</limit>
				<use_parent_model_frame>0</use_parent_model_frame>
			</axis>
		</joint>
		<joint name="elbow_right" type="revolute">
			<parent>arm_right_lower</parent>
			<child>arm_right_upper</child>
			<pose frame="">-0.06239924077861709 -0.05891284646414949 -0.07215504332118428 0 0 0</pose>
			<axis>
				<xyz>0.048932268751824236 0.826658752653104 -0.5605719755185908</xyz>
				<limit>
					<lower>0.0</lower>
					<upper>0.0</upper>
				</limit>
				<use_parent_model_frame>0</use_parent_model_frame>
			</axis>
		</joint>
		<joint name="hand_right_index_joint0" type="revolute">
			<parent>arm_right_palm</parent>
			<child>hand_right_index_link0</child>
			<pose frame="">0.01117192927158925 0.008775224553004186 0.019107804119841417 0 0 0</pose>
			<axis>
				<xyz>-0.0004571659885742185 0.7851556617927034 -0.6192982946481612</xyz>
				<limit>
					<lower>0.0</lower>
					<upper>0.0</upper>
				</limit>
				<use_parent_model_frame>0</use_parent_model_frame>
			</axis>
		</joint>
		<joint name="hand_right_middle_joint0" type="revolute">
			<parent>arm_right_palm</parent>
			<child>hand_right_middle_link0</child>
			<pose frame="">0.010878608598128068 0.006939934514382849 0.02001062848035576 0 0 0</pose>
			<axis>
				<xyz>0.04893227162172448 0.8266587548903904 -0.5605719719688159</xyz>
				<limit>
					<lower>0.0</lower>
					<upper>0.0</upper>
				</limit>
				<use_parent_model_frame>0</use_parent_model_frame>
			</axis>
		</joint>
		<joint name="hand_right_ring_joint0" type="revolute">
			<parent>arm_right_palm</parent>
			<child>hand_right_ring_link0</child>
			<pose frame="">0.010486676469139127 0.005056535423802373 0.02077058058187099 0 0 0</pose>
			<axis>
				<xyz>0.09794930223986442 0.8618704734843621 -0.4975793616364782</xyz>
				<limit>
					<lower>0.0</lower>
					<upper>0.0</upper>
				</limit>
				<use_parent_model_frame>0</use_parent_model_frame>
			</axis>
		</joint>
		<joint name="hand_right_little_joint0" type="revolute">
			<parent>arm_right_palm</parent>
			<child>hand_right_little_link0</child>
			<pose frame="">0.005551542562736813 0.0006167073890361507 0.013533833528704502 0 0 0</pose>
			<axis>
				<xyz>0.1270253744259705 0.8798641095453655 -0.4579341688342145</xyz>
				<limit>
					<lower>0.0</lower>
					<upper>0.0</upper>
				</limit>
				<use_parent_model_frame>0</use_parent_model_frame>
			</axis>
		</joint>
		<joint name="hand_right_thumb_joint0" type="revolute">
			<parent>arm_right_palm</parent>
			<child>hand_right_thumb_link0</child>
			<pose frame="">0.005031812720187006 0.019005814710372278 -0.005740446872674046 0 0 0</pose>
			<axis>
				<xyz>0.5645437991104548 0.44010187762403513 0.698284065547635</xyz>
				<limit>
					<lower>0.0</lower>
					<upper>0.0</upper>
				</limit>
				<use_parent_model_frame>0</use_parent_model_frame>
			</axis>
		</joint>
		<joint name="hand_right_index_joint1" type="revolute">
			<parent>hand_right_index_link0</parent>
			<child>hand_right_index_link1</child>
			<pose frame="">0.006379269094215232 0.0038374734385426025 0.012530339931035953 0 0 0</pose>
			<axis>
				<xyz>-0.00045716598854308706 0.7851556617927065 -0.6192982946481643</xyz>
				<limit>
					<lower>0.0</lower>
					<upper>0.0</upper>
				</limit>
				<use_parent_model_frame>0</use_parent_model_frame>
			</axis>
		</joint>
		<joint name="hand_right_index_joint2" type="revolute">
			<parent>hand_right_index_link1</parent>
			<child>hand_right_index_link2</child>
			<pose frame="">0.006311447176464071 0.003299072362865303 0.011848212384543403 0 0 0</pose>
			<axis>
				<xyz>-0.00045716598854293245 0.7851556617927031 -0.6192982946481616</xyz>
				<limit>
					<lower>0.0</lower>
					<upper>0.0</upper>
				</limit>
				<use_parent_model_frame>0</use_parent_model_frame>
			</axis>
		</joint>
		<joint name="hand_right_middle_joint1" type="revolute">
			<parent>hand_right_middle_link0</parent>
			<child>hand_right_middle_link1</child>
			<pose frame="">0.0061158775116469145 0.002677782061949081 0.012955862847028383 0 0 0</pose>
			<axis>
				<xyz>0.04893227162175261 0.8266587548903902 -0.5605719719688139</xyz>
				<limit>
					<lower>0.0</lower>
					<upper>0.0</upper>
				</limit>
				<use_parent_model_frame>0</use_parent_model_frame>
			</axis>
		</joint>
		<joint name="hand_right_middle_joint2" type="revolute">
			<parent>hand_right_middle_link1</parent>
			<child>hand_right_middle_link2</child>
			<pose frame="">0.0060496625105142246 0.0021925461970707617 0.012234922008449525 0 0 0</pose>
			<axis>
				<xyz>0.04893227162175252 0.8266587548903902 -0.5605719719688139</xyz>
				<limit>
					<lower>0.0</lower>
					<upper>0.0</upper>
				</limit>
				<use_parent_model_frame>0</use_parent_model_frame>
			</axis>
		</joint>
		<joint name="hand_right_ring_joint1" type="revolute">
			<parent>hand_right_ring_link0</parent>
			<child>hand_right_ring_link1</child>
			<pose frame="">0.005795516107246641 0.0015020766721620404 0.013288448288379655 0 0 0</pose>
			<axis>
				<xyz>0.09794930223988946 0.8618704734843619 -0.49757936163647376</xyz>
				<limit>
					<lower>0.0</lower>
					<upper>0.0</upper>
				</limit>
				<use_parent_model_frame>0</use_parent_model_frame>
			</axis>
		</joint>
		<joint name="hand_right_ring_joint2" type="revolute">
			<parent>hand_right_ring_link1</parent>
			<child>hand_right_ring_link2</child>
			<pose frame="">0.005733973962649515 0.001072541007593877 0.012532656784602239 0 0 0</pose>
			<axis>
				<xyz>0.0979493022398894 0.861870473484362 -0.4975793616364738</xyz>
				<limit>
					<lower>0.0</lower>
					<upper>0.0</upper>
				</limit>
				<use_parent_model_frame>0</use_parent_model_frame>
			</axis>
		</joint>
		<joint name="hand_right_little_joint1" type="revolute">
			<parent>hand_right_little_link0</parent>
			<child>hand_right_little_link1</child>
			<pose frame="">0.005576947707723861 0.0007926802518630893 0.013442246792434621 0 0 0</pose>
			<axis>
				<xyz>0.12702537442599368 0.8798641095453656 -0.4579341688342087</xyz>
				<limit>
					<lower>0.0</lower>
					<upper>0.0</upper>
				</limit>
				<use_parent_model_frame>0</use_parent_model_frame>
			</axis>
		</joint>
		<joint name="hand_right_little_joint2" type="revolute">
			<parent>hand_right_little_link1</parent>
			<child>hand_right_little_link2</child>
			<pose frame="">0.005519626111717599 0.00039754995263020733 0.012667571225857243 0 0 0</pose>
			<axis>
				<xyz>0.12702537442599324 0.8798641095453656 -0.4579341688342094</xyz>
				<limit>
					<lower>0.0</lower>
					<upper>0.0</upper>
				</limit>
				<use_parent_model_frame>0</use_parent_model_frame>
			</axis>
		</joint>
		<joint name="hand_right_thumb_joint1" type="revolute">
			<parent>hand_right_thumb_link0</parent>
			<child>hand_right_thumb_link1</child>
			<pose frame="">-0.002302618910469079 0.013706585742585986 -0.004390237862403588 0 0 0</pose>
			<axis>
				<xyz>0.8239514135922897 -0.3506360562946327 -0.44514988943659817</xyz>
				<limit>
					<lower>0.0</lower>
					<upper>0.0</upper>
				</limit>
				<use_parent_model_frame>0</use_parent_model_frame>
			</axis>
		</joint>
		<joint name="hand_right_thumb_joint2" type="revolute">
			<parent>hand_right_thumb_link1</parent>
			<child>hand_right_thumb_link2</child>
			<pose frame="">-0.0027531238186532647 0.012957435827960708 -0.004179160085389242 0 0 0</pose>
			<axis>
				<xyz>-0.82395141359229 0.3506360562946326 0.4451498894365984</xyz>
				<limit>
					<lower>0.0</lower>
					<upper>0.0</upper>
				</limit>
				<use_parent_model_frame>0</use_parent_model_frame>
			</axis>
		</joint>
		<joint name="wrist_left_axis0" type="revolute">
			<parent>arm_left_lower</parent>
			<child>wrist_left_link1</child>
			<pose frame="">-4.860947413476424e-09 -1.5044456347368395e-10 5.400231373187125e-12 0 0 0</pose>
			<axis>
				<xyz>0.8239514135922543 0.35063605629463684 0.44514988943665973</xyz>
				<limit>
					<lower>-3.141592653589793</lower>
					<upper>3.141592653589793</upper>
				</limit>
				<use_parent_model_frame>0</use_parent_model_frame>
			</axis>
		</joint>
		<joint name="wrist_left_axis1" type="revolute">
			<parent>wrist_left_link1</parent>
			<child>wrist_left_link2</child>
			<pose frame="">-6.316724920907291e-14 8.447475607908927e-11 4.3615358435999954e-10 0 0 0</pose>
			<axis>
				<xyz>0.04893226875178811 -0.8266587526530969 0.5605719755186017</xyz>
				<limit>
					<lower>-3.141592653589793</lower>
					<upper>3.141592653589793</upper>
				</limit>
				<use_parent_model_frame>0</use_parent_model_frame>
			</axis>
		</joint>
		<joint name="elbow_left" type="revolute">
			<parent>arm_left_upper</parent>
			<child>arm_left_lower</child>
			<pose frame="">-0.07662423141246222 0.05077700323426766 0.10119302537671189 0 0 0</pose>
			<axis>
				<xyz>0.04893226875181578 -0.8266587526531016 0.5605719755185945</xyz>
				<limit>
					<lower>0.0</lower>
					<upper>0.0</upper>
				</limit>
				<use_parent_model_frame>0</use_parent_model_frame>
			</axis>
		</joint>
		<joint name="shoulder_left_axis0" type="revolute">
			<parent>torso</parent>
			<child>shoulder_left_link1</child>
			<pose frame="">-4.860963365160842e-09 -1.5044763213012403e-10 5.4201620969251966e-12 0 0 0</pose>
			<axis>
				<xyz>0.8239514135922348 0.35063605629465305 0.445149889436685</xyz>
				<limit>
					<lower>-3.141592653589793</lower>
					<upper>3.141592653589793</upper>
				</limit>
				<use_parent_model_frame>0</use_parent_model_frame>
			</axis>
		</joint>
		<joint name="shoulder_left_axis1" type="revolute">
			<parent>shoulder_left_link1</parent>
			<child>shoulder_left_link2</child>
			<pose frame="">-6.320277634586091e-14 8.447477384265767e-11 4.3615351330572595e-10 0 0 0</pose>
			<axis>
				<xyz>0.048932268751815826 -0.8266587526531001 0.5605719755185947</xyz>
				<limit>
					<lower>-3.141592653589793</lower>
					<upper>3.141592653589793</upper>
				</limit>
				<use_parent_model_frame>0</use_parent_model_frame>
			</axis>
		</joint>
		<joint name="hand_left_middle_joint0" type="revolute">
			<parent>arm_left_palm (1)</parent>
			<child>hand_left_middle_link0</child>
			<pose frame="">-0.011438517559807196 0.013416445692411507 0.015944410908516903 0 0 0</pose>
			<axis>
				<xyz>-0.09794930082119623 0.8618704725531164 -0.4975793635287807</xyz>
				<limit>
					<lower>0.0</lower>
					<upper>0.0</upper>
				</limit>
				<use_parent_model_frame>0</use_parent_model_frame>
			</axis>
		</joint>
		<joint name="hand_left_iring_joint0" type="revolute">
			<parent>arm_left_palm (1)</parent>
			<child>hand_left_ring_link0</child>
			<pose frame="">-0.011353534171066144 0.014956243310704664 0.014574949968047087 0 0 0</pose>
			<axis>
				<xyz>0.04893227018675722 -0.826658753771757 0.5605719737436891</xyz>
				<limit>
					<lower>0.0</lower>
					<upper>0.0</upper>
				</limit>
				<use_parent_model_frame>0</use_parent_model_frame>
			</axis>
		</joint>
		<joint name="hand_left_little_joint0" type="revolute">
			<parent>arm_left_palm (1)</parent>
			<child>hand_left_index_link0</child>
			<pose frame="">-0.011167490912476978 0.016388848422478546 0.013102491155629786 0 0 0</pose>
			<axis>
				<xyz>0.0004571674289195615 0.7851556604951957 -0.6192982962920972</xyz>
				<limit>
					<lower>0.0</lower>
					<upper>0.0</upper>
				</limit>
				<use_parent_model_frame>0</use_parent_model_frame>
			</axis>
		</joint>
		<joint name="hand_left_index_joint0" type="revolute">
			<parent>arm_left_palm (1)</parent>
			<child>hand_left_little_link0</child>
			<pose frame="">-0.007340793876029324 0.008166978172304128 0.009102988697151383 0 0 0</pose>
			<axis>
				<xyz>-0.12702537302227587 0.8798641087300483 -0.4579341707901142</xyz>
				<limit>
					<lower>0.0</lower>
					<upper>0.0</upper>
				</limit>
				<use_parent_model_frame>0</use_parent_model_frame>
			</axis>
		</joint>
		<joint name="hand_left_thumb_joint0" type="revolute">
			<parent>arm_left_palm (1)</parent>
			<child>hand_left_thumb_link0</child>
			<pose frame="">0.00011011819785835542 0.015071155644260337 -0.011991445427988108 0 0 0</pose>
			<axis>
				<xyz>-0.5645437991104708 0.44010187762402625 0.698284065547626</xyz>
				<limit>
					<lower>0.0</lower>
					<upper>0.0</upper>
				</limit>
				<use_parent_model_frame>0</use_parent_model_frame>
			</axis>
		</joint>
		<joint name="hand_left_middle_joint1" type="revolute">
			<parent>hand_left_middle_link0</parent>
			<child>hand_left_middle_link1</child>
			<pose frame="">-0.0067255620816948185 0.009689852027569081 0.008561881375150007 0 0 0</pose>
			<axis>
				<xyz>0.09794930082119506 -0.8618704725531152 0.49757936352877974</xyz>
				<limit>
					<lower>0.0</lower>
					<upper>0.0</upper>
				</limit>
				<use_parent_model_frame>0</use_parent_model_frame>
			</axis>
		</joint>
		<joint name="hand_left_middle_joint2" type="revolute">
			<parent>hand_left_middle_link1</parent>
			<child>hand_left_middle_link2</child>
			<pose frame="">-0.006663550153413667 0.009261958069227489 0.007804274436405168 0 0 0</pose>
			<axis>
				<xyz>0.09794930082119598 -0.8618704725531151 0.49757936352877974</xyz>
				<limit>
					<lower>0.0</lower>
					<upper>0.0</upper>
				</limit>
				<use_parent_model_frame>0</use_parent_model_frame>
			</axis>
		</joint>
		<joint name="hand_left_index_joint1" type="revolute">
			<parent>hand_left_index_link0</parent>
			<child>hand_left_index_link1</child>
			<pose frame="">-0.006374938536654468 0.011296249392186972 0.006647179030050667 0 0 0</pose>
			<axis>
				<xyz>-0.00045716742892036073 -0.785155660495199 0.6192982962920981</xyz>
				<limit>
					<lower>0.0</lower>
					<upper>0.0</upper>
				</limit>
				<use_parent_model_frame>0</use_parent_model_frame>
			</axis>
		</joint>
		<joint name="hand_left_index_joint2" type="revolute">
			<parent>hand_left_index_link1</parent>
			<child>hand_left_index_link2</child>
			<pose frame="">-0.0063071019752518965 0.010760099567160921 0.005963259636935439 0 0 0</pose>
			<axis>
				<xyz>-0.00045716742891963367 -0.7851556604951972 0.6192982962920986</xyz>
				<limit>
					<lower>0.0</lower>
					<upper>0.0</upper>
				</limit>
				<use_parent_model_frame>0</use_parent_model_frame>
			</axis>
		</joint>
		<joint name="hand_left_ring_joint1" type="revolute">
			<parent>hand_left_ring_link0</parent>
			<child>hand_left_ring_link1</child>
			<pose frame="">-0.006580487917872517 0.010530963644601777 0.007630699202666022 0 0 0</pose>
			<axis>
				<xyz>0.04893227018675659 -0.8266587537717585 0.5605719737436887</xyz>
				<limit>
					<lower>0.0</lower>
					<upper>0.0</upper>
				</limit>
				<use_parent_model_frame>0</use_parent_model_frame>
			</axis>
		</joint>
		<joint name="hand_left_ring_joint2" type="revolute">
			<parent>hand_left_ring_link1</parent>
			<child>hand_left_ring_link2</child>
			<pose frame="">-0.006513990955528186 0.010047506859282436 0.006907939478808465 0 0 0</pose>
			<axis>
				<xyz>0.048932270186757575 -0.8266587537717563 0.5605719737436886</xyz>
				<limit>
					<lower>0.0</lower>
					<upper>0.0</upper>
				</limit>
				<use_parent_model_frame>0</use_parent_model_frame>
			</axis>
		</joint>
		<plugin filename="libcardsflow_gazebo_plugin.so" name="cardsflow_gazebo_plugin"/>
	</model>
</sdf>
