<?xml version="1.0" ?>
<sdf version="1.6">
	<model name="roboy_icecream">
		<link name="head">
			<self_collide>false</self_collide>
			<pose frame="">0.0005102180295691139 0.046445898229309404 0.8611776443142852 0.0 -0.0 0.0</pose>
			<inertial>
				<pose frame="">0.0 0.0 0.0 0 0 0</pose>
				<mass>0.20495740351295888</mass>
				<inertia>
					<ixx>0.1556736912222776</ixx>
					<ixy>-6.313507101682236e-06</ixy>
					<ixz>-0.00010119595995300494</ixz>
					<iyy>0.15459780882221164</iyy>
					<iyz>-0.00846658481145499</iyz>
					<izz>0.0030527659727341504</izz>
				</inertia>
			</inertial>
			<collision name="head_collision">
				<geometry>
					<mesh>
						<uri>model://roboy_icecream/meshes/CAD/head.stl</uri>
						<scale>0.001 0.001 0.001</scale>
					</mesh>
				</geometry>
			</collision>
			<visual name="head_visual">
				<geometry>
					<mesh>
						<uri>model://roboy_icecream/meshes/CAD/head.stl</uri>
						<scale>0.001 0.001 0.001</scale>
					</mesh>
				</geometry>
			</visual>
		</link>
		<link name="torso">
			<self_collide>false</self_collide>
			<pose frame="">1.5654144647214706e-16 0.001521781085073083 0.2993372744464763 0.0 -0.0 0.0</pose>
			<inertial>
				<pose frame="">0.0 0.0 0.0 0 0 0</pose>
				<mass>1.1519352383740125</mass>
				<inertia>
					<ixx>0.31683367909806137</ixx>
					<ixy>-0.00013345135928581465</ixy>
					<ixz>6.117362846899187e-05</ixz>
					<iyy>0.3423593850628956</iyy>
					<iyz>0.0007981326615620965</iyz>
					<izz>0.03205526083913695</izz>
				</inertia>
			</inertial>
			<collision name="torso_collision">
				<geometry>
					<mesh>
						<uri>model://roboy_icecream/meshes/CAD/torso.stl</uri>
						<scale>0.001 0.001 0.001</scale>
					</mesh>
				</geometry>
			</collision>
			<visual name="torso_visual">
				<geometry>
					<mesh>
						<uri>model://roboy_icecream/meshes/CAD/torso.stl</uri>
						<scale>0.001 0.001 0.001</scale>
					</mesh>
				</geometry>
			</visual>
		</link>
		<link name="arm_right_upper">
			<self_collide>false</self_collide>
			<pose frame="">-0.2905824305929891 0.008361103804432501 0.29935547585316236 0.0 -0.0 0.0</pose>
			<inertial>
				<pose frame="">0.0 0.0 0.0 0 0 0</pose>
				<mass>0.30382570619625904</mass>
				<inertia>
					<ixx>0.03049623206630643</ixx>
					<ixy>0.0007371558107975156</ixy>
					<ixz>0.02649409699991024</ixz>
					<iyy>0.05611966012683304</iyy>
					<iyz>-0.0007087184318262786</iyz>
					<izz>0.02589050836629296</izz>
				</inertia>
			</inertial>
			<collision name="arm_right_upper_collision">
				<geometry>
					<mesh>
						<uri>model://roboy_icecream/meshes/CAD/arm_right_upper.stl</uri>
						<scale>0.001 0.001 0.001</scale>
					</mesh>
				</geometry>
			</collision>
			<visual name="arm_right_upper_visual">
				<geometry>
					<mesh>
						<uri>model://roboy_icecream/meshes/CAD/arm_right_upper.stl</uri>
						<scale>0.001 0.001 0.001</scale>
					</mesh>
				</geometry>
			</visual>
		</link>
		<link name="arm_right_lower">
			<self_collide>false</self_collide>
			<pose frame="">-0.2840989276843958 0.02165517371430804 0.027678706761530045 0.0 -0.0 0.0</pose>
			<inertial>
				<pose frame="">0.0 0.0 0.0 0 0 0</pose>
				<mass>0.26996310025843295</mass>
				<inertia>
					<ixx>0.002571663931061366</ixx>
					<ixy>0.0016461138635503918</ixy>
					<ixz>0.0022023955316728245</ixz>
					<iyy>0.02418617692367755</iyy>
					<iyz>2.0140739726766566e-05</iyz>
					<izz>0.022081325924676896</izz>
				</inertia>
			</inertial>
			<collision name="arm_right_lower_collision">
				<geometry>
					<mesh>
						<uri>model://roboy_icecream/meshes/CAD/arm_right_lower.stl</uri>
						<scale>0.001 0.001 0.001</scale>
					</mesh>
				</geometry>
			</collision>
			<visual name="arm_right_lower_visual">
				<geometry>
					<mesh>
						<uri>model://roboy_icecream/meshes/CAD/arm_right_lower.stl</uri>
						<scale>0.001 0.001 0.001</scale>
					</mesh>
				</geometry>
			</visual>
		</link>
		<link name="arm_left_upper">
			<self_collide>false</self_collide>
			<pose frame="">0.2895450347468578 0.00889718424791615 0.2980861333027241 0.0 -0.0 0.0</pose>
			<inertial>
				<pose frame="">0.0 0.0 0.0 0 0 0</pose>
				<mass>0.3010990375097506</mass>
				<inertia>
					<ixx>0.030095352612167777</ixx>
					<ixy>-0.0007764334680049139</ixy>
					<ixz>-0.026048562145339373</ixz>
					<iyy>0.055307965864145874</iyy>
					<iyz>-0.0008516321854404289</iyz>
					<izz>0.025477903124651775</izz>
				</inertia>
			</inertial>
			<collision name="arm_left_upper_collision">
				<geometry>
					<mesh>
						<uri>model://roboy_icecream/meshes/CAD/arm_left_upper.stl</uri>
						<scale>0.001 0.001 0.001</scale>
					</mesh>
				</geometry>
			</collision>
			<visual name="arm_left_upper_visual">
				<geometry>
					<mesh>
						<uri>model://roboy_icecream/meshes/CAD/arm_left_upper.stl</uri>
						<scale>0.001 0.001 0.001</scale>
					</mesh>
				</geometry>
			</visual>
		</link>
		<link name="arm_left_lower">
			<self_collide>false</self_collide>
			<pose frame="">0.2886463732074582 0.004893012940308637 0.11329774422525493 0.0 -0.0 0.0</pose>
			<inertial>
				<pose frame="">0.0 0.0 0.0 0 0 0</pose>
				<mass>0.11243588187932435</mass>
				<inertia>
					<ixx>0.0021374786122984857</ixx>
					<ixy>-0.000158980874190659</ixy>
					<ixz>-0.003678854504594684</ixz>
					<iyy>0.011493725443881088</iyy>
					<iyz>-6.916112821282024e-05</iyz>
					<izz>0.009416325302496205</izz>
				</inertia>
			</inertial>
			<collision name="arm_left_lower_collision">
				<geometry>
					<mesh>
						<uri>model://roboy_icecream/meshes/CAD/arm_left_lower.stl</uri>
						<scale>0.001 0.001 0.001</scale>
					</mesh>
				</geometry>
			</collision>
			<visual name="arm_left_lower_visual">
				<geometry>
					<mesh>
						<uri>model://roboy_icecream/meshes/CAD/arm_left_lower.stl</uri>
						<scale>0.001 0.001 0.001</scale>
					</mesh>
				</geometry>
			</visual>
		</link>
		<link name="scooper">
			<self_collide>false</self_collide>
			<pose frame="">-0.22058776229621266 0.13105777492900084 -0.028074403551902823 0.0 -0.0 0.0</pose>
			<inertial>
				<pose frame="">0.0 0.0 0.0 0 0 0</pose>
				<mass>0.011097676048805946</mass>
				<inertia>
					<ixx>0.0002003609114548049</ixx>
					<ixy>0.00032083094363668857</ixy>
					<ixz>-6.872646348889796e-05</ixz>
					<iyy>0.0005497470545276575</iyy>
					<iyz>4.083244369422042e-05</iyz>
					<izz>0.0007316154170927664</izz>
				</inertia>
			</inertial>
			<collision name="scooper_collision">
				<geometry>
					<mesh>
						<uri>model://roboy_icecream/meshes/CAD/scooper.stl</uri>
						<scale>0.001 0.001 0.001</scale>
					</mesh>
				</geometry>
			</collision>
			<visual name="scooper_visual">
				<geometry>
					<mesh>
						<uri>model://roboy_icecream/meshes/CAD/scooper.stl</uri>
						<scale>0.001 0.001 0.001</scale>
					</mesh>
				</geometry>
			</visual>
		</link>
		<link name="scooper">
			<self_collide>false</self_collide>
			<pose frame="">-0.22058776229621266 0.13105777492900084 -0.028074403551902823 0.0 -0.0 0.0</pose>
			<inertial>
				<pose frame="">0.0 0.0 0.0 0 0 0</pose>
				<mass>0.011097676048805946</mass>
				<inertia>
					<ixx>0.0002003609114548049</ixx>
					<ixy>0.00032083094363668857</ixy>
					<ixz>-6.872646348889796e-05</ixz>
					<iyy>0.0005497470545276575</iyy>
					<iyz>4.083244369422042e-05</iyz>
					<izz>0.0007316154170927664</izz>
				</inertia>
			</inertial>
			<collision name="scooper_collision">
				<geometry>
					<mesh>
						<uri>model://roboy_icecream/meshes/CAD/scooper.stl</uri>
						<scale>0.001 0.001 0.001</scale>
					</mesh>
				</geometry>
			</collision>
			<visual name="scooper_visual">
				<geometry>
					<mesh>
						<uri>model://roboy_icecream/meshes/CAD/scooper.stl</uri>
						<scale>0.001 0.001 0.001</scale>
					</mesh>
				</geometry>
			</visual>
		</link>
		<link name="shoulder_left_link1">
			<self_collide>false</self_collide>
			<pose frame="">0.29189388396936844 0.013936649708446084 0.5448924278024039 0.0 -0.0 0.0</pose>
			<inertial>
				<pose frame="">0.0 0.0 0.0 0 0 0</pose>
				<mass>0.009036188404972216</mass>
				<inertia>
					<ixx>0.0026853786874337163</ixx>
					<ixy>-3.675942095743902e-05</ixy>
					<ixz>-0.0014372126974415212</ixz>
					<iyy>0.003453525279236198</iyy>
					<iyz>-6.862058794001134e-05</iyz>
					<izz>0.0007723659313968807</izz>
				</inertia>
			</inertial>
			<collision name="shoulder_left_link1_collision">
				<geometry>
					<mesh>
						<uri>model://roboy_icecream/meshes/CAD/shoulder_left_link1.stl</uri>
						<scale>0.001 0.001 0.001</scale>
					</mesh>
				</geometry>
			</collision>
			<visual name="shoulder_left_link1_visual">
				<geometry>
					<mesh>
						<uri>model://roboy_icecream/meshes/CAD/shoulder_left_link1.stl</uri>
						<scale>0.001 0.001 0.001</scale>
					</mesh>
				</geometry>
			</visual>
		</link>
		<link name="shoulder_left_link2">
			<self_collide>false</self_collide>
			<pose frame="">0.29189387258386296 0.013936775290985024 0.5448924436270218 0.0 -0.0 0.0</pose>
			<inertial>
				<pose frame="">0.0 0.0 0.0 0 0 0</pose>
				<mass>0.0007113170108844941</mass>
				<inertia>
					<ixx>0.00021134396605301215</ixx>
					<ixy>-2.8936797892132433e-06</ixy>
					<ixz>-0.00011313551510286908</ixz>
					<iyy>0.000271811459643765</iyy>
					<iyz>-5.401772354685746e-06</iyz>
					<izz>6.07540702812908e-05</izz>
				</inertia>
			</inertial>
			<collision name="shoulder_left_link2_collision">
				<geometry>
					<mesh>
						<uri>model://roboy_icecream/meshes/CAD/shoulder_left_link2.stl</uri>
						<scale>0.001 0.001 0.001</scale>
					</mesh>
				</geometry>
			</collision>
			<visual name="shoulder_left_link2_visual">
				<geometry>
					<mesh>
						<uri>model://roboy_icecream/meshes/CAD/shoulder_left_link2.stl</uri>
						<scale>0.001 0.001 0.001</scale>
					</mesh>
				</geometry>
			</visual>
		</link>
		<link name="shoulder_right_link1">
			<self_collide>false</self_collide>
			<pose frame="">-0.29317381623663624 0.009234619138342707 0.5481032586387985 0.0 -0.0 0.0</pose>
			<inertial>
				<pose frame="">0.0 0.0 0.0 0 0 0</pose>
				<mass>0.009036760208789225</mass>
				<inertia>
					<ixx>0.002716277857038176</ixx>
					<ixy>2.4465659548951448e-05</ixy>
					<ixz>0.0014521126966952603</ixz>
					<iyy>0.0034922247415397722</iyy>
					<iyz>-4.5739786268846117e-05</iyz>
					<izz>0.0007781973864830209</izz>
				</inertia>
			</inertial>
			<collision name="shoulder_right_link1_collision">
				<geometry>
					<mesh>
						<uri>model://roboy_icecream/meshes/CAD/shoulder_right_link1.stl</uri>
						<scale>0.001 0.001 0.001</scale>
					</mesh>
				</geometry>
			</collision>
			<visual name="shoulder_right_link1_visual">
				<geometry>
					<mesh>
						<uri>model://roboy_icecream/meshes/CAD/shoulder_right_link1.stl</uri>
						<scale>0.001 0.001 0.001</scale>
					</mesh>
				</geometry>
			</visual>
		</link>
		<link name="shoulder_right_link2">
			<self_collide>false</self_collide>
			<pose frame="">-0.2931738685724693 0.009234231768945902 0.5481033912318385 0.0 -0.0 0.0</pose>
			<inertial>
				<pose frame="">0.0 0.0 0.0 0 0 0</pose>
				<mass>0.0007113171768782597</mass>
				<inertia>
					<ixx>0.0002137629132340016</ixx>
					<ixy>1.9257030781476827e-06</ixy>
					<ixz>0.00011430126664005363</ixz>
					<iyy>0.0002748406222637266</iyy>
					<iyz>-3.6001994065082846e-06</iyz>
					<izz>6.120927174830888e-05</izz>
				</inertia>
			</inertial>
			<collision name="shoulder_right_link2_collision">
				<geometry>
					<mesh>
						<uri>model://roboy_icecream/meshes/CAD/shoulder_right_link2.stl</uri>
						<scale>0.001 0.001 0.001</scale>
					</mesh>
				</geometry>
			</collision>
			<visual name="shoulder_right_link2_visual">
				<geometry>
					<mesh>
						<uri>model://roboy_icecream/meshes/CAD/shoulder_right_link2.stl</uri>
						<scale>0.001 0.001 0.001</scale>
					</mesh>
				</geometry>
			</visual>
		</link>
		<link name="zed_camera_left_lense">
			<self_collide>false</self_collide>
			<pose frame="">0.060224029002958875 -0.06914536611449566 0.9297742812708069 0.0 -0.0 0.0</pose>
			<inertial>
				<pose frame="">0.0 0.0 0.0 0 0 0</pose>
				<mass>0.0005755421856391891</mass>
				<inertia>
					<ixx>0.0005003354055639959</ixx>
					<ixy>2.3967379469334977e-06</ixy>
					<ixz>-3.222735583266803e-05</ixz>
					<iyy>0.0004996529496255549</iyy>
					<iyz>3.70054972711012e-05</iyz>
					<izz>4.878384607433585e-06</izz>
				</inertia>
			</inertial>
			<collision name="zed_camera_left_lense_collision">
				<geometry>
					<mesh>
						<uri>model://roboy_icecream/meshes/CAD/zed_camera_left_lense.stl</uri>
						<scale>0.001 0.001 0.001</scale>
					</mesh>
				</geometry>
			</collision>
			<visual name="zed_camera_left_lense_visual">
				<geometry>
					<mesh>
						<uri>model://roboy_icecream/meshes/CAD/zed_camera_left_lense.stl</uri>
						<scale>0.001 0.001 0.001</scale>
					</mesh>
				</geometry>
			</visual>
		</link>
		<link name="zed_camera_right_lense">
			<self_collide>false</self_collide>
			<pose frame="">-0.05977745584801778 -0.06952236314727904 0.9297742812332496 0.0 -0.0 0.0</pose>
			<inertial>
				<pose frame="">0.0 0.0 0.0 0 0 0</pose>
				<mass>0.0005755421855125974</mass>
				<inertia>
					<ixx>0.0005003654932232295</ixx>
					<ixy>-2.391821338968771e-06</ixy>
					<ixz>3.1988357548007145e-05</ixz>
					<iyy>0.0004996221065096928</iyy>
					<iyz>3.720723754360987e-05</iyz>
					<izz>4.877629449989427e-06</izz>
				</inertia>
			</inertial>
			<collision name="zed_camera_right_lense_collision">
				<geometry>
					<mesh>
						<uri>model://roboy_icecream/meshes/CAD/zed_camera_right_lense.stl</uri>
						<scale>0.001 0.001 0.001</scale>
					</mesh>
				</geometry>
			</collision>
			<visual name="zed_camera_right_lense_visual">
				<geometry>
					<mesh>
						<uri>model://roboy_icecream/meshes/CAD/zed_camera_right_lense.stl</uri>
						<scale>0.001 0.001 0.001</scale>
					</mesh>
				</geometry>
			</visual>
		</link>
		<link name="zed_camera">
			<self_collide>false</self_collide>
			<pose frame="">0.004244484790251953 -0.057938621286604985 0.9271942136470953 0.0 -0.0 0.0</pose>
			<inertial>
				<pose frame="">0.0 0.0 0.0 0 0 0</pose>
				<mass>0.0009633907989226702</mass>
				<inertia>
					<ixx>0.0008314802982788687</ixx>
					<ixy>2.436533895216603e-07</ixy>
					<ixz>-3.793293439362343e-06</ixz>
					<iyy>0.0008297308522063661</iyy>
					<iyz>5.174870196291635e-05</iyz>
					<izz>4.725323656366554e-06</izz>
				</inertia>
			</inertial>
			<collision name="zed_camera_collision">
				<geometry>
					<mesh>
						<uri>model://roboy_icecream/meshes/CAD/zed_camera.stl</uri>
						<scale>0.001 0.001 0.001</scale>
					</mesh>
				</geometry>
			</collision>
			<visual name="zed_camera_visual">
				<geometry>
					<mesh>
						<uri>model://roboy_icecream/meshes/CAD/zed_camera.stl</uri>
						<scale>0.001 0.001 0.001</scale>
					</mesh>
				</geometry>
			</visual>
		</link>
		<link name="neck_link1">
			<self_collide>false</self_collide>
			<pose frame="">-1.506123287543706e-10 0.0015217809344427158 0.7156779292283452 0.0 -0.0 0.0</pose>
			<inertial>
				<pose frame="">0.0 0.0 0.0 0 0 0</pose>
				<mass>0.0017038665636260374</mass>
				<inertia>
					<ixx>0.0008728267843512113</ixx>
					<ixy>3.9052463248877987e-16</ixy>
					<ixz>1.836596576210159e-13</ixz>
					<iyy>0.0008728228385076957</iyy>
					<iyz>-1.855689641317778e-06</iyz>
					<izz>1.1502292854573882e-07</izz>
				</inertia>
			</inertial>
			<collision name="neck_link1_collision">
				<geometry>
					<mesh>
						<uri>model://roboy_icecream/meshes/CAD/neck_link1.stl</uri>
						<scale>0.001 0.001 0.001</scale>
					</mesh>
				</geometry>
			</collision>
			<visual name="neck_link1_visual">
				<geometry>
					<mesh>
						<uri>model://roboy_icecream/meshes/CAD/neck_link1.stl</uri>
						<scale>0.001 0.001 0.001</scale>
					</mesh>
				</geometry>
			</visual>
		</link>
		<link name="neck_link2">
			<self_collide>false</self_collide>
			<pose frame="">-1.2765957254235939e-10 0.0015217809573941732 0.7156779292283448 0.0 -0.0 0.0</pose>
			<inertial>
				<pose frame="">0.0 0.0 0.0 0 0 0</pose>
				<mass>0.0011421521917888836</mass>
				<inertia>
					<ixx>0.0005850573477666747</ixx>
					<ixy>2.21885727293928e-16</ixy>
					<ixz>1.0435059226432399e-13</ixz>
					<iyy>0.0005850547027508899</iyy>
					<iyz>-1.243923713466404e-06</iyz>
					<izz>5.28219512713884e-08</izz>
				</inertia>
			</inertial>
			<collision name="neck_link2_collision">
				<geometry>
					<mesh>
						<uri>model://roboy_icecream/meshes/CAD/neck_link2.stl</uri>
						<scale>0.001 0.001 0.001</scale>
					</mesh>
				</geometry>
			</collision>
			<visual name="neck_link2_visual">
				<geometry>
					<mesh>
						<uri>model://roboy_icecream/meshes/CAD/neck_link2.stl</uri>
						<scale>0.001 0.001 0.001</scale>
					</mesh>
				</geometry>
			</visual>
		</link>
		<link name="bike_back">
			<self_collide>false</self_collide>
			<pose frame="">-0.00011016712007182441 -0.36126275744903424 -0.5575062332679439 0.0 -0.0 0.0</pose>
			<inertial>
				<pose frame="">0.0 0.0 0.0 0 0 0</pose>
				<mass>1.2951344920362922</mass>
				<inertia>
					<ixx>0.8442264729699303</ixx>
					<ixy>0.005546017500224689</ixy>
					<ixz>-0.00017735467712802575</ixz>
					<iyy>0.42643007759447893</iyy>
					<iyz>-0.29995137524469556</iyz>
					<izz>0.4303003496245288</izz>
				</inertia>
			</inertial>
			<collision name="bike_back_collision">
				<geometry>
					<mesh>
						<uri>model://roboy_icecream/meshes/CAD/bike_back.stl</uri>
						<scale>0.001 0.001 0.001</scale>
					</mesh>
				</geometry>
			</collision>
			<visual name="bike_back_visual">
				<geometry>
					<mesh>
						<uri>model://roboy_icecream/meshes/CAD/bike_back.stl</uri>
						<scale>0.001 0.001 0.001</scale>
					</mesh>
				</geometry>
			</visual>
		</link>
		<link name="bike_front">
			<self_collide>false</self_collide>
			<pose frame="">0.001211683303697229 -1.1105264212253108 -0.13497386907788986 0.0 -0.0 0.0</pose>
			<inertial>
				<pose frame="">0.0 0.0 0.0 0 0 0</pose>
				<mass>63.7307664696775</mass>
				<inertia>
					<ixx>97.29796056018368</ixx>
					<ixy>0.18846553118688075</ixy>
					<ixz>0.05000139261544522</ixz>
					<iyy>6.576697684911534</iyy>
					<iyz>-15.1057167024435</iyz>
					<izz>93.78235037267204</izz>
				</inertia>
			</inertial>
			<collision name="bike_front_collision">
				<geometry>
					<mesh>
						<uri>model://roboy_icecream/meshes/CAD/bike_front.stl</uri>
						<scale>0.001 0.001 0.001</scale>
					</mesh>
				</geometry>
			</collision>
			<visual name="bike_front_visual">
				<geometry>
					<mesh>
						<uri>model://roboy_icecream/meshes/CAD/bike_front.stl</uri>
						<scale>0.001 0.001 0.001</scale>
					</mesh>
				</geometry>
			</visual>
		</link>
		<link name="zed_mini">
			<self_collide>false</self_collide>
			<pose frame="">-0.001019700980953229 -0.11846878800848305 0.3935576598835387 0.0 -0.0 0.0</pose>
			<inertial>
				<pose frame="">0.0 0.0 0.0 0 0 0</pose>
				<mass>0.043618915158257776</mass>
				<inertia>
					<ixx>0.00737257003290057</ixx>
					<ixy>-6.039631699136496e-06</ixy>
					<ixz>1.7504257606619555e-05</ixz>
					<iyy>0.006813337441384371</iyy>
					<iyz>0.0020337006242750425</iyz>
					<izz>0.0006694076484380283</izz>
				</inertia>
			</inertial>
			<collision name="zed_mini_collision">
				<geometry>
					<mesh>
						<uri>model://roboy_icecream/meshes/CAD/zed_mini.stl</uri>
						<scale>0.001 0.001 0.001</scale>
					</mesh>
				</geometry>
			</collision>
			<visual name="zed_mini_visual">
				<geometry>
					<mesh>
						<uri>model://roboy_icecream/meshes/CAD/zed_mini.stl</uri>
						<scale>0.001 0.001 0.001</scale>
					</mesh>
				</geometry>
			</visual>
		</link>
		<link name="pico_flexx">
			<self_collide>false</self_collide>
			<pose frame="">0.01636582286047142 -0.11769402429443933 0.41518622532478316 0.0 -0.0 0.0</pose>
			<inertial>
				<pose frame="">0.0 0.0 0.0 0 0 0</pose>
				<mass>0.0015436810520105988</mass>
				<inertia>
					<ixx>0.0002875421261491332</ixx>
					<ixy>2.9660169029790847e-06</ixy>
					<ixz>-1.0489308848843665e-05</ixz>
					<iyy>0.00026725118905498264</iyy>
					<iyz>7.543345735127459e-05</iyz>
					<izz>2.2486643967097435e-05</izz>
				</inertia>
			</inertial>
			<collision name="pico_flexx_collision">
				<geometry>
					<mesh>
						<uri>model://roboy_icecream/meshes/CAD/pico_flexx.stl</uri>
						<scale>0.001 0.001 0.001</scale>
					</mesh>
				</geometry>
			</collision>
			<visual name="pico_flexx_visual">
				<geometry>
					<mesh>
						<uri>model://roboy_icecream/meshes/CAD/pico_flexx.stl</uri>
						<scale>0.001 0.001 0.001</scale>
					</mesh>
				</geometry>
			</visual>
		</link>
		<link name="sphere_link1">
			<self_collide>false</self_collide>
			<pose frame="">-0.22058776229621266 0.1310577749290009 -0.028074403551902744 0.0 -0.0 0.0</pose>
			<inertial>
				<pose frame="">0.0 0.0 0.0 0 0 0</pose>
				<mass>0.003806502884740438</mass>
				<inertia>
					<ixx>6.854907414658848e-05</ixx>
					<ixy>0.00011004501366738414</ixy>
					<ixz>-2.3573176976691907e-05</ixz>
					<iyy>0.0001883885212205768</iyy>
					<iyz>1.4005528187117557e-05</iyz>
					<izz>0.0002507693695804091</izz>
				</inertia>
			</inertial>
			<collision name="sphere_link1_collision">
				<geometry>
					<mesh>
						<uri>model://roboy_icecream/meshes/CAD/sphere_link1.stl</uri>
						<scale>0.001 0.001 0.001</scale>
					</mesh>
				</geometry>
			</collision>
			<visual name="sphere_link1_visual">
				<geometry>
					<mesh>
						<uri>model://roboy_icecream/meshes/CAD/sphere_link1.stl</uri>
						<scale>0.001 0.001 0.001</scale>
					</mesh>
				</geometry>
			</visual>
		</link>
		<link name="sphere_link2">
			<self_collide>false</self_collide>
			<pose frame="">-0.22058776229621252 0.1310577749290009 -0.028074403551902778 0.0 -0.0 0.0</pose>
			<inertial>
				<pose frame="">0.0 0.0 0.0 0 0 0</pose>
				<mass>0.00029963725331776065</mass>
				<inertia>
					<ixx>5.385204318233014e-06</ixx>
					<ixy>8.662435478190593e-06</ixy>
					<ixz>-1.8556145142002415e-06</ixz>
					<iyy>1.4818630181200015e-05</iyy>
					<iyz>1.1024759797439506e-06</iyz>
					<izz>1.972907597045796e-05</izz>
				</inertia>
			</inertial>
			<collision name="sphere_link2_collision">
				<geometry>
					<mesh>
						<uri>model://roboy_icecream/meshes/CAD/sphere_link2.stl</uri>
						<scale>0.001 0.001 0.001</scale>
					</mesh>
				</geometry>
			</collision>
			<visual name="sphere_link2_visual">
				<geometry>
					<mesh>
						<uri>model://roboy_icecream/meshes/CAD/sphere_link2.stl</uri>
						<scale>0.001 0.001 0.001</scale>
					</mesh>
				</geometry>
			</visual>
		</link>
		<link name="scooper_target">
			<self_collide>false</self_collide>
			<pose frame="">-0.22058753522041952 0.12080167912625438 -0.028074678995817323 0.0 -0.0 0.0</pose>
			<inertial>
				<pose frame="">0.0 0.0 0.0 0 0 0</pose>
				<mass>0.0016515273283131571</mass>
				<inertia>
					<ixx>2.5473989808842502e-05</ixx>
					<ixy>4.4008821568885375e-05</ixy>
					<ixz>-1.0227783233291555e-05</ixz>
					<iyy>8.169017438211724e-05</iyy>
					<iyz>5.6010982531039826e-06</iyz>
					<izz>0.00010453369608993696</izz>
				</inertia>
			</inertial>
			<collision name="scooper_target_collision">
				<geometry>
					<mesh>
						<uri>model://roboy_icecream/meshes/CAD/scooper_target.stl</uri>
						<scale>0.001 0.001 0.001</scale>
					</mesh>
				</geometry>
			</collision>
			<visual name="scooper_target_visual">
				<geometry>
					<mesh>
						<uri>model://roboy_icecream/meshes/CAD/scooper_target.stl</uri>
						<scale>0.001 0.001 0.001</scale>
					</mesh>
				</geometry>
			</visual>
		</link>
		<link name="scooper_link0">
			<self_collide>false</self_collide>
			<pose frame="">-4.218861302418105e-18 0.0 0.05 0.0 -0.0 0.0</pose>
			<inertial>
				<pose frame="">0.0 0.0 0.0 0 0 0</pose>
				<mass>0.02648405776597615</mass>
				<inertia>
					<ixx>6.206497899009215e-05</ixx>
					<ixy>8.829478225497096e-05</ixy>
					<ixz>-0.0002584830356234787</ixz>
					<iyy>0.0014090138898241297</iyy>
					<iyz>1.6858471230719796e-05</iyz>
					<izz>0.001369824173631999</izz>
				</inertia>
			</inertial>
			<collision name="scooper_link0_collision">
				<geometry>
					<mesh>
						<uri>model://roboy_icecream/meshes/CAD/scooper_link0.stl</uri>
						<scale>0.001 0.001 0.001</scale>
					</mesh>
				</geometry>
			</collision>
			<visual name="scooper_link0_visual">
				<geometry>
					<mesh>
						<uri>model://roboy_icecream/meshes/CAD/scooper_link0.stl</uri>
						<scale>0.001 0.001 0.001</scale>
					</mesh>
				</geometry>
			</visual>
		</link>
		<link name="scooper_link1">
			<self_collide>false</self_collide>
			<pose frame="">-4.5356372103014414e-05 0.015 0.1401335355489842 0.0 -0.0 0.0</pose>
			<inertial>
				<pose frame="">0.0 0.0 0.0 0 0 0</pose>
				<mass>0.0382252965133526</mass>
				<inertia>
					<ixx>0.0003900325574964314</ixx>
					<ixy>0.0007313110006281329</ixy>
					<ixz>-0.000365620597160959</ixz>
					<iyy>0.0019722999108079966</iyy>
					<iyz>0.00014129596098199864</iyz>
					<izz>0.0022172114308511557</izz>
				</inertia>
			</inertial>
			<collision name="scooper_link1_collision">
				<geometry>
					<mesh>
						<uri>model://roboy_icecream/meshes/CAD/scooper_link1.stl</uri>
						<scale>0.001 0.001 0.001</scale>
					</mesh>
				</geometry>
			</collision>
			<visual name="scooper_link1_visual">
				<geometry>
					<mesh>
						<uri>model://roboy_icecream/meshes/CAD/scooper_link1.stl</uri>
						<scale>0.001 0.001 0.001</scale>
					</mesh>
				</geometry>
			</visual>
		</link>
		<joint name="spine" type="revolute">
			<parent>torso</parent>
			<child>bike_back</child>
			<pose frame="">0.00011016712009334052 0.36124080296251676 0.8568435077144142 0 0 0</pose>
			<axis>
				<xyz>8.881784197001363e-16 -8.242182021273602e-15 -1.0000000000000013</xyz>
				<limit>
					<lower>0.0</lower>
					<upper>0.0</upper>
				</limit>
				<use_parent_model_frame>0</use_parent_model_frame>
			</axis>
		</joint>
		<joint name="zed_pico_attachement" type="fixed">
			<parent>zed_mini</parent>
			<child>pico_flexx</child>
			<pose frame="">0.04170918832895287 0.0022156345492233775 -0.008311850212956173 0 0 0</pose>
		</joint>
		<joint name="zed_mini_attachement" type="fixed">
			<parent>torso</parent>
			<child>zed_mini</child>
			<pose frame="">0.0014947135695966053 0.00964539826326817 0.03000459728702701 0 0 0</pose>
		</joint>
		<joint name="zed_camera_right" type="fixed">
			<parent>zed_camera</parent>
			<child>zed_camera_right_lense</child>
			<pose frame="">-3.4778066173002385e-05 0.011070006217811717 -0.0023530140921069176 0 0 0</pose>
		</joint>
		<joint name="zed_camera_left" type="fixed">
			<parent>zed_camera</parent>
			<child>zed_camera_left_lense</child>
			<pose frame="">-5.466550911876311e-05 0.011069943702269311 -0.0023530142604900562 0 0 0</pose>
		</joint>
		<joint name="neck_axis0" type="revolute">
			<parent>torso</parent>
			<child>neck_link1</child>
			<pose frame="">1.5061504170881626e-10 1.5061483921163798e-10 0.0 0 0 0</pose>
			<axis>
				<xyz>0.12498691257369461 -0.9921583904222635 6.724690979212187e-15</xyz>
				<limit>
					<lower>-0.5235987755982988</lower>
					<upper>0.5235987755982988</upper>
				</limit>
				<use_parent_model_frame>0</use_parent_model_frame>
			</axis>
		</joint>
		<joint name="neck_axis2" type="revolute">
			<parent>neck_link2</parent>
			<child>head</child>
			<pose frame="">-0.0005102180295663994 -0.04492411714425187 -0.14549971508594026 0 0 0</pose>
			<axis>
				<xyz>-2.4972812708040394e-14 3.6318961320475e-15 1.0</xyz>
				<limit>
					<lower>-0.5235987755982988</lower>
					<upper>0.5235987755982988</upper>
				</limit>
				<use_parent_model_frame>0</use_parent_model_frame>
			</axis>
		</joint>
		<joint name="neck_axis1" type="revolute">
			<parent>neck_link1</parent>
			<child>neck_link2</child>
			<pose frame="">1.2766228137374175e-10 1.27663441207293e-10 2.842170943040401e-16 0 0 0</pose>
			<axis>
				<xyz>-0.9921583904222635 -0.12498691257369464 -2.432304617639304e-14</xyz>
				<limit>
					<lower>-0.5235987755982988</lower>
					<upper>0.5235987755982988</upper>
				</limit>
				<use_parent_model_frame>0</use_parent_model_frame>
			</axis>
		</joint>
		<joint name="zed_camera_mount" type="fixed">
			<parent>head</parent>
			<child>zed_camera</child>
			<pose frame="">0.01743765468509108 0.001405588958414743 0.008052233827783653 0 0 0</pose>
		</joint>
		<joint name="shoulder_right_axis0" type="revolute">
			<parent>torso</parent>
			<child>shoulder_right_link1</child>
			<pose frame="">-5.233583294739219e-08 -3.8736939575012564e-07 1.3259304864732258e-07 0 0 0</pose>
			<axis>
				<xyz>0.9986354432836153 -0.050744296328168695 0.012339684270770077</xyz>
				<limit>
					<lower>-3.141592653589793</lower>
					<upper>3.141592653589793</upper>
				</limit>
				<use_parent_model_frame>0</use_parent_model_frame>
			</axis>
		</joint>
		<joint name="shoulder_right_axis1" type="revolute">
			<parent>shoulder_right_link1</parent>
			<child>shoulder_right_link2</child>
			<pose frame="">1.4210854715202004e-16 1.0502709812953982e-15 8.668621376273222e-15 0 0 0</pose>
			<axis>
				<xyz>-0.050743529127072876 -0.9987116467140966 -0.0003754588500051825</xyz>
				<limit>
					<lower>-3.141592653589793</lower>
					<upper>3.141592653589793</upper>
				</limit>
				<use_parent_model_frame>0</use_parent_model_frame>
			</axis>
		</joint>
		<joint name="shoulder_right_axis2" type="revolute">
			<parent>shoulder_right_link2</parent>
			<child>arm_right_upper</child>
			<pose frame="">-0.002591437979480276 0.0008731279645144763 0.24874791537868413 0 0 0</pose>
			<axis>
				<xyz>0.01234283879313641 -0.00025121261310212685 -0.9999237927075992</xyz>
				<limit>
					<lower>-3.141592653589793</lower>
					<upper>3.141592653589793</upper>
				</limit>
				<use_parent_model_frame>0</use_parent_model_frame>
			</axis>
		</joint>
		<joint name="shoulder_left_axis0" type="revolute">
			<parent>torso</parent>
			<child>shoulder_left_link1</child>
			<pose frame="">-1.1385505445105081e-08 1.2559192860583934e-07 1.4254478415409721e-08 0 0 0</pose>
			<axis>
				<xyz>-0.9986354432836135 -0.05074429632816786 0.012339684270767625</xyz>
				<limit>
					<lower>-3.141592653589793</lower>
					<upper>3.141592653589793</upper>
				</limit>
				<use_parent_model_frame>0</use_parent_model_frame>
			</axis>
		</joint>
		<joint name="shoulder_left_axis1" type="revolute">
			<parent>shoulder_left_link1</parent>
			<child>shoulder_left_link2</child>
			<pose frame="">-3.552713678800501e-17 9.389691246752819e-12 -1.5701394318057283e-09 0 0 0</pose>
			<axis>
				<xyz>-0.05101049431667528 0.998448888302568 -0.022310242422104942</xyz>
				<limit>
					<lower>-3.141592653589793</lower>
					<upper>3.141592653589793</upper>
				</limit>
				<use_parent_model_frame>0</use_parent_model_frame>
			</axis>
		</joint>
		<joint name="shoulder_left_axis2" type="revolute">
			<parent>shoulder_left_link2</parent>
			<child>arm_left_upper</child>
			<pose frame="">0.002348837837005142 0.005039591052458574 0.24680630875415838 0 0 0</pose>
			<axis>
				<xyz>-0.011188426489531611 -0.022909252225327616 -0.9996749398055182</xyz>
				<limit>
					<lower>-3.141592653589793</lower>
					<upper>3.141592653589793</upper>
				</limit>
				<use_parent_model_frame>0</use_parent_model_frame>
			</axis>
		</joint>
		<joint name="bike_steering" type="revolute">
			<parent>bike_back</parent>
			<child>bike_front</child>
			<pose frame="">-0.003146200605151102 -0.09182232572244772 -0.46868885849281433 0 0 0</pose>
			<axis>
				<xyz>-1.8044974943364984e-16 -9.570458378672299e-08 0.9999999999999957</xyz>
				<limit>
					<lower>-0.5235987755982988</lower>
					<upper>0.5235987755982988</upper>
				</limit>
				<use_parent_model_frame>0</use_parent_model_frame>
			</axis>
		</joint>
		<joint name="elbow_right" type="revolute">
			<parent>arm_right_upper</parent>
			<child>arm_right_lower</child>
			<pose frame="">-0.02208024793692591 -0.011623910797073818 0.15801714290834953 0 0 0</pose>
			<axis>
				<xyz>-0.9986354432836136 0.050744296328171457 -0.012339684270769206</xyz>
				<limit>
					<lower>0.0</lower>
					<upper>1.9198621771937625</upper>
				</limit>
				<use_parent_model_frame>0</use_parent_model_frame>
			</axis>
		</joint>
		<joint name="elbow_left" type="revolute">
			<parent>arm_left_upper</parent>
			<child>arm_left_lower</child>
			<pose frame="">0.016671169312367874 0.0016340517888877581 0.0692962893927708 0 0 0</pose>
			<axis>
				<xyz>-0.9986354432836131 -0.05074429632816898 0.01233968427076712</xyz>
				<limit>
					<lower>0.0</lower>
					<upper>0.0</upper>
				</limit>
				<use_parent_model_frame>0</use_parent_model_frame>
			</axis>
		</joint>
		<joint name="scooper_target_axis0" type="revolute">
			<parent>scooper</parent>
			<child>sphere_link1</child>
			<pose frame="">0.0 -7.105427357601002e-17 -7.549516567451065e-17 0 0 0</pose>
			<axis>
				<xyz>1.0 -3.8163916471489786e-16 -4.718447854656967e-16</xyz>
				<limit>
					<lower>-3.141592653589793</lower>
					<upper>3.141592653589793</upper>
				</limit>
				<use_parent_model_frame>0</use_parent_model_frame>
			</axis>
		</joint>
		<joint name="scooper_target_axis1" type="revolute">
			<parent>sphere_link1</parent>
			<child>sphere_link2</child>
			<pose frame="">-2.1316282072803005e-16 0.0 2.6645352591003756e-17 0 0 0</pose>
			<axis>
				<xyz>4.9894328060826745e-16 -1.2684048525500657e-14 1.0</xyz>
				<limit>
					<lower>-3.141592653589793</lower>
					<upper>3.141592653589793</upper>
				</limit>
				<use_parent_model_frame>0</use_parent_model_frame>
			</axis>
		</joint>
		<joint name="scooper_target_axis2" type="revolute">
			<parent>sphere_link2</parent>
			<child>scooper_target</child>
			<pose frame="">-2.2707579304892534e-07 0.010256095802746543 2.754439145347121e-07 0 0 0</pose>
			<axis>
				<xyz>-6.397427334395047e-16 -1.0000000000000013 -1.2649478821402009e-14</xyz>
				<limit>
					<lower>-3.141592653589793</lower>
					<upper>3.141592653589793</upper>
				</limit>
				<use_parent_model_frame>0</use_parent_model_frame>
			</axis>
		</joint>
		<joint name="scoop_tool" type="revolute">
			<parent>arm_right_lower</parent>
			<child>scooper</child>
			<pose frame="">-0.024214327790023197 -0.09902664243293777 -0.015325164692090764 0 0 0</pose>
			<axis>
				<xyz>0.9986354432836129 -0.05074429632816074 0.012339684270771395</xyz>
				<limit>
					<lower>0.0</lower>
					<upper>3.141592653589793</upper>
				</limit>
				<use_parent_model_frame>0</use_parent_model_frame>
			</axis>
		</joint>
		<plugin filename="libcardsflow_gazebo_plugin.so" name="cardsflow_gazebo_plugin"/>
	</model>
</sdf>
