<robot name="roboy_icecream">
  <joint name="elbow_right" type="revolute">
    <parent link="arm_right_upper" />
    <child link="arm_right_lower" />
    <origin rpy="0  0  0" xyz="-0.00816 -0.00684 -0.30497" />
    <axis xyz="0.99863 -0.05074  0.01234" />
    <limit effort="0.0" lower="0.0" upper="0.0" velocity="0.0" />
  </joint>
  <joint name="hand_right_index_joint0" type="revolute">
    <parent link="arm_right_palm" />
    <child link="hand_right_index_link0" />
    <origin rpy="0  0  0" xyz="-0.03947 -0.06578 -0.09727" />
    <axis xyz="0.99272 -0.10801 -0.0532" />
    <limit effort="0.0" lower="0.0" upper="0.0" velocity="0.0" />
  </joint>
  <joint name="hand_right_middle_joint0" type="revolute">
    <parent link="arm_right_palm" />
    <child link="hand_right_middle_link0" />
    <origin rpy="0  0  0" xyz="-0.01152 -0.07229 -0.10272" />
    <axis xyz="0.99863 -0.05074  0.01234" />
    <limit effort="0.0" lower="0.0" upper="0.0" velocity="0.0" />
  </joint>
  <joint name="hand_right_ring_joint0" type="revolute">
    <parent link="arm_right_palm" />
    <child link="hand_right_ring_link0" />
    <origin rpy="0  0  0" xyz="0.01553 -0.06864 -0.09667" />
    <axis xyz="0.99694  0.00691  0.07778" />
    <limit effort="0.0" lower="0.0" upper="0.0" velocity="0.0" />
  </joint>
  <joint name="hand_right_little_joint0" type="revolute">
    <parent link="arm_right_palm" />
    <child link="hand_right_little_link0" />
    <origin rpy="0  0  0" xyz="0.03945 -0.06054 -0.08578" />
    <axis xyz="0.99228  0.04151  0.1168" />
    <limit effort="0.0" lower="0.0" upper="0.0" velocity="0.0" />
  </joint>
  <joint name="hand_right_thumb_joint0" type="revolute">
    <parent link="arm_right_palm" />
    <child link="hand_right_thumb_link0" />
    <origin rpy="0  0  0" xyz="-0.02237 -0.03474 -0.03349" />
    <axis xyz="0.02421  0.65934  0.75145" />
    <limit effort="0.0" lower="0.0" upper="0.0" velocity="0.0" />
  </joint>
  <joint name="hand_right_index_joint1" type="revolute">
    <parent link="hand_right_index_link0" />
    <child link="hand_right_index_link1" />
    <origin rpy="0  0  0" xyz="-0.00485 -0.02937 -0.03374" />
    <axis xyz="0.99272 -0.10801 -0.0532" />
    <limit effort="0.0" lower="0.0" upper="0.0" velocity="0.0" />
  </joint>
  <joint name="hand_right_index_joint2" type="revolute">
    <parent link="hand_right_index_link1" />
    <child link="hand_right_index_link2" />
    <origin rpy="0  0  0" xyz="-0.00294 -0.01695 -0.01948" />
    <axis xyz="0.99272 -0.10801 -0.0532" />
    <limit effort="0.0" lower="0.0" upper="0.0" velocity="0.0" />
  </joint>
  <joint name="hand_right_middle_joint1" type="revolute">
    <parent link="hand_right_middle_link0" />
    <child link="hand_right_middle_link1" />
    <origin rpy="0  0  0" xyz="-0.00094 -0.02967 -0.03381" />
    <axis xyz="0.99863 -0.05074  0.01234" />
    <limit effort="0.0" lower="0.0" upper="0.0" velocity="0.0" />
  </joint>
  <joint name="hand_right_middle_joint2" type="revolute">
    <parent link="hand_right_middle_link1" />
    <child link="hand_right_middle_link2" />
    <origin rpy="0  0  0" xyz="-0.00068 -0.01714 -0.01953" />
    <axis xyz="0.99863 -0.05074  0.01234" />
    <limit effort="0.0" lower="0.0" upper="0.0" velocity="0.0" />
  </joint>
  <joint name="hand_right_ring_joint1" type="revolute">
    <parent link="hand_right_ring_link0" />
    <child link="hand_right_ring_link1" />
    <origin rpy="0  0  0" xyz="0.00298 -0.02975 -0.03362" />
    <axis xyz="0.99694  0.00691  0.07778" />
    <limit effort="0.0" lower="0.0" upper="0.0" velocity="0.0" />
  </joint>
  <joint name="hand_right_ring_joint2" type="revolute">
    <parent link="hand_right_ring_link1" />
    <child link="hand_right_ring_link2" />
    <origin rpy="0  0  0" xyz="0.00158 -0.01719 -0.01943" />
    <axis xyz="0.99694  0.00691  0.07778" />
    <limit effort="0.0" lower="0.0" upper="0.0" velocity="0.0" />
  </joint>
  <joint name="hand_right_little_joint1" type="revolute">
    <parent link="hand_right_little_link0" />
    <child link="hand_right_little_link1" />
    <origin rpy="0  0  0" xyz="0.00313 -0.01715 -0.01928" />
    <axis xyz="0.99228  0.04151  0.1168" />
    <limit effort="0.0" lower="0.0" upper="0.0" velocity="0.0" />
  </joint>
  <joint name="hand_right_little_joint2" type="revolute">
    <parent link="hand_right_little_link1" />
    <child link="hand_right_little_link2" />
    <origin rpy="0  0  0" xyz="0.00294 -0.01716 -0.0193" />
    <axis xyz="0.99228  0.04151  0.1168" />
    <limit effort="0.0" lower="0.0" upper="0.0" velocity="0.0" />
  </joint>
  <joint name="hand_right_thumb_joint1" type="revolute">
    <parent link="hand_right_thumb_link0" />
    <child link="hand_right_thumb_link1" />
    <origin rpy="0  0  0" xyz="-0.04393 -0.00576 -0.01691" />
    <axis xyz="-0.04626 -0.75013  0.65966" />
    <limit effort="0.0" lower="0.0" upper="0.0" velocity="0.0" />
  </joint>
  <joint name="hand_right_thumb_joint2" type="revolute">
    <parent link="hand_right_thumb_link1" />
    <child link="hand_right_thumb_link2" />
    <origin rpy="0  0  0" xyz="-0.02596  0.00135 -0.00035" />
    <axis xyz="0.04626  0.75013 -0.65966" />
    <limit effort="0.0" lower="0.0" upper="0.0" velocity="0.0" />
  </joint>
  <joint name="elbow_left" type="revolute">
    <parent link="arm_left_upper" />
    <child link="arm_left_lower" />
    <origin rpy="0  0  0" xyz="0.00707 -0.00681 -0.30096" />
    <axis xyz="0.99863  0.05074 -0.01234" />
    <limit effort="0.0" lower="0.0" upper="0.0" velocity="0.0" />
  </joint>
  <joint name="hand_left_middle_joint0" type="revolute">
    <parent link="arm_left_palm" />
    <child link="hand_left_middle_link0" />
    <origin rpy="0  0  0" xyz="-0.02964  0.00901 -0.11157" />
    <axis xyz="-0.99386 -0.04855  0.09942" />
    <limit effort="0.0" lower="0.0" upper="0.0" velocity="0.0" />
  </joint>
  <joint name="hand_left_ring_joint0" type="revolute">
    <parent link="arm_left_palm" />
    <child link="hand_left_ring_link0" />
    <origin rpy="0  0  0" xyz="-0.00289  0.01018 -0.12037" />
    <axis xyz="0.99863  0.05074 -0.01234" />
    <limit effort="0.0" lower="0.0" upper="0.0" velocity="0.0" />
  </joint>
  <joint name="hand_left_little_joint0" type="revolute">
    <parent link="arm_left_palm" />
    <child link="hand_left_index_link0" />
    <origin rpy="0  0  0" xyz="0.02535  0.01177 -0.11388" />
    <axis xyz="-0.99581 -0.05254 -0.07483" />
    <limit effort="0.0" lower="0.0" upper="0.0" velocity="0.0" />
  </joint>
  <joint name="hand_left_index_joint0" type="revolute">
    <parent link="arm_left_palm" />
    <child link="hand_left_little_link0" />
    <origin rpy="0  0  0" xyz="-0.05299  0.00815 -0.09666" />
    <axis xyz="-0.98736 -0.04706  0.15134" />
    <limit effort="0.0" lower="0.0" upper="0.0" velocity="0.0" />
  </joint>
  <joint name="hand_left_thumb_joint0" type="revolute">
    <parent link="arm_left_palm" />
    <child link="hand_left_thumb_link0" />
    <origin rpy="0  0  0" xyz="0.02063 -0.00513 -0.05274" />
    <axis xyz="0.01118  0.0229   0.99967" />
    <limit effort="0.0" lower="0.0" upper="0.0" velocity="0.0" />
  </joint>
  <joint name="shoulder_left_axis0" type="revolute">
    <parent link="torso" />
    <child link="shoulder_left_link1" />
    <origin rpy="0  0  0" xyz="0.29189  0.01393  0.54489" />
    <axis xyz="1 0 0" />
    <limit effort="0.0" lower="-3.14159265359" upper="3.14159265359" velocity="0.0" />
  </joint>
  <joint name="shoulder_left_axis1" type="revolute">
    <parent link="shoulder_left_link1" />
    <child link="shoulder_left_link2" />
    <origin rpy="0  0  0" xyz="0  0  0" />
    <axis xyz="0 1 0" />
    <limit effort="0.0" lower="-3.14159265359" upper="3.14159265359" velocity="0.0" />
  </joint>
  <joint name="shoulder_left_axis2" type="revolute">
    <parent link="shoulder_left_link2" />
    <child link="arm_left_upper" />
    <origin rpy="0  0  0" xyz="0  0  0" />
    <axis xyz="1 0 0" />
    <limit effort="0.0" lower="-3.14159265359" upper="3.14159265359" velocity="0.0" />
  </joint>
  <joint name="hand_left_index_joint1" type="revolute">
    <parent link="hand_left_index_link0" />
    <child link="hand_left_index_link1" />
    <origin rpy="0  0  0" xyz="0.00336 -0.00083 -0.04486" />
    <axis xyz="0.99581  0.05254  0.07483" />
    <limit effort="0.0" lower="0.0" upper="0.0" velocity="0.0" />
  </joint>
  <joint name="hand_left_index_joint2" type="revolute">
    <parent link="hand_left_index_link1" />
    <child link="hand_left_index_link2" />
    <origin rpy="0  0  0" xyz="0.00192 -0.00048 -0.02592" />
    <axis xyz="0.99581  0.05254  0.07483" />
    <limit effort="0.0" lower="0.0" upper="0.0" velocity="0.0" />
  </joint>
  <joint name="hand_left_thumb_joint1" type="revolute">
    <parent link="hand_left_thumb_link0" />
    <child link="hand_left_thumb_link1" />
    <origin rpy="0  0  0" xyz="0.04388 -0.00276 -0.009" />
    <axis xyz="-0.05101  0.99844 -0.02231" />
    <limit effort="0.0" lower="0.0" upper="0.0" velocity="0.0" />
  </joint>
  <joint name="hand_left_thumb_joint2" type="revolute">
    <parent link="hand_left_thumb_link1" />
    <child link="hand_left_thumb_link2" />
    <origin rpy="0  0  0" xyz="0.02596  0.00126 -0.00032" />
    <axis xyz="0.05101 -0.99844  0.02231" />
    <limit effort="0.0" lower="0.0" upper="0.0" velocity="0.0" />
  </joint>
  <joint name="hand_left_middle_joint1" type="revolute">
    <parent link="hand_left_middle_link0" />
    <child link="hand_left_middle_link1" />
    <origin rpy="0  0  0" xyz="-0.00446 -0.00122 -0.04476" />
    <axis xyz="0.99386  0.04855 -0.09942" />
    <limit effort="0.0" lower="0.0" upper="0.0" velocity="0.0" />
  </joint>
  <joint name="hand_left_middle_joint2" type="revolute">
    <parent link="hand_left_middle_link1" />
    <child link="hand_left_middle_link2" />
    <origin rpy="0  0  0" xyz="-0.0026  -0.00071 -0.02586" />
    <axis xyz="0.99386  0.04855 -0.09942" />
    <limit effort="0.0" lower="0.0" upper="0.0" velocity="0.0" />
  </joint>
  <joint name="hand_left_little_joint1" type="revolute">
    <parent link="hand_left_little_link0" />
    <child link="hand_left_little_link1" />
    <origin rpy="0  0  0" xyz="-4.78000000e-03  -1.00000000e-05  -2.55800000e-02" />
    <axis xyz="0.98736  0.04706 -0.15134" />
    <limit effort="0.0" lower="0.0" upper="0.0" velocity="0.0" />
  </joint>
  <joint name="hand_left_little_joint2" type="revolute">
    <parent link="hand_left_little_link1" />
    <child link="hand_left_little_link2" />
    <origin rpy="0  0  0" xyz="-0.00395 -0.00077 -0.02568" />
    <axis xyz="0.98736  0.04706 -0.15134" />
    <limit effort="0.0" lower="0.0" upper="0.0" velocity="0.0" />
  </joint>
  <joint name="hand_left_ring_joint1" type="revolute">
    <parent link="hand_left_ring_link0" />
    <child link="hand_left_ring_link1" />
    <origin rpy="0  0  0" xyz="-0.00055 -0.00103 -0.04498" />
    <axis xyz="0.99863  0.05074 -0.01234" />
    <limit effort="0.0" lower="0.0" upper="0.0" velocity="0.0" />
  </joint>
  <joint name="hand_left_ring_joint2" type="revolute">
    <parent link="hand_left_ring_link1" />
    <child link="hand_left_ring_link2" />
    <origin rpy="0  0  0" xyz="-0.00034 -0.00059 -0.02599" />
    <axis xyz="0.99863  0.05074 -0.01234" />
    <limit effort="0.0" lower="0.0" upper="0.0" velocity="0.0" />
  </joint>
  <joint name="shoulder_right_axis0" type="revolute">
    <parent link="torso" />
    <child link="shoulder_right_link1" />
    <origin rpy="0  0  0" xyz="-0.29317  0.00923  0.5481" />
    <axis xyz="1 0 0" />
    <limit effort="0.0" lower="-3.14159265359" upper="3.14159265359" velocity="0.0" />
  </joint>
  <joint name="shoulder_right_axis1" type="revolute">
    <parent link="shoulder_right_link1" />
    <child link="shoulder_right_link2" />
    <origin rpy="0  0  0" xyz="0  0  0" />
    <axis xyz="0 1 0" />
    <limit effort="0.0" lower="-3.14159265359" upper="3.14159265359" velocity="0.0" />
  </joint>
  <joint name="shoulder_right_axis2" type="revolute">
    <parent link="shoulder_right_link2" />
    <child link="arm_right_upper" />
    <origin rpy="0  0  0" xyz="0  0  0" />
    <axis xyz="1 0 0" />
    <limit effort="0.0" lower="-3.14159265359" upper="3.14159265359" velocity="0.0" />
  </joint>
  <joint name="zed_camera_mount" type="revolute">
    <parent link="head" />
    <child link="zed_camera" />
    <origin rpy="0  0  0" xyz="0.02168 -0.05805  0.21956" />
    <axis xyz="0  0  0" />
    <limit effort="0" lower="0" upper="0" velocity="0" />
  </joint>
  <joint name="wrist_left_axis0" type="revolute">
    <parent link="arm_left_lower" />
    <child link="wrist_left_link1" />
    <origin rpy="0  0  0" xyz="-0.01364 -0.00601 -0.23778" />
    <axis xyz="-0.05101  0.99844 -0.02231" />
    <limit effort="0.0" lower="-3.14159265359" upper="3.14159265359" velocity="0.0" />
  </joint>
  <joint name="wrist_left_axis1" type="revolute">
    <parent link="wrist_left_link1" />
    <child link="wrist_left_link2" />
    <origin rpy="0  0  0" xyz="0  0  0" />
    <axis xyz="0.99863  0.05074 -0.01234" />
    <limit effort="0.0" lower="-3.14159265359" upper="3.14159265359" velocity="0.0" />
  </joint>
  <joint name="wrist_left_axis2" type="revolute">
    <parent link="wrist_left_link2" />
    <child link="arm_left_palm" />
    <origin rpy="0  0  0" xyz="0  0  0" />
    <axis xyz="-0.01118 -0.0229  -0.99967" />
    <limit effort="0.0" lower="-3.14159265359" upper="3.14159265359" velocity="0.0" />
  </joint>
  <joint name="wrist_right_axis0" type="revolute">
    <parent link="arm_right_lower" />
    <child link="wrist_right_link1" />
    <origin rpy="0  0  0" xyz="0.00534 -0.15418 -0.17495" />
    <axis xyz="0.99863 -0.05074  0.01234" />
    <limit effort="0.0" lower="-3.14159265359" upper="3.14159265359" velocity="0.0" />
  </joint>
  <joint name="wrist_right_axis1" type="revolute">
    <parent link="wrist_right_link1" />
    <child link="wrist_right_link2" />
    <origin rpy="0  0  0" xyz="0  0  0" />
    <axis xyz="-0.04626 -0.75013  0.65966" />
    <limit effort="0.0" lower="-3.14159265359" upper="3.14159265359" velocity="0.0" />
  </joint>
  <joint name="wrist_right_axis2" type="revolute">
    <parent link="wrist_right_link2" />
    <child link="arm_right_palm" />
    <origin rpy="0  0  0" xyz="0  0  0" />
    <axis xyz="-0.02421 -0.65934 -0.75145" />
    <limit effort="0.0" lower="-3.14159265359" upper="3.14159265359" velocity="0.0" />
  </joint>
  <joint name="neck_axis0" type="revolute">
    <parent link="torso" />
    <child link="neck_link1" />
    <origin rpy="0  0  0" xyz="0       0.00152  0.71567" />
    <axis xyz="0.12498 -0.99215  0" />
    <limit effort="0.0" lower="-0.523598775598" upper="0.523598775598" velocity="0.0" />
  </joint>
  <joint name="neck_axis2" type="revolute">
    <parent link="neck_link2" />
    <child link="head" />
    <origin rpy="0  0  0" xyz="0  0  0" />
    <axis xyz="0  0  1" />
    <limit effort="0.0" lower="-0.523598775598" upper="0.523598775598" velocity="0.0" />
  </joint>
  <joint name="neck_axis1" type="revolute">
    <parent link="neck_link1" />
    <child link="neck_link2" />
    <origin rpy="0  0  0" xyz="0  0  0" />
    <axis xyz="-0.99215 -0.12498  0" />
    <limit effort="0.0" lower="-0.523598775598" upper="0.523598775598" velocity="0.0" />
  </joint>
  <joint name="zed_camera_right" type="revolute">
    <parent link="zed_camera" />
    <child link="zed_camera_right_lense" />
    <origin rpy="0  0  0" xyz="-0.08149 -0.00191 -0.00782" />
    <axis xyz="0  0  0" />
    <limit effort="0" lower="0" upper="0" velocity="0" />
  </joint>
  <joint name="zed_camera_left" type="revolute">
    <parent link="zed_camera" />
    <child link="zed_camera_left_lense" />
    <origin rpy="0  0  0" xyz="0.03848 -0.00154 -0.00782" />
    <axis xyz="0  0  0" />
    <limit effort="0" lower="0" upper="0" velocity="0" />
  </joint>
  <joint name="joint_foot_left" type="revolute">
    <parent link="leg_left" />
    <child link="foot_left" />
    <origin rpy="0  0  0" xyz="-0.0244  0     -0.366" />
    <axis xyz="-1  0  0" />
    <limit effort="0.0" lower="-3.14159265359" upper="3.14159265359" velocity="0.0" />
  </joint>
  <joint name="joint_foot_left_tip" type="revolute">
    <parent link="foot_left" />
    <child link="foot_left_tip" />
    <origin rpy="0  0  0" xyz="0.024   -0.0623  -0.03622" />
    <axis xyz="0  0  0" />
    <limit effort="0" lower="0" upper="0" velocity="0" />
  </joint>
  <joint name="joint_foot_right" type="revolute">
    <parent link="leg_right" />
    <child link="foot_right" />
    <origin rpy="0  0  0" xyz="-0.026  0    -0.366" />
    <axis xyz="-1  0  0" />
    <limit effort="0.0" lower="-3.14159265359" upper="3.14159265359" velocity="0.0" />
  </joint>
  <joint name="joint_foot_right_tip" type="revolute">
    <parent link="foot_right" />
    <child link="foot_right_tip" />
    <origin rpy="0  0  0" xyz="0.024 -0.063 -0.035" />
    <axis xyz="0  0  0" />
    <limit effort="0" lower="0" upper="0" velocity="0" />
  </joint>
  <joint name="hip_right_axis0" type="revolute">
    <parent link="torso" />
    <child link="hip_right_tendon_guide" />
    <origin rpy="0  0  0" xyz="-0.1718   0.00152 -0.14299" />
    <axis xyz="-1  0  0" />
    <limit effort="0.0" lower="0.0" upper="0.0" velocity="0.0" />
  </joint>
  <joint name="hip_right_axis1" type="revolute">
    <parent link="hip_right_tendon_guide" />
    <child link="thigh_right" />
    <origin rpy="0  0  0" xyz="0.0001  -0.02828 -0.02828" />
    <axis xyz="1  0  0" />
    <limit effort="0.0" lower="0.0" upper="0.0" velocity="0.0" />
  </joint>
  <joint name="hip_left_axis0" type="revolute">
    <parent link="torso" />
    <child link="hip_left_tendon_guide" />
    <origin rpy="0  0  0" xyz="0.1757   0.00152 -0.14299" />
    <axis xyz="-1  0  0" />
    <limit effort="0.0" lower="0.0" upper="0.0" velocity="0.0" />
  </joint>
  <joint name="hip_left_axis1" type="revolute">
    <parent link="hip_left_tendon_guide" />
    <child link="thigh_left" />
    <origin rpy="0  0  0" xyz="0.0004  -0.02828 -0.02828" />
    <axis xyz="1  0  0" />
    <limit effort="0.0" lower="0.0" upper="0.0" velocity="0.0" />
  </joint>
  <joint name="knee_left_axis0" type="revolute">
    <parent link="thigh_left" />
    <child link="knee_left_tendon_guide" />
    <origin rpy="0  0  0" xyz="-2.90000000e-04  -3.10000000e-01   0.00000000e+00" />
    <axis xyz="-1  0  0" />
    <limit effort="0.0" lower="0.0" upper="0.0" velocity="0.0" />
  </joint>
  <joint name="knee_left_axis1" type="revolute">
    <parent link="knee_left_tendon_guide" />
    <child link="leg_left" />
    <origin rpy="0  0  0" xyz="0.0039  -0.02828 -0.02828" />
    <axis xyz="1  0  0" />
    <limit effort="0.0" lower="0.0" upper="0.0" velocity="0.0" />
  </joint>
  <joint name="knee_right_axis0" type="revolute">
    <parent link="thigh_right" />
    <child link="knee_right_tendon_guide" />
    <origin rpy="0  0  0" xyz="0.0058 -0.31    0" />
    <axis xyz="1  0  0" />
    <limit effort="0.0" lower="0.0" upper="0.0" velocity="0.0" />
  </joint>
  <joint name="knee_right_axis1" type="revolute">
    <parent link="knee_right_tendon_guide" />
    <child link="leg_right" />
    <origin rpy="0  0  0" xyz="-0.0004  -0.02828 -0.02828" />
    <axis xyz="-1  0  0" />
    <limit effort="0.0" lower="0.0" upper="0.0" velocity="0.0" />
  </joint>
  <link name="head">
    <inertial>
      <mass value="2.049574035129589" />
      <origin rpy="0  0  0" xyz="0.00051  0.04492  0.14549" />
      <inertia ixx="1.5567369122227759" ixy="-6.313507101682236e-05" ixz="-0.0010119595995300493" iyy="1.5459780882221161" iyz="-0.08466584811454989" izz="0.0305276597273415" />
    </inertial>
    <collision name="head_collision">
      <origin rpy="0  0  0" xyz="0.00051  0.04492  0.14549" />
      <geometry>
        <mesh filename="package://robots/roboy_icecream/meshes/collisions/head.stl" scale="0.001 0.001 0.001" />
      </geometry>
    </collision>
    <visual name="head_visual">
      <origin rpy="0  0  0" xyz="0.00051  0.04492  0.14549" />
      <geometry>
        <mesh filename="package://robots/roboy_icecream/meshes/visuals/head.stl" scale="0.001 0.001 0.001" />
      </geometry>
    </visual>
  </link>
  <link name="arm_right_palm">
    <inertial>
      <mass value="0.8274574519860363" />
      <origin rpy="0  0  0" xyz="-0.00054 -0.03184 -0.0531" />
      <inertia ixx="0.028944754959120526" ixy="-0.04506388478325301" ixz="0.0036627336647303437" iyy="0.07406789126962156" iyz="0.001949434715555099" izz="0.10150769936534196" />
    </inertial>
    <collision name="arm_right_palm_collision">
      <origin rpy="0  0  0" xyz="-0.00054 -0.03184 -0.0531" />
      <geometry>
        <mesh filename="package://robots/roboy_icecream/meshes/collisions/arm_right_palm.stl" scale="0.001 0.001 0.001" />
      </geometry>
    </collision>
    <visual name="arm_right_palm_visual">
      <origin rpy="0  0  0" xyz="-0.00054 -0.03184 -0.0531" />
      <geometry>
        <mesh filename="package://robots/roboy_icecream/meshes/visuals/arm_right_palm.stl" scale="0.001 0.001 0.001" />
      </geometry>
    </visual>
  </link>
  <link name="arm_left_palm">
    <inertial>
      <mass value="0.8274415425908241" />
      <origin rpy="0  0  0" xyz="-0.00161  0.00979 -0.05638" />
      <inertia ixx="0.0030211242146956" ixy="-0.0025792388927827208" ixz="0.011813541875318582" iyy="0.07000952471148557" iyz="0.0005300733988418556" izz="0.067316807270155" />
    </inertial>
    <collision name="arm_left_palm_collision">
      <origin rpy="0  0  0" xyz="-0.00161  0.00979 -0.05638" />
      <geometry>
        <mesh filename="package://robots/roboy_icecream/meshes/collisions/arm_left_palm.stl" scale="0.001 0.001 0.001" />
      </geometry>
    </collision>
    <visual name="arm_left_palm_visual">
      <origin rpy="0  0  0" xyz="-0.00161  0.00979 -0.05638" />
      <geometry>
        <mesh filename="package://robots/roboy_icecream/meshes/visuals/arm_left_palm.stl" scale="0.001 0.001 0.001" />
      </geometry>
    </visual>
  </link>
  <link name="arm_left_lower">
    <inertial>
      <mass value="7.2740122404446215" />
      <origin rpy="0  0  0" xyz="-0.01252 -0.00339 -0.13609" />
      <inertia ixx="0.12037113083481145" ixy="-0.007777455090088065" ixz="-0.22500454055734478" iyy="0.7170688743333976" iyz="-0.003963613614425154" izz="0.6029257602858726" />
    </inertial>
    <collision name="arm_left_lower_collision">
      <origin rpy="0  0  0" xyz="-0.01252 -0.00339 -0.13609" />
      <geometry>
        <mesh filename="package://robots/roboy_icecream/meshes/collisions/arm_left_lower.stl" scale="0.001 0.001 0.001" />
      </geometry>
    </collision>
    <visual name="arm_left_lower_visual">
      <origin rpy="0  0  0" xyz="-0.01252 -0.00339 -0.13609" />
      <geometry>
        <mesh filename="package://robots/roboy_icecream/meshes/visuals/arm_left_lower.stl" scale="0.001 0.001 0.001" />
      </geometry>
    </visual>
  </link>
  <link name="arm_right_lower">
    <inertial>
      <mass value="7.274015985787583" />
      <origin rpy="0  0  0" xyz="0.0077  -0.09006 -0.10231" />
      <inertia ixx="0.23556400818655904" ixy="-0.18777310085978346" ixz="0.30022020480282985" iyy="0.7936530603445563" iyz="0.07517064245307571" izz="0.7022304777078652" />
    </inertial>
    <collision name="arm_right_lower_collision">
      <origin rpy="0  0  0" xyz="0.0077  -0.09006 -0.10231" />
      <geometry>
        <mesh filename="package://robots/roboy_icecream/meshes/collisions/arm_right_lower.stl" scale="0.001 0.001 0.001" />
      </geometry>
    </collision>
    <visual name="arm_right_lower_visual">
      <origin rpy="0  0  0" xyz="0.0077  -0.09006 -0.10231" />
      <geometry>
        <mesh filename="package://robots/roboy_icecream/meshes/visuals/arm_right_lower.stl" scale="0.001 0.001 0.001" />
      </geometry>
    </visual>
  </link>
  <link name="torso">
    <inertial>
      <mass value="25.25525236846473" />
      <origin rpy="0  0  0" xyz="0.00119  0.0005   0.23644" />
      <inertia ixx="3.261438455736942" ixy="-0.0009569092580773052" ixz="0.0009571519581312355" iyy="3.7687825445335514" iyz="0.012688766188417125" izz="0.6431742227674527" />
    </inertial>
    <collision name="torso_collision">
      <origin rpy="0  0  0" xyz="0.00119  0.0005   0.23644" />
      <geometry>
        <mesh filename="package://robots/roboy_icecream/meshes/collisions/torso.stl" scale="0.001 0.001 0.001" />
      </geometry>
    </collision>
    <visual name="torso_visual">
      <origin rpy="0  0  0" xyz="0.00119  0.0005   0.23644" />
      <geometry>
        <mesh filename="package://robots/roboy_icecream/meshes/visuals/torso.stl" scale="0.001 0.001 0.001" />
      </geometry>
    </visual>
  </link>
  <link name="leg_left">
    <inertial>
      <mass value="5.306908605335246" />
      <origin rpy="0  0  0" xyz="0.0247   0      -0.17741" />
      <inertia ixx="1.4958514962952234" ixy="0.39626126461968625" ixz="0.4040719772021063" iyy="1.007934683000551" iyz="-0.7304668669744697" izz="0.9402349967104962" />
    </inertial>
    <collision name="leg_left_collision">
      <origin rpy="0  0  0" xyz="0.0247   0      -0.17741" />
      <geometry>
        <mesh filename="package://robots/roboy_icecream/meshes/collisions/leg_left.stl" scale="0.001 0.001 0.001" />
      </geometry>
    </collision>
    <visual name="leg_left_visual">
      <origin rpy="0  0  0" xyz="0.0247   0      -0.17741" />
      <geometry>
        <mesh filename="package://robots/roboy_icecream/meshes/visuals/leg_left.stl" scale="0.001 0.001 0.001" />
      </geometry>
    </visual>
  </link>
  <link name="leg_right">
    <inertial>
      <mass value="5.307143647531778" />
      <origin rpy="0  0  0" xyz="-0.02811  0      -0.17741" />
      <inertia ixx="1.4959067826097436" ixy="-0.376381226304725" ixz="-0.3840964982466324" iyy="0.9868335594143278" iyz="-0.7302141353671603" izz="0.9191322833570325" />
    </inertial>
    <collision name="leg_right_collision">
      <origin rpy="0  0  0" xyz="-0.02811  0      -0.17741" />
      <geometry>
        <mesh filename="package://robots/roboy_icecream/meshes/collisions/leg_right.stl" scale="0.001 0.001 0.001" />
      </geometry>
    </collision>
    <visual name="leg_right_visual">
      <origin rpy="0  0  0" xyz="-0.02811  0      -0.17741" />
      <geometry>
        <mesh filename="package://robots/roboy_icecream/meshes/visuals/leg_right.stl" scale="0.001 0.001 0.001" />
      </geometry>
    </visual>
  </link>
  <link name="thigh_right">
    <inertial>
      <mass value="4.868895609721555" />
      <origin rpy="0  0  0" xyz="-0.025   -0.11647  0" />
      <inertia ixx="0.26287716971675307" ixy="-0.1339443795773639" ixz="-0.16432108177873003" iyy="0.34212124237365166" iyz="-0.11958770332972476" izz="0.3056754037294872" />
    </inertial>
    <collision name="thigh_right_collision">
      <origin rpy="0  0  0" xyz="-0.025   -0.11647  0" />
      <geometry>
        <mesh filename="package://robots/roboy_icecream/meshes/collisions/thigh_right.stl" scale="0.001 0.001 0.001" />
      </geometry>
    </collision>
    <visual name="thigh_right_visual">
      <origin rpy="0  0  0" xyz="-0.025   -0.11647  0" />
      <geometry>
        <mesh filename="package://robots/roboy_icecream/meshes/visuals/thigh_right.stl" scale="0.001 0.001 0.001" />
      </geometry>
    </visual>
  </link>
  <link name="thigh_left">
    <inertial>
      <mass value="4.8688957108641855" />
      <origin rpy="0  0  0" xyz="0.03051 -0.11647  0" />
      <inertia ixx="0.2628774035237147" ixy="0.14083610318444495" ixz="0.17203256927961605" iyy="0.3615745898532772" iyz="-0.11930747101919766" izz="0.32512853942534875" />
    </inertial>
    <collision name="thigh_left_collision">
      <origin rpy="0  0  0" xyz="0.03051 -0.11647  0" />
      <geometry>
        <mesh filename="package://robots/roboy_icecream/meshes/collisions/thigh_left.stl" scale="0.001 0.001 0.001" />
      </geometry>
    </collision>
    <visual name="thigh_left_visual">
      <origin rpy="0  0  0" xyz="0.03051 -0.11647  0" />
      <geometry>
        <mesh filename="package://robots/roboy_icecream/meshes/visuals/thigh_left.stl" scale="0.001 0.001 0.001" />
      </geometry>
    </visual>
  </link>
  <link name="arm_left_upper">
    <inertial>
      <mass value="3.6100762893022953" />
      <origin rpy="0  0  0" xyz="-0.00197 -0.00274 -0.1915" />
      <inertia ixx="0.4825839634550129" ixy="-0.011756431561699959" ixz="-0.37037302183595333" iyy="0.7861877702121866" iyz="-0.014684589432237364" izz="0.3063486825603662" />
    </inertial>
    <collision name="arm_left_upper_collision">
      <origin rpy="0  0  0" xyz="-0.00197 -0.00274 -0.1915" />
      <geometry>
        <mesh filename="package://robots/roboy_icecream/meshes/collisions/arm_left_upper.stl" scale="0.001 0.001 0.001" />
      </geometry>
    </collision>
    <visual name="arm_left_upper_visual">
      <origin rpy="0  0  0" xyz="-0.00197 -0.00274 -0.1915" />
      <geometry>
        <mesh filename="package://robots/roboy_icecream/meshes/visuals/arm_left_upper.stl" scale="0.001 0.001 0.001" />
      </geometry>
    </visual>
  </link>
  <link name="arm_right_upper">
    <inertial>
      <mass value="3.61005569877743" />
      <origin rpy="0  0  0" xyz="0.00214 -0.00274 -0.19142" />
      <inertia ixx="0.49280050851573554" ixy="0.006849875206860319" ixz="0.3750667834303389" iyy="0.7990348130585907" iyz="-0.008787984096762295" izz="0.30837886787606134" />
    </inertial>
    <collision name="arm_right_upper_collision">
      <origin rpy="0  0  0" xyz="0.00214 -0.00274 -0.19142" />
      <geometry>
        <mesh filename="package://robots/roboy_icecream/meshes/collisions/arm_right_upper.stl" scale="0.001 0.001 0.001" />
      </geometry>
    </collision>
    <visual name="arm_right_upper_visual">
      <origin rpy="0  0  0" xyz="0.00214 -0.00274 -0.19142" />
      <geometry>
        <mesh filename="package://robots/roboy_icecream/meshes/visuals/arm_right_upper.stl" scale="0.001 0.001 0.001" />
      </geometry>
    </visual>
  </link>
  <link name="shoulder_left_link1">
    <inertial>
      <mass value="0.09036188404972213" />
      <origin rpy="0  0  0" xyz="0  0  0" />
      <inertia ixx="0.02685378687433705" ixy="-0.0003675942095744657" ixz="-0.014372126974416378" iyy="0.03453525279236316" iyz="-0.0006862058794001957" izz="0.007723659313970099" />
    </inertial>
    <collision name="shoulder_left_link1_collision">
      <origin rpy="0  0  0" xyz="0  0  0" />
      <geometry>
        <mesh filename="package://robots/roboy_icecream/meshes/collisions/shoulder_left_link1.stl" scale="0.001 0.001 0.001" />
      </geometry>
    </collision>
    <visual name="shoulder_left_link1_visual">
      <origin rpy="0  0  0" xyz="0  0  0" />
      <geometry>
        <mesh filename="package://robots/roboy_icecream/meshes/visuals/shoulder_left_link1.stl" scale="0.001 0.001 0.001" />
      </geometry>
    </visual>
  </link>
  <link name="shoulder_left_link2">
    <inertial>
      <mass value="0.0071131701088449385" />
      <origin rpy="0  0  0" xyz="0  0  0" />
      <inertia ixx="0.0021134396605301123" ixy="-2.8936797892138277e-05" ixz="-0.0011313551510287823" iyy="0.0027181145964377414" iyz="-5.401772354686376e-05" izz="0.0006075407028130095" />
    </inertial>
    <collision name="shoulder_left_link2_collision">
      <origin rpy="0  0  0" xyz="0  0  0" />
      <geometry>
        <mesh filename="package://robots/roboy_icecream/meshes/collisions/shoulder_left_link2.stl" scale="0.001 0.001 0.001" />
      </geometry>
    </collision>
    <visual name="shoulder_left_link2_visual">
      <origin rpy="0  0  0" xyz="0  0  0" />
      <geometry>
        <mesh filename="package://robots/roboy_icecream/meshes/visuals/shoulder_left_link2.stl" scale="0.001 0.001 0.001" />
      </geometry>
    </visual>
  </link>
  <link name="hand_left_index_link1">
    <inertial>
      <mass value="0.03081999399001323" />
      <origin rpy="0  0  0" xyz="0.00585 -0.00166 -0.01324" />
      <inertia ixx="0.0008529955661754427" ixy="-0.00010242073660686651" ixz="0.001635194911902723" iyy="0.004003788547791524" iyz="5.3103529837074764e-05" izz="0.0031582607279420413" />
    </inertial>
    <collision name="hand_left_index_link1_collision">
      <origin rpy="0  0  0" xyz="0.00585 -0.00166 -0.01324" />
      <geometry>
        <mesh filename="package://robots/roboy_icecream/meshes/collisions/hand_left_index_link1.stl" scale="0.001 0.001 0.001" />
      </geometry>
    </collision>
    <visual name="hand_left_index_link1_visual">
      <origin rpy="0  0  0" xyz="0.00585 -0.00166 -0.01324" />
      <geometry>
        <mesh filename="package://robots/roboy_icecream/meshes/visuals/hand_left_index_link1.stl" scale="0.001 0.001 0.001" />
      </geometry>
    </visual>
  </link>
  <link name="hand_left_index_link0">
    <inertial>
      <mass value="0.055846781261061205" />
      <origin rpy="0  0  0" xyz="0.0066  -0.00255 -0.02268" />
      <inertia ixx="0.0009657959159058646" ixy="-0.0001830636209412824" ixz="0.002311738865877808" iyy="0.006582207879564719" iyz="7.518259271502304e-05" izz="0.005629871962983775" />
    </inertial>
    <collision name="hand_left_index_link0_collision">
      <origin rpy="0  0  0" xyz="0.0066  -0.00255 -0.02268" />
      <geometry>
        <mesh filename="package://robots/roboy_icecream/meshes/collisions/hand_left_index_link0.stl" scale="0.001 0.001 0.001" />
      </geometry>
    </collision>
    <visual name="hand_left_index_link0_visual">
      <origin rpy="0  0  0" xyz="0.0066  -0.00255 -0.02268" />
      <geometry>
        <mesh filename="package://robots/roboy_icecream/meshes/visuals/hand_left_index_link0.stl" scale="0.001 0.001 0.001" />
      </geometry>
    </visual>
  </link>
  <link name="hand_left_index_link2">
    <inertial>
      <mass value="0.030336880161010958" />
      <origin rpy="0  0  0" xyz="0.00577 -0.00121 -0.01249" />
      <inertia ixx="0.0011119122895000154" ixy="-0.00010104616475891981" ixz="0.001864620937874951" iyy="0.004249244721721791" iyz="5.991141864306283e-05" izz="0.0031445994588523885" />
    </inertial>
    <collision name="hand_left_index_link2_collision">
      <origin rpy="0  0  0" xyz="0.00577 -0.00121 -0.01249" />
      <geometry>
        <mesh filename="package://robots/roboy_icecream/meshes/collisions/hand_left_index_link2.stl" scale="0.001 0.001 0.001" />
      </geometry>
    </collision>
    <visual name="hand_left_index_link2_visual">
      <origin rpy="0  0  0" xyz="0.00577 -0.00121 -0.01249" />
      <geometry>
        <mesh filename="package://robots/roboy_icecream/meshes/visuals/hand_left_index_link2.stl" scale="0.001 0.001 0.001" />
      </geometry>
    </visual>
  </link>
  <link name="hand_left_middle_link1">
    <inertial>
      <mass value="0.03082014849979441" />
      <origin rpy="0  0  0" xyz="0.00346 -0.0018  -0.01404" />
      <inertia ixx="0.0008347235881121535" ixy="-5.5673992561349775e-05" ixz="0.0012889822675614148" iyy="0.002832453821565424" iyz="3.589660701065682e-05" izz="0.0020016469714842153" />
    </inertial>
    <collision name="hand_left_middle_link1_collision">
      <origin rpy="0  0  0" xyz="0.00346 -0.0018  -0.01404" />
      <geometry>
        <mesh filename="package://robots/roboy_icecream/meshes/collisions/hand_left_middle_link1.stl" scale="0.001 0.001 0.001" />
      </geometry>
    </collision>
    <visual name="hand_left_middle_link1_visual">
      <origin rpy="0  0  0" xyz="0.00346 -0.0018  -0.01404" />
      <geometry>
        <mesh filename="package://robots/roboy_icecream/meshes/visuals/hand_left_middle_link1.stl" scale="0.001 0.001 0.001" />
      </geometry>
    </visual>
  </link>
  <link name="hand_left_middle_link0">
    <inertial>
      <mass value="0.0558465981006835" />
      <origin rpy="0  0  0" xyz="0.00256 -0.00277 -0.02346" />
      <inertia ixx="0.0009405620790881097" ixy="-0.00010601760855411946" ixz="0.001858184815701468" iyy="0.00466246726626394" iyz="5.2762933833103056e-05" izz="0.0037294804570108383" />
    </inertial>
    <collision name="hand_left_middle_link0_collision">
      <origin rpy="0  0  0" xyz="0.00256 -0.00277 -0.02346" />
      <geometry>
        <mesh filename="package://robots/roboy_icecream/meshes/collisions/hand_left_middle_link0.stl" scale="0.001 0.001 0.001" />
      </geometry>
    </collision>
    <visual name="hand_left_middle_link0_visual">
      <origin rpy="0  0  0" xyz="0.00256 -0.00277 -0.02346" />
      <geometry>
        <mesh filename="package://robots/roboy_icecream/meshes/visuals/hand_left_middle_link0.stl" scale="0.001 0.001 0.001" />
      </geometry>
    </visual>
  </link>
  <link name="hand_left_middle_link2">
    <inertial>
      <mass value="0.030336901843144165" />
      <origin rpy="0  0  0" xyz="0.00351 -0.00135 -0.01329" />
      <inertia ixx="0.0010906408506466366" ixy="-5.228526379838738e-05" ixz="0.0014482329806854454" iyy="0.0030179451258381586" iyz="3.916555852949865e-05" izz="0.0019309051615765435" />
    </inertial>
    <collision name="hand_left_middle_link2_collision">
      <origin rpy="0  0  0" xyz="0.00351 -0.00135 -0.01329" />
      <geometry>
        <mesh filename="package://robots/roboy_icecream/meshes/collisions/hand_left_middle_link2.stl" scale="0.001 0.001 0.001" />
      </geometry>
    </collision>
    <visual name="hand_left_middle_link2_visual">
      <origin rpy="0  0  0" xyz="0.00351 -0.00135 -0.01329" />
      <geometry>
        <mesh filename="package://robots/roboy_icecream/meshes/visuals/hand_left_middle_link2.stl" scale="0.001 0.001 0.001" />
      </geometry>
    </visual>
  </link>
  <link name="hand_left_ring_link1">
    <inertial>
      <mass value="0.03082008411770575" />
      <origin rpy="0  0  0" xyz="0.00467 -0.00173 -0.01369" />
      <inertia ixx="0.0009256324899164542" ixy="-7.530911722964287e-05" ixz="0.0015270552420065505" iyy="0.0034543385276265513" iyz="4.544181289362746e-05" izz="0.00253400381473524" />
    </inertial>
    <collision name="hand_left_ring_link1_collision">
      <origin rpy="0  0  0" xyz="0.00467 -0.00173 -0.01369" />
      <geometry>
        <mesh filename="package://robots/roboy_icecream/meshes/collisions/hand_left_ring_link1.stl" scale="0.001 0.001 0.001" />
      </geometry>
    </collision>
    <visual name="hand_left_ring_link1_visual">
      <origin rpy="0  0  0" xyz="0.00467 -0.00173 -0.01369" />
      <geometry>
        <mesh filename="package://robots/roboy_icecream/meshes/visuals/hand_left_ring_link1.stl" scale="0.001 0.001 0.001" />
      </geometry>
    </visual>
  </link>
  <link name="hand_left_ring_link0">
    <inertial>
      <mass value="0.05584669978299005" />
      <origin rpy="0  0  0" xyz="0.0046  -0.00266 -0.02316" />
      <inertia ixx="0.0010682574340430899" ixy="-0.00013834793804779803" ixz="0.0022023992315908375" iyy="0.005665523834499811" iyz="6.611328545601585e-05" izz="0.004607125225278142" />
    </inertial>
    <collision name="hand_left_ring_link0_collision">
      <origin rpy="0  0  0" xyz="0.0046  -0.00266 -0.02316" />
      <geometry>
        <mesh filename="package://robots/roboy_icecream/meshes/collisions/hand_left_ring_link0.stl" scale="0.001 0.001 0.001" />
      </geometry>
    </collision>
    <visual name="hand_left_ring_link0_visual">
      <origin rpy="0  0  0" xyz="0.0046  -0.00266 -0.02316" />
      <geometry>
        <mesh filename="package://robots/roboy_icecream/meshes/visuals/hand_left_ring_link0.stl" scale="0.001 0.001 0.001" />
      </geometry>
    </visual>
  </link>
  <link name="hand_left_ring_link2">
    <inertial>
      <mass value="0.030336893727523316" />
      <origin rpy="0  0  0" xyz="0.00466 -0.00128 -0.01294" />
      <inertia ixx="0.001194918317406741" ixy="-7.27444900577493e-05" ixz="0.0017204695406271844" iyy="0.0036779062062114757" iyz="5.027399310360077e-05" izz="0.00248801208746307" />
    </inertial>
    <collision name="hand_left_ring_link2_collision">
      <origin rpy="0  0  0" xyz="0.00466 -0.00128 -0.01294" />
      <geometry>
        <mesh filename="package://robots/roboy_icecream/meshes/collisions/hand_left_ring_link2.stl" scale="0.001 0.001 0.001" />
      </geometry>
    </collision>
    <visual name="hand_left_ring_link2_visual">
      <origin rpy="0  0  0" xyz="0.00466 -0.00128 -0.01294" />
      <geometry>
        <mesh filename="package://robots/roboy_icecream/meshes/visuals/hand_left_ring_link2.stl" scale="0.001 0.001 0.001" />
      </geometry>
    </visual>
  </link>
  <link name="hand_left_little_link1">
    <inertial>
      <mass value="0.0308201844370646" />
      <origin rpy="0  0  0" xyz="0.00272 -0.00184 -0.01419" />
      <inertia ixx="0.0005268585539362232" ixy="-5.2557803708650235e-05" ixz="0.000924618880937142" iyy="0.0021596950498956407" iyz="2.9734402375813296e-05" izz="0.0016370323595462034" />
    </inertial>
    <collision name="hand_left_little_link1_collision">
      <origin rpy="0  0  0" xyz="0.00272 -0.00184 -0.01419" />
      <geometry>
        <mesh filename="package://robots/roboy_icecream/meshes/collisions/hand_left_little_link1.stl" scale="0.001 0.001 0.001" />
      </geometry>
    </collision>
    <visual name="hand_left_little_link1_visual">
      <origin rpy="0  0  0" xyz="0.00272 -0.00184 -0.01419" />
      <geometry>
        <mesh filename="package://robots/roboy_icecream/meshes/visuals/hand_left_little_link1.stl" scale="0.001 0.001 0.001" />
      </geometry>
    </visual>
  </link>
  <link name="hand_left_little_link2">
    <inertial>
      <mass value="0.030336907136663423" />
      <origin rpy="0  0  0" xyz="0.00281 -0.00139 -0.01345" />
      <inertia ixx="0.0007342772791164949" ixy="-4.8671913146458515e-05" ixz="0.0010662908144874557" iyy="0.0022881694449709902" iyz="3.3271296180239216e-05" izz="0.0015577043897836076" />
    </inertial>
    <collision name="hand_left_little_link2_collision">
      <origin rpy="0  0  0" xyz="0.00281 -0.00139 -0.01345" />
      <geometry>
        <mesh filename="package://robots/roboy_icecream/meshes/collisions/hand_left_little_link2.stl" scale="0.001 0.001 0.001" />
      </geometry>
    </collision>
    <visual name="hand_left_little_link2_visual">
      <origin rpy="0  0  0" xyz="0.00281 -0.00139 -0.01345" />
      <geometry>
        <mesh filename="package://robots/roboy_icecream/meshes/visuals/hand_left_little_link2.stl" scale="0.001 0.001 0.001" />
      </geometry>
    </visual>
  </link>
  <link name="hand_left_little_link0">
    <inertial>
      <mass value="0.030820184437064607" />
      <origin rpy="0  0  0" xyz="0.00189 -0.00108 -0.01409" />
      <inertia ixx="0.0003412577348785526" ixy="-5.90597015096791e-05" ixz="0.0007550643462079467" iyy="0.002030282385427836" iyz="2.637464642941845e-05" izz="0.0016939657239161538" />
    </inertial>
    <collision name="hand_left_little_link0_collision">
      <origin rpy="0  0  0" xyz="0.00189 -0.00108 -0.01409" />
      <geometry>
        <mesh filename="package://robots/roboy_icecream/meshes/collisions/hand_left_little_link0.stl" scale="0.001 0.001 0.001" />
      </geometry>
    </collision>
    <visual name="hand_left_little_link0_visual">
      <origin rpy="0  0  0" xyz="0.00189 -0.00108 -0.01409" />
      <geometry>
        <mesh filename="package://robots/roboy_icecream/meshes/visuals/hand_left_little_link0.stl" scale="0.001 0.001 0.001" />
      </geometry>
    </visual>
  </link>
  <link name="hand_left_thumb_link2">
    <inertial>
      <mass value="0.030336869955457046" />
      <origin rpy="0  0  0" xyz="0.01263  0.00556 -0.0015" />
      <inertia ixx="0.00010112026909590822" ixy="-6.1570648037768e-07" ixz="0.0006768452773705971" iyy="0.004679048930713366" iyz="9.771038819996494e-08" izz="0.0045792867430520376" />
    </inertial>
    <collision name="hand_left_thumb_link2_collision">
      <origin rpy="0  0  0" xyz="0.01263  0.00556 -0.0015" />
      <geometry>
        <mesh filename="package://robots/roboy_icecream/meshes/collisions/hand_left_thumb_link2.stl" scale="0.001 0.001 0.001" />
      </geometry>
    </collision>
    <visual name="hand_left_thumb_link2_visual">
      <origin rpy="0  0  0" xyz="0.01263  0.00556 -0.0015" />
      <geometry>
        <mesh filename="package://robots/roboy_icecream/meshes/visuals/hand_left_thumb_link2.stl" scale="0.001 0.001 0.001" />
      </geometry>
    </visual>
  </link>
  <link name="hand_left_thumb_link0">
    <inertial>
      <mass value="0.11643341043888081" />
      <origin rpy="0  0  0" xyz="0.01917  0.00097  0.00156" />
      <inertia ixx="0.00024859447967718874" ixy="0.00011456996339700878" ixz="0.00170795611510389" iyy="0.01256957933338741" iyz="-1.59426532478255e-05" izz="0.012329455324028979" />
    </inertial>
    <collision name="hand_left_thumb_link0_collision">
      <origin rpy="0  0  0" xyz="0.01917  0.00097  0.00156" />
      <geometry>
        <mesh filename="package://robots/roboy_icecream/meshes/collisions/hand_left_thumb_link0.stl" scale="0.001 0.001 0.001" />
      </geometry>
    </collision>
    <visual name="hand_left_thumb_link0_visual">
      <origin rpy="0  0  0" xyz="0.01917  0.00097  0.00156" />
      <geometry>
        <mesh filename="package://robots/roboy_icecream/meshes/visuals/hand_left_thumb_link0.stl" scale="0.001 0.001 0.001" />
      </geometry>
    </visual>
  </link>
  <link name="hand_left_thumb_link1">
    <inertial>
      <mass value="0.030820276240393865" />
      <origin rpy="0  0  0" xyz="0.01339  0.00539 -0.00193" />
      <inertia ixx="0.00010327253744889074" ixy="1.5505688071356868e-05" ixz="0.0006442330172967815" iyy="0.004170361380094778" iyz="-2.4569469568697167e-06" izz="0.004068674803025456" />
    </inertial>
    <collision name="hand_left_thumb_link1_collision">
      <origin rpy="0  0  0" xyz="0.01339  0.00539 -0.00193" />
      <geometry>
        <mesh filename="package://robots/roboy_icecream/meshes/collisions/hand_left_thumb_link1.stl" scale="0.001 0.001 0.001" />
      </geometry>
    </collision>
    <visual name="hand_left_thumb_link1_visual">
      <origin rpy="0  0  0" xyz="0.01339  0.00539 -0.00193" />
      <geometry>
        <mesh filename="package://robots/roboy_icecream/meshes/visuals/hand_left_thumb_link1.stl" scale="0.001 0.001 0.001" />
      </geometry>
    </visual>
  </link>
  <link name="shoulder_right_link1">
    <inertial>
      <mass value="0.09036491191489954" />
      <origin rpy="0  0  0" xyz="0  0  0" />
      <inertia ixx="0.027161982499601865" ixy="0.0002446351983003588" ixz="0.014520690305838616" iyy="0.03492121325205229" iyz="-0.0004573582024898006" izz="0.007781732682689985" />
    </inertial>
    <collision name="shoulder_right_link1_collision">
      <origin rpy="0  0  0" xyz="0  0  0" />
      <geometry>
        <mesh filename="package://robots/roboy_icecream/meshes/collisions/shoulder_right_link1.stl" scale="0.001 0.001 0.001" />
      </geometry>
    </collision>
    <visual name="shoulder_right_link1_visual">
      <origin rpy="0  0  0" xyz="0  0  0" />
      <geometry>
        <mesh filename="package://robots/roboy_icecream/meshes/visuals/shoulder_right_link1.stl" scale="0.001 0.001 0.001" />
      </geometry>
    </visual>
  </link>
  <link name="shoulder_right_link2">
    <inertial>
      <mass value="0.00711317178967469" />
      <origin rpy="0  0  0" xyz="0  0  0" />
      <inertia ixx="0.002137629138590559" ixy="1.9257030838094223e-05" ixz="0.0011430126697503566" iyy="0.0027484062306818192" iyz="-3.600199417069216e-05" izz="0.0006120927192806694" />
    </inertial>
    <collision name="shoulder_right_link2_collision">
      <origin rpy="0  0  0" xyz="0  0  0" />
      <geometry>
        <mesh filename="package://robots/roboy_icecream/meshes/collisions/shoulder_right_link2.stl" scale="0.001 0.001 0.001" />
      </geometry>
    </collision>
    <visual name="shoulder_right_link2_visual">
      <origin rpy="0  0  0" xyz="0  0  0" />
      <geometry>
        <mesh filename="package://robots/roboy_icecream/meshes/visuals/shoulder_right_link2.stl" scale="0.001 0.001 0.001" />
      </geometry>
    </visual>
  </link>
  <link name="hand_right_index_link1">
    <inertial>
      <mass value="0.03082510142164794" />
      <origin rpy="0  0  0" xyz="0.00311 -0.01068 -0.0094" />
      <inertia ixx="0.00220892332689956" ixy="-0.002678017501329726" ixz="-0.0007510939826706352" iyy="0.0036677066784096177" iyz="-0.0005743451079610962" izz="0.005552675676154473" />
    </inertial>
    <collision name="hand_right_index_link1_collision">
      <origin rpy="0  0  0" xyz="0.00311 -0.01068 -0.0094" />
      <geometry>
        <mesh filename="package://robots/roboy_icecream/meshes/collisions/hand_right_index_link1.stl" scale="0.001 0.001 0.001" />
      </geometry>
    </collision>
    <visual name="hand_right_index_link1_visual">
      <origin rpy="0  0  0" xyz="0.00311 -0.01068 -0.0094" />
      <geometry>
        <mesh filename="package://robots/roboy_icecream/meshes/visuals/hand_right_index_link1.stl" scale="0.001 0.001 0.001" />
      </geometry>
    </visual>
  </link>
  <link name="hand_right_index_link0">
    <inertial>
      <mass value="0.055845410084095805" />
      <origin rpy="0  0  0" xyz="0.00222 -0.01743 -0.01606" />
      <inertia ixx="0.0032080012575634274" ixy="-0.004374091061079879" ixz="-0.0008411675185489977" iyy="0.006322152318968103" iyz="-0.0005967744338203047" izz="0.009291354755989079" />
    </inertial>
    <collision name="hand_right_index_link0_collision">
      <origin rpy="0  0  0" xyz="0.00222 -0.01743 -0.01606" />
      <geometry>
        <mesh filename="package://robots/roboy_icecream/meshes/collisions/hand_right_index_link0.stl" scale="0.001 0.001 0.001" />
      </geometry>
    </collision>
    <visual name="hand_right_index_link0_visual">
      <origin rpy="0  0  0" xyz="0.00222 -0.01743 -0.01606" />
      <geometry>
        <mesh filename="package://robots/roboy_icecream/meshes/visuals/hand_right_index_link0.stl" scale="0.001 0.001 0.001" />
      </geometry>
    </visual>
  </link>
  <link name="hand_right_index_link2">
    <inertial>
      <mass value="0.030337404031818088" />
      <origin rpy="0  0  0" xyz="0.00322 -0.00986 -0.00912" />
      <inertia ixx="0.002529245326764701" ixy="-0.002824281572804406" ixz="-0.0009435322724474182" iyy="0.003762962551451083" iyz="-0.0007600390419019828" izz="0.005783147775169394" />
    </inertial>
    <collision name="hand_right_index_link2_collision">
      <origin rpy="0  0  0" xyz="0.00322 -0.00986 -0.00912" />
      <geometry>
        <mesh filename="package://robots/roboy_icecream/meshes/collisions/hand_right_index_link2.stl" scale="0.001 0.001 0.001" />
      </geometry>
    </collision>
    <visual name="hand_right_index_link2_visual">
      <origin rpy="0  0  0" xyz="0.00322 -0.00986 -0.00912" />
      <geometry>
        <mesh filename="package://robots/roboy_icecream/meshes/visuals/hand_right_index_link2.stl" scale="0.001 0.001 0.001" />
      </geometry>
    </visual>
  </link>
  <link name="hand_right_middle_link1">
    <inertial>
      <mass value="0.030825180144102245" />
      <origin rpy="0  0  0" xyz="0.00433 -0.0105  -0.00912" />
      <inertia ixx="0.002339920150392634" ixy="-0.0024775618822195627" ixz="-0.0007264219122156758" iyy="0.003037987998367633" iyz="-0.0006317591437845601" izz="0.005005655633173577" />
    </inertial>
    <collision name="hand_right_middle_link1_collision">
      <origin rpy="0  0  0" xyz="0.00433 -0.0105  -0.00912" />
      <geometry>
        <mesh filename="package://robots/roboy_icecream/meshes/collisions/hand_right_middle_link1.stl" scale="0.001 0.001 0.001" />
      </geometry>
    </collision>
    <visual name="hand_right_middle_link1_visual">
      <origin rpy="0  0  0" xyz="0.00433 -0.0105  -0.00912" />
      <geometry>
        <mesh filename="package://robots/roboy_icecream/meshes/visuals/hand_right_middle_link1.stl" scale="0.001 0.001 0.001" />
      </geometry>
    </visual>
  </link>
  <link name="hand_right_middle_link0">
    <inertial>
      <mass value="0.055845163544770086" />
      <origin rpy="0  0  0" xyz="0.00427 -0.01731 -0.01578" />
      <inertia ixx="0.0034056748604233927" ixy="-0.004088300248452689" ixz="-0.0008524817743358295" iyy="0.005283675810754391" iyz="-0.0006825741923770827" izz="0.008395422042018943" />
    </inertial>
    <collision name="hand_right_middle_link0_collision">
      <origin rpy="0  0  0" xyz="0.00427 -0.01731 -0.01578" />
      <geometry>
        <mesh filename="package://robots/roboy_icecream/meshes/collisions/hand_right_middle_link0.stl" scale="0.001 0.001 0.001" />
      </geometry>
    </collision>
    <visual name="hand_right_middle_link0_visual">
      <origin rpy="0  0  0" xyz="0.00427 -0.01731 -0.01578" />
      <geometry>
        <mesh filename="package://robots/roboy_icecream/meshes/visuals/hand_right_middle_link0.stl" scale="0.001 0.001 0.001" />
      </geometry>
    </visual>
  </link>
  <link name="hand_right_middle_link2">
    <inertial>
      <mass value="0.03033726768863161" />
      <origin rpy="0  0  0" xyz="0.00437 -0.00968 -0.00883" />
      <inertia ixx="0.00267405758229694" ixy="-0.002594338654298116" ixz="-0.000894453529117409" iyy="0.0031031546691390726" iyz="-0.0008239006721959797" izz="0.00520786379286533" />
    </inertial>
    <collision name="hand_right_middle_link2_collision">
      <origin rpy="0  0  0" xyz="0.00437 -0.00968 -0.00883" />
      <geometry>
        <mesh filename="package://robots/roboy_icecream/meshes/collisions/hand_right_middle_link2.stl" scale="0.001 0.001 0.001" />
      </geometry>
    </collision>
    <visual name="hand_right_middle_link2_visual">
      <origin rpy="0  0  0" xyz="0.00437 -0.00968 -0.00883" />
      <geometry>
        <mesh filename="package://robots/roboy_icecream/meshes/visuals/hand_right_middle_link2.stl" scale="0.001 0.001 0.001" />
      </geometry>
    </visual>
  </link>
  <link name="hand_right_ring_link1">
    <inertial>
      <mass value="0.030825311874925553" />
      <origin rpy="0  0  0" xyz="0.00551 -0.01026 -0.00875" />
      <inertia ixx="0.002247982752957782" ixy="-0.0021834578712181785" ixz="-0.0005942230086554486" iyy="0.0024365705819440085" iyz="-0.0005696630066745308" izz="0.004372665385895383" />
    </inertial>
    <collision name="hand_right_ring_link1_collision">
      <origin rpy="0  0  0" xyz="0.00551 -0.01026 -0.00875" />
      <geometry>
        <mesh filename="package://robots/roboy_icecream/meshes/collisions/hand_right_ring_link1.stl" scale="0.001 0.001 0.001" />
      </geometry>
    </collision>
    <visual name="hand_right_ring_link1_visual">
      <origin rpy="0  0  0" xyz="0.00551 -0.01026 -0.00875" />
      <geometry>
        <mesh filename="package://robots/roboy_icecream/meshes/visuals/hand_right_ring_link1.stl" scale="0.001 0.001 0.001" />
      </geometry>
    </visual>
  </link>
  <link name="hand_right_ring_link0">
    <inertial>
      <mass value="0.055843843204094676" />
      <origin rpy="0  0  0" xyz="0.00628 -0.01707 -0.01536" />
      <inertia ixx="0.0032675718891288234" ixy="-0.0036362633393568107" ixz="-0.0006712987463868374" iyy="0.004312016933531748" iyz="-0.0005859168968352344" izz="0.007353738616577911" />
    </inertial>
    <collision name="hand_right_ring_link0_collision">
      <origin rpy="0  0  0" xyz="0.00628 -0.01707 -0.01536" />
      <geometry>
        <mesh filename="package://robots/roboy_icecream/meshes/collisions/hand_right_ring_link0.stl" scale="0.001 0.001 0.001" />
      </geometry>
    </collision>
    <visual name="hand_right_ring_link0_visual">
      <origin rpy="0  0  0" xyz="0.00628 -0.01707 -0.01536" />
      <geometry>
        <mesh filename="package://robots/roboy_icecream/meshes/visuals/hand_right_ring_link0.stl" scale="0.001 0.001 0.001" />
      </geometry>
    </visual>
  </link>
  <link name="hand_right_ring_link2">
    <inertial>
      <mass value="0.03033719311018232" />
      <origin rpy="0  0  0" xyz="0.00549 -0.00943 -0.00847" />
      <inertia ixx="0.0025724107173731147" ixy="-0.002270837212640243" ixz="-0.0007386449228050139" iyy="0.0024655261373049573" iyz="-0.0007566216894171891" izz="0.004544461650246048" />
    </inertial>
    <collision name="hand_right_ring_link2_collision">
      <origin rpy="0  0  0" xyz="0.00549 -0.00943 -0.00847" />
      <geometry>
        <mesh filename="package://robots/roboy_icecream/meshes/collisions/hand_right_ring_link2.stl" scale="0.001 0.001 0.001" />
      </geometry>
    </collision>
    <visual name="hand_right_ring_link2_visual">
      <origin rpy="0  0  0" xyz="0.00549 -0.00943 -0.00847" />
      <geometry>
        <mesh filename="package://robots/roboy_icecream/meshes/visuals/hand_right_ring_link2.stl" scale="0.001 0.001 0.001" />
      </geometry>
    </visual>
  </link>
  <link name="hand_right_little_link1">
    <inertial>
      <mass value="0.03082699976349423" />
      <origin rpy="0  0  0" xyz="0.0062  -0.01007 -0.0085" />
      <inertia ixx="0.0018348189516158848" ixy="-0.0018255698507275903" ixz="-0.00034590868438162957" iyy="0.0019490186783575393" iyz="-0.00033583865533359824" izz="0.0036546592764521457" />
    </inertial>
    <collision name="hand_right_little_link1_collision">
      <origin rpy="0  0  0" xyz="0.0062  -0.01007 -0.0085" />
      <geometry>
        <mesh filename="package://robots/roboy_icecream/meshes/collisions/hand_right_little_link1.stl" scale="0.001 0.001 0.001" />
      </geometry>
    </collision>
    <visual name="hand_right_little_link1_visual">
      <origin rpy="0  0  0" xyz="0.0062  -0.01007 -0.0085" />
      <geometry>
        <mesh filename="package://robots/roboy_icecream/meshes/visuals/hand_right_little_link1.stl" scale="0.001 0.001 0.001" />
      </geometry>
    </visual>
  </link>
  <link name="hand_right_little_link2">
    <inertial>
      <mass value="0.030337137210337213" />
      <origin rpy="0  0  0" xyz="0.00614 -0.00925 -0.00822" />
      <inertia ixx="0.0021143534570680135" ixy="-0.0018967735555924271" ixz="-0.0004775521994537564" iyy="0.0019382591086159005" iyz="-0.0005006424219566718" izz="0.003799201359615068" />
    </inertial>
    <collision name="hand_right_little_link2_collision">
      <origin rpy="0  0  0" xyz="0.00614 -0.00925 -0.00822" />
      <geometry>
        <mesh filename="package://robots/roboy_icecream/meshes/collisions/hand_right_little_link2.stl" scale="0.001 0.001 0.001" />
      </geometry>
    </collision>
    <visual name="hand_right_little_link2_visual">
      <origin rpy="0  0  0" xyz="0.00614 -0.00925 -0.00822" />
      <geometry>
        <mesh filename="package://robots/roboy_icecream/meshes/visuals/hand_right_little_link2.stl" scale="0.001 0.001 0.001" />
      </geometry>
    </visual>
  </link>
  <link name="hand_right_little_link0">
    <inertial>
      <mass value="0.03082699976349422" />
      <origin rpy="0  0  0" xyz="0.0064  -0.01007 -0.00847" />
      <inertia ixx="0.0015478499358335977" ixy="-0.0017149536805960812" ixz="-0.00020113506382196504" iyy="0.0019515433649103038" iyz="-0.00017943046016893164" izz="0.003455325342577029" />
    </inertial>
    <collision name="hand_right_little_link0_collision">
      <origin rpy="0  0  0" xyz="0.0064  -0.01007 -0.00847" />
      <geometry>
        <mesh filename="package://robots/roboy_icecream/meshes/collisions/hand_right_little_link0.stl" scale="0.001 0.001 0.001" />
      </geometry>
    </collision>
    <visual name="hand_right_little_link0_visual">
      <origin rpy="0  0  0" xyz="0.0064  -0.01007 -0.00847" />
      <geometry>
        <mesh filename="package://robots/roboy_icecream/meshes/visuals/hand_right_little_link0.stl" scale="0.001 0.001 0.001" />
      </geometry>
    </visual>
  </link>
  <link name="hand_right_thumb_link2">
    <inertial>
      <mass value="0.030336936473636927" />
      <origin rpy="0  0  0" xyz="-0.01315 -0.00386  0.00217" />
      <inertia ixx="0.001164084037740139" ixy="-0.0023725215242158776" ixz="0.00023855424244476758" iyy="0.0049020530453175275" iyz="0.00011594508683095755" izz="0.006041824145272198" />
    </inertial>
    <collision name="hand_right_thumb_link2_collision">
      <origin rpy="0  0  0" xyz="-0.01315 -0.00386  0.00217" />
      <geometry>
        <mesh filename="package://robots/roboy_icecream/meshes/collisions/hand_right_thumb_link2.stl" scale="0.001 0.001 0.001" />
      </geometry>
    </collision>
    <visual name="hand_right_thumb_link2_visual">
      <origin rpy="0  0  0" xyz="-0.01315 -0.00386  0.00217" />
      <geometry>
        <mesh filename="package://robots/roboy_icecream/meshes/visuals/hand_right_thumb_link2.stl" scale="0.001 0.001 0.001" />
      </geometry>
    </visual>
  </link>
  <link name="hand_right_thumb_link0">
    <inertial>
      <mass value="0.11642987827012777" />
      <origin rpy="0  0  0" xyz="-0.01932 -0.00374 -0.00566" />
      <inertia ixx="0.00432482011614137" ixy="-0.007482666081392829" ixz="0.0011381805909767475" iyy="0.013398731295881528" iyz="0.0006403430498124654" izz="0.01751556950955123" />
    </inertial>
    <collision name="hand_right_thumb_link0_collision">
      <origin rpy="0  0  0" xyz="-0.01932 -0.00374 -0.00566" />
      <geometry>
        <mesh filename="package://robots/roboy_icecream/meshes/collisions/hand_right_thumb_link0.stl" scale="0.001 0.001 0.001" />
      </geometry>
    </collision>
    <visual name="hand_right_thumb_link0_visual">
      <origin rpy="0  0  0" xyz="-0.01932 -0.00374 -0.00566" />
      <geometry>
        <mesh filename="package://robots/roboy_icecream/meshes/visuals/hand_right_thumb_link0.stl" scale="0.001 0.001 0.001" />
      </geometry>
    </visual>
  </link>
  <link name="hand_right_thumb_link1">
    <inertial>
      <mass value="0.030824868780265316" />
      <origin rpy="0  0  0" xyz="-0.01391 -0.00396  0.00171" />
      <inertia ixx="0.0012002939589627673" ixy="-0.0022761190106096243" ixz="0.00022595549533621875" iyy="0.0043768891599822455" iyz="0.00011802626527313545" izz="0.005552685724634151" />
    </inertial>
    <collision name="hand_right_thumb_link1_collision">
      <origin rpy="0  0  0" xyz="-0.01391 -0.00396  0.00171" />
      <geometry>
        <mesh filename="package://robots/roboy_icecream/meshes/collisions/hand_right_thumb_link1.stl" scale="0.001 0.001 0.001" />
      </geometry>
    </collision>
    <visual name="hand_right_thumb_link1_visual">
      <origin rpy="0  0  0" xyz="-0.01391 -0.00396  0.00171" />
      <geometry>
        <mesh filename="package://robots/roboy_icecream/meshes/visuals/hand_right_thumb_link1.stl" scale="0.001 0.001 0.001" />
      </geometry>
    </visual>
  </link>
  <link name="wrist_left_link1">
    <inertial>
      <mass value="0.09036188404972215" />
      <origin rpy="0  0  0" xyz="0  0  0" />
      <inertia ixx="1.0612254947764261e-05" ixy="-2.8648605263951756e-05" ixz="-0.0001583627834401005" iyy="0.007366690060429517" iyz="-6.167426435441506e-07" izz="0.007363392330233558" />
    </inertial>
    <collision name="wrist_left_link1_collision">
      <origin rpy="0  0  0" xyz="0  0  0" />
      <geometry>
        <mesh filename="package://robots/roboy_icecream/meshes/collisions/wrist_left_link1.stl" scale="0.001 0.001 0.001" />
      </geometry>
    </collision>
    <visual name="wrist_left_link1_visual">
      <origin rpy="0  0  0" xyz="0  0  0" />
      <geometry>
        <mesh filename="package://robots/roboy_icecream/meshes/visuals/wrist_left_link1.stl" scale="0.001 0.001 0.001" />
      </geometry>
    </visual>
  </link>
  <link name="wrist_left_link2">
    <inertial>
      <mass value="0.007113171769630984" />
      <origin rpy="0  0  0" xyz="0  0  0" />
      <inertia ixx="3.7968653928705695e-07" ixy="-2.2554360123069993e-06" ixz="-1.2466143898479008e-05" iyy="0.0005794406521686492" iyz="-4.8554755039067315e-08" izz="0.00057918106728786" />
    </inertial>
    <collision name="wrist_left_link2_collision">
      <origin rpy="0  0  0" xyz="0  0  0" />
      <geometry>
        <mesh filename="package://robots/roboy_icecream/meshes/collisions/wrist_left_link2.stl" scale="0.001 0.001 0.001" />
      </geometry>
    </collision>
    <visual name="wrist_left_link2_visual">
      <origin rpy="0  0  0" xyz="0  0  0" />
      <geometry>
        <mesh filename="package://robots/roboy_icecream/meshes/visuals/wrist_left_link2.stl" scale="0.001 0.001 0.001" />
      </geometry>
    </visual>
  </link>
  <link name="wrist_right_link1">
    <inertial>
      <mass value="0.09036361367400472" />
      <origin rpy="0  0  0" xyz="0  0  0" />
      <inertia ixx="0.0025093261876695154" ixy="-0.004060182751831486" ixz="0.0018234627806208046" iyy="0.008344041576107804" iyz="0.0009351555044771426" izz="0.010006303506829543" />
    </inertial>
    <collision name="wrist_right_link1_collision">
      <origin rpy="0  0  0" xyz="0  0  0" />
      <geometry>
        <mesh filename="package://robots/roboy_icecream/meshes/collisions/wrist_right_link1.stl" scale="0.001 0.001 0.001" />
      </geometry>
    </collision>
    <visual name="wrist_right_link1_visual">
      <origin rpy="0  0  0" xyz="0  0  0" />
      <geometry>
        <mesh filename="package://robots/roboy_icecream/meshes/visuals/wrist_right_link1.stl" scale="0.001 0.001 0.001" />
      </geometry>
    </visual>
  </link>
  <link name="wrist_right_link2">
    <inertial>
      <mass value="0.007113172058538673" />
      <origin rpy="0  0  0" xyz="0  0  0" />
      <inertia ixx="0.00019707148973104998" ixy="-0.0003196063075976644" ixz="0.00014353791804577433" iyy="0.0006563640646310661" iyz="7.361284107438622e-05" izz="0.0007872127129728578" />
    </inertial>
    <collision name="wrist_right_link2_collision">
      <origin rpy="0  0  0" xyz="0  0  0" />
      <geometry>
        <mesh filename="package://robots/roboy_icecream/meshes/collisions/wrist_right_link2.stl" scale="0.001 0.001 0.001" />
      </geometry>
    </collision>
    <visual name="wrist_right_link2_visual">
      <origin rpy="0  0  0" xyz="0  0  0" />
      <geometry>
        <mesh filename="package://robots/roboy_icecream/meshes/visuals/wrist_right_link2.stl" scale="0.001 0.001 0.001" />
      </geometry>
    </visual>
  </link>
  <link name="zed_camera_left_lense">
    <inertial>
      <mass value="0.005755421856391891" />
      <origin rpy="0  0  0" xyz="5.00000000e-05  -1.10700000e-02   2.35000000e-03" />
      <inertia ixx="0.005003354055639959" ixy="2.3967379469334976e-05" ixz="-0.0003222735583266803" iyy="0.004996529496255549" iyz="0.000370054972711012" izz="4.878384607433584e-05" />
    </inertial>
    <collision name="zed_camera_left_lense_collision">
      <origin rpy="0  0  0" xyz="5.00000000e-05  -1.10700000e-02   2.35000000e-03" />
      <geometry>
        <mesh filename="package://robots/roboy_icecream/meshes/collisions/zed_camera_left_lense.stl" scale="0.001 0.001 0.001" />
      </geometry>
    </collision>
    <visual name="zed_camera_left_lense_visual">
      <origin rpy="0  0  0" xyz="5.00000000e-05  -1.10700000e-02   2.35000000e-03" />
      <geometry>
        <mesh filename="package://robots/roboy_icecream/meshes/visuals/zed_camera_left_lense.stl" scale="0.001 0.001 0.001" />
      </geometry>
    </visual>
  </link>
  <link name="zed_camera_right_lense">
    <inertial>
      <mass value="0.0057554218551259745" />
      <origin rpy="0  0  0" xyz="3.00000000e-05  -1.10700000e-02   2.35000000e-03" />
      <inertia ixx="0.0050036549322322954" ixy="-2.391821338968771e-05" ixz="0.00031988357548007145" iyy="0.004996221065096928" iyz="0.00037207237543609864" izz="4.877629449989427e-05" />
    </inertial>
    <collision name="zed_camera_right_lense_collision">
      <origin rpy="0  0  0" xyz="3.00000000e-05  -1.10700000e-02   2.35000000e-03" />
      <geometry>
        <mesh filename="package://robots/roboy_icecream/meshes/collisions/zed_camera_right_lense.stl" scale="0.001 0.001 0.001" />
      </geometry>
    </collision>
    <visual name="zed_camera_right_lense_visual">
      <origin rpy="0  0  0" xyz="3.00000000e-05  -1.10700000e-02   2.35000000e-03" />
      <geometry>
        <mesh filename="package://robots/roboy_icecream/meshes/visuals/zed_camera_right_lense.stl" scale="0.001 0.001 0.001" />
      </geometry>
    </visual>
  </link>
  <link name="zed_camera">
    <inertial>
      <mass value="0.009633907989226701" />
      <origin rpy="0  0  0" xyz="-0.01743 -0.0014  -0.00805" />
      <inertia ixx="0.008314802982788687" ixy="2.4365338952166025e-06" ixz="-3.793293439362343e-05" iyy="0.008297308522063661" iyz="0.0005174870196291635" izz="4.725323656366554e-05" />
    </inertial>
    <collision name="zed_camera_collision">
      <origin rpy="0  0  0" xyz="-0.01743 -0.0014  -0.00805" />
      <geometry>
        <mesh filename="package://robots/roboy_icecream/meshes/collisions/zed_camera.stl" scale="0.001 0.001 0.001" />
      </geometry>
    </collision>
    <visual name="zed_camera_visual">
      <origin rpy="0  0  0" xyz="-0.01743 -0.0014  -0.00805" />
      <geometry>
        <mesh filename="package://robots/roboy_icecream/meshes/visuals/zed_camera.stl" scale="0.001 0.001 0.001" />
      </geometry>
    </visual>
  </link>
  <link name="neck_link1">
    <inertial>
      <mass value="0.017038665636260372" />
      <origin rpy="0  0  0" xyz="0  0  0" />
      <inertia ixx="0.008728267843512112" ixy="3.905246324887799e-15" ixz="1.836596576210159e-12" iyy="0.008728228385076956" iyz="-1.855689641317778e-05" izz="1.150229285457388e-06" />
    </inertial>
    <collision name="neck_link1_collision">
      <origin rpy="0  0  0" xyz="0  0  0" />
      <geometry>
        <mesh filename="package://robots/roboy_icecream/meshes/collisions/neck_link1.stl" scale="0.001 0.001 0.001" />
      </geometry>
    </collision>
    <visual name="neck_link1_visual">
      <origin rpy="0  0  0" xyz="0  0  0" />
      <geometry>
        <mesh filename="package://robots/roboy_icecream/meshes/visuals/neck_link1.stl" scale="0.001 0.001 0.001" />
      </geometry>
    </visual>
  </link>
  <link name="neck_link2">
    <inertial>
      <mass value="0.011421521917888835" />
      <origin rpy="0  0  0" xyz="0  0  0" />
      <inertia ixx="0.005850573477666747" ixy="2.21885727293928e-15" ixz="1.0435059226432398e-12" iyy="0.005850547027508899" iyz="-1.243923713466404e-05" izz="5.28219512713884e-07" />
    </inertial>
    <collision name="neck_link2_collision">
      <origin rpy="0  0  0" xyz="0  0  0" />
      <geometry>
        <mesh filename="package://robots/roboy_icecream/meshes/collisions/neck_link2.stl" scale="0.001 0.001 0.001" />
      </geometry>
    </collision>
    <visual name="neck_link2_visual">
      <origin rpy="0  0  0" xyz="0  0  0" />
      <geometry>
        <mesh filename="package://robots/roboy_icecream/meshes/visuals/neck_link2.stl" scale="0.001 0.001 0.001" />
      </geometry>
    </visual>
  </link>
  <link name="foot_right">
    <inertial>
      <mass value="0.7293872776434517" />
      <origin rpy="0  0  0" xyz="0.02408 -0.00218 -0.02579" />
      <inertia ixx="0.35408899217191014" ixy="-0.045058777822451934" ixz="-0.07256033928073168" iyy="0.2762400728992758" iyz="-0.15841385385165987" izz="0.11966132360417292" />
    </inertial>
    <collision name="foot_right_collision">
      <origin rpy="0  0  0" xyz="0.02408 -0.00218 -0.02579" />
      <geometry>
        <mesh filename="package://robots/roboy_icecream/meshes/collisions/foot_right.stl" scale="0.001 0.001 0.001" />
      </geometry>
    </collision>
    <visual name="foot_right_visual">
      <origin rpy="0  0  0" xyz="0.02408 -0.00218 -0.02579" />
      <geometry>
        <mesh filename="package://robots/roboy_icecream/meshes/visuals/foot_right.stl" scale="0.001 0.001 0.001" />
      </geometry>
    </visual>
  </link>
  <link name="foot_right_tip">
    <inertial>
      <mass value="0.27796169383200264" />
      <origin rpy="0  0  0" xyz="0.00116 -0.04124 -0.00428" />
      <inertia ixx="0.163018926716156" ixy="-0.021792868769714743" ixz="-0.028098576274686173" iyy="0.10953700480881963" iyz="-0.07890333279317867" izz="0.0691720869721408" />
    </inertial>
    <collision name="foot_right_tip_collision">
      <origin rpy="0  0  0" xyz="0.00116 -0.04124 -0.00428" />
      <geometry>
        <mesh filename="package://robots/roboy_icecream/meshes/collisions/foot_right_tip.stl" scale="0.001 0.001 0.001" />
      </geometry>
    </collision>
    <visual name="foot_right_tip_visual">
      <origin rpy="0  0  0" xyz="0.00116 -0.04124 -0.00428" />
      <geometry>
        <mesh filename="package://robots/roboy_icecream/meshes/visuals/foot_right_tip.stl" scale="0.001 0.001 0.001" />
      </geometry>
    </visual>
  </link>
  <link name="foot_left">
    <inertial>
      <mass value="0.7293778980792932" />
      <origin rpy="0  0  0" xyz="0.02392 -0.00181 -0.02581" />
      <inertia ixx="0.3539015699777266" ixy="0.04795411958144601" ixz="0.07730674080298215" iyy="0.27903896738870787" iyz="-0.15825897052973287" izz="0.12224975405698266" />
    </inertial>
    <collision name="foot_left_collision">
      <origin rpy="0  0  0" xyz="0.02392 -0.00181 -0.02581" />
      <geometry>
        <mesh filename="package://robots/roboy_icecream/meshes/collisions/foot_left.stl" scale="0.001 0.001 0.001" />
      </geometry>
    </collision>
    <visual name="foot_left_visual">
      <origin rpy="0  0  0" xyz="0.02392 -0.00181 -0.02581" />
      <geometry>
        <mesh filename="package://robots/roboy_icecream/meshes/visuals/foot_left.stl" scale="0.001 0.001 0.001" />
      </geometry>
    </visual>
  </link>
  <link name="foot_left_tip">
    <inertial>
      <mass value="0.2779374729954732" />
      <origin rpy="0  0  0" xyz="-0.00116 -0.04115 -0.00508" />
      <inertia ixx="0.16348309724729793" ixy="0.023187053562808757" ixz="0.03004593384309638" iyy="0.1112667447436401" iyz="-0.07903061678042086" izz="0.07001667828903972" />
    </inertial>
    <collision name="foot_left_tip_collision">
      <origin rpy="0  0  0" xyz="-0.00116 -0.04115 -0.00508" />
      <geometry>
        <mesh filename="package://robots/roboy_icecream/meshes/collisions/foot_left_tip.stl" scale="0.001 0.001 0.001" />
      </geometry>
    </collision>
    <visual name="foot_left_tip_visual">
      <origin rpy="0  0  0" xyz="-0.00116 -0.04115 -0.00508" />
      <geometry>
        <mesh filename="package://robots/roboy_icecream/meshes/visuals/foot_left_tip.stl" scale="0.001 0.001 0.001" />
      </geometry>
    </visual>
  </link>
  <link name="hip_right_tendon_guide">
    <inertial>
      <mass value="0.0256071741027992" />
      <origin rpy="0  0  0" xyz="0.0026   0.00145 -0.02974" />
      <inertia ixx="0.0007688721042748645" ixy="1.2907946738553109e-05" ixz="-0.0007484377774593835" iyy="0.0015017398221674476" iyz="1.31280501412243e-05" izz="0.000737868889511365" />
    </inertial>
    <collision name="hip_right_tendon_guide_collision">
      <origin rpy="0  0  0" xyz="0.0026   0.00145 -0.02974" />
      <geometry>
        <mesh filename="package://robots/roboy_icecream/meshes/collisions/hip_right_tendon_guide.stl" scale="0.001 0.001 0.001" />
      </geometry>
    </collision>
    <visual name="hip_right_tendon_guide_visual">
      <origin rpy="0  0  0" xyz="0.0026   0.00145 -0.02974" />
      <geometry>
        <mesh filename="package://robots/roboy_icecream/meshes/visuals/hip_right_tendon_guide.stl" scale="0.001 0.001 0.001" />
      </geometry>
    </visual>
  </link>
  <link name="hip_left_tendon_guide">
    <inertial>
      <mass value="0.025607174102799196" />
      <origin rpy="0  0  0" xyz="0.0029   0.00145 -0.02974" />
      <inertia ixx="0.0007688721042745984" ixy="-1.3625007727511813e-05" ixz="0.0007900179804727504" iyy="0.0015854586181906136" iyz="1.3128050125302672e-05" izz="0.0008215876855336989" />
    </inertial>
    <collision name="hip_left_tendon_guide_collision">
      <origin rpy="0  0  0" xyz="0.0029   0.00145 -0.02974" />
      <geometry>
        <mesh filename="package://robots/roboy_icecream/meshes/collisions/hip_left_tendon_guide.stl" scale="0.001 0.001 0.001" />
      </geometry>
    </collision>
    <visual name="hip_left_tendon_guide_visual">
      <origin rpy="0  0  0" xyz="0.0029   0.00145 -0.02974" />
      <geometry>
        <mesh filename="package://robots/roboy_icecream/meshes/visuals/hip_left_tendon_guide.stl" scale="0.001 0.001 0.001" />
      </geometry>
    </visual>
  </link>
  <link name="knee_right_tendon_guide">
    <inertial>
      <mass value="0.02560490583004142" />
      <origin rpy="0  0  0" xyz="-0.0029  -0.02974  0.00145" />
      <inertia ixx="0.0041823946263214945" ixy="-0.0015840714252371775" ixz="-0.0007340025726217843" iyy="0.001472575084145065" iyz="-0.0015937408745932437" izz="0.004173503757151044" />
    </inertial>
    <collision name="knee_right_tendon_guide_collision">
      <origin rpy="0  0  0" xyz="-0.0029  -0.02974  0.00145" />
      <geometry>
        <mesh filename="package://robots/roboy_icecream/meshes/collisions/knee_right_tendon_guide.stl" scale="0.001 0.001 0.001" />
      </geometry>
    </collision>
    <visual name="knee_right_tendon_guide_visual">
      <origin rpy="0  0  0" xyz="-0.0029  -0.02974  0.00145" />
      <geometry>
        <mesh filename="package://robots/roboy_icecream/meshes/visuals/knee_right_tendon_guide.stl" scale="0.001 0.001 0.001" />
      </geometry>
    </visual>
  </link>
  <link name="knee_left_tendon_guide">
    <inertial>
      <mass value="0.025604905830041404" />
      <origin rpy="0  0  0" xyz="0.0029  -0.02974  0.00145" />
      <inertia ixx="0.004182394626728793" ixy="0.0016769753387839929" ixz="0.0007770510269326971" iyy="0.0015606617148220664" iyz="-0.0015937408747146232" izz="0.004261590388171581" />
    </inertial>
    <collision name="knee_left_tendon_guide_collision">
      <origin rpy="0  0  0" xyz="0.0029  -0.02974  0.00145" />
      <geometry>
        <mesh filename="package://robots/roboy_icecream/meshes/collisions/knee_left_tendon_guide.stl" scale="0.001 0.001 0.001" />
      </geometry>
    </collision>
    <visual name="knee_left_tendon_guide_visual">
      <origin rpy="0  0  0" xyz="0.0029  -0.02974  0.00145" />
      <geometry>
        <mesh filename="package://robots/roboy_icecream/meshes/visuals/knee_left_tendon_guide.stl" scale="0.001 0.001 0.001" />
      </geometry>
    </visual>
  </link>
</robot>