<sdf version='1.6'>
  <world name='default'>
    <light name='sun' type='directional'>
      <cast_shadows>1</cast_shadows>
      <pose frame=''>0 0 10 0 -0 0</pose>
      <diffuse>0.8 0.8 0.8 1</diffuse>
      <specular>0.2 0.2 0.2 1</specular>
      <attenuation>
        <range>1000</range>
        <constant>0.9</constant>
        <linear>0.01</linear>
        <quadratic>0.001</quadratic>
      </attenuation>
      <direction>-0.5 0.1 -0.9</direction>
    </light>
    <model name='ground_plane'>
      <static>1</static>
      <link name='link'>
        <collision name='collision'>
          <geometry>
            <plane>
              <normal>0 0 1</normal>
              <size>100 100</size>
            </plane>
          </geometry>
          <surface>
            <contact>
              <collide_bitmask>65535</collide_bitmask>
              <ode/>
            </contact>
            <friction>
              <ode>
                <mu>100</mu>
                <mu2>50</mu2>
              </ode>
              <torsional>
                <ode/>
              </torsional>
            </friction>
            <bounce/>
          </surface>
          <max_contacts>10</max_contacts>
        </collision>
        <visual name='visual'>
          <cast_shadows>0</cast_shadows>
          <geometry>
            <plane>
              <normal>0 0 1</normal>
              <size>100 100</size>
            </plane>
          </geometry>
          <material>
            <script>
              <uri>file://media/materials/scripts/gazebo.material</uri>
              <name>Gazebo/Grey</name>
            </script>
          </material>
        </visual>
        <self_collide>0</self_collide>
        <enable_wind>0</enable_wind>
        <kinematic>0</kinematic>
      </link>
    </model>
    <gravity>0 0 -9.81</gravity>
    <magnetic_field>6e-06 2.3e-05 -4.2e-05</magnetic_field>
    <atmosphere type='adiabatic'/>
    <physics name='default_physics' default='0' type='ode'>
      <max_step_size>0.001</max_step_size>
      <real_time_factor>1</real_time_factor>
      <real_time_update_rate>1000</real_time_update_rate>
    </physics>
    <scene>
      <ambient>0.4 0.4 0.4 1</ambient>
      <background>0.7 0.7 0.7 1</background>
      <shadows>1</shadows>
    </scene>
    <audio>
      <device>default</device>
    </audio>
    <wind/>
    <spherical_coordinates>
      <surface_model>EARTH_WGS84</surface_model>
      <latitude_deg>0</latitude_deg>
      <longitude_deg>0</longitude_deg>
      <elevation>0</elevation>
      <heading_deg>0</heading_deg>
    </spherical_coordinates>
    <model name='musc-le-ball'>
      <link name='base'>
        <kinematic>1</kinematic>
        <self_collide>0</self_collide>
        <pose frame=''>0.239578 0.30164 -0.00404 0 -0 0</pose>
        <inertial>
          <pose frame=''>0 0 0 0 -0 0</pose>
          <mass>4.57796</mass>
          <inertia>
            <ixx>0.696498</ixx>
            <ixy>-0.331245</ixy>
            <ixz>0.00520695</ixz>
            <iyy>0.325257</iyy>
            <iyz>0.00404122</iyz>
            <izz>1.02006</izz>
          </inertia>
        </inertial>
        <enable_wind>0</enable_wind>
        <visual name='base_visual'>
          <geometry>
            <mesh>
              <uri>model://musc-le/meshes/visuals/base.dae</uri>
              <scale>0.001 0.001 0.001</scale>
            </mesh>
          </geometry>
          <pose frame=''>0 0 0 0 -0 0</pose>
          <transparency>0</transparency>
          <cast_shadows>1</cast_shadows>
        </visual>
        <collision name='base_collision'>
          <laser_retro>0</laser_retro>
          <max_contacts>10</max_contacts>
          <pose frame=''>0 0 0 0 -0 0</pose>
          <geometry>
            <mesh>
              <uri>/home/missxa/.gazebo/models/musc-le/meshes/collisions/base.dae</uri>
              <scale>0.001 0.001 0.001</scale>
            </mesh>
          </geometry>
          <surface>
            <friction>
              <ode>
                <mu>1</mu>
                <mu2>1</mu2>
                <fdir1>0 0 0</fdir1>
                <slip1>0</slip1>
                <slip2>0</slip2>
              </ode>
              <torsional>
                <coefficient>1</coefficient>
                <patch_radius>0</patch_radius>
                <surface_radius>0</surface_radius>
                <use_patch_radius>1</use_patch_radius>
                <ode>
                  <slip>0</slip>
                </ode>
              </torsional>
            </friction>
            <bounce>
              <restitution_coefficient>0</restitution_coefficient>
              <threshold>1e+06</threshold>
            </bounce>
            <contact>
              <collide_without_contact>0</collide_without_contact>
              <collide_without_contact_bitmask>1</collide_without_contact_bitmask>
              <collide_bitmask>1</collide_bitmask>
              <ode>
                <soft_cfm>0</soft_cfm>
                <soft_erp>0.2</soft_erp>
                <kp>1e+13</kp>
                <kd>1</kd>
                <max_vel>0.01</max_vel>
                <min_depth>0</min_depth>
              </ode>
              <bullet>
                <split_impulse>1</split_impulse>
                <split_impulse_penetration_threshold>-0.01</split_impulse_penetration_threshold>
                <soft_cfm>0</soft_cfm>
                <soft_erp>0.2</soft_erp>
                <kp>1e+13</kp>
                <kd>1</kd>
              </bullet>
            </contact>
          </surface>
        </collision>
      </link>
      <link name='ball'>
        <inertial>
          <mass>0.0117872</mass>
          <inertia>
            <ixx>1.257e-05</ixx>
            <ixy>0</ixy>
            <ixz>0</ixz>
            <iyy>1.257e-05</iyy>
            <iyz>0</iyz>
            <izz>1.257e-05</izz>
          </inertia>
          <pose frame=''>0 0 0 0 -0 0</pose>
        </inertial>
        <pose frame=''>0.238225 0.295141 0.900279 0 -0 0</pose>
        <gravity>1</gravity>
        <self_collide>0</self_collide>
        <kinematic>0</kinematic>
        <enable_wind>0</enable_wind>
        <visual name='visual'>
          <pose frame=''>0 0 0 0 -0 0</pose>
          <geometry>
            <sphere>
              <radius>0.0516307</radius>
            </sphere>
          </geometry>
          <material>
            <lighting>1</lighting>
            <script>
              <uri>file://media/materials/scripts/gazebo.material</uri>
              <name>Gazebo/Grey</name>
            </script>
            <shader type='vertex'>
              <normal_map>__default__</normal_map>
            </shader>
            <emissive>0 0 0 1</emissive>
          </material>
          <transparency>0</transparency>
          <cast_shadows>1</cast_shadows>
        </visual>
        <collision name='collision'>
          <laser_retro>0</laser_retro>
          <max_contacts>10</max_contacts>
          <pose frame=''>0 0 0 0 -0 0</pose>
          <geometry>
            <sphere>
              <radius>0.051631</radius>
            </sphere>
          </geometry>
          <surface>
            <friction>
              <ode>
                <mu>1</mu>
                <mu2>1</mu2>
                <fdir1>0 0 0</fdir1>
                <slip1>0</slip1>
                <slip2>0</slip2>
              </ode>
              <torsional>
                <coefficient>1</coefficient>
                <patch_radius>0</patch_radius>
                <surface_radius>0</surface_radius>
                <use_patch_radius>1</use_patch_radius>
                <ode>
                  <slip>0</slip>
                </ode>
              </torsional>
            </friction>
            <bounce>
              <restitution_coefficient>0</restitution_coefficient>
              <threshold>1e+06</threshold>
            </bounce>
            <contact>
              <collide_without_contact>0</collide_without_contact>
              <collide_without_contact_bitmask>1</collide_without_contact_bitmask>
              <collide_bitmask>1</collide_bitmask>
              <ode>
                <soft_cfm>0</soft_cfm>
                <soft_erp>0.2</soft_erp>
                <kp>1e+13</kp>
                <kd>1</kd>
                <max_vel>0.01</max_vel>
                <min_depth>0</min_depth>
              </ode>
              <bullet>
                <split_impulse>1</split_impulse>
                <split_impulse_penetration_threshold>-0.01</split_impulse_penetration_threshold>
                <soft_cfm>0</soft_cfm>
                <soft_erp>0.2</soft_erp>
                <kp>1e+13</kp>
                <kd>1</kd>
              </bullet>
            </contact>
          </surface>
        </collision>
      </link>
      <link name='lower_arm'>
        <self_collide>0</self_collide>
        <pose frame=''>0.239039 0.302085 0.267292 0 -0 0</pose>
        <inertial>
          <pose frame=''>0 0 0 0 -0 0</pose>
          <mass>0.152374</mass>
          <inertia>
            <ixx>0.0276992</ixx>
            <ixy>-0.0110195</ixy>
            <ixz>-0.0122758</ixz>
            <iyy>0.0224755</iyy>
            <iyz>-0.00971948</iyz>
            <izz>0.0226828</izz>
          </inertia>
        </inertial>
        <enable_wind>0</enable_wind>
        <kinematic>0</kinematic>
        <visual name='lower_arm_visual'>
          <geometry>
            <mesh>
              <uri>model://musc-le/meshes/visuals/lower_arm.dae</uri>
              <scale>0.001 0.001 0.001</scale>
            </mesh>
          </geometry>
          <pose frame=''>0 0 0 0 -0 0</pose>
          <transparency>0</transparency>
          <cast_shadows>1</cast_shadows>
        </visual>
        <collision name='lower_arm_collision'>
          <laser_retro>0</laser_retro>
          <max_contacts>10</max_contacts>
          <pose frame=''>0 0 0 0 -0 0</pose>
          <geometry>
            <mesh>
              <uri>/home/missxa/.gazebo/models/musc-le/meshes/collisions/lower_arm.dae</uri>
              <scale>0.001 0.001 0.001</scale>
            </mesh>
          </geometry>
          <surface>
            <friction>
              <ode>
                <mu>1</mu>
                <mu2>1</mu2>
                <fdir1>0 0 0</fdir1>
                <slip1>0</slip1>
                <slip2>0</slip2>
              </ode>
              <torsional>
                <coefficient>1</coefficient>
                <patch_radius>0</patch_radius>
                <surface_radius>0</surface_radius>
                <use_patch_radius>1</use_patch_radius>
                <ode>
                  <slip>0</slip>
                </ode>
              </torsional>
            </friction>
            <bounce>
              <restitution_coefficient>0</restitution_coefficient>
              <threshold>1e+06</threshold>
            </bounce>
            <contact>
              <collide_without_contact>0</collide_without_contact>
              <collide_without_contact_bitmask>1</collide_without_contact_bitmask>
              <collide_bitmask>1</collide_bitmask>
              <ode>
                <soft_cfm>0</soft_cfm>
                <soft_erp>0.2</soft_erp>
                <kp>1e+13</kp>
                <kd>1</kd>
                <max_vel>0.01</max_vel>
                <min_depth>0</min_depth>
              </ode>
              <bullet>
                <split_impulse>1</split_impulse>
                <split_impulse_penetration_threshold>-0.01</split_impulse_penetration_threshold>
                <soft_cfm>0</soft_cfm>
                <soft_erp>0.2</soft_erp>
                <kp>1e+13</kp>
                <kd>1</kd>
              </bullet>
            </contact>
          </surface>
        </collision>
      </link>
      <link name='upper_arm'>
        <self_collide>0</self_collide>
        <pose frame=''>0.240473 0.296462 0.598889 0 -0 0</pose>
        <inertial>
          <pose frame=''>0 0 0 0 -0 0</pose>
          <mass>0.0743535</mass>
          <inertia>
            <ixx>0.0343257</ixx>
            <ixy>-0.00530075</ixy>
            <ixz>-0.0132014</ixz>
            <iyy>0.0320916</iyy>
            <iyz>-0.0107095</iyz>
            <izz>0.010845</izz>
          </inertia>
        </inertial>
        <enable_wind>0</enable_wind>
        <kinematic>0</kinematic>
        <visual name='upper_arm_visual'>
          <geometry>
            <mesh>
              <uri>model://musc-le/meshes/visuals/upper_arm.dae</uri>
              <scale>0.001 0.001 0.001</scale>
            </mesh>
          </geometry>
          <pose frame=''>0 0 0 0 -0 0</pose>
          <transparency>0</transparency>
          <cast_shadows>1</cast_shadows>
          <material>
            <emissive>0 0 0 1</emissive>
          </material>
        </visual>
        <collision name='upper_arm_collision'>
          <laser_retro>0</laser_retro>
          <max_contacts>10</max_contacts>
          <pose frame=''>0 0 0 0 -0 0</pose>
          <geometry>
            <mesh>
              <uri>/home/missxa/.gazebo/models/musc-le/meshes/collisions/upper_arm.dae</uri>
              <scale>0.001 0.001 0.001</scale>
            </mesh>
          </geometry>
          <surface>
            <friction>
              <ode>
                <mu>1</mu>
                <mu2>1</mu2>
                <fdir1>0 0 0</fdir1>
                <slip1>0</slip1>
                <slip2>0</slip2>
              </ode>
              <torsional>
                <coefficient>1</coefficient>
                <patch_radius>0</patch_radius>
                <surface_radius>0</surface_radius>
                <use_patch_radius>1</use_patch_radius>
                <ode>
                  <slip>0</slip>
                </ode>
              </torsional>
            </friction>
            <bounce>
              <restitution_coefficient>0</restitution_coefficient>
              <threshold>1e+06</threshold>
            </bounce>
            <contact>
              <collide_without_contact>0</collide_without_contact>
              <collide_without_contact_bitmask>1</collide_without_contact_bitmask>
              <collide_bitmask>1</collide_bitmask>
              <ode>
                <soft_cfm>0</soft_cfm>
                <soft_erp>0.2</soft_erp>
                <kp>1e+13</kp>
                <kd>1</kd>
                <max_vel>0.01</max_vel>
                <min_depth>0</min_depth>
              </ode>
              <bullet>
                <split_impulse>1</split_impulse>
                <split_impulse_penetration_threshold>-0.01</split_impulse_penetration_threshold>
                <soft_cfm>0</soft_cfm>
                <soft_erp>0.2</soft_erp>
                <kp>1e+13</kp>
                <kd>1</kd>
              </bullet>
            </contact>
          </surface>
        </collision>
      </link>
      <joint name='lower_joint' type='revolute'>
        <parent>base</parent>
        <child>lower_arm</child>
        <pose frame=''>-0.016839 -8.5e-05 -0.229631 0 -0 0</pose>
        <axis>
          <xyz>-1 0 0</xyz>
          <use_parent_model_frame>0</use_parent_model_frame>
          <limit>
            <lower>-1.0472</lower>
            <upper>1.0472</upper>
            <effort>-1</effort>
            <velocity>-1</velocity>
          </limit>
          <dynamics>
            <spring_reference>0</spring_reference>
            <spring_stiffness>0</spring_stiffness>
            <damping>0</damping>
            <friction>0</friction>
          </dynamics>
        </axis>
        <physics>
          <ode>
            <limit>
              <cfm>0</cfm>
              <erp>0.2</erp>
            </limit>
            <suspension>
              <cfm>0</cfm>
              <erp>0.2</erp>
            </suspension>
          </ode>
        </physics>
      </joint>
      <joint name='ball_joint' type='fixed'>
        <parent>upper_arm</parent>
        <child>ball</child>
        <pose frame=''>0 0 0 0 -0 0</pose>
        <physics>
          <ode>
            <limit>
              <cfm>0</cfm>
              <erp>0.2</erp>
            </limit>
            <suspension>
              <cfm>0</cfm>
              <erp>0.2</erp>
            </suspension>
          </ode>
        </physics>
      </joint>
      <joint name='upper_joint' type='revolute'>
        <parent>lower_arm</parent>
        <child>upper_arm</child>
        <pose frame=''>-0.004823 -3.3e-05 -0.137753 0 -0 0</pose>
        <axis>
          <xyz>1 -0 -0</xyz>
          <use_parent_model_frame>0</use_parent_model_frame>
          <limit>
            <lower>-1.39626</lower>
            <upper>1.39626</upper>
            <effort>-1</effort>
            <velocity>-1</velocity>
          </limit>
          <dynamics>
            <spring_reference>0</spring_reference>
            <spring_stiffness>0</spring_stiffness>
            <damping>0</damping>
            <friction>0</friction>
          </dynamics>
        </axis>
        <physics>
          <ode>
            <limit>
              <cfm>0</cfm>
              <erp>0.2</erp>
            </limit>
            <suspension>
              <cfm>0</cfm>
              <erp>0.2</erp>
            </suspension>
          </ode>
        </physics>
      </joint>
      <static>0</static>
      <allow_auto_disable>1</allow_auto_disable>
      <plugin name='cardsflow_gazebo_plugin' filename='libcardsflow_gazebo_plugin.so'/>
      <pose frame=''>-0.819565 -0.860009 0 0 -0 0</pose>
    </model>
    <state world_name='default'>
      <sim_time>42 774000000</sim_time>
      <real_time>85 296988557</real_time>
      <wall_time>1555015173 440678073</wall_time>
      <iterations>42774</iterations>
      <model name='ground_plane'>
        <pose frame=''>0 0 0 0 -0 0</pose>
        <scale>1 1 1</scale>
        <link name='link'>
          <pose frame=''>0 0 0 0 -0 0</pose>
          <velocity>0 0 0 0 -0 0</velocity>
          <acceleration>0 0 0 0 -0 0</acceleration>
          <wrench>0 0 0 0 -0 0</wrench>
        </link>
      </model>
      <model name='musc-le-ball'>
        <pose frame=''>-0.819565 -0.860009 0 0 -0 0</pose>
        <scale>1 1 1</scale>
        <link name='ball'>
          <pose frame=''>-0.581333 -0.137303 0.543695 -1.3844 -2e-06 9e-06</pose>
          <velocity>0 1.28769 -1.06645 -2.53902 -2.3e-05 6e-06</velocity>
          <acceleration>0.093137 -1.14909 -5.1753 2.83726 -0.013478 0.126065</acceleration>
          <wrench>0.001098 -0.013545 -0.061002 0 -0 0</wrench>
        </link>
        <link name='base'>
          <pose frame=''>-0.579987 -0.558369 -0.00404 0 -0 0</pose>
          <velocity>0 0 0 0 -0 0</velocity>
          <acceleration>-0.050193 -0.543288 2.17178 0.740609 0.70054 -0.006077</acceleration>
          <wrench>-0.229781 -2.48715 9.94233 0 -0 0</wrench>
        </link>
        <link name='lower_arm'>
          <pose frame=''>-0.580526 -0.56065 0.26728 0.011873 -0 0</pose>
          <velocity>-0 0.583804 0.007471 -2.54253 -2e-06 -1e-06</velocity>
          <acceleration>-0.000183 0.701112 -1.47397 2.25889 0.604577 2.82521</acceleration>
          <wrench>-2.8e-05 0.106831 -0.224595 0 -0 0</wrench>
        </link>
        <link name='upper_arm'>
          <pose frame=''>-0.579092 -0.433232 0.486543 -1.3844 0 0</pose>
          <velocity>-2e-06 1.14161 -0.315293 -2.53899 -2e-05 1e-06</velocity>
          <acceleration>0.001347 0.557254 -3.38962 -0.796835 0.929418 1.58917</acceleration>
          <wrench>0.0001 0.041434 -0.25203 0 -0 0</wrench>
        </link>
      </model>
      <light name='sun'>
        <pose frame=''>0 0 10 0 -0 0</pose>
      </light>
    </state>
    <gui fullscreen='0'>
      <camera name='user_camera'>
        <pose frame=''>5.06566 -4.91248 2.05464 0 0.275643 2.35619</pose>
        <view_controller>orbit</view_controller>
        <projection_type>perspective</projection_type>
      </camera>
    </gui>
  </world>
</sdf>
