<robot name="rikshaw">
  <joint name="right_wrist_0" type="revolute">
    <parent link="lower_arm_right" />
    <child link="wrist_right_1" />
    <origin rpy="0  0  0" xyz="0.00952  0.1943  -0.17993" />
    <axis xyz="-0.02346 -0.63212 -0.77451" />
    <limit effort="0.0" lower="-0.523598775598" upper="0.523598775598" velocity="0.0" />
  </joint>
  <joint name="right_wrist_1" type="revolute">
    <parent link="wrist_right_1" />
    <child link="right_hand" />
    <origin rpy="0  0  0" xyz="0.01772  0.00587  0.00822" />
    <axis xyz="0.99902 -0.04386  0.00553" />
    <limit effort="0.0" lower="-0.523598775598" upper="0.523598775598" velocity="0.0" />
  </joint>
  <joint name="zed_camera_mount" type="revolute">
    <parent link="head" />
    <child link="zed_camera" />
    <origin rpy="0  0  0" xyz="-0.10663 -0.0215   0.20551" />
    <axis xyz="0  0  0" />
    <limit effort="0" lower="0" upper="0" velocity="0" />
  </joint>
  <joint name="elbow_left_rot1" type="revolute">
    <parent link="elbow_left" />
    <child link="lower_arm_left" />
    <origin rpy="0  0  0" xyz="0.0068  -0.03837 -0.05667" />
    <axis xyz="0.03688 -0.7578  -0.65143" />
    <limit effort="0.0" lower="-1.57079632679" upper="1.57079632679" velocity="0.0" />
  </joint>
  <joint name="elbow_left_rot0" type="revolute">
    <parent link="upper_arm_left" />
    <child link="elbow_left" />
    <origin rpy="0  0  0" xyz="0.00549 -0.21448 -0.16081" />
    <axis xyz="-0.03535  0.65048 -0.75869" />
    <limit effort="0.0" lower="0.0" upper="1.57079632679" velocity="0.0" />
  </joint>
  <joint name="left_shoulder_axis0" type="revolute">
    <parent link="torso" />
    <child link="left_shoulder_link1" />
    <origin rpy="0  0  0" xyz="-0.00146 -0.29218  0.46833" />
    <axis xyz="0.05097 -0.99863 -0.01134" />
    <limit effort="0.0" lower="-3.14159265359" upper="3.14159265359" velocity="0.0" />
  </joint>
  <joint name="left_shoulder_axis1" type="revolute">
    <parent link="left_shoulder_link1" />
    <child link="left_shoulder_link2" />
    <origin rpy="0  0  0" xyz="0  0  0" />
    <axis xyz="0.99869  0.05101 -0.0028" />
    <limit effort="0.0" lower="-3.14159265359" upper="3.14159265359" velocity="0.0" />
  </joint>
  <joint name="left_shoulder_axis2" type="revolute">
    <parent link="left_shoulder_link2" />
    <child link="upper_arm_left" />
    <origin rpy="0  0  0" xyz="0  0  0" />
    <axis xyz="0.03688 -0.7578  -0.65143" />
    <limit effort="0.0" lower="-3.14159265359" upper="3.14159265359" velocity="0.0" />
  </joint>
  <joint name="zed_camera_right" type="revolute">
    <parent link="zed_camera" />
    <child link="zed_camera_right_lense" />
    <origin rpy="0  0  0" xyz="0.00015  0.0815  -0.00799" />
    <axis xyz="0  0  0" />
    <limit effort="0" lower="0" upper="0" velocity="0" />
  </joint>
  <joint name="zed_camera_left" type="revolute">
    <parent link="zed_camera" />
    <child link="zed_camera_left_lense" />
    <origin rpy="0  0  0" xyz="0.00015 -0.03848 -0.00799" />
    <axis xyz="0  0  0" />
    <limit effort="0" lower="0" upper="0" velocity="0" />
  </joint>
  <joint name="elbow_right_rot0" type="revolute">
    <parent link="upper_arm_right" />
    <child link="elbow_right" />
    <origin rpy="0  0  0" xyz="0.00555  0.21561 -0.16179" />
    <axis xyz="0.03535  0.65048  0.75869" />
    <limit effort="0.0" lower="0.0" upper="1.57079632679" velocity="0.0" />
  </joint>
  <joint name="right_shoulder_axis0" type="revolute">
    <parent link="torso" />
    <child link="right_shoulder_link1" />
    <origin rpy="0  0  0" xyz="-0.00149  0.29218  0.46833" />
    <axis xyz="0.99869 -0.05101 -0.0028" />
    <limit effort="0.0" lower="-3.14159265359" upper="3.14159265359" velocity="0.0" />
  </joint>
  <joint name="right_shoulder_axis2" type="revolute">
    <parent link="right_shoulder_link2" />
    <child link="upper_arm_right" />
    <origin rpy="0  0  0" xyz="0  0  0" />
    <axis xyz="0.03688  0.7578  -0.65143" />
    <limit effort="0.0" lower="-3.14159265359" upper="3.14159265359" velocity="0.0" />
  </joint>
  <joint name="right_shoulder_axis1" type="revolute">
    <parent link="right_shoulder_link1" />
    <child link="right_shoulder_link2" />
    <origin rpy="0  0  0" xyz="0  0  0" />
    <axis xyz="0.03535  0.65048  0.75869" />
    <limit effort="0.0" lower="-3.14159265359" upper="3.14159265359" velocity="0.0" />
  </joint>
  <joint name="head_axis0" type="revolute">
    <parent link="torso" />
    <child link="sphere_head_link1" />
    <origin rpy="0  0  0" xyz="-0.01217  0       0.62324" />
    <axis xyz="-0.9998   0      -0.01953" />
    <limit effort="0.0" lower="-0.523598775598" upper="0.523598775598" velocity="0.0" />
  </joint>
  <joint name="head_axis2" type="revolute">
    <parent link="sphere_head_link2" />
    <child link="head" />
    <origin rpy="0  0  0" xyz="0  0  0" />
    <axis xyz="-0.01953  0       0.9998" />
    <limit effort="0.0" lower="-0.523598775598" upper="0.523598775598" velocity="0.0" />
  </joint>
  <joint name="head_axis1" type="revolute">
    <parent link="sphere_head_link1" />
    <child link="sphere_head_link2" />
    <origin rpy="0  0  0" xyz="0  0  0" />
    <axis xyz="0  1  0" />
    <limit effort="0.0" lower="-0.523598775598" upper="0.523598775598" velocity="0.0" />
  </joint>
  <joint name="left_wrist_0" type="revolute">
    <parent link="lower_arm_left" />
    <child link="wrist_left_1" />
    <origin rpy="0  0  0" xyz="0.00914 -0.19129 -0.17959" />
    <axis xyz="-0.04721  0.66836 -0.74233" />
    <limit effort="0.0" lower="-0.523598775598" upper="0.523598775598" velocity="0.0" />
  </joint>
  <joint name="left_wrist_1" type="revolute">
    <parent link="wrist_left_1" />
    <child link="left_hand" />
    <origin rpy="0  0  0" xyz="-0.01697 -0.00803  0.00798" />
    <axis xyz="0.99824  0.05815 -0.01113" />
    <limit effort="0.0" lower="-0.523598775598" upper="0.523598775598" velocity="0.0" />
  </joint>
  <joint name="joint_wheel_right" type="revolute">
    <parent link="front_part" />
    <child link="right_wheel" />
    <origin rpy="0  0  0" xyz="-0.052   0.338   0.0345" />
    <axis xyz="0  1  0" />
    <limit effort="0.0" lower="-3.14159265359" upper="3.14159265359" velocity="0.0" />
  </joint>
  <joint name="joint_wheel_back" type="revolute">
    <parent link="bike" />
    <child link="wheel_back" />
    <origin rpy="0  0  0" xyz="0.53689 -0.06544  0.04941" />
    <axis xyz="0 -1  0" />
    <limit effort="0.0" lower="-3.14159265359" upper="3.14159265359" velocity="0.0" />
  </joint>
  <joint name="joint_pedal" type="revolute">
    <parent link="bike" />
    <child link="kurbel" />
    <origin rpy="0  0  0" xyz="0.0925  -0.035    0.00326" />
    <axis xyz="0  1  0" />
    <limit effort="0.0" lower="-3.14159265359" upper="3.14159265359" velocity="0.0" />
  </joint>
  <joint name="spine_joint" type="revolute">
    <parent link="bike" />
    <child link="torso" />
    <origin rpy="0  0  0" xyz="0.22048 -0.01442  0.69498" />
    <axis xyz="0.01953  0      -0.9998" />
    <limit effort="0.0" lower="-0.523598775598" upper="0.523598775598" velocity="0.0" />
  </joint>
  <joint name="joint_wheel_left" type="revolute">
    <parent link="front_part" />
    <child link="left_wheel" />
    <origin rpy="0  0  0" xyz="-0.052  -0.304   0.0345" />
    <axis xyz="0 -1  0" />
    <limit effort="0.0" lower="-3.14159265359" upper="3.14159265359" velocity="0.0" />
  </joint>
  <joint name="joint_front" type="revolute">
    <parent link="bike" />
    <child link="front_part" />
    <origin rpy="0  0  0" xyz="-0.94642  0       0.01116" />
    <axis xyz="0  0  1" />
    <limit effort="0.0" lower="-0.523598775598" upper="0.523598775598" velocity="0.0" />
  </joint>
  <joint name="elbow_right_rot1" type="revolute">
    <parent link="elbow_right" />
    <child link="lower_arm_right" />
    <origin rpy="0  0  0" xyz="0.0068   0.03837 -0.05667" />
    <axis xyz="-0.03688 -0.7578   0.65143" />
    <limit effort="0.0" lower="-1.57079632679" upper="1.57079632679" velocity="0.0" />
  </joint>
  <joint name="joint_hip_left" type="revolute">
    <parent link="bike" />
    <child link="thigh_left" />
    <origin rpy="0  0  0" xyz="0.2245  -0.20207  0.48902" />
    <axis xyz="0 -1  0" />
    <limit effort="0.0" lower="-1.9" upper="0.4" velocity="0.0" />
  </joint>
  <joint name="joint_hip_right" type="revolute">
    <parent link="bike" />
    <child link="thigh_right" />
    <origin rpy="0  0  0" xyz="0.2245   0.16192  0.48902" />
    <axis xyz="0 -1  0" />
    <limit effort="0.0" lower="-1.9" upper="0.4" velocity="0.0" />
  </joint>
  <joint name="joint_knee_left" type="revolute">
    <parent link="thigh_left" />
    <child link="leg_left" />
    <origin rpy="0  0  0" xyz="0.01653  0.02405 -0.30873" />
    <axis xyz="0 -1  0" />
    <limit effort="0.0" lower="0.0" upper="2.6" velocity="0.0" />
  </joint>
  <joint name="joint_knee_right" type="revolute">
    <parent link="thigh_right" />
    <child link="leg_right" />
    <origin rpy="0  0  0" xyz="0.01603  0.0077  -0.30874" />
    <axis xyz="0  1  0" />
    <limit effort="0.0" lower="-2.6" upper="0.0" velocity="0.0" />
  </joint>
  <joint name="joint_foot_left" type="revolute">
    <parent link="leg_left" />
    <child link="foot_left" />
    <origin rpy="0  0  0" xyz="-0.00318  0.0135  -0.34912" />
    <axis xyz="0  1  0" />
    <limit effort="0.0" lower="-0.6" upper="0.6" velocity="0.0" />
  </joint>
  <joint name="joint_foot_left_tip" type="revolute">
    <parent link="foot_left" />
    <child link="foot_left_tip" />
    <origin rpy="0  0  0" xyz="-0.06158 -0.024   -0.03743" />
    <axis xyz="0  0  0" />
    <limit effort="0" lower="0" upper="0" velocity="0" />
  </joint>
  <joint name="joint_foot_right" type="revolute">
    <parent link="leg_right" />
    <child link="foot_right" />
    <origin rpy="0  0  0" xyz="0       0.0135  -0.34914" />
    <axis xyz="0  1  0" />
    <limit effort="0.0" lower="-0.6" upper="0.6" velocity="0.0" />
  </joint>
  <joint name="joint_foot_right_tip" type="revolute">
    <parent link="foot_right" />
    <child link="foot_right_tip" />
    <origin rpy="0  0  0" xyz="-0.06197 -0.024   -0.03679" />
    <axis xyz="0  0  0" />
    <limit effort="0" lower="0" upper="0" velocity="0" />
  </joint>
  <joint name="joint_pedal_right" type="revolute">
    <parent link="kurbel" />
    <child link="pedal_right" />
    <origin rpy="0  0  0" xyz="-0.01468  0.22498  0.16854" />
    <axis xyz="0  1  0" />
    <limit effort="0.0" lower="-3.14159265359" upper="3.14159265359" velocity="0.0" />
  </joint>
  <joint name="joint_pedal_left" type="revolute">
    <parent link="kurbel" />
    <child link="pedal_left" />
    <origin rpy="0  0  0" xyz="0.01482 -0.15624 -0.16858" />
    <axis xyz="0 -1  0" />
    <limit effort="0.0" lower="-3.14159265359" upper="3.14159265359" velocity="0.0" />
  </joint>
  <link name="bike">
    <inertial>
      <mass value="21.819480362884757" />
      <origin rpy="0  0  0" xyz="0  0  0" />
      <inertia ixx="5.88647979750313" ixy="0.052466044382052206" ixz="0.14605356512826828" iyy="9.145452768014158" iyz="-2.309312656009525" izz="3.8627003582898043" />
    </inertial>
    <collision name="bike_collision">
      <origin rpy="0  0  0" xyz="0  0  0" />
      <geometry>
        <mesh filename="package://robots/rikshaw/meshes/collisions/bike.stl" scale="0.001 0.001 0.001" />
      </geometry>
    </collision>
    <visual name="bike_visual">
      <origin rpy="0  0  0" xyz="0  0  0" />
      <geometry>
        <mesh filename="package://robots/rikshaw/meshes/visuals/bike.stl" scale="0.001 0.001 0.001" />
      </geometry>
    </visual>
  </link>
  <link name="upper_arm_right">
    <inertial>
      <mass value="1.09455247923321" />
      <origin rpy="0  0  0" xyz="0.00388  0.1226  -0.08951" />
      <inertia ixx="1.442114635113044" ixy="-0.09774756907521549" ixz="-0.4688761464900038" iyy="1.3199752604716208" iyz="-0.2618914755705522" izz="0.23432575661628963" />
    </inertial>
    <collision name="upper_arm_right_collision">
      <origin rpy="0  0  0" xyz="0.00388  0.1226  -0.08951" />
      <geometry>
        <mesh filename="package://robots/rikshaw/meshes/collisions/upper_arm_right.stl" scale="0.001 0.001 0.001" />
      </geometry>
    </collision>
    <visual name="upper_arm_right_visual">
      <origin rpy="0  0  0" xyz="0.00388  0.1226  -0.08951" />
      <geometry>
        <mesh filename="package://robots/rikshaw/meshes/visuals/upper_arm_right.stl" scale="0.001 0.001 0.001" />
      </geometry>
    </visual>
  </link>
  <link name="torso">
    <inertial>
      <mass value="12.829176243663477" />
      <origin rpy="0  0  0" xyz="-0.22048  0.01442 -0.69498" />
      <inertia ixx="17.25650105427057" ixy="0.04356904654679028" ixz="0.24048016421448187" iyy="17.518102091652363" iyz="-2.951529784014056" izz="0.8597292911212528" />
    </inertial>
    <collision name="torso_collision">
      <origin rpy="0  0  0" xyz="-0.22048  0.01442 -0.69498" />
      <geometry>
        <mesh filename="package://robots/rikshaw/meshes/collisions/torso.stl" scale="0.001 0.001 0.001" />
      </geometry>
    </collision>
    <visual name="torso_visual">
      <origin rpy="0  0  0" xyz="-0.22048  0.01442 -0.69498" />
      <geometry>
        <mesh filename="package://robots/rikshaw/meshes/visuals/torso.stl" scale="0.001 0.001 0.001" />
      </geometry>
    </visual>
  </link>
  <link name="front_part">
    <inertial>
      <mass value="16.81067246564987" />
      <origin rpy="0  0  0" xyz="0.23003  0.01038  0.20527" />
      <inertia ixx="3.20922967583295" ixy="0.1811361599346656" ixz="-0.006723082654580219" iyy="14.662960288859963" iyz="1.2419706811357931" izz="13.912919701383359" />
    </inertial>
    <collision name="front_part_collision">
      <origin rpy="0  0  0" xyz="0.23003  0.01038  0.20527" />
      <geometry>
        <mesh filename="package://robots/rikshaw/meshes/collisions/front_part.stl" scale="0.001 0.001 0.001" />
      </geometry>
    </collision>
    <visual name="front_part_visual">
      <origin rpy="0  0  0" xyz="0.23003  0.01038  0.20527" />
      <geometry>
        <mesh filename="package://robots/rikshaw/meshes/visuals/front_part.stl" scale="0.001 0.001 0.001" />
      </geometry>
    </visual>
  </link>
  <link name="left_wheel">
    <inertial>
      <mass value="13.340163929097853" />
      <origin rpy="0  0  0" xyz="0    -0.046  0" />
      <inertia ixx="2.1711695314274517" ixy="-4.661713033463329" ixz="0.21322209220250807" iyy="14.342326161889547" iyz="0.608246286975286" izz="15.441547158388715" />
    </inertial>
    <collision name="left_wheel_collision">
      <origin rpy="0  0  0" xyz="0    -0.046  0" />
      <geometry>
        <mesh filename="package://robots/rikshaw/meshes/collisions/left_wheel.stl" scale="0.001 0.001 0.001" />
      </geometry>
    </collision>
    <visual name="left_wheel_visual">
      <origin rpy="0  0  0" xyz="0    -0.046  0" />
      <geometry>
        <mesh filename="package://robots/rikshaw/meshes/visuals/left_wheel.stl" scale="0.001 0.001 0.001" />
      </geometry>
    </visual>
  </link>
  <link name="right_wheel">
    <inertial>
      <mass value="13.340163929097852" />
      <origin rpy="0  0  0" xyz="0     0.004  0" />
      <inertia ixx="2.0973170247321944" ixy="4.555157860544093" ixz="-0.20834836515382574" iyy="14.34232616188958" iyz="0.608246286975689" izz="15.367694651693421" />
    </inertial>
    <collision name="right_wheel_collision">
      <origin rpy="0  0  0" xyz="0     0.004  0" />
      <geometry>
        <mesh filename="package://robots/rikshaw/meshes/collisions/right_wheel.stl" scale="0.001 0.001 0.001" />
      </geometry>
    </collision>
    <visual name="right_wheel_visual">
      <origin rpy="0  0  0" xyz="0     0.004  0" />
      <geometry>
        <mesh filename="package://robots/rikshaw/meshes/visuals/right_wheel.stl" scale="0.001 0.001 0.001" />
      </geometry>
    </visual>
  </link>
  <link name="pedal_right">
    <inertial>
      <mass value="0.946002588602011" />
      <origin rpy="0  0  0" xyz="4.00000000e-05  -4.20000000e-02   6.00000000e-05" />
      <inertia ixx="0.049584952858415854" ixy="-0.010901175565176115" ixz="-0.024062204564554247" iyy="0.03409659621083961" iyz="-0.012633073677194028" izz="0.02706062629596726" />
    </inertial>
    <collision name="pedal_right_collision">
      <origin rpy="0  0  0" xyz="4.00000000e-05  -4.20000000e-02   6.00000000e-05" />
      <geometry>
        <mesh filename="package://robots/rikshaw/meshes/collisions/pedal_right.stl" scale="0.001 0.001 0.001" />
      </geometry>
    </collision>
    <visual name="pedal_right_visual">
      <origin rpy="0  0  0" xyz="4.00000000e-05  -4.20000000e-02   6.00000000e-05" />
      <geometry>
        <mesh filename="package://robots/rikshaw/meshes/visuals/pedal_right.stl" scale="0.001 0.001 0.001" />
      </geometry>
    </visual>
  </link>
  <link name="kurbel">
    <inertial>
      <mass value="2.7832708381108002" />
      <origin rpy="0  0  0" xyz="-0.00027  0.03513  0.001" />
      <inertia ixx="0.03321525556564324" ixy="0.0010218101556732108" ixz="-0.012937192477662387" iyy="0.04158688185273832" iyz="0.00030143634944108515" izz="0.039731070916127355" />
    </inertial>
    <collision name="kurbel_collision">
      <origin rpy="0  0  0" xyz="-0.00027  0.03513  0.001" />
      <geometry>
        <mesh filename="package://robots/rikshaw/meshes/collisions/kurbel.stl" scale="0.001 0.001 0.001" />
      </geometry>
    </collision>
    <visual name="kurbel_visual">
      <origin rpy="0  0  0" xyz="-0.00027  0.03513  0.001" />
      <geometry>
        <mesh filename="package://robots/rikshaw/meshes/visuals/kurbel.stl" scale="0.001 0.001 0.001" />
      </geometry>
    </visual>
  </link>
  <link name="pedal_left">
    <inertial>
      <mass value="0.9460025886020074" />
      <origin rpy="0  0  0" xyz="5.00000000e-05   4.20000000e-02  -5.00000000e-05" />
      <inertia ixx="0.0478650709459344" ixy="0.015160685733445756" ixz="-0.02334903344265402" iyy="0.037196017563940593" iyz="0.016827373941817436" izz="0.032585937449107163" />
    </inertial>
    <collision name="pedal_left_collision">
      <origin rpy="0  0  0" xyz="5.00000000e-05   4.20000000e-02  -5.00000000e-05" />
      <geometry>
        <mesh filename="package://robots/rikshaw/meshes/collisions/pedal_left.stl" scale="0.001 0.001 0.001" />
      </geometry>
    </collision>
    <visual name="pedal_left_visual">
      <origin rpy="0  0  0" xyz="5.00000000e-05   4.20000000e-02  -5.00000000e-05" />
      <geometry>
        <mesh filename="package://robots/rikshaw/meshes/visuals/pedal_left.stl" scale="0.001 0.001 0.001" />
      </geometry>
    </visual>
  </link>
  <link name="foot_left">
    <inertial>
      <mass value="0.729398908095776" />
      <origin rpy="0  0  0" xyz="-0.06202 -0.024   -0.03764" />
      <inertia ixx="0.054071148495108426" ixy="0.03251558359012369" ixz="-0.0267607053444042" iyy="0.06910655839384243" iyz="0.0335724905553697" izz="0.06736985121094373" />
    </inertial>
    <collision name="foot_left_collision">
      <origin rpy="0  0  0" xyz="-0.06202 -0.024   -0.03764" />
      <geometry>
        <mesh filename="package://robots/rikshaw/meshes/collisions/foot_left.stl" scale="0.001 0.001 0.001" />
      </geometry>
    </collision>
    <visual name="foot_left_visual">
      <origin rpy="0  0  0" xyz="-0.06202 -0.024   -0.03764" />
      <geometry>
        <mesh filename="package://robots/rikshaw/meshes/visuals/foot_left.stl" scale="0.001 0.001 0.001" />
      </geometry>
    </visual>
  </link>
  <link name="foot_left_tip">
    <inertial>
      <mass value="0.2779608699489159" />
      <origin rpy="0  0  0" xyz="-0.04104  0.00116 -0.00588" />
      <inertia ixx="0.022352432140469582" ixy="0.007051209655785971" ixz="-0.011047918197745182" iyy="0.017709776432523597" iyz="0.007965691481929648" izz="0.015032605387340966" />
    </inertial>
    <collision name="foot_left_tip_collision">
      <origin rpy="0  0  0" xyz="-0.04104  0.00116 -0.00588" />
      <geometry>
        <mesh filename="package://robots/rikshaw/meshes/collisions/foot_left_tip.stl" scale="0.001 0.001 0.001" />
      </geometry>
    </collision>
    <visual name="foot_left_tip_visual">
      <origin rpy="0  0  0" xyz="-0.04104  0.00116 -0.00588" />
      <geometry>
        <mesh filename="package://robots/rikshaw/meshes/visuals/foot_left_tip.stl" scale="0.001 0.001 0.001" />
      </geometry>
    </visual>
  </link>
  <link name="foot_right">
    <inertial>
      <mass value="0.7293896455411302" />
      <origin rpy="0  0  0" xyz="-0.06298 -0.0235  -0.03601" />
      <inertia ixx="0.04662856715772369" ixy="-0.027737155016923216" ixz="0.022589445195432944" iyy="0.06999772599908857" iyz="0.03393990029859617" izz="0.06080289056176407" />
    </inertial>
    <collision name="foot_right_collision">
      <origin rpy="0  0  0" xyz="-0.06298 -0.0235  -0.03601" />
      <geometry>
        <mesh filename="package://robots/rikshaw/meshes/collisions/foot_right.stl" scale="0.001 0.001 0.001" />
      </geometry>
    </collision>
    <visual name="foot_right_visual">
      <origin rpy="0  0  0" xyz="-0.06298 -0.0235  -0.03601" />
      <geometry>
        <mesh filename="package://robots/rikshaw/meshes/visuals/foot_right.stl" scale="0.001 0.001 0.001" />
      </geometry>
    </visual>
  </link>
  <link name="foot_right_tip">
    <inertial>
      <mass value="0.2779507369992495" />
      <origin rpy="0  0  0" xyz="-0.04109 -0.00116 -0.00545" />
      <inertia ixx="0.01940696459090884" ixy="-0.006044281399509727" ixz="0.00926827632383988" iyy="0.017755497306462906" iyz="0.008058438745184105" izz="0.012380586242452805" />
    </inertial>
    <collision name="foot_right_tip_collision">
      <origin rpy="0  0  0" xyz="-0.04109 -0.00116 -0.00545" />
      <geometry>
        <mesh filename="package://robots/rikshaw/meshes/collisions/foot_right_tip.stl" scale="0.001 0.001 0.001" />
      </geometry>
    </collision>
    <visual name="foot_right_tip_visual">
      <origin rpy="0  0  0" xyz="-0.04109 -0.00116 -0.00545" />
      <geometry>
        <mesh filename="package://robots/rikshaw/meshes/visuals/foot_right_tip.stl" scale="0.001 0.001 0.001" />
      </geometry>
    </visual>
  </link>
  <link name="thigh_right">
    <inertial>
      <mass value="5.563526842051087" />
      <origin rpy="0  0  0" xyz="0.0043   0.0219  -0.11113" />
      <inertia ixx="1.010776410644986" ixy="-0.23394788163488325" ixz="-0.38955605197647547" iyy="1.116930895029097" iyz="-0.4818325951246939" izz="0.4914242463875166" />
    </inertial>
    <collision name="thigh_right_collision">
      <origin rpy="0  0  0" xyz="0.0043   0.0219  -0.11113" />
      <geometry>
        <mesh filename="package://robots/rikshaw/meshes/collisions/thigh_right.stl" scale="0.001 0.001 0.001" />
      </geometry>
    </collision>
    <visual name="thigh_right_visual">
      <origin rpy="0  0  0" xyz="0.0043   0.0219  -0.11113" />
      <geometry>
        <mesh filename="package://robots/rikshaw/meshes/visuals/thigh_right.stl" scale="0.001 0.001 0.001" />
      </geometry>
    </visual>
  </link>
  <link name="thigh_left">
    <inertial>
      <mass value="5.56358906512719" />
      <origin rpy="0  0  0" xyz="0.00477 -0.01055 -0.11112" />
      <inertia ixx="1.0743469445640734" ixy="0.2706115436993354" ixz="0.4500933625889936" iyy="1.1181844164691626" iyz="-0.4831067929963112" izz="0.5561292948599905" />
    </inertial>
    <collision name="thigh_left_collision">
      <origin rpy="0  0  0" xyz="0.00477 -0.01055 -0.11112" />
      <geometry>
        <mesh filename="package://robots/rikshaw/meshes/collisions/thigh_left.stl" scale="0.001 0.001 0.001" />
      </geometry>
    </collision>
    <visual name="thigh_left_visual">
      <origin rpy="0  0  0" xyz="0.00477 -0.01055 -0.11112" />
      <geometry>
        <mesh filename="package://robots/rikshaw/meshes/visuals/thigh_left.stl" scale="0.001 0.001 0.001" />
      </geometry>
    </visual>
  </link>
  <link name="leg_right">
    <inertial>
      <mass value="5.741522183296272" />
      <origin rpy="0  0  0" xyz="-0.00763  0.01363 -0.15031" />
      <inertia ixx="0.23781953163587924" ixy="-0.24551774910333893" ixz="-0.03496958960490945" iyy="0.3593991546848349" iyz="-0.03759074399885916" izz="0.5167551685561281" />
    </inertial>
    <collision name="leg_right_collision">
      <origin rpy="0  0  0" xyz="-0.00763  0.01363 -0.15031" />
      <geometry>
        <mesh filename="package://robots/rikshaw/meshes/collisions/leg_right.stl" scale="0.001 0.001 0.001" />
      </geometry>
    </collision>
    <visual name="leg_right_visual">
      <origin rpy="0  0  0" xyz="-0.00763  0.01363 -0.15031" />
      <geometry>
        <mesh filename="package://robots/rikshaw/meshes/visuals/leg_right.stl" scale="0.001 0.001 0.001" />
      </geometry>
    </visual>
  </link>
  <link name="leg_left">
    <inertial>
      <mass value="5.7426173662328" />
      <origin rpy="0  0  0" xyz="-0.00899 -0.03366 -0.1502" />
      <inertia ixx="0.3024368006754475" ixy="0.28199913616735084" ixz="0.040011871670719415" iyy="0.357202809628062" iyz="-0.03813052890420756" izz="0.5789432910018966" />
    </inertial>
    <collision name="leg_left_collision">
      <origin rpy="0  0  0" xyz="-0.00899 -0.03366 -0.1502" />
      <geometry>
        <mesh filename="package://robots/rikshaw/meshes/collisions/leg_left.stl" scale="0.001 0.001 0.001" />
      </geometry>
    </collision>
    <visual name="leg_left_visual">
      <origin rpy="0  0  0" xyz="-0.00899 -0.03366 -0.1502" />
      <geometry>
        <mesh filename="package://robots/rikshaw/meshes/visuals/leg_left.stl" scale="0.001 0.001 0.001" />
      </geometry>
    </visual>
  </link>
  <link name="wheel_back">
    <inertial>
      <mass value="13.340163929098475" />
      <origin rpy="0  0  0" xyz="0     0.069  0" />
      <inertia ixx="0.5419188938328752" ixy="-0.02542584611932503" ixz="-0.0023401868697195947" iyy="4.894303401629515" iyz="-0.3539312731878215" izz="4.3547634684642125" />
    </inertial>
    <collision name="wheel_back_collision">
      <origin rpy="0  0  0" xyz="0     0.069  0" />
      <geometry>
        <mesh filename="package://robots/rikshaw/meshes/collisions/wheel_back.stl" scale="0.001 0.001 0.001" />
      </geometry>
    </collision>
    <visual name="wheel_back_visual">
      <origin rpy="0  0  0" xyz="0     0.069  0" />
      <geometry>
        <mesh filename="package://robots/rikshaw/meshes/visuals/wheel_back.stl" scale="0.001 0.001 0.001" />
      </geometry>
    </visual>
  </link>
  <link name="elbow_left">
    <inertial>
      <mass value="0.15681540300142793" />
      <origin rpy="0  0  0" xyz="0.00614 -0.01903 -0.03504" />
      <inertia ixx="0.19266629452448158" ixy="0.0195417941766464" ixz="0.08195067997388937" iyy="0.1552331044117411" iyz="-0.03499484398504671" izz="0.054226846547573475" />
    </inertial>
    <collision name="elbow_left_collision">
      <origin rpy="0  0  0" xyz="0.00614 -0.01903 -0.03504" />
      <geometry>
        <mesh filename="package://robots/rikshaw/meshes/collisions/elbow_left.stl" scale="0.001 0.001 0.001" />
      </geometry>
    </collision>
    <visual name="elbow_left_visual">
      <origin rpy="0  0  0" xyz="0.00614 -0.01903 -0.03504" />
      <geometry>
        <mesh filename="package://robots/rikshaw/meshes/visuals/elbow_left.stl" scale="0.001 0.001 0.001" />
      </geometry>
    </visual>
  </link>
  <link name="elbow_right">
    <inertial>
      <mass value="0.17350645372007023" />
      <origin rpy="0  0  0" xyz="0.00618  0.02031 -0.03655" />
      <inertia ixx="0.20750006127745746" ixy="-0.020569149555644393" ixz="-0.08601032502390117" iyy="0.17091901706305593" iyz="-0.03862989297418956" izz="0.055162497229075506" />
    </inertial>
    <collision name="elbow_right_collision">
      <origin rpy="0  0  0" xyz="0.00618  0.02031 -0.03655" />
      <geometry>
        <mesh filename="package://robots/rikshaw/meshes/collisions/elbow_right.stl" scale="0.001 0.001 0.001" />
      </geometry>
    </collision>
    <visual name="elbow_right_visual">
      <origin rpy="0  0  0" xyz="0.00618  0.02031 -0.03655" />
      <geometry>
        <mesh filename="package://robots/rikshaw/meshes/visuals/elbow_right.stl" scale="0.001 0.001 0.001" />
      </geometry>
    </visual>
  </link>
  <link name="left_shoulder_link1">
    <inertial>
      <mass value="0.046753530242572526" />
      <origin rpy="0  0  0" xyz="0  0  0" />
      <inertia ixx="0.06767403176162043" ixy="0.0031396290483470734" ixz="0.016675979709794873" iyy="0.06552178683987907" iyz="-0.011912569008629326" izz="0.006643838018602061" />
    </inertial>
    <collision name="left_shoulder_link1_collision">
      <origin rpy="0  0  0" xyz="0  0  0" />
      <geometry>
        <mesh filename="package://robots/rikshaw/meshes/collisions/left_shoulder_link1.stl" scale="0.001 0.001 0.001" />
      </geometry>
    </collision>
    <visual name="left_shoulder_link1_visual">
      <origin rpy="0  0  0" xyz="0  0  0" />
      <geometry>
        <mesh filename="package://robots/rikshaw/meshes/visuals/left_shoulder_link1.stl" scale="0.001 0.001 0.001" />
      </geometry>
    </visual>
  </link>
  <link name="left_shoulder_link2">
    <inertial>
      <mass value="0.03133730384743737" />
      <origin rpy="0  0  0" xyz="0  0  0" />
      <inertia ixx="0.04535827893996492" ixy="0.0021043777578654633" ixz="0.011177303220150906" iyy="0.043915721516588194" iyz="-0.00798458486619213" izz="0.004451810061398645" />
    </inertial>
    <collision name="left_shoulder_link2_collision">
      <origin rpy="0  0  0" xyz="0  0  0" />
      <geometry>
        <mesh filename="package://robots/rikshaw/meshes/collisions/left_shoulder_link2.stl" scale="0.001 0.001 0.001" />
      </geometry>
    </collision>
    <visual name="left_shoulder_link2_visual">
      <origin rpy="0  0  0" xyz="0  0  0" />
      <geometry>
        <mesh filename="package://robots/rikshaw/meshes/visuals/left_shoulder_link2.stl" scale="0.001 0.001 0.001" />
      </geometry>
    </visual>
  </link>
  <link name="wrist_left_1">
    <inertial>
      <mass value="0.012762217633342557" />
      <origin rpy="0  0  0" xyz="0.00041 -0.00553  0.00829" />
      <inertia ixx="0.014959120890854383" ixy="0.002324972046736957" ixz="0.007477062127211706" iyy="0.008400753322856894" iyz="-0.0023811669065757295" izz="0.008043969436768382" />
    </inertial>
    <collision name="wrist_left_1_collision">
      <origin rpy="0  0  0" xyz="0.00041 -0.00553  0.00829" />
      <geometry>
        <mesh filename="package://robots/rikshaw/meshes/collisions/wrist_left_1.stl" scale="0.001 0.001 0.001" />
      </geometry>
    </collision>
    <visual name="wrist_left_1_visual">
      <origin rpy="0  0  0" xyz="0.00041 -0.00553  0.00829" />
      <geometry>
        <mesh filename="package://robots/rikshaw/meshes/visuals/wrist_left_1.stl" scale="0.001 0.001 0.001" />
      </geometry>
    </visual>
  </link>
  <link name="left_hand">
    <inertial>
      <mass value="0.08391816593462983" />
      <origin rpy="0  0  0" xyz="0.02378 -0.0557  -0.05642" />
      <inertia ixx="0.09909320434120036" ixy="0.016915090376039513" ixz="0.048980966391204535" iyy="0.048505356256449084" iyz="-0.01487737090918695" izz="0.06095877796136134" />
    </inertial>
    <collision name="left_hand_collision">
      <origin rpy="0  0  0" xyz="0.02378 -0.0557  -0.05642" />
      <geometry>
        <mesh filename="package://robots/rikshaw/meshes/collisions/left_hand.stl" scale="0.001 0.001 0.001" />
      </geometry>
    </collision>
    <visual name="left_hand_visual">
      <origin rpy="0  0  0" xyz="0.02378 -0.0557  -0.05642" />
      <geometry>
        <mesh filename="package://robots/rikshaw/meshes/visuals/left_hand.stl" scale="0.001 0.001 0.001" />
      </geometry>
    </visual>
  </link>
  <link name="wrist_right_1">
    <inertial>
      <mass value="0.012761782896867233" />
      <origin rpy="0  0  0" xyz="0.0002   0.00591  0.00952" />
      <inertia ixx="0.014495291225078663" ixy="-0.002252026307743208" ixz="-0.007235743263019458" iyy="0.008400173050448542" iyz="-0.0023827992689265253" izz="0.007583137992308799" />
    </inertial>
    <collision name="wrist_right_1_collision">
      <origin rpy="0  0  0" xyz="0.0002   0.00591  0.00952" />
      <geometry>
        <mesh filename="package://robots/rikshaw/meshes/collisions/wrist_right_1.stl" scale="0.001 0.001 0.001" />
      </geometry>
    </collision>
    <visual name="wrist_right_1_visual">
      <origin rpy="0  0  0" xyz="0.0002   0.00591  0.00952" />
      <geometry>
        <mesh filename="package://robots/rikshaw/meshes/visuals/wrist_right_1.stl" scale="0.001 0.001 0.001" />
      </geometry>
    </visual>
  </link>
  <link name="right_hand">
    <inertial>
      <mass value="0.08391622141997471" />
      <origin rpy="0  0  0" xyz="-0.0123   0.06191 -0.05179" />
      <inertia ixx="0.09673331577568908" ixy="-0.016427975920384325" ixz="-0.04797429263668558" iyy="0.0488785196891631" iyz="-0.014904711928062248" izz="0.05815012342983344" />
    </inertial>
    <collision name="right_hand_collision">
      <origin rpy="0  0  0" xyz="-0.0123   0.06191 -0.05179" />
      <geometry>
        <mesh filename="package://robots/rikshaw/meshes/collisions/right_hand.stl" scale="0.001 0.001 0.001" />
      </geometry>
    </collision>
    <visual name="right_hand_visual">
      <origin rpy="0  0  0" xyz="-0.0123   0.06191 -0.05179" />
      <geometry>
        <mesh filename="package://robots/rikshaw/meshes/visuals/right_hand.stl" scale="0.001 0.001 0.001" />
      </geometry>
    </visual>
  </link>
  <link name="upper_arm_left">
    <inertial>
      <mass value="1.1803838170765908" />
      <origin rpy="0  0  0" xyz="0.00627 -0.12298 -0.08898" />
      <inertia ixx="1.5852445346771415" ixy="0.11434979829456188" ixz="0.5429329624802077" iyy="1.4261073107265458" iyz="-0.2855827227702544" izz="0.2826521534806978" />
    </inertial>
    <collision name="upper_arm_left_collision">
      <origin rpy="0  0  0" xyz="0.00627 -0.12298 -0.08898" />
      <geometry>
        <mesh filename="package://robots/rikshaw/meshes/collisions/upper_arm_left.stl" scale="0.001 0.001 0.001" />
      </geometry>
    </collision>
    <visual name="upper_arm_left_visual">
      <origin rpy="0  0  0" xyz="0.00627 -0.12298 -0.08898" />
      <geometry>
        <mesh filename="package://robots/rikshaw/meshes/visuals/upper_arm_left.stl" scale="0.001 0.001 0.001" />
      </geometry>
    </visual>
  </link>
  <link name="lower_arm_left">
    <inertial>
      <mass value="1.4159186820902163" />
      <origin rpy="0  0  0" xyz="0.00442 -0.09092 -0.07847" />
      <inertia ixx="1.6711043720010217" ixy="0.21726236762087098" ixz="0.7959155751126917" iyy="1.1476118832729991" iyz="-0.28939502407711376" izz="0.6821912770654517" />
    </inertial>
    <collision name="lower_arm_left_collision">
      <origin rpy="0  0  0" xyz="0.00442 -0.09092 -0.07847" />
      <geometry>
        <mesh filename="package://robots/rikshaw/meshes/collisions/lower_arm_left.stl" scale="0.001 0.001 0.001" />
      </geometry>
    </collision>
    <visual name="lower_arm_left_visual">
      <origin rpy="0  0  0" xyz="0.00442 -0.09092 -0.07847" />
      <geometry>
        <mesh filename="package://robots/rikshaw/meshes/visuals/lower_arm_left.stl" scale="0.001 0.001 0.001" />
      </geometry>
    </visual>
  </link>
  <link name="lower_arm_right">
    <inertial>
      <mass value="1.3992272098428604" />
      <origin rpy="0  0  0" xyz="0.00456  0.09373 -0.08064" />
      <inertia ixx="1.5991623337798295" ixy="-0.2066261893802688" ixz="-0.753684363769014" iyy="1.1265213782473609" iyz="-0.28515053749097663" izz="0.6296965516831181" />
    </inertial>
    <collision name="lower_arm_right_collision">
      <origin rpy="0  0  0" xyz="0.00456  0.09373 -0.08064" />
      <geometry>
        <mesh filename="package://robots/rikshaw/meshes/collisions/lower_arm_right.stl" scale="0.001 0.001 0.001" />
      </geometry>
    </collision>
    <visual name="lower_arm_right_visual">
      <origin rpy="0  0  0" xyz="0.00456  0.09373 -0.08064" />
      <geometry>
        <mesh filename="package://robots/rikshaw/meshes/visuals/lower_arm_right.stl" scale="0.001 0.001 0.001" />
      </geometry>
    </visual>
  </link>
  <link name="right_shoulder_link1">
    <inertial>
      <mass value="0.046749002886596384" />
      <origin rpy="0  0  0" xyz="0  0  0" />
      <inertia ixx="0.0668796020851593" ixy="-0.0028436269903427762" ixz="-0.015105873634725039" iyy="0.06551483087487732" iyz="-0.011909766198106813" izz="0.005854687475636317" />
    </inertial>
    <collision name="right_shoulder_link1_collision">
      <origin rpy="0  0  0" xyz="0  0  0" />
      <geometry>
        <mesh filename="package://robots/rikshaw/meshes/collisions/right_shoulder_link1.stl" scale="0.001 0.001 0.001" />
      </geometry>
    </collision>
    <visual name="right_shoulder_link1_visual">
      <origin rpy="0  0  0" xyz="0  0  0" />
      <geometry>
        <mesh filename="package://robots/rikshaw/meshes/visuals/right_shoulder_link1.stl" scale="0.001 0.001 0.001" />
      </geometry>
    </visual>
  </link>
  <link name="right_shoulder_link2">
    <inertial>
      <mass value="0.031337303847116804" />
      <origin rpy="0  0  0" xyz="0  0  0" />
      <inertia ixx="0.044830156212659796" ixy="-0.0019061688408127894" ixz="-0.01012592262164037" iyy="0.043915313236125075" iyz="-0.007983484644614952" izz="0.003923266667258534" />
    </inertial>
    <collision name="right_shoulder_link2_collision">
      <origin rpy="0  0  0" xyz="0  0  0" />
      <geometry>
        <mesh filename="package://robots/rikshaw/meshes/collisions/right_shoulder_link2.stl" scale="0.001 0.001 0.001" />
      </geometry>
    </collision>
    <visual name="right_shoulder_link2_visual">
      <origin rpy="0  0  0" xyz="0  0  0" />
      <geometry>
        <mesh filename="package://robots/rikshaw/meshes/visuals/right_shoulder_link2.stl" scale="0.001 0.001 0.001" />
      </geometry>
    </visual>
  </link>
  <link name="zed_camera_left_lense">
    <inertial>
      <mass value="0.005755421818056277" />
      <origin rpy="0  0  0" xyz="-1.13100000e-02  -2.00000000e-05  -2.20000000e-04" />
      <inertia ixx="0.013251176831653201" ixy="3.8768589463782255e-05" ixz="0.0006491587768829331" iyy="0.013266636501492101" iyz="-0.0007894656460929536" izz="7.942719339666764e-05" />
    </inertial>
    <collision name="zed_camera_left_lense_collision">
      <origin rpy="0  0  0" xyz="-1.13100000e-02  -2.00000000e-05  -2.20000000e-04" />
      <geometry>
        <mesh filename="package://robots/rikshaw/meshes/collisions/zed_camera_left_lense.stl" scale="0.001 0.001 0.001" />
      </geometry>
    </collision>
    <visual name="zed_camera_left_lense_visual">
      <origin rpy="0  0  0" xyz="-1.13100000e-02  -2.00000000e-05  -2.20000000e-04" />
      <geometry>
        <mesh filename="package://robots/rikshaw/meshes/visuals/zed_camera_left_lense.stl" scale="0.001 0.001 0.001" />
      </geometry>
    </visual>
  </link>
  <link name="zed_camera_right_lense">
    <inertial>
      <mass value="0.0057554218180561716" />
      <origin rpy="0  0  0" xyz="-0.01131  0      -0.00022" />
      <inertia ixx="0.013231254412614635" ixy="-2.3742546783151577e-05" ixz="-0.0003975558462797777" iyy="0.013266636502212869" iyz="-0.0007894656461122461" izz="5.950477363678162e-05" />
    </inertial>
    <collision name="zed_camera_right_lense_collision">
      <origin rpy="0  0  0" xyz="-0.01131  0      -0.00022" />
      <geometry>
        <mesh filename="package://robots/rikshaw/meshes/collisions/zed_camera_right_lense.stl" scale="0.001 0.001 0.001" />
      </geometry>
    </collision>
    <visual name="zed_camera_right_lense_visual">
      <origin rpy="0  0  0" xyz="-0.01131  0      -0.00022" />
      <geometry>
        <mesh filename="package://robots/rikshaw/meshes/visuals/zed_camera_right_lense.stl" scale="0.001 0.001 0.001" />
      </geometry>
    </visual>
  </link>
  <link name="zed_camera">
    <inertial>
      <mass value="0.009633908101970077" />
      <origin rpy="0  0  0" xyz="0.00051  0.01744 -0.00814" />
      <inertia ixx="0.022147578635390432" ixy="1.8076394680573262e-05" ixz="0.0002698161379215394" iyy="0.02223019298553041" iyz="-0.0014919337341075076" izz="0.00011860478819208992" />
    </inertial>
    <collision name="zed_camera_collision">
      <origin rpy="0  0  0" xyz="0.00051  0.01744 -0.00814" />
      <geometry>
        <mesh filename="package://robots/rikshaw/meshes/collisions/zed_camera.stl" scale="0.001 0.001 0.001" />
      </geometry>
    </collision>
    <visual name="zed_camera_visual">
      <origin rpy="0  0  0" xyz="0.00051  0.01744 -0.00814" />
      <geometry>
        <mesh filename="package://robots/rikshaw/meshes/visuals/zed_camera.stl" scale="0.001 0.001 0.001" />
      </geometry>
    </visual>
  </link>
  <link name="sphere_head_link1">
    <inertial>
      <mass value="0.0239381008023698" />
      <origin rpy="0  0  0" xyz="0  0  0" />
      <inertia ixx="0.04160499755559109" ixy="7.1914592462645e-05" ixz="0.0004551000613388576" iyy="0.04263872626177148" iyz="-0.006573296422452246" izz="0.0010456442314470246" />
    </inertial>
    <collision name="sphere_head_link1_collision">
      <origin rpy="0  0  0" xyz="0  0  0" />
      <geometry>
        <mesh filename="package://robots/rikshaw/meshes/collisions/sphere_head_link1.stl" scale="0.001 0.001 0.001" />
      </geometry>
    </collision>
    <visual name="sphere_head_link1_visual">
      <origin rpy="0  0  0" xyz="0  0  0" />
      <geometry>
        <mesh filename="package://robots/rikshaw/meshes/visuals/sphere_head_link1.stl" scale="0.001 0.001 0.001" />
      </geometry>
    </visual>
  </link>
  <link name="sphere_head_link2">
    <inertial>
      <mass value="0.016046417516495708" />
      <origin rpy="0  0  0" xyz="0  0  0" />
      <inertia ixx="0.027888633416306888" ixy="4.82064799422182e-05" ixz="0.00030506704171381774" iyy="0.02858157236560378" iyz="-0.004406275156294533" izz="0.0007004983586646301" />
    </inertial>
    <collision name="sphere_head_link2_collision">
      <origin rpy="0  0  0" xyz="0  0  0" />
      <geometry>
        <mesh filename="package://robots/rikshaw/meshes/collisions/sphere_head_link2.stl" scale="0.001 0.001 0.001" />
      </geometry>
    </collision>
    <visual name="sphere_head_link2_visual">
      <origin rpy="0  0  0" xyz="0  0  0" />
      <geometry>
        <mesh filename="package://robots/rikshaw/meshes/visuals/sphere_head_link2.stl" scale="0.001 0.001 0.001" />
      </geometry>
    </visual>
  </link>
  <link name="head">
    <inertial>
      <mass value="2.0664114767603747" />
      <origin rpy="0  0  0" xyz="0.01048 -0.00064  0.15561" />
      <inertia ixx="4.516723647125966" ixy="0.00682006891216185" ixz="0.046026757318554906" iyy="4.620317474855017" iyz="-0.6688033041466639" izz="0.12437320485348337" />
    </inertial>
    <collision name="head_collision">
      <origin rpy="0  0  0" xyz="0.01048 -0.00064  0.15561" />
      <geometry>
        <mesh filename="package://robots/rikshaw/meshes/collisions/head.stl" scale="0.001 0.001 0.001" />
      </geometry>
    </collision>
    <visual name="head_visual">
      <origin rpy="0  0  0" xyz="0.01048 -0.00064  0.15561" />
      <geometry>
        <mesh filename="package://robots/rikshaw/meshes/visuals/head.stl" scale="0.001 0.001 0.001" />
      </geometry>
    </visual>
  </link>
</robot>
