<?xml version="1.0" ?>
<sdf version="1.6">
	<model name="rikshaw">
		<link name="bike">
			<self_collide>false</self_collide>
			<pose frame="">-0.8347147288551219 0.034372244266416344 0.03699999999999589 0.0 -0.0 0.0</pose>
			<inertial>
				<pose frame="">0.0 0.0 0.0 0 0 0</pose>
				<mass>21.813314987301997</mass>
				<inertia>
					<ixx>10.275552951787107</ixx>
					<ixy>-0.013989875106434159</ixy>
					<ixz>-0.2472724707609125</ixz>
					<iyy>13.853123065374536</iyy>
					<iyz>-3.796078472952304</iyz>
					<izz>4.200869439036604</izz>
				</inertia>
			</inertial>
			<collision name="bike_collision">
				<geometry>
					<mesh>
						<uri>model://rikshaw/meshes/CAD/bike.stl</uri>
						<scale>0.001 0.001 0.001</scale>
					</mesh>
				</geometry>
			</collision>
			<visual name="bike_visual">
				<geometry>
					<mesh>
						<uri>model://rikshaw/meshes/CAD/bike.stl</uri>
						<scale>0.001 0.001 0.001</scale>
					</mesh>
				</geometry>
			</visual>
		</link>
		<link name="upper_arm_right">
			<self_collide>false</self_collide>
			<pose frame="">0.33457009175212965 0.4347349710816881 1.2816454241145712 0.0 -0.0 0.0</pose>
			<inertial>
				<pose frame="">0.0 0.0 0.0 0 0 0</pose>
				<mass>1.094552479232937</mass>
				<inertia>
					<ixx>2.009361473024954</ixx>
					<ixy>-0.15927999238941815</ixy>
					<ixz>-0.6081702930098083</ixz>
					<iyy>1.9239533934426856</iyy>
					<iyz>-0.4692767107668228</iyz>
					<izz>0.3338930906950165</izz>
				</inertia>
			</inertial>
			<collision name="upper_arm_right_collision">
				<geometry>
					<mesh>
						<uri>model://rikshaw/meshes/CAD/upper_arm_right.stl</uri>
						<scale>0.001 0.001 0.001</scale>
					</mesh>
				</geometry>
			</collision>
			<visual name="upper_arm_right_visual">
				<geometry>
					<mesh>
						<uri>model://rikshaw/meshes/CAD/upper_arm_right.stl</uri>
						<scale>0.001 0.001 0.001</scale>
					</mesh>
				</geometry>
			</visual>
		</link>
		<link name="torso">
			<self_collide>false</self_collide>
			<pose frame="">0.3109685394055649 0.017547815368009458 1.324266414199839 0.0 -0.0 0.0</pose>
			<inertial>
				<pose frame="">0.0 0.0 0.0 0 0 0</pose>
				<mass>10.567390774387572</mass>
				<inertia>
					<ixx>18.931261294108232</ixx>
					<ixy>-0.05633179125653744</ixy>
					<ixz>-0.24498372786071856</ixz>
					<iyy>19.71302486118391</iyy>
					<iyz>-4.351122150233511</iyz>
					<izz>1.3404190207940572</izz>
				</inertia>
			</inertial>
			<collision name="torso_collision">
				<geometry>
					<mesh>
						<uri>model://rikshaw/meshes/CAD/torso.stl</uri>
						<scale>0.001 0.001 0.001</scale>
					</mesh>
				</geometry>
			</collision>
			<visual name="torso_visual">
				<geometry>
					<mesh>
						<uri>model://rikshaw/meshes/CAD/torso.stl</uri>
						<scale>0.001 0.001 0.001</scale>
					</mesh>
				</geometry>
			</visual>
		</link>
		<link name="front_part">
			<self_collide>false</self_collide>
			<pose frame="">-0.6046185937738651 0.04475872331475336 0.42323667552386796 0.0 -0.0 0.0</pose>
			<inertial>
				<pose frame="">0.0 0.0 0.0 0 0 0</pose>
				<mass>16.813631845520145</mass>
				<inertia>
					<ixx>5.465779053028134</ixx>
					<ixy>0.5110471712217488</ixy>
					<ixz>-0.2874402446427835</ixz>
					<iyy>14.406698754685804</iyy>
					<iyz>2.938162171335791</iyz>
					<izz>11.464360009565059</izz>
				</inertia>
			</inertial>
			<collision name="front_part_collision">
				<geometry>
					<mesh>
						<uri>model://rikshaw/meshes/CAD/front_part.stl</uri>
						<scale>0.001 0.001 0.001</scale>
					</mesh>
				</geometry>
			</collision>
			<visual name="front_part_visual">
				<geometry>
					<mesh>
						<uri>model://rikshaw/meshes/CAD/front_part.stl</uri>
						<scale>0.001 0.001 0.001</scale>
					</mesh>
				</geometry>
			</visual>
		</link>
		<link name="left_wheel">
			<self_collide>false</self_collide>
			<pose frame="">-0.8867148521253287 -0.3156284088111488 0.25250000000001005 0.0 -0.0 0.0</pose>
			<inertial>
				<pose frame="">0.0 0.0 0.0 0 0 0</pose>
				<mass>13.340163929097852</mass>
				<inertia>
					<ixx>2.6886582542943365</ixx>
					<ixy>-3.7335436664890733</ixy>
					<ixz>1.0631600153408756</ixz>
					<iyy>12.355706573664586</iyy>
					<iyz>2.9868026751438275</iyz>
					<izz>12.327019793799991</izz>
				</inertia>
			</inertial>
			<collision name="left_wheel_collision">
				<geometry>
					<mesh>
						<uri>model://rikshaw/meshes/CAD/left_wheel.stl</uri>
						<scale>0.001 0.001 0.001</scale>
					</mesh>
				</geometry>
			</collision>
			<visual name="left_wheel_visual">
				<geometry>
					<mesh>
						<uri>model://rikshaw/meshes/CAD/left_wheel.stl</uri>
						<scale>0.001 0.001 0.001</scale>
					</mesh>
				</geometry>
			</visual>
		</link>
		<link name="right_wheel">
			<self_collide>false</self_collide>
			<pose frame="">-0.8867148521253283 0.37637226941711827 0.25250000000004 0.0 -0.0 0.0</pose>
			<inertial>
				<pose frame="">0.0 0.0 0.0 0 0 0</pose>
				<mass>13.340163929097853</mass>
				<inertia>
					<ixx>3.24940928013889</ixx>
					<ixy>4.4520780243364495</ixy>
					<ixz>-1.2677691125288908</ixz>
					<iyy>12.355706573664742</iyy>
					<iyz>2.9868026751441725</iyz>
					<izz>12.887770819644302</izz>
				</inertia>
			</inertial>
			<collision name="right_wheel_collision">
				<geometry>
					<mesh>
						<uri>model://rikshaw/meshes/CAD/right_wheel.stl</uri>
						<scale>0.001 0.001 0.001</scale>
					</mesh>
				</geometry>
			</collision>
			<visual name="right_wheel_visual">
				<geometry>
					<mesh>
						<uri>model://rikshaw/meshes/CAD/right_wheel.stl</uri>
						<scale>0.001 0.001 0.001</scale>
					</mesh>
				</geometry>
			</visual>
		</link>
		<link name="pedal_right">
			<self_collide>false</self_collide>
			<pose frame="">0.1895775120643991 0.18236129042854501 0.3787080359371545 0.0 -0.0 0.0</pose>
			<inertial>
				<pose frame="">0.0 0.0 0.0 0 0 0</pose>
				<mass>0.9460025886020109</mass>
				<inertia>
					<ixx>0.1680562235402652</ixx>
					<ixy>-0.03270482284264949</ixy>
					<ixz>-0.06533253385140439</ixz>
					<iyy>0.17008937607447944</iyy>
					<iyz>-0.06789023681759175</iyz>
					<izz>0.0660654950965225</izz>
				</inertia>
			</inertial>
			<collision name="pedal_right_collision">
				<geometry>
					<mesh>
						<uri>model://rikshaw/meshes/CAD/pedal_right.stl</uri>
						<scale>0.001 0.001 0.001</scale>
					</mesh>
				</geometry>
			</collision>
			<visual name="pedal_right_visual">
				<geometry>
					<mesh>
						<uri>model://rikshaw/meshes/CAD/pedal_right.stl</uri>
						<scale>0.001 0.001 0.001</scale>
					</mesh>
				</geometry>
			</visual>
		</link>
		<link name="kurbel">
			<self_collide>false</self_collide>
			<pose frame="">0.20393972619138423 0.034503718012089186 0.21111028349653616 0.0 -0.0 0.0</pose>
			<inertial>
				<pose frame="">0.0 0.0 0.0 0 0 0</pose>
				<mass>2.7832708381108002</mass>
				<inertia>
					<ixx>0.160521356335058</ixx>
					<ixy>-0.018529361068994183</ixy>
					<ixz>-0.033209218815758404</ixz>
					<iyy>0.25766480698009997</iyy>
					<iyz>-0.11843090757691721</iyz>
					<izz>0.13512980306006003</izz>
				</inertia>
			</inertial>
			<collision name="kurbel_collision">
				<geometry>
					<mesh>
						<uri>model://rikshaw/meshes/CAD/kurbel.stl</uri>
						<scale>0.001 0.001 0.001</scale>
					</mesh>
				</geometry>
			</collision>
			<visual name="kurbel_visual">
				<geometry>
					<mesh>
						<uri>model://rikshaw/meshes/CAD/kurbel.stl</uri>
						<scale>0.001 0.001 0.001</scale>
					</mesh>
				</geometry>
			</visual>
		</link>
		<link name="pedal_left">
			<self_collide>false</self_collide>
			<pose frame="">0.21909203245690276 -0.11487270957145634 0.04145503741802313 0.0 -0.0 0.0</pose>
			<inertial>
				<pose frame="">0.0 0.0 0.0 0 0 0</pose>
				<mass>0.9460025886020087</mass>
				<inertia>
					<ixx>0.015029704878197391</ixx>
					<ixy>0.023808705010641276</ixy>
					<ixz>0.004504913967078801</ixz>
					<iyy>0.04745000655927284</iyy>
					<iyz>-0.00856421037217533</iyz>
					<izz>0.05849920799521962</izz>
				</inertia>
			</inertial>
			<collision name="pedal_left_collision">
				<geometry>
					<mesh>
						<uri>model://rikshaw/meshes/CAD/pedal_left.stl</uri>
						<scale>0.001 0.001 0.001</scale>
					</mesh>
				</geometry>
			</collision>
			<visual name="pedal_left_visual">
				<geometry>
					<mesh>
						<uri>model://rikshaw/meshes/CAD/pedal_left.stl</uri>
						<scale>0.001 0.001 0.001</scale>
					</mesh>
				</geometry>
			</visual>
		</link>
		<link name="foot_left">
			<self_collide>false</self_collide>
			<pose frame="">0.28754458320217474 -0.1541499997874013 0.00034853941343019555 0.0 -0.0 0.0</pose>
			<inertial>
				<pose frame="">0.0 0.0 0.0 0 0 0</pose>
				<mass>1.0073655678455569</mass>
				<inertia>
					<ixx>0.024540710607575827</ixx>
					<ixy>0.049601762440905854</ixy>
					<ixz>0.0011937057141964478</ixz>
					<iyy>0.10611861418986646</iyy>
					<iyz>-0.002834365654500939</iyz>
					<izz>0.12991068416512136</izz>
				</inertia>
			</inertial>
			<collision name="foot_left_collision">
				<geometry>
					<mesh>
						<uri>model://rikshaw/meshes/CAD/foot_left.stl</uri>
						<scale>0.001 0.001 0.001</scale>
					</mesh>
				</geometry>
			</collision>
			<visual name="foot_left_visual">
				<geometry>
					<mesh>
						<uri>model://rikshaw/meshes/CAD/foot_left.stl</uri>
						<scale>0.001 0.001 0.001</scale>
					</mesh>
				</geometry>
			</visual>
		</link>
		<link name="foot_right">
			<self_collide>false</self_collide>
			<pose frame="">0.2892679290406894 0.19400000036486462 0.0019531918769282396 0.0 -0.0 0.0</pose>
			<inertial>
				<pose frame="">0.0 0.0 0.0 0 0 0</pose>
				<mass>1.007352459928085</mass>
				<inertia>
					<ixx>0.03848112914971559</ixx>
					<ixy>-0.06281908353900195</ixy>
					<ixz>-0.0016489922126967657</ixz>
					<iyy>0.10736081745250295</iyy>
					<iyz>-0.0030346879286066784</iyz>
					<izz>0.145102699250954</izz>
				</inertia>
			</inertial>
			<collision name="foot_right_collision">
				<geometry>
					<mesh>
						<uri>model://rikshaw/meshes/CAD/foot_right.stl</uri>
						<scale>0.001 0.001 0.001</scale>
					</mesh>
				</geometry>
			</collision>
			<visual name="foot_right_visual">
				<geometry>
					<mesh>
						<uri>model://rikshaw/meshes/CAD/foot_right.stl</uri>
						<scale>0.001 0.001 0.001</scale>
					</mesh>
				</geometry>
			</visual>
		</link>
		<link name="thigh_right">
			<self_collide>false</self_collide>
			<pose frame="">0.3405209228543209 0.21820782179174741 0.5847307607601452 0.0 -0.0 0.0</pose>
			<inertial>
				<pose frame="">0.0 0.0 0.0 0 0 0</pose>
				<mass>5.563526842051091</mass>
				<inertia>
					<ixx>2.1953753518764234</ixx>
					<ixy>-0.4133207779831457</ixy>
					<ixz>-0.712917502636253</ixz>
					<iyy>2.578490277932215</iyy>
					<iyz>-1.1085430579007103</iyz>
					<izz>0.9221499084687812</izz>
				</inertia>
			</inertial>
			<collision name="thigh_right_collision">
				<geometry>
					<mesh>
						<uri>model://rikshaw/meshes/CAD/thigh_right.stl</uri>
						<scale>0.001 0.001 0.001</scale>
					</mesh>
				</geometry>
			</collision>
			<visual name="thigh_right_visual">
				<geometry>
					<mesh>
						<uri>model://rikshaw/meshes/CAD/thigh_right.stl</uri>
						<scale>0.001 0.001 0.001</scale>
					</mesh>
				</geometry>
			</visual>
		</link>
		<link name="thigh_left">
			<self_collide>false</self_collide>
			<pose frame="">0.3409918863044915 -0.17825567804350545 0.584740324404241 0.0 -0.0 0.0</pose>
			<inertial>
				<pose frame="">0.0 0.0 0.0 0 0 0</pose>
				<mass>5.563589065127255</mass>
				<inertia>
					<ixx>2.1073483656597585</ixx>
					<ixy>0.3375542359065887</ixy>
					<ixz>0.5829504291423683</ixz>
					<iyy>2.5803675604914544</iyy>
					<iyz>-1.11037215564166</iyz>
					<izz>0.8358124248821934</izz>
				</inertia>
			</inertial>
			<collision name="thigh_left_collision">
				<geometry>
					<mesh>
						<uri>model://rikshaw/meshes/CAD/thigh_left.stl</uri>
						<scale>0.001 0.001 0.001</scale>
					</mesh>
				</geometry>
			</collision>
			<visual name="thigh_left_visual">
				<geometry>
					<mesh>
						<uri>model://rikshaw/meshes/CAD/thigh_left.stl</uri>
						<scale>0.001 0.001 0.001</scale>
					</mesh>
				</geometry>
			</visual>
		</link>
		<link name="leg_right">
			<self_collide>false</self_collide>
			<pose frame="">0.34462326574207924 0.21763744306410948 0.23680567606208847 0.0 -0.0 0.0</pose>
			<inertial>
				<pose frame="">0.0 0.0 0.0 0 0 0</pose>
				<mass>5.741522183296334</mass>
				<inertia>
					<ixx>0.6337458051838858</ixx>
					<ixy>-0.43107317072067103</ixy>
					<ixz>-0.2993369937343584</ixz>
					<iyy>1.046634426174878</iyy>
					<iyz>-0.46606762221676656</iyz>
					<izz>0.9662986162769234</izz>
				</inertia>
			</inertial>
			<collision name="leg_right_collision">
				<geometry>
					<mesh>
						<uri>model://rikshaw/meshes/CAD/leg_right.stl</uri>
						<scale>0.001 0.001 0.001</scale>
					</mesh>
				</geometry>
			</collision>
			<visual name="leg_right_visual">
				<geometry>
					<mesh>
						<uri>model://rikshaw/meshes/CAD/leg_right.stl</uri>
						<scale>0.001 0.001 0.001</scale>
					</mesh>
				</geometry>
			</visual>
		</link>
		<link name="leg_left">
			<self_collide>false</self_collide>
			<pose frame="">0.3437549608105543 -0.1773193606400357 0.23691811780625952 0.0 -0.0 0.0</pose>
			<inertial>
				<pose frame="">0.0 0.0 0.0 0 0 0</pose>
				<mass>5.7426173662328575</mass>
				<inertia>
					<ixx>0.5427884169781724</ixx>
					<ixy>0.3499498433914676</ixy>
					<ixz>0.24468683550206866</ixz>
					<iyy>1.0437222226233074</iyy>
					<iyz>-0.4657299321823802</iyz>
					<izz>0.8715411400437341</izz>
				</inertia>
			</inertial>
			<collision name="leg_left_collision">
				<geometry>
					<mesh>
						<uri>model://rikshaw/meshes/CAD/leg_left.stl</uri>
						<scale>0.001 0.001 0.001</scale>
					</mesh>
				</geometry>
			</collision>
			<visual name="leg_left_visual">
				<geometry>
					<mesh>
						<uri>model://rikshaw/meshes/CAD/leg_left.stl</uri>
						<scale>0.001 0.001 0.001</scale>
					</mesh>
				</geometry>
			</visual>
		</link>
		<link name="wheel_back">
			<self_collide>false</self_collide>
			<pose frame="">0.6486084286036904 0.03792195562129225 0.2562488702490249 0.0 -0.0 0.0</pose>
			<inertial>
				<pose frame="">0.0 0.0 0.0 0 0 0</pose>
				<mass>13.340163929098479</mass>
				<inertia>
					<ixx>1.4043208422760698</ixx>
					<ixy>-0.32812134268378185</ixy>
					<ixz>-0.1296324865039446</ixz>
					<iyy>7.504381180421911</iyy>
					<iyz>-2.217204307894474</iyz>
					<izz>6.140471373352847</izz>
				</inertia>
			</inertial>
			<collision name="wheel_back_collision">
				<geometry>
					<mesh>
						<uri>model://rikshaw/meshes/CAD/wheel_back.stl</uri>
						<scale>0.001 0.001 0.001</scale>
					</mesh>
				</geometry>
			</collision>
			<visual name="wheel_back_visual">
				<geometry>
					<mesh>
						<uri>model://rikshaw/meshes/CAD/wheel_back.stl</uri>
						<scale>0.001 0.001 0.001</scale>
					</mesh>
				</geometry>
			</visual>
		</link>
		<link name="elbow_left">
			<self_collide>false</self_collide>
			<pose frame="">0.34235555932044215 -0.5057451715724758 1.175302552031454 0.0 -0.0 0.0</pose>
			<inertial>
				<pose frame="">0.0 0.0 0.0 0 0 0</pose>
				<mass>0.15681540300170926</mass>
				<inertia>
					<ixx>0.256864953120857</ixx>
					<ixy>0.02715659840956128</ixy>
					<ixz>0.09321889691014267</ixz>
					<iyy>0.23510542876452983</iyy>
					<iyz>-0.0630978624555684</iyz>
					<izz>0.05862599276052077</izz>
				</inertia>
			</inertial>
			<collision name="elbow_left_collision">
				<geometry>
					<mesh>
						<uri>model://rikshaw/meshes/CAD/elbow_left.stl</uri>
						<scale>0.001 0.001 0.001</scale>
					</mesh>
				</geometry>
			</collision>
			<visual name="elbow_left_visual">
				<geometry>
					<mesh>
						<uri>model://rikshaw/meshes/CAD/elbow_left.stl</uri>
						<scale>0.001 0.001 0.001</scale>
					</mesh>
				</geometry>
			</visual>
		</link>
		<link name="elbow_right">
			<self_collide>false</self_collide>
			<pose frame="">0.3424164038373494 0.5480622878983098 1.1728089476220742 0.0 -0.0 0.0</pose>
			<inertial>
				<pose frame="">0.0 0.0 0.0 0 0 0</pose>
				<mass>0.17350645370716086</mass>
				<inertia>
					<ixx>0.29092134642236867</ixx>
					<ixy>-0.03256614172841492</ixy>
					<ixz>-0.11152852379310105</ixz>
					<iyy>0.25911527550455765</iyy>
					<iyz>-0.06967799853294211</iyz>
					<izz>0.07260155373740665</izz>
				</inertia>
			</inertial>
			<collision name="elbow_right_collision">
				<geometry>
					<mesh>
						<uri>model://rikshaw/meshes/CAD/elbow_right.stl</uri>
						<scale>0.001 0.001 0.001</scale>
					</mesh>
				</geometry>
			</collision>
			<visual name="elbow_right_visual">
				<geometry>
					<mesh>
						<uri>model://rikshaw/meshes/CAD/elbow_right.stl</uri>
						<scale>0.001 0.001 0.001</scale>
					</mesh>
				</geometry>
			</visual>
		</link>
		<link name="sphere_left_link1">
			<self_collide>false</self_collide>
			<pose frame="">0.33071409957862036 -0.272229961573844 1.3711603774754806 0.0 -0.0 0.0</pose>
			<inertial>
				<pose frame="">0.0 0.0 0.0 0 0 0</pose>
				<mass>0.04675353024257251</mass>
				<inertia>
					<ixx>0.09137125206316106</ixx>
					<ixy>0.0042092337289464975</ixy>
					<ixz>0.017451734035662726</ixz>
					<iyy>0.09301990605817985</iyy>
					<iyz>-0.021200952585589232</iyz>
					<izz>0.008584356847086794</izz>
				</inertia>
			</inertial>
			<collision name="sphere_left_link1_collision">
				<geometry>
					<mesh>
						<uri>model://rikshaw/meshes/CAD/sphere_left_link1.stl</uri>
						<scale>0.001 0.001 0.001</scale>
					</mesh>
				</geometry>
			</collision>
			<visual name="sphere_left_link1_visual">
				<geometry>
					<mesh>
						<uri>model://rikshaw/meshes/CAD/sphere_left_link1.stl</uri>
						<scale>0.001 0.001 0.001</scale>
					</mesh>
				</geometry>
			</visual>
		</link>
		<link name="sphere_left_link2">
			<self_collide>false</self_collide>
			<pose frame="">0.3307139439493934 -0.27222887035970095 1.3711603794928573 0.0 -0.0 0.0</pose>
			<inertial>
				<pose frame="">0.0 0.0 0.0 0 0 0</pose>
				<mass>0.03133730384743735</mass>
				<inertia>
					<ixx>0.0612417234672702</ixx>
					<ixy>0.002821293806067818</ixy>
					<ixz>0.011697257895575418</ixz>
					<iyy>0.06234677609149785</iyy>
					<iyz>-0.014210271992560993</iyz>
					<izz>0.005752475204868141</izz>
				</inertia>
			</inertial>
			<collision name="sphere_left_link2_collision">
				<geometry>
					<mesh>
						<uri>model://rikshaw/meshes/CAD/sphere_left_link2.stl</uri>
						<scale>0.001 0.001 0.001</scale>
					</mesh>
				</geometry>
			</collision>
			<visual name="sphere_left_link2_visual">
				<geometry>
					<mesh>
						<uri>model://rikshaw/meshes/CAD/sphere_left_link2.stl</uri>
						<scale>0.001 0.001 0.001</scale>
					</mesh>
				</geometry>
			</visual>
		</link>
		<link name="wrist_left_1">
			<self_collide>false</self_collide>
			<pose frame="">0.3525770552666536 -0.7219119321445063 0.9823636609975489 0.0 -0.0 0.0</pose>
			<inertial>
				<pose frame="">0.0 0.0 0.0 0 0 0</pose>
				<mass>0.012762217633342583</mass>
				<inertia>
					<ixx>0.018970691396491133</ixx>
					<ixy>0.003248339947130892</ixy>
					<ixz>0.009052108796479035</ixz>
					<iyy>0.013906693497415518</iyy>
					<iyz>-0.004420385057485256</iyz>
					<izz>0.008241479604974272</izz>
				</inertia>
			</inertial>
			<collision name="wrist_left_1_collision">
				<geometry>
					<mesh>
						<uri>model://rikshaw/meshes/CAD/wrist_left_1.stl</uri>
						<scale>0.001 0.001 0.001</scale>
					</mesh>
				</geometry>
			</collision>
			<visual name="wrist_left_1_visual">
				<geometry>
					<mesh>
						<uri>model://rikshaw/meshes/CAD/wrist_left_1.stl</uri>
						<scale>0.001 0.001 0.001</scale>
					</mesh>
				</geometry>
			</visual>
		</link>
		<link name="left_hand">
			<self_collide>false</self_collide>
			<pose frame="">0.35897432631015136 -0.7801156502009481 0.9256308203227356 0.0 -0.0 0.0</pose>
			<inertial>
				<pose frame="">0.0 0.0 0.0 0 0 0</pose>
				<mass>0.08391816593127362</mass>
				<inertia>
					<ixx>0.12315663152243422</ixx>
					<ixy>0.02351379836528688</ixy>
					<ixz>0.06051648116403934</ixz>
					<iyy>0.08285072728366757</iyy>
					<iyz>-0.027866103240523472</iyz>
					<izz>0.062041662036345445</izz>
				</inertia>
			</inertial>
			<collision name="left_hand_collision">
				<geometry>
					<mesh>
						<uri>model://rikshaw/meshes/CAD/left_hand.stl</uri>
						<scale>0.001 0.001 0.001</scale>
					</mesh>
				</geometry>
			</collision>
			<visual name="left_hand_visual">
				<geometry>
					<mesh>
						<uri>model://rikshaw/meshes/CAD/left_hand.stl</uri>
						<scale>0.001 0.001 0.001</scale>
					</mesh>
				</geometry>
			</visual>
		</link>
		<link name="wrist_right_1">
			<self_collide>false</self_collide>
			<pose frame="">0.3527779991782979 0.7663484010848209 0.9822800767844028 0.0 -0.0 0.0</pose>
			<inertial>
				<pose frame="">0.0 0.0 0.0 0 0 0</pose>
				<mass>0.012761782896867226</mass>
				<inertia>
					<ixx>0.01981192653797364</ixx>
					<ixy>-0.0034501178168721454</ixy>
					<ixz>-0.00960805204659084</ixz>
					<iyy>0.013906055128874585</iyy>
					<iyz>-0.004422361782762946</iyz>
					<izz>0.00908685911865395</izz>
				</inertia>
			</inertial>
			<collision name="wrist_right_1_collision">
				<geometry>
					<mesh>
						<uri>model://rikshaw/meshes/CAD/wrist_right_1.stl</uri>
						<scale>0.001 0.001 0.001</scale>
					</mesh>
				</geometry>
			</collision>
			<visual name="wrist_right_1_visual">
				<geometry>
					<mesh>
						<uri>model://rikshaw/meshes/CAD/wrist_right_1.stl</uri>
						<scale>0.001 0.001 0.001</scale>
					</mesh>
				</geometry>
			</visual>
		</link>
		<link name="right_hand">
			<self_collide>false</self_collide>
			<pose frame="">0.3579935592610073 0.8282164032599036 0.9291916463314303 0.0 -0.0 0.0</pose>
			<inertial>
				<pose frame="">0.0 0.0 0.0 0 0 0</pose>
				<mass>0.08391622142376684</mass>
				<inertia>
					<ixx>0.13019843505363257</ixx>
					<ixy>-0.02490104700630209</ixy>
					<ixz>-0.06449950190353403</ixz>
					<iyy>0.08332891545792796</iyy>
					<iyz>-0.027909412829306077</iyz>
					<izz>0.06849264168180677</izz>
				</inertia>
			</inertial>
			<collision name="right_hand_collision">
				<geometry>
					<mesh>
						<uri>model://rikshaw/meshes/CAD/right_hand.stl</uri>
						<scale>0.001 0.001 0.001</scale>
					</mesh>
				</geometry>
			</collision>
			<visual name="right_hand_visual">
				<geometry>
					<mesh>
						<uri>model://rikshaw/meshes/CAD/right_hand.stl</uri>
						<scale>0.001 0.001 0.001</scale>
					</mesh>
				</geometry>
			</visual>
		</link>
		<link name="upper_arm_left">
			<self_collide>false</self_collide>
			<pose frame="">0.3369874459564149 -0.39521680284457417 1.2821766593957298 0.0 -0.0 0.0</pose>
			<inertial>
				<pose frame="">0.0 0.0 0.0 0 0 0</pose>
				<mass>1.1803838170765448</mass>
				<inertia>
					<ixx>2.1298878606900375</ixx>
					<ixy>0.15731396320754892</ixy>
					<ixz>0.5963000881547096</ixz>
					<iyy>2.078345545756509</iyy>
					<iyz>-0.5098935199657852</iyz>
					<izz>0.3233187846841082</izz>
				</inertia>
			</inertial>
			<collision name="upper_arm_left_collision">
				<geometry>
					<mesh>
						<uri>model://rikshaw/meshes/CAD/upper_arm_left.stl</uri>
						<scale>0.001 0.001 0.001</scale>
					</mesh>
				</geometry>
			</collision>
			<visual name="upper_arm_left_visual">
				<geometry>
					<mesh>
						<uri>model://rikshaw/meshes/CAD/upper_arm_left.stl</uri>
						<scale>0.001 0.001 0.001</scale>
					</mesh>
				</geometry>
			</visual>
		</link>
		<link name="lower_arm_left">
			<self_collide>false</self_collide>
			<pose frame="">0.34744686819866183 -0.6160036188623645 1.0751884439087638 0.0 -0.0 0.0</pose>
			<inertial>
				<pose frame="">0.0 0.0 0.0 0 0 0</pose>
				<mass>1.4159186820902159</mass>
				<inertia>
					<ixx>2.1811131919385804</ixx>
					<ixy>0.3032071609440758</ixy>
					<ixz>0.9349772174239721</ixz>
					<iyy>1.8114839178439186</iyy>
					<iyz>-0.5288085786732152</iyz>
					<izz>0.7127903112759242</izz>
				</inertia>
			</inertial>
			<collision name="lower_arm_left_collision">
				<geometry>
					<mesh>
						<uri>model://rikshaw/meshes/CAD/lower_arm_left.stl</uri>
						<scale>0.001 0.001 0.001</scale>
					</mesh>
				</geometry>
			</collision>
			<visual name="lower_arm_left_visual">
				<geometry>
					<mesh>
						<uri>model://rikshaw/meshes/CAD/lower_arm_left.stl</uri>
						<scale>0.001 0.001 0.001</scale>
					</mesh>
				</geometry>
			</visual>
		</link>
		<link name="lower_arm_right">
			<self_collide>false</self_collide>
			<pose frame="">0.34760976727486603 0.6598569907376691 1.0720505294558855 0.0 -0.0 0.0</pose>
			<inertial>
				<pose frame="">0.0 0.0 0.0 0 0 0</pose>
				<mass>1.3992272098428602</mass>
				<inertia>
					<ixx>2.224056987713926</ixx>
					<ixy>-0.32109609612110884</ixy>
					<ixz>-0.9871381806426893</ixz>
					<iyy>1.7807932691131367</iyy>
					<iyz>-0.5212987529954032</iyz>
					<izz>0.7827088740676036</izz>
				</inertia>
			</inertial>
			<collision name="lower_arm_right_collision">
				<geometry>
					<mesh>
						<uri>model://rikshaw/meshes/CAD/lower_arm_right.stl</uri>
						<scale>0.001 0.001 0.001</scale>
					</mesh>
				</geometry>
			</collision>
			<visual name="lower_arm_right_visual">
				<geometry>
					<mesh>
						<uri>model://rikshaw/meshes/CAD/lower_arm_right.stl</uri>
						<scale>0.001 0.001 0.001</scale>
					</mesh>
				</geometry>
			</visual>
		</link>
		<link name="sphere_left_link1">
			<self_collide>false</self_collide>
			<pose frame="">0.33071409957862036 -0.272229961573844 1.3711603774754806 0.0 -0.0 0.0</pose>
			<inertial>
				<pose frame="">0.0 0.0 0.0 0 0 0</pose>
				<mass>0.04675353024257251</mass>
				<inertia>
					<ixx>0.09137125206316106</ixx>
					<ixy>0.0042092337289464975</ixy>
					<ixz>0.017451734035662726</ixz>
					<iyy>0.09301990605817985</iyy>
					<iyz>-0.021200952585589232</iyz>
					<izz>0.008584356847086794</izz>
				</inertia>
			</inertial>
			<collision name="sphere_left_link1_collision">
				<geometry>
					<mesh>
						<uri>model://rikshaw/meshes/CAD/sphere_left_link1.stl</uri>
						<scale>0.001 0.001 0.001</scale>
					</mesh>
				</geometry>
			</collision>
			<visual name="sphere_left_link1_visual">
				<geometry>
					<mesh>
						<uri>model://rikshaw/meshes/CAD/sphere_left_link1.stl</uri>
						<scale>0.001 0.001 0.001</scale>
					</mesh>
				</geometry>
			</visual>
		</link>
		<link name="sphere_left_link2">
			<self_collide>false</self_collide>
			<pose frame="">0.3307139439493934 -0.27222887035970095 1.3711603794928573 0.0 -0.0 0.0</pose>
			<inertial>
				<pose frame="">0.0 0.0 0.0 0 0 0</pose>
				<mass>0.03133730384743735</mass>
				<inertia>
					<ixx>0.0612417234672702</ixx>
					<ixy>0.002821293806067818</ixy>
					<ixz>0.011697257895575418</ixz>
					<iyy>0.06234677609149785</iyy>
					<iyz>-0.014210271992560993</iyz>
					<izz>0.005752475204868141</izz>
				</inertia>
			</inertial>
			<collision name="sphere_left_link2_collision">
				<geometry>
					<mesh>
						<uri>model://rikshaw/meshes/CAD/sphere_left_link2.stl</uri>
						<scale>0.001 0.001 0.001</scale>
					</mesh>
				</geometry>
			</collision>
			<visual name="sphere_left_link2_visual">
				<geometry>
					<mesh>
						<uri>model://rikshaw/meshes/CAD/sphere_left_link2.stl</uri>
						<scale>0.001 0.001 0.001</scale>
					</mesh>
				</geometry>
			</visual>
		</link>
		<joint name="joint_wheel_left" type="revolute">
			<parent>front_part</parent>
			<child>left_wheel</child>
			<pose frame="">-0.8867148521253273 -0.26962806218634705 0.25250000000001727 0 0 0</pose>
			<axis>
				<xyz>3.1662288285729275e-30 -0.9999999999999998 -4.317059530368993e-14</xyz>
				<limit>
					<lower>-3.141592653589793</lower>
					<upper>3.141592653589793</upper>
				</limit>
				<use_parent_model_frame>0</use_parent_model_frame>
			</axis>
		</joint>
		<joint name="joint_wheel_right" type="revolute">
			<parent>front_part</parent>
			<child>right_wheel</child>
			<pose frame="">-0.8867148521253273 0.3723726160419198 0.25250000000004547 0 0 0</pose>
			<axis>
				<xyz>-3.1662288285729275e-30 0.9999999999999998 4.317059530368993e-14</xyz>
				<limit>
					<lower>-3.141592653589793</lower>
					<upper>3.141592653589793</upper>
				</limit>
				<use_parent_model_frame>0</use_parent_model_frame>
			</axis>
		</joint>
		<joint name="joint_front" type="revolute">
			<parent>bike</parent>
			<child>front_part</child>
			<pose frame="">-0.8347147288551195 0.03437224426641265 0.21799999821669747 0 0 0</pose>
			<axis>
				<xyz>5.345642609144017e-16 -4.084397910750052e-14 1.0</xyz>
				<limit>
					<lower>-0.3490658503988659</lower>
					<upper>0.3490658503988659</upper>
				</limit>
				<use_parent_model_frame>0</use_parent_model_frame>
			</axis>
		</joint>
		<joint name="joint_wheel_back" type="revolute">
			<parent>bike</parent>
			<child>wheel_back</child>
			<pose frame="">0.6486084286036902 -0.031077697753905262 0.2562488702490252 0 0 0</pose>
			<axis>
				<xyz>6.938893903907228e-17 -1.0 1.27675647831893e-15</xyz>
				<limit>
					<lower>-3.141592653589793</lower>
					<upper>3.141592653589793</upper>
				</limit>
				<use_parent_model_frame>0</use_parent_model_frame>
			</axis>
		</joint>
		<joint name="joint_pedal" type="revolute">
			<parent>bike</parent>
			<child>kurbel</child>
			<pose frame="">0.20421801757812547 -0.0006279315437303268 0.2101009521484399 0 0 0</pose>
			<axis>
				<xyz>-6.938893903907228e-17 1.0 -1.27675647831893e-15</xyz>
				<limit>
					<lower>-3.141592653589793</lower>
					<upper>3.141592653589793</upper>
				</limit>
				<use_parent_model_frame>0</use_parent_model_frame>
			</axis>
		</joint>
		<joint name="spine_joint" type="revolute">
			<parent>bike</parent>
			<child>torso</child>
			<pose frame="">0.3321949623512944 0.01994999985417912 0.9018217848680884 0 0 0</pose>
			<axis>
				<xyz>0.019535911231678107 4.747112516936242e-10 -0.9998091558754337</xyz>
				<limit>
					<lower>-0.5235987755982988</lower>
					<upper>0.5235987755982988</upper>
				</limit>
				<use_parent_model_frame>0</use_parent_model_frame>
			</axis>
		</joint>
		<joint name="joint_pedal_right" type="revolute">
			<parent>kurbel</parent>
			<child>pedal_right</child>
			<pose frame="">0.1895353022330539 0.2243612904285452 0.3786421113694053 0 0 0</pose>
			<axis>
				<xyz>-5.847985275656098e-16 1.0000000000000007 -1.5799660158833418e-15</xyz>
				<limit>
					<lower>-3.141592653589793</lower>
					<upper>3.141592653589793</upper>
				</limit>
				<use_parent_model_frame>0</use_parent_model_frame>
			</axis>
		</joint>
		<joint name="joint_pedal_left" type="revolute">
			<parent>kurbel</parent>
			<child>pedal_left</child>
			<pose frame="">0.21903901620668648 -0.15687270957145544 0.04151263078316902 0 0 0</pose>
			<axis>
				<xyz>5.847985275656129e-16 -1.0 1.5799660158833554e-15</xyz>
				<limit>
					<lower>-3.141592653589793</lower>
					<upper>3.141592653589793</upper>
				</limit>
				<use_parent_model_frame>0</use_parent_model_frame>
			</axis>
		</joint>
		<joint name="joint_hip_left" type="revolute">
			<parent>bike</parent>
			<child>thigh_left</child>
			<pose frame="">0.3362193600606554 -0.16770000004279115 0.695861098668567 0 0 0</pose>
			<axis>
				<xyz>4.7135677734903885e-12 -0.9999999999999998 -4.747094653015647e-10</xyz>
				<limit>
					<lower>-3.141592653589793</lower>
					<upper>3.141592653589793</upper>
				</limit>
				<use_parent_model_frame>0</use_parent_model_frame>
			</axis>
		</joint>
		<joint name="joint_hip_right" type="revolute">
			<parent>bike</parent>
			<child>thigh_right</child>
			<pose frame="">0.3362193600589623 0.1962999999467291 0.6958610988413618 0 0 0</pose>
			<axis>
				<xyz>4.713397833840625e-12 -0.9999999999999999 -4.747100165437955e-10</xyz>
				<limit>
					<lower>-3.141592653589793</lower>
					<upper>3.141592653589793</upper>
				</limit>
				<use_parent_model_frame>0</use_parent_model_frame>
			</axis>
		</joint>
		<joint name="joint_knee_left" type="revolute">
			<parent>thigh_left</parent>
			<child>leg_left</child>
			<pose frame="">0.35275395276803556 -0.14364999990136 0.38712519658031314 0 0 0</pose>
			<axis>
				<xyz>-6.508844489870669e-12 -1.0000000000000238 -2.7242031319306746e-10</xyz>
				<limit>
					<lower>-3.141592653589793</lower>
					<upper>3.141592653589793</upper>
				</limit>
				<use_parent_model_frame>0</use_parent_model_frame>
			</axis>
		</joint>
		<joint name="joint_knee_right" type="revolute">
			<parent>thigh_right</parent>
			<child>leg_right</child>
			<pose frame="">0.35225404838523944 0.2040000001005075 0.3871154289691083 0 0 0</pose>
			<axis>
				<xyz>-5.578288888957696e-12 1.0000000000000224 5.18998748174747e-10</xyz>
				<limit>
					<lower>-3.141592653589793</lower>
					<upper>3.141592653589793</upper>
				</limit>
				<use_parent_model_frame>0</use_parent_model_frame>
			</axis>
		</joint>
		<joint name="joint_foot_left" type="revolute">
			<parent>leg_left</parent>
			<child>foot_left</child>
			<pose frame="">0.3495738942280449 -0.1381499998028399 0.03799644206616796 0 0 0</pose>
			<axis>
				<xyz>1.573517675843796e-10 0.9999999999999996 1.508275800568426e-10</xyz>
				<limit>
					<lower>-3.141592653589793</lower>
					<upper>3.141592653589793</upper>
				</limit>
				<use_parent_model_frame>0</use_parent_model_frame>
			</axis>
		</joint>
		<joint name="joint_foot_right" type="revolute">
			<parent>leg_right</parent>
			<child>foot_right</child>
			<pose frame="">0.35225706821781566 0.20950000033893448 0.037972191676040705 0 0 0</pose>
			<axis>
				<xyz>-1.845734425466025e-10 -0.9999999999999996 -6.15133494266132e-10</xyz>
				<limit>
					<lower>-3.141592653589793</lower>
					<upper>3.141592653589793</upper>
				</limit>
				<use_parent_model_frame>0</use_parent_model_frame>
			</axis>
		</joint>
		<joint name="left_shoulder_axis0" type="revolute">
			<parent>torso</parent>
			<child>sphere_left_link1</child>
			<pose frame="">0.3307335142628559 -0.27223005652383836 1.3701605703636661 0 0 0</pose>
			<axis>
				<xyz>0.050975679058603555 -0.9986354432779868 -0.01134599372001004</xyz>
				<limit>
					<lower>-3.141592653589793</lower>
					<upper>3.141592653589793</upper>
				</limit>
				<use_parent_model_frame>0</use_parent_model_frame>
			</axis>
		</joint>
		<joint name="left_shoulder_axis1" type="revolute">
			<parent>sphere_left_link1</parent>
			<child>sphere_left_link2</child>
			<pose frame="">0.3307335142628566 -0.2722300565238386 1.3701605703636657 0 0 0</pose>
			<axis>
				<xyz>0.9986941911138321 0.05101049432270832 -0.002800375767957668</xyz>
				<limit>
					<lower>-3.141592653589793</lower>
					<upper>3.141592653589793</upper>
				</limit>
				<use_parent_model_frame>0</use_parent_model_frame>
			</axis>
		</joint>
		<joint name="left_shoulder_axis2" type="revolute">
			<parent>sphere_left_link2</parent>
			<child>upper_arm_left</child>
			<pose frame="">0.33073351314672905 -0.27223005658084765 1.3701605703667965 0 0 0</pose>
			<axis>
				<xyz>0.036880022287882085 -0.7578073498002895 -0.6514352496946403</xyz>
				<limit>
					<lower>-3.141592653589793</lower>
					<upper>3.141592653589793</upper>
				</limit>
				<use_parent_model_frame>0</use_parent_model_frame>
			</axis>
		</joint>
		<joint name="elbow_left_rot1" type="revolute">
			<parent>elbow_left</parent>
			<child>lower_arm_left</child>
			<pose frame="">0.3430386853671773 -0.525083211441096 1.1526681858705972 0 0 0</pose>
			<axis>
				<xyz>0.03688002228788128 -0.7578073498002852 -0.6514352496946373</xyz>
				<limit>
					<lower>-1.5707963267948966</lower>
					<upper>1.5707963267948966</upper>
				</limit>
				<use_parent_model_frame>0</use_parent_model_frame>
			</axis>
		</joint>
		<joint name="elbow_left_rot0" type="revolute">
			<parent>upper_arm_left</parent>
			<child>elbow_left</child>
			<pose frame="">0.3362311817291628 -0.4867120945171237 1.2093446164235655 0 0 0</pose>
			<axis>
				<xyz>-0.035352179445318495 0.6504813218360854 -0.7586990663964502</xyz>
				<limit>
					<lower>0.0</lower>
					<upper>1.5707963267948966</upper>
				</limit>
				<use_parent_model_frame>0</use_parent_model_frame>
			</axis>
		</joint>
		<joint name="elbow_right_rot1" type="revolute">
			<parent>elbow_right</parent>
			<child>lower_arm_right</child>
			<pose frame="">0.34306380959888727 0.566121464253513 1.151691118184744 0 0 0</pose>
			<axis>
				<xyz>-0.03688002228074262 -0.7578073504191257 0.6514352489751488</xyz>
				<limit>
					<lower>-1.5707963267948966</lower>
					<upper>1.5707963267948966</upper>
				</limit>
				<use_parent_model_frame>0</use_parent_model_frame>
			</axis>
		</joint>
		<joint name="left_wrist_0" type="revolute">
			<parent>lower_arm_left</parent>
			<child>wrist_left_1</child>
			<pose frame="">0.3521825987446058 -0.7163776369731448 0.9730692428986756 0 0 0</pose>
			<axis>
				<xyz>-0.047216894784735494 0.6683646979703977 -0.7423336145924062</xyz>
				<limit>
					<lower>-0.5235987755982988</lower>
					<upper>0.5235987755982988</upper>
				</limit>
				<use_parent_model_frame>0</use_parent_model_frame>
			</axis>
		</joint>
		<joint name="left_wrist_1" type="revolute">
			<parent>wrist_left_1</parent>
			<child>left_hand</child>
			<pose frame="">0.3352090792683362 -0.7244131561950344 0.9810586152861233 0 0 0</pose>
			<axis>
				<xyz>0.9982455359929417 0.05815370141400431 -0.011135388723325113</xyz>
				<limit>
					<lower>-0.5235987755982988</lower>
					<upper>0.5235987755982988</upper>
				</limit>
				<use_parent_model_frame>0</use_parent_model_frame>
			</axis>
		</joint>
		<joint name="elbow_right_rot0" type="revolute">
			<parent>upper_arm_right</parent>
			<child>elbow_right</child>
			<pose frame="">0.33625630596123435 0.5277503472756658 1.2083675487012806 0 0 0</pose>
			<axis>
				<xyz>0.03535217943919201 0.6504813211160858 0.7586990670140391</xyz>
				<limit>
					<lower>0.0</lower>
					<upper>1.5707963267948966</upper>
				</limit>
				<use_parent_model_frame>0</use_parent_model_frame>
			</axis>
		</joint>
		<joint name="right_wrist_0" type="revolute">
			<parent>lower_arm_right</parent>
			<child>wrist_right_1</child>
			<pose frame="">0.3525916238857079 0.7604291236950868 0.9717543721396057 0 0 0</pose>
			<axis>
				<xyz>-0.023461713055419463 -0.6321241248586623 -0.7745118713048712</xyz>
				<limit>
					<lower>-0.5235987755982988</lower>
					<upper>0.5235987755982988</upper>
				</limit>
				<use_parent_model_frame>0</use_parent_model_frame>
			</axis>
		</joint>
		<joint name="right_wrist_1" type="revolute">
			<parent>wrist_right_1</parent>
			<child>right_hand</child>
			<pose frame="">0.370320862205131 0.7662988572257728 0.9799836088534097 0 0 0</pose>
			<axis>
				<xyz>0.9990223047052151 -0.04386113030445875 0.005534975148719447</xyz>
				<limit>
					<lower>-0.5235987755982988</lower>
					<upper>0.5235987755982988</upper>
				</limit>
				<use_parent_model_frame>0</use_parent_model_frame>
			</axis>
		</joint>
		<joint name="right_shoulder_axis0" type="revolute">
			<parent>torso</parent>
			<child>sphere_left_link1</child>
			<pose frame="">0.33070331734740194 0.3121315981610224 1.370160655314343 0 0 0</pose>
			<axis>
				<xyz>0.9986941911143129 -0.051010494310641946 -0.002800375816389377</xyz>
				<limit>
					<lower>-3.141592653589793</lower>
					<upper>3.141592653589793</upper>
				</limit>
				<use_parent_model_frame>0</use_parent_model_frame>
			</axis>
		</joint>
		<joint name="right_shoulder_axis2" type="revolute">
			<parent>sphere_left_link2</parent>
			<child>upper_arm_right</child>
			<pose frame="">0.33070331734740044 0.31213159816102215 1.3701606553143426 0 0 0</pose>
			<axis>
				<xyz>0.03688002228074296 0.7578073504191245 -0.651435248975152</xyz>
				<limit>
					<lower>-3.141592653589793</lower>
					<upper>3.141592653589793</upper>
				</limit>
				<use_parent_model_frame>0</use_parent_model_frame>
			</axis>
		</joint>
		<joint name="right_shoulder_axis1" type="revolute">
			<parent>sphere_left_link1</parent>
			<child>sphere_left_link2</child>
			<pose frame="">0.3307033173474007 0.31213159816102193 1.3701606553143442 0 0 0</pose>
			<axis>
				<xyz>0.03535217943919347 0.6504813211160871 0.7586990670140364</xyz>
				<limit>
					<lower>-3.141592653589793</lower>
					<upper>3.141592653589793</upper>
				</limit>
				<use_parent_model_frame>0</use_parent_model_frame>
			</axis>
		</joint>
		<plugin filename="libcardsflow_gazebo_plugin.so" name="cardsflow_gazebo_plugin"/>
	</model>
</sdf>
