<?xml version="1.0" ?>
<sdf version="1.6">
	<model name="rikshaw">
		<link name="pedal_left">
			<self_collide>false</self_collide>
			<pose frame="">4.474047106928748 0.0005139113343922151 0.0725299926087887 0.0 -0.0 0.0</pose>
			<inertial>
				<pose frame="">0.0 0.0 0.0 0 0 0</pose>
				<mass>1.4041650832963233</mass>
				<inertia>
					<ixx>0.014689396282226548</ixx>
					<ixy>-0.002046612762490566</ixy>
					<ixz>0.0020889090747527473</ixz>
					<iyy>28.11681244961605</iyy>
					<iyz>-0.45611884464196356</iyz>
					<izz>28.113279986970344</izz>
				</inertia>
			</inertial>
			<collision name="pedal_left_collision">
				<geometry>
					<mesh>
						<uri>model://rikshaw/meshes/CAD/pedal_left.stl</uri>
						<scale>0.001 0.001 0.001</scale>
					</mesh>
				</geometry>
			</collision>
			<visual name="pedal_left_visual">
				<geometry>
					<mesh>
						<uri>model://rikshaw/meshes/CAD/pedal_left.stl</uri>
						<scale>0.001 0.001 0.001</scale>
					</mesh>
				</geometry>
			</visual>
		</link>
		<link name="pedal_right">
			<self_collide>false</self_collide>
			<pose frame="">4.454588267227227 0.09193307049294273 -0.13010528274151725 0.0 -0.0 0.0</pose>
			<inertial>
				<pose frame="">0.0 0.0 0.0 0 0 0</pose>
				<mass>1.37910575481467</mass>
				<inertia>
					<ixx>0.0421743971885497</ixx>
					<ixy>-0.5636765255442244</ixy>
					<ixz>0.018614661902484543</ixz>
					<iyy>27.391501878818794</iyy>
					<iyz>0.7988519839415706</iyz>
					<izz>27.383555692846585</izz>
				</inertia>
			</inertial>
			<collision name="pedal_right_collision">
				<geometry>
					<mesh>
						<uri>model://rikshaw/meshes/CAD/pedal_right.stl</uri>
						<scale>0.001 0.001 0.001</scale>
					</mesh>
				</geometry>
			</collision>
			<visual name="pedal_right_visual">
				<geometry>
					<mesh>
						<uri>model://rikshaw/meshes/CAD/pedal_right.stl</uri>
						<scale>0.001 0.001 0.001</scale>
					</mesh>
				</geometry>
			</visual>
		</link>
		<link name="thigh_right">
			<self_collide>false</self_collide>
			<pose frame="">4.482406978583961 0.5923290572515559 -0.22820807094029077 0.0 -0.0 0.0</pose>
			<inertial>
				<pose frame="">0.0 0.0 0.0 0 0 0</pose>
				<mass>5.563551775927843</mass>
				<inertia>
					<ixx>2.2540844816246466</ixx>
					<ixy>-14.773567348478899</ixy>
					<ixz>0.7526493865535845</ixz>
					<iyy>112.10031359674323</iyy>
					<iyz>5.694060857559582</iyz>
					<izz>113.76568614434035</izz>
				</inertia>
			</inertial>
			<collision name="thigh_right_collision">
				<geometry>
					<mesh>
						<uri>model://rikshaw/meshes/CAD/thigh_right.stl</uri>
						<scale>0.001 0.001 0.001</scale>
					</mesh>
				</geometry>
			</collision>
			<visual name="thigh_right_visual">
				<geometry>
					<mesh>
						<uri>model://rikshaw/meshes/CAD/thigh_right.stl</uri>
						<scale>0.001 0.001 0.001</scale>
					</mesh>
				</geometry>
			</visual>
		</link>
		<link name="thigh_left">
			<self_collide>false</self_collide>
			<pose frame="">4.595876869382049 0.5047400667081398 0.16825565062979922 0.0 -0.0 0.0</pose>
			<inertial>
				<pose frame="">0.0 0.0 0.0 0 0 0</pose>
				<mass>5.563591173165812</mass>
				<inertia>
					<ixx>1.6031563220499725</ixx>
					<ixy>-12.907005690422219</ixy>
					<ixz>-0.4755295405561013</ixz>
					<iyy>117.6840240023188</iyy>
					<iyz>-4.301596584809158</iyz>
					<izz>118.96294393154832</izz>
				</inertia>
			</inertial>
			<collision name="thigh_left_collision">
				<geometry>
					<mesh>
						<uri>model://rikshaw/meshes/CAD/thigh_left.stl</uri>
						<scale>0.001 0.001 0.001</scale>
					</mesh>
				</geometry>
			</collision>
			<visual name="thigh_left_visual">
				<geometry>
					<mesh>
						<uri>model://rikshaw/meshes/CAD/thigh_left.stl</uri>
						<scale>0.001 0.001 0.001</scale>
					</mesh>
				</geometry>
			</visual>
		</link>
		<link name="leg_right">
			<self_collide>false</self_collide>
			<pose frame="">4.389690776822594 0.433860790349951 -0.22763758059414468 0.0 -0.0 0.0</pose>
			<inertial>
				<pose frame="">0.0 0.0 0.0 0 0 0</pose>
				<mass>5.741541926498232</mass>
				<inertia>
					<ixx>1.4021784642612567</ixx>
					<ixy>-10.921123103233803</ixy>
					<ixz>0.5698103162846716</ixz>
					<iyy>110.96190199569568</iyy>
					<iyz>5.735197097520718</iyz>
					<izz>111.75953654424973</izz>
				</inertia>
			</inertial>
			<collision name="leg_right_collision">
				<geometry>
					<mesh>
						<uri>model://rikshaw/meshes/CAD/leg_right.stl</uri>
						<scale>0.001 0.001 0.001</scale>
					</mesh>
				</geometry>
			</collision>
			<visual name="leg_right_visual">
				<geometry>
					<mesh>
						<uri>model://rikshaw/meshes/CAD/leg_right.stl</uri>
						<scale>0.001 0.001 0.001</scale>
					</mesh>
				</geometry>
			</visual>
		</link>
		<link name="leg_left">
			<self_collide>false</self_collide>
			<pose frame="">4.598629618603139 0.1569181399062989 0.16731935488900093 0.0 -0.0 0.0</pose>
			<inertial>
				<pose frame="">0.0 0.0 0.0 0 0 0</pose>
				<mass>5.74261779584804</mass>
				<inertia>
					<ixx>0.3420650596526541</ixx>
					<ixy>-4.1419635133241695</ixy>
					<ixz>-0.15421345580619206</ixz>
					<iyy>121.6146044398638</iyy>
					<iyz>-4.418511753540427</iyz>
					<izz>121.62564473735647</izz>
				</inertia>
			</inertial>
			<collision name="leg_left_collision">
				<geometry>
					<mesh>
						<uri>model://rikshaw/meshes/CAD/leg_left.stl</uri>
						<scale>0.001 0.001 0.001</scale>
					</mesh>
				</geometry>
			</collision>
			<visual name="leg_left_visual">
				<geometry>
					<mesh>
						<uri>model://rikshaw/meshes/CAD/leg_left.stl</uri>
						<scale>0.001 0.001 0.001</scale>
					</mesh>
				</geometry>
			</visual>
		</link>
		<link name="hip_and_bike">
			<self_collide>false</self_collide>
			<pose frame="">4.40878815193635 0.4577261469344515 -0.02993971835740389 0.0 -0.0 0.0</pose>
			<inertial>
				<pose frame="">0.0 0.0 0.0 0 0 0</pose>
				<mass>23.226257664981986</mass>
				<inertia>
					<ixx>8.452039555486737</ixx>
					<ixy>-49.149272176653</ixy>
					<ixz>0.31954159911132696</ixz>
					<iyy>455.6075441566423</iyy>
					<iyz>3.0705292899339365</iyz>
					<izz>463.4079705234321</izz>
				</inertia>
			</inertial>
			<collision name="hip_and_bike_collision">
				<geometry>
					<mesh>
						<uri>model://rikshaw/meshes/CAD/hip_and_bike.stl</uri>
						<scale>0.001 0.001 0.001</scale>
					</mesh>
				</geometry>
			</collision>
			<visual name="hip_and_bike_visual">
				<geometry>
					<mesh>
						<uri>model://rikshaw/meshes/CAD/hip_and_bike.stl</uri>
						<scale>0.001 0.001 0.001</scale>
					</mesh>
				</geometry>
			</visual>
		</link>
		<link name="foot_right">
			<self_collide>false</self_collide>
			<pose frame="">4.4740023777634415 0.2373090815286854 -0.20795362849129087 0.0 -0.0 0.0</pose>
			<inertial>
				<pose frame="">0.0 0.0 0.0 0 0 0</pose>
				<mass>1.9533512703186307</mass>
				<inertia>
					<ixx>0.19724326335819242</ixx>
					<ixy>-2.076789526057118</ixy>
					<ixz>0.09619994523800227</ixz>
					<iyy>39.190821220063754</iyy>
					<iyz>1.81702968703426</iyz>
					<izz>39.21723607050835</izz>
				</inertia>
			</inertial>
			<collision name="foot_right_collision">
				<geometry>
					<mesh>
						<uri>model://rikshaw/meshes/CAD/foot_right.stl</uri>
						<scale>0.001 0.001 0.001</scale>
					</mesh>
				</geometry>
			</collision>
			<visual name="foot_right_visual">
				<geometry>
					<mesh>
						<uri>model://rikshaw/meshes/CAD/foot_right.stl</uri>
						<scale>0.001 0.001 0.001</scale>
					</mesh>
				</geometry>
			</visual>
		</link>
		<link name="foot_left">
			<self_collide>false</self_collide>
			<pose frame="">4.541225339343001 -0.09709228053316477 0.14904779823071665 0.0 -0.0 0.0</pose>
			<inertial>
				<pose frame="">0.0 0.0 0.0 0 0 0</pose>
				<mass>1.9533515605720653</mass>
				<inertia>
					<ixx>0.06417499609160869</ixx>
					<ixy>0.8588547922529038</ixy>
					<ixz>0.02848251824220356</ixz>
					<iyy>40.33358604496351</iyy>
					<iyz>-1.3217395956062619</iyz>
					<izz>40.30905041196982</izz>
				</inertia>
			</inertial>
			<collision name="foot_left_collision">
				<geometry>
					<mesh>
						<uri>model://rikshaw/meshes/CAD/foot_left.stl</uri>
						<scale>0.001 0.001 0.001</scale>
					</mesh>
				</geometry>
			</collision>
			<visual name="foot_left_visual">
				<geometry>
					<mesh>
						<uri>model://rikshaw/meshes/CAD/foot_left.stl</uri>
						<scale>0.001 0.001 0.001</scale>
					</mesh>
				</geometry>
			</visual>
		</link>
		<joint name="joint_pedal_left" type="revolute">
			<parent>pedal_left</parent>
			<child>foot_left</child>
			<pose frame="">-0.0416607597700181 -0.02152964621683598 0.047619375627528465 0 0 0</pose>
			<axis>
				<xyz>-1.4643984436989822e-13 -2.335975556973714e-10 0.9999999999999992</xyz>
				<limit>
					<lower>-3.141592653589793</lower>
					<upper>3.141592653589793</upper>
				</limit>
				<use_parent_model_frame>0</use_parent_model_frame>
			</axis>
		</joint>
		<joint name="joint_pedal_right" type="revolute">
			<parent>pedal_right</parent>
			<child>foot_right</child>
			<pose frame="">-0.04258658159526874 -0.024460061761821417 -0.04661350460504753 0 0 0</pose>
			<axis>
				<xyz>-1.1979912112813704e-14 2.3358675429566076e-10 -0.9999999999999953</xyz>
				<limit>
					<lower>-3.141592653589793</lower>
					<upper>3.141592653589793</upper>
				</limit>
				<use_parent_model_frame>0</use_parent_model_frame>
			</axis>
		</joint>
		<joint name="joint_bike_right" type="revolute">
			<parent>hip_and_bike</parent>
			<child>pedal_right</child>
			<pose frame="">0.0093960579970053 -0.045159259685814704 0.06615514960638472 0 0 0</pose>
			<axis>
				<xyz>-2.537627663319977e-15 2.335889876728244e-10 -1.0</xyz>
				<limit>
					<lower>-3.141592653589793</lower>
					<upper>3.141592653589793</upper>
				</limit>
				<use_parent_model_frame>0</use_parent_model_frame>
			</axis>
		</joint>
		<joint name="joint_bike_left" type="revolute">
			<parent>hip_and_bike</parent>
			<child>pedal_left</child>
			<pose frame="">-0.010062781704514237 0.04625989945638452 -0.06647981871190926 0 0 0</pose>
			<axis>
				<xyz>-2.537627663319977e-15 2.335889876728244e-10 -1.0</xyz>
				<limit>
					<lower>-3.141592653589793</lower>
					<upper>3.141592653589793</upper>
				</limit>
				<use_parent_model_frame>0</use_parent_model_frame>
			</axis>
		</joint>
		<joint name="joint_hip_left" type="revolute">
			<parent>hip_and_bike</parent>
			<child>thigh_left</child>
			<pose frame="">-0.004781372556813608 0.11112103196042618 -0.010555650587007168 0 0 0</pose>
			<axis>
				<xyz>4.714070638884272e-12 -4.747097531970313e-10 1.0</xyz>
				<limit>
					<lower>-3.141592653589793</lower>
					<upper>3.141592653589793</upper>
				</limit>
				<use_parent_model_frame>0</use_parent_model_frame>
			</axis>
		</joint>
		<joint name="joint_hip_right" type="revolute">
			<parent>hip_and_bike</parent>
			<child>thigh_right</child>
			<pose frame="">0.10868851823958153 0.023532041589804892 0.021908070993561814 0 0 0</pose>
			<axis>
				<xyz>4.7139676717674495e-12 -4.747103063846467e-10 1.0</xyz>
				<limit>
					<lower>-3.141592653589793</lower>
					<upper>3.141592653589793</upper>
				</limit>
				<use_parent_model_frame>0</use_parent_model_frame>
			</axis>
		</joint>
		<joint name="joint_knee_left" type="revolute">
			<parent>thigh_left</parent>
			<child>leg_left</child>
			<pose frame="">0.009000470929301514 0.15020705667403828 -0.033669354987951684 0 0 0</pose>
			<axis>
				<xyz>7.781012720611506e-13 -2.7304206476907006e-10 1.0000000000000004</xyz>
				<limit>
					<lower>-3.141592653589793</lower>
					<upper>3.141592653589793</upper>
				</limit>
				<use_parent_model_frame>0</use_parent_model_frame>
			</axis>
		</joint>
		<joint name="joint_knee_right" type="revolute">
			<parent>thigh_right</parent>
			<child>leg_right</child>
			<pose frame="">-0.0998660150286355 0.11259610022346692 0.013637580592141312 0 0 0</pose>
			<axis>
				<xyz>3.992581482318776e-11 4.832701806911493e-10 -1.0000000000000002</xyz>
				<limit>
					<lower>-3.141592653589793</lower>
					<upper>3.141592653589793</upper>
				</limit>
				<use_parent_model_frame>0</use_parent_model_frame>
			</axis>
		</joint>
		<joint name="joint_foot_left" type="revolute">
			<parent>leg_left</parent>
			<child>foot_left</child>
			<pose frame="">0.06322469164941424 0.05508872259936036 -0.020897798428385687 0 0 0</pose>
			<axis>
				<xyz>1.5062616827321692e-10 1.5145911274643596e-10 -0.999999999999997</xyz>
				<limit>
					<lower>-3.141592653589793</lower>
					<upper>3.141592653589793</upper>
				</limit>
				<use_parent_model_frame>0</use_parent_model_frame>
			</axis>
		</joint>
		<joint name="joint_foot_right" type="revolute">
			<parent>leg_right</parent>
			<child>foot_right</child>
			<pose frame="">0.060445053417886356 0.06002785848687989 -0.011546372175624597 0 0 0</pose>
			<axis>
				<xyz>-1.0930223258736039e-10 -6.773951306649867e-10 0.9999999999999976</xyz>
				<limit>
					<lower>-3.141592653589793</lower>
					<upper>3.141592653589793</upper>
				</limit>
				<use_parent_model_frame>0</use_parent_model_frame>
			</axis>
		</joint>
		<plugin filename="libmusc_plugin.so" name="musc_plugin">
			<myoMuscle name="motor0">
				<link name="hip_and_bike">
					<viaPoint type="FIXPOINT">0.23785065908215758 0.21535626288148735 0.173689718418593</viaPoint>
					<viaPoint type="FIXPOINT">0.25984861678479376 0.16110126920990545 0.17368971839998382</viaPoint>
					<viaPoint type="FIXPOINT">0.22844902492373023 0.05518969132519835 0.1736897183738808</viaPoint>
				</link>
			</myoMuscle>
			<myoMuscle name="motor1">
				<link name="hip_and_bike">
					<viaPoint type="FIXPOINT">0.13539523013127108 0.2152424996506467 0.17108971841324627</viaPoint>
					<viaPoint type="FIXPOINT">0.1351166471343396 0.06129487742250298 0.17193971837535857</viaPoint>
				</link>
			</myoMuscle>
			<myoMuscle name="motor2">
				<link name="hip_and_bike">
					<viaPoint type="FIXPOINT">0.1326181531332378 0.21524249973471526 -0.1773102815875182</viaPoint>
					<viaPoint type="FIXPOINT">0.08536573316467638 0.18413887398173814 -0.17556028158452616</viaPoint>
				</link>
			</myoMuscle>
			<myoMuscle name="motor3">
				<link name="hip_and_bike">
					<viaPoint type="FIXPOINT">0.23342531589201088 0.2152424997347036 -0.17731028157700107</viaPoint>
					<viaPoint type="FIXPOINT">0.20602993270566913 0.07885637265835513 -0.17656028160993043</viaPoint>
					<viaPoint type="FIXPOINT">0.0972447803776123 0.09032355770469856 -0.17381028158732295</viaPoint>
				</link>
			</myoMuscle>
			<myoMuscle name="motor4">
				<link name="thigh_right">
					<viaPoint type="FIXPOINT">-0.07507117889137874 0.02389499428427712 0.027354052768398206</viaPoint>
					<viaPoint type="FIXPOINT">-0.2580542699466753 -0.11064906906294866 0.027208070409968137</viaPoint>
					<viaPoint type="FIXPOINT">-0.14257221221021837 -0.17708830628753724 0.026313333536589524</viaPoint>
				</link>
			</myoMuscle>
			<myoMuscle name="motor5">
				<link name="thigh_right">
					<viaPoint type="FIXPOINT">-0.0640802445788995 -0.0503011643111887 0.0226551740822228</viaPoint>
					<viaPoint type="FIXPOINT">-0.08330364882497122 -0.10535870125941416 0.026208070415236373</viaPoint>
				</link>
			</myoMuscle>
			<myoMuscle name="motor6">
				<link name="thigh_left">
					<viaPoint type="FIXPOINT">-0.04411666815178478 -0.07510263905072023 -0.02748550870716082</viaPoint>
					<viaPoint type="FIXPOINT">-0.08586552904038457 -0.20168267387013522 -0.021505650566024083</viaPoint>
					<viaPoint type="FIXPOINT">-0.04640691915260959 -0.32489165131654957 -0.022505650604825185</viaPoint>
				</link>
			</myoMuscle>
			<myoMuscle name="motor7">
				<link name="thigh_left">
					<viaPoint type="FIXPOINT">0.037817941788994176 -0.07545010154681273 -0.02753576527867425</viaPoint>
					<viaPoint type="FIXPOINT">0.045395058376647625 -0.3307008959954182 -0.026505650615387708</viaPoint>
				</link>
			</myoMuscle>
			<myoMuscle name="motor8">
				<link name="leg_left">
					<viaPoint type="FIXPOINT">0.039943182586570744 -0.07251874274106794 -0.02684946756011543</viaPoint>
					<viaPoint type="FIXPOINT">0.04592721475014912 -0.2369123973793718 -0.025569354849653083</viaPoint>
				</link>
			</myoMuscle>
			<myoMuscle name="motor9">
				<link name="leg_left">
					<viaPoint type="FIXPOINT">-0.044893376020737605 -0.07288612119701998 -0.02601979010157274</viaPoint>
					<viaPoint type="FIXPOINT">-0.08146558784502418 -0.2371841453348006 -0.02556935489468705</viaPoint>
				</link>
			</myoMuscle>
			<myoMuscle name="motor11">
				<link name="leg_right">
					<viaPoint type="FIXPOINT">0.027925270898562643 -0.06612073246305904 0.02623121042855722</viaPoint>
					<viaPoint type="FIXPOINT">0.20183519480626844 -0.15570822472055512 0.023637579920472405</viaPoint>
				</link>
			</myoMuscle>
			<myoMuscle name="motor10">
				<link name="leg_right">
					<viaPoint type="FIXPOINT">0.025229304242655532 -0.07122500315519084 0.025272245083924717</viaPoint>
					<viaPoint type="FIXPOINT">0.0774415249142254 -0.18318939810870094 0.023637579888260804</viaPoint>
				</link>
			</myoMuscle>
		</plugin>
	</model>
</sdf>
