<?xml version="1.0" ?>
<robot name="rikshaw">
  <joint name="joint_pedal_right" type="revolute">
    <parent link="foot_right"/>
    <child link="pedal_right"/>
    <origin rpy="0 0 0" xyz="-0.09847 -0.08985 -0.03506"/>
    <axis xyz="0  0 -1"/>
    <limit effort="0.0" lower="-3.14159265359" upper="3.14159265359" velocity="0.0"/>
  </joint>
  <joint name="joint_bike_left" type="revolute">
    <parent link="pedal_left"/>
    <child link="bike"/>
    <origin rpy="0 0 0" xyz="0.00236  0.16916 -0.19061"/>
    <axis xyz="0 0 1"/>
    <limit effort="0.0" lower="-3.14159265359" upper="3.14159265359" velocity="0.0"/>
  </joint>
  <joint name="joint_bike_right" type="revolute">
    <parent link="pedal_right"/>
    <child link="bike"/>
    <origin rpy="0 0 0" xyz="0.05552 -0.15987  0.19061"/>
    <axis xyz="0 0 1"/>
    <limit effort="0.0" lower="-3.14159265359" upper="3.14159265359" velocity="0.0"/>
  </joint>
  <joint name="joint_pedal_left" type="revolute">
    <parent link="foot_left"/>
    <child link="pedal_left"/>
    <origin rpy="0 0 0" xyz="-0.11662 -0.05739  0.06851"/>
    <axis xyz="0 0 1"/>
    <limit effort="0.0" lower="-3.14159265359" upper="3.14159265359" velocity="0.0"/>
  </joint>
  <joint name="joint_hip_right" type="revolute">
    <parent link="hip"/>
    <child link="thigh_right"/>
    <origin rpy="0 0 0" xyz="4.59109  0.61586 -0.2063"/>
    <axis xyz="0 0 1"/>
    <limit effort="0.0" lower="-3.14159265359" upper="3.14159265359" velocity="0.0"/>
  </joint>
  <joint name="joint_hip_left" type="revolute">
    <parent link="hip"/>
    <child link="thigh_left"/>
    <origin rpy="0 0 0" xyz="4.59109 0.61586 0.1577"/>
    <axis xyz="0 0 1"/>
    <limit effort="0.0" lower="-3.14159265359" upper="3.14159265359" velocity="0.0"/>
  </joint>
  <joint name="joint_knee_left" type="revolute">
    <parent link="thigh_left"/>
    <child link="leg_left"/>
    <origin rpy="0 0 0" xyz="0.04271 -0.30621 -0.02405"/>
    <axis xyz="0 0 1"/>
    <limit effort="0.0" lower="-3.14159265359" upper="3.14159265359" velocity="0.0"/>
  </joint>
  <joint name="joint_knee_right" type="revolute">
    <parent link="thigh_right"/>
    <child link="leg_right"/>
    <origin rpy="0 0 0" xyz="-0.30127 -0.0694  -0.0077"/>
    <axis xyz="0  0 -1"/>
    <limit effort="0.0" lower="-3.14159265359" upper="3.14159265359" velocity="0.0"/>
  </joint>
  <joint name="joint_foot_left" type="revolute">
    <parent link="leg_left"/>
    <child link="foot_left"/>
    <origin rpy="0 0 0" xyz="-0.00521 -0.3491  -0.0055"/>
    <axis xyz="0  0 -1"/>
    <limit effort="0.0" lower="-3.14159265359" upper="3.14159265359" velocity="0.0"/>
  </joint>
  <joint name="joint_foot_right" type="revolute">
    <parent link="leg_right"/>
    <child link="foot_right"/>
    <origin rpy="0 0 0" xyz="0.26746 -0.22442 -0.0055"/>
    <axis xyz="0 0 1"/>
    <limit effort="0.0" lower="-3.14159265359" upper="3.14159265359" velocity="0.0"/>
  </joint>
  <link name="bike">
    <inertial>
      <mass value="9.123377965809581"/>
      <origin rpy="0 0 0" xyz="-0.33357 -0.02899  0.03417"/>
      <inertia ixx="0.16346290903950503" ixy="-1.9666610132662103" ixz="0.01173377483333641" iyy="162.13648331160095" iyz="1.1393797176519782" izz="162.27448532188913"/>
    </inertial>
    <collision name="bike_collision">
      <origin rpy="0 0 0" xyz="-0.33357 -0.02899  0.03417"/>
      <geometry>
        <mesh filename="package://robots/rikshaw/meshes/CAD/bike.stl" scale="0.001 0.001 0.001"/>
      </geometry>
    </collision>
    <visual name="bike_visual">
      <origin rpy="0 0 0" xyz="-0.33357 -0.02899  0.03417"/>
      <geometry>
        <mesh filename="package://robots/rikshaw/meshes/CAD/bike.stl" scale="0.001 0.001 0.001"/>
      </geometry>
    </visual>
  </link>
  <link name="pedal_left">
    <inertial>
      <mass value="1.4041650832964538"/>
      <origin rpy="0 0 0" xyz="0.00181  0.12182 -0.12413"/>
      <inertia ixx="0.015820415845091626" ixy="-0.1583353443063753" ixz="-0.0003524302760303509" iyy="28.61801360912151" iyz="-0.4596741409198141" izz="28.61561216582371"/>
    </inertial>
    <collision name="pedal_left_collision">
      <origin rpy="0 0 0" xyz="0.00181  0.12182 -0.12413"/>
      <geometry>
        <mesh filename="package://robots/rikshaw/meshes/CAD/pedal_left.stl" scale="0.001 0.001 0.001"/>
      </geometry>
    </collision>
    <visual name="pedal_left_visual">
      <origin rpy="0 0 0" xyz="0.00181  0.12182 -0.12413"/>
      <geometry>
        <mesh filename="package://robots/rikshaw/meshes/CAD/pedal_left.stl" scale="0.001 0.001 0.001"/>
      </geometry>
    </visual>
  </link>
  <link name="pedal_right">
    <inertial>
      <mass value="1.3791057548146473"/>
      <origin rpy="0 0 0" xyz="0.03989 -0.11647  0.12446"/>
      <inertia ixx="0.04857612245235656" ixy="-0.7160938598379938" ixz="0.022798947227890415" iyy="27.93660227293208" iyz="0.8064744535092542" izz="27.935057812607344"/>
    </inertial>
    <collision name="pedal_right_collision">
      <origin rpy="0 0 0" xyz="0.03989 -0.11647  0.12446"/>
      <geometry>
        <mesh filename="package://robots/rikshaw/meshes/CAD/pedal_right.stl" scale="0.001 0.001 0.001"/>
      </geometry>
    </collision>
    <visual name="pedal_right_visual">
      <origin rpy="0 0 0" xyz="0.03989 -0.11647  0.12446"/>
      <geometry>
        <mesh filename="package://robots/rikshaw/meshes/CAD/pedal_right.stl" scale="0.001 0.001 0.001"/>
      </geometry>
    </visual>
  </link>
  <link name="thigh_right">
    <inertial>
      <mass value="5.563551777256041"/>
      <origin rpy="0 0 0" xyz="-0.10868 -0.02353 -0.0219"/>
      <inertia ixx="2.2540844818461845" ixy="-14.773567350941738" ixz="0.7526493866122135" iyy="112.10031362234692" iyz="5.69406085836139" izz="113.76568617013422"/>
    </inertial>
    <collision name="thigh_right_collision">
      <origin rpy="0 0 0" xyz="-0.10868 -0.02353 -0.0219"/>
      <geometry>
        <mesh filename="package://robots/rikshaw/meshes/CAD/thigh_right.stl" scale="0.001 0.001 0.001"/>
      </geometry>
    </collision>
    <visual name="thigh_right_visual">
      <origin rpy="0 0 0" xyz="-0.10868 -0.02353 -0.0219"/>
      <geometry>
        <mesh filename="package://robots/rikshaw/meshes/CAD/thigh_right.stl" scale="0.001 0.001 0.001"/>
      </geometry>
    </visual>
  </link>
  <link name="thigh_left">
    <inertial>
      <mass value="5.563588220882872"/>
      <origin rpy="0 0 0" xyz="0.0142  -0.11031  0.01055"/>
      <inertia ixx="1.6077548688712473" ixy="-12.952780859734082" ixz="-0.47622162028353426" iyy="118.16643321608184" iyz="-4.310161865753099" izz="119.4499519644409"/>
    </inertial>
    <collision name="thigh_left_collision">
      <origin rpy="0 0 0" xyz="0.0142  -0.11031  0.01055"/>
      <geometry>
        <mesh filename="package://robots/rikshaw/meshes/CAD/thigh_left.stl" scale="0.001 0.001 0.001"/>
      </geometry>
    </collision>
    <visual name="thigh_left_visual">
      <origin rpy="0 0 0" xyz="0.0142  -0.11031  0.01055"/>
      <geometry>
        <mesh filename="package://robots/rikshaw/meshes/CAD/thigh_left.stl" scale="0.001 0.001 0.001"/>
      </geometry>
    </visual>
  </link>
  <link name="leg_right">
    <inertial>
      <mass value="5.74162172765816"/>
      <origin rpy="0 0 0" xyz="0.11023 -0.10246 -0.01363"/>
      <inertia ixx="1.450690266700547" ixy="-11.203822382085622" ixz="0.5828509903319964" iyy="111.48947401354596" iyz="5.74858660109064" izz="112.3356099041297"/>
    </inertial>
    <collision name="leg_right_collision">
      <origin rpy="0 0 0" xyz="0.11023 -0.10246 -0.01363"/>
      <geometry>
        <mesh filename="package://robots/rikshaw/meshes/CAD/leg_right.stl" scale="0.001 0.001 0.001"/>
      </geometry>
    </collision>
    <visual name="leg_right_visual">
      <origin rpy="0 0 0" xyz="0.11023 -0.10246 -0.01363"/>
      <geometry>
        <mesh filename="package://robots/rikshaw/meshes/CAD/leg_right.stl" scale="0.001 0.001 0.001"/>
      </geometry>
    </visual>
  </link>
  <link name="leg_left">
    <inertial>
      <mass value="5.742615306134412"/>
      <origin rpy="0 0 0" xyz="-0.00987 -0.15015  0.03366"/>
      <inertia ixx="0.34676911359298046" ixy="-4.233350605272005" ixz="-0.15668987959500288" iyy="122.95463045223542" iyz="-4.442841032506932" izz="122.97037522179788"/>
    </inertial>
    <collision name="leg_left_collision">
      <origin rpy="0 0 0" xyz="-0.00987 -0.15015  0.03366"/>
      <geometry>
        <mesh filename="package://robots/rikshaw/meshes/CAD/leg_left.stl" scale="0.001 0.001 0.001"/>
      </geometry>
    </collision>
    <visual name="leg_left_visual">
      <origin rpy="0 0 0" xyz="-0.00987 -0.15015  0.03366"/>
      <geometry>
        <mesh filename="package://robots/rikshaw/meshes/CAD/leg_left.stl" scale="0.001 0.001 0.001"/>
      </geometry>
    </visual>
  </link>
  <link name="hip">
    <inertial>
      <mass value="13.796356920916345"/>
      <origin rpy="0 0 0" xyz="4.58813  0.74863 -0.03004"/>
      <inertia ixx="8.07789701100973" ixy="-47.38781270121512" ixz="0.3103935607232576" iyy="290.76482385847" iyz="1.902413734220211" izz="298.2357019675895"/>
    </inertial>
    <collision name="hip_collision">
      <origin rpy="0 0 0" xyz="4.58813  0.74863 -0.03004"/>
      <geometry>
        <mesh filename="package://robots/rikshaw/meshes/CAD/hip.stl" scale="0.001 0.001 0.001"/>
      </geometry>
    </collision>
    <visual name="hip_visual">
      <origin rpy="0 0 0" xyz="4.58813  0.74863 -0.03004"/>
      <geometry>
        <mesh filename="package://robots/rikshaw/meshes/CAD/hip.stl" scale="0.001 0.001 0.001"/>
      </geometry>
    </visual>
  </link>
  <link name="foot_right">
    <inertial>
      <mass value="1.9533513694241225"/>
      <origin rpy="0 0 0" xyz="-0.05715 -0.06316  0.01154"/>
      <inertia ixx="0.21845609130671984" ixy="-2.2786036133127396" ixz="0.1049395043743295" iyy="39.6484872601728" iyz="1.827653334790452" izz="39.69611493273963"/>
    </inertial>
    <collision name="foot_right_collision">
      <origin rpy="0 0 0" xyz="-0.05715 -0.06316  0.01154"/>
      <geometry>
        <mesh filename="package://robots/rikshaw/meshes/CAD/foot_right.stl" scale="0.001 0.001 0.001"/>
      </geometry>
    </collision>
    <visual name="foot_right_visual">
      <origin rpy="0 0 0" xyz="-0.05715 -0.06316  0.01154"/>
      <geometry>
        <mesh filename="package://robots/rikshaw/meshes/CAD/foot_right.stl" scale="0.001 0.001 0.001"/>
      </geometry>
    </visual>
  </link>
  <link name="foot_left">
    <inertial>
      <mass value="1.953351402134416"/>
      <origin rpy="0 0 0" xyz="-0.07178 -0.04334  0.02089"/>
      <inertia ixx="0.05846825609853681" ixy="0.7355006503840088" ixz="0.024248791652542182" iyy="40.61121359949935" iyz="-1.3262454939985975" izz="40.58097122730241"/>
    </inertial>
    <collision name="foot_left_collision">
      <origin rpy="0 0 0" xyz="-0.07178 -0.04334  0.02089"/>
      <geometry>
        <mesh filename="package://robots/rikshaw/meshes/CAD/foot_left.stl" scale="0.001 0.001 0.001"/>
      </geometry>
    </collision>
    <visual name="foot_left_visual">
      <origin rpy="0 0 0" xyz="-0.07178 -0.04334  0.02089"/>
      <geometry>
        <mesh filename="package://robots/rikshaw/meshes/CAD/foot_left.stl" scale="0.001 0.001 0.001"/>
      </geometry>
    </visual>
  </link>
</robot>
