<?xml version="1.0" ?>
<sdf version="1.6">
	<model name="rikshaw">
		<link name="bike">
			<self_collide>false</self_collide>
			<pose frame="">4.131579748021964 0.006489838411077831 -0.02977667897897922 0.0 -0.0 0.0</pose>
			<inertial>
				<pose frame="">0.0 0.0 0.0 0 0 0</pose>
				<mass>9.123372404145295</mass>
				<inertia>
					<ixx>0.17093742101265288</ixx>
					<ixy>-0.6439083609700426</ixy>
					<ixz>0.001851985163027304</ixz>
					<iyy>158.38284353329578</iyy>
					<iyz>1.1260191551165304</iyz>
					<izz>158.52832005559148</izz>
				</inertia>
			</inertial>
			<collision name="bike_collision">
				<geometry>
					<mesh>
						<uri>model://rikshaw/meshes/CAD/bike.stl</uri>
						<scale>0.001 0.001 0.001</scale>
					</mesh>
				</geometry>
			</collision>
			<visual name="bike_visual">
				<geometry>
					<mesh>
						<uri>model://rikshaw/meshes/CAD/bike.stl</uri>
						<scale>0.001 0.001 0.001</scale>
					</mesh>
				</geometry>
			</visual>
		</link>
		<link name="pedal_left">
			<self_collide>false</self_collide>
			<pose frame="">4.474047106928748 0.0005139113343922151 0.0725299926087887 0.0 -0.0 0.0</pose>
			<inertial>
				<pose frame="">0.0 0.0 0.0 0 0 0</pose>
				<mass>1.4041650832963233</mass>
				<inertia>
					<ixx>0.014689396282226548</ixx>
					<ixy>-0.002046612762490566</ixy>
					<ixz>0.0020889090747527473</ixz>
					<iyy>28.11681244961605</iyy>
					<iyz>-0.45611884464196356</iyz>
					<izz>28.113279986970344</izz>
				</inertia>
			</inertial>
			<collision name="pedal_left_collision">
				<geometry>
					<mesh>
						<uri>model://rikshaw/meshes/CAD/pedal_left.stl</uri>
						<scale>0.001 0.001 0.001</scale>
					</mesh>
				</geometry>
			</collision>
			<visual name="pedal_left_visual">
				<geometry>
					<mesh>
						<uri>model://rikshaw/meshes/CAD/pedal_left.stl</uri>
						<scale>0.001 0.001 0.001</scale>
					</mesh>
				</geometry>
			</visual>
		</link>
		<link name="pedal_right">
			<self_collide>false</self_collide>
			<pose frame="">4.454588267227227 0.09193307049294273 -0.13010528274151725 0.0 -0.0 0.0</pose>
			<inertial>
				<pose frame="">0.0 0.0 0.0 0 0 0</pose>
				<mass>1.37910575481467</mass>
				<inertia>
					<ixx>0.0421743971885497</ixx>
					<ixy>-0.5636765255442244</ixy>
					<ixz>0.018614661902484543</ixz>
					<iyy>27.391501878818794</iyy>
					<iyz>0.7988519839415706</iyz>
					<izz>27.383555692846585</izz>
				</inertia>
			</inertial>
			<collision name="pedal_right_collision">
				<geometry>
					<mesh>
						<uri>model://rikshaw/meshes/CAD/pedal_right.stl</uri>
						<scale>0.001 0.001 0.001</scale>
					</mesh>
				</geometry>
			</collision>
			<visual name="pedal_right_visual">
				<geometry>
					<mesh>
						<uri>model://rikshaw/meshes/CAD/pedal_right.stl</uri>
						<scale>0.001 0.001 0.001</scale>
					</mesh>
				</geometry>
			</visual>
		</link>
		<link name="thigh_right">
			<self_collide>false</self_collide>
			<pose frame="">4.482406978583961 0.5923290572515558 -0.22820807094029077 0.0 -0.0 0.0</pose>
			<inertial>
				<pose frame="">0.0 0.0 0.0 0 0 0</pose>
				<mass>5.563551775927808</mass>
				<inertia>
					<ixx>2.2540844816246466</ixx>
					<ixy>-14.773567348478899</ixy>
					<ixz>0.7526493865535845</ixz>
					<iyy>112.10031359674326</iyy>
					<iyz>5.694060857559583</iyz>
					<izz>113.76568614434035</izz>
				</inertia>
			</inertial>
			<collision name="thigh_right_collision">
				<geometry>
					<mesh>
						<uri>model://rikshaw/meshes/CAD/thigh_right.stl</uri>
						<scale>0.001 0.001 0.001</scale>
					</mesh>
				</geometry>
			</collision>
			<visual name="thigh_right_visual">
				<geometry>
					<mesh>
						<uri>model://rikshaw/meshes/CAD/thigh_right.stl</uri>
						<scale>0.001 0.001 0.001</scale>
					</mesh>
				</geometry>
			</visual>
		</link>
		<link name="thigh_left">
			<self_collide>false</self_collide>
			<pose frame="">4.595876869382048 0.5047400667081398 0.1682556506297993 0.0 -0.0 0.0</pose>
			<inertial>
				<pose frame="">0.0 0.0 0.0 0 0 0</pose>
				<mass>5.563591173165814</mass>
				<inertia>
					<ixx>1.6031563220499725</ixx>
					<ixy>-12.907005690422219</ixy>
					<ixz>-0.4755295405561013</ixz>
					<iyy>117.6840240023188</iyy>
					<iyz>-4.301596584809158</iyz>
					<izz>118.96294393154832</izz>
				</inertia>
			</inertial>
			<collision name="thigh_left_collision">
				<geometry>
					<mesh>
						<uri>model://rikshaw/meshes/CAD/thigh_left.stl</uri>
						<scale>0.001 0.001 0.001</scale>
					</mesh>
				</geometry>
			</collision>
			<visual name="thigh_left_visual">
				<geometry>
					<mesh>
						<uri>model://rikshaw/meshes/CAD/thigh_left.stl</uri>
						<scale>0.001 0.001 0.001</scale>
					</mesh>
				</geometry>
			</visual>
		</link>
		<link name="leg_right">
			<self_collide>false</self_collide>
			<pose frame="">4.389690776822594 0.433860790349951 -0.22763758059414468 0.0 -0.0 0.0</pose>
			<inertial>
				<pose frame="">0.0 0.0 0.0 0 0 0</pose>
				<mass>5.741541926498232</mass>
				<inertia>
					<ixx>1.4021784642612571</ixx>
					<ixy>-10.921123103233803</ixy>
					<ixz>0.5698103162846716</ixz>
					<iyy>110.96190199569567</iyy>
					<iyz>5.735197097520718</iyz>
					<izz>111.75953654424973</izz>
				</inertia>
			</inertial>
			<collision name="leg_right_collision">
				<geometry>
					<mesh>
						<uri>model://rikshaw/meshes/CAD/leg_right.stl</uri>
						<scale>0.001 0.001 0.001</scale>
					</mesh>
				</geometry>
			</collision>
			<visual name="leg_right_visual">
				<geometry>
					<mesh>
						<uri>model://rikshaw/meshes/CAD/leg_right.stl</uri>
						<scale>0.001 0.001 0.001</scale>
					</mesh>
				</geometry>
			</visual>
		</link>
		<link name="leg_left">
			<self_collide>false</self_collide>
			<pose frame="">4.598629618603139 0.1569181399062989 0.16731935488900093 0.0 -0.0 0.0</pose>
			<inertial>
				<pose frame="">0.0 0.0 0.0 0 0 0</pose>
				<mass>5.742617795848039</mass>
				<inertia>
					<ixx>0.3420650596526541</ixx>
					<ixy>-4.1419635133241695</ixy>
					<ixz>-0.15421345580619206</ixz>
					<iyy>121.6146044398638</iyy>
					<iyz>-4.418511753540427</iyz>
					<izz>121.62564473735647</izz>
				</inertia>
			</inertial>
			<collision name="leg_left_collision">
				<geometry>
					<mesh>
						<uri>model://rikshaw/meshes/CAD/leg_left.stl</uri>
						<scale>0.001 0.001 0.001</scale>
					</mesh>
				</geometry>
			</collision>
			<visual name="leg_left_visual">
				<geometry>
					<mesh>
						<uri>model://rikshaw/meshes/CAD/leg_left.stl</uri>
						<scale>0.001 0.001 0.001</scale>
					</mesh>
				</geometry>
			</visual>
		</link>
		<link name="hip">
			<self_collide>false</self_collide>
			<pose frame="">4.5881393646769375 0.7486351489098538 -0.030047322415476373 0.0 -0.0 0.0</pose>
			<inertial>
				<pose frame="">0.0 0.0 0.0 0 0 0</pose>
				<mass>13.796356920916345</mass>
				<inertia>
					<ixx>8.07789701100973</ixx>
					<ixy>-47.38781270121511</ixy>
					<ixz>0.3103935607232576</ixz>
					<iyy>290.76482385847</iyy>
					<iyz>1.9024137342202108</iyz>
					<izz>298.2357019675895</izz>
				</inertia>
			</inertial>
			<collision name="hip_collision">
				<geometry>
					<mesh>
						<uri>model://rikshaw/meshes/CAD/hip.stl</uri>
						<scale>0.001 0.001 0.001</scale>
					</mesh>
				</geometry>
			</collision>
			<visual name="hip_visual">
				<geometry>
					<mesh>
						<uri>model://rikshaw/meshes/CAD/hip.stl</uri>
						<scale>0.001 0.001 0.001</scale>
					</mesh>
				</geometry>
			</visual>
		</link>
		<link name="foot_right">
			<self_collide>false</self_collide>
			<pose frame="">4.4740023777634415 0.23730908152868538 -0.20795362849129093 0.0 -0.0 0.0</pose>
			<inertial>
				<pose frame="">0.0 0.0 0.0 0 0 0</pose>
				<mass>1.9533512703186307</mass>
				<inertia>
					<ixx>0.19724326335819248</ixx>
					<ixy>-2.0767895260571185</ixy>
					<ixz>0.0961999452380023</ixz>
					<iyy>39.19082122006376</iyy>
					<iyz>1.8170296870342606</iyz>
					<izz>39.21723607050836</izz>
				</inertia>
			</inertial>
			<collision name="foot_right_collision">
				<geometry>
					<mesh>
						<uri>model://rikshaw/meshes/CAD/foot_right.stl</uri>
						<scale>0.001 0.001 0.001</scale>
					</mesh>
				</geometry>
			</collision>
			<visual name="foot_right_visual">
				<geometry>
					<mesh>
						<uri>model://rikshaw/meshes/CAD/foot_right.stl</uri>
						<scale>0.001 0.001 0.001</scale>
					</mesh>
				</geometry>
			</visual>
		</link>
		<link name="foot_left">
			<self_collide>false</self_collide>
			<pose frame="">4.5412253393430015 -0.09709228053316478 0.14904779823071668 0.0 -0.0 0.0</pose>
			<inertial>
				<pose frame="">0.0 0.0 0.0 0 0 0</pose>
				<mass>1.953351560572059</mass>
				<inertia>
					<ixx>0.06417499609160866</ixx>
					<ixy>0.8588547922529037</ixy>
					<ixz>0.028482518242203554</ixz>
					<iyy>40.333586044963496</iyy>
					<iyz>-1.3217395956062616</iyz>
					<izz>40.30905041196981</izz>
				</inertia>
			</inertial>
			<collision name="foot_left_collision">
				<geometry>
					<mesh>
						<uri>model://rikshaw/meshes/CAD/foot_left.stl</uri>
						<scale>0.001 0.001 0.001</scale>
					</mesh>
				</geometry>
			</collision>
			<visual name="foot_left_visual">
				<geometry>
					<mesh>
						<uri>model://rikshaw/meshes/CAD/foot_left.stl</uri>
						<scale>0.001 0.001 0.001</scale>
					</mesh>
				</geometry>
			</visual>
		</link>
		<joint name="joint_pedal_right" type="revolute">
			<parent>pedal_right</parent>
			<child>foot_right</child>
			<pose frame="">-0.04258658159526874 -0.02446006176182138 -0.0466135046050475 0 0 0</pose>
			<axis>
				<xyz>-1.1979912112813704e-14 2.3358675429566076e-10 -0.9999999999999953</xyz>
				<limit>
					<lower>-3.141592653589793</lower>
					<upper>3.141592653589793</upper>
				</limit>
				<use_parent_model_frame>0</use_parent_model_frame>
			</axis>
		</joint>
		<joint name="joint_bike_right" type="revolute">
			<parent>bike</parent>
			<child>pedal_right</child>
			<pose frame="">0.0093960579970053 -0.045159259685814704 0.06615514960638472 0 0 0</pose>
			<axis>
				<xyz>-2.537627663319977e-15 2.335889876728244e-10 -1.0</xyz>
				<limit>
					<lower>-3.141592653589793</lower>
					<upper>3.141592653589793</upper>
				</limit>
				<use_parent_model_frame>0</use_parent_model_frame>
			</axis>
		</joint>
		<joint name="joint_bike_left" type="revolute">
			<parent>bike</parent>
			<child>pedal_left</child>
			<pose frame="">-0.010062781704514237 0.04625989945638452 -0.06647981871190926 0 0 0</pose>
			<axis>
				<xyz>-2.537627663319977e-15 2.335889876728244e-10 -1.0</xyz>
				<limit>
					<lower>-3.141592653589793</lower>
					<upper>3.141592653589793</upper>
				</limit>
				<use_parent_model_frame>0</use_parent_model_frame>
			</axis>
		</joint>
		<joint name="joint_pedal_left" type="revolute">
			<parent>pedal_left</parent>
			<child>foot_left</child>
			<pose frame="">-0.04166075977001924 -0.021529646216835962 0.04761937562752845 0 0 0</pose>
			<axis>
				<xyz>-1.4643984436989822e-13 -2.335975556973714e-10 0.9999999999999992</xyz>
				<limit>
					<lower>-3.141592653589793</lower>
					<upper>3.141592653589793</upper>
				</limit>
				<use_parent_model_frame>0</use_parent_model_frame>
			</axis>
		</joint>
		<joint name="joint_hip_right" type="revolute">
			<parent>hip</parent>
			<child>thigh_right</child>
			<pose frame="">0.10868851823958153 0.023532041589804962 0.021908070993561814 0 0 0</pose>
			<axis>
				<xyz>4.7139676717674495e-12 -4.747103063846467e-10 1.0</xyz>
				<limit>
					<lower>-3.141592653589793</lower>
					<upper>3.141592653589793</upper>
				</limit>
				<use_parent_model_frame>0</use_parent_model_frame>
			</axis>
		</joint>
		<joint name="joint_hip_left" type="revolute">
			<parent>hip</parent>
			<child>thigh_left</child>
			<pose frame="">-0.004781372556813039 0.11112103196042625 -0.01055565058700724 0 0 0</pose>
			<axis>
				<xyz>4.714070638884272e-12 -4.747097531970313e-10 1.0</xyz>
				<limit>
					<lower>-3.141592653589793</lower>
					<upper>3.141592653589793</upper>
				</limit>
				<use_parent_model_frame>0</use_parent_model_frame>
			</axis>
		</joint>
		<joint name="joint_knee_left" type="revolute">
			<parent>thigh_left</parent>
			<child>leg_left</child>
			<pose frame="">0.009000470929301514 0.15020705667403828 -0.033669354987951684 0 0 0</pose>
			<axis>
				<xyz>7.781012720611506e-13 -2.7304206476907006e-10 1.0000000000000004</xyz>
				<limit>
					<lower>-3.141592653589793</lower>
					<upper>3.141592653589793</upper>
				</limit>
				<use_parent_model_frame>0</use_parent_model_frame>
			</axis>
		</joint>
		<joint name="joint_knee_right" type="revolute">
			<parent>thigh_right</parent>
			<child>leg_right</child>
			<pose frame="">-0.0998660150286355 0.11259610022346692 0.013637580592141312 0 0 0</pose>
			<axis>
				<xyz>3.992581482318776e-11 4.832701806911493e-10 -1.0000000000000002</xyz>
				<limit>
					<lower>-3.141592653589793</lower>
					<upper>3.141592653589793</upper>
				</limit>
				<use_parent_model_frame>0</use_parent_model_frame>
			</axis>
		</joint>
		<joint name="joint_foot_left" type="revolute">
			<parent>leg_left</parent>
			<child>foot_left</child>
			<pose frame="">0.0632246916494131 0.055088722599360374 -0.020897798428385708 0 0 0</pose>
			<axis>
				<xyz>1.5062616827321692e-10 1.5145911274643596e-10 -0.999999999999997</xyz>
				<limit>
					<lower>-3.141592653589793</lower>
					<upper>3.141592653589793</upper>
				</limit>
				<use_parent_model_frame>0</use_parent_model_frame>
			</axis>
		</joint>
		<joint name="joint_foot_right" type="revolute">
			<parent>leg_right</parent>
			<child>foot_right</child>
			<pose frame="">0.060445053417886356 0.06002785848687992 -0.011546372175624563 0 0 0</pose>
			<axis>
				<xyz>-1.0930223258736039e-10 -6.773951306649867e-10 0.9999999999999976</xyz>
				<limit>
					<lower>-3.141592653589793</lower>
					<upper>3.141592653589793</upper>
				</limit>
				<use_parent_model_frame>0</use_parent_model_frame>
			</axis>
		</joint>
		<plugin filename="libmusc_plugin.so" name="musc_plugin">
			<myoMuscle name="motor0">
				<link name="hip">
					<viaPoint type="FIXPOINT">0.05849944634156998 -0.07555273909391502 0.1737973224766655</viaPoint>
				</link>
				<link name="thigh_left">
					<viaPoint type="FIXPOINT">0.07275989933909557 0.11408734943621723 -0.024505650587219385</viaPoint>
					<viaPoint type="FIXPOINT">0.04136030747803204 0.008175771551510138 -0.024505650613322362</viaPoint>
				</link>
			</myoMuscle>
			<myoMuscle name="motor1">
				<link name="hip">
					<viaPoint type="FIXPOINT">-0.04395598260931649 -0.07566650232475568 0.17119732247131877</viaPoint>
				</link>
				<link name="thigh_left">
					<viaPoint type="FIXPOINT">-0.05197207031135861 0.014280957648814763 -0.026255650611844636</viaPoint>
				</link>
			</myoMuscle>
			<myoMuscle name="motor2">
				<link name="hip">
					<viaPoint type="FIXPOINT">-0.04673305960734979 -0.07566650224068709 -0.1772026775294457</viaPoint>
				</link>
				<link name="thigh_right">
					<viaPoint type="FIXPOINT">0.011746906517065555 0.0495359636646338 0.02270807099836073</viaPoint>
				</link>
			</myoMuscle>
			<myoMuscle name="motor3">
				<link name="hip">
					<viaPoint type="FIXPOINT">0.05407410315142329 -0.07566650224069875 -0.1772026775189286</viaPoint>
				</link>
				<link name="thigh_right">
					<viaPoint type="FIXPOINT">0.1324111060580583 -0.05574653765874921 0.021708070972956472</viaPoint>
					<viaPoint type="FIXPOINT">0.02362595373000147 -0.04427935261240577 0.024458070995563935</viaPoint>
				</link>
			</myoMuscle>
			<myoMuscle name="motor4">
				<link name="thigh_right">
					<viaPoint type="FIXPOINT">-0.07507117889137874 0.023894994284277188 0.027354052768398206</viaPoint>
				</link>
				<link name="leg_right">
					<viaPoint type="FIXPOINT">-0.16533806818530822 0.04781919783865625 0.02663758006382203</viaPoint>
					<viaPoint type="FIXPOINT">-0.049856010448851296 -0.01862003938593233 0.025742843190443416</viaPoint>
				</link>
			</myoMuscle>
			<myoMuscle name="motor5">
				<link name="thigh_right">
					<viaPoint type="FIXPOINT">-0.0640802445788995 -0.05030116431118863 0.0226551740822228</viaPoint>
				</link>
				<link name="leg_right">
					<viaPoint type="FIXPOINT">0.009412552936395854 0.05310956564219076 0.02563758006909026</viaPoint>
				</link>
			</myoMuscle>
			<myoMuscle name="motor6">
				<link name="thigh_left">
					<viaPoint type="FIXPOINT">-0.044116668151784215 -0.07510263905072016 -0.027485508707160895</viaPoint>
				</link>
				<link name="leg_left">
					<viaPoint type="FIXPOINT">-0.08861827826147475 0.14613925293170565 -0.020569354825225778</viaPoint>
					<viaPoint type="FIXPOINT">-0.04915966837369979 0.022930275485291265 -0.021569354864026877</viaPoint>
				</link>
			</myoMuscle>
			<myoMuscle name="motor7">
				<link name="thigh_left">
					<viaPoint type="FIXPOINT">0.037817941788994745 -0.07545010154681264 -0.027535765278674323</viaPoint>
				</link>
				<link name="leg_left">
					<viaPoint type="FIXPOINT">0.04264230915555743 0.01712103080642267 -0.0255693548745894</viaPoint>
				</link>
			</myoMuscle>
			<myoMuscle name="motor8">
				<link name="leg_left">
					<viaPoint type="FIXPOINT">0.039943182586570744 -0.07251874274106794 -0.02684946756011543</viaPoint>
				</link>
				<link name="foot_left">
					<viaPoint type="FIXPOINT">0.10333149401028607 0.017098023060091876 -0.007297798191368834</viaPoint>
				</link>
			</myoMuscle>
			<myoMuscle name="motor9">
				<link name="leg_left">
					<viaPoint type="FIXPOINT">-0.044893376020737605 -0.07288612119701998 -0.02601979010157274</viaPoint>
				</link>
				<link name="foot_left">
					<viaPoint type="FIXPOINT">-0.02406130858488723 0.01682627510466313 -0.007297798236402801</viaPoint>
				</link>
			</myoMuscle>
			<myoMuscle name="motor10">
				<link name="leg_right">
					<viaPoint type="FIXPOINT">0.025229304242655532 -0.07122500315519084 0.025272245083924717</viaPoint>
				</link>
				<link name="foot_right">
					<viaPoint type="FIXPOINT">-0.0068700760266222 0.013362310712564671 0.003953627785407044</viaPoint>
				</link>
			</myoMuscle>
			<myoMuscle name="motor11">
				<link name="leg_right">
					<viaPoint type="FIXPOINT">0.07972175621445331 -0.017144531520149754 0.021671285690849834</viaPoint>
				</link>
				<link name="foot_right">
					<viaPoint type="FIXPOINT">0.11752359386542083 0.040843484100710516 0.003953627817618646</viaPoint>
				</link>
			</myoMuscle>
		</plugin>
	</model>
</sdf>
