<?xml version="1.0" ?>
<sdf version="1.6">
	<model name="rikshaw">
		<link name="bike">
			<self_collide>false</self_collide>
			<pose frame="">-0.08857855461656707 0.03232678669767529 0.1146025606045478 0.0 -0.0 0.0</pose>
			<inertial>
				<pose frame="">0.0 0.0 0.0 0 0 0</pose>
				<mass>9.123374541674044</mass>
				<inertia>
					<ixx>0.2676110458247469</ixx>
					<ixy>0.022504055650875893</ixy>
					<ixz>-0.033766151670108296</ixz>
					<iyy>2.9838143890229882</iyy>
					<iyz>-0.22182970031409888</iyz>
					<izz>2.7445539890238853</izz>
				</inertia>
			</inertial>
			<collision name="bike_collision">
				<geometry>
					<mesh>
						<uri>model://rikshaw/meshes/CAD/bike.stl</uri>
						<scale>0.001 0.001 0.001</scale>
					</mesh>
				</geometry>
			</collision>
			<visual name="bike_visual">
				<geometry>
					<mesh>
						<uri>model://rikshaw/meshes/CAD/bike.stl</uri>
						<scale>0.001 0.001 0.001</scale>
					</mesh>
				</geometry>
			</visual>
		</link>
		<link name="pedal_left">
			<self_collide>false</self_collide>
			<pose frame="">0.2444488071691209 -0.06998001899389801 0.09625710324688459 0.0 -0.0 0.0</pose>
			<inertial>
				<pose frame="">0.0 0.0 0.0 0 0 0</pose>
				<mass>1.4041650832964538</mass>
				<inertia>
					<ixx>0.02744479218908917</ixx>
					<ixy>0.023992648630360568</ixy>
					<ixz>0.007267871424477564</ixz>
					<iyy>0.10288660231176043</iyy>
					<iyz>-0.03310858577936466</iyz>
					<izz>0.09264313094014832</izz>
				</inertia>
			</inertial>
			<collision name="pedal_left_collision">
				<geometry>
					<mesh>
						<uri>model://rikshaw/meshes/CAD/pedal_left.stl</uri>
						<scale>0.001 0.001 0.001</scale>
					</mesh>
				</geometry>
			</collision>
			<visual name="pedal_left_visual">
				<geometry>
					<mesh>
						<uri>model://rikshaw/meshes/CAD/pedal_left.stl</uri>
						<scale>0.001 0.001 0.001</scale>
					</mesh>
				</geometry>
			</visual>
		</link>
		<link name="pedal_right">
			<self_collide>false</self_collide>
			<pose frame="">0.22936974881958036 0.13265525635124195 0.18699204441983652 0.0 -0.0 0.0</pose>
			<inertial>
				<pose frame="">0.0 0.0 0.0 0 0 0</pose>
				<mass>1.3791057548146732</mass>
				<inertia>
					<ixx>0.0792588266121774</ixx>
					<ixy>-0.041239315608420014</ixy>
					<ixz>-0.036247382164239415</ixz>
					<iyy>0.12658985919785845</iyy>
					<iyz>-0.05738482595103527</iyz>
					<izz>0.09929970693471371</izz>
				</inertia>
			</inertial>
			<collision name="pedal_right_collision">
				<geometry>
					<mesh>
						<uri>model://rikshaw/meshes/CAD/pedal_right.stl</uri>
						<scale>0.001 0.001 0.001</scale>
					</mesh>
				</geometry>
			</collision>
			<visual name="pedal_right_visual">
				<geometry>
					<mesh>
						<uri>model://rikshaw/meshes/CAD/pedal_right.stl</uri>
						<scale>0.001 0.001 0.001</scale>
					</mesh>
				</geometry>
			</visual>
		</link>
		<link name="thigh_right">
			<self_collide>false</self_collide>
			<pose frame="">0.2130676220272979 0.23075804961914492 0.6636155811866733 0.0 -0.0 0.0</pose>
			<inertial>
				<pose frame="">0.0 0.0 0.0 0 0 0</pose>
				<mass>5.563551531361345</mass>
				<inertia>
					<ixx>2.7587103141393774</ixx>
					<ixy>-0.27653691454319923</ixy>
					<ixz>-0.8525725925194048</ixz>
					<iyy>2.7338304215308424</iyy>
					<iyz>-0.7886856442807302</iyz>
					<izz>0.5768546331244859</izz>
				</inertia>
			</inertial>
			<collision name="thigh_right_collision">
				<geometry>
					<mesh>
						<uri>model://rikshaw/meshes/CAD/thigh_right.stl</uri>
						<scale>0.001 0.001 0.001</scale>
					</mesh>
				</geometry>
			</collision>
			<visual name="thigh_right_visual">
				<geometry>
					<mesh>
						<uri>model://rikshaw/meshes/CAD/thigh_right.stl</uri>
						<scale>0.001 0.001 0.001</scale>
					</mesh>
				</geometry>
			</visual>
		</link>
		<link name="thigh_left">
			<self_collide>false</self_collide>
			<pose frame="">0.33596172751211206 -0.165705685121125 0.5768343943578617 0.0 -0.0 0.0</pose>
			<inertial>
				<pose frame="">0.0 0.0 0.0 0 0 0</pose>
				<mass>5.563586550484201</mass>
				<inertia>
					<ixx>2.032298455269805</ixx>
					<ixy>0.30885145604075287</ixy>
					<ixz>0.5347695724937122</ixz>
					<iyy>2.5103291140248376</iyy>
					<iyz>-1.0778482754769985</iyz>
					<izz>0.7927908850236612</izz>
				</inertia>
			</inertial>
			<collision name="thigh_left_collision">
				<geometry>
					<mesh>
						<uri>model://rikshaw/meshes/CAD/thigh_left.stl</uri>
						<scale>0.001 0.001 0.001</scale>
					</mesh>
				</geometry>
			</collision>
			<visual name="thigh_left_visual">
				<geometry>
					<mesh>
						<uri>model://rikshaw/meshes/CAD/thigh_left.stl</uri>
						<scale>0.001 0.001 0.001</scale>
					</mesh>
				</geometry>
			</visual>
		</link>
		<link name="leg_right">
			<self_collide>false</self_collide>
			<pose frame="">0.13073111293726639 0.23018790159214506 0.5152814010211896 0.0 -0.0 0.0</pose>
			<inertial>
				<pose frame="">0.0 0.0 0.0 0 0 0</pose>
				<mass>5.7416066293880625</mass>
				<inertia>
					<ixx>1.8500195908173283</ixx>
					<ixy>-0.17043594464017472</ixy>
					<ixz>-0.6835654057960041</ixz>
					<iyy>1.6653849427476624</iyy>
					<iyz>-0.37372738986267745</iyz>
					<izz>0.4333240399601409</izz>
				</inertia>
			</inertial>
			<collision name="leg_right_collision">
				<geometry>
					<mesh>
						<uri>model://rikshaw/meshes/CAD/leg_right.stl</uri>
						<scale>0.001 0.001 0.001</scale>
					</mesh>
				</geometry>
			</collision>
			<visual name="leg_right_visual">
				<geometry>
					<mesh>
						<uri>model://rikshaw/meshes/CAD/leg_right.stl</uri>
						<scale>0.001 0.001 0.001</scale>
					</mesh>
				</geometry>
			</visual>
		</link>
		<link name="leg_left">
			<self_collide>false</self_collide>
			<pose frame="">0.35460216180609017 -0.16476933592867768 0.2307814775788578 0.0 -0.0 0.0</pose>
			<inertial>
				<pose frame="">0.0 0.0 0.0 0 0 0</pose>
				<mass>5.742615089607888</mass>
				<inertia>
					<ixx>0.5016738260717913</ixx>
					<ixy>0.3354589885668807</ixy>
					<ixz>0.22180598001631352</ixz>
					<iyy>1.070741512212526</iyy>
					<iyz>-0.4681515967886399</iyz>
					<izz>0.8903661507239246</izz>
				</inertia>
			</inertial>
			<collision name="leg_left_collision">
				<geometry>
					<mesh>
						<uri>model://rikshaw/meshes/CAD/leg_left.stl</uri>
						<scale>0.001 0.001 0.001</scale>
					</mesh>
				</geometry>
			</collision>
			<visual name="leg_left_visual">
				<geometry>
					<mesh>
						<uri>model://rikshaw/meshes/CAD/leg_left.stl</uri>
						<scale>0.001 0.001 0.001</scale>
					</mesh>
				</geometry>
			</visual>
		</link>
		<link name="hip">
			<self_collide>false</self_collide>
			<pose frame="">0.3188054114712725 0.03259725162001076 0.8199215837346147 0.0 -0.0 0.0</pose>
			<inertial>
				<pose frame="">0.0 0.0 0.0 0 0 0</pose>
				<mass>13.796358839496321</mass>
				<inertia>
					<ixx>9.622766189285441</ixx>
					<ixy>-0.14380494608466368</ixy>
					<ixz>-0.36878952400805726</ixz>
					<iyy>10.7532784485541</iyy>
					<iyz>-3.6058239375753556</iyz>
					<izz>1.7419388881373217</izz>
				</inertia>
			</inertial>
			<collision name="hip_collision">
				<geometry>
					<mesh>
						<uri>model://rikshaw/meshes/CAD/hip.stl</uri>
						<scale>0.001 0.001 0.001</scale>
					</mesh>
				</geometry>
			</collision>
			<visual name="hip_visual">
				<geometry>
					<mesh>
						<uri>model://rikshaw/meshes/CAD/hip.stl</uri>
						<scale>0.001 0.001 0.001</scale>
					</mesh>
				</geometry>
			</visual>
		</link>
		<link name="foot_right">
			<self_collide>false</self_collide>
			<pose frame="">0.23078034023968821 0.21050360507473392 0.3301538298419227 0.0 -0.0 0.0</pose>
			<inertial>
				<pose frame="">0.0 0.0 0.0 0 0 0</pose>
				<mass>1.9533512343981427</mass>
				<inertia>
					<ixx>0.3025600513950909</ixx>
					<ixy>-0.09457237923285203</ixy>
					<ixz>-0.13554099111341522</ixz>
					<iyy>0.3246916605138675</iyy>
					<iyz>-0.15191511975860528</iyz>
					<izz>0.1971286762725725</izz>
				</inertia>
			</inertial>
			<collision name="foot_right_collision">
				<geometry>
					<mesh>
						<uri>model://rikshaw/meshes/CAD/foot_right.stl</uri>
						<scale>0.001 0.001 0.001</scale>
					</mesh>
				</geometry>
			</collision>
			<visual name="foot_right_visual">
				<geometry>
					<mesh>
						<uri>model://rikshaw/meshes/CAD/foot_right.stl</uri>
						<scale>0.001 0.001 0.001</scale>
					</mesh>
				</geometry>
			</visual>
		</link>
		<link name="foot_left">
			<self_collide>false</self_collide>
			<pose frame="">0.28746026033547045 -0.1464978271419891 -0.011512207248022328 0.0 -0.0 0.0</pose>
			<inertial>
				<pose frame="">0.0 0.0 0.0 0 0 0</pose>
				<mass>1.9533510268194152</mass>
				<inertia>
					<ixx>0.04386356442023626</ixx>
					<ixy>0.08182852386066176</ixy>
					<ixz>-0.003436930655597172</ixz>
					<iyy>0.16902388320136888</iyy>
					<iyz>0.004970750201399241</iyz>
					<izz>0.21092671026717796</izz>
				</inertia>
			</inertial>
			<collision name="foot_left_collision">
				<geometry>
					<mesh>
						<uri>model://rikshaw/meshes/CAD/foot_left.stl</uri>
						<scale>0.001 0.001 0.001</scale>
					</mesh>
				</geometry>
			</collision>
			<visual name="foot_left_visual">
				<geometry>
					<mesh>
						<uri>model://rikshaw/meshes/CAD/foot_left.stl</uri>
						<scale>0.001 0.001 0.001</scale>
					</mesh>
				</geometry>
			</visual>
		</link>
		<joint name="joint_pedal_right" type="revolute">
			<parent>foot_right</parent>
			<child>pedal_right</child>
			<pose frame="">-0.03989180963305358 0.1244618503468464 0.11647434794801739 0 0 0</pose>
			<axis>
				<xyz>-1.0474289204478013e-10 0.9999999999999999 2.7515982639923474e-10</xyz>
				<limit>
					<lower>-3.141592653589793</lower>
					<upper>3.141592653589793</upper>
				</limit>
				<use_parent_model_frame>0</use_parent_model_frame>
			</axis>
		</joint>
		<joint name="joint_bike_left" type="revolute">
			<parent>pedal_left</parent>
			<child>bike</child>
			<pose frame="">0.33358131896486654 -0.03582698698179355 0.028993015421412752 0 0 0</pose>
			<axis>
				<xyz>1.4238488985885442e-10 -0.9999999999999999 -2.7441464235583507e-10</xyz>
				<limit>
					<lower>-3.141592653589793</lower>
					<upper>3.141592653589793</upper>
				</limit>
				<use_parent_model_frame>0</use_parent_model_frame>
			</axis>
		</joint>
		<joint name="joint_bike_right" type="revolute">
			<parent>pedal_right</parent>
			<child>bike</child>
			<pose frame="">0.3335813189575388 0.034173320050219065 0.02899301544067585 0 0 0</pose>
			<axis>
				<xyz>1.0474358406622928e-10 -1.0000000000000004 -2.7516404609824913e-10</xyz>
				<limit>
					<lower>-3.141592653589793</lower>
					<upper>3.141592653589793</upper>
				</limit>
				<use_parent_model_frame>0</use_parent_model_frame>
			</axis>
		</joint>
		<joint name="joint_pedal_left" type="revolute">
			<parent>foot_left</parent>
			<child>pedal_left</child>
			<pose frame="">-0.001814332799598688 -0.12413718074049786 -0.12182445371959495 0 0 0</pose>
			<axis>
				<xyz>1.4230742896098652e-10 -1.0 -2.7440939389598657e-10</xyz>
				<limit>
					<lower>-3.141592653589793</lower>
					<upper>3.141592653589793</upper>
				</limit>
				<use_parent_model_frame>0</use_parent_model_frame>
			</axis>
		</joint>
		<joint name="joint_hip_left" type="revolute">
			<parent>hip</parent>
			<child>thigh_left</child>
			<pose frame="">-0.014198391986819488 0.010555659221835115 0.11031310191475584 0 0 0</pose>
			<axis>
				<xyz>4.714220161252588e-12 -0.9999999999999999 -4.747072576310608e-10</xyz>
				<limit>
					<lower>-3.141592653589793</lower>
					<upper>3.141592653589793</upper>
				</limit>
				<use_parent_model_frame>0</use_parent_model_frame>
			</axis>
		</joint>
		<joint name="joint_hip_right" type="revolute">
			<parent>hip</parent>
			<child>thigh_right</child>
			<pose frame="">0.10869571349630182 -0.02190807552891389 0.023531915258738254 0 0 0</pose>
			<axis>
				<xyz>4.714117194135765e-12 -0.9999999999999999 -4.747078088732916e-10</xyz>
				<limit>
					<lower>-3.141592653589793</lower>
					<upper>3.141592653589793</upper>
				</limit>
				<use_parent_model_frame>0</use_parent_model_frame>
			</axis>
		</joint>
		<joint name="joint_foot_left" type="revolute">
			<parent>leg_left</parent>
			<child>foot_left</child>
			<pose frame="">0.07180290654911549 0.020897801482261044 0.04334149852288286 0 0 0</pose>
			<axis>
				<xyz>1.7379113579511293e-10 0.9999999999999997 1.5163702627450592e-10</xyz>
				<limit>
					<lower>-3.141592653589793</lower>
					<upper>3.141592653589793</upper>
				</limit>
				<use_parent_model_frame>0</use_parent_model_frame>
			</axis>
		</joint>
		<joint name="joint_knee_right" type="revolute">
			<parent>thigh_right</parent>
			<child>leg_right</child>
			<pose frame="">-0.1102385124091251 -0.013637927463249823 0.10246188711047716 0 0 0</pose>
			<axis>
				<xyz>3.8751886398178056e-11 1.000000000000023 4.832504674201488e-10</xyz>
				<limit>
					<lower>-3.141592653589793</lower>
					<upper>3.141592653589793</upper>
				</limit>
				<use_parent_model_frame>0</use_parent_model_frame>
			</axis>
		</joint>
		<joint name="joint_knee_left" type="revolute">
			<parent>thigh_left</parent>
			<child>leg_left</child>
			<pose frame="">0.009873151240645512 0.033669310169744816 0.15015214413791014 0 0 0</pose>
			<axis>
				<xyz>-2.3658644533201752e-11 -1.0000000000000242 -2.741036256664899e-10</xyz>
				<limit>
					<lower>-3.141592653589793</lower>
					<upper>3.141592653589793</upper>
				</limit>
				<use_parent_model_frame>0</use_parent_model_frame>
			</axis>
		</joint>
		<joint name="joint_foot_right" type="revolute">
			<parent>leg_right</parent>
			<child>foot_right</child>
			<pose frame="">0.05717343818275868 0.011546369209471977 0.06316682467872305 0 0 0</pose>
			<axis>
				<xyz>-8.733427660066444e-11 -1.0000000000000018 -6.907090334408558e-10</xyz>
				<limit>
					<lower>-3.141592653589793</lower>
					<upper>3.141592653589793</upper>
				</limit>
				<use_parent_model_frame>0</use_parent_model_frame>
			</axis>
		</joint>
		<plugin filename="libmusc_plugin.so" name="musc_plugin">
			<myoMuscle name="motor0">
				<link name="hip">
					<viaPoint type="FIXPOINT">-0.043485160015104114 -0.1722472775508108 -0.07066954313494549</viaPoint>
				</link>
				<link name="thigh_left">
					<viaPoint type="FIXPOINT">-0.034764826231186596 0.024405659262930843 0.023691673957603784</viaPoint>
				</link>
			</myoMuscle>
			<myoMuscle name="motor1">
				<link name="hip">
					<viaPoint type="FIXPOINT">0.0456414183786281 -0.17272580060346168 -0.06891802619575373</viaPoint>
				</link>
				<link name="thigh_left">
					<viaPoint type="FIXPOINT">0.06115303680091145 0.02740565921307308 0.12721572664247263</viaPoint>
					<viaPoint type="FIXPOINT">0.02490709750950188 0.024405659259801222 0.029957575096739433</viaPoint>
				</link>
			</myoMuscle>
			<myoMuscle name="motor2">
				<link name="thigh_left">
					<viaPoint type="FIXPOINT">-0.03035421492516548 0.02599006911176474 -0.0737053342373094</viaPoint>
				</link>
				<link name="leg_left">
					<viaPoint type="FIXPOINT">-0.08222234717168463 0.026669310077922878 0.1511797590800569</viaPoint>
					<viaPoint type="FIXPOINT">-0.028477155929903332 0.02366931014477583 0.029614789148275877</viaPoint>
				</link>
			</myoMuscle>
			<myoMuscle name="motor3">
				<link name="thigh_left">
					<viaPoint type="FIXPOINT">0.0411609112229528 0.022903017683455946 -0.06943850205959493</viaPoint>
				</link>
				<link name="leg_left">
					<viaPoint type="FIXPOINT">0.03151719987622883 0.023669310148913353 0.030437754157998393</viaPoint>
				</link>
			</myoMuscle>
			<myoMuscle name="motor4">
				<link name="leg_left">
					<viaPoint type="FIXPOINT">-0.032926532555208186 0.02525371999857029 -0.06778045583219332</viaPoint>
				</link>
				<link name="foot_left">
					<viaPoint type="FIXPOINT">-0.005667227045797674 0.004897801499757648 0.016744912250461905</viaPoint>
				</link>
			</myoMuscle>
			<myoMuscle name="motor5">
				<link name="leg_left">
					<viaPoint type="FIXPOINT">0.0373451326056324 0.024884554957642885 -0.0673060665066313</viaPoint>
				</link>
				<link name="foot_left">
					<viaPoint type="FIXPOINT">0.12151135525610275 0.0048978014787756765 0.009355175876367567</viaPoint>
				</link>
			</myoMuscle>
			<myoMuscle name="motor6">
				<link name="hip">
					<viaPoint type="FIXPOINT">-0.043530282260763546 0.17517050358904007 -0.07067042464243897</viaPoint>
				</link>
				<link name="thigh_left">
					<viaPoint type="FIXPOINT">-0.10240712057358323 0.3720556592046569 0.12355017352290673</viaPoint>
				</link>
			</myoMuscle>
			<myoMuscle name="motor7">
				<link name="hip">
					<viaPoint type="FIXPOINT">0.04575947330223617 0.17213494130207274 -0.06892573494152415</viaPoint>
				</link>
				<link name="thigh_left">
					<viaPoint type="FIXPOINT">0.009271256113597701 0.37505565924614437 0.0372634067918257</viaPoint>
				</link>
				<link name="leg_left">
					<viaPoint type="FIXPOINT">-0.10947630563721213 0.37111931004021187 0.4107294443196113</viaPoint>
				</link>
			</myoMuscle>
			<myoMuscle name="motor9">
				<link name="thigh_left">
					<viaPoint type="FIXPOINT">-0.18175060293719264 0.3699180131335132 0.02695236672700176</viaPoint>
				</link>
				<link name="leg_left">
					<viaPoint type="FIXPOINT">-0.22760051691910388 0.3713193100818539 0.32817555817172045</viaPoint>
				</link>
			</myoMuscle>
			<myoMuscle name="motor8">
				<link name="thigh_left">
					<viaPoint type="FIXPOINT">-0.19925223182579652 0.3708468529946282 0.1090801328633043</viaPoint>
				</link>
				<link name="leg_left">
					<viaPoint type="FIXPOINT">-0.3930439830446676 0.36831931009405916 0.3161849021734073</viaPoint>
					<viaPoint type="FIXPOINT">-0.2648351027444377 0.3713193101060331 0.28112680028784176</viaPoint>
				</link>
			</myoMuscle>
			<myoMuscle name="motor10">
				<link name="leg_left">
					<viaPoint type="FIXPOINT">-0.19065032519957612 0.3724559263538882 0.21503940573902483</viaPoint>
				</link>
				<link name="foot_left">
					<viaPoint type="FIXPOINT">-0.06423686806660808 0.35304780145454007 0.354643449446079</viaPoint>
				</link>
			</myoMuscle>
			<myoMuscle name="motor11">
				<link name="leg_left">
					<viaPoint type="FIXPOINT">-0.1476935327981159 0.3697349003019042 0.27231408140924473</viaPoint>
				</link>
				<link name="foot_left">
					<viaPoint type="FIXPOINT">0.05851402393057963 0.3530478014452491 0.38872010588263267</viaPoint>
				</link>
			</myoMuscle>
		</plugin>
	</model>
</sdf>
