<?xml version="1.0" ?>
<sdf version="1.6">
	<model name="rikshaw">
		<link name="bike">
			<self_collide>false</self_collide>
			<pose frame="">0.11407161388991904 0.03170624505765542 0.5831929199333695 0.0 -0.0 0.0</pose>
			<inertial>
				<pose frame="">0.0 0.0 0.0 0 0 0</pose>
				<mass>21.81331498933295</mass>
				<inertia>
					<ixx>10.083898654031916</ixx>
					<ixy>-0.06607369188353159</ixy>
					<ixz>-0.3883753822995066</ixz>
					<iyy>13.522231324250988</iyy>
					<iyz>-3.5907666395614837</iyz>
					<izz>4.078177458509554</izz>
				</inertia>
			</inertial>
			<collision name="bike_collision">
				<geometry>
					<mesh>
						<uri>model://rikshaw/meshes/CAD/bike.stl</uri>
						<scale>0.001 0.001 0.001</scale>
					</mesh>
				</geometry>
			</collision>
			<visual name="bike_visual">
				<geometry>
					<mesh>
						<uri>model://rikshaw/meshes/CAD/bike.stl</uri>
						<scale>0.001 0.001 0.001</scale>
					</mesh>
				</geometry>
			</visual>
		</link>
		<link name="foot_left">
			<self_collide>false</self_collide>
			<pose frame="">0.32953037112482525 -0.14122043737664075 0.0016945492770594505 0.0 -0.0 0.0</pose>
			<inertial>
				<pose frame="">0.0 0.0 0.0 0 0 0</pose>
				<mass>1.0073570813716561</mass>
				<inertia>
					<ixx>0.020750513605191527</ixx>
					<ixy>0.04690908383866695</ixy>
					<ixz>0.00024345371490371603</ixz>
					<iyy>0.11228597885468367</iyy>
					<iyz>-0.0009047423260076533</iyz>
					<izz>0.13240932064928215</izz>
				</inertia>
			</inertial>
			<collision name="foot_left_collision">
				<geometry>
					<mesh>
						<uri>model://rikshaw/meshes/CAD/foot_left.stl</uri>
						<scale>0.001 0.001 0.001</scale>
					</mesh>
				</geometry>
			</collision>
			<visual name="foot_left_visual">
				<geometry>
					<mesh>
						<uri>model://rikshaw/meshes/CAD/foot_left.stl</uri>
						<scale>0.001 0.001 0.001</scale>
					</mesh>
				</geometry>
			</visual>
		</link>
		<link name="foot_right">
			<self_collide>false</self_collide>
			<pose frame="">0.2695456664829376 0.20617071215293895 0.355200304611504 0.0 -0.0 0.0</pose>
			<inertial>
				<pose frame="">0.0 0.0 0.0 0 0 0</pose>
				<mass>1.0073526294372792</mass>
				<inertia>
					<ixx>0.1710169135614256</ixx>
					<ixy>-0.056008864515654636</ixy>
					<ixz>-0.07378206564558545</ixz>
					<iyy>0.20317739089550094</iyy>
					<iyz>-0.09741171616210452</iyz>
					<izz>0.11849200847169264</izz>
				</inertia>
			</inertial>
			<collision name="foot_right_collision">
				<geometry>
					<mesh>
						<uri>model://rikshaw/meshes/CAD/foot_right.stl</uri>
						<scale>0.001 0.001 0.001</scale>
					</mesh>
				</geometry>
			</collision>
			<visual name="foot_right_visual">
				<geometry>
					<mesh>
						<uri>model://rikshaw/meshes/CAD/foot_right.stl</uri>
						<scale>0.001 0.001 0.001</scale>
					</mesh>
				</geometry>
			</visual>
		</link>
		<link name="thigh_right">
			<self_collide>false</self_collide>
			<pose frame="">0.2130676220272979 0.23075804961914492 0.6636155811866733 0.0 -0.0 0.0</pose>
			<inertial>
				<pose frame="">0.0 0.0 0.0 0 0 0</pose>
				<mass>5.563551531361345</mass>
				<inertia>
					<ixx>2.7587103141393774</ixx>
					<ixy>-0.27653691454319923</ixy>
					<ixz>-0.8525725925194048</ixz>
					<iyy>2.7338304215308424</iyy>
					<iyz>-0.7886856442807302</iyz>
					<izz>0.5768546331244859</izz>
				</inertia>
			</inertial>
			<collision name="thigh_right_collision">
				<geometry>
					<mesh>
						<uri>model://rikshaw/meshes/CAD/thigh_right.stl</uri>
						<scale>0.001 0.001 0.001</scale>
					</mesh>
				</geometry>
			</collision>
			<visual name="thigh_right_visual">
				<geometry>
					<mesh>
						<uri>model://rikshaw/meshes/CAD/thigh_right.stl</uri>
						<scale>0.001 0.001 0.001</scale>
					</mesh>
				</geometry>
			</visual>
		</link>
		<link name="thigh_left">
			<self_collide>false</self_collide>
			<pose frame="">0.33596172751211206 -0.165705685121125 0.5768343943578617 0.0 -0.0 0.0</pose>
			<inertial>
				<pose frame="">0.0 0.0 0.0 0 0 0</pose>
				<mass>5.563586550484201</mass>
				<inertia>
					<ixx>2.032298455269805</ixx>
					<ixy>0.30885145604075287</ixy>
					<ixz>0.5347695724937122</ixz>
					<iyy>2.5103291140248376</iyy>
					<iyz>-1.0778482754769985</iyz>
					<izz>0.7927908850236612</izz>
				</inertia>
			</inertial>
			<collision name="thigh_left_collision">
				<geometry>
					<mesh>
						<uri>model://rikshaw/meshes/CAD/thigh_left.stl</uri>
						<scale>0.001 0.001 0.001</scale>
					</mesh>
				</geometry>
			</collision>
			<visual name="thigh_left_visual">
				<geometry>
					<mesh>
						<uri>model://rikshaw/meshes/CAD/thigh_left.stl</uri>
						<scale>0.001 0.001 0.001</scale>
					</mesh>
				</geometry>
			</visual>
		</link>
		<link name="leg_right">
			<self_collide>false</self_collide>
			<pose frame="">0.13073111293726639 0.23018790159214506 0.5152814010211896 0.0 -0.0 0.0</pose>
			<inertial>
				<pose frame="">0.0 0.0 0.0 0 0 0</pose>
				<mass>5.7416066293880625</mass>
				<inertia>
					<ixx>1.8500195908173283</ixx>
					<ixy>-0.17043594464017472</ixy>
					<ixz>-0.6835654057960041</ixz>
					<iyy>1.6653849427476624</iyy>
					<iyz>-0.37372738986267745</iyz>
					<izz>0.4333240399601409</izz>
				</inertia>
			</inertial>
			<collision name="leg_right_collision">
				<geometry>
					<mesh>
						<uri>model://rikshaw/meshes/CAD/leg_right.stl</uri>
						<scale>0.001 0.001 0.001</scale>
					</mesh>
				</geometry>
			</collision>
			<visual name="leg_right_visual">
				<geometry>
					<mesh>
						<uri>model://rikshaw/meshes/CAD/leg_right.stl</uri>
						<scale>0.001 0.001 0.001</scale>
					</mesh>
				</geometry>
			</visual>
		</link>
		<link name="leg_left">
			<self_collide>false</self_collide>
			<pose frame="">0.35460216180609017 -0.16476933592867768 0.2307814775788578 0.0 -0.0 0.0</pose>
			<inertial>
				<pose frame="">0.0 0.0 0.0 0 0 0</pose>
				<mass>5.742615089607888</mass>
				<inertia>
					<ixx>0.5016738260717913</ixx>
					<ixy>0.3354589885668807</ixy>
					<ixz>0.22180598001631352</ixz>
					<iyy>1.070741512212526</iyy>
					<iyz>-0.4681515967886399</iyz>
					<izz>0.8903661507239246</izz>
				</inertia>
			</inertial>
			<collision name="leg_left_collision">
				<geometry>
					<mesh>
						<uri>model://rikshaw/meshes/CAD/leg_left.stl</uri>
						<scale>0.001 0.001 0.001</scale>
					</mesh>
				</geometry>
			</collision>
			<visual name="leg_left_visual">
				<geometry>
					<mesh>
						<uri>model://rikshaw/meshes/CAD/leg_left.stl</uri>
						<scale>0.001 0.001 0.001</scale>
					</mesh>
				</geometry>
			</visual>
		</link>
		<link name="back_wheel">
			<self_collide>false</self_collide>
			<pose frame="">0.6486084286036901 0.03492264887089664 0.25624887024902543 0.0 -0.0 0.0</pose>
			<inertial>
				<pose frame="">0.0 0.0 0.0 0 0 0</pose>
				<mass>13.340163929098477</mass>
				<inertia>
					<ixx>1.4014062390517636</ixx>
					<ixy>-0.3021697127655251</ixy>
					<ixz>-0.11937965050242952</ixz>
					<iyy>7.504381180421915</iyy>
					<iyz>-2.2172043078944803</iyz>
					<izz>6.137556770128537</izz>
				</inertia>
			</inertial>
			<collision name="back_wheel_collision">
				<geometry>
					<mesh>
						<uri>model://rikshaw/meshes/CAD/back_wheel.stl</uri>
						<scale>0.001 0.001 0.001</scale>
					</mesh>
				</geometry>
			</collision>
			<visual name="back_wheel_visual">
				<geometry>
					<mesh>
						<uri>model://rikshaw/meshes/CAD/back_wheel.stl</uri>
						<scale>0.001 0.001 0.001</scale>
					</mesh>
				</geometry>
			</visual>
		</link>
		<link name="front_part">
			<self_collide>false</self_collide>
			<pose frame="">-0.6046185937738633 0.04475872331475462 0.42323667552386973 0.0 -0.0 0.0</pose>
			<inertial>
				<pose frame="">0.0 0.0 0.0 0 0 0</pose>
				<mass>16.813631847740364</mass>
				<inertia>
					<ixx>5.4657790536527395</ixx>
					<ixy>0.5110471711964572</ixy>
					<ixz>-0.28744024450617317</ixz>
					<iyy>14.406698755232574</iyy>
					<iyz>2.938162171440261</iyz>
					<izz>11.464360009651763</izz>
				</inertia>
			</inertial>
			<collision name="front_part_collision">
				<geometry>
					<mesh>
						<uri>model://rikshaw/meshes/CAD/front_part.stl</uri>
						<scale>0.001 0.001 0.001</scale>
					</mesh>
				</geometry>
			</collision>
			<visual name="front_part_visual">
				<geometry>
					<mesh>
						<uri>model://rikshaw/meshes/CAD/front_part.stl</uri>
						<scale>0.001 0.001 0.001</scale>
					</mesh>
				</geometry>
			</visual>
		</link>
		<link name="left_wheel">
			<self_collide>false</self_collide>
			<pose frame="">-0.8867148521253287 -0.3156284088111488 0.25250000000001 0.0 -0.0 0.0</pose>
			<inertial>
				<pose frame="">0.0 0.0 0.0 0 0 0</pose>
				<mass>13.340163929097853</mass>
				<inertia>
					<ixx>2.6886582542943342</ixx>
					<ixy>-3.73354366648907</ixy>
					<ixz>1.0631600153408742</ixz>
					<iyy>12.355706573664577</iyy>
					<iyz>2.986802675143824</iyz>
					<izz>12.327019793799982</izz>
				</inertia>
			</inertial>
			<collision name="left_wheel_collision">
				<geometry>
					<mesh>
						<uri>model://rikshaw/meshes/CAD/left_wheel.stl</uri>
						<scale>0.001 0.001 0.001</scale>
					</mesh>
				</geometry>
			</collision>
			<visual name="left_wheel_visual">
				<geometry>
					<mesh>
						<uri>model://rikshaw/meshes/CAD/left_wheel.stl</uri>
						<scale>0.001 0.001 0.001</scale>
					</mesh>
				</geometry>
			</visual>
		</link>
		<link name="right_wheel">
			<self_collide>false</self_collide>
			<pose frame="">-0.8867148521253283 0.37637226941711827 0.25250000000004 0.0 -0.0 0.0</pose>
			<inertial>
				<pose frame="">0.0 0.0 0.0 0 0 0</pose>
				<mass>13.340163929097853</mass>
				<inertia>
					<ixx>3.24940928013889</ixx>
					<ixy>4.452078024336449</ixy>
					<ixz>-1.2677691125288901</ixz>
					<iyy>12.35570657366474</iyy>
					<iyz>2.98680267514417</iyz>
					<izz>12.8877708196443</izz>
				</inertia>
			</inertial>
			<collision name="right_wheel_collision">
				<geometry>
					<mesh>
						<uri>model://rikshaw/meshes/CAD/right_wheel.stl</uri>
						<scale>0.001 0.001 0.001</scale>
					</mesh>
				</geometry>
			</collision>
			<visual name="right_wheel_visual">
				<geometry>
					<mesh>
						<uri>model://rikshaw/meshes/CAD/right_wheel.stl</uri>
						<scale>0.001 0.001 0.001</scale>
					</mesh>
				</geometry>
			</visual>
		</link>
		<link name="pedal_right">
			<self_collide>false</self_collide>
			<pose frame="">0.37345950464140776 0.18236129042854465 0.20999067049847114 0.0 -0.0 0.0</pose>
			<inertial>
				<pose frame="">0.0 0.0 0.0 0 0 0</pose>
				<mass>0.9460025886020094</mass>
				<inertia>
					<ixx>0.07377911577090149</ixx>
					<ixy>-0.06442708739658828</ixy>
					<ixz>-0.03622638361731796</ixz>
					<iyy>0.1740707923266257</iyy>
					<iyz>-0.07418824195613966</iyz>
					<izz>0.16432401911803204</izz>
				</inertia>
			</inertial>
			<collision name="pedal_right_collision">
				<geometry>
					<mesh>
						<uri>model://rikshaw/meshes/CAD/pedal_right.stl</uri>
						<scale>0.001 0.001 0.001</scale>
					</mesh>
				</geometry>
			</collision>
			<visual name="pedal_right_visual">
				<geometry>
					<mesh>
						<uri>model://rikshaw/meshes/CAD/pedal_right.stl</uri>
						<scale>0.001 0.001 0.001</scale>
					</mesh>
				</geometry>
			</visual>
		</link>
		<link name="kurbel">
			<self_collide>false</self_collide>
			<pose frame="">0.20524776280826626 0.034503718012087355 0.21029021552905797 0.0 -0.0 0.0</pose>
			<inertial>
				<pose frame="">0.0 0.0 0.0 0 0 0</pose>
				<mass>2.7832708381107576</mass>
				<inertia>
					<ixx>0.1423383234578622</ixx>
					<ixy>-0.032689001789628226</ixy>
					<ixz>-0.02011903160634835</ixz>
					<iyy>0.25819266867802115</iyy>
					<iyz>-0.12002315705190886</iyz>
					<izz>0.15384069763517777</izz>
				</inertia>
			</inertial>
			<collision name="kurbel_collision">
				<geometry>
					<mesh>
						<uri>model://rikshaw/meshes/CAD/kurbel.stl</uri>
						<scale>0.001 0.001 0.001</scale>
					</mesh>
				</geometry>
			</collision>
			<visual name="kurbel_visual">
				<geometry>
					<mesh>
						<uri>model://rikshaw/meshes/CAD/kurbel.stl</uri>
						<scale>0.001 0.001 0.001</scale>
					</mesh>
				</geometry>
			</visual>
		</link>
		<link name="pedal_left">
			<self_collide>false</self_collide>
			<pose frame="">0.03491749565445945 -0.11487270957145626 0.20998199734654882 0.0 -0.0 0.0</pose>
			<inertial>
				<pose frame="">0.0 0.0 0.0 0 0 0</pose>
				<mass>0.9460025886020111</mass>
				<inertia>
					<ixx>0.054798951844923956</ixx>
					<ixy>0.0037944800841213187</ixy>
					<ixz>0.022818718582806888</ixz>
					<iyy>0.04327986812473328</iyy>
					<iyz>-0.006936264200881655</iyz>
					<izz>0.01455982259395355</izz>
				</inertia>
			</inertial>
			<collision name="pedal_left_collision">
				<geometry>
					<mesh>
						<uri>model://rikshaw/meshes/CAD/pedal_left.stl</uri>
						<scale>0.001 0.001 0.001</scale>
					</mesh>
				</geometry>
			</collision>
			<visual name="pedal_left_visual">
				<geometry>
					<mesh>
						<uri>model://rikshaw/meshes/CAD/pedal_left.stl</uri>
						<scale>0.001 0.001 0.001</scale>
					</mesh>
				</geometry>
			</visual>
		</link>
		<joint name="joint_pedal_right" type="revolute">
			<parent>kurbel</parent>
			<child>pedal_right</child>
			<pose frame="">-6.199487566426853e-05 0.041999999999999885 4.779491486118559e-05 0 0 0</pose>
			<axis>
				<xyz>-2.5713482822523515e-16 1.0000000000000007 4.56357540647104e-17</xyz>
				<limit>
					<lower>-3.141592653589793</lower>
					<upper>3.141592653589793</upper>
				</limit>
				<use_parent_model_frame>0</use_parent_model_frame>
			</axis>
		</joint>
		<joint name="joint_pedal_left" type="revolute">
			<parent>kurbel</parent>
			<child>pedal_left</child>
			<pose frame="">6.199487566573846e-05 -0.04199999999999953 4.779491486139875e-05 0 0 0</pose>
			<axis>
				<xyz>2.5713482822524407e-16 -1.0 -4.563575406471198e-17</xyz>
				<limit>
					<lower>-3.141592653589793</lower>
					<upper>3.141592653589793</upper>
				</limit>
				<use_parent_model_frame>0</use_parent_model_frame>
			</axis>
		</joint>
		<joint name="joint_wheel_left" type="revolute">
			<parent>front_part</parent>
			<child>left_wheel</child>
			<pose frame="">1.4210854715202005e-15 0.04600034662480176 7.283063041541026e-15 0 0 0</pose>
			<axis>
				<xyz>3.1662288285729275e-30 -0.9999999999999998 -4.317059530368993e-14</xyz>
				<limit>
					<lower>-3.141592653589793</lower>
					<upper>3.141592653589793</upper>
				</limit>
				<use_parent_model_frame>0</use_parent_model_frame>
			</axis>
		</joint>
		<joint name="joint_wheel_right" type="revolute">
			<parent>front_part</parent>
			<child>right_wheel</child>
			<pose frame="">9.947598300641404e-16 -0.003999653375198448 5.4711790653527716e-15 0 0 0</pose>
			<axis>
				<xyz>-3.1662288285729275e-30 0.9999999999999998 4.317059530368993e-14</xyz>
				<limit>
					<lower>-3.141592653589793</lower>
					<upper>3.141592653589793</upper>
				</limit>
				<use_parent_model_frame>0</use_parent_model_frame>
			</axis>
		</joint>
		<joint name="joint_front" type="revolute">
			<parent>bike</parent>
			<child>front_part</child>
			<pose frame="">-0.23009613508125631 -0.01038647904833785 -0.20523667730717188 0 0 0</pose>
			<axis>
				<xyz>6.603440870084913e-16 -4.31170590847569e-14 1.0</xyz>
				<limit>
					<lower>-0.3490658503988659</lower>
					<upper>0.3490658503988659</upper>
				</limit>
				<use_parent_model_frame>0</use_parent_model_frame>
			</axis>
		</joint>
		<joint name="joint_pedal" type="revolute">
			<parent>bike</parent>
			<child>kurbel</child>
			<pose frame="">-0.0010297452301407971 -0.03513164955581818 -0.00018926338061788783 0 0 0</pose>
			<axis>
				<xyz>0.0 1.0 -5.551115123125783e-16</xyz>
				<limit>
					<lower>-3.141592653589793</lower>
					<upper>3.141592653589793</upper>
				</limit>
				<use_parent_model_frame>0</use_parent_model_frame>
			</axis>
		</joint>
		<joint name="joint_foot_left" type="revolute">
			<parent>leg_left</parent>
			<child>foot_left</child>
			<pose frame="">0.02973279575976065 0.015620411716912681 0.030134741997801084 0 0 0</pose>
			<axis>
				<xyz>1.7379113579511293e-10 0.9999999999999997 1.5163702627450592e-10</xyz>
				<limit>
					<lower>-3.141592653589793</lower>
					<upper>3.141592653589793</upper>
				</limit>
				<use_parent_model_frame>0</use_parent_model_frame>
			</axis>
		</joint>
		<joint name="joint_knee_right" type="revolute">
			<parent>thigh_right</parent>
			<child>leg_right</child>
			<pose frame="">-0.1102385124091251 -0.013637927463249823 0.10246188711047716 0 0 0</pose>
			<axis>
				<xyz>3.8751886398178056e-11 1.000000000000023 4.832504674201488e-10</xyz>
				<limit>
					<lower>-3.141592653589793</lower>
					<upper>3.141592653589793</upper>
				</limit>
				<use_parent_model_frame>0</use_parent_model_frame>
			</axis>
		</joint>
		<joint name="joint_foot_right" type="revolute">
			<parent>leg_right</parent>
			<child>foot_right</child>
			<pose frame="">0.01840811193950934 0.015879262131266964 0.03812034990914178 0 0 0</pose>
			<axis>
				<xyz>-8.733427660066444e-11 -1.0000000000000018 -6.907090334408558e-10</xyz>
				<limit>
					<lower>-3.141592653589793</lower>
					<upper>3.141592653589793</upper>
				</limit>
				<use_parent_model_frame>0</use_parent_model_frame>
			</axis>
		</joint>
		<joint name="joint_hip_right" type="revolute">
			<parent>bike</parent>
			<child>thigh_right</child>
			<pose frame="">0.10869571349630182 -0.02190807552891389 0.023531915258738254 0 0 0</pose>
			<axis>
				<xyz>4.714117194135765e-12 -0.9999999999999999 -4.747078088732916e-10</xyz>
				<limit>
					<lower>-3.141592653589793</lower>
					<upper>3.141592653589793</upper>
				</limit>
				<use_parent_model_frame>0</use_parent_model_frame>
			</axis>
		</joint>
		<joint name="joint_knee_left" type="revolute">
			<parent>thigh_left</parent>
			<child>leg_left</child>
			<pose frame="">0.009873151240645512 0.033669310169744816 0.15015214413791014 0 0 0</pose>
			<axis>
				<xyz>-2.3658644533201752e-11 -1.0000000000000242 -2.741036256664899e-10</xyz>
				<limit>
					<lower>-3.141592653589793</lower>
					<upper>3.141592653589793</upper>
				</limit>
				<use_parent_model_frame>0</use_parent_model_frame>
			</axis>
		</joint>
		<joint name="joint_hip_left" type="revolute">
			<parent>bike</parent>
			<child>thigh_left</child>
			<pose frame="">-0.014198391986819488 0.010555659221835115 0.11031310191475584 0 0 0</pose>
			<axis>
				<xyz>4.714220161252588e-12 -0.9999999999999999 -4.747072576310608e-10</xyz>
				<limit>
					<lower>-3.141592653589793</lower>
					<upper>3.141592653589793</upper>
				</limit>
				<use_parent_model_frame>0</use_parent_model_frame>
			</axis>
		</joint>
		<joint name="back_wheel" type="revolute">
			<parent>bike</parent>
			<child>back_wheel</child>
			<pose frame="">1.4210854715202004e-16 -0.06600034662480248 -1.0658141036401502e-16 0 0 0</pose>
			<axis>
				<xyz>0.0 -1.0 5.551115123125783e-16</xyz>
				<limit>
					<lower>-3.141592653589793</lower>
					<upper>3.141592653589793</upper>
				</limit>
				<use_parent_model_frame>0</use_parent_model_frame>
			</axis>
		</joint>
		<plugin filename="libmusc_plugin.so" name="musc_plugin">
			<myoMuscle name="motor0">
				<link name="bike">
					<viaPoint type="FIXPOINT">0.16124863756624933 -0.17135627098845546 0.1660591206662997</viaPoint>
				</link>
				<link name="thigh_left">
					<viaPoint type="FIXPOINT">-0.034764826231186596 0.024405659262930843 0.023691673957603784</viaPoint>
				</link>
			</myoMuscle>
			<myoMuscle name="motor1">
				<link name="bike">
					<viaPoint type="FIXPOINT">0.2503752159599816 -0.17183479404110635 0.16781063760549145</viaPoint>
				</link>
				<link name="thigh_left">
					<viaPoint type="FIXPOINT">0.06115303680091145 0.02740565921307308 0.12721572664247263</viaPoint>
					<viaPoint type="FIXPOINT">0.02490709750950188 0.024405659259801222 0.029957575096739433</viaPoint>
				</link>
			</myoMuscle>
			<myoMuscle name="motor2">
				<link name="thigh_left">
					<viaPoint type="FIXPOINT">-0.03035421492516548 0.02599006911176474 -0.0737053342373094</viaPoint>
				</link>
				<link name="leg_left">
					<viaPoint type="FIXPOINT">-0.08222234717168463 0.026669310077922878 0.1511797590800569</viaPoint>
					<viaPoint type="FIXPOINT">-0.028477155929903332 0.02366931014477583 0.029614789148275877</viaPoint>
				</link>
			</myoMuscle>
			<myoMuscle name="motor3">
				<link name="thigh_left">
					<viaPoint type="FIXPOINT">0.0411609112229528 0.022903017683455946 -0.06943850205959493</viaPoint>
				</link>
				<link name="leg_left">
					<viaPoint type="FIXPOINT">0.03151719987622883 0.023669310148913353 0.030437754157998393</viaPoint>
				</link>
			</myoMuscle>
			<myoMuscle name="motor4">
				<link name="leg_left">
					<viaPoint type="FIXPOINT">-0.032926532555208186 0.02525371999857029 -0.06778045583219332</viaPoint>
				</link>
				<link name="foot_left">
					<viaPoint type="FIXPOINT">-0.04773733783515251 -0.0003795882655907157 0.0035381557253801265</viaPoint>
				</link>
			</myoMuscle>
			<myoMuscle name="motor5">
				<link name="leg_left">
					<viaPoint type="FIXPOINT">0.0373451326056324 0.024884554957642885 -0.0673060665066313</viaPoint>
				</link>
				<link name="foot_left">
					<viaPoint type="FIXPOINT">0.07944124446674793 -0.0003795882865726874 -0.0038515806487142115</viaPoint>
				</link>
			</myoMuscle>
			<myoMuscle name="motor6">
				<link name="bike">
					<viaPoint type="FIXPOINT">0.1612035153205899 0.17606151015139543 0.16605823915880621</viaPoint>
				</link>
				<link name="thigh_left">
					<viaPoint type="FIXPOINT">-0.10240712057358323 0.3720556592046569 0.12355017352290673</viaPoint>
				</link>
			</myoMuscle>
			<myoMuscle name="motor7">
				<link name="bike">
					<viaPoint type="FIXPOINT">0.25049327088358964 0.17302594786442807 0.16780292885972103</viaPoint>
				</link>
				<link name="thigh_left">
					<viaPoint type="FIXPOINT">0.009271256113597701 0.37505565924614437 0.0372634067918257</viaPoint>
				</link>
				<link name="leg_left">
					<viaPoint type="FIXPOINT">-0.10947630563721213 0.37111931004021187 0.4107294443196113</viaPoint>
				</link>
			</myoMuscle>
			<myoMuscle name="motor9">
				<link name="thigh_left">
					<viaPoint type="FIXPOINT">-0.18175060293719264 0.3699180131335132 0.02695236672700176</viaPoint>
				</link>
				<link name="leg_left">
					<viaPoint type="FIXPOINT">-0.22760051691910388 0.3713193100818539 0.32817555817172045</viaPoint>
				</link>
			</myoMuscle>
			<myoMuscle name="motor8">
				<link name="thigh_left">
					<viaPoint type="FIXPOINT">-0.19925223182579652 0.3708468529946282 0.1090801328633043</viaPoint>
				</link>
				<link name="leg_left">
					<viaPoint type="FIXPOINT">-0.3930439830446676 0.36831931009405916 0.3161849021734073</viaPoint>
					<viaPoint type="FIXPOINT">-0.2648351027444377 0.3713193101060331 0.28112680028784176</viaPoint>
				</link>
			</myoMuscle>
			<myoMuscle name="motor10">
				<link name="leg_left">
					<viaPoint type="FIXPOINT">-0.19065032519957612 0.3724559263538882 0.21503940573902483</viaPoint>
				</link>
				<link name="foot_left">
					<viaPoint type="FIXPOINT">-0.10630697885596291 0.34777041168919165 0.3414366929209973</viaPoint>
				</link>
			</myoMuscle>
			<myoMuscle name="motor11">
				<link name="leg_left">
					<viaPoint type="FIXPOINT">-0.1476935327981159 0.3697349003019042 0.27231408140924473</viaPoint>
				</link>
				<link name="foot_left">
					<viaPoint type="FIXPOINT">0.016443913141224797 0.3477704116799007 0.37551334935755093</viaPoint>
				</link>
			</myoMuscle>
		</plugin>
	</model>
</sdf>
