<?xml version="1.0" ?>
<sdf version="1.6">
	<model name="rikshaw">
		<link name="bike">
			<self_collide>false</self_collide>
			<pose frame="">-1.3108998963673458e-07 2.442664557200658e-07 1.774980865576481e-07 0.0 -0.0 0.0</pose>
			<inertial>
				<pose frame="">0.0 0.0 0.0 0 0 0</pose>
				<mass>21.819480362884757</mass>
				<inertia>
					<ixx>5.88647979750313</ixx>
					<ixy>0.052466044382052206</ixy>
					<ixz>0.14605356512826828</ixz>
					<iyy>9.145452768014158</iyy>
					<iyz>-2.309312656009525</iyz>
					<izz>3.8627003582898043</izz>
				</inertia>
			</inertial>
			<collision name="bike_collision">
				<geometry>
					<mesh>
						<uri>model://rikshaw/meshes/CAD/bike.stl</uri>
						<scale>0.001 0.001 0.001</scale>
					</mesh>
				</geometry>
			</collision>
			<visual name="bike_visual">
				<geometry>
					<mesh>
						<uri>model://rikshaw/meshes/CAD/bike.stl</uri>
						<scale>0.001 0.001 0.001</scale>
					</mesh>
				</geometry>
			</visual>
		</link>
		<link name="torso">
			<self_collide>false</self_collide>
			<pose frame="">0.19987549420485287 -0.017084439834377765 1.1388750556029874 0.0 -0.0 0.0</pose>
			<inertial>
				<pose frame="">0.0 0.0 0.0 0 0 0</pose>
				<mass>12.615235486751962</mass>
				<inertia>
					<ixx>16.813065641766094</ixx>
					<ixy>0.057160953642478765</ixy>
					<ixz>0.24558572970336837</ixz>
					<iyy>17.06350479421755</iyy>
					<iyz>-2.871755700403481</iyz>
					<izz>0.8439527128677823</izz>
				</inertia>
			</inertial>
			<collision name="torso_collision">
				<geometry>
					<mesh>
						<uri>model://rikshaw/meshes/CAD/torso.stl</uri>
						<scale>0.001 0.001 0.001</scale>
					</mesh>
				</geometry>
			</collision>
			<visual name="torso_visual">
				<geometry>
					<mesh>
						<uri>model://rikshaw/meshes/CAD/torso.stl</uri>
						<scale>0.001 0.001 0.001</scale>
					</mesh>
				</geometry>
			</visual>
		</link>
		<link name="lower_arm_right">
			<self_collide>false</self_collide>
			<pose frame="">0.22749926421069158 0.6047004795045655 0.8788946890236794 0.0 -0.0 0.0</pose>
			<inertial>
				<pose frame="">0.0 0.0 0.0 0 0 0</pose>
				<mass>7.123104239811117</mass>
				<inertia>
					<ixx>8.14076607631484</ixx>
					<ixy>-0.9820466828131674</ixy>
					<ixz>-3.771936104318434</ixz>
					<iyy>5.889053032331287</iyy>
					<iyz>-1.422424777459208</iyz>
					<izz>2.9955515293501502</izz>
				</inertia>
			</inertial>
			<collision name="lower_arm_right_collision">
				<geometry>
					<mesh>
						<uri>model://rikshaw/meshes/CAD/lower_arm_right.stl</uri>
						<scale>0.001 0.001 0.001</scale>
					</mesh>
				</geometry>
			</collision>
			<visual name="lower_arm_right_visual">
				<geometry>
					<mesh>
						<uri>model://rikshaw/meshes/CAD/lower_arm_right.stl</uri>
						<scale>0.001 0.001 0.001</scale>
					</mesh>
				</geometry>
			</visual>
		</link>
		<link name="lower_arm_left">
			<self_collide>false</self_collide>
			<pose frame="">0.23432273108915624 -0.6363202060151564 0.88302787869392 0.0 -0.0 0.0</pose>
			<inertial>
				<pose frame="">0.0 0.0 0.0 0 0 0</pose>
				<mass>7.123102043007604</mass>
				<inertia>
					<ixx>8.472323633353955</ixx>
					<ixy>1.0626016899805515</ixy>
					<ixz>3.9885451540856223</ixz>
					<iyy>5.963142620867367</iyy>
					<iyz>-1.4734310474311096</iyz>
					<izz>3.297380369176723</izz>
				</inertia>
			</inertial>
			<collision name="lower_arm_left_collision">
				<geometry>
					<mesh>
						<uri>model://rikshaw/meshes/CAD/lower_arm_left.stl</uri>
						<scale>0.001 0.001 0.001</scale>
					</mesh>
				</geometry>
			</collision>
			<visual name="lower_arm_left_visual">
				<geometry>
					<mesh>
						<uri>model://rikshaw/meshes/CAD/lower_arm_left.stl</uri>
						<scale>0.001 0.001 0.001</scale>
					</mesh>
				</geometry>
			</visual>
		</link>
		<link name="upper_arm_right">
			<self_collide>false</self_collide>
			<pose frame="">0.22580121079334348 0.41835940899848456 1.0400299660922039 0.0 -0.0 0.0</pose>
			<inertial>
				<pose frame="">0.0 0.0 0.0 0 0 0</pose>
				<mass>3.6087085067988065</mass>
				<inertia>
					<ixx>4.567203154344452</ixx>
					<ixy>-0.34372896409735515</ixy>
					<ixz>-1.5550484818139934</ixz>
					<iyy>4.103561033215363</iyy>
					<iyz>-0.8449642325002235</iyz>
					<izz>0.835877040964359</izz>
				</inertia>
			</inertial>
			<collision name="upper_arm_right_collision">
				<geometry>
					<mesh>
						<uri>model://rikshaw/meshes/CAD/upper_arm_right.stl</uri>
						<scale>0.001 0.001 0.001</scale>
					</mesh>
				</geometry>
			</collision>
			<visual name="upper_arm_right_visual">
				<geometry>
					<mesh>
						<uri>model://rikshaw/meshes/CAD/upper_arm_right.stl</uri>
						<scale>0.001 0.001 0.001</scale>
					</mesh>
				</geometry>
			</visual>
		</link>
		<link name="upper_arm_left">
			<self_collide>false</self_collide>
			<pose frame="">0.2328360018396073 -0.4496594867949622 1.0419648159011983 0.0 -0.0 0.0</pose>
			<inertial>
				<pose frame="">0.0 0.0 0.0 0 0 0</pose>
				<mass>3.6086368702723797</mass>
				<inertia>
					<ixx>4.680318579636587</ixx>
					<ixy>0.3773751948351723</ixy>
					<ixz>1.6753564989705276</ixz>
					<iyy>4.129212182825604</iyy>
					<iyz>-0.8758056805051924</iyz>
					<izz>0.9457203842980147</izz>
				</inertia>
			</inertial>
			<collision name="upper_arm_left_collision">
				<geometry>
					<mesh>
						<uri>model://rikshaw/meshes/CAD/upper_arm_left.stl</uri>
						<scale>0.001 0.001 0.001</scale>
					</mesh>
				</geometry>
			</collision>
			<visual name="upper_arm_left_visual">
				<geometry>
					<mesh>
						<uri>model://rikshaw/meshes/CAD/upper_arm_left.stl</uri>
						<scale>0.001 0.001 0.001</scale>
					</mesh>
				</geometry>
			</visual>
		</link>
		<link name="front_part">
			<self_collide>false</self_collide>
			<pose frame="">-0.716390260045379 0.010388552481776845 0.21643769422809594 0.0 -0.0 0.0</pose>
			<inertial>
				<pose frame="">0.0 0.0 0.0 0 0 0</pose>
				<mass>16.81067246564987</mass>
				<inertia>
					<ixx>3.20922967583295</ixx>
					<ixy>0.1811361599346656</ixy>
					<ixz>-0.006723082654580219</ixz>
					<iyy>14.662960288859963</iyy>
					<iyz>1.2419706811357931</iyz>
					<izz>13.912919701383359</izz>
				</inertia>
			</inertial>
			<collision name="front_part_collision">
				<geometry>
					<mesh>
						<uri>model://rikshaw/meshes/CAD/front_part.stl</uri>
						<scale>0.001 0.001 0.001</scale>
					</mesh>
				</geometry>
			</collision>
			<visual name="front_part_visual">
				<geometry>
					<mesh>
						<uri>model://rikshaw/meshes/CAD/front_part.stl</uri>
						<scale>0.001 0.001 0.001</scale>
					</mesh>
				</geometry>
			</visual>
		</link>
		<link name="left_wheel">
			<self_collide>false</self_collide>
			<pose frame="">-0.9984258521253281 -0.3500004088111488 0.04566700000000946 0.0 -0.0 0.0</pose>
			<inertial>
				<pose frame="">0.0 0.0 0.0 0 0 0</pose>
				<mass>13.340163929097853</mass>
				<inertia>
					<ixx>2.1711695314274517</ixx>
					<ixy>-4.661713033463329</ixy>
					<ixz>0.21322209220250807</ixz>
					<iyy>14.342326161889547</iyy>
					<iyz>0.608246286975286</iyz>
					<izz>15.441547158388715</izz>
				</inertia>
			</inertial>
			<collision name="left_wheel_collision">
				<geometry>
					<mesh>
						<uri>model://rikshaw/meshes/CAD/left_wheel.stl</uri>
						<scale>0.001 0.001 0.001</scale>
					</mesh>
				</geometry>
			</collision>
			<visual name="left_wheel_visual">
				<geometry>
					<mesh>
						<uri>model://rikshaw/meshes/CAD/left_wheel.stl</uri>
						<scale>0.001 0.001 0.001</scale>
					</mesh>
				</geometry>
			</visual>
		</link>
		<link name="right_wheel">
			<self_collide>false</self_collide>
			<pose frame="">-0.9984258521253281 0.34200026941711825 0.04566700000003973 0.0 -0.0 0.0</pose>
			<inertial>
				<pose frame="">0.0 0.0 0.0 0 0 0</pose>
				<mass>13.340163929097852</mass>
				<inertia>
					<ixx>2.0973170247321944</ixx>
					<ixy>4.555157860544093</ixy>
					<ixz>-0.20834836515382574</ixz>
					<iyy>14.34232616188958</iyy>
					<iyz>0.608246286975689</iyz>
					<izz>15.367694651693421</izz>
				</inertia>
			</inertial>
			<collision name="right_wheel_collision">
				<geometry>
					<mesh>
						<uri>model://rikshaw/meshes/CAD/right_wheel.stl</uri>
						<scale>0.001 0.001 0.001</scale>
					</mesh>
				</geometry>
			</collision>
			<visual name="right_wheel_visual">
				<geometry>
					<mesh>
						<uri>model://rikshaw/meshes/CAD/right_wheel.stl</uri>
						<scale>0.001 0.001 0.001</scale>
					</mesh>
				</geometry>
			</visual>
		</link>
		<link name="pedal_right">
			<self_collide>false</self_collide>
			<pose frame="">0.077866512064399 0.14798929042854536 0.17187503593715686 0.0 -0.0 0.0</pose>
			<inertial>
				<pose frame="">0.0 0.0 0.0 0 0 0</pose>
				<mass>0.946002588602011</mass>
				<inertia>
					<ixx>0.049584952858415854</ixx>
					<ixy>-0.010901175565176115</ixy>
					<ixz>-0.024062204564554247</ixz>
					<iyy>0.03409659621083961</iyy>
					<iyz>-0.012633073677194028</iyz>
					<izz>0.02706062629596726</izz>
				</inertia>
			</inertial>
			<collision name="pedal_right_collision">
				<geometry>
					<mesh>
						<uri>model://rikshaw/meshes/CAD/pedal_right.stl</uri>
						<scale>0.001 0.001 0.001</scale>
					</mesh>
				</geometry>
			</collision>
			<visual name="pedal_right_visual">
				<geometry>
					<mesh>
						<uri>model://rikshaw/meshes/CAD/pedal_right.stl</uri>
						<scale>0.001 0.001 0.001</scale>
					</mesh>
				</geometry>
			</visual>
		</link>
		<link name="kurbel">
			<self_collide>false</self_collide>
			<pose frame="">0.09222872619138603 0.00013171801209023543 0.0042772834965418725 0.0 -0.0 0.0</pose>
			<inertial>
				<pose frame="">0.0 0.0 0.0 0 0 0</pose>
				<mass>2.7832708381108002</mass>
				<inertia>
					<ixx>0.03321525556564324</ixx>
					<ixy>0.0010218101556732108</ixy>
					<ixz>-0.012937192477662387</ixz>
					<iyy>0.04158688185273832</iyy>
					<iyz>0.00030143634944108515</iyz>
					<izz>0.039731070916127355</izz>
				</inertia>
			</inertial>
			<collision name="kurbel_collision">
				<geometry>
					<mesh>
						<uri>model://rikshaw/meshes/CAD/kurbel.stl</uri>
						<scale>0.001 0.001 0.001</scale>
					</mesh>
				</geometry>
			</collision>
			<visual name="kurbel_visual">
				<geometry>
					<mesh>
						<uri>model://rikshaw/meshes/CAD/kurbel.stl</uri>
						<scale>0.001 0.001 0.001</scale>
					</mesh>
				</geometry>
			</visual>
		</link>
		<link name="pedal_left">
			<self_collide>false</self_collide>
			<pose frame="">0.10738103245690385 -0.14924470957145594 -0.16537796258198015 0.0 -0.0 0.0</pose>
			<inertial>
				<pose frame="">0.0 0.0 0.0 0 0 0</pose>
				<mass>0.9460025886020074</mass>
				<inertia>
					<ixx>0.0478650709459344</ixx>
					<ixy>0.015160685733445756</ixy>
					<ixz>-0.02334903344265402</ixz>
					<iyy>0.037196017563940593</iyy>
					<iyz>0.016827373941817436</iyz>
					<izz>0.032585937449107163</izz>
				</inertia>
			</inertial>
			<collision name="pedal_left_collision">
				<geometry>
					<mesh>
						<uri>model://rikshaw/meshes/CAD/pedal_left.stl</uri>
						<scale>0.001 0.001 0.001</scale>
					</mesh>
				</geometry>
			</collision>
			<visual name="pedal_left_visual">
				<geometry>
					<mesh>
						<uri>model://rikshaw/meshes/CAD/pedal_left.stl</uri>
						<scale>0.001 0.001 0.001</scale>
					</mesh>
				</geometry>
			</visual>
		</link>
		<link name="foot_left">
			<self_collide>false</self_collide>
			<pose frame="">0.1758335832021747 -0.18852199978740128 -0.20648446058656983 0.0 -0.0 0.0</pose>
			<inertial>
				<pose frame="">0.0 0.0 0.0 0 0 0</pose>
				<mass>0.7293868680453512</mass>
				<inertia>
					<ixx>0.05407030165176465</ixx>
					<ixy>0.032515128675582344</ixy>
					<ixz>-0.02676028535957317</ixz>
					<iyy>0.06910552877147094</iyy>
					<iyz>0.033571986359585956</iyz>
					<izz>0.06736891274795608</izz>
				</inertia>
			</inertial>
			<collision name="foot_left_collision">
				<geometry>
					<mesh>
						<uri>model://rikshaw/meshes/CAD/foot_left.stl</uri>
						<scale>0.001 0.001 0.001</scale>
					</mesh>
				</geometry>
			</collision>
			<visual name="foot_left_visual">
				<geometry>
					<mesh>
						<uri>model://rikshaw/meshes/CAD/foot_left.stl</uri>
						<scale>0.001 0.001 0.001</scale>
					</mesh>
				</geometry>
			</visual>
		</link>
		<link name="foot_left_tip">
			<self_collide>false</self_collide>
			<pose frame="">0.13523740897369785 -0.1873561275007122 -0.2121568313241679 0.0 -0.0 0.0</pose>
			<inertial>
				<pose frame="">0.0 0.0 0.0 0 0 0</pose>
				<mass>0.27793994464342403</mass>
				<inertia>
					<ixx>0.022350829516196824</ixx>
					<ixy>0.007050691747742392</ixy>
					<ixz>-0.011047147308991735</ixz>
					<iyy>0.017708282428285958</iyy>
					<iyz>0.007965007798907258</iyz>
					<izz>0.01503154610940157</izz>
				</inertia>
			</inertial>
			<collision name="foot_left_tip_collision">
				<geometry>
					<mesh>
						<uri>model://rikshaw/meshes/CAD/foot_left_tip.stl</uri>
						<scale>0.001 0.001 0.001</scale>
					</mesh>
				</geometry>
			</collision>
			<visual name="foot_left_tip_visual">
				<geometry>
					<mesh>
						<uri>model://rikshaw/meshes/CAD/foot_left_tip.stl</uri>
						<scale>0.001 0.001 0.001</scale>
					</mesh>
				</geometry>
			</visual>
		</link>
		<link name="foot_right">
			<self_collide>false</self_collide>
			<pose frame="">0.17755692904068937 0.15962800036486463 -0.2048798081230718 0.0 -0.0 0.0</pose>
			<inertial>
				<pose frame="">0.0 0.0 0.0 0 0 0</pose>
				<mass>0.729389451072159</mass>
				<inertia>
					<ixx>0.04662855348933404</ixx>
					<ixy>-0.027737149337326197</ixy>
					<ixz>0.02258943857652172</ixz>
					<iyy>0.06999771150432102</iyy>
					<iyz>0.03393989295119285</iyz>
					<izz>0.06080287947049831</izz>
				</inertia>
			</inertial>
			<collision name="foot_right_collision">
				<geometry>
					<mesh>
						<uri>model://rikshaw/meshes/CAD/foot_right.stl</uri>
						<scale>0.001 0.001 0.001</scale>
					</mesh>
				</geometry>
			</collision>
			<visual name="foot_right_visual">
				<geometry>
					<mesh>
						<uri>model://rikshaw/meshes/CAD/foot_right.stl</uri>
						<scale>0.001 0.001 0.001</scale>
					</mesh>
				</geometry>
			</visual>
		</link>
		<link name="foot_right_tip">
			<self_collide>false</self_collide>
			<pose frame="">0.13747575892772618 0.1579606226770175 -0.21111014954892007 0.0 -0.0 0.0</pose>
			<inertial>
				<pose frame="">0.0 0.0 0.0 0 0 0</pose>
				<mass>0.27795073699830286</mass>
				<inertia>
					<ixx>0.01940696467770468</ixx>
					<ixy>-0.006044281421455188</ixy>
					<ixz>0.009268276355937553</ixz>
					<iyy>0.017755497432934832</iyy>
					<iyz>0.008058438802785882</iyz>
					<izz>0.012380586280311603</izz>
				</inertia>
			</inertial>
			<collision name="foot_right_tip_collision">
				<geometry>
					<mesh>
						<uri>model://rikshaw/meshes/CAD/foot_right_tip.stl</uri>
						<scale>0.001 0.001 0.001</scale>
					</mesh>
				</geometry>
			</collision>
			<visual name="foot_right_tip_visual">
				<geometry>
					<mesh>
						<uri>model://rikshaw/meshes/CAD/foot_right_tip.stl</uri>
						<scale>0.001 0.001 0.001</scale>
					</mesh>
				</geometry>
			</visual>
		</link>
		<link name="thigh_right">
			<self_collide>false</self_collide>
			<pose frame="">0.2288096962986095 0.1838357520950985 0.3778973413662584 0.0 -0.0 0.0</pose>
			<inertial>
				<pose frame="">0.0 0.0 0.0 0 0 0</pose>
				<mass>5.563526842051083</mass>
				<inertia>
					<ixx>1.010776410503541</ixx>
					<ixy>-0.2339478815586405</ixy>
					<ixz>-0.38955605191739445</ixz>
					<iyy>1.1169308947780017</iyy>
					<iyz>-0.4818325949799062</iyz>
					<izz>0.4914242462128824</izz>
				</inertia>
			</inertial>
			<collision name="thigh_right_collision">
				<geometry>
					<mesh>
						<uri>model://rikshaw/meshes/CAD/thigh_right.stl</uri>
						<scale>0.001 0.001 0.001</scale>
					</mesh>
				</geometry>
			</collision>
			<visual name="thigh_right_visual">
				<geometry>
					<mesh>
						<uri>model://rikshaw/meshes/CAD/thigh_right.stl</uri>
						<scale>0.001 0.001 0.001</scale>
					</mesh>
				</geometry>
			</visual>
		</link>
		<link name="thigh_left">
			<self_collide>false</self_collide>
			<pose frame="">0.2292806537828578 -0.21262774954037852 0.3779068936299882 0.0 -0.0 0.0</pose>
			<inertial>
				<pose frame="">0.0 0.0 0.0 0 0 0</pose>
				<mass>5.56358907681273</mass>
				<inertia>
					<ixx>1.074346946173753</ixx>
					<ixy>0.27061154427198303</ixy>
					<ixz>0.4500933632421805</ixz>
					<iyy>1.11818441834799</iyy>
					<iyz>-0.48310679386128286</iyz>
					<izz>0.5561292960445591</izz>
				</inertia>
			</inertial>
			<collision name="thigh_left_collision">
				<geometry>
					<mesh>
						<uri>model://rikshaw/meshes/CAD/thigh_left.stl</uri>
						<scale>0.001 0.001 0.001</scale>
					</mesh>
				</geometry>
			</collision>
			<visual name="thigh_left_visual">
				<geometry>
					<mesh>
						<uri>model://rikshaw/meshes/CAD/thigh_left.stl</uri>
						<scale>0.001 0.001 0.001</scale>
					</mesh>
				</geometry>
			</visual>
		</link>
		<link name="leg_right">
			<self_collide>false</self_collide>
			<pose frame="">0.23291230339322222 0.18326545464147473 0.02997274571608183 0.0 -0.0 0.0</pose>
			<inertial>
				<pose frame="">0.0 0.0 0.0 0 0 0</pose>
				<mass>5.741522183296095</mass>
				<inertia>
					<ixx>0.23781953162702005</ixx>
					<ixy>-0.24551774912550647</ixy>
					<ixz>-0.0349695895920111</ixz>
					<iyy>0.35939915474470285</iyy>
					<iyz>-0.03759074396148515</iyz>
					<izz>0.5167551686248066</izz>
				</inertia>
			</inertial>
			<collision name="leg_right_collision">
				<geometry>
					<mesh>
						<uri>model://rikshaw/meshes/CAD/leg_right.stl</uri>
						<scale>0.001 0.001 0.001</scale>
					</mesh>
				</geometry>
			</collision>
			<visual name="leg_right_visual">
				<geometry>
					<mesh>
						<uri>model://rikshaw/meshes/CAD/leg_right.stl</uri>
						<scale>0.001 0.001 0.001</scale>
					</mesh>
				</geometry>
			</visual>
		</link>
		<link name="leg_left">
			<self_collide>false</self_collide>
			<pose frame="">0.23204399957549993 -0.21169134883590915 0.03008519121128405 0.0 -0.0 0.0</pose>
			<inertial>
				<pose frame="">0.0 0.0 0.0 0 0 0</pose>
				<mass>5.742617323881256</mass>
				<inertia>
					<ixx>0.30243679771490606</ixx>
					<ixy>0.2819991342227071</ixy>
					<ixz>0.04001187315119927</ixz>
					<iyy>0.3572028058613215</iyy>
					<iyz>-0.03813053072294939</iyz>
					<izz>0.5789432870277177</izz>
				</inertia>
			</inertial>
			<collision name="leg_left_collision">
				<geometry>
					<mesh>
						<uri>model://rikshaw/meshes/CAD/leg_left.stl</uri>
						<scale>0.001 0.001 0.001</scale>
					</mesh>
				</geometry>
			</collision>
			<visual name="leg_left_visual">
				<geometry>
					<mesh>
						<uri>model://rikshaw/meshes/CAD/leg_left.stl</uri>
						<scale>0.001 0.001 0.001</scale>
					</mesh>
				</geometry>
			</visual>
		</link>
		<link name="wheel_back">
			<self_collide>false</self_collide>
			<pose frame="">0.53689742860369 0.0035499556212922633 0.049415870249024677 0.0 -0.0 0.0</pose>
			<inertial>
				<pose frame="">0.0 0.0 0.0 0 0 0</pose>
				<mass>13.340163929098475</mass>
				<inertia>
					<ixx>0.5419188938328752</ixx>
					<ixy>-0.02542584611932503</ixy>
					<ixz>-0.0023401868697195947</ixz>
					<iyy>4.894303401629515</iyy>
					<iyz>-0.3539312731878215</iyz>
					<izz>4.3547634684642125</izz>
				</inertia>
			</inertial>
			<collision name="wheel_back_collision">
				<geometry>
					<mesh>
						<uri>model://rikshaw/meshes/CAD/wheel_back.stl</uri>
						<scale>0.001 0.001 0.001</scale>
					</mesh>
				</geometry>
			</collision>
			<visual name="wheel_back_visual">
				<geometry>
					<mesh>
						<uri>model://rikshaw/meshes/CAD/wheel_back.stl</uri>
						<scale>0.001 0.001 0.001</scale>
					</mesh>
				</geometry>
			</visual>
		</link>
		<link name="left_shoulder_link1">
			<self_collide>false</self_collide>
			<pose frame="">0.234499556870264 -0.3057835063704398 1.1636294622513998 0.0 -0.0 0.0</pose>
			<inertial>
				<pose frame="">0.0 0.0 0.0 0 0 0</pose>
				<mass>0.046754318188270985</mass>
				<inertia>
					<ixx>0.06768458325753283</ixx>
					<ixy>0.0033525696636321494</ixy>
					<ixz>0.01663606058190128</ixz>
					<iyy>0.06588391032537416</iyy>
					<iyz>-0.01275787854145993</iyz>
					<izz>0.006948690775751864</izz>
				</inertia>
			</inertial>
			<collision name="left_shoulder_link1_collision">
				<geometry>
					<mesh>
						<uri>model://rikshaw/meshes/CAD/left_shoulder_link1.stl</uri>
						<scale>0.001 0.001 0.001</scale>
					</mesh>
				</geometry>
			</collision>
			<visual name="left_shoulder_link1_visual">
				<geometry>
					<mesh>
						<uri>model://rikshaw/meshes/CAD/left_shoulder_link1.stl</uri>
						<scale>0.001 0.001 0.001</scale>
					</mesh>
				</geometry>
			</visual>
		</link>
		<link name="left_shoulder_link2">
			<self_collide>false</self_collide>
			<pose frame="">0.23449955914367152 -0.3057827254054156 1.1636302626853117 0.0 -0.0 0.0</pose>
			<inertial>
				<pose frame="">0.0 0.0 0.0 0 0 0</pose>
				<mass>0.031341649376529494</mass>
				<inertia>
					<ixx>0.045370941519395296</ixx>
					<ixy>0.0022473816229572393</ixy>
					<ixz>0.011151924037378065</ixz>
					<iyy>0.044163879572415216</iyy>
					<iyz>-0.00855222042487607</iyz>
					<izz>0.004656717890960706</izz>
				</inertia>
			</inertial>
			<collision name="left_shoulder_link2_collision">
				<geometry>
					<mesh>
						<uri>model://rikshaw/meshes/CAD/left_shoulder_link2.stl</uri>
						<scale>0.001 0.001 0.001</scale>
					</mesh>
				</geometry>
			</collision>
			<visual name="left_shoulder_link2_visual">
				<geometry>
					<mesh>
						<uri>model://rikshaw/meshes/CAD/left_shoulder_link2.stl</uri>
						<scale>0.001 0.001 0.001</scale>
					</mesh>
				</geometry>
			</visual>
		</link>
		<link name="right_shoulder_link1">
			<self_collide>false</self_collide>
			<pose frame="">0.20349365438321168 0.27775836042986796 1.163027939851875 0.0 -0.0 0.0</pose>
			<inertial>
				<pose frame="">0.0 0.0 0.0 0 0 0</pose>
				<mass>0.046737542469703665</mass>
				<inertia>
					<ixx>0.06683054639698344</ixx>
					<ixy>-0.0026417023367387225</ixy>
					<ixz>-0.015098130031610583</ixz>
					<iyy>0.06516014659339606</iyy>
					<iyz>-0.011061318354391007</iyz>
					<izz>0.005547146012772539</izz>
				</inertia>
			</inertial>
			<collision name="right_shoulder_link1_collision">
				<geometry>
					<mesh>
						<uri>model://rikshaw/meshes/CAD/right_shoulder_link1.stl</uri>
						<scale>0.001 0.001 0.001</scale>
					</mesh>
				</geometry>
			</collision>
			<visual name="right_shoulder_link1_visual">
				<geometry>
					<mesh>
						<uri>model://rikshaw/meshes/CAD/right_shoulder_link1.stl</uri>
						<scale>0.001 0.001 0.001</scale>
					</mesh>
				</geometry>
			</visual>
		</link>
		<link name="right_shoulder_link2">
			<self_collide>false</self_collide>
			<pose frame="">0.20349360310474382 0.27775511606610254 1.1630248171245832 0.0 -0.0 0.0</pose>
			<inertial>
				<pose frame="">0.0 0.0 0.0 0 0 0</pose>
				<mass>0.03133944344667861</mass>
				<inertia>
					<ixx>0.04481103963121709</ixx>
					<ixy>-0.001771348888551383</ixy>
					<ixz>-0.010123771369935102</ixz>
					<iyy>0.043691022672523526</iyy>
					<iyz>-0.007417046865804014</iyz>
					<izz>0.0037182261451840287</izz>
				</inertia>
			</inertial>
			<collision name="right_shoulder_link2_collision">
				<geometry>
					<mesh>
						<uri>model://rikshaw/meshes/CAD/right_shoulder_link2.stl</uri>
						<scale>0.001 0.001 0.001</scale>
					</mesh>
				</geometry>
			</collision>
			<visual name="right_shoulder_link2_visual">
				<geometry>
					<mesh>
						<uri>model://rikshaw/meshes/CAD/right_shoulder_link2.stl</uri>
						<scale>0.001 0.001 0.001</scale>
					</mesh>
				</geometry>
			</visual>
		</link>
		<link name="zed_camera_left_lense">
			<self_collide>false</self_collide>
			<pose frame="">0.13329433518456796 -0.07464603694664317 1.5398836881584137 0.0 -0.0 0.0</pose>
			<inertial>
				<pose frame="">0.0 0.0 0.0 0 0 0</pose>
				<mass>0.005755421853194515</mass>
				<inertia>
					<ixx>0.013679771209499064</ixx>
					<ixy>5.726525469349843e-05</ixy>
					<ixz>0.0006615640759674412</ixz>
					<iyy>0.013750144080850644</iyy>
					<iyz>-0.0011813074233920898</iyz>
					<izz>0.0001347218674401277</izz>
				</inertia>
			</inertial>
			<collision name="zed_camera_left_lense_collision">
				<geometry>
					<mesh>
						<uri>model://rikshaw/meshes/CAD/zed_camera_left_lense.stl</uri>
						<scale>0.001 0.001 0.001</scale>
					</mesh>
				</geometry>
			</collision>
			<visual name="zed_camera_left_lense_visual">
				<geometry>
					<mesh>
						<uri>model://rikshaw/meshes/CAD/zed_camera_left_lense.stl</uri>
						<scale>0.001 0.001 0.001</scale>
					</mesh>
				</geometry>
			</visual>
		</link>
		<link name="zed_camera_right_lense">
			<self_collide>false</self_collide>
			<pose frame="">0.13291753408108645 0.04535544832718309 1.5398763705896203 0.0 -0.0 0.0</pose>
			<inertial>
				<pose frame="">0.0 0.0 0.0 0 0 0</pose>
				<mass>0.0057554218519331405</mass>
				<inertia>
					<ixx>0.013659411686808433</ixx>
					<ixy>-3.4697332175563284e-05</ixy>
					<ixz>-0.00040196880644093893</ixz>
					<iyy>0.01374943705146634</iyy>
					<iyz>-0.0011779623575235952</iyz>
					<izz>0.00011391473381891815</izz>
				</inertia>
			</inertial>
			<collision name="zed_camera_right_lense_collision">
				<geometry>
					<mesh>
						<uri>model://rikshaw/meshes/CAD/zed_camera_right_lense.stl</uri>
						<scale>0.001 0.001 0.001</scale>
					</mesh>
				</geometry>
			</collision>
			<visual name="zed_camera_right_lense_visual">
				<geometry>
					<mesh>
						<uri>model://rikshaw/meshes/CAD/zed_camera_right_lense.stl</uri>
						<scale>0.001 0.001 0.001</scale>
					</mesh>
				</geometry>
			</visual>
		</link>
		<link name="zed_camera">
			<self_collide>false</self_collide>
			<pose frame="">0.14454940292537402 -0.018666503380143074 1.5375230682804268 0.0 -0.0 0.0</pose>
			<inertial>
				<pose frame="">0.0 0.0 0.0 0 0 0</pose>
				<mass>0.009633907998289063</mass>
				<inertia>
					<ixx>0.022792666578554423</ixx>
					<ixy>2.5926776330602043e-05</ixy>
					<ixz>0.0002765126220790255</ixz>
					<iyy>0.022975931983248037</iyy>
					<iyz>-0.0021411625974831305</iyz>
					<izz>0.0002193907040420383</izz>
				</inertia>
			</inertial>
			<collision name="zed_camera_collision">
				<geometry>
					<mesh>
						<uri>model://rikshaw/meshes/CAD/zed_camera.stl</uri>
						<scale>0.001 0.001 0.001</scale>
					</mesh>
				</geometry>
			</collision>
			<visual name="zed_camera_visual">
				<geometry>
					<mesh>
						<uri>model://rikshaw/meshes/CAD/zed_camera.stl</uri>
						<scale>0.001 0.001 0.001</scale>
					</mesh>
				</geometry>
			</visual>
		</link>
		<link name="sphere_head_link1">
			<self_collide>false</self_collide>
			<pose frame="">0.2081696086061305 -0.014422001372557842 1.325209030798238 0.0 -0.0 0.0</pose>
			<inertial>
				<pose frame="">0.0 0.0 0.0 0 0 0</pose>
				<mass>0.017037660152065294</mass>
				<inertia>
					<ixx>0.029925835018192334</ixx>
					<ixy>5.115084454446518e-05</ixy>
					<ixz>0.0003256265969558982</ixz>
					<iyy>0.030660611222104128</iyy>
					<iyz>-0.004700149409530272</iyz>
					<izz>0.0007429744412817213</izz>
				</inertia>
			</inertial>
			<collision name="sphere_head_link1_collision">
				<geometry>
					<mesh>
						<uri>model://rikshaw/meshes/CAD/sphere_head_link1.stl</uri>
						<scale>0.001 0.001 0.001</scale>
					</mesh>
				</geometry>
			</collision>
			<visual name="sphere_head_link1_visual">
				<geometry>
					<mesh>
						<uri>model://rikshaw/meshes/CAD/sphere_head_link1.stl</uri>
						<scale>0.001 0.001 0.001</scale>
					</mesh>
				</geometry>
			</visual>
		</link>
		<link name="sphere_head_link2">
			<self_collide>false</self_collide>
			<pose frame="">0.20816962194727778 -0.014421998969456935 1.3252092596581908 0.0 -0.0 0.0</pose>
			<inertial>
				<pose frame="">0.0 0.0 0.0 0 0 0</pose>
				<mass>0.011421516918761764</mass>
				<inertia>
					<ixx>0.02006111218075207</ixx>
					<ixy>3.428993016456809e-05</ixy>
					<ixz>0.00021828993383593312</ixz>
					<iyy>0.020553683338140852</iyy>
					<iyz>-0.0031508345766862664</iyz>
					<izz>0.0004978241420242784</izz>
				</inertia>
			</inertial>
			<collision name="sphere_head_link2_collision">
				<geometry>
					<mesh>
						<uri>model://rikshaw/meshes/CAD/sphere_head_link2.stl</uri>
						<scale>0.001 0.001 0.001</scale>
					</mesh>
				</geometry>
			</collision>
			<visual name="sphere_head_link2_visual">
				<geometry>
					<mesh>
						<uri>model://rikshaw/meshes/CAD/sphere_head_link2.stl</uri>
						<scale>0.001 0.001 0.001</scale>
					</mesh>
				</geometry>
			</visual>
		</link>
		<link name="head">
			<self_collide>false</self_collide>
			<pose frame="">0.24888633175877495 -0.01493152222449911 1.468899526100001 0.0 -0.0 0.0</pose>
			<inertial>
				<pose frame="">0.0 0.0 0.0 0 0 0</pose>
				<mass>2.118808936153909</mass>
				<inertia>
					<ixx>4.599596642186236</ixx>
					<ixy>0.007886725770330701</ixy>
					<ixz>0.04658343672096889</ixz>
					<iyy>4.736715552901334</iyy>
					<iyz>-0.7776869488012329</iyz>
					<izz>0.15785271778512713</izz>
				</inertia>
			</inertial>
			<collision name="head_collision">
				<geometry>
					<mesh>
						<uri>model://rikshaw/meshes/CAD/head.stl</uri>
						<scale>0.001 0.001 0.001</scale>
					</mesh>
				</geometry>
			</collision>
			<visual name="head_visual">
				<geometry>
					<mesh>
						<uri>model://rikshaw/meshes/CAD/head.stl</uri>
						<scale>0.001 0.001 0.001</scale>
					</mesh>
				</geometry>
			</visual>
		</link>
		<link name="little_right_link2">
			<self_collide>false</self_collide>
			<pose frame="">0.2703776223993091 0.8551792977612176 0.6609678941498701 0.0 -0.0 0.0</pose>
			<inertial>
				<pose frame="">0.0 0.0 0.0 0 0 0</pose>
				<mass>0.007230564904666386</mass>
				<inertia>
					<ixx>0.00844754881737185</ixx>
					<ixy>-0.0016717256846055766</ixy>
					<ixz>-0.004086825994589089</ixz>
					<iyy>0.0036879821037301506</iyy>
					<iyz>-0.001292278840354022</iyz>
					<izz>0.005817180780529369</izz>
				</inertia>
			</inertial>
			<collision name="little_right_link2_collision">
				<geometry>
					<mesh>
						<uri>model://rikshaw/meshes/CAD/little_right_link2.stl</uri>
						<scale>0.001 0.001 0.001</scale>
					</mesh>
				</geometry>
			</collision>
			<visual name="little_right_link2_visual">
				<geometry>
					<mesh>
						<uri>model://rikshaw/meshes/CAD/little_right_link2.stl</uri>
						<scale>0.001 0.001 0.001</scale>
					</mesh>
				</geometry>
			</visual>
		</link>
		<link name="little_right_link0">
			<self_collide>false</self_collide>
			<pose frame="">0.26585625284436415 0.8128811956220895 0.6970769583771008 0.0 -0.0 0.0</pose>
			<inertial>
				<pose frame="">0.0 0.0 0.0 0 0 0</pose>
				<mass>0.010783208913438909</mass>
				<inertia>
					<ixx>0.012367043466895366</ixx>
					<ixy>-0.00232988608190317</ixy>
					<ixz>-0.006109371663701634</ixz>
					<iyy>0.006003251624155561</iyy>
					<iyz>-0.001998744106830586</iyz>
					<izz>0.007889121819399299</izz>
				</inertia>
			</inertial>
			<collision name="little_right_link0_collision">
				<geometry>
					<mesh>
						<uri>model://rikshaw/meshes/CAD/little_right_link0.stl</uri>
						<scale>0.001 0.001 0.001</scale>
					</mesh>
				</geometry>
			</collision>
			<visual name="little_right_link0_visual">
				<geometry>
					<mesh>
						<uri>model://rikshaw/meshes/CAD/little_right_link0.stl</uri>
						<scale>0.001 0.001 0.001</scale>
					</mesh>
				</geometry>
			</visual>
		</link>
		<link name="little_right_link1">
			<self_collide>false</self_collide>
			<pose frame="">0.2668262159022453 0.8364616564640865 0.6767894442890324 0.0 -0.0 0.0</pose>
			<inertial>
				<pose frame="">0.0 0.0 0.0 0 0 0</pose>
				<mass>0.008727399884658343</mass>
				<inertia>
					<ixx>0.010105036327609968</ixx>
					<ixy>-0.001947516201001286</ixy>
					<ixz>-0.004940183790417728</ixz>
					<iyy>0.004619848536697083</iyy>
					<iyz>-0.0015763175050061216</iyz>
					<izz>0.006728786504275826</izz>
				</inertia>
			</inertial>
			<collision name="little_right_link1_collision">
				<geometry>
					<mesh>
						<uri>model://rikshaw/meshes/CAD/little_right_link1.stl</uri>
						<scale>0.001 0.001 0.001</scale>
					</mesh>
				</geometry>
			</collision>
			<visual name="little_right_link1_visual">
				<geometry>
					<mesh>
						<uri>model://rikshaw/meshes/CAD/little_right_link1.stl</uri>
						<scale>0.001 0.001 0.001</scale>
					</mesh>
				</geometry>
			</visual>
		</link>
		<link name="ring_right_link2">
			<self_collide>false</self_collide>
			<pose frame="">0.23153053787238567 0.8616310221513926 0.6569170037412038 0.0 -0.0 0.0</pose>
			<inertial>
				<pose frame="">0.0 0.0 0.0 0 0 0</pose>
				<mass>0.007230552864674504</mass>
				<inertia>
					<ixx>0.008488987634079495</ixx>
					<ixy>-0.0014422893175977246</ixy>
					<ixz>-0.004092432946782776</ixz>
					<iyy>0.0035084158367746235</iyy>
					<iyz>-0.0010998563639696747</iyz>
					<izz>0.005756295137618685</izz>
				</inertia>
			</inertial>
			<collision name="ring_right_link2_collision">
				<geometry>
					<mesh>
						<uri>model://rikshaw/meshes/CAD/ring_right_link2.stl</uri>
						<scale>0.001 0.001 0.001</scale>
					</mesh>
				</geometry>
			</collision>
			<visual name="ring_right_link2_visual">
				<geometry>
					<mesh>
						<uri>model://rikshaw/meshes/CAD/ring_right_link2.stl</uri>
						<scale>0.001 0.001 0.001</scale>
					</mesh>
				</geometry>
			</visual>
		</link>
		<link name="ring_right_link0">
			<self_collide>false</self_collide>
			<pose frame="">0.23225971142689347 0.8190768449309755 0.6930010068941554 0.0 -0.0 0.0</pose>
			<inertial>
				<pose frame="">0.0 0.0 0.0 0 0 0</pose>
				<mass>0.010783248840452798</mass>
				<inertia>
					<ixx>0.012414898178048861</ixx>
					<ixy>-0.0020508301340881976</ixy>
					<ixz>-0.006120027515095472</ixz>
					<iyy>0.005761788122486669</iyy>
					<iyz>-0.0017360773271864654</iyz>
					<izz>0.007817779405669642</izz>
				</inertia>
			</inertial>
			<collision name="ring_right_link0_collision">
				<geometry>
					<mesh>
						<uri>model://rikshaw/meshes/CAD/ring_right_link0.stl</uri>
						<scale>0.001 0.001 0.001</scale>
					</mesh>
				</geometry>
			</collision>
			<visual name="ring_right_link0_visual">
				<geometry>
					<mesh>
						<uri>model://rikshaw/meshes/CAD/ring_right_link0.stl</uri>
						<scale>0.001 0.001 0.001</scale>
					</mesh>
				</geometry>
			</visual>
		</link>
		<link name="ring_right_link1">
			<self_collide>false</self_collide>
			<pose frame="">0.23029991205691183 0.8426893460756414 0.6728225549659885 0.0 -0.0 0.0</pose>
			<inertial>
				<pose frame="">0.0 0.0 0.0 0 0 0</pose>
				<mass>0.00872746416092259</mass>
				<inertia>
					<ixx>0.010149561482833908</ixx>
					<ixy>-0.0016933565068352327</ixy>
					<ixz>-0.004947874958369445</ixz>
					<iyy>0.004414733369149532</iyy>
					<iyz>-0.0013526392046900083</iyz>
					<izz>0.006661665499802899</izz>
				</inertia>
			</inertial>
			<collision name="ring_right_link1_collision">
				<geometry>
					<mesh>
						<uri>model://rikshaw/meshes/CAD/ring_right_link1.stl</uri>
						<scale>0.001 0.001 0.001</scale>
					</mesh>
				</geometry>
			</collision>
			<visual name="ring_right_link1_visual">
				<geometry>
					<mesh>
						<uri>model://rikshaw/meshes/CAD/ring_right_link1.stl</uri>
						<scale>0.001 0.001 0.001</scale>
					</mesh>
				</geometry>
			</visual>
		</link>
		<link name="middle_right_link2">
			<self_collide>false</self_collide>
			<pose frame="">0.20060527237412132 0.860299757868816 0.6598948502203558 0.0 -0.0 0.0</pose>
			<inertial>
				<pose frame="">0.0 0.0 0.0 0 0 0</pose>
				<mass>0.007230650401745365</mass>
				<inertia>
					<ixx>0.008500854287556139</ixx>
					<ixy>-0.0012476938264289865</ixy>
					<ixz>-0.004104701457077143</ixz>
					<iyy>0.0034402019364678503</iyy>
					<iyz>-0.0009573068442030666</iyz>
					<izz>0.005643178583406474</izz>
				</inertia>
			</inertial>
			<collision name="middle_right_link2_collision">
				<geometry>
					<mesh>
						<uri>model://rikshaw/meshes/CAD/middle_right_link2.stl</uri>
						<scale>0.001 0.001 0.001</scale>
					</mesh>
				</geometry>
			</collision>
			<visual name="middle_right_link2_visual">
				<geometry>
					<mesh>
						<uri>model://rikshaw/meshes/CAD/middle_right_link2.stl</uri>
						<scale>0.001 0.001 0.001</scale>
					</mesh>
				</geometry>
			</visual>
		</link>
		<link name="middle_right_link0">
			<self_collide>false</self_collide>
			<pose frame="">0.2048341551868794 0.8177839770780796 0.695782787665069 0.0 -0.0 0.0</pose>
			<inertial>
				<pose frame="">0.0 0.0 0.0 0 0 0</pose>
				<mass>0.010783222786021226</mass>
				<inertia>
					<ixx>0.012433613043271768</ixx>
					<ixy>-0.001805688612972297</ixy>
					<ixz>-0.006134928948914575</ixz>
					<iyy>0.005674221087862887</iyy>
					<iyz>-0.0015373102779523043</iyz>
					<izz>0.007665717661803175</izz>
				</inertia>
			</inertial>
			<collision name="middle_right_link0_collision">
				<geometry>
					<mesh>
						<uri>model://rikshaw/meshes/CAD/middle_right_link0.stl</uri>
						<scale>0.001 0.001 0.001</scale>
					</mesh>
				</geometry>
			</collision>
			<visual name="middle_right_link0_visual">
				<geometry>
					<mesh>
						<uri>model://rikshaw/meshes/CAD/middle_right_link0.stl</uri>
						<scale>0.001 0.001 0.001</scale>
					</mesh>
				</geometry>
			</visual>
		</link>
		<link name="middle_right_link1">
			<self_collide>false</self_collide>
			<pose frame="">0.20092912448970393 0.8413012508989332 0.6757766218706687 0.0 -0.0 0.0</pose>
			<inertial>
				<pose frame="">0.0 0.0 0.0 0 0 0</pose>
				<mass>0.008727454453508098</mass>
				<inertia>
					<ixx>0.010163853752980198</ixx>
					<ixy>-0.0014748911218410256</ixy>
					<ixz>-0.004961440588380607</ixz>
					<iyy>0.0043389962082691</iyy>
					<iyz>-0.0011853664474558144</iyz>
					<izz>0.0065307472361486206</izz>
				</inertia>
			</inertial>
			<collision name="middle_right_link1_collision">
				<geometry>
					<mesh>
						<uri>model://rikshaw/meshes/CAD/middle_right_link1.stl</uri>
						<scale>0.001 0.001 0.001</scale>
					</mesh>
				</geometry>
			</collision>
			<visual name="middle_right_link1_visual">
				<geometry>
					<mesh>
						<uri>model://rikshaw/meshes/CAD/middle_right_link1.stl</uri>
						<scale>0.001 0.001 0.001</scale>
					</mesh>
				</geometry>
			</visual>
		</link>
		<link name="index_right_link2">
			<self_collide>false</self_collide>
			<pose frame="">0.16174685403884753 0.8555045775324542 0.6658166712766795 0.0 -0.0 0.0</pose>
			<inertial>
				<pose frame="">0.0 0.0 0.0 0 0 0</pose>
				<mass>0.007230613589821098</mass>
				<inertia>
					<ixx>0.008498029515265326</ixx>
					<ixy>-0.0010003395016302805</ixy>
					<ixz>-0.0041184596389472776</ixz>
					<iyy>0.0033951724444091654</iyy>
					<iyz>-0.000778828582884532</iyz>
					<izz>0.0054818716216465755</izz>
				</inertia>
			</inertial>
			<collision name="index_right_link2_collision">
				<geometry>
					<mesh>
						<uri>model://rikshaw/meshes/CAD/index_right_link2.stl</uri>
						<scale>0.001 0.001 0.001</scale>
					</mesh>
				</geometry>
			</collision>
			<visual name="index_right_link2_visual">
				<geometry>
					<mesh>
						<uri>model://rikshaw/meshes/CAD/index_right_link2.stl</uri>
						<scale>0.001 0.001 0.001</scale>
					</mesh>
				</geometry>
			</visual>
		</link>
		<link name="index_right_link0">
			<self_collide>false</self_collide>
			<pose frame="">0.17272012775816362 0.8135406747045084 0.7009172289613816 0.0 -0.0 0.0</pose>
			<inertial>
				<pose frame="">0.0 0.0 0.0 0 0 0</pose>
				<mass>0.010783226463222334</mass>
				<inertia>
					<ixx>0.01243610136086843</ixx>
					<ixy>-0.001514522125897847</ixy>
					<ixz>-0.006148237114841062</ixz>
					<iyy>0.005620922589857911</iyy>
					<iyz>-0.001305979259153262</iyz>
					<izz>0.007460419515803034</izz>
				</inertia>
			</inertial>
			<collision name="index_right_link0_collision">
				<geometry>
					<mesh>
						<uri>model://rikshaw/meshes/CAD/index_right_link0.stl</uri>
						<scale>0.001 0.001 0.001</scale>
					</mesh>
				</geometry>
			</collision>
			<visual name="index_right_link0_visual">
				<geometry>
					<mesh>
						<uri>model://rikshaw/meshes/CAD/index_right_link0.stl</uri>
						<scale>0.001 0.001 0.001</scale>
					</mesh>
				</geometry>
			</visual>
		</link>
		<link name="index_right_link1">
			<self_collide>false</self_collide>
			<pose frame="">0.16508378889178013 0.8366077017977238 0.6814709448736221 0.0 -0.0 0.0</pose>
			<inertial>
				<pose frame="">0.0 0.0 0.0 0 0 0</pose>
				<mass>0.008727441849375963</mass>
				<inertia>
					<ixx>0.010162426172463936</ixx>
					<ixy>-0.0012049130980499247</ixy>
					<ixz>-0.00497539412198021</ixz>
					<iyy>0.004292014324158273</iyy>
					<iyz>-0.0009821728451054178</iyz>
					<izz>0.006347559401626066</izz>
				</inertia>
			</inertial>
			<collision name="index_right_link1_collision">
				<geometry>
					<mesh>
						<uri>model://rikshaw/meshes/CAD/index_right_link1.stl</uri>
						<scale>0.001 0.001 0.001</scale>
					</mesh>
				</geometry>
			</collision>
			<visual name="index_right_link1_visual">
				<geometry>
					<mesh>
						<uri>model://rikshaw/meshes/CAD/index_right_link1.stl</uri>
						<scale>0.001 0.001 0.001</scale>
					</mesh>
				</geometry>
			</visual>
		</link>
		<link name="thumb_right_link2">
			<self_collide>false</self_collide>
			<pose frame="">0.2195430165803426 0.7497177206373775 0.6922423387496061 0.0 -0.0 0.0</pose>
			<inertial>
				<pose frame="">0.0 0.0 0.0 0 0 0</pose>
				<mass>0.007230558586521256</mass>
				<inertia>
					<ixx>0.007529565126577462</ixx>
					<ixy>-0.0011902855020857258</ixy>
					<ixz>-0.0037524150229174126</ixz>
					<iyy>0.0038140681793013254</iyy>
					<iyz>-0.0010986943575693965</iyz>
					<izz>0.004413301222077684</izz>
				</inertia>
			</inertial>
			<collision name="thumb_right_link2_collision">
				<geometry>
					<mesh>
						<uri>model://rikshaw/meshes/CAD/thumb_right_link2.stl</uri>
						<scale>0.001 0.001 0.001</scale>
					</mesh>
				</geometry>
			</collision>
			<visual name="thumb_right_link2_visual">
				<geometry>
					<mesh>
						<uri>model://rikshaw/meshes/CAD/thumb_right_link2.stl</uri>
						<scale>0.001 0.001 0.001</scale>
					</mesh>
				</geometry>
			</visual>
		</link>
		<link name="thumb_right_link0">
			<self_collide>false</self_collide>
			<pose frame="">0.20241947586468978 0.7099355347918156 0.7274217573851316 0.0 -0.0 0.0</pose>
			<inertial>
				<pose frame="">0.0 0.0 0.0 0 0 0</pose>
				<mass>0.010783131534927236</mass>
				<inertia>
					<ixx>0.011142002558176154</ixx>
					<ixy>-0.001550241899037904</ixy>
					<ixz>-0.005568115940637139</ixz>
					<iyy>0.006149426938912064</iyy>
					<iyz>-0.0015871353634802543</iyz>
					<izz>0.00587849323091298</izz>
				</inertia>
			</inertial>
			<collision name="thumb_right_link0_collision">
				<geometry>
					<mesh>
						<uri>model://rikshaw/meshes/CAD/thumb_right_link0.stl</uri>
						<scale>0.001 0.001 0.001</scale>
					</mesh>
				</geometry>
			</collision>
			<visual name="thumb_right_link0_visual">
				<geometry>
					<mesh>
						<uri>model://rikshaw/meshes/CAD/thumb_right_link0.stl</uri>
						<scale>0.001 0.001 0.001</scale>
					</mesh>
				</geometry>
			</visual>
		</link>
		<link name="thumb_right_link1">
			<self_collide>false</self_collide>
			<pose frame="">0.21343805092525256 0.7318152578247713 0.7082264894633125 0.0 -0.0 0.0</pose>
			<inertial>
				<pose frame="">0.0 0.0 0.0 0 0 0</pose>
				<mass>0.008726839160214994</mass>
				<inertia>
					<ixx>0.009051747565890505</ixx>
					<ixy>-0.0013635009423986735</ixy>
					<ixz>-0.004522768730971857</ixz>
					<iyy>0.004776043937501841</iyy>
					<iyz>-0.0013187908359639123</iyz>
					<izz>0.005072526532214788</izz>
				</inertia>
			</inertial>
			<collision name="thumb_right_link1_collision">
				<geometry>
					<mesh>
						<uri>model://rikshaw/meshes/CAD/thumb_right_link1.stl</uri>
						<scale>0.001 0.001 0.001</scale>
					</mesh>
				</geometry>
			</collision>
			<visual name="thumb_right_link1_visual">
				<geometry>
					<mesh>
						<uri>model://rikshaw/meshes/CAD/thumb_right_link1.stl</uri>
						<scale>0.001 0.001 0.001</scale>
					</mesh>
				</geometry>
			</visual>
		</link>
		<link name="wrist_right_sphere_link1">
			<self_collide>false</self_collide>
			<pose frame="">0.23848604705855894 0.6799865821863746 0.8140339724919676 0.0 -0.0 0.0</pose>
			<inertial>
				<pose frame="">0.0 0.0 0.0 0 0 0</pose>
				<mass>0.06978897865508384</mass>
				<inertia>
					<ixx>0.07852655514875412</ixx>
					<ixy>-0.011317491086956394</ixy>
					<ixz>-0.0386304454073032</ixz>
					<iyy>0.05022669496166983</iyy>
					<iyz>-0.01354853531311649</iyz>
					<izz>0.0362500867874966</izz>
				</inertia>
			</inertial>
			<collision name="wrist_right_sphere_link1_collision">
				<geometry>
					<mesh>
						<uri>model://rikshaw/meshes/CAD/wrist_right_sphere_link1.stl</uri>
						<scale>0.001 0.001 0.001</scale>
					</mesh>
				</geometry>
			</collision>
			<visual name="wrist_right_sphere_link1_visual">
				<geometry>
					<mesh>
						<uri>model://rikshaw/meshes/CAD/wrist_right_sphere_link1.stl</uri>
						<scale>0.001 0.001 0.001</scale>
					</mesh>
				</geometry>
			</visual>
		</link>
		<link name="wrist_right_sphere_link2">
			<self_collide>false</self_collide>
			<pose frame="">0.2384860166047287 0.6799875983759012 0.8140339643290095 0.0 -0.0 0.0</pose>
			<inertial>
				<pose frame="">0.0 0.0 0.0 0 0 0</pose>
				<mass>0.0467775497412831</mass>
				<inertia>
					<ixx>0.05263161457519681</ixx>
					<ixy>-0.007585799881420901</ixy>
					<ixz>-0.02589291745967604</ixz>
					<iyy>0.03366296563526608</iyy>
					<iyz>-0.009081193183496273</iyz>
					<izz>0.024294910939130866</izz>
				</inertia>
			</inertial>
			<collision name="wrist_right_sphere_link2_collision">
				<geometry>
					<mesh>
						<uri>model://rikshaw/meshes/CAD/wrist_right_sphere_link2.stl</uri>
						<scale>0.001 0.001 0.001</scale>
					</mesh>
				</geometry>
			</collision>
			<visual name="wrist_right_sphere_link2_visual">
				<geometry>
					<mesh>
						<uri>model://rikshaw/meshes/CAD/wrist_right_sphere_link2.stl</uri>
						<scale>0.001 0.001 0.001</scale>
					</mesh>
				</geometry>
			</visual>
		</link>
		<link name="palm_right">
			<self_collide>false</self_collide>
			<pose frame="">0.2349635944464265 0.7248068355318789 0.7755235140776628 0.0 -0.0 0.0</pose>
			<inertial>
				<pose frame="">0.0 0.0 0.0 0 0 0</pose>
				<mass>0.41273188866593385</mass>
				<inertia>
					<ixx>0.4659944484740799</ixx>
					<ixy>-0.07017151633840833</ixy>
					<ixz>-0.2315980652230987</ixz>
					<iyy>0.27173072537241216</iyy>
					<iyz>-0.07532376897936786</iyz>
					<izz>0.2403980958320139</izz>
				</inertia>
			</inertial>
			<collision name="palm_right_collision">
				<geometry>
					<mesh>
						<uri>model://rikshaw/meshes/CAD/palm_right.stl</uri>
						<scale>0.001 0.001 0.001</scale>
					</mesh>
				</geometry>
			</collision>
			<visual name="palm_right_visual">
				<geometry>
					<mesh>
						<uri>model://rikshaw/meshes/CAD/palm_right.stl</uri>
						<scale>0.001 0.001 0.001</scale>
					</mesh>
				</geometry>
			</visual>
		</link>
		<link name="little_left_link2">
			<self_collide>false</self_collide>
			<pose frame="">0.1527022528822468 -0.8824425373256056 0.6745100154002251 0.0 -0.0 0.0</pose>
			<inertial>
				<pose frame="">0.0 0.0 0.0 0 0 0</pose>
				<mass>0.007230544692585402</mass>
				<inertia>
					<ixx>0.008920880258361583</ixx>
					<ixy>0.0009743736267820488</ixy>
					<ixz>0.004303486641826472</ixz>
					<iyy>0.0034587316347614457</iyy>
					<iyz>-0.0007447000804050939</iyz>
					<izz>0.005799688502855049</izz>
				</inertia>
			</inertial>
			<collision name="little_left_link2_collision">
				<geometry>
					<mesh>
						<uri>model://rikshaw/meshes/CAD/little_left_link2.stl</uri>
						<scale>0.001 0.001 0.001</scale>
					</mesh>
				</geometry>
			</collision>
			<visual name="little_left_link2_visual">
				<geometry>
					<mesh>
						<uri>model://rikshaw/meshes/CAD/little_left_link2.stl</uri>
						<scale>0.001 0.001 0.001</scale>
					</mesh>
				</geometry>
			</visual>
		</link>
		<link name="little_left_link0">
			<self_collide>false</self_collide>
			<pose frame="">0.17020676141301394 -0.8416420046085294 0.7083087992453713 0.0 -0.0 0.0</pose>
			<inertial>
				<pose frame="">0.0 0.0 0.0 0 0 0</pose>
				<mass>0.010783173954625098</mass>
				<inertia>
					<ixx>0.013050537947837957</ixx>
					<ixy>0.0015448938998691203</ixy>
					<ixz>0.006427369765599661</ixz>
					<iyy>0.005723599934643548</iyy>
					<iyz>-0.001299861202817692</iyz>
					<izz>0.007952348786091058</izz>
				</inertia>
			</inertial>
			<collision name="little_left_link0_collision">
				<geometry>
					<mesh>
						<uri>model://rikshaw/meshes/CAD/little_left_link0.stl</uri>
						<scale>0.001 0.001 0.001</scale>
					</mesh>
				</geometry>
			</collision>
			<visual name="little_left_link0_visual">
				<geometry>
					<mesh>
						<uri>model://rikshaw/meshes/CAD/little_left_link0.stl</uri>
						<scale>0.001 0.001 0.001</scale>
					</mesh>
				</geometry>
			</visual>
		</link>
		<link name="little_left_link1">
			<self_collide>false</self_collide>
			<pose frame="">0.16191868291951 -0.8645929374420694 0.6889924199397375 0.0 -0.0 0.0</pose>
			<inertial>
				<pose frame="">0.0 0.0 0.0 0 0 0</pose>
				<mass>0.008727381894054248</mass>
				<inertia>
					<ixx>0.010668270119737738</ixx>
					<ixy>0.0012219684355427216</ixy>
					<ixz>0.0051983250610510125</ixz>
					<iyy>0.004372675337793752</iyy>
					<iyz>-0.0009734704573553792</iyz>
					<izz>0.0067537630870727235</izz>
				</inertia>
			</inertial>
			<collision name="little_left_link1_collision">
				<geometry>
					<mesh>
						<uri>model://rikshaw/meshes/CAD/little_left_link1.stl</uri>
						<scale>0.001 0.001 0.001</scale>
					</mesh>
				</geometry>
			</collision>
			<visual name="little_left_link1_visual">
				<geometry>
					<mesh>
						<uri>model://rikshaw/meshes/CAD/little_left_link1.stl</uri>
						<scale>0.001 0.001 0.001</scale>
					</mesh>
				</geometry>
			</visual>
		</link>
		<link name="ring_left_link2">
			<self_collide>false</self_collide>
			<pose frame="">0.1913598966491293 -0.8880035284468629 0.6679409872183222 0.0 -0.0 0.0</pose>
			<inertial>
				<pose frame="">0.0 0.0 0.0 0 0 0</pose>
				<mass>0.007230598064083806</mass>
				<inertia>
					<ixx>0.008928347943888085</ixx>
					<ixy>0.0012287783920687059</ixy>
					<ixz>0.0042884722257512725</ixz>
					<iyy>0.0034911807104839997</iyy>
					<iyz>-0.0009241193018912809</iyz>
					<izz>0.005967098279851658</izz>
				</inertia>
			</inertial>
			<collision name="ring_left_link2_collision">
				<geometry>
					<mesh>
						<uri>model://rikshaw/meshes/CAD/ring_left_link2.stl</uri>
						<scale>0.001 0.001 0.001</scale>
					</mesh>
				</geometry>
			</collision>
			<visual name="ring_left_link2_visual">
				<geometry>
					<mesh>
						<uri>model://rikshaw/meshes/CAD/ring_left_link2.stl</uri>
						<scale>0.001 0.001 0.001</scale>
					</mesh>
				</geometry>
			</visual>
		</link>
		<link name="ring_left_link0">
			<self_collide>false</self_collide>
			<pose frame="">0.20228202777025925 -0.8460328999893737 0.7030496477195615 0.0 -0.0 0.0</pose>
			<inertial>
				<pose frame="">0.0 0.0 0.0 0 0 0</pose>
				<mass>0.01078319636299043</mass>
				<inertia>
					<ixx>0.013050353856718076</ixx>
					<ixy>0.0018457311875845475</ixy>
					<ixz>0.006412979579479117</ixz>
					<iyy>0.005772461258785232</iyy>
					<iyz>-0.0015332437248958364</iyz>
					<izz>0.008161133515715705</izz>
				</inertia>
			</inertial>
			<collision name="ring_left_link0_collision">
				<geometry>
					<mesh>
						<uri>model://rikshaw/meshes/CAD/ring_left_link0.stl</uri>
						<scale>0.001 0.001 0.001</scale>
					</mesh>
				</geometry>
			</collision>
			<visual name="ring_left_link0_visual">
				<geometry>
					<mesh>
						<uri>model://rikshaw/meshes/CAD/ring_left_link0.stl</uri>
						<scale>0.001 0.001 0.001</scale>
					</mesh>
				</geometry>
			</visual>
		</link>
		<link name="ring_left_link1">
			<self_collide>false</self_collide>
			<pose frame="">0.1977091246517408 -0.8694958098327338 0.6831211857189616 0.0 -0.0 0.0</pose>
			<inertial>
				<pose frame="">0.0 0.0 0.0 0 0 0</pose>
				<mass>0.008727381460149852</mass>
				<inertia>
					<ixx>0.0106720870988414</ixx>
					<ixy>0.001500573385804876</ixy>
					<ixz>0.005183289283126989</ixz>
					<iyy>0.00441474733162996</iyy>
					<iyz>-0.0011784768980072368</iyz>
					<izz>0.006940322536460743</izz>
				</inertia>
			</inertial>
			<collision name="ring_left_link1_collision">
				<geometry>
					<mesh>
						<uri>model://rikshaw/meshes/CAD/ring_left_link1.stl</uri>
						<scale>0.001 0.001 0.001</scale>
					</mesh>
				</geometry>
			</collision>
			<visual name="ring_left_link1_visual">
				<geometry>
					<mesh>
						<uri>model://rikshaw/meshes/CAD/ring_left_link1.stl</uri>
						<scale>0.001 0.001 0.001</scale>
					</mesh>
				</geometry>
			</visual>
		</link>
		<link name="middle_left_link2">
			<self_collide>false</self_collide>
			<pose frame="">0.2228839511342991 -0.8897754687089438 0.6645574347612028 0.0 -0.0 0.0</pose>
			<inertial>
				<pose frame="">0.0 0.0 0.0 0 0 0</pose>
				<mass>0.007230534463346676</mass>
				<inertia>
					<ixx>0.008918428027545364</ixx>
					<ixy>0.001434054012472262</ixy>
					<ixz>0.004275232975691135</ixz>
					<iyy>0.003552984068267793</iyy>
					<iyz>-0.0010708879374729916</iyz>
					<izz>0.006084250285497725</izz>
				</inertia>
			</inertial>
			<collision name="middle_left_link2_collision">
				<geometry>
					<mesh>
						<uri>model://rikshaw/meshes/CAD/middle_left_link2.stl</uri>
						<scale>0.001 0.001 0.001</scale>
					</mesh>
				</geometry>
			</collision>
			<visual name="middle_left_link2_visual">
				<geometry>
					<mesh>
						<uri>model://rikshaw/meshes/CAD/middle_left_link2.stl</uri>
						<scale>0.001 0.001 0.001</scale>
					</mesh>
				</geometry>
			</visual>
		</link>
		<link name="middle_left_link0">
			<self_collide>false</self_collide>
			<pose frame="">0.22996515461799877 -0.8474152059522435 0.7001791161204252 0.0 -0.0 0.0</pose>
			<inertial>
				<pose frame="">0.0 0.0 0.0 0 0 0</pose>
				<mass>0.010783098914055156</mass>
				<inertia>
					<ixx>0.013031975769836177</ixx>
					<ixy>0.002101771045467862</ixy>
					<ixz>0.006397203441008441</ixz>
					<iyy>0.005858047706991271</iyy>
					<iyz>-0.0017359086798026798</iyz>
					<izz>0.008315355985877862</izz>
				</inertia>
			</inertial>
			<collision name="middle_left_link0_collision">
				<geometry>
					<mesh>
						<uri>model://rikshaw/meshes/CAD/middle_left_link0.stl</uri>
						<scale>0.001 0.001 0.001</scale>
					</mesh>
				</geometry>
			</collision>
			<visual name="middle_left_link0_visual">
				<geometry>
					<mesh>
						<uri>model://rikshaw/meshes/CAD/middle_left_link0.stl</uri>
						<scale>0.001 0.001 0.001</scale>
					</mesh>
				</geometry>
			</visual>
		</link>
		<link name="middle_left_link1">
			<self_collide>false</self_collide>
			<pose frame="">0.22754934374608804 -0.8710137185041562 0.6800339221592827 0.0 -0.0 0.0</pose>
			<inertial>
				<pose frame="">0.0 0.0 0.0 0 0 0</pose>
				<mass>0.008727362475596008</mass>
				<inertia>
					<ixx>0.010658338230062873</ixx>
					<ixy>0.0017300647056782534</ixy>
					<ixz>0.005168885794635883</ixz>
					<iyy>0.004488791514126455</iyy>
					<iyz>-0.0013502093617883272</iyz>
					<izz>0.007074133817852468</izz>
				</inertia>
			</inertial>
			<collision name="middle_left_link1_collision">
				<geometry>
					<mesh>
						<uri>model://rikshaw/meshes/CAD/middle_left_link1.stl</uri>
						<scale>0.001 0.001 0.001</scale>
					</mesh>
				</geometry>
			</collision>
			<visual name="middle_left_link1_visual">
				<geometry>
					<mesh>
						<uri>model://rikshaw/meshes/CAD/middle_left_link1.stl</uri>
						<scale>0.001 0.001 0.001</scale>
					</mesh>
				</geometry>
			</visual>
		</link>
		<link name="index_left_link2">
			<self_collide>false</self_collide>
			<pose frame="">0.2610470175686598 -0.8837182251165928 0.6679724360252719 0.0 -0.0 0.0</pose>
			<inertial>
				<pose frame="">0.0 0.0 0.0 0 0 0</pose>
				<mass>0.007230503768900909</mass>
				<inertia>
					<ixx>0.008873590522653468</ixx>
					<ixy>0.0016681634092363144</ixy>
					<ixz>0.004267944140816451</ixz>
					<iyy>0.003719425898373414</iyy>
					<iyz>-0.0012606859497717002</iyz>
					<izz>0.006140096258693527</izz>
				</inertia>
			</inertial>
			<collision name="index_left_link2_collision">
				<geometry>
					<mesh>
						<uri>model://rikshaw/meshes/CAD/index_left_link2.stl</uri>
						<scale>0.001 0.001 0.001</scale>
					</mesh>
				</geometry>
			</collision>
			<visual name="index_left_link2_visual">
				<geometry>
					<mesh>
						<uri>model://rikshaw/meshes/CAD/index_left_link2.stl</uri>
						<scale>0.001 0.001 0.001</scale>
					</mesh>
				</geometry>
			</visual>
		</link>
		<link name="index_left_link0">
			<self_collide>false</self_collide>
			<pose frame="">0.26328063424698317 -0.8411599444575804 0.7039898022328486 0.0 -0.0 0.0</pose>
			<inertial>
				<pose frame="">0.0 0.0 0.0 0 0 0</pose>
				<mass>0.01078315363645507</mass>
				<inertia>
					<ixx>0.0129757401236309</ixx>
					<ixy>0.002388541236316474</ixy>
					<ixz>0.0063846227873153825</ixz>
					<iyy>0.0060930376728418065</iyy>
					<iyz>-0.0019981937422370736</iyz>
					<izz>0.00837873716964178</izz>
				</inertia>
			</inertial>
			<collision name="index_left_link0_collision">
				<geometry>
					<mesh>
						<uri>model://rikshaw/meshes/CAD/index_left_link0.stl</uri>
						<scale>0.001 0.001 0.001</scale>
					</mesh>
				</geometry>
			</collision>
			<visual name="index_left_link0_visual">
				<geometry>
					<mesh>
						<uri>model://rikshaw/meshes/CAD/index_left_link0.stl</uri>
						<scale>0.001 0.001 0.001</scale>
					</mesh>
				</geometry>
			</visual>
		</link>
		<link name="index_left_link1">
			<self_collide>false</self_collide>
			<pose frame="">0.2635765816290412 -0.8647663480999566 0.6837114504594517 0.0 -0.0 0.0</pose>
			<inertial>
				<pose frame="">0.0 0.0 0.0 0 0 0</pose>
				<mass>0.008727346342048834</mass>
				<inertia>
					<ixx>0.010607370368679802</ixx>
					<ixy>0.0019895981922273785</ixy>
					<ixz>0.005159591614657695</ixz>
					<iyy>0.004687020948416652</iyy>
					<iyz>-0.001572445371030485</iyz>
					<izz>0.007133932177059939</izz>
				</inertia>
			</inertial>
			<collision name="index_left_link1_collision">
				<geometry>
					<mesh>
						<uri>model://rikshaw/meshes/CAD/index_left_link1.stl</uri>
						<scale>0.001 0.001 0.001</scale>
					</mesh>
				</geometry>
			</collision>
			<visual name="index_left_link1_visual">
				<geometry>
					<mesh>
						<uri>model://rikshaw/meshes/CAD/index_left_link1.stl</uri>
						<scale>0.001 0.001 0.001</scale>
					</mesh>
				</geometry>
			</visual>
		</link>
		<link name="thumb_left_link2">
			<self_collide>false</self_collide>
			<pose frame="">0.22654793338357976 -0.775539322371942 0.7011389473389591 0.0 -0.0 0.0</pose>
			<inertial>
				<pose frame="">0.0 0.0 0.0 0 0 0</pose>
				<mass>0.00723049056417055</mass>
				<inertia>
					<ixx>0.007904131551100648</ixx>
					<ixy>0.0012703680949582837</ixy>
					<ixz>0.003931393372166253</ixz>
					<iyy>0.003926120843353529</iyy>
					<iyz>-0.001148507006648317</iyz>
					<izz>0.004720525292561911</izz>
				</inertia>
			</inertial>
			<collision name="thumb_left_link2_collision">
				<geometry>
					<mesh>
						<uri>model://rikshaw/meshes/CAD/thumb_left_link2.stl</uri>
						<scale>0.001 0.001 0.001</scale>
					</mesh>
				</geometry>
			</collision>
			<visual name="thumb_left_link2_visual">
				<geometry>
					<mesh>
						<uri>model://rikshaw/meshes/CAD/thumb_left_link2.stl</uri>
						<scale>0.001 0.001 0.001</scale>
					</mesh>
				</geometry>
			</visual>
		</link>
		<link name="thumb_left_link0">
			<self_collide>false</self_collide>
			<pose frame="">0.20303953249677834 -0.7378091852681823 0.7348614073940793 0.0 -0.0 0.0</pose>
			<inertial>
				<pose frame="">0.0 0.0 0.0 0 0 0</pose>
				<mass>0.010783039116982735</mass>
				<inertia>
					<ixx>0.01169520211112829</ixx>
					<ixy>0.0016153324035202534</ixy>
					<ixz>0.005845475018461105</ixz>
					<iyy>0.006268874743371903</iyy>
					<iyz>-0.001608904130526376</iyz>
					<izz>0.006315959812178764</izz>
				</inertia>
			</inertial>
			<collision name="thumb_left_link0_collision">
				<geometry>
					<mesh>
						<uri>model://rikshaw/meshes/CAD/thumb_left_link0.stl</uri>
						<scale>0.001 0.001 0.001</scale>
					</mesh>
				</geometry>
			</collision>
			<visual name="thumb_left_link0_visual">
				<geometry>
					<mesh>
						<uri>model://rikshaw/meshes/CAD/thumb_left_link0.stl</uri>
						<scale>0.001 0.001 0.001</scale>
					</mesh>
				</geometry>
			</visual>
		</link>
		<link name="thumb_left_link1">
			<self_collide>false</self_collide>
			<pose frame="">0.21473820979735841 -0.7594691385774748 0.7158210317963688 0.0 -0.0 0.0</pose>
			<inertial>
				<pose frame="">0.0 0.0 0.0 0 0 0</pose>
				<mass>0.00872735081798693</mass>
				<inertia>
					<ixx>0.009507203688669103</ixx>
					<ixy>0.0014232195177277813</ixy>
					<ixz>0.004743991528645309</ixz>
					<iyy>0.004875188349125673</iyy>
					<iyz>-0.0013416019875791862</iyz>
					<izz>0.005437352140995431</izz>
				</inertia>
			</inertial>
			<collision name="thumb_left_link1_collision">
				<geometry>
					<mesh>
						<uri>model://rikshaw/meshes/CAD/thumb_left_link1.stl</uri>
						<scale>0.001 0.001 0.001</scale>
					</mesh>
				</geometry>
			</collision>
			<visual name="thumb_left_link1_visual">
				<geometry>
					<mesh>
						<uri>model://rikshaw/meshes/CAD/thumb_left_link1.stl</uri>
						<scale>0.001 0.001 0.001</scale>
					</mesh>
				</geometry>
			</visual>
		</link>
		<link name="wrist_left_sphere_link1">
			<self_collide>false</self_collide>
			<pose frame="">0.23753243034048546 -0.7083637172932641 0.8211146532900278 0.0 -0.0 0.0</pose>
			<inertial>
				<pose frame="">0.0 0.0 0.0 0 0 0</pose>
				<mass>0.06978284193312742</mass>
				<inertia>
					<ixx>0.08207685574030728</ixx>
					<ixy>0.011741615977790195</ixy>
					<ixz>0.04058903845103665</ixz>
					<iyy>0.05099854561667496</iyy>
					<iyz>-0.013610540338370846</iyz>
					<izz>0.03896448438178479</izz>
				</inertia>
			</inertial>
			<collision name="wrist_left_sphere_link1_collision">
				<geometry>
					<mesh>
						<uri>model://rikshaw/meshes/CAD/wrist_left_sphere_link1.stl</uri>
						<scale>0.001 0.001 0.001</scale>
					</mesh>
				</geometry>
			</collision>
			<visual name="wrist_left_sphere_link1_visual">
				<geometry>
					<mesh>
						<uri>model://rikshaw/meshes/CAD/wrist_left_sphere_link1.stl</uri>
						<scale>0.001 0.001 0.001</scale>
					</mesh>
				</geometry>
			</visual>
		</link>
		<link name="wrist_left_sphere_link2">
			<self_collide>false</self_collide>
			<pose frame="">0.23753242114127976 -0.7083641031994964 0.8211146532961595 0.0 -0.0 0.0</pose>
			<inertial>
				<pose frame="">0.0 0.0 0.0 0 0 0</pose>
				<mass>0.04677754976643715</mass>
				<inertia>
					<ixx>0.05501607903754897</ixx>
					<ixy>0.007870764341958117</ixy>
					<ixz>0.027208075049578565</ixz>
					<iyy>0.03418332144432361</iyy>
					<iyz>-0.00912355653248001</iyz>
					<izz>0.026116552220382255</izz>
				</inertia>
			</inertial>
			<collision name="wrist_left_sphere_link2_collision">
				<geometry>
					<mesh>
						<uri>model://rikshaw/meshes/CAD/wrist_left_sphere_link2.stl</uri>
						<scale>0.001 0.001 0.001</scale>
					</mesh>
				</geometry>
			</collision>
			<visual name="wrist_left_sphere_link2_visual">
				<geometry>
					<mesh>
						<uri>model://rikshaw/meshes/CAD/wrist_left_sphere_link2.stl</uri>
						<scale>0.001 0.001 0.001</scale>
					</mesh>
				</geometry>
			</visual>
		</link>
		<link name="palm_left">
			<self_collide>false</self_collide>
			<pose frame="">0.23430678166939548 -0.7510747867492498 0.7815593046106248 0.0 -0.0 0.0</pose>
			<inertial>
				<pose frame="">0.0 0.0 0.0 0 0 0</pose>
				<mass>0.4014213812126051</mass>
				<inertia>
					<ixx>0.4725658096435884</ixx>
					<ixy>0.0705315706118846</ixy>
					<ixz>0.23525005817609446</ixz>
					<iyy>0.2679013471323959</iyy>
					<iyz>-0.07361068126203199</iyz>
					<izz>0.24928388635951798</izz>
				</inertia>
			</inertial>
			<collision name="palm_left_collision">
				<geometry>
					<mesh>
						<uri>model://rikshaw/meshes/CAD/palm_left.stl</uri>
						<scale>0.001 0.001 0.001</scale>
					</mesh>
				</geometry>
			</collision>
			<visual name="palm_left_visual">
				<geometry>
					<mesh>
						<uri>model://rikshaw/meshes/CAD/palm_left.stl</uri>
						<scale>0.001 0.001 0.001</scale>
					</mesh>
				</geometry>
			</visual>
		</link>
		<joint name="joint_hip_left" type="revolute">
			<parent>bike</parent>
			<child>thigh_left</child>
			<pose frame="">-0.004772293722202186 0.010555749497587285 0.11112120503857874 0 0 0</pose>
			<axis>
				<xyz>4.713567773490396e-12 -0.9999999999999998 -4.747094653015647e-10</xyz>
				<limit>
					<lower>-3.141592653589793</lower>
					<upper>3.141592653589793</upper>
				</limit>
				<use_parent_model_frame>0</use_parent_model_frame>
			</axis>
		</joint>
		<joint name="joint_pedal_right" type="revolute">
			<parent>kurbel</parent>
			<child>pedal_right</child>
			<pose frame="">-4.220983134520573e-05 0.042000000000000405 -6.592456775077693e-05 0 0 0</pose>
			<axis>
				<xyz>-5.847985275656098e-16 1.0000000000000007 -1.5799660158833414e-15</xyz>
				<limit>
					<lower>-3.141592653589793</lower>
					<upper>3.141592653589793</upper>
				</limit>
				<use_parent_model_frame>0</use_parent_model_frame>
			</axis>
		</joint>
		<joint name="joint_pedal_left" type="revolute">
			<parent>kurbel</parent>
			<child>pedal_left</child>
			<pose frame="">-5.301625021756351e-05 -0.04199999999999946 5.759336515112068e-05 0 0 0</pose>
			<axis>
				<xyz>5.847985275656082e-16 -1.0 1.5799660158833548e-15</xyz>
				<limit>
					<lower>-3.141592653589793</lower>
					<upper>3.141592653589793</upper>
				</limit>
				<use_parent_model_frame>0</use_parent_model_frame>
			</axis>
		</joint>
		<joint name="joint_wheel_right" type="revolute">
			<parent>front_part</parent>
			<child>right_wheel</child>
			<pose frame="">5.684341886080802e-16 -0.003999653375198307 5.577760475716787e-15 0 0 0</pose>
			<axis>
				<xyz>-3.1662288285727846e-30 0.9999999999999998 4.317059530368991e-14</xyz>
				<limit>
					<lower>-3.141592653589793</lower>
					<upper>3.141592653589793</upper>
				</limit>
				<use_parent_model_frame>0</use_parent_model_frame>
			</axis>
		</joint>
		<joint name="joint_wheel_back" type="revolute">
			<parent>bike</parent>
			<child>wheel_back</child>
			<pose frame="">-1.4210854715202004e-16 -0.0689996533751975 2.1316282072803005e-16 0 0 0</pose>
			<axis>
				<xyz>6.938893903907228e-17 -1.0 1.27675647831893e-15</xyz>
				<limit>
					<lower>-3.141592653589793</lower>
					<upper>3.141592653589793</upper>
				</limit>
				<use_parent_model_frame>0</use_parent_model_frame>
			</axis>
		</joint>
		<joint name="joint_pedal" type="revolute">
			<parent>bike</parent>
			<child>kurbel</child>
			<pose frame="">0.0002782913867391912 -0.035131649555820536 -0.0010093313481022886 0 0 0</pose>
			<axis>
				<xyz>-6.938893903907228e-17 1.0 -1.27675647831893e-15</xyz>
				<limit>
					<lower>-3.141592653589793</lower>
					<upper>3.141592653589793</upper>
				</limit>
				<use_parent_model_frame>0</use_parent_model_frame>
			</axis>
		</joint>
		<joint name="spine_joint" type="revolute">
			<parent>bike</parent>
			<child>torso</child>
			<pose frame="">0.020608468146441475 0.002662439688556928 -0.4438862707348987 0 0 0</pose>
			<axis>
				<xyz>0.01953591123167811 4.747112516936242e-10 -0.9998091558754337</xyz>
				<limit>
					<lower>-0.5235987755982988</lower>
					<upper>0.5235987755982988</upper>
				</limit>
				<use_parent_model_frame>0</use_parent_model_frame>
			</axis>
		</joint>
		<joint name="joint_wheel_left" type="revolute">
			<parent>front_part</parent>
			<child>left_wheel</child>
			<pose frame="">5.684341886080802e-16 0.04600034662480173 7.638334409421077e-15 0 0 0</pose>
			<axis>
				<xyz>3.1662288285727846e-30 -0.9999999999999998 -4.317059530368991e-14</xyz>
				<limit>
					<lower>-3.141592653589793</lower>
					<upper>3.141592653589793</upper>
				</limit>
				<use_parent_model_frame>0</use_parent_model_frame>
			</axis>
		</joint>
		<joint name="joint_front" type="revolute">
			<parent>bike</parent>
			<child>front_part</child>
			<pose frame="">-0.23003546880974085 -0.010388308215364166 -0.2052706960113988 0 0 0</pose>
			<axis>
				<xyz>5.345642609144017e-16 -4.084397910750052e-14 1.0</xyz>
				<limit>
					<lower>-0.5235987755982988</lower>
					<upper>0.5235987755982988</upper>
				</limit>
				<use_parent_model_frame>0</use_parent_model_frame>
			</axis>
		</joint>
		<joint name="elbow_left" type="revolute">
			<parent>upper_arm_left</parent>
			<child>lower_arm_left</child>
			<pose frame="">-0.004866469492249408 0.09466304244122839 0.09457325094477369 0 0 0</pose>
			<axis>
				<xyz>0.03535217944532111 -0.650481321836088 0.7586990663964489</xyz>
				<limit>
					<lower>-1.221730476396031</lower>
					<upper>0.0</upper>
				</limit>
				<use_parent_model_frame>0</use_parent_model_frame>
			</axis>
		</joint>
		<joint name="elbow_right" type="revolute">
			<parent>upper_arm_right</parent>
			<child>lower_arm_right</child>
			<pose frame="">0.00927077944815654 -0.10974391577254544 0.08022562625910921 0 0 0</pose>
			<axis>
				<xyz>-0.03518693302123469 -0.6493794478502403 -0.7596500592077103</xyz>
				<limit>
					<lower>-1.221730476396031</lower>
					<upper>0.0</upper>
				</limit>
				<use_parent_model_frame>0</use_parent_model_frame>
			</axis>
		</joint>
		<joint name="little_right_joint0" type="revolute">
			<parent>palm_right</parent>
			<child>little_right_link0</child>
			<pose frame="">0.008296971379913707 -0.013873061345971962 0.011076615573679192 0 0 0</pose>
			<axis>
				<xyz>-0.999185730289981 0.03777716328458339 0.014169062038204639</xyz>
				<limit>
					<lower>0.0</lower>
					<upper>0.0</upper>
				</limit>
				<use_parent_model_frame>0</use_parent_model_frame>
			</axis>
		</joint>
		<joint name="ring_right_joint0" type="revolute">
			<parent>palm_right</parent>
			<child>ring_right_link0</child>
			<pose frame="">0.009928761325575053 -0.013256836224033605 0.010472221902896308 0 0 0</pose>
			<axis>
				<xyz>-0.9965812248848281 -0.03377938338290869 0.07539771525267164</xyz>
				<limit>
					<lower>0.0</lower>
					<upper>0.0</upper>
				</limit>
				<use_parent_model_frame>0</use_parent_model_frame>
			</axis>
		</joint>
		<joint name="middle_right_joint0" type="revolute">
			<parent>palm_right</parent>
			<child>middle_right_link0</child>
			<pose frame="">0.01096836230888833 -0.012781397617544172 0.010016163618993375 0 0 0</pose>
			<axis>
				<xyz>-0.9899259309590018 -0.0813563351408041 0.11587837566779582</xyz>
				<limit>
					<lower>0.0</lower>
					<upper>0.0</upper>
				</limit>
				<use_parent_model_frame>0</use_parent_model_frame>
			</axis>
		</joint>
		<joint name="index_right_joint0" type="revolute">
			<parent>palm_right</parent>
			<child>index_right_link0</child>
			<pose frame="">0.01286234915171569 -0.011716712160467609 0.009015080810856802 0 0 0</pose>
			<axis>
				<xyz>-0.9658386796997146 -0.17277984858019002 0.19313924697097476</xyz>
				<limit>
					<lower>0.0</lower>
					<upper>0.0</upper>
				</limit>
				<use_parent_model_frame>0</use_parent_model_frame>
			</axis>
		</joint>
		<joint name="thumb_right_joint0" type="revolute">
			<parent>palm_right</parent>
			<child>thumb_right_link0</child>
			<pose frame="">-0.014457615150512382 -0.009486994703732422 0.00921796007900312 0 0 0</pose>
			<axis>
				<xyz>0.9303407514815806 -0.29908302356210714 0.21216840280690452</xyz>
				<limit>
					<lower>0.0</lower>
					<upper>0.0</upper>
				</limit>
				<use_parent_model_frame>0</use_parent_model_frame>
			</axis>
		</joint>
		<joint name="little_right_joint1" type="revolute">
			<parent>little_right_link0</parent>
			<child>little_right_link1</child>
			<pose frame="">0.008004621004631254 -0.011018422836367137 0.00866805135631239 0 0 0</pose>
			<axis>
				<xyz>-0.9991857302899829 0.03777716328458346 0.01416906203820477</xyz>
				<limit>
					<lower>0.0</lower>
					<upper>0.0</upper>
				</limit>
				<use_parent_model_frame>0</use_parent_model_frame>
			</axis>
		</joint>
		<joint name="little_right_joint2" type="revolute">
			<parent>little_right_link1</parent>
			<child>little_right_link2</child>
			<pose frame="">0.005338037811606498 -0.009267948872275014 0.006899745822374684 0 0 0</pose>
			<axis>
				<xyz>-0.9991857302899813 0.037777163284583366 0.01416906203820481</xyz>
				<limit>
					<lower>0.0</lower>
					<upper>0.0</upper>
				</limit>
				<use_parent_model_frame>0</use_parent_model_frame>
			</axis>
		</joint>
		<joint name="ring_right_joint1" type="revolute">
			<parent>ring_right_link0</parent>
			<child>ring_right_link1</child>
			<pose frame="">0.00928634661594991 -0.01042766809896321 0.008101788820116411 0 0 0</pose>
			<axis>
				<xyz>-0.9965812248848287 -0.03377938338290934 0.0753977152526714</xyz>
				<limit>
					<lower>0.0</lower>
					<upper>0.0</upper>
				</limit>
				<use_parent_model_frame>0</use_parent_model_frame>
			</axis>
		</joint>
		<joint name="ring_right_joint2" type="revolute">
			<parent>ring_right_link1</parent>
			<child>ring_right_link2</child>
			<pose frame="">0.006398420731685128 -0.008870370558855143 0.006509479764146278 0 0 0</pose>
			<axis>
				<xyz>-0.9965812248848267 -0.033779383382909214 0.07539771525267128</xyz>
				<limit>
					<lower>0.0</lower>
					<upper>0.0</upper>
				</limit>
				<use_parent_model_frame>0</use_parent_model_frame>
			</axis>
		</joint>
		<joint name="middle_right_joint1" type="revolute">
			<parent>middle_right_link0</parent>
			<child>middle_right_link1</child>
			<pose frame="">0.010095668233527776 -0.009983092319431819 0.007682919198385179 0 0 0</pose>
			<axis>
				<xyz>-0.9899259309590029 -0.08135633514080493 0.11587837566779541</xyz>
				<limit>
					<lower>0.0</lower>
					<upper>0.0</upper>
				</limit>
				<use_parent_model_frame>0</use_parent_model_frame>
			</axis>
		</joint>
		<joint name="middle_right_joint2" type="revolute">
			<parent>middle_right_link1</parent>
			<child>middle_right_link2</child>
			<pose frame="">0.007074254096604271 -0.00856318658299827 0.006214552708587035 0 0 0</pose>
			<axis>
				<xyz>-0.9899259309590008 -0.08135633514080473 0.11587837566779519</xyz>
				<limit>
					<lower>0.0</lower>
					<upper>0.0</upper>
				</limit>
				<use_parent_model_frame>0</use_parent_model_frame>
			</axis>
		</joint>
		<joint name="index_right_joint1" type="revolute">
			<parent>index_right_link0</parent>
			<child>index_right_link1</child>
			<pose frame="">0.011552452062521255 -0.009009825280963214 0.006780593974199008 0 0 0</pose>
			<axis>
				<xyz>-0.9658386796997157 -0.17277984858019121 0.19313924697097398</xyz>
				<limit>
					<lower>0.0</lower>
					<upper>0.0</upper>
				</limit>
				<use_parent_model_frame>0</use_parent_model_frame>
			</axis>
		</joint>
		<joint name="index_right_joint2" type="revolute">
			<parent>index_right_link1</parent>
			<child>index_right_link2</child>
			<pose frame="">0.008305715093693813 -0.007875044181522383 0.00556721607343988 0 0 0</pose>
			<axis>
				<xyz>-0.9658386796997139 -0.1727798485801909 0.19313924697097354</xyz>
				<limit>
					<lower>0.0</lower>
					<upper>0.0</upper>
				</limit>
				<use_parent_model_frame>0</use_parent_model_frame>
			</axis>
		</joint>
		<joint name="thumb_right_joint1" type="revolute">
			<parent>thumb_right_link0</parent>
			<child>thumb_right_link1</child>
			<pose frame="">-0.012757722627659689 -0.007002958227170524 0.006988162959730318 0 0 0</pose>
			<axis>
				<xyz>0.9303407514815814 -0.29908302356210714 0.21216840280690513</xyz>
				<limit>
					<lower>0.0</lower>
					<upper>0.0</upper>
				</limit>
				<use_parent_model_frame>0</use_parent_model_frame>
			</axis>
		</joint>
		<joint name="thumb_right_joint2" type="revolute">
			<parent>thumb_right_link1</parent>
			<child>thumb_right_link2</child>
			<pose frame="">-0.009343536287220929 -0.0059208587461890266 0.006295928662484869 0 0 0</pose>
			<axis>
				<xyz>0.9303407514815796 -0.29908302356210664 0.2121684028069049</xyz>
				<limit>
					<lower>0.0</lower>
					<upper>0.0</upper>
				</limit>
				<use_parent_model_frame>0</use_parent_model_frame>
			</axis>
		</joint>
		<joint name="little_left_joint0" type="revolute">
			<parent>palm_left</parent>
			<child>little_left_link0</child>
			<pose frame="">-0.0038960492918171143 0.014702122215729646 0.012355577686201685 0 0 0</pose>
			<axis>
				<xyz>0.9663080757242779 -0.17142255416927965 -0.19199742371220438</xyz>
				<limit>
					<lower>0.0</lower>
					<upper>0.0</upper>
				</limit>
				<use_parent_model_frame>0</use_parent_model_frame>
			</axis>
		</joint>
		<joint name="ring_left_joint0" type="revolute">
			<parent>palm_left</parent>
			<child>ring_left_link0</child>
			<pose frame="">-0.006205923552755621 0.014180607751261221 0.012016063653604903 0 0 0</pose>
			<axis>
				<xyz>0.9901758132211792 -0.0799706758709044 -0.1147020048322089</xyz>
				<limit>
					<lower>0.0</lower>
					<upper>0.0</upper>
				</limit>
				<use_parent_model_frame>0</use_parent_model_frame>
			</axis>
		</joint>
		<joint name="middle_left_joint0" type="revolute">
			<parent>palm_left</parent>
			<child>middle_left_link0</child>
			<pose frame="">-0.007486633138271443 0.013788598677024026 0.01173970620373325 0 0 0</pose>
			<axis>
				<xyz>0.9972008124297198 -0.027088776645619574 -0.06969029967901205</xyz>
				<limit>
					<lower>0.0</lower>
					<upper>0.0</upper>
				</limit>
				<use_parent_model_frame>0</use_parent_model_frame>
			</axis>
		</joint>
		<joint name="index_left_joint0" type="revolute">
			<parent>palm_left</parent>
			<child>index_left_link0</child>
			<pose frame="">0.2542451167646977 -0.8279542304865437 0.7153019249802823 0 0 0</pose>
			<axis>
				<xyz>0.9991483720023661 0.0391689147079214 -0.012974083614126204</xyz>
				<limit>
					<lower>0.0</lower>
					<upper>0.0</upper>
				</limit>
				<use_parent_model_frame>0</use_parent_model_frame>
			</axis>
		</joint>
		<joint name="thumb_left_joint0" type="revolute">
			<parent>palm_left</parent>
			<child>thumb_left_link0</child>
			<pose frame="">0.20469039081526305 -0.7231451428554782 0.7477549254944496 0 0 0</pose>
			<axis>
				<xyz>-0.9303508207375801 -0.2988983516681708 -0.2123843820128083</xyz>
				<limit>
					<lower>0.0</lower>
					<upper>0.0</upper>
				</limit>
				<use_parent_model_frame>0</use_parent_model_frame>
			</axis>
		</joint>
		<joint name="wrist_right_sphere_axis0" type="revolute">
			<parent>lower_arm_right</parent>
			<child>wrist_right_sphere_link1</child>
			<pose frame="">7.587483352722302e-09 -3.346532007242331e-07 -8.128860287115459e-09 0 0 0</pose>
			<axis>
				<xyz>-0.9929907650875736 0.10853726860345808 -0.046786769229123115</xyz>
				<limit>
					<lower>-3.141592653589793</lower>
					<upper>3.141592653589793</upper>
				</limit>
				<use_parent_model_frame>0</use_parent_model_frame>
			</axis>
		</joint>
		<joint name="wrist_right_sphere_axis2" type="revolute">
			<parent>wrist_right_sphere_link2</parent>
			<child>palm_right</child>
			<pose frame="">0.00352246019962152 -0.04482058799868668 0.03851045028542771 0 0 0</pose>
			<axis>
				<xyz>0.036880022280746654 0.7578073504191248 -0.6514352489751525</xyz>
				<limit>
					<lower>-3.141592653589793</lower>
					<upper>3.141592653589793</upper>
				</limit>
				<use_parent_model_frame>0</use_parent_model_frame>
			</axis>
		</joint>
		<joint name="wrist_right_sphere_axis1" type="revolute">
			<parent>wrist_right_sphere_link1</parent>
			<child>wrist_right_sphere_link2</child>
			<pose frame="">3.8041318575210425e-08 -1.35084271292385e-06 3.408402449167625e-11 0 0 0</pose>
			<axis>
				<xyz>-0.03535217943912361 -0.6504813211160916 -0.758699067014036</xyz>
				<limit>
					<lower>-3.141592653589793</lower>
					<upper>3.141592653589793</upper>
				</limit>
				<use_parent_model_frame>0</use_parent_model_frame>
			</axis>
		</joint>
		<joint name="little_left_joint1" type="revolute">
			<parent>little_left_link0</parent>
			<child>little_left_link1</child>
			<pose frame="">-0.004492438168613582 0.011868137328671367 0.00997887365149083 0 0 0</pose>
			<axis>
				<xyz>0.9663080757242769 -0.17142255416927957 -0.19199742371220413</xyz>
				<limit>
					<lower>0.0</lower>
					<upper>0.0</upper>
				</limit>
				<use_parent_model_frame>0</use_parent_model_frame>
			</axis>
		</joint>
		<joint name="little_left_joint2" type="revolute">
			<parent>little_left_link1</parent>
			<child>little_left_link2</child>
			<pose frame="">-0.0025076021524014893 0.009801504534056562 0.007722777629392397 0 0 0</pose>
			<axis>
				<xyz>0.9663080757242752 -0.1714225541692791 -0.1919974237122037</xyz>
				<limit>
					<lower>0.0</lower>
					<upper>0.0</upper>
				</limit>
				<use_parent_model_frame>0</use_parent_model_frame>
			</axis>
		</joint>
		<joint name="ring_left_joint1" type="revolute">
			<parent>ring_left_link0</parent>
			<child>ring_left_link1</child>
			<pose frame="">-0.00634744355378114 0.011322781051525368 0.009597744015633368 0 0 0</pose>
			<axis>
				<xyz>0.9901758132211781 -0.0799706758709029 -0.11470200483221009</xyz>
				<limit>
					<lower>0.0</lower>
					<upper>0.0</upper>
				</limit>
				<use_parent_model_frame>0</use_parent_model_frame>
			</axis>
		</joint>
		<joint name="ring_left_joint2" type="revolute">
			<parent>ring_left_link1</parent>
			<child>ring_left_link2</child>
			<pose frame="">-0.004007485132257891 0.009466186050521373 0.007505126716953044 0 0 0</pose>
			<axis>
				<xyz>0.9901758132211763 -0.0799706758709028 -0.1147020048322099</xyz>
				<limit>
					<lower>0.0</lower>
					<upper>0.0</upper>
				</limit>
				<use_parent_model_frame>0</use_parent_model_frame>
			</axis>
		</joint>
		<joint name="middle_left_joint1" type="revolute">
			<parent>middle_left_link0</parent>
			<child>middle_left_link1</child>
			<pose frame="">0.2201825771794201 -0.8600776266318332 0.6893476499600782 0 0 0</pose>
			<axis>
				<xyz>0.9972008124297193 -0.02708877664561783 -0.06969029967901386</xyz>
				<limit>
					<lower>0.0</lower>
					<upper>0.0</upper>
				</limit>
				<use_parent_model_frame>0</use_parent_model_frame>
			</axis>
		</joint>
		<joint name="middle_left_joint2" type="revolute">
			<parent>middle_left_link1</parent>
			<child>middle_left_link2</child>
			<pose frame="">-0.0048393538210491725 0.009213543148528203 0.007327334087132442 0 0 0</pose>
			<axis>
				<xyz>0.9972008124297173 -0.027088776645617787 -0.06969029967901369</xyz>
				<limit>
					<lower>0.0</lower>
					<upper>0.0</upper>
				</limit>
				<use_parent_model_frame>0</use_parent_model_frame>
			</axis>
		</joint>
		<joint name="index_left_joint1" type="revolute">
			<parent>index_left_link0</parent>
			<child>index_left_link1</child>
			<pose frame="">0.2549866139685211 -0.8543868699359684 0.6926049789135402 0 0 0</pose>
			<axis>
				<xyz>0.9991483720023647 0.039168914707923656 -0.012974083614128742</xyz>
				<limit>
					<lower>0.0</lower>
					<upper>0.0</upper>
				</limit>
				<use_parent_model_frame>0</use_parent_model_frame>
			</axis>
		</joint>
		<joint name="index_left_joint2" type="revolute">
			<parent>index_left_link1</parent>
			<child>index_left_link2</child>
			<pose frame="">0.25520131994175016 -0.874880788123229 0.6750242253487616 0 0 0</pose>
			<axis>
				<xyz>0.9991483720023628 0.03916891470792362 -0.012974083614128702</xyz>
				<limit>
					<lower>0.0</lower>
					<upper>0.0</upper>
				</limit>
				<use_parent_model_frame>0</use_parent_model_frame>
			</axis>
		</joint>
		<joint name="left_shoulder_axis0" type="revolute">
			<parent>torso</parent>
			<child>left_shoulder_link1</child>
			<pose frame="">1.331322607711627e-11 1.062051033784428e-09 5.239577004090279e-07 0 0 0</pose>
			<axis>
				<xyz>0.10383989977340724 -0.9945405553822597 -0.01031304586282346</xyz>
				<limit>
					<lower>-3.141592653589793</lower>
					<upper>3.141592653589793</upper>
				</limit>
				<use_parent_model_frame>0</use_parent_model_frame>
			</axis>
		</joint>
		<joint name="left_shoulder_axis1" type="revolute">
			<parent>left_shoulder_link1</parent>
			<child>left_shoulder_link2</child>
			<pose frame="">-2.260076499283059e-09 -7.799030942123864e-07 -2.7647614274428635e-07 0 0 0</pose>
			<axis>
				<xyz>0.9893526083353811 0.10435024586593224 -0.10145167602209751</xyz>
				<limit>
					<lower>-3.141592653589793</lower>
					<upper>3.141592653589793</upper>
				</limit>
				<use_parent_model_frame>0</use_parent_model_frame>
			</axis>
		</joint>
		<joint name="left_shoulder_axis2" type="revolute">
			<parent>left_shoulder_link2</parent>
			<child>upper_arm_left</child>
			<pose frame="">0.0016635539384484588 0.14387598136984853 0.12166517042126841 0 0 0</pose>
			<axis>
				<xyz>0.013092562311313633 -0.7580659487780016 -0.6520464723587133</xyz>
				<limit>
					<lower>-3.141592653589793</lower>
					<upper>3.141592653589793</upper>
				</limit>
				<use_parent_model_frame>0</use_parent_model_frame>
			</axis>
		</joint>
		<joint name="right_shoulder_axis0" type="revolute">
			<parent>torso</parent>
			<child>right_shoulder_link1</child>
			<pose frame="">-4.104739161903126e-08 -3.683943895040898e-06 -3.1236383816235503e-06 0 0 0</pose>
			<axis>
				<xyz>0.9999941556578312 0.001997038856384874 -0.0027749749516837634</xyz>
				<limit>
					<lower>-3.141592653589793</lower>
					<upper>3.141592653589793</upper>
				</limit>
				<use_parent_model_frame>0</use_parent_model_frame>
			</axis>
		</joint>
		<joint name="right_shoulder_axis2" type="revolute">
			<parent>right_shoulder_link2</parent>
			<child>upper_arm_right</child>
			<pose frame="">-0.022307597457547425 -0.14060473251238823 0.12299485012128628 0 0 0</pose>
			<axis>
				<xyz>0.11283270888955219 0.7526792105765325 -0.6486468883533901</xyz>
				<limit>
					<lower>-3.141592653589793</lower>
					<upper>3.141592653589793</upper>
				</limit>
				<use_parent_model_frame>0</use_parent_model_frame>
			</axis>
		</joint>
		<joint name="right_shoulder_axis1" type="revolute">
			<parent>right_shoulder_link1</parent>
			<child>right_shoulder_link2</child>
			<pose frame="">1.0231074334399182e-08 -4.3958001526789304e-07 -9.110850385241065e-10 0 0 0</pose>
			<axis>
				<xyz>0.0007986973661296407 0.6527468538026165 0.7575756773638544</xyz>
				<limit>
					<lower>-3.141592653589793</lower>
					<upper>3.141592653589793</upper>
				</limit>
				<use_parent_model_frame>0</use_parent_model_frame>
			</axis>
		</joint>
		<joint name="zed_camera_mount" type="fixed">
			<parent>head</parent>
			<child>zed_camera</child>
			<pose frame="">0.0012479955006530475 -0.017437659200940158 0.008078149594948344 0 0 0</pose>
		</joint>
		<joint name="zed_camera_right" type="fixed">
			<parent>zed_camera</parent>
			<child>zed_camera_right_lense</child>
			<pose frame="">0.011113861745865546 3.47674127294173e-05 -0.002136303089838805 0 0 0</pose>
		</joint>
		<joint name="zed_camera_left" type="fixed">
			<parent>zed_camera</parent>
			<child>zed_camera_left_lense</child>
			<pose frame="">0.011113799265661068 5.465488632535376e-05 -0.002136304473231121 0 0 0</pose>
		</joint>
		<joint name="sphere_head_axis0" type="revolute">
			<parent>torso</parent>
			<child>sphere_head_link1</child>
			<pose frame="">7.46675987173262e-08 9.276434509430942e-10 1.1204126735719911e-07 0 0 0</pose>
			<axis>
				<xyz>-0.9839485984847454 -0.17741340534829908 -0.019226001730235052</xyz>
				<limit>
					<lower>-0.5235987755982988</lower>
					<upper>0.5235987755982988</upper>
				</limit>
				<use_parent_model_frame>0</use_parent_model_frame>
			</axis>
		</joint>
		<joint name="sphere_head_axis2" type="revolute">
			<parent>sphere_head_link2</parent>
			<child>head</child>
			<pose frame="">-0.04071664848501868 0.0005095217795897056 -0.1436903832604949 0 0 0</pose>
			<axis>
				<xyz>-0.019535845674752025 -3.749543195645573e-07 0.9998091571563203</xyz>
				<limit>
					<lower>-0.5235987755982988</lower>
					<upper>0.5235987755982988</upper>
				</limit>
				<use_parent_model_frame>0</use_parent_model_frame>
			</axis>
		</joint>
		<joint name="sphere_head_axis1" type="revolute">
			<parent>sphere_head_link1</parent>
			<child>sphere_head_link2</child>
			<pose frame="">6.132645424372641e-08 -1.4754568811170544e-09 -1.1681868471669078e-07 0 0 0</pose>
			<axis>
				<xyz>-0.17737955447839734 0.9841364151389665 -0.003465551971739624</xyz>
				<limit>
					<lower>-0.5235987755982988</lower>
					<upper>0.5235987755982988</upper>
				</limit>
				<use_parent_model_frame>0</use_parent_model_frame>
			</axis>
		</joint>
		<joint name="thumb_left_joint1" type="revolute">
			<parent>thumb_left_link0</parent>
			<child>thumb_left_link1</child>
			<pose frame="">0.2174088583989083 -0.7475089023445385 0.7263298604302284 0 0 0</pose>
			<axis>
				<xyz>-0.930350820737579 -0.2988983516681703 -0.21238438201280818</xyz>
				<limit>
					<lower>0.0</lower>
					<upper>0.0</upper>
				</limit>
				<use_parent_model_frame>0</use_parent_model_frame>
			</axis>
		</joint>
		<joint name="thumb_left_joint2" type="revolute">
			<parent>thumb_left_link1</parent>
			<child>thumb_left_link2</child>
			<pose frame="">0.22759805890703608 -0.7662781271977877 0.7098063599342702 0 0 0</pose>
			<axis>
				<xyz>-0.9303508207375775 -0.29889835166816975 -0.21238438201280796</xyz>
				<limit>
					<lower>0.0</lower>
					<upper>0.0</upper>
				</limit>
				<use_parent_model_frame>0</use_parent_model_frame>
			</axis>
		</joint>
		<joint name="wrist_left_sphere_axis0" type="revolute">
			<parent>lower_arm_left</parent>
			<child>wrist_left_sphere_link1</child>
			<pose frame="">0.23753245918254295 -0.7083654588813468 0.8211146533302407 0 0 0</pose>
			<axis>
				<xyz>-0.9986941911138317 -0.0510104943227163 0.0028003757679504566</xyz>
				<limit>
					<lower>-3.141592653589793</lower>
					<upper>3.141592653589793</upper>
				</limit>
				<use_parent_model_frame>0</use_parent_model_frame>
			</axis>
		</joint>
		<joint name="wrist_left_sphere_axis2" type="revolute">
			<parent>wrist_left_sphere_link2</parent>
			<child>palm_left</child>
			<pose frame="">0.23753245918254326 -0.7083654588813468 0.8211146533302409 0 0 0</pose>
			<axis>
				<xyz>0.036880022287891945 -0.7578073498002825 -0.6514352496946396</xyz>
				<limit>
					<lower>-3.141592653589793</lower>
					<upper>3.141592653589793</upper>
				</limit>
				<use_parent_model_frame>0</use_parent_model_frame>
			</axis>
		</joint>
		<joint name="wrist_left_sphere_axis1" type="revolute">
			<parent>wrist_left_sphere_link1</parent>
			<child>wrist_left_sphere_link2</child>
			<pose frame="">0.2375324591825433 -0.7083654588813474 0.8211146533302407 0 0 0</pose>
			<axis>
				<xyz>0.03535217944532112 -0.6504813218360879 0.7586990663964479</xyz>
				<limit>
					<lower>-3.141592653589793</lower>
					<upper>3.141592653589793</upper>
				</limit>
				<use_parent_model_frame>0</use_parent_model_frame>
			</axis>
		</joint>
		<joint name="joint_knee_left" type="revolute">
			<parent>thigh_left</parent>
			<child>leg_left</child>
			<pose frame="">0.008998953193511135 0.03366934893478955 0.1502070053691074 0 0 0</pose>
			<axis>
				<xyz>7.650706696754678e-13 -1.0000000000000242 -2.724202984566474e-10</xyz>
				<limit>
					<lower>-3.141592653589793</lower>
					<upper>3.141592653589793</upper>
				</limit>
				<use_parent_model_frame>0</use_parent_model_frame>
			</axis>
		</joint>
		<joint name="joint_hip_right" type="revolute">
			<parent>bike</parent>
			<child>thigh_right</child>
			<pose frame="">-0.0043013362396470715 -0.021907752148369503 0.11113075747510301 0 0 0</pose>
			<axis>
				<xyz>4.713397833840635e-12 -0.9999999999999999 -4.747100165437955e-10</xyz>
				<limit>
					<lower>-3.141592653589793</lower>
					<upper>3.141592653589793</upper>
				</limit>
				<use_parent_model_frame>0</use_parent_model_frame>
			</axis>
		</joint>
		<joint name="joint_knee_right" type="revolute">
			<parent>thigh_right</parent>
			<child>leg_right</child>
			<pose frame="">0.007630744880886909 -0.013637454540967155 0.15030968324725197 0 0 0</pose>
			<axis>
				<xyz>-5.578294770547387e-12 1.0000000000000238 5.18998843901386e-10</xyz>
				<limit>
					<lower>-3.141592653589793</lower>
					<upper>3.141592653589793</upper>
				</limit>
				<use_parent_model_frame>0</use_parent_model_frame>
			</axis>
		</joint>
		<joint name="joint_foot_left" type="revolute">
			<parent>leg_left</parent>
			<child>foot_left</child>
			<pose frame="">0.062029311023970135 0.02399999998477682 0.037647902654059 0 0 0</pose>
			<axis>
				<xyz>2.3717178592197033e-12 1.0000000000000004 1.1192845873769567e-10</xyz>
				<limit>
					<lower>-3.141592653589793</lower>
					<upper>3.141592653589793</upper>
				</limit>
				<use_parent_model_frame>0</use_parent_model_frame>
			</axis>
		</joint>
		<joint name="joint_foot_left_tip" type="fixed">
			<parent>foot_left</parent>
			<child>foot_left_tip</child>
			<pose frame="">0.04104082618663035 -0.0011658722973624692 0.005885933969600999 0 0 0</pose>
		</joint>
		<joint name="joint_foot_right" type="revolute">
			<parent>leg_right</parent>
			<child>foot_right</child>
			<pose frame="">0.06298913883515056 0.02349999997007709 0.0360190000292614 0 0 0</pose>
			<axis>
				<xyz>-1.1248040916633449e-11 0.9999999999999997 7.168121649584346e-10</xyz>
				<limit>
					<lower>-3.141592653589793</lower>
					<upper>3.141592653589793</upper>
				</limit>
				<use_parent_model_frame>0</use_parent_model_frame>
			</axis>
		</joint>
		<joint name="joint_foot_right_tip" type="fixed">
			<parent>foot_right</parent>
			<child>foot_right_tip</child>
			<pose frame="">0.0410989272113666 0.001167377683599078 0.005458746911520578 0 0 0</pose>
		</joint>
		<plugin filename="libcardsflow_gazebo_plugin.so" name="cardsflow_gazebo_plugin"/>
	</model>
</sdf>
