<robot name="rikshaw">
  <joint name="joint_hip_left" type="revolute">
    <parent link="bike" />
    <child link="thigh_left" />
    <origin rpy="0  0  0" xyz="-0.2245   0.20207  0.48902" />
    <axis xyz="0  1  0" />
    <limit effort="0.0" lower="-3.14159265359" upper="3.14159265359" velocity="0.0" />
  </joint>
  <joint name="joint_hip_right" type="revolute">
    <parent link="bike" />
    <child link="thigh_right" />
    <origin rpy="0  0  0" xyz="-0.2245  -0.16192  0.48902" />
    <axis xyz="0  1  0" />
    <limit effort="0.0" lower="-3.14159265359" upper="3.14159265359" velocity="0.0" />
  </joint>
  <joint name="joint_knee_left" type="revolute">
    <parent link="thigh_left" />
    <child link="leg_left" />
    <origin rpy="0  0  0" xyz="-0.01653 -0.02405 -0.30873" />
    <axis xyz="0  1  0" />
    <limit effort="0.0" lower="-3.14159265359" upper="3.14159265359" velocity="0.0" />
  </joint>
  <joint name="joint_knee_right" type="revolute">
    <parent link="thigh_right" />
    <child link="leg_right" />
    <origin rpy="0  0  0" xyz="-0.01603 -0.0077  -0.30874" />
    <axis xyz="0 -1  0" />
    <limit effort="0.0" lower="-3.14159265359" upper="3.14159265359" velocity="0.0" />
  </joint>
  <joint name="joint_foot_left" type="revolute">
    <parent link="leg_left" />
    <child link="foot_left" />
    <origin rpy="0  0  0" xyz="0.00318 -0.0135  -0.34912" />
    <axis xyz="0 -1  0" />
    <limit effort="0.0" lower="-3.14159265359" upper="3.14159265359" velocity="0.0" />
  </joint>
  <joint name="joint_foot_left_tip" type="revolute">
    <parent link="foot_left" />
    <child link="foot_left_tip" />
    <origin rpy="0  0  0" xyz="0.06158  0.024   -0.03743" />
    <axis xyz="0  0  0" />
    <limit effort="0" lower="0" upper="0" velocity="0" />
  </joint>
  <joint name="joint_foot_right" type="revolute">
    <parent link="leg_right" />
    <child link="foot_right" />
    <origin rpy="0  0  0" xyz="0      -0.0135  -0.34914" />
    <axis xyz="0 -1  0" />
    <limit effort="0.0" lower="-3.14159265359" upper="3.14159265359" velocity="0.0" />
  </joint>
  <joint name="joint_foot_right_tip" type="revolute">
    <parent link="foot_right" />
    <child link="foot_right_tip" />
    <origin rpy="0  0  0" xyz="0.06197  0.024   -0.03679" />
    <axis xyz="0  0  0" />
    <limit effort="0" lower="0" upper="0" velocity="0" />
  </joint>
  <joint name="joint_pedal_right" type="revolute">
    <parent link="kurbel" />
    <child link="pedal_right" />
    <origin rpy="0  0  0" xyz="0.01468 -0.22498  0.16854" />
    <axis xyz="0 -1  0" />
    <limit effort="0.0" lower="-3.14159265359" upper="3.14159265359" velocity="0.0" />
  </joint>
  <joint name="joint_pedal_left" type="revolute">
    <parent link="kurbel" />
    <child link="pedal_left" />
    <origin rpy="0  0  0" xyz="-0.01482  0.15624 -0.16858" />
    <axis xyz="0  1  0" />
    <limit effort="0.0" lower="-3.14159265359" upper="3.14159265359" velocity="0.0" />
  </joint>
  <joint name="elbow_right_rot1" type="revolute">
    <parent link="elbow_right" />
    <child link="lower_arm_right" />
    <origin rpy="0  0  0" xyz="-0.0068  -0.03837 -0.05667" />
    <axis xyz="0.03688  0.7578   0.65143" />
    <limit effort="0.0" lower="-1.57079632679" upper="1.57079632679" velocity="0.0" />
  </joint>
  <joint name="left_shoulder_axis0" type="revolute">
    <parent link="torso" />
    <child link="left_shoulder_link1" />
    <origin rpy="0  0  0" xyz="0.00146  0.29218  0.46833" />
    <axis xyz="-0.05097  0.99863 -0.01134" />
    <limit effort="0.0" lower="-3.14159265359" upper="3.14159265359" velocity="0.0" />
  </joint>
  <joint name="left_shoulder_axis1" type="revolute">
    <parent link="left_shoulder_link1" />
    <child link="left_shoulder_link2" />
    <origin rpy="0  0  0" xyz="0  0  0" />
    <axis xyz="-0.99869 -0.05101 -0.0028" />
    <limit effort="0.0" lower="-3.14159265359" upper="3.14159265359" velocity="0.0" />
  </joint>
  <joint name="left_shoulder_axis2" type="revolute">
    <parent link="left_shoulder_link2" />
    <child link="upper_arm_left" />
    <origin rpy="0  0  0" xyz="0  0  0" />
    <axis xyz="-0.03688  0.7578  -0.65143" />
    <limit effort="0.0" lower="-3.14159265359" upper="3.14159265359" velocity="0.0" />
  </joint>
  <joint name="elbow_left_rot1" type="revolute">
    <parent link="elbow_left" />
    <child link="lower_arm_left" />
    <origin rpy="0  0  0" xyz="-0.0068   0.03837 -0.05667" />
    <axis xyz="-0.03688  0.7578  -0.65143" />
    <limit effort="0.0" lower="-1.57079632679" upper="1.57079632679" velocity="0.0" />
  </joint>
  <joint name="elbow_left_rot0" type="revolute">
    <parent link="upper_arm_left" />
    <child link="elbow_left" />
    <origin rpy="0  0  0" xyz="-0.00549  0.21448 -0.16081" />
    <axis xyz="0.03535 -0.65048 -0.75869" />
    <limit effort="0.0" lower="0.0" upper="1.57079632679" velocity="0.0" />
  </joint>
  <joint name="left_wrist_0" type="revolute">
    <parent link="lower_arm_left" />
    <child link="wrist_left_1" />
    <origin rpy="0  0  0" xyz="-0.00914  0.19129 -0.17959" />
    <axis xyz="0.04721 -0.66836 -0.74233" />
    <limit effort="0.0" lower="-0.523598775598" upper="0.523598775598" velocity="0.0" />
  </joint>
  <joint name="left_wrist_1" type="revolute">
    <parent link="wrist_left_1" />
    <child link="left_hand" />
    <origin rpy="0  0  0" xyz="0.01697  0.00803  0.00798" />
    <axis xyz="-0.99824 -0.05815 -0.01113" />
    <limit effort="0.0" lower="-0.523598775598" upper="0.523598775598" velocity="0.0" />
  </joint>
  <joint name="elbow_right_rot0" type="revolute">
    <parent link="upper_arm_right" />
    <child link="elbow_right" />
    <origin rpy="0  0  0" xyz="-0.00555 -0.21561 -0.16179" />
    <axis xyz="-0.03535 -0.65048  0.75869" />
    <limit effort="0.0" lower="0.0" upper="1.57079632679" velocity="0.0" />
  </joint>
  <joint name="right_wrist_0" type="revolute">
    <parent link="lower_arm_right" />
    <child link="wrist_right_1" />
    <origin rpy="0  0  0" xyz="-0.00952 -0.1943  -0.17993" />
    <axis xyz="0.02346  0.63212 -0.77451" />
    <limit effort="0.0" lower="-0.523598775598" upper="0.523598775598" velocity="0.0" />
  </joint>
  <joint name="right_wrist_1" type="revolute">
    <parent link="wrist_right_1" />
    <child link="right_hand" />
    <origin rpy="0  0  0" xyz="-0.01772 -0.00587  0.00822" />
    <axis xyz="-0.99902  0.04386  0.00553" />
    <limit effort="0.0" lower="-0.523598775598" upper="0.523598775598" velocity="0.0" />
  </joint>
  <joint name="right_shoulder_axis0" type="revolute">
    <parent link="torso" />
    <child link="right_shoulder_link1" />
    <origin rpy="0  0  0" xyz="0.00149 -0.29218  0.46833" />
    <axis xyz="-0.99869  0.05101 -0.0028" />
    <limit effort="0.0" lower="-3.14159265359" upper="3.14159265359" velocity="0.0" />
  </joint>
  <joint name="right_shoulder_axis2" type="revolute">
    <parent link="right_shoulder_link2" />
    <child link="upper_arm_right" />
    <origin rpy="0  0  0" xyz="0  0  0" />
    <axis xyz="-0.03688 -0.7578  -0.65143" />
    <limit effort="0.0" lower="-3.14159265359" upper="3.14159265359" velocity="0.0" />
  </joint>
  <joint name="right_shoulder_axis1" type="revolute">
    <parent link="right_shoulder_link1" />
    <child link="right_shoulder_link2" />
    <origin rpy="0  0  0" xyz="0  0  0" />
    <axis xyz="-0.03535 -0.65048  0.75869" />
    <limit effort="0.0" lower="-3.14159265359" upper="3.14159265359" velocity="0.0" />
  </joint>
  <joint name="zed_camera_mount" type="revolute">
    <parent link="head" />
    <child link="zed_camera" />
    <origin rpy="0  0  0" xyz="0.10663  0.0215   0.20551" />
    <axis xyz="0  0  0" />
    <limit effort="0" lower="0" upper="0" velocity="0" />
  </joint>
  <joint name="zed_camera_right" type="revolute">
    <parent link="zed_camera" />
    <child link="zed_camera_right_lense" />
    <origin rpy="0  0  0" xyz="-0.00015 -0.0815  -0.00799" />
    <axis xyz="0  0  0" />
    <limit effort="0" lower="0" upper="0" velocity="0" />
  </joint>
  <joint name="zed_camera_left" type="revolute">
    <parent link="zed_camera" />
    <child link="zed_camera_left_lense" />
    <origin rpy="0  0  0" xyz="-0.00015  0.03848 -0.00799" />
    <axis xyz="0  0  0" />
    <limit effort="0" lower="0" upper="0" velocity="0" />
  </joint>
  <joint name="head_axis0" type="revolute">
    <parent link="torso" />
    <child link="sphere_head_link1" />
    <origin rpy="0  0  0" xyz="0.01217  0       0.62324" />
    <axis xyz="0.9998   0      -0.01953" />
    <limit effort="0.0" lower="-0.523598775598" upper="0.523598775598" velocity="0.0" />
  </joint>
  <joint name="head_axis2" type="revolute">
    <parent link="sphere_head_link2" />
    <child link="head" />
    <origin rpy="0  0  0" xyz="0  0  0" />
    <axis xyz="0.01953  0       0.9998" />
    <limit effort="0.0" lower="-0.523598775598" upper="0.523598775598" velocity="0.0" />
  </joint>
  <joint name="head_axis1" type="revolute">
    <parent link="sphere_head_link1" />
    <child link="sphere_head_link2" />
    <origin rpy="0  0  0" xyz="0  0  0" />
    <axis xyz="0 -1  0" />
    <limit effort="0.0" lower="-0.523598775598" upper="0.523598775598" velocity="0.0" />
  </joint>
  <joint name="joint_wheel_right" type="revolute">
    <parent link="front_part" />
    <child link="right_wheel" />
    <origin rpy="0  0  0" xyz="0.052  -0.338   0.0345" />
    <axis xyz="0 -1  0" />
    <limit effort="0.0" lower="-3.14159265359" upper="3.14159265359" velocity="0.0" />
  </joint>
  <joint name="joint_wheel_back" type="revolute">
    <parent link="bike" />
    <child link="wheel_back" />
    <origin rpy="0  0  0" xyz="-0.53689  0.06544  0.04941" />
    <axis xyz="0  1  0" />
    <limit effort="0.0" lower="-3.14159265359" upper="3.14159265359" velocity="0.0" />
  </joint>
  <joint name="joint_pedal" type="revolute">
    <parent link="bike" />
    <child link="kurbel" />
    <origin rpy="0  0  0" xyz="-0.0925   0.035    0.00326" />
    <axis xyz="0 -1  0" />
    <limit effort="0.0" lower="-3.14159265359" upper="3.14159265359" velocity="0.0" />
  </joint>
  <joint name="spine_joint" type="revolute">
    <parent link="bike" />
    <child link="torso" />
    <origin rpy="0  0  0" xyz="-0.22048  0.01442  0.69498" />
    <axis xyz="-0.01953  0      -0.9998" />
    <limit effort="0.0" lower="-0.523598775598" upper="0.523598775598" velocity="0.0" />
  </joint>
  <joint name="joint_wheel_left" type="revolute">
    <parent link="front_part" />
    <child link="left_wheel" />
    <origin rpy="0  0  0" xyz="0.052   0.304   0.0345" />
    <axis xyz="0  1  0" />
    <limit effort="0.0" lower="-3.14159265359" upper="3.14159265359" velocity="0.0" />
  </joint>
  <joint name="joint_front" type="revolute">
    <parent link="bike" />
    <child link="front_part" />
    <origin rpy="0  0  0" xyz="0.94642  0       0.01116" />
    <axis xyz="0  0  1" />
    <limit effort="0.0" lower="-0.523598775598" upper="0.523598775598" velocity="0.0" />
  </joint>
  <link name="bike">
    <inertial>
      <mass value="21.81947805717533" />
      <origin rpy="0  0  0" xyz="0  0  0" />
      <inertia ixx="5.886482099704385" ixy="0.05246604407007407" ixz="-0.14605334861846847" iyy="9.145464405182723" iyz="2.3093169469685275" izz="3.8627096944427937" />
    </inertial>
    <collision name="bike_collision">
      <origin rpy="0  0  0" xyz="0  0  0" />
      <geometry>
        <mesh filename="package://robots/rikshaw/meshes/collisions/bike.stl" scale="0.001 0.001 0.001" />
      </geometry>
    </collision>
    <visual name="bike_visual">
      <origin rpy="0  0  0" xyz="0  0  0" />
      <geometry>
        <mesh filename="package://robots/rikshaw/meshes/visuals/bike.stl" scale="0.001 0.001 0.001" />
      </geometry>
    </visual>
  </link>
  <link name="upper_arm_right">
    <inertial>
      <mass value="1.0945525999991552" />
      <origin rpy="0  0  0" xyz="-0.00388 -0.1226  -0.08951" />
      <inertia ixx="1.4421148034784848" ixy="-0.0977475801484251" ixz="0.4688762159986468" iyy="1.3199753951468367" iyz="0.26189149622628766" izz="0.2343257965627362" />
    </inertial>
    <collision name="upper_arm_right_collision">
      <origin rpy="0  0  0" xyz="-0.00388 -0.1226  -0.08951" />
      <geometry>
        <mesh filename="package://robots/rikshaw/meshes/collisions/upper_arm_right.stl" scale="0.001 0.001 0.001" />
      </geometry>
    </collision>
    <visual name="upper_arm_right_visual">
      <origin rpy="0  0  0" xyz="-0.00388 -0.1226  -0.08951" />
      <geometry>
        <mesh filename="package://robots/rikshaw/meshes/visuals/upper_arm_right.stl" scale="0.001 0.001 0.001" />
      </geometry>
    </visual>
  </link>
  <link name="torso">
    <inertial>
      <mass value="12.829194596051684" />
      <origin rpy="0  0  0" xyz="0.22048 -0.01442 -0.69498" />
      <inertia ixx="17.25655500920537" ixy="0.04357283427721384" ixz="-0.2404715577566944" iyy="17.518149027040117" iyz="2.95154696517872" izz="0.8597492821307174" />
    </inertial>
    <collision name="torso_collision">
      <origin rpy="0  0  0" xyz="0.22048 -0.01442 -0.69498" />
      <geometry>
        <mesh filename="package://robots/rikshaw/meshes/collisions/torso.stl" scale="0.001 0.001 0.001" />
      </geometry>
    </collision>
    <visual name="torso_visual">
      <origin rpy="0  0  0" xyz="0.22048 -0.01442 -0.69498" />
      <geometry>
        <mesh filename="package://robots/rikshaw/meshes/visuals/torso.stl" scale="0.001 0.001 0.001" />
      </geometry>
    </visual>
  </link>
  <link name="front_part">
    <inertial>
      <mass value="16.810672465638184" />
      <origin rpy="0  0  0" xyz="-0.23003 -0.01038  0.20527" />
      <inertia ixx="3.2092296528945967" ixy="0.18113615628275678" ixz="0.006723073533121614" iyy="14.66296026711583" iyz="-1.241970673631743" izz="13.91291969418297" />
    </inertial>
    <collision name="front_part_collision">
      <origin rpy="0  0  0" xyz="-0.23003 -0.01038  0.20527" />
      <geometry>
        <mesh filename="package://robots/rikshaw/meshes/collisions/front_part.stl" scale="0.001 0.001 0.001" />
      </geometry>
    </collision>
    <visual name="front_part_visual">
      <origin rpy="0  0  0" xyz="-0.23003 -0.01038  0.20527" />
      <geometry>
        <mesh filename="package://robots/rikshaw/meshes/visuals/front_part.stl" scale="0.001 0.001 0.001" />
      </geometry>
    </visual>
  </link>
  <link name="left_wheel">
    <inertial>
      <mass value="13.34016392909787" />
      <origin rpy="0  0  0" xyz="0     0.046  0" />
      <inertia ixx="2.171169531427472" ixy="-4.661713033463371" ixz="-0.21322209220250452" iyy="14.34232616188963" iyz="-0.608246286975269" izz="15.441547158388817" />
    </inertial>
    <collision name="left_wheel_collision">
      <origin rpy="0  0  0" xyz="0     0.046  0" />
      <geometry>
        <mesh filename="package://robots/rikshaw/meshes/collisions/left_wheel.stl" scale="0.001 0.001 0.001" />
      </geometry>
    </collision>
    <visual name="left_wheel_visual">
      <origin rpy="0  0  0" xyz="0     0.046  0" />
      <geometry>
        <mesh filename="package://robots/rikshaw/meshes/visuals/left_wheel.stl" scale="0.001 0.001 0.001" />
      </geometry>
    </visual>
  </link>
  <link name="right_wheel">
    <inertial>
      <mass value="13.34016392909787" />
      <origin rpy="0  0  0" xyz="0    -0.004  0" />
      <inertia ixx="2.097317024732184" ixy="4.55515786054409" ixz="0.2083483651538148" iyy="14.342326161889634" iyz="-0.6082462869756708" izz="15.367694651693467" />
    </inertial>
    <collision name="right_wheel_collision">
      <origin rpy="0  0  0" xyz="0    -0.004  0" />
      <geometry>
        <mesh filename="package://robots/rikshaw/meshes/collisions/right_wheel.stl" scale="0.001 0.001 0.001" />
      </geometry>
    </collision>
    <visual name="right_wheel_visual">
      <origin rpy="0  0  0" xyz="0    -0.004  0" />
      <geometry>
        <mesh filename="package://robots/rikshaw/meshes/visuals/right_wheel.stl" scale="0.001 0.001 0.001" />
      </geometry>
    </visual>
  </link>
  <link name="pedal_right">
    <inertial>
      <mass value="0.9460025886020137" />
      <origin rpy="0  0  0" xyz="-4.00000000e-05   4.20000000e-02   6.00000000e-05" />
      <inertia ixx="0.049584952858416534" ixy="-0.01090117556517612" ixz="0.024062204564554542" iyy="0.03409659621084031" iyz="0.012633073677194193" izz="0.027060626295967245" />
    </inertial>
    <collision name="pedal_right_collision">
      <origin rpy="0  0  0" xyz="-4.00000000e-05   4.20000000e-02   6.00000000e-05" />
      <geometry>
        <mesh filename="package://robots/rikshaw/meshes/collisions/pedal_right.stl" scale="0.001 0.001 0.001" />
      </geometry>
    </collision>
    <visual name="pedal_right_visual">
      <origin rpy="0  0  0" xyz="-4.00000000e-05   4.20000000e-02   6.00000000e-05" />
      <geometry>
        <mesh filename="package://robots/rikshaw/meshes/visuals/pedal_right.stl" scale="0.001 0.001 0.001" />
      </geometry>
    </visual>
  </link>
  <link name="kurbel">
    <inertial>
      <mass value="2.7832708381107603" />
      <origin rpy="0  0  0" xyz="0.00027 -0.03513  0.001" />
      <inertia ixx="0.0332152555656024" ixy="0.001021810155673795" ixz="0.012937192477663303" iyy="0.041586881852696926" iyz="-0.0003014363494414667" izz="0.039731070916128416" />
    </inertial>
    <collision name="kurbel_collision">
      <origin rpy="0  0  0" xyz="0.00027 -0.03513  0.001" />
      <geometry>
        <mesh filename="package://robots/rikshaw/meshes/collisions/kurbel.stl" scale="0.001 0.001 0.001" />
      </geometry>
    </collision>
    <visual name="kurbel_visual">
      <origin rpy="0  0  0" xyz="0.00027 -0.03513  0.001" />
      <geometry>
        <mesh filename="package://robots/rikshaw/meshes/visuals/kurbel.stl" scale="0.001 0.001 0.001" />
      </geometry>
    </visual>
  </link>
  <link name="pedal_left">
    <inertial>
      <mass value="0.9460025886020093" />
      <origin rpy="0  0  0" xyz="-5.00000000e-05  -4.20000000e-02  -5.00000000e-05" />
      <inertia ixx="0.047865070945934965" ixy="0.01516068573344577" ixz="0.023349033442654262" iyy="0.037196017563941204" iyz="-0.016827373941817634" izz="0.03258593744910717" />
    </inertial>
    <collision name="pedal_left_collision">
      <origin rpy="0  0  0" xyz="-5.00000000e-05  -4.20000000e-02  -5.00000000e-05" />
      <geometry>
        <mesh filename="package://robots/rikshaw/meshes/collisions/pedal_left.stl" scale="0.001 0.001 0.001" />
      </geometry>
    </collision>
    <visual name="pedal_left_visual">
      <origin rpy="0  0  0" xyz="-5.00000000e-05  -4.20000000e-02  -5.00000000e-05" />
      <geometry>
        <mesh filename="package://robots/rikshaw/meshes/visuals/pedal_left.stl" scale="0.001 0.001 0.001" />
      </geometry>
    </visual>
  </link>
  <link name="foot_left">
    <inertial>
      <mass value="0.7294147785294234" />
      <origin rpy="0  0  0" xyz="0.06202  0.024   -0.03764" />
      <inertia ixx="0.05407216953667249" ixy="0.03251612036702484" ixz="0.026761208182578378" iyy="0.06910783811131357" iyz="-0.03357311404413584" izz="0.06737097284992735" />
    </inertial>
    <collision name="foot_left_collision">
      <origin rpy="0  0  0" xyz="0.06202  0.024   -0.03764" />
      <geometry>
        <mesh filename="package://robots/rikshaw/meshes/collisions/foot_left.stl" scale="0.001 0.001 0.001" />
      </geometry>
    </collision>
    <visual name="foot_left_visual">
      <origin rpy="0  0  0" xyz="0.06202  0.024   -0.03764" />
      <geometry>
        <mesh filename="package://robots/rikshaw/meshes/visuals/foot_left.stl" scale="0.001 0.001 0.001" />
      </geometry>
    </visual>
  </link>
  <link name="foot_left_tip">
    <inertial>
      <mass value="0.27796086995260727" />
      <origin rpy="0  0  0" xyz="0.04104 -0.00116 -0.00588" />
      <inertia ixx="0.022352432140757796" ixy="0.007051209655856457" ixz="0.01104791819788336" iyy="0.017709776432757476" iyz="-0.007965691482024362" izz="0.01503260538749266" />
    </inertial>
    <collision name="foot_left_tip_collision">
      <origin rpy="0  0  0" xyz="0.04104 -0.00116 -0.00588" />
      <geometry>
        <mesh filename="package://robots/rikshaw/meshes/collisions/foot_left_tip.stl" scale="0.001 0.001 0.001" />
      </geometry>
    </collision>
    <visual name="foot_left_tip_visual">
      <origin rpy="0  0  0" xyz="0.04104 -0.00116 -0.00588" />
      <geometry>
        <mesh filename="package://robots/rikshaw/meshes/visuals/foot_left_tip.stl" scale="0.001 0.001 0.001" />
      </geometry>
    </visual>
  </link>
  <link name="foot_right">
    <inertial>
      <mass value="0.7293884039293155" />
      <origin rpy="0  0  0" xyz="0.06298  0.0235  -0.03601" />
      <inertia ixx="0.046628493153724276" ixy="-0.027737105196730626" ixz="-0.02258940931322784" iyy="0.06999759190491005" iyz="-0.033939836746644796" izz="0.06080277396500069" />
    </inertial>
    <collision name="foot_right_collision">
      <origin rpy="0  0  0" xyz="0.06298  0.0235  -0.03601" />
      <geometry>
        <mesh filename="package://robots/rikshaw/meshes/collisions/foot_right.stl" scale="0.001 0.001 0.001" />
      </geometry>
    </collision>
    <visual name="foot_right_visual">
      <origin rpy="0  0  0" xyz="0.06298  0.0235  -0.03601" />
      <geometry>
        <mesh filename="package://robots/rikshaw/meshes/visuals/foot_right.stl" scale="0.001 0.001 0.001" />
      </geometry>
    </visual>
  </link>
  <link name="foot_right_tip">
    <inertial>
      <mass value="0.27795073699924977" />
      <origin rpy="0  0  0" xyz="0.04109  0.00116 -0.00545" />
      <inertia ixx="0.01940696459090878" ixy="-0.006044281399509699" ixz="-0.009268276323839846" iyy="0.017755497306462847" iyz="-0.008058438745184075" izz="0.012380586242452746" />
    </inertial>
    <collision name="foot_right_tip_collision">
      <origin rpy="0  0  0" xyz="0.04109  0.00116 -0.00545" />
      <geometry>
        <mesh filename="package://robots/rikshaw/meshes/collisions/foot_right_tip.stl" scale="0.001 0.001 0.001" />
      </geometry>
    </collision>
    <visual name="foot_right_tip_visual">
      <origin rpy="0  0  0" xyz="0.04109  0.00116 -0.00545" />
      <geometry>
        <mesh filename="package://robots/rikshaw/meshes/visuals/foot_right_tip.stl" scale="0.001 0.001 0.001" />
      </geometry>
    </visual>
  </link>
  <link name="thigh_right">
    <inertial>
      <mass value="5.563544538495218" />
      <origin rpy="0  0  0" xyz="-0.0043  -0.0219  -0.11113" />
      <inertia ixx="1.0107794337760492" ixy="-0.23394874645676036" ixz="0.3895573298264988" iyy="1.116934262404504" iyz="0.4818341397585977" izz="0.49142600627784244" />
    </inertial>
    <collision name="thigh_right_collision">
      <origin rpy="0  0  0" xyz="-0.0043  -0.0219  -0.11113" />
      <geometry>
        <mesh filename="package://robots/rikshaw/meshes/collisions/thigh_right.stl" scale="0.001 0.001 0.001" />
      </geometry>
    </collision>
    <visual name="thigh_right_visual">
      <origin rpy="0  0  0" xyz="-0.0043  -0.0219  -0.11113" />
      <geometry>
        <mesh filename="package://robots/rikshaw/meshes/visuals/thigh_right.stl" scale="0.001 0.001 0.001" />
      </geometry>
    </visual>
  </link>
  <link name="thigh_left">
    <inertial>
      <mass value="5.563607010025899" />
      <origin rpy="0  0  0" xyz="-0.00477  0.01055 -0.11112" />
      <inertia ixx="1.0743502428394167" ixy="0.27061255753829405" ixz="-0.4500948529131707" iyy="1.1181878375700518" iyz="0.4831083644344466" izz="0.5561313234967189" />
    </inertial>
    <collision name="thigh_left_collision">
      <origin rpy="0  0  0" xyz="-0.00477  0.01055 -0.11112" />
      <geometry>
        <mesh filename="package://robots/rikshaw/meshes/collisions/thigh_left.stl" scale="0.001 0.001 0.001" />
      </geometry>
    </collision>
    <visual name="thigh_left_visual">
      <origin rpy="0  0  0" xyz="-0.00477  0.01055 -0.11112" />
      <geometry>
        <mesh filename="package://robots/rikshaw/meshes/visuals/thigh_left.stl" scale="0.001 0.001 0.001" />
      </geometry>
    </visual>
  </link>
  <link name="leg_right">
    <inertial>
      <mass value="5.741539074839567" />
      <origin rpy="0  0  0" xyz="0.00763 -0.01363 -0.15031" />
      <inertia ixx="0.23782026670704295" ixy="-0.2455186518053473" ixz="0.03496971541512629" iyy="0.35940035869454817" iyz="0.03759088986317208" izz="0.5167570394584527" />
    </inertial>
    <collision name="leg_right_collision">
      <origin rpy="0  0  0" xyz="0.00763 -0.01363 -0.15031" />
      <geometry>
        <mesh filename="package://robots/rikshaw/meshes/collisions/leg_right.stl" scale="0.001 0.001 0.001" />
      </geometry>
    </collision>
    <visual name="leg_right_visual">
      <origin rpy="0  0  0" xyz="0.00763 -0.01363 -0.15031" />
      <geometry>
        <mesh filename="package://robots/rikshaw/meshes/visuals/leg_right.stl" scale="0.001 0.001 0.001" />
      </geometry>
    </visual>
  </link>
  <link name="leg_left">
    <inertial>
      <mass value="5.742633907090983" />
      <origin rpy="0  0  0" xyz="0.00899  0.03366 -0.1502" />
      <inertia ixx="0.3024377123250296" ixy="0.28200011187752894" ixz="-0.04001203273953342" iyy="0.3572039205308176" iyz="0.0381306989371113" izz="0.5789452561844931" />
    </inertial>
    <collision name="leg_left_collision">
      <origin rpy="0  0  0" xyz="0.00899  0.03366 -0.1502" />
      <geometry>
        <mesh filename="package://robots/rikshaw/meshes/collisions/leg_left.stl" scale="0.001 0.001 0.001" />
      </geometry>
    </collision>
    <visual name="leg_left_visual">
      <origin rpy="0  0  0" xyz="0.00899  0.03366 -0.1502" />
      <geometry>
        <mesh filename="package://robots/rikshaw/meshes/visuals/leg_left.stl" scale="0.001 0.001 0.001" />
      </geometry>
    </visual>
  </link>
  <link name="wheel_back">
    <inertial>
      <mass value="13.340163929098493" />
      <origin rpy="0  0  0" xyz="0    -0.069  0" />
      <inertia ixx="0.5419188938328757" ixy="-0.025425846119324413" ixz="0.0023401868697195947" iyy="4.894303401629517" iyz="0.35393127318782075" izz="4.354763468464214" />
    </inertial>
    <collision name="wheel_back_collision">
      <origin rpy="0  0  0" xyz="0    -0.069  0" />
      <geometry>
        <mesh filename="package://robots/rikshaw/meshes/collisions/wheel_back.stl" scale="0.001 0.001 0.001" />
      </geometry>
    </collision>
    <visual name="wheel_back_visual">
      <origin rpy="0  0  0" xyz="0    -0.069  0" />
      <geometry>
        <mesh filename="package://robots/rikshaw/meshes/visuals/wheel_back.stl" scale="0.001 0.001 0.001" />
      </geometry>
    </visual>
  </link>
  <link name="elbow_left">
    <inertial>
      <mass value="0.15681540300967223" />
      <origin rpy="0  0  0" xyz="-0.00614  0.01903 -0.03504" />
      <inertia ixx="0.19266629450625464" ixy="0.019541794174774592" ixz="-0.08195067996592703" iyy="0.1552331043974446" iyz="0.034994843981859466" izz="0.05422684654213822" />
    </inertial>
    <collision name="elbow_left_collision">
      <origin rpy="0  0  0" xyz="-0.00614  0.01903 -0.03504" />
      <geometry>
        <mesh filename="package://robots/rikshaw/meshes/collisions/elbow_left.stl" scale="0.001 0.001 0.001" />
      </geometry>
    </collision>
    <visual name="elbow_left_visual">
      <origin rpy="0  0  0" xyz="-0.00614  0.01903 -0.03504" />
      <geometry>
        <mesh filename="package://robots/rikshaw/meshes/visuals/elbow_left.stl" scale="0.001 0.001 0.001" />
      </geometry>
    </visual>
  </link>
  <link name="elbow_right">
    <inertial>
      <mass value="0.1735064537201356" />
      <origin rpy="0  0  0" xyz="-0.00618 -0.02031 -0.03655" />
      <inertia ixx="0.2075000206797995" ixy="-0.02056914602319384" ixz="0.08601030782639262" iyy="0.17091898467001698" iyz="0.03862988659000414" izz="0.055162486401777906" />
    </inertial>
    <collision name="elbow_right_collision">
      <origin rpy="0  0  0" xyz="-0.00618 -0.02031 -0.03655" />
      <geometry>
        <mesh filename="package://robots/rikshaw/meshes/collisions/elbow_right.stl" scale="0.001 0.001 0.001" />
      </geometry>
    </collision>
    <visual name="elbow_right_visual">
      <origin rpy="0  0  0" xyz="-0.00618 -0.02031 -0.03655" />
      <geometry>
        <mesh filename="package://robots/rikshaw/meshes/visuals/elbow_right.stl" scale="0.001 0.001 0.001" />
      </geometry>
    </visual>
  </link>
  <link name="left_shoulder_link1">
    <inertial>
      <mass value="0.046753849896631366" />
      <origin rpy="0  0  0" xyz="0  0  0" />
      <inertia ixx="0.06767449740992429" ixy="0.00313965054739232" ixz="-0.01667609874350618" iyy="0.06552223385053244" iyz="0.0119126470601849" izz="0.006643884826415351" />
    </inertial>
    <collision name="left_shoulder_link1_collision">
      <origin rpy="0  0  0" xyz="0  0  0" />
      <geometry>
        <mesh filename="package://robots/rikshaw/meshes/collisions/left_shoulder_link1.stl" scale="0.001 0.001 0.001" />
      </geometry>
    </collision>
    <visual name="left_shoulder_link1_visual">
      <origin rpy="0  0  0" xyz="0  0  0" />
      <geometry>
        <mesh filename="package://robots/rikshaw/meshes/visuals/left_shoulder_link1.stl" scale="0.001 0.001 0.001" />
      </geometry>
    </visual>
  </link>
  <link name="left_shoulder_link2">
    <inertial>
      <mass value="0.031337295884972576" />
      <origin rpy="0  0  0" xyz="0  0  0" />
      <inertia ixx="0.045358313011474534" ixy="0.0021043939017770154" ixz="-0.011177386877311443" iyy="0.04391571091145054" iyz="0.007984584297783932" izz="0.004451855074852757" />
    </inertial>
    <collision name="left_shoulder_link2_collision">
      <origin rpy="0  0  0" xyz="0  0  0" />
      <geometry>
        <mesh filename="package://robots/rikshaw/meshes/collisions/left_shoulder_link2.stl" scale="0.001 0.001 0.001" />
      </geometry>
    </collision>
    <visual name="left_shoulder_link2_visual">
      <origin rpy="0  0  0" xyz="0  0  0" />
      <geometry>
        <mesh filename="package://robots/rikshaw/meshes/visuals/left_shoulder_link2.stl" scale="0.001 0.001 0.001" />
      </geometry>
    </visual>
  </link>
  <link name="wrist_left_1">
    <inertial>
      <mass value="0.01276210274228386" />
      <origin rpy="0  0  0" xyz="-0.00041  0.00553  0.00829" />
      <inertia ixx="0.014958953395600197" ixy="0.0023249649587372334" ixz="-0.0074769785070066775" iyy="0.008400668033256913" iyz="0.002381158490744941" izz="0.008043893530445803" />
    </inertial>
    <collision name="wrist_left_1_collision">
      <origin rpy="0  0  0" xyz="-0.00041  0.00553  0.00829" />
      <geometry>
        <mesh filename="package://robots/rikshaw/meshes/collisions/wrist_left_1.stl" scale="0.001 0.001 0.001" />
      </geometry>
    </collision>
    <visual name="wrist_left_1_visual">
      <origin rpy="0  0  0" xyz="-0.00041  0.00553  0.00829" />
      <geometry>
        <mesh filename="package://robots/rikshaw/meshes/visuals/wrist_left_1.stl" scale="0.001 0.001 0.001" />
      </geometry>
    </visual>
  </link>
  <link name="left_hand">
    <inertial>
      <mass value="0.08391854013243093" />
      <origin rpy="0  0  0" xyz="-0.02378  0.0557  -0.05642" />
      <inertia ixx="0.0990936807995511" ixy="0.016915179144618795" ixz="-0.04898119948040993" iyy="0.04850556851408662" iyz="0.014877442754935744" izz="0.06095909720368022" />
    </inertial>
    <collision name="left_hand_collision">
      <origin rpy="0  0  0" xyz="-0.02378  0.0557  -0.05642" />
      <geometry>
        <mesh filename="package://robots/rikshaw/meshes/collisions/left_hand.stl" scale="0.001 0.001 0.001" />
      </geometry>
    </collision>
    <visual name="left_hand_visual">
      <origin rpy="0  0  0" xyz="-0.02378  0.0557  -0.05642" />
      <geometry>
        <mesh filename="package://robots/rikshaw/meshes/visuals/left_hand.stl" scale="0.001 0.001 0.001" />
      </geometry>
    </visual>
  </link>
  <link name="wrist_right_1">
    <inertial>
      <mass value="0.012761742618737516" />
      <origin rpy="0  0  0" xyz="-0.0002  -0.00592  0.00952" />
      <inertia ixx="0.014495265462586292" ixy="-0.002252044804095112" ixz="0.007235730703507522" iyy="0.008400166661985523" iyz="0.002382816635337103" izz="0.007583144518463848" />
    </inertial>
    <collision name="wrist_right_1_collision">
      <origin rpy="0  0  0" xyz="-0.0002  -0.00592  0.00952" />
      <geometry>
        <mesh filename="package://robots/rikshaw/meshes/collisions/wrist_right_1.stl" scale="0.001 0.001 0.001" />
      </geometry>
    </collision>
    <visual name="wrist_right_1_visual">
      <origin rpy="0  0  0" xyz="-0.0002  -0.00592  0.00952" />
      <geometry>
        <mesh filename="package://robots/rikshaw/meshes/visuals/wrist_right_1.stl" scale="0.001 0.001 0.001" />
      </geometry>
    </visual>
  </link>
  <link name="right_hand">
    <inertial>
      <mass value="0.08391560474704363" />
      <origin rpy="0  0  0" xyz="0.0123  -0.06191 -0.05179" />
      <inertia ixx="0.09673260828008547" ixy="-0.01642785532035098" ixz="0.04797394115153065" iyy="0.0488781699072868" iyz="0.014904604866633244" izz="0.058149691796935264" />
    </inertial>
    <collision name="right_hand_collision">
      <origin rpy="0  0  0" xyz="0.0123  -0.06191 -0.05179" />
      <geometry>
        <mesh filename="package://robots/rikshaw/meshes/collisions/right_hand.stl" scale="0.001 0.001 0.001" />
      </geometry>
    </collision>
    <visual name="right_hand_visual">
      <origin rpy="0  0  0" xyz="0.0123  -0.06191 -0.05179" />
      <geometry>
        <mesh filename="package://robots/rikshaw/meshes/visuals/right_hand.stl" scale="0.001 0.001 0.001" />
      </geometry>
    </visual>
  </link>
  <link name="upper_arm_left">
    <inertial>
      <mass value="1.1803819781445266" />
      <origin rpy="0  0  0" xyz="-0.00627  0.12298 -0.08898" />
      <inertia ixx="1.585242002687883" ixy="0.11434969923035074" ixz="-0.5429322961403309" iyy="1.4261049013852967" iyz="0.28558236377926466" izz="0.2826519290728222" />
    </inertial>
    <collision name="upper_arm_left_collision">
      <origin rpy="0  0  0" xyz="-0.00627  0.12298 -0.08898" />
      <geometry>
        <mesh filename="package://robots/rikshaw/meshes/collisions/upper_arm_left.stl" scale="0.001 0.001 0.001" />
      </geometry>
    </collision>
    <visual name="upper_arm_left_visual">
      <origin rpy="0  0  0" xyz="-0.00627  0.12298 -0.08898" />
      <geometry>
        <mesh filename="package://robots/rikshaw/meshes/visuals/upper_arm_left.stl" scale="0.001 0.001 0.001" />
      </geometry>
    </visual>
  </link>
  <link name="lower_arm_left">
    <inertial>
      <mass value="1.4159186820905578" />
      <origin rpy="0  0  0" xyz="-0.00442  0.09092 -0.07847" />
      <inertia ixx="1.6711043719939074" ixy="0.21726236763332382" ixz="-0.7959155751086089" iyy="1.1476118832810638" iyz="0.28939502409604073" izz="0.6821912770719468" />
    </inertial>
    <collision name="lower_arm_left_collision">
      <origin rpy="0  0  0" xyz="-0.00442  0.09092 -0.07847" />
      <geometry>
        <mesh filename="package://robots/rikshaw/meshes/collisions/lower_arm_left.stl" scale="0.001 0.001 0.001" />
      </geometry>
    </collision>
    <visual name="lower_arm_left_visual">
      <origin rpy="0  0  0" xyz="-0.00442  0.09092 -0.07847" />
      <geometry>
        <mesh filename="package://robots/rikshaw/meshes/visuals/lower_arm_left.stl" scale="0.001 0.001 0.001" />
      </geometry>
    </visual>
  </link>
  <link name="lower_arm_right">
    <inertial>
      <mass value="1.3992272098428604" />
      <origin rpy="0  0  0" xyz="-0.00456 -0.09373 -0.08064" />
      <inertia ixx="1.5991623337794942" ixy="-0.20662618938024316" ixz="0.753684363768859" iyy="1.1265213782471069" iyz="0.2851505374909441" izz="0.6296965516830374" />
    </inertial>
    <collision name="lower_arm_right_collision">
      <origin rpy="0  0  0" xyz="-0.00456 -0.09373 -0.08064" />
      <geometry>
        <mesh filename="package://robots/rikshaw/meshes/collisions/lower_arm_right.stl" scale="0.001 0.001 0.001" />
      </geometry>
    </collision>
    <visual name="lower_arm_right_visual">
      <origin rpy="0  0  0" xyz="-0.00456 -0.09373 -0.08064" />
      <geometry>
        <mesh filename="package://robots/rikshaw/meshes/visuals/lower_arm_right.stl" scale="0.001 0.001 0.001" />
      </geometry>
    </visual>
  </link>
  <link name="right_shoulder_link1">
    <inertial>
      <mass value="0.04674901102976101" />
      <origin rpy="0  0  0" xyz="0  0  0" />
      <inertia ixx="0.06687953509128483" ixy="-0.0028435966522462296" ixz="0.015105711571040226" iyy="0.06551484259180702" iyz="0.011909769073168024" izz="0.005854610150255846" />
    </inertial>
    <collision name="right_shoulder_link1_collision">
      <origin rpy="0  0  0" xyz="0  0  0" />
      <geometry>
        <mesh filename="package://robots/rikshaw/meshes/collisions/right_shoulder_link1.stl" scale="0.001 0.001 0.001" />
      </geometry>
    </collision>
    <visual name="right_shoulder_link1_visual">
      <origin rpy="0  0  0" xyz="0  0  0" />
      <geometry>
        <mesh filename="package://robots/rikshaw/meshes/visuals/right_shoulder_link1.stl" scale="0.001 0.001 0.001" />
      </geometry>
    </visual>
  </link>
  <link name="right_shoulder_link2">
    <inertial>
      <mass value="0.03133729588511852" />
      <origin rpy="0  0  0" xyz="0  0  0" />
      <inertia ixx="0.04483010367618182" ixy="-0.0019061524746546135" ixz="0.010125833877362215" iyy="0.04391530263166799" iyz="0.007983484076604644" izz="0.003923225072147937" />
    </inertial>
    <collision name="right_shoulder_link2_collision">
      <origin rpy="0  0  0" xyz="0  0  0" />
      <geometry>
        <mesh filename="package://robots/rikshaw/meshes/collisions/right_shoulder_link2.stl" scale="0.001 0.001 0.001" />
      </geometry>
    </collision>
    <visual name="right_shoulder_link2_visual">
      <origin rpy="0  0  0" xyz="0  0  0" />
      <geometry>
        <mesh filename="package://robots/rikshaw/meshes/visuals/right_shoulder_link2.stl" scale="0.001 0.001 0.001" />
      </geometry>
    </visual>
  </link>
  <link name="zed_camera_left_lense">
    <inertial>
      <mass value="0.005755421733357211" />
      <origin rpy="0  0  0" xyz="1.13100000e-02   2.00000000e-05  -2.20000000e-04" />
      <inertia ixx="0.013251176636323792" ixy="3.876858906286288e-05" ixz="-0.0006491587708028636" iyy="0.013266636305534263" iyz="0.0007894656332276956" izz="7.942719232827483e-05" />
    </inertial>
    <collision name="zed_camera_left_lense_collision">
      <origin rpy="0  0  0" xyz="1.13100000e-02   2.00000000e-05  -2.20000000e-04" />
      <geometry>
        <mesh filename="package://robots/rikshaw/meshes/collisions/zed_camera_left_lense.stl" scale="0.001 0.001 0.001" />
      </geometry>
    </collision>
    <visual name="zed_camera_left_lense_visual">
      <origin rpy="0  0  0" xyz="1.13100000e-02   2.00000000e-05  -2.20000000e-04" />
      <geometry>
        <mesh filename="package://robots/rikshaw/meshes/visuals/zed_camera_left_lense.stl" scale="0.001 0.001 0.001" />
      </geometry>
    </visual>
  </link>
  <link name="zed_camera_right_lense">
    <inertial>
      <mass value="0.005755421733357103" />
      <origin rpy="0  0  0" xyz="0.01131  0      -0.00022" />
      <inertia ixx="0.01323125421744619" ixy="-2.374254662672125e-05" ixz="0.00039755584390753414" iyy="0.01326663630625537" iyz="0.0007894656332470204" izz="5.9504772729015e-05" />
    </inertial>
    <collision name="zed_camera_right_lense_collision">
      <origin rpy="0  0  0" xyz="0.01131  0      -0.00022" />
      <geometry>
        <mesh filename="package://robots/rikshaw/meshes/collisions/zed_camera_right_lense.stl" scale="0.001 0.001 0.001" />
      </geometry>
    </collision>
    <visual name="zed_camera_right_lense_visual">
      <origin rpy="0  0  0" xyz="0.01131  0      -0.00022" />
      <geometry>
        <mesh filename="package://robots/rikshaw/meshes/visuals/zed_camera_right_lense.stl" scale="0.001 0.001 0.001" />
      </geometry>
    </visual>
  </link>
  <link name="zed_camera">
    <inertial>
      <mass value="0.009633908101969985" />
      <origin rpy="0  0  0" xyz="-0.00051 -0.01744 -0.00814" />
      <inertia ixx="0.02214757863539191" ixy="1.807639468020231e-05" ixz="-0.00026981613792170637" iyy="0.02223019298553637" iyz="0.0014919337341406241" izz="0.0001186047881965815" />
    </inertial>
    <collision name="zed_camera_collision">
      <origin rpy="0  0  0" xyz="-0.00051 -0.01744 -0.00814" />
      <geometry>
        <mesh filename="package://robots/rikshaw/meshes/collisions/zed_camera.stl" scale="0.001 0.001 0.001" />
      </geometry>
    </collision>
    <visual name="zed_camera_visual">
      <origin rpy="0  0  0" xyz="-0.00051 -0.01744 -0.00814" />
      <geometry>
        <mesh filename="package://robots/rikshaw/meshes/visuals/zed_camera.stl" scale="0.001 0.001 0.001" />
      </geometry>
    </visual>
  </link>
  <link name="sphere_head_link1">
    <inertial>
      <mass value="0.02393810080236979" />
      <origin rpy="0  0  0" xyz="0  0  0" />
      <inertia ixx="0.04160499755559101" ixy="7.19145924626448e-05" ixz="-0.00045510006133885777" iyy="0.0426387262617714" iyz="0.006573296422452212" izz="0.0010456442314470164" />
    </inertial>
    <collision name="sphere_head_link1_collision">
      <origin rpy="0  0  0" xyz="0  0  0" />
      <geometry>
        <mesh filename="package://robots/rikshaw/meshes/collisions/sphere_head_link1.stl" scale="0.001 0.001 0.001" />
      </geometry>
    </collision>
    <visual name="sphere_head_link1_visual">
      <origin rpy="0  0  0" xyz="0  0  0" />
      <geometry>
        <mesh filename="package://robots/rikshaw/meshes/visuals/sphere_head_link1.stl" scale="0.001 0.001 0.001" />
      </geometry>
    </visual>
  </link>
  <link name="sphere_head_link2">
    <inertial>
      <mass value="0.016046417516495715" />
      <origin rpy="0  0  0" xyz="0  0  0" />
      <inertia ixx="0.02788863341630688" ixy="4.8206479942218094e-05" ixz="-0.000305067041713818" iyy="0.028581572365603776" iyz="0.0044062751562945176" izz="0.0007004983586646253" />
    </inertial>
    <collision name="sphere_head_link2_collision">
      <origin rpy="0  0  0" xyz="0  0  0" />
      <geometry>
        <mesh filename="package://robots/rikshaw/meshes/collisions/sphere_head_link2.stl" scale="0.001 0.001 0.001" />
      </geometry>
    </collision>
    <visual name="sphere_head_link2_visual">
      <origin rpy="0  0  0" xyz="0  0  0" />
      <geometry>
        <mesh filename="package://robots/rikshaw/meshes/visuals/sphere_head_link2.stl" scale="0.001 0.001 0.001" />
      </geometry>
    </visual>
  </link>
  <link name="head">
    <inertial>
      <mass value="2.0664370230195903" />
      <origin rpy="0  0  0" xyz="-0.01048  0.00064  0.15561" />
      <inertia ixx="4.516784822650517" ixy="0.00682015432548133" ixz="-0.04602734647260561" iyy="4.620379896985018" iyz="0.6688122473703546" izz="0.12437460828210316" />
    </inertial>
    <collision name="head_collision">
      <origin rpy="0  0  0" xyz="-0.01048  0.00064  0.15561" />
      <geometry>
        <mesh filename="package://robots/rikshaw/meshes/collisions/head.stl" scale="0.001 0.001 0.001" />
      </geometry>
    </collision>
    <visual name="head_visual">
      <origin rpy="0  0  0" xyz="-0.01048  0.00064  0.15561" />
      <geometry>
        <mesh filename="package://robots/rikshaw/meshes/visuals/head.stl" scale="0.001 0.001 0.001" />
      </geometry>
    </visual>
  </link>
</robot>
