<sdf version="1.6">
	<model name="rikshaw">
		<link name="bike">
			<self_collide>false</self_collide>
			<pose frame="">-1.3108998963673458e-07 2.442664557200658e-07 1.774980865576481e-07 0.0 -0.0 0.0</pose>
			<inertial>
				<pose frame="">0.0 0.0 0.0 0 0 0</pose>
				<mass>21.819480362884757</mass>
				<inertia>
					<ixx>5.88647979750313</ixx>
					<ixy>0.052466044382052206</ixy>
					<ixz>0.14605356512826828</ixz>
					<iyy>9.145452768014158</iyy>
					<iyz>-2.309312656009525</iyz>
					<izz>3.8627003582898043</izz>
				</inertia>
			</inertial>
			<collision name="bike_collision">
				<geometry>
					<mesh>
						<uri>model://rikshaw/meshes/collisions/bike.stl</uri>
						<scale>0.001 0.001 0.001</scale>
					</mesh>
				</geometry>
			</collision>
			<visual name="bike_visual">
				<geometry>
					<mesh>
						<uri>model://rikshaw/meshes/visuals/bike.stl</uri>
						<scale>0.001 0.001 0.001</scale>
					</mesh>
				</geometry>
			</visual>
		</link>
		<link name="upper_arm_right">
			<self_collide>false</self_collide>
			<pose frame="">0.22287862401978265 0.4003629699606503 1.0738126081792558 0.0 -0.0 0.0</pose>
			<inertial>
				<pose frame="">0.0 0.0 0.0 0 0 0</pose>
				<mass>1.09455247923321</mass>
				<inertia>
					<ixx>1.442114635113044</ixx>
					<ixy>-0.09774756907521549</ixy>
					<ixz>-0.4688761464900038</ixz>
					<iyy>1.3199752604716208</iyy>
					<iyz>-0.2618914755705522</iyz>
					<izz>0.23432575661628963</izz>
				</inertia>
			</inertial>
			<collision name="upper_arm_right_collision">
				<geometry>
					<mesh>
						<uri>model://rikshaw/meshes/collisions/upper_arm_right.stl</uri>
						<scale>0.001 0.001 0.001</scale>
					</mesh>
				</geometry>
			</collision>
			<visual name="upper_arm_right_visual">
				<geometry>
					<mesh>
						<uri>model://rikshaw/meshes/visuals/upper_arm_right.stl</uri>
						<scale>0.001 0.001 0.001</scale>
					</mesh>
				</geometry>
			</visual>
		</link>
		<link name="torso">
			<self_collide>false</self_collide>
			<pose frame="">0.0 0.0 0.0 0.0 -0.0 0.0</pose>
			<inertial>
				<pose frame="">0.0 0.0 0.0 0 0 0</pose>
				<mass>12.829176243663477</mass>
				<inertia>
					<ixx>17.25650105427057</ixx>
					<ixy>0.04356904654679028</ixy>
					<ixz>0.24048016421448187</ixz>
					<iyy>17.518102091652363</iyy>
					<iyz>-2.951529784014056</iyz>
					<izz>0.8597292911212528</izz>
				</inertia>
			</inertial>
			<collision name="torso_collision">
				<geometry>
					<mesh>
						<uri>model://rikshaw/meshes/collisions/torso.stl</uri>
						<scale>0.001 0.001 0.001</scale>
					</mesh>
				</geometry>
			</collision>
			<visual name="torso_visual">
				<geometry>
					<mesh>
						<uri>model://rikshaw/meshes/visuals/torso.stl</uri>
						<scale>0.001 0.001 0.001</scale>
					</mesh>
				</geometry>
			</visual>
		</link>
		<link name="front_part">
			<self_collide>false</self_collide>
			<pose frame="">-0.716390260045379 0.010388552481776845 0.21643769422809594 0.0 -0.0 0.0</pose>
			<inertial>
				<pose frame="">0.0 0.0 0.0 0 0 0</pose>
				<mass>16.81067246564987</mass>
				<inertia>
					<ixx>3.20922967583295</ixx>
					<ixy>0.1811361599346656</ixy>
					<ixz>-0.006723082654580219</ixz>
					<iyy>14.662960288859963</iyy>
					<iyz>1.2419706811357931</iyz>
					<izz>13.912919701383359</izz>
				</inertia>
			</inertial>
			<collision name="front_part_collision">
				<geometry>
					<mesh>
						<uri>model://rikshaw/meshes/collisions/front_part.stl</uri>
						<scale>0.001 0.001 0.001</scale>
					</mesh>
				</geometry>
			</collision>
			<visual name="front_part_visual">
				<geometry>
					<mesh>
						<uri>model://rikshaw/meshes/visuals/front_part.stl</uri>
						<scale>0.001 0.001 0.001</scale>
					</mesh>
				</geometry>
			</visual>
		</link>
		<link name="left_wheel">
			<self_collide>false</self_collide>
			<pose frame="">-0.9984258521253281 -0.3500004088111488 0.04566700000000946 0.0 -0.0 0.0</pose>
			<inertial>
				<pose frame="">0.0 0.0 0.0 0 0 0</pose>
				<mass>13.340163929097853</mass>
				<inertia>
					<ixx>2.1711695314274517</ixx>
					<ixy>-4.661713033463329</ixy>
					<ixz>0.21322209220250807</ixz>
					<iyy>14.342326161889547</iyy>
					<iyz>0.608246286975286</iyz>
					<izz>15.441547158388715</izz>
				</inertia>
			</inertial>
			<collision name="left_wheel_collision">
				<geometry>
					<mesh>
						<uri>model://rikshaw/meshes/collisions/left_wheel.stl</uri>
						<scale>0.001 0.001 0.001</scale>
					</mesh>
				</geometry>
			</collision>
			<visual name="left_wheel_visual">
				<geometry>
					<mesh>
						<uri>model://rikshaw/meshes/visuals/left_wheel.stl</uri>
						<scale>0.001 0.001 0.001</scale>
					</mesh>
				</geometry>
			</visual>
		</link>
		<link name="right_wheel">
			<self_collide>false</self_collide>
			<pose frame="">-0.9984258521253281 0.34200026941711825 0.04566700000003973 0.0 -0.0 0.0</pose>
			<inertial>
				<pose frame="">0.0 0.0 0.0 0 0 0</pose>
				<mass>13.340163929097852</mass>
				<inertia>
					<ixx>2.0973170247321944</ixx>
					<ixy>4.555157860544093</ixy>
					<ixz>-0.20834836515382574</ixz>
					<iyy>14.34232616188958</iyy>
					<iyz>0.608246286975689</iyz>
					<izz>15.367694651693421</izz>
				</inertia>
			</inertial>
			<collision name="right_wheel_collision">
				<geometry>
					<mesh>
						<uri>model://rikshaw/meshes/collisions/right_wheel.stl</uri>
						<scale>0.001 0.001 0.001</scale>
					</mesh>
				</geometry>
			</collision>
			<visual name="right_wheel_visual">
				<geometry>
					<mesh>
						<uri>model://rikshaw/meshes/visuals/right_wheel.stl</uri>
						<scale>0.001 0.001 0.001</scale>
					</mesh>
				</geometry>
			</visual>
		</link>
		<link name="pedal_right">
			<self_collide>false</self_collide>
			<pose frame="">0.077866512064399 0.14798929042854536 0.17187503593715686 0.0 -0.0 0.0</pose>
			<inertial>
				<pose frame="">0.0 0.0 0.0 0 0 0</pose>
				<mass>0.946002588602011</mass>
				<inertia>
					<ixx>0.049584952858415854</ixx>
					<ixy>-0.010901175565176115</ixy>
					<ixz>-0.024062204564554247</ixz>
					<iyy>0.03409659621083961</iyy>
					<iyz>-0.012633073677194028</iyz>
					<izz>0.02706062629596726</izz>
				</inertia>
			</inertial>
			<collision name="pedal_right_collision">
				<geometry>
					<mesh>
						<uri>model://rikshaw/meshes/collisions/pedal_right.stl</uri>
						<scale>0.001 0.001 0.001</scale>
					</mesh>
				</geometry>
			</collision>
			<visual name="pedal_right_visual">
				<geometry>
					<mesh>
						<uri>model://rikshaw/meshes/visuals/pedal_right.stl</uri>
						<scale>0.001 0.001 0.001</scale>
					</mesh>
				</geometry>
			</visual>
		</link>
		<link name="kurbel">
			<self_collide>false</self_collide>
			<pose frame="">0.09222872619138603 0.00013171801209023543 0.0042772834965418725 0.0 -0.0 0.0</pose>
			<inertial>
				<pose frame="">0.0 0.0 0.0 0 0 0</pose>
				<mass>2.7832708381108002</mass>
				<inertia>
					<ixx>0.03321525556564324</ixx>
					<ixy>0.0010218101556732108</ixy>
					<ixz>-0.012937192477662387</ixz>
					<iyy>0.04158688185273832</iyy>
					<iyz>0.00030143634944108515</iyz>
					<izz>0.039731070916127355</izz>
				</inertia>
			</inertial>
			<collision name="kurbel_collision">
				<geometry>
					<mesh>
						<uri>model://rikshaw/meshes/collisions/kurbel.stl</uri>
						<scale>0.001 0.001 0.001</scale>
					</mesh>
				</geometry>
			</collision>
			<visual name="kurbel_visual">
				<geometry>
					<mesh>
						<uri>model://rikshaw/meshes/visuals/kurbel.stl</uri>
						<scale>0.001 0.001 0.001</scale>
					</mesh>
				</geometry>
			</visual>
		</link>
		<link name="pedal_left">
			<self_collide>false</self_collide>
			<pose frame="">0.10738103245690385 -0.14924470957145594 -0.16537796258198015 0.0 -0.0 0.0</pose>
			<inertial>
				<pose frame="">0.0 0.0 0.0 0 0 0</pose>
				<mass>0.9460025886020074</mass>
				<inertia>
					<ixx>0.0478650709459344</ixx>
					<ixy>0.015160685733445756</ixy>
					<ixz>-0.02334903344265402</ixz>
					<iyy>0.037196017563940593</iyy>
					<iyz>0.016827373941817436</iyz>
					<izz>0.032585937449107163</izz>
				</inertia>
			</inertial>
			<collision name="pedal_left_collision">
				<geometry>
					<mesh>
						<uri>model://rikshaw/meshes/collisions/pedal_left.stl</uri>
						<scale>0.001 0.001 0.001</scale>
					</mesh>
				</geometry>
			</collision>
			<visual name="pedal_left_visual">
				<geometry>
					<mesh>
						<uri>model://rikshaw/meshes/visuals/pedal_left.stl</uri>
						<scale>0.001 0.001 0.001</scale>
					</mesh>
				</geometry>
			</visual>
		</link>
		<link name="foot_left">
			<self_collide>false</self_collide>
			<pose frame="">0.1758335832021747 -0.18852199978740128 -0.20648446058656983 0.0 -0.0 0.0</pose>
			<inertial>
				<pose frame="">0.0 0.0 0.0 0 0 0</pose>
				<mass>0.729398908095776</mass>
				<inertia>
					<ixx>0.054071148495108426</ixx>
					<ixy>0.03251558359012369</ixy>
					<ixz>-0.0267607053444042</ixz>
					<iyy>0.06910655839384243</iyy>
					<iyz>0.0335724905553697</iyz>
					<izz>0.06736985121094373</izz>
				</inertia>
			</inertial>
			<collision name="foot_left_collision">
				<geometry>
					<mesh>
						<uri>model://rikshaw/meshes/collisions/foot_left.stl</uri>
						<scale>0.001 0.001 0.001</scale>
					</mesh>
				</geometry>
			</collision>
			<visual name="foot_left_visual">
				<geometry>
					<mesh>
						<uri>model://rikshaw/meshes/visuals/foot_left.stl</uri>
						<scale>0.001 0.001 0.001</scale>
					</mesh>
				</geometry>
			</visual>
		</link>
		<link name="foot_left_tip">
			<self_collide>false</self_collide>
			<pose frame="">0.13523838377518937 -0.18735459670189283 -0.21215746469129887 0.0 -0.0 0.0</pose>
			<inertial>
				<pose frame="">0.0 0.0 0.0 0 0 0</pose>
				<mass>0.2779608699489159</mass>
				<inertia>
					<ixx>0.022352432140469582</ixx>
					<ixy>0.007051209655785971</ixy>
					<ixz>-0.011047918197745182</ixz>
					<iyy>0.017709776432523597</iyy>
					<iyz>0.007965691481929648</iyz>
					<izz>0.015032605387340966</izz>
				</inertia>
			</inertial>
			<collision name="foot_left_tip_collision">
				<geometry>
					<mesh>
						<uri>model://rikshaw/meshes/collisions/foot_left_tip.stl</uri>
						<scale>0.001 0.001 0.001</scale>
					</mesh>
				</geometry>
			</collision>
			<visual name="foot_left_tip_visual">
				<geometry>
					<mesh>
						<uri>model://rikshaw/meshes/visuals/foot_left_tip.stl</uri>
						<scale>0.001 0.001 0.001</scale>
					</mesh>
				</geometry>
			</visual>
		</link>
		<link name="foot_right">
			<self_collide>false</self_collide>
			<pose frame="">0.17755692904068937 0.15962800036486463 -0.2048798081230718 0.0 -0.0 0.0</pose>
			<inertial>
				<pose frame="">0.0 0.0 0.0 0 0 0</pose>
				<mass>0.7293896455411302</mass>
				<inertia>
					<ixx>0.04662856715772369</ixx>
					<ixy>-0.027737155016923216</ixy>
					<ixz>0.022589445195432944</ixz>
					<iyy>0.06999772599908857</iyy>
					<iyz>0.03393990029859617</iyz>
					<izz>0.06080289056176407</izz>
				</inertia>
			</inertial>
			<collision name="foot_right_collision">
				<geometry>
					<mesh>
						<uri>model://rikshaw/meshes/collisions/foot_right.stl</uri>
						<scale>0.001 0.001 0.001</scale>
					</mesh>
				</geometry>
			</collision>
			<visual name="foot_right_visual">
				<geometry>
					<mesh>
						<uri>model://rikshaw/meshes/visuals/foot_right.stl</uri>
						<scale>0.001 0.001 0.001</scale>
					</mesh>
				</geometry>
			</visual>
		</link>
		<link name="foot_right_tip">
			<self_collide>false</self_collide>
			<pose frame="">0.13747575841859594 0.1579606226871027 -0.21111014880223608 0.0 -0.0 0.0</pose>
			<inertial>
				<pose frame="">0.0 0.0 0.0 0 0 0</pose>
				<mass>0.2779507369992495</mass>
				<inertia>
					<ixx>0.01940696459090884</ixx>
					<ixy>-0.006044281399509727</ixy>
					<ixz>0.00926827632383988</ixz>
					<iyy>0.017755497306462906</iyy>
					<iyz>0.008058438745184105</iyz>
					<izz>0.012380586242452805</izz>
				</inertia>
			</inertial>
			<collision name="foot_right_tip_collision">
				<geometry>
					<mesh>
						<uri>model://rikshaw/meshes/collisions/foot_right_tip.stl</uri>
						<scale>0.001 0.001 0.001</scale>
					</mesh>
				</geometry>
			</collision>
			<visual name="foot_right_tip_visual">
				<geometry>
					<mesh>
						<uri>model://rikshaw/meshes/visuals/foot_right_tip.stl</uri>
						<scale>0.001 0.001 0.001</scale>
					</mesh>
				</geometry>
			</visual>
		</link>
		<link name="thigh_right">
			<self_collide>false</self_collide>
			<pose frame="">0.22880969633365464 0.18383575209433126 0.37789734135697756 0.0 -0.0 0.0</pose>
			<inertial>
				<pose frame="">0.0 0.0 0.0 0 0 0</pose>
				<mass>5.563526842051087</mass>
				<inertia>
					<ixx>1.010776410644986</ixx>
					<ixy>-0.23394788163488325</ixy>
					<ixz>-0.38955605197647547</ixz>
					<iyy>1.116930895029097</iyy>
					<iyz>-0.4818325951246939</iyz>
					<izz>0.4914242463875166</izz>
				</inertia>
			</inertial>
			<collision name="thigh_right_collision">
				<geometry>
					<mesh>
						<uri>model://rikshaw/meshes/collisions/thigh_right.stl</uri>
						<scale>0.001 0.001 0.001</scale>
					</mesh>
				</geometry>
			</collision>
			<visual name="thigh_right_visual">
				<geometry>
					<mesh>
						<uri>model://rikshaw/meshes/visuals/thigh_right.stl</uri>
						<scale>0.001 0.001 0.001</scale>
					</mesh>
				</geometry>
			</visual>
		</link>
		<link name="thigh_left">
			<self_collide>false</self_collide>
			<pose frame="">0.2292806537639528 -0.2126277495925066 0.37790689387442783 0.0 -0.0 0.0</pose>
			<inertial>
				<pose frame="">0.0 0.0 0.0 0 0 0</pose>
				<mass>5.56358906512719</mass>
				<inertia>
					<ixx>1.0743469445640734</ixx>
					<ixy>0.2706115436993354</ixy>
					<ixz>0.4500933625889936</ixz>
					<iyy>1.1181844164691626</iyy>
					<iyz>-0.4831067929963112</iyz>
					<izz>0.5561292948599905</izz>
				</inertia>
			</inertial>
			<collision name="thigh_left_collision">
				<geometry>
					<mesh>
						<uri>model://rikshaw/meshes/collisions/thigh_left.stl</uri>
						<scale>0.001 0.001 0.001</scale>
					</mesh>
				</geometry>
			</collision>
			<visual name="thigh_left_visual">
				<geometry>
					<mesh>
						<uri>model://rikshaw/meshes/visuals/thigh_left.stl</uri>
						<scale>0.001 0.001 0.001</scale>
					</mesh>
				</geometry>
			</visual>
		</link>
		<link name="leg_right">
			<self_collide>false</self_collide>
			<pose frame="">0.23291230336919502 0.18326545464147428 0.02997274572871179 0.0 -0.0 0.0</pose>
			<inertial>
				<pose frame="">0.0 0.0 0.0 0 0 0</pose>
				<mass>5.741522183296272</mass>
				<inertia>
					<ixx>0.23781953163587924</ixx>
					<ixy>-0.24551774910333893</ixy>
					<ixz>-0.03496958960490945</ixz>
					<iyy>0.3593991546848349</iyy>
					<iyz>-0.03759074399885916</iyz>
					<izz>0.5167551685561281</izz>
				</inertia>
			</inertial>
			<collision name="leg_right_collision">
				<geometry>
					<mesh>
						<uri>model://rikshaw/meshes/collisions/leg_right.stl</uri>
						<scale>0.001 0.001 0.001</scale>
					</mesh>
				</geometry>
			</collision>
			<visual name="leg_right_visual">
				<geometry>
					<mesh>
						<uri>model://rikshaw/meshes/visuals/leg_right.stl</uri>
						<scale>0.001 0.001 0.001</scale>
					</mesh>
				</geometry>
			</visual>
		</link>
		<link name="leg_left">
			<self_collide>false</self_collide>
			<pose frame="">0.23204399961628525 -0.21169134870002534 0.03008518965509079 0.0 -0.0 0.0</pose>
			<inertial>
				<pose frame="">0.0 0.0 0.0 0 0 0</pose>
				<mass>5.7426173662328</mass>
				<inertia>
					<ixx>0.3024368006754475</ixx>
					<ixy>0.28199913616735084</ixy>
					<ixz>0.040011871670719415</ixz>
					<iyy>0.357202809628062</iyy>
					<iyz>-0.03813052890420756</iyz>
					<izz>0.5789432910018966</izz>
				</inertia>
			</inertial>
			<collision name="leg_left_collision">
				<geometry>
					<mesh>
						<uri>model://rikshaw/meshes/collisions/leg_left.stl</uri>
						<scale>0.001 0.001 0.001</scale>
					</mesh>
				</geometry>
			</collision>
			<visual name="leg_left_visual">
				<geometry>
					<mesh>
						<uri>model://rikshaw/meshes/visuals/leg_left.stl</uri>
						<scale>0.001 0.001 0.001</scale>
					</mesh>
				</geometry>
			</visual>
		</link>
		<link name="wheel_back">
			<self_collide>false</self_collide>
			<pose frame="">0.53689742860369 0.0035499556212922633 0.049415870249024677 0.0 -0.0 0.0</pose>
			<inertial>
				<pose frame="">0.0 0.0 0.0 0 0 0</pose>
				<mass>13.340163929098475</mass>
				<inertia>
					<ixx>0.5419188938328752</ixx>
					<ixy>-0.02542584611932503</ixy>
					<ixz>-0.0023401868697195947</ixz>
					<iyy>4.894303401629515</iyy>
					<iyz>-0.3539312731878215</iyz>
					<izz>4.3547634684642125</izz>
				</inertia>
			</inertial>
			<collision name="wheel_back_collision">
				<geometry>
					<mesh>
						<uri>model://rikshaw/meshes/collisions/wheel_back.stl</uri>
						<scale>0.001 0.001 0.001</scale>
					</mesh>
				</geometry>
			</collision>
			<visual name="wheel_back_visual">
				<geometry>
					<mesh>
						<uri>model://rikshaw/meshes/visuals/wheel_back.stl</uri>
						<scale>0.001 0.001 0.001</scale>
					</mesh>
				</geometry>
			</visual>
		</link>
		<link name="elbow_left">
			<self_collide>false</self_collide>
			<pose frame="">0.2306640950991497 -0.5401171716152683 0.9674697426324589 0.0 -0.0 0.0</pose>
			<inertial>
				<pose frame="">0.0 0.0 0.0 0 0 0</pose>
				<mass>0.15681540300142793</mass>
				<inertia>
					<ixx>0.19266629452448158</ixx>
					<ixy>0.0195417941766464</ixy>
					<ixz>0.08195067997388937</ixz>
					<iyy>0.1552331044117411</iyy>
					<iyz>-0.03499484398504671</iyz>
					<izz>0.054226846547573475</izz>
				</inertia>
			</inertial>
			<collision name="elbow_left_collision">
				<geometry>
					<mesh>
						<uri>model://rikshaw/meshes/collisions/elbow_left.stl</uri>
						<scale>0.001 0.001 0.001</scale>
					</mesh>
				</geometry>
			</collision>
			<visual name="elbow_left_visual">
				<geometry>
					<mesh>
						<uri>model://rikshaw/meshes/visuals/elbow_left.stl</uri>
						<scale>0.001 0.001 0.001</scale>
					</mesh>
				</geometry>
			</visual>
		</link>
		<link name="elbow_right">
			<self_collide>false</self_collide>
			<pose frame="">0.23072493962985935 0.5136902878611298 0.9649761382442716 0.0 -0.0 0.0</pose>
			<inertial>
				<pose frame="">0.0 0.0 0.0 0 0 0</pose>
				<mass>0.17350645372007023</mass>
				<inertia>
					<ixx>0.20750006127745746</ixx>
					<ixy>-0.020569149555644393</ixy>
					<ixz>-0.08601032502390117</ixz>
					<iyy>0.17091901706305593</iyy>
					<iyz>-0.03862989297418956</iyz>
					<izz>0.055162497229075506</izz>
				</inertia>
			</inertial>
			<collision name="elbow_right_collision">
				<geometry>
					<mesh>
						<uri>model://rikshaw/meshes/collisions/elbow_right.stl</uri>
						<scale>0.001 0.001 0.001</scale>
					</mesh>
				</geometry>
			</collision>
			<visual name="elbow_right_visual">
				<geometry>
					<mesh>
						<uri>model://rikshaw/meshes/visuals/elbow_right.stl</uri>
						<scale>0.001 0.001 0.001</scale>
					</mesh>
				</geometry>
			</visual>
		</link>
		<link name="left_shoulder_link1">
			<self_collide>false</self_collide>
			<pose frame="">0.21902263548985093 -0.30660196157336944 1.1633275683196005 0.0 -0.0 0.0</pose>
			<inertial>
				<pose frame="">0.0 0.0 0.0 0 0 0</pose>
				<mass>0.046753530242572526</mass>
				<inertia>
					<ixx>0.06767403176162043</ixx>
					<ixy>0.0031396290483470734</ixy>
					<ixz>0.016675979709794873</ixz>
					<iyy>0.06552178683987907</iyy>
					<iyz>-0.011912569008629326</iyz>
					<izz>0.006643838018602061</izz>
				</inertia>
			</inertial>
			<collision name="left_shoulder_link1_collision">
				<geometry>
					<mesh>
						<uri>model://rikshaw/meshes/collisions/left_shoulder_link1.stl</uri>
						<scale>0.001 0.001 0.001</scale>
					</mesh>
				</geometry>
			</collision>
			<visual name="left_shoulder_link1_visual">
				<geometry>
					<mesh>
						<uri>model://rikshaw/meshes/visuals/left_shoulder_link1.stl</uri>
						<scale>0.001 0.001 0.001</scale>
					</mesh>
				</geometry>
			</visual>
		</link>
		<link name="left_shoulder_link2">
			<self_collide>false</self_collide>
			<pose frame="">0.21902247986062384 -0.30660087035922695 1.1633275703369779 0.0 -0.0 0.0</pose>
			<inertial>
				<pose frame="">0.0 0.0 0.0 0 0 0</pose>
				<mass>0.03133730384743737</mass>
				<inertia>
					<ixx>0.04535827893996492</ixx>
					<ixy>0.0021043777578654633</ixy>
					<ixz>0.011177303220150906</ixz>
					<iyy>0.043915721516588194</iyy>
					<iyz>-0.00798458486619213</iyz>
					<izz>0.004451810061398645</izz>
				</inertia>
			</inertial>
			<collision name="left_shoulder_link2_collision">
				<geometry>
					<mesh>
						<uri>model://rikshaw/meshes/collisions/left_shoulder_link2.stl</uri>
						<scale>0.001 0.001 0.001</scale>
					</mesh>
				</geometry>
			</collision>
			<visual name="left_shoulder_link2_visual">
				<geometry>
					<mesh>
						<uri>model://rikshaw/meshes/visuals/left_shoulder_link2.stl</uri>
						<scale>0.001 0.001 0.001</scale>
					</mesh>
				</geometry>
			</visual>
		</link>
		<link name="wrist_left_1">
			<self_collide>false</self_collide>
			<pose frame="">0.24088559117788702 -0.7562839321440314 0.774530851841674 0.0 -0.0 0.0</pose>
			<inertial>
				<pose frame="">0.0 0.0 0.0 0 0 0</pose>
				<mass>0.012762217633342557</mass>
				<inertia>
					<ixx>0.014959120890854383</ixx>
					<ixy>0.002324972046736957</ixy>
					<ixz>0.007477062127211706</ixz>
					<iyy>0.008400753322856894</iyy>
					<iyz>-0.0023811669065757295</iyz>
					<izz>0.008043969436768382</izz>
				</inertia>
			</inertial>
			<collision name="wrist_left_1_collision">
				<geometry>
					<mesh>
						<uri>model://rikshaw/meshes/collisions/wrist_left_1.stl</uri>
						<scale>0.001 0.001 0.001</scale>
					</mesh>
				</geometry>
			</collision>
			<visual name="wrist_left_1_visual">
				<geometry>
					<mesh>
						<uri>model://rikshaw/meshes/visuals/wrist_left_1.stl</uri>
						<scale>0.001 0.001 0.001</scale>
					</mesh>
				</geometry>
			</visual>
		</link>
		<link name="left_hand">
			<self_collide>false</self_collide>
			<pose frame="">0.247282862176359 -0.8144876502163109 0.7177980110804164 0.0 -0.0 0.0</pose>
			<inertial>
				<pose frame="">0.0 0.0 0.0 0 0 0</pose>
				<mass>0.08391816593462983</mass>
				<inertia>
					<ixx>0.09909320434120036</ixx>
					<ixy>0.016915090376039513</ixy>
					<ixz>0.048980966391204535</ixz>
					<iyy>0.048505356256449084</iyy>
					<iyz>-0.01487737090918695</iyz>
					<izz>0.06095877796136134</izz>
				</inertia>
			</inertial>
			<collision name="left_hand_collision">
				<geometry>
					<mesh>
						<uri>model://rikshaw/meshes/collisions/left_hand.stl</uri>
						<scale>0.001 0.001 0.001</scale>
					</mesh>
				</geometry>
			</collision>
			<visual name="left_hand_visual">
				<geometry>
					<mesh>
						<uri>model://rikshaw/meshes/visuals/left_hand.stl</uri>
						<scale>0.001 0.001 0.001</scale>
					</mesh>
				</geometry>
			</visual>
		</link>
		<link name="wrist_right_1">
			<self_collide>false</self_collide>
			<pose frame="">0.2410865350895292 0.7319764010852948 0.7744472676285281 0.0 -0.0 0.0</pose>
			<inertial>
				<pose frame="">0.0 0.0 0.0 0 0 0</pose>
				<mass>0.012761782896867233</mass>
				<inertia>
					<ixx>0.014495291225078663</ixx>
					<ixy>-0.002252026307743208</ixy>
					<ixz>-0.007235743263019458</ixz>
					<iyy>0.008400173050448542</iyy>
					<iyz>-0.0023827992689265253</iyz>
					<izz>0.007583137992308799</izz>
				</inertia>
			</inertial>
			<collision name="wrist_right_1_collision">
				<geometry>
					<mesh>
						<uri>model://rikshaw/meshes/collisions/wrist_right_1.stl</uri>
						<scale>0.001 0.001 0.001</scale>
					</mesh>
				</geometry>
			</collision>
			<visual name="wrist_right_1_visual">
				<geometry>
					<mesh>
						<uri>model://rikshaw/meshes/visuals/wrist_right_1.stl</uri>
						<scale>0.001 0.001 0.001</scale>
					</mesh>
				</geometry>
			</visual>
		</link>
		<link name="right_hand">
			<self_collide>false</self_collide>
			<pose frame="">0.2463020952284976 0.7938444032809479 0.7213588372773556 0.0 -0.0 0.0</pose>
			<inertial>
				<pose frame="">0.0 0.0 0.0 0 0 0</pose>
				<mass>0.08391622141997471</mass>
				<inertia>
					<ixx>0.09673331577568908</ixx>
					<ixy>-0.016427975920384325</ixy>
					<ixz>-0.04797429263668558</ixz>
					<iyy>0.0488785196891631</iyy>
					<iyz>-0.014904711928062248</iyz>
					<izz>0.05815012342983344</izz>
				</inertia>
			</inertial>
			<collision name="right_hand_collision">
				<geometry>
					<mesh>
						<uri>model://rikshaw/meshes/collisions/right_hand.stl</uri>
						<scale>0.001 0.001 0.001</scale>
					</mesh>
				</geometry>
			</collision>
			<visual name="right_hand_visual">
				<geometry>
					<mesh>
						<uri>model://rikshaw/meshes/visuals/right_hand.stl</uri>
						<scale>0.001 0.001 0.001</scale>
					</mesh>
				</geometry>
			</visual>
		</link>
		<link name="upper_arm_left">
			<self_collide>false</self_collide>
			<pose frame="">0.22529597862550976 -0.42958880384163756 1.074343844206896 0.0 -0.0 0.0</pose>
			<inertial>
				<pose frame="">0.0 0.0 0.0 0 0 0</pose>
				<mass>1.1803838170765908</mass>
				<inertia>
					<ixx>1.5852445346771415</ixx>
					<ixy>0.11434979829456188</ixy>
					<ixz>0.5429329624802077</ixz>
					<iyy>1.4261073107265458</iyy>
					<iyz>-0.2855827227702544</iyz>
					<izz>0.2826521534806978</izz>
				</inertia>
			</inertial>
			<collision name="upper_arm_left_collision">
				<geometry>
					<mesh>
						<uri>model://rikshaw/meshes/collisions/upper_arm_left.stl</uri>
						<scale>0.001 0.001 0.001</scale>
					</mesh>
				</geometry>
			</collision>
			<visual name="upper_arm_left_visual">
				<geometry>
					<mesh>
						<uri>model://rikshaw/meshes/visuals/upper_arm_left.stl</uri>
						<scale>0.001 0.001 0.001</scale>
					</mesh>
				</geometry>
			</visual>
		</link>
		<link name="lower_arm_left">
			<self_collide>false</self_collide>
			<pose frame="">0.23575540410989257 -0.6503756188618909 0.867355634752885 0.0 -0.0 0.0</pose>
			<inertial>
				<pose frame="">0.0 0.0 0.0 0 0 0</pose>
				<mass>1.4159186820902163</mass>
				<inertia>
					<ixx>1.6711043720010217</ixx>
					<ixy>0.21726236762087098</ixy>
					<ixz>0.7959155751126917</ixz>
					<iyy>1.1476118832729991</iyy>
					<iyz>-0.28939502407711376</iyz>
					<izz>0.6821912770654517</izz>
				</inertia>
			</inertial>
			<collision name="lower_arm_left_collision">
				<geometry>
					<mesh>
						<uri>model://rikshaw/meshes/collisions/lower_arm_left.stl</uri>
						<scale>0.001 0.001 0.001</scale>
					</mesh>
				</geometry>
			</collision>
			<visual name="lower_arm_left_visual">
				<geometry>
					<mesh>
						<uri>model://rikshaw/meshes/visuals/lower_arm_left.stl</uri>
						<scale>0.001 0.001 0.001</scale>
					</mesh>
				</geometry>
			</visual>
		</link>
		<link name="lower_arm_right">
			<self_collide>false</self_collide>
			<pose frame="">0.23591830318609674 0.6254849907381432 0.8642177203000108 0.0 -0.0 0.0</pose>
			<inertial>
				<pose frame="">0.0 0.0 0.0 0 0 0</pose>
				<mass>1.3992272098428604</mass>
				<inertia>
					<ixx>1.5991623337798295</ixx>
					<ixy>-0.2066261893802688</ixy>
					<ixz>-0.753684363769014</ixz>
					<iyy>1.1265213782473609</iyy>
					<iyz>-0.28515053749097663</iyz>
					<izz>0.6296965516831181</izz>
				</inertia>
			</inertial>
			<collision name="lower_arm_right_collision">
				<geometry>
					<mesh>
						<uri>model://rikshaw/meshes/collisions/lower_arm_right.stl</uri>
						<scale>0.001 0.001 0.001</scale>
					</mesh>
				</geometry>
			</collision>
			<visual name="lower_arm_right_visual">
				<geometry>
					<mesh>
						<uri>model://rikshaw/meshes/visuals/lower_arm_right.stl</uri>
						<scale>0.001 0.001 0.001</scale>
					</mesh>
				</geometry>
			</visual>
		</link>
		<link name="right_shoulder_link1">
			<self_collide>false</self_collide>
			<pose frame="">0.21899229309963897 0.2777611123103101 1.163327655279157 0.0 -0.0 0.0</pose>
			<inertial>
				<pose frame="">0.0 0.0 0.0 0 0 0</pose>
				<mass>0.046749002886596384</mass>
				<inertia>
					<ixx>0.0668796020851593</ixx>
					<ixy>-0.0028436269903427762</ixy>
					<ixz>-0.015105873634725039</ixz>
					<iyy>0.06551483087487732</iyy>
					<iyz>-0.011909766198106813</iyz>
					<izz>0.005854687475636317</izz>
				</inertia>
			</inertial>
			<collision name="right_shoulder_link1_collision">
				<geometry>
					<mesh>
						<uri>model://rikshaw/meshes/collisions/right_shoulder_link1.stl</uri>
						<scale>0.001 0.001 0.001</scale>
					</mesh>
				</geometry>
			</collision>
			<visual name="right_shoulder_link1_visual">
				<geometry>
					<mesh>
						<uri>model://rikshaw/meshes/visuals/right_shoulder_link1.stl</uri>
						<scale>0.001 0.001 0.001</scale>
					</mesh>
				</geometry>
			</visual>
		</link>
		<link name="right_shoulder_link2">
			<self_collide>false</self_collide>
			<pose frame="">0.21899228406128005 0.2777607801421144 1.1633276552845175 0.0 -0.0 0.0</pose>
			<inertial>
				<pose frame="">0.0 0.0 0.0 0 0 0</pose>
				<mass>0.031337303847116804</mass>
				<inertia>
					<ixx>0.044830156212659796</ixx>
					<ixy>-0.0019061688408127894</ixy>
					<ixz>-0.01012592262164037</ixz>
					<iyy>0.043915313236125075</iyy>
					<iyz>-0.007983484644614952</iyz>
					<izz>0.003923266667258534</izz>
				</inertia>
			</inertial>
			<collision name="right_shoulder_link2_collision">
				<geometry>
					<mesh>
						<uri>model://rikshaw/meshes/collisions/right_shoulder_link2.stl</uri>
						<scale>0.001 0.001 0.001</scale>
					</mesh>
				</geometry>
			</collision>
			<visual name="right_shoulder_link2_visual">
				<geometry>
					<mesh>
						<uri>model://rikshaw/meshes/visuals/right_shoulder_link2.stl</uri>
						<scale>0.001 0.001 0.001</scale>
					</mesh>
				</geometry>
			</visual>
		</link>
		<link name="zed_camera_left_lense">
			<self_collide>false</self_collide>
			<pose frame="">0.09050895003980906 -0.07442372550153037 1.5155224302657617 0.0 -0.0 0.0</pose>
			<inertial>
				<pose frame="">0.0 0.0 0.0 0 0 0</pose>
				<mass>0.005755421818056277</mass>
				<inertia>
					<ixx>0.013251176831653201</ixx>
					<ixy>3.8768589463782255e-05</ixy>
					<ixz>0.0006491587768829331</ixz>
					<iyy>0.013266636501492101</iyy>
					<iyz>-0.0007894656460929536</iyz>
					<izz>7.942719339666764e-05</izz>
				</inertia>
			</inertial>
			<collision name="zed_camera_left_lense_collision">
				<geometry>
					<mesh>
						<uri>model://rikshaw/meshes/collisions/zed_camera_left_lense.stl</uri>
						<scale>0.001 0.001 0.001</scale>
					</mesh>
				</geometry>
			</collision>
			<visual name="zed_camera_left_lense_visual">
				<geometry>
					<mesh>
						<uri>model://rikshaw/meshes/visuals/zed_camera_left_lense.stl</uri>
						<scale>0.001 0.001 0.001</scale>
					</mesh>
				</geometry>
			</visual>
		</link>
		<link name="zed_camera_right_lense">
			<self_collide>false</self_collide>
			<pose frame="">0.09050895003954786 0.04557835189286703 1.5155224303071282 0.0 -0.0 0.0</pose>
			<inertial>
				<pose frame="">0.0 0.0 0.0 0 0 0</pose>
				<mass>0.0057554218180561716</mass>
				<inertia>
					<ixx>0.013231254412614635</ixx>
					<ixy>-2.3742546783151577e-05</ixy>
					<ixz>-0.0003975558462797777</ixz>
					<iyy>0.013266636502212869</iyy>
					<iyz>-0.0007894656461122461</iyz>
					<izz>5.950477363678162e-05</izz>
				</inertia>
			</inertial>
			<collision name="zed_camera_right_lense_collision">
				<geometry>
					<mesh>
						<uri>model://rikshaw/meshes/collisions/zed_camera_right_lense.stl</uri>
						<scale>0.001 0.001 0.001</scale>
					</mesh>
				</geometry>
			</collision>
			<visual name="zed_camera_right_lense_visual">
				<geometry>
					<mesh>
						<uri>model://rikshaw/meshes/visuals/zed_camera_right_lense.stl</uri>
						<scale>0.001 0.001 0.001</scale>
					</mesh>
				</geometry>
			</visual>
		</link>
		<link name="zed_camera">
			<self_collide>false</self_collide>
			<pose frame="">0.10218003663699063 -0.01847966390303911 1.5155933282605139 0.0 -0.0 0.0</pose>
			<inertial>
				<pose frame="">0.0 0.0 0.0 0 0 0</pose>
				<mass>0.009633908101970077</mass>
				<inertia>
					<ixx>0.022147578635390432</ixx>
					<ixy>1.8076394680573262e-05</ixy>
					<ixz>0.0002698161379215394</ixz>
					<iyy>0.02223019298553041</iyy>
					<iyz>-0.0014919337341075076</iyz>
					<izz>0.00011860478819208992</izz>
				</inertia>
			</inertial>
			<collision name="zed_camera_collision">
				<geometry>
					<mesh>
						<uri>model://rikshaw/meshes/collisions/zed_camera.stl</uri>
						<scale>0.001 0.001 0.001</scale>
					</mesh>
				</geometry>
			</collision>
			<visual name="zed_camera_visual">
				<geometry>
					<mesh>
						<uri>model://rikshaw/meshes/visuals/zed_camera.stl</uri>
						<scale>0.001 0.001 0.001</scale>
					</mesh>
				</geometry>
			</visual>
		</link>
		<link name="sphere_head_link1">
			<self_collide>false</self_collide>
			<pose frame="">0.20830602314000896 -0.014422000441736547 1.318231539134621 0.0 -0.0 0.0</pose>
			<inertial>
				<pose frame="">0.0 0.0 0.0 0 0 0</pose>
				<mass>0.0239381008023698</mass>
				<inertia>
					<ixx>0.04160499755559109</ixx>
					<ixy>7.1914592462645e-05</ixy>
					<ixz>0.0004551000613388576</ixz>
					<iyy>0.04263872626177148</iyy>
					<iyz>-0.006573296422452246</iyz>
					<izz>0.0010456442314470246</izz>
				</inertia>
			</inertial>
			<collision name="sphere_head_link1_collision">
				<geometry>
					<mesh>
						<uri>model://rikshaw/meshes/collisions/sphere_head_link1.stl</uri>
						<scale>0.001 0.001 0.001</scale>
					</mesh>
				</geometry>
			</collision>
			<visual name="sphere_head_link1_visual">
				<geometry>
					<mesh>
						<uri>model://rikshaw/meshes/visuals/sphere_head_link1.stl</uri>
						<scale>0.001 0.001 0.001</scale>
					</mesh>
				</geometry>
			</visual>
		</link>
		<link name="sphere_head_link2">
			<self_collide>false</self_collide>
			<pose frame="">0.20830602314000882 -0.014422000441736551 1.3182315391346213 0.0 -0.0 0.0</pose>
			<inertial>
				<pose frame="">0.0 0.0 0.0 0 0 0</pose>
				<mass>0.016046417516495708</mass>
				<inertia>
					<ixx>0.027888633416306888</ixx>
					<ixy>4.82064799422182e-05</ixy>
					<ixz>0.00030506704171381774</ixz>
					<iyy>0.02858157236560378</iyy>
					<iyz>-0.004406275156294533</iyz>
					<izz>0.0007004983586646301</izz>
				</inertia>
			</inertial>
			<collision name="sphere_head_link2_collision">
				<geometry>
					<mesh>
						<uri>model://rikshaw/meshes/collisions/sphere_head_link2.stl</uri>
						<scale>0.001 0.001 0.001</scale>
					</mesh>
				</geometry>
			</collision>
			<visual name="sphere_head_link2_visual">
				<geometry>
					<mesh>
						<uri>model://rikshaw/meshes/visuals/sphere_head_link2.stl</uri>
						<scale>0.001 0.001 0.001</scale>
					</mesh>
				</geometry>
			</visual>
		</link>
		<link name="head">
			<self_collide>false</self_collide>
			<pose frame="">0.21879112509353926 -0.015071180506464181 1.473849953958155 0.0 -0.0 0.0</pose>
			<inertial>
				<pose frame="">0.0 0.0 0.0 0 0 0</pose>
				<mass>2.0664114767603747</mass>
				<inertia>
					<ixx>4.516723647125966</ixx>
					<ixy>0.00682006891216185</ixy>
					<ixz>0.046026757318554906</ixz>
					<iyy>4.620317474855017</iyy>
					<iyz>-0.6688033041466639</iyz>
					<izz>0.12437320485348337</izz>
				</inertia>
			</inertial>
			<collision name="head_collision">
				<geometry>
					<mesh>
						<uri>model://rikshaw/meshes/collisions/head.stl</uri>
						<scale>0.001 0.001 0.001</scale>
					</mesh>
				</geometry>
			</collision>
			<visual name="head_visual">
				<geometry>
					<mesh>
						<uri>model://rikshaw/meshes/visuals/head.stl</uri>
						<scale>0.001 0.001 0.001</scale>
					</mesh>
				</geometry>
			</visual>
		</link>
		<joint name="right_wrist_0" type="revolute">
			<parent>lower_arm_right</parent>
			<child>wrist_right_1</child>
			<pose frame="">-0.00020591120382142946 -0.005919277390208464 -0.009525895488922487 0 0 0</pose>
			<axis>
				<xyz>-0.023461713055419463 -0.6321241248586623 -0.7745118713048712</xyz>
				<limit>
					<lower>-0.5235987755982988</lower>
					<upper>0.5235987755982988</upper>
				</limit>
				<use_parent_model_frame>0</use_parent_model_frame>
			</axis>
		</joint>
		<joint name="right_wrist_1" type="revolute">
			<parent>wrist_right_1</parent>
			<child>right_hand</child>
			<pose frame="">0.012307766976632948 -0.06191754605517602 0.051791771576053525 0 0 0</pose>
			<axis>
				<xyz>0.9990223047052151 -0.04386113030445874 0.005534975148719472</xyz>
				<limit>
					<lower>-0.5235987755982988</lower>
					<upper>0.5235987755982988</upper>
				</limit>
				<use_parent_model_frame>0</use_parent_model_frame>
			</axis>
		</joint>
		<joint name="zed_camera_mount" type="fixed">
			<parent>head</parent>
			<child>zed_camera</child>
			<pose frame="">-0.0005121610898689078 -0.01744198483982812 0.008148669928214645 0 0 0</pose>
		</joint>
		<joint name="elbow_left_rot1" type="revolute">
			<parent>elbow_left</parent>
			<child>lower_arm_left</child>
			<pose frame="">-0.004427718742715427 0.09092040742079448 0.07847955111771157 0 0 0</pose>
			<axis>
				<xyz>0.03688002228788129 -0.7578073498002852 -0.6514352496946373</xyz>
				<limit>
					<lower>-1.5707963267948966</lower>
					<upper>1.5707963267948966</upper>
				</limit>
				<use_parent_model_frame>0</use_parent_model_frame>
			</axis>
		</joint>
		<joint name="elbow_left_rot0" type="revolute">
			<parent>upper_arm_left</parent>
			<child>elbow_left</child>
			<pose frame="">-0.006143913369986791 0.019033077098144703 0.03504187379110675 0 0 0</pose>
			<axis>
				<xyz>-0.035352179445318495 0.6504813218360854 -0.7586990663964502</xyz>
				<limit>
					<lower>0.0</lower>
					<upper>1.5707963267948966</upper>
				</limit>
				<use_parent_model_frame>0</use_parent_model_frame>
			</axis>
		</joint>
		<joint name="left_shoulder_axis0" type="revolute">
			<parent>torso</parent>
			<child>left_shoulder_link1</child>
			<pose frame="">-1.2122699509120593e-07 -9.49504689629066e-08 2.0440650416730933e-09 0 0 0</pose>
			<axis>
				<xyz>0.050975679058603535 -0.9986354432779868 -0.011345993720010035</xyz>
				<limit>
					<lower>-3.141592653589793</lower>
					<upper>3.141592653589793</upper>
				</limit>
				<use_parent_model_frame>0</use_parent_model_frame>
			</axis>
		</joint>
		<joint name="left_shoulder_axis1" type="revolute">
			<parent>left_shoulder_link1</parent>
			<child>left_shoulder_link2</child>
			<pose frame="">3.440223238726503e-08 -1.1861646111555047e-06 2.66869903953193e-11 0 0 0</pose>
			<axis>
				<xyz>0.9986941911138321 0.05101049432270832 -0.0028003757679576683</xyz>
				<limit>
					<lower>-3.141592653589793</lower>
					<upper>3.141592653589793</upper>
				</limit>
				<use_parent_model_frame>0</use_parent_model_frame>
			</axis>
		</joint>
		<joint name="left_shoulder_axis2" type="revolute">
			<parent>left_shoulder_link2</parent>
			<child>upper_arm_left</child>
			<pose frame="">-0.006273465478780658 0.12298674726078908 0.08898372615990098 0 0 0</pose>
			<axis>
				<xyz>0.036880022287882085 -0.7578073498002895 -0.6514352496946403</xyz>
				<limit>
					<lower>-3.141592653589793</lower>
					<upper>3.141592653589793</upper>
				</limit>
				<use_parent_model_frame>0</use_parent_model_frame>
			</axis>
		</joint>
		<joint name="zed_camera_right" type="fixed">
			<parent>zed_camera</parent>
			<child>zed_camera_right_lense</child>
			<pose frame="">0.011315212787613103 3.254635227989411e-10 0.00022109515587516172 0 0 0</pose>
		</joint>
		<joint name="zed_camera_left" type="fixed">
			<parent>zed_camera</parent>
			<child>zed_camera_left_lense</child>
			<pose frame="">0.011315212790530023 1.9888224031641146e-05 0.00022109500656398496 0 0 0</pose>
		</joint>
		<joint name="elbow_right_rot0" type="revolute">
			<parent>upper_arm_right</parent>
			<child>elbow_right</child>
			<pose frame="">-0.006179633668625257 -0.02031194058546447 0.03655841045700825 0 0 0</pose>
			<axis>
				<xyz>0.03535217943919201 0.6504813211160858 0.7586990670140391</xyz>
				<limit>
					<lower>0.0</lower>
					<upper>1.5707963267948966</upper>
				</limit>
				<use_parent_model_frame>0</use_parent_model_frame>
			</axis>
		</joint>
		<joint name="right_shoulder_axis0" type="revolute">
			<parent>torso</parent>
			<child>right_shoulder_link1</child>
			<pose frame="">2.4247762695495113e-08 -1.5141492875514472e-06 3.518479729791579e-11 0 0 0</pose>
			<axis>
				<xyz>0.9986941911143129 -0.051010494310641946 -0.0028003758163893775</xyz>
				<limit>
					<lower>-3.141592653589793</lower>
					<upper>3.141592653589793</upper>
				</limit>
				<use_parent_model_frame>0</use_parent_model_frame>
			</axis>
		</joint>
		<joint name="right_shoulder_axis2" type="revolute">
			<parent>right_shoulder_link2</parent>
			<child>upper_arm_right</child>
			<pose frame="">-0.003886306672382034 -0.12260337179962726 0.08951504713508669 0 0 0</pose>
			<axis>
				<xyz>0.03688002228074296 0.7578073504191245 -0.651435248975152</xyz>
				<limit>
					<lower>-3.141592653589793</lower>
					<upper>3.141592653589793</upper>
				</limit>
				<use_parent_model_frame>0</use_parent_model_frame>
			</axis>
		</joint>
		<joint name="right_shoulder_axis1" type="revolute">
			<parent>right_shoulder_link1</parent>
			<child>right_shoulder_link2</child>
			<pose frame="">3.3286120917352944e-08 -1.1819810933033636e-06 2.9826310310454576e-11 0 0 0</pose>
			<axis>
				<xyz>0.03535217943919346 0.6504813211160871 0.7586990670140364</xyz>
				<limit>
					<lower>-3.141592653589793</lower>
					<upper>3.141592653589793</upper>
				</limit>
				<use_parent_model_frame>0</use_parent_model_frame>
			</axis>
		</joint>
		<joint name="head_axis0" type="revolute">
			<parent>torso</parent>
			<child>sphere_head_link1</child>
			<pose frame="">-3.1974423109204507e-16 4.440892098500626e-18 1.1368683772161603e-15 0 0 0</pose>
			<axis>
				<xyz>-0.9998091558754352 4.561994461556559e-12 -0.019535911231678183</xyz>
				<limit>
					<lower>-0.5235987755982988</lower>
					<upper>0.5235987755982988</upper>
				</limit>
				<use_parent_model_frame>0</use_parent_model_frame>
			</axis>
		</joint>
		<joint name="head_axis2" type="revolute">
			<parent>sphere_head_link2</parent>
			<child>head</child>
			<pose frame="">-0.010485101953530496 0.0006491800647276302 -0.15561841482353372 0 0 0</pose>
			<axis>
				<xyz>-0.01953591123167816 -4.747127448079257e-10 0.9998091558754341</xyz>
				<limit>
					<lower>-0.5235987755982988</lower>
					<upper>0.5235987755982988</upper>
				</limit>
				<use_parent_model_frame>0</use_parent_model_frame>
			</axis>
		</joint>
		<joint name="head_axis1" type="revolute">
			<parent>sphere_head_link1</parent>
			<child>sphere_head_link2</child>
			<pose frame="">-1.7763568394002506e-16 1.3322676295501878e-17 -5.684341886080802e-16 0 0 0</pose>
			<axis>
				<xyz>-4.712822211393013e-12 1.0000000000000009 4.747112713885635e-10</xyz>
				<limit>
					<lower>-0.5235987755982988</lower>
					<upper>0.5235987755982988</upper>
				</limit>
				<use_parent_model_frame>0</use_parent_model_frame>
			</axis>
		</joint>
		<joint name="left_wrist_0" type="revolute">
			<parent>lower_arm_left</parent>
			<child>wrist_left_1</child>
			<pose frame="">-0.0004139924332811873 0.005534295170885741 -0.008294608942997854 0 0 0</pose>
			<axis>
				<xyz>-0.047216894784735494 0.6683646979703977 -0.7423336145924062</xyz>
				<limit>
					<lower>-0.5235987755982988</lower>
					<upper>0.5235987755982988</upper>
				</limit>
				<use_parent_model_frame>0</use_parent_model_frame>
			</axis>
		</joint>
		<joint name="left_wrist_1" type="revolute">
			<parent>wrist_left_1</parent>
			<child>left_hand</child>
			<pose frame="">-0.02378478290802299 0.05570249402127686 0.05642760420570653 0 0 0</pose>
			<axis>
				<xyz>0.9982455359929417 0.05815370141400429 -0.011135388723325151</xyz>
				<limit>
					<lower>-0.5235987755982988</lower>
					<upper>0.5235987755982988</upper>
				</limit>
				<use_parent_model_frame>0</use_parent_model_frame>
			</axis>
		</joint>
		<joint name="joint_wheel_right" type="revolute">
			<parent>front_part</parent>
			<child>right_wheel</child>
			<pose frame="">5.684341886080802e-16 -0.003999653375198307 5.577760475716787e-15 0 0 0</pose>
			<axis>
				<xyz>-3.1662288285727846e-30 0.9999999999999998 4.317059530368991e-14</xyz>
				<limit>
					<lower>-3.141592653589793</lower>
					<upper>3.141592653589793</upper>
				</limit>
				<use_parent_model_frame>0</use_parent_model_frame>
			</axis>
		</joint>
		<joint name="joint_wheel_back" type="revolute">
			<parent>bike</parent>
			<child>wheel_back</child>
			<pose frame="">-1.4210854715202004e-16 -0.0689996533751975 2.1316282072803005e-16 0 0 0</pose>
			<axis>
				<xyz>6.938893903907228e-17 -1.0 1.27675647831893e-15</xyz>
				<limit>
					<lower>-3.141592653589793</lower>
					<upper>3.141592653589793</upper>
				</limit>
				<use_parent_model_frame>0</use_parent_model_frame>
			</axis>
		</joint>
		<joint name="joint_pedal" type="revolute">
			<parent>bike</parent>
			<child>kurbel</child>
			<pose frame="">0.0002782913867391912 -0.035131649555820536 -0.0010093313481022886 0 0 0</pose>
			<axis>
				<xyz>-6.938893903907228e-17 1.0 -1.27675647831893e-15</xyz>
				<limit>
					<lower>-3.141592653589793</lower>
					<upper>3.141592653589793</upper>
				</limit>
				<use_parent_model_frame>0</use_parent_model_frame>
			</axis>
		</joint>
		<joint name="spine_joint" type="revolute">
			<parent>bike</parent>
			<child>torso</child>
			<pose frame="">0.22048396235129436 -0.014422000145820837 0.6949887848680887 0 0 0</pose>
			<axis>
				<xyz>0.01953591123167811 4.747112516936242e-10 -0.9998091558754337</xyz>
				<limit>
					<lower>-0.5235987755982988</lower>
					<upper>0.5235987755982988</upper>
				</limit>
				<use_parent_model_frame>0</use_parent_model_frame>
			</axis>
		</joint>
		<joint name="joint_wheel_left" type="revolute">
			<parent>front_part</parent>
			<child>left_wheel</child>
			<pose frame="">5.684341886080802e-16 0.04600034662480173 7.638334409421077e-15 0 0 0</pose>
			<axis>
				<xyz>3.1662288285727846e-30 -0.9999999999999998 -4.317059530368991e-14</xyz>
				<limit>
					<lower>-3.141592653589793</lower>
					<upper>3.141592653589793</upper>
				</limit>
				<use_parent_model_frame>0</use_parent_model_frame>
			</axis>
		</joint>
		<joint name="joint_front" type="revolute">
			<parent>bike</parent>
			<child>front_part</child>
			<pose frame="">-0.23003546880974085 -0.010388308215364166 -0.2052706960113988 0 0 0</pose>
			<axis>
				<xyz>5.345642609144017e-16 -4.084397910750052e-14 1.0</xyz>
				<limit>
					<lower>-0.5235987755982988</lower>
					<upper>0.5235987755982988</upper>
				</limit>
				<use_parent_model_frame>0</use_parent_model_frame>
			</axis>
		</joint>
		<joint name="elbow_right_rot1" type="revolute">
			<parent>elbow_right</parent>
			<child>lower_arm_right</child>
			<pose frame="">-0.004565493587209879 -0.09373552648463011 0.0806403978847321 0 0 0</pose>
			<axis>
				<xyz>-0.03688002228074262 -0.7578073504191257 0.6514352489751488</xyz>
				<limit>
					<lower>-1.5707963267948966</lower>
					<upper>1.5707963267948966</upper>
				</limit>
				<use_parent_model_frame>0</use_parent_model_frame>
			</axis>
		</joint>
		<joint name="joint_hip_left" type="revolute">
			<parent>bike</parent>
			<child>thigh_left</child>
			<pose frame="">-0.004772293703297166 0.010555749549715365 0.1111212047941391 0 0 0</pose>
			<axis>
				<xyz>4.713567773490396e-12 -0.9999999999999998 -4.747094653015647e-10</xyz>
				<limit>
					<lower>-1.9</lower>
					<upper>0.4</upper>
				</limit>
				<use_parent_model_frame>0</use_parent_model_frame>
			</axis>
		</joint>
		<joint name="joint_hip_right" type="revolute">
			<parent>bike</parent>
			<child>thigh_right</child>
			<pose frame="">-0.004301336274692211 -0.02190775214760226 0.11113075748438384 0 0 0</pose>
			<axis>
				<xyz>4.713397833840635e-12 -0.9999999999999999 -4.747100165437955e-10</xyz>
				<limit>
					<lower>-1.9</lower>
					<upper>0.4</upper>
				</limit>
				<use_parent_model_frame>0</use_parent_model_frame>
			</axis>
		</joint>
		<joint name="joint_knee_left" type="revolute">
			<parent>thigh_left</parent>
			<child>leg_left</child>
			<pose frame="">0.008998953151750193 0.033669348798665164 0.15020700692522204 0 0 0</pose>
			<axis>
				<xyz>-6.508844489870675e-12 -1.0000000000000238 -2.724203131930673e-10</xyz>
				<limit>
					<lower>0.0</lower>
					<upper>2.6</upper>
				</limit>
				<use_parent_model_frame>0</use_parent_model_frame>
			</axis>
		</joint>
		<joint name="joint_knee_right" type="revolute">
			<parent>thigh_right</parent>
			<child>leg_right</child>
			<pose frame="">0.007630745016043897 -0.01363745454096673 0.15030968324039598 0 0 0</pose>
			<axis>
				<xyz>-5.5782888889577e-12 1.0000000000000224 5.189987481747476e-10</xyz>
				<limit>
					<lower>-2.6</lower>
					<upper>0.0</upper>
				</limit>
				<use_parent_model_frame>0</use_parent_model_frame>
			</axis>
		</joint>
		<joint name="joint_foot_left" type="revolute">
			<parent>leg_left</parent>
			<child>foot_left</child>
			<pose frame="">0.0620293110271249 0.02399999998456085 0.03764790265394325 0 0 0</pose>
			<axis>
				<xyz>9.645942725302535e-12 0.9999999999999991 1.1192843308369593e-10</xyz>
				<limit>
					<lower>-0.6</lower>
					<upper>0.6</upper>
				</limit>
				<use_parent_model_frame>0</use_parent_model_frame>
			</axis>
		</joint>
		<joint name="joint_foot_left_tip" type="fixed">
			<parent>foot_left</parent>
			<child>foot_left_tip</child>
			<pose frame="">0.04103985138486481 -0.0011674030869608743 0.005886567336209403 0 0 0</pose>
		</joint>
		<joint name="joint_foot_right" type="revolute">
			<parent>leg_right</parent>
			<child>foot_right</child>
			<pose frame="">0.0629891386323365 0.023499999970076412 0.03601900003503324 0 0 0</pose>
			<axis>
				<xyz>-1.1247986451406825e-11 0.9999999999999987 7.1681206641122e-10</xyz>
				<limit>
					<lower>-0.6</lower>
					<upper>0.6</upper>
				</limit>
				<use_parent_model_frame>0</use_parent_model_frame>
			</axis>
		</joint>
		<joint name="joint_foot_right_tip" type="fixed">
			<parent>foot_right</parent>
			<child>foot_right_tip</child>
			<pose frame="">0.041098927250866134 0.0011673776796483893 0.0054587466160410615 0 0 0</pose>
		</joint>
		<joint name="joint_pedal_right" type="revolute">
			<parent>kurbel</parent>
			<child>pedal_right</child>
			<pose frame="">-4.220983134520573e-05 0.042000000000000405 -6.592456775077693e-05 0 0 0</pose>
			<axis>
				<xyz>-5.847985275656098e-16 1.0000000000000007 -1.5799660158833414e-15</xyz>
				<limit>
					<lower>-3.141592653589793</lower>
					<upper>3.141592653589793</upper>
				</limit>
				<use_parent_model_frame>0</use_parent_model_frame>
			</axis>
		</joint>
		<joint name="joint_pedal_left" type="revolute">
			<parent>kurbel</parent>
			<child>pedal_left</child>
			<pose frame="">-5.301625021756351e-05 -0.04199999999999946 5.759336515112068e-05 0 0 0</pose>
			<axis>
				<xyz>5.847985275656082e-16 -1.0 1.5799660158833548e-15</xyz>
				<limit>
					<lower>-3.141592653589793</lower>
					<upper>3.141592653589793</upper>
				</limit>
				<use_parent_model_frame>0</use_parent_model_frame>
			</axis>
		</joint>
	</model>
</sdf>
