<robot name="rikshaw">
  <joint name="joint_wheel_left" type="revolute">
    <parent link="front_part" />
    <child link="left_wheel" />
    <origin rpy="0 0 0" xyz="-0.33409 -0.66438 -0.13623" />
    <axis xyz="0 -1  0" />
    <limit effort="0.0" lower="-3.14159265359" upper="3.14159265359" velocity="0.0" />
  </joint>
  <joint name="joint_wheel_right" type="revolute">
    <parent link="front_part" />
    <child link="right_wheel" />
    <origin rpy="0 0 0" xyz="-0.33409  0.66961 -0.13623" />
    <axis xyz="0 1 0" />
    <limit effort="0.0" lower="-3.14159265359" upper="3.14159265359" velocity="0.0" />
  </joint>
  <joint name="joint_front" type="revolute">
    <parent link="bike" />
    <child link="front_part" />
    <origin rpy="0 0 0" xyz="-1.43933  0.07913  0.64123" />
    <axis xyz="0 0 1" />
    <limit effort="0.0" lower="-0.349065850399" upper="0.349065850399" velocity="0.0" />
  </joint>
  <joint name="joint_wheel_back" type="revolute">
    <parent link="bike" />
    <child link="wheel_back" />
    <origin rpy="0 0 0" xyz="1.29721 0.00684 0.51249" />
    <axis xyz="0 -1  0" />
    <limit effort="0.0" lower="-3.14159265359" upper="3.14159265359" velocity="0.0" />
  </joint>
  <joint name="joint_pedal" type="revolute">
    <parent link="bike" />
    <child link="kurbel" />
    <origin rpy="0 0 0" xyz="0.40815 0.03387 0.42121" />
    <axis xyz="0 1 0" />
    <limit effort="0.0" lower="-3.14159265359" upper="3.14159265359" velocity="0.0" />
  </joint>
  <joint name="spine_joint" type="revolute">
    <parent link="bike" />
    <child link="torso" />
    <origin rpy="0 0 0" xyz="0.64316 0.03749 2.22608" />
    <axis xyz="0.01953  0      -0.9998" />
    <limit effort="0.0" lower="-0.523598775598" upper="0.523598775598" velocity="0.0" />
  </joint>
  <joint name="joint_pedal_right" type="revolute">
    <parent link="kurbel" />
    <child link="pedal_right" />
    <origin rpy="0 0 0" xyz="-0.02904  0.37284  0.33613" />
    <axis xyz="0 1 0" />
    <limit effort="0.0" lower="-3.14159265359" upper="3.14159265359" velocity="0.0" />
  </joint>
  <joint name="joint_pedal_left" type="revolute">
    <parent link="kurbel" />
    <child link="pedal_left" />
    <origin rpy="0 0 0" xyz="0.02997 -0.30562 -0.33824" />
    <axis xyz="0 -1  0" />
    <limit effort="0.0" lower="-3.14159265359" upper="3.14159265359" velocity="0.0" />
  </joint>
  <joint name="joint_hip_left" type="revolute">
    <parent link="bike" />
    <child link="thigh_left" />
    <origin rpy="0 0 0" xyz="0.67721 -0.34595  1.2806" />
    <axis xyz="0 -1  0" />
    <limit effort="0.0" lower="-3.14159265359" upper="3.14159265359" velocity="0.0" />
  </joint>
  <joint name="joint_hip_right" type="revolute">
    <parent link="bike" />
    <child link="thigh_right" />
    <origin rpy="0 0 0" xyz="0.67674 0.4145  1.28059" />
    <axis xyz="0 -1  0" />
    <limit effort="0.0" lower="-3.14159265359" upper="3.14159265359" velocity="0.0" />
  </joint>
  <joint name="joint_knee_left" type="revolute">
    <parent link="thigh_left" />
    <child link="leg_left" />
    <origin rpy="0 0 0" xyz="0.01929  0.02498 -0.65655" />
    <axis xyz="0 -1  0" />
    <limit effort="0.0" lower="-3.14159265359" upper="3.14159265359" velocity="0.0" />
  </joint>
  <joint name="joint_knee_right" type="revolute">
    <parent link="thigh_right" />
    <child link="leg_right" />
    <origin rpy="0 0 0" xyz="0.02013  0.00713 -0.65667" />
    <axis xyz="0 1 0" />
    <limit effort="0.0" lower="-3.14159265359" upper="3.14159265359" velocity="0.0" />
  </joint>
  <joint name="joint_foot_left" type="revolute">
    <parent link="leg_left" />
    <child link="foot_left" />
    <origin rpy="0 0 0" xyz="-0.05939  0.02866 -0.58569" />
    <axis xyz="0 1 0" />
    <limit effort="0.0" lower="-3.14159265359" upper="3.14159265359" velocity="0.0" />
  </joint>
  <joint name="joint_foot_right" type="revolute">
    <parent link="leg_right" />
    <child link="foot_right" />
    <origin rpy="0 0 0" xyz="-0.05535 -0.01813 -0.58399" />
    <axis xyz="0 -1  0" />
    <limit effort="0.0" lower="-3.14159265359" upper="3.14159265359" velocity="0.0" />
  </joint>
  <joint name="left_shoulder_axis0" type="revolute">
    <parent link="torso" />
    <child link="left_shoulder_link1" />
    <origin rpy="0 0 0" xyz="-0.31243 -0.30972 -0.85592" />
    <axis xyz="0.05097 -0.99863 -0.01134" />
    <limit effort="0.0" lower="-3.14159265359" upper="3.14159265359" velocity="0.0" />
  </joint>
  <joint name="left_shoulder_axis1" type="revolute">
    <parent link="left_shoulder_link1" />
    <child link="left_shoulder_link2" />
    <origin rpy="0 0 0" xyz="0 0 0" />
    <axis xyz="0.99869  0.05101 -0.0028" />
    <limit effort="0.0" lower="-3.14159265359" upper="3.14159265359" velocity="0.0" />
  </joint>
  <joint name="left_shoulder_axis2" type="revolute">
    <parent link="left_shoulder_link2" />
    <child link="upper_arm_left" />
    <origin rpy="0 0 0" xyz="0.33698 -0.39521  1.28217" />
    <axis xyz="0.03688 -0.7578  -0.65143" />
    <limit effort="0.0" lower="-3.14159265359" upper="3.14159265359" velocity="0.0" />
  </joint>
  <joint name="elbow_left_rot1" type="revolute">
    <parent link="elbow_left" />
    <child link="lower_arm_left" />
    <origin rpy="0 0 0" xyz="0.01189 -0.14863 -0.15679" />
    <axis xyz="0.03688 -0.7578  -0.65143" />
    <limit effort="0.0" lower="-1.57079632679" upper="1.57079632679" velocity="0.0" />
  </joint>
  <joint name="elbow_left_rot0" type="revolute">
    <parent link="upper_arm_left" />
    <child link="elbow_left" />
    <origin rpy="0 0 0" xyz="0.01086 -0.32501 -0.26769" />
    <axis xyz="-0.03535  0.65048 -0.75869" />
    <limit effort="0.0" lower="0.0" upper="1.57079632679" velocity="0.0" />
  </joint>
  <joint name="elbow_right_rot1" type="revolute">
    <parent link="elbow_right" />
    <child link="lower_arm_right" />
    <origin rpy="0 0 0" xyz="0.012    0.15016 -0.15743" />
    <axis xyz="-0.03688 -0.7578   0.65143" />
    <limit effort="0.0" lower="-1.57079632679" upper="1.57079632679" velocity="0.0" />
  </joint>
  <joint name="left_wrist_0" type="revolute">
    <parent link="lower_arm_left" />
    <child link="wrist_left_1" />
    <origin rpy="0 0 0" xyz="0.01427 -0.2972  -0.27242" />
    <axis xyz="-0.04721  0.66836 -0.74233" />
    <limit effort="0.0" lower="-0.523598775598" upper="0.523598775598" velocity="0.0" />
  </joint>
  <joint name="left_wrist_1" type="revolute">
    <parent link="wrist_left_1" />
    <child link="left_hand" />
    <origin rpy="0 0 0" xyz="-0.01057 -0.06623 -0.04874" />
    <axis xyz="0.99824  0.05815 -0.01113" />
    <limit effort="0.0" lower="-0.523598775598" upper="0.523598775598" velocity="0.0" />
  </joint>
  <joint name="elbow_right_rot0" type="revolute">
    <parent link="upper_arm_right" />
    <child link="elbow_right" />
    <origin rpy="0 0 0" xyz="0.01339  0.32894 -0.27062" />
    <axis xyz="0.03535 0.65048 0.75869" />
    <limit effort="0.0" lower="0.0" upper="1.57079632679" velocity="0.0" />
  </joint>
  <joint name="right_wrist_0" type="revolute">
    <parent link="lower_arm_right" />
    <child link="wrist_right_1" />
    <origin rpy="0 0 0" xyz="0.01469  0.30079 -0.2697" />
    <axis xyz="-0.02346 -0.63212 -0.77451" />
    <limit effort="0.0" lower="-0.523598775598" upper="0.523598775598" velocity="0.0" />
  </joint>
  <joint name="right_wrist_1" type="revolute">
    <parent link="wrist_right_1" />
    <child link="right_hand" />
    <origin rpy="0 0 0" xyz="0.02294  0.06773 -0.04485" />
    <axis xyz="0.99902 -0.04386  0.00553" />
    <limit effort="0.0" lower="-0.523598775598" upper="0.523598775598" velocity="0.0" />
  </joint>
  <joint name="right_shoulder_axis0" type="revolute">
    <parent link="torso" />
    <child link="right_shoulder_link1" />
    <origin rpy="0 0 0" xyz="-0.31246  0.27463 -0.85592" />
    <axis xyz="0.99869 -0.05101 -0.0028" />
    <limit effort="0.0" lower="-3.14159265359" upper="3.14159265359" velocity="0.0" />
  </joint>
  <joint name="right_shoulder_axis2" type="revolute">
    <parent link="right_shoulder_link2" />
    <child link="upper_arm_right" />
    <origin rpy="0 0 0" xyz="0.33457 0.43473 1.28164" />
    <axis xyz="0.03688  0.7578  -0.65143" />
    <limit effort="0.0" lower="-3.14159265359" upper="3.14159265359" velocity="0.0" />
  </joint>
  <joint name="right_shoulder_axis1" type="revolute">
    <parent link="right_shoulder_link1" />
    <child link="right_shoulder_link2" />
    <origin rpy="0 0 0" xyz="0 0 0" />
    <axis xyz="0.03535 0.65048 0.75869" />
    <limit effort="0.0" lower="-3.14159265359" upper="3.14159265359" velocity="0.0" />
  </joint>
  <link name="bike">
    <inertial>
      <mass value="21.813314987301997" />
      <origin rpy="0 0 0" xyz="-0.83471  0.03437  0.037" />
      <inertia ixx="10.275552951787107" ixy="-0.013989875106434159" ixz="-0.2472724707609125" iyy="13.853123065374536" iyz="-3.796078472952304" izz="4.200869439036604" />
    </inertial>
    <collision name="bike_collision">
      <origin rpy="0 0 0" xyz="-0.83471  0.03437  0.037" />
      <geometry>
        <mesh filename="package://robots/rikshaw/meshes/collisions/bike.stl" scale="0.001 0.001 0.001" />
      </geometry>
    </collision>
    <visual name="bike_visual">
      <origin rpy="0 0 0" xyz="-0.83471  0.03437  0.037" />
      <geometry>
        <mesh filename="package://robots/rikshaw/meshes/visuals/bike.stl" scale="0.001 0.001 0.001" />
      </geometry>
    </visual>
  </link>
  <link name="upper_arm_right">
    <inertial>
      <mass value="1.094552479232937" />
      <origin rpy="0 0 0" xyz="-0.3307  -0.31213 -1.37016" />
      <inertia ixx="2.009361473024954" ixy="-0.15927999238941815" ixz="-0.6081702930098083" iyy="1.9239533934426856" iyz="-0.4692767107668228" izz="0.3338930906950165" />
    </inertial>
    <collision name="upper_arm_right_collision">
      <origin rpy="0 0 0" xyz="-0.3307  -0.31213 -1.37016" />
      <geometry>
        <mesh filename="package://robots/rikshaw/meshes/collisions/upper_arm_right.stl" scale="0.001 0.001 0.001" />
      </geometry>
    </collision>
    <visual name="upper_arm_right_visual">
      <origin rpy="0 0 0" xyz="-0.3307  -0.31213 -1.37016" />
      <geometry>
        <mesh filename="package://robots/rikshaw/meshes/visuals/upper_arm_right.stl" scale="0.001 0.001 0.001" />
      </geometry>
    </visual>
  </link>
  <link name="torso">
    <inertial>
      <mass value="10.567390774387572" />
      <origin rpy="0 0 0" xyz="-0.33219 -0.01995 -0.90182" />
      <inertia ixx="18.931261294108232" ixy="-0.05633179125653744" ixz="-0.24498372786071856" iyy="19.71302486118391" iyz="-4.351122150233511" izz="1.3404190207940572" />
    </inertial>
    <collision name="torso_collision">
      <origin rpy="0 0 0" xyz="-0.33219 -0.01995 -0.90182" />
      <geometry>
        <mesh filename="package://robots/rikshaw/meshes/collisions/torso.stl" scale="0.001 0.001 0.001" />
      </geometry>
    </collision>
    <visual name="torso_visual">
      <origin rpy="0 0 0" xyz="-0.33219 -0.01995 -0.90182" />
      <geometry>
        <mesh filename="package://robots/rikshaw/meshes/visuals/torso.stl" scale="0.001 0.001 0.001" />
      </geometry>
    </visual>
  </link>
  <link name="front_part">
    <inertial>
      <mass value="16.813631845520145" />
      <origin rpy="0 0 0" xyz="0.83471 -0.03437 -0.218" />
      <inertia ixx="5.465779053028134" ixy="0.5110471712217488" ixz="-0.2874402446427835" iyy="14.406698754685804" iyz="2.938162171335791" izz="11.464360009565059" />
    </inertial>
    <collision name="front_part_collision">
      <origin rpy="0 0 0" xyz="0.83471 -0.03437 -0.218" />
      <geometry>
        <mesh filename="package://robots/rikshaw/meshes/collisions/front_part.stl" scale="0.001 0.001 0.001" />
      </geometry>
    </collision>
    <visual name="front_part_visual">
      <origin rpy="0 0 0" xyz="0.83471 -0.03437 -0.218" />
      <geometry>
        <mesh filename="package://robots/rikshaw/meshes/visuals/front_part.stl" scale="0.001 0.001 0.001" />
      </geometry>
    </visual>
  </link>
  <link name="left_wheel">
    <inertial>
      <mass value="13.340163929097852" />
      <origin rpy="0 0 0" xyz="0.88671  0.26962 -0.2525" />
      <inertia ixx="2.6886582542943365" ixy="-3.7335436664890733" ixz="1.0631600153408756" iyy="12.355706573664586" iyz="2.9868026751438275" izz="12.327019793799991" />
    </inertial>
    <collision name="left_wheel_collision">
      <origin rpy="0 0 0" xyz="0.88671  0.26962 -0.2525" />
      <geometry>
        <mesh filename="package://robots/rikshaw/meshes/collisions/left_wheel.stl" scale="0.001 0.001 0.001" />
      </geometry>
    </collision>
    <visual name="left_wheel_visual">
      <origin rpy="0 0 0" xyz="0.88671  0.26962 -0.2525" />
      <geometry>
        <mesh filename="package://robots/rikshaw/meshes/visuals/left_wheel.stl" scale="0.001 0.001 0.001" />
      </geometry>
    </visual>
  </link>
  <link name="right_wheel">
    <inertial>
      <mass value="13.340163929097853" />
      <origin rpy="0 0 0" xyz="0.88671 -0.37237 -0.2525" />
      <inertia ixx="3.24940928013889" ixy="4.4520780243364495" ixz="-1.2677691125288908" iyy="12.355706573664742" iyz="2.9868026751441725" izz="12.887770819644302" />
    </inertial>
    <collision name="right_wheel_collision">
      <origin rpy="0 0 0" xyz="0.88671 -0.37237 -0.2525" />
      <geometry>
        <mesh filename="package://robots/rikshaw/meshes/collisions/right_wheel.stl" scale="0.001 0.001 0.001" />
      </geometry>
    </collision>
    <visual name="right_wheel_visual">
      <origin rpy="0 0 0" xyz="0.88671 -0.37237 -0.2525" />
      <geometry>
        <mesh filename="package://robots/rikshaw/meshes/visuals/right_wheel.stl" scale="0.001 0.001 0.001" />
      </geometry>
    </visual>
  </link>
  <link name="pedal_right">
    <inertial>
      <mass value="0.9460025886020109" />
      <origin rpy="0 0 0" xyz="-0.18953 -0.22436 -0.37864" />
      <inertia ixx="0.1680562235402652" ixy="-0.03270482284264949" ixz="-0.06533253385140439" iyy="0.17008937607447944" iyz="-0.06789023681759175" izz="0.0660654950965225" />
    </inertial>
    <collision name="pedal_right_collision">
      <origin rpy="0 0 0" xyz="-0.18953 -0.22436 -0.37864" />
      <geometry>
        <mesh filename="package://robots/rikshaw/meshes/collisions/pedal_right.stl" scale="0.001 0.001 0.001" />
      </geometry>
    </collision>
    <visual name="pedal_right_visual">
      <origin rpy="0 0 0" xyz="-0.18953 -0.22436 -0.37864" />
      <geometry>
        <mesh filename="package://robots/rikshaw/meshes/visuals/pedal_right.stl" scale="0.001 0.001 0.001" />
      </geometry>
    </visual>
  </link>
  <link name="kurbel">
    <inertial>
      <mass value="2.7832708381108002" />
      <origin rpy="0 0 0" xyz="-0.20421  0.00062 -0.2101" />
      <inertia ixx="0.160521356335058" ixy="-0.018529361068994183" ixz="-0.033209218815758404" iyy="0.25766480698009997" iyz="-0.11843090757691721" izz="0.13512980306006003" />
    </inertial>
    <collision name="kurbel_collision">
      <origin rpy="0 0 0" xyz="-0.20421  0.00062 -0.2101" />
      <geometry>
        <mesh filename="package://robots/rikshaw/meshes/collisions/kurbel.stl" scale="0.001 0.001 0.001" />
      </geometry>
    </collision>
    <visual name="kurbel_visual">
      <origin rpy="0 0 0" xyz="-0.20421  0.00062 -0.2101" />
      <geometry>
        <mesh filename="package://robots/rikshaw/meshes/visuals/kurbel.stl" scale="0.001 0.001 0.001" />
      </geometry>
    </visual>
  </link>
  <link name="pedal_left">
    <inertial>
      <mass value="0.9460025886020087" />
      <origin rpy="0 0 0" xyz="-0.21903  0.15687 -0.04151" />
      <inertia ixx="0.015029704878197391" ixy="0.023808705010641276" ixz="0.004504913967078801" iyy="0.04745000655927284" iyz="-0.00856421037217533" izz="0.05849920799521962" />
    </inertial>
    <collision name="pedal_left_collision">
      <origin rpy="0 0 0" xyz="-0.21903  0.15687 -0.04151" />
      <geometry>
        <mesh filename="package://robots/rikshaw/meshes/collisions/pedal_left.stl" scale="0.001 0.001 0.001" />
      </geometry>
    </collision>
    <visual name="pedal_left_visual">
      <origin rpy="0 0 0" xyz="-0.21903  0.15687 -0.04151" />
      <geometry>
        <mesh filename="package://robots/rikshaw/meshes/visuals/pedal_left.stl" scale="0.001 0.001 0.001" />
      </geometry>
    </visual>
  </link>
  <link name="foot_left">
    <inertial>
      <mass value="1.0073655678455569" />
      <origin rpy="0 0 0" xyz="-0.34957  0.13815 -0.03799" />
      <inertia ixx="0.024540710607575827" ixy="0.049601762440905854" ixz="0.0011937057141964478" iyy="0.10611861418986646" iyz="-0.002834365654500939" izz="0.12991068416512136" />
    </inertial>
    <collision name="foot_left_collision">
      <origin rpy="0 0 0" xyz="-0.34957  0.13815 -0.03799" />
      <geometry>
        <mesh filename="package://robots/rikshaw/meshes/collisions/foot_left.stl" scale="0.001 0.001 0.001" />
      </geometry>
    </collision>
    <visual name="foot_left_visual">
      <origin rpy="0 0 0" xyz="-0.34957  0.13815 -0.03799" />
      <geometry>
        <mesh filename="package://robots/rikshaw/meshes/visuals/foot_left.stl" scale="0.001 0.001 0.001" />
      </geometry>
    </visual>
  </link>
  <link name="foot_right">
    <inertial>
      <mass value="1.007352459928085" />
      <origin rpy="0 0 0" xyz="-0.35225 -0.2095  -0.03797" />
      <inertia ixx="0.03848112914971559" ixy="-0.06281908353900195" ixz="-0.0016489922126967657" iyy="0.10736081745250295" iyz="-0.0030346879286066784" izz="0.145102699250954" />
    </inertial>
    <collision name="foot_right_collision">
      <origin rpy="0 0 0" xyz="-0.35225 -0.2095  -0.03797" />
      <geometry>
        <mesh filename="package://robots/rikshaw/meshes/collisions/foot_right.stl" scale="0.001 0.001 0.001" />
      </geometry>
    </collision>
    <visual name="foot_right_visual">
      <origin rpy="0 0 0" xyz="-0.35225 -0.2095  -0.03797" />
      <geometry>
        <mesh filename="package://robots/rikshaw/meshes/visuals/foot_right.stl" scale="0.001 0.001 0.001" />
      </geometry>
    </visual>
  </link>
  <link name="thigh_right">
    <inertial>
      <mass value="5.563526842051091" />
      <origin rpy="0 0 0" xyz="-0.33621 -0.1963  -0.69586" />
      <inertia ixx="2.1953753518764234" ixy="-0.4133207779831457" ixz="-0.712917502636253" iyy="2.578490277932215" iyz="-1.1085430579007103" izz="0.9221499084687812" />
    </inertial>
    <collision name="thigh_right_collision">
      <origin rpy="0 0 0" xyz="-0.33621 -0.1963  -0.69586" />
      <geometry>
        <mesh filename="package://robots/rikshaw/meshes/collisions/thigh_right.stl" scale="0.001 0.001 0.001" />
      </geometry>
    </collision>
    <visual name="thigh_right_visual">
      <origin rpy="0 0 0" xyz="-0.33621 -0.1963  -0.69586" />
      <geometry>
        <mesh filename="package://robots/rikshaw/meshes/visuals/thigh_right.stl" scale="0.001 0.001 0.001" />
      </geometry>
    </visual>
  </link>
  <link name="thigh_left">
    <inertial>
      <mass value="5.563589065127255" />
      <origin rpy="0 0 0" xyz="-0.33621  0.1677  -0.69586" />
      <inertia ixx="2.1073483656597585" ixy="0.3375542359065887" ixz="0.5829504291423683" iyy="2.5803675604914544" iyz="-1.11037215564166" izz="0.8358124248821934" />
    </inertial>
    <collision name="thigh_left_collision">
      <origin rpy="0 0 0" xyz="-0.33621  0.1677  -0.69586" />
      <geometry>
        <mesh filename="package://robots/rikshaw/meshes/collisions/thigh_left.stl" scale="0.001 0.001 0.001" />
      </geometry>
    </collision>
    <visual name="thigh_left_visual">
      <origin rpy="0 0 0" xyz="-0.33621  0.1677  -0.69586" />
      <geometry>
        <mesh filename="package://robots/rikshaw/meshes/visuals/thigh_left.stl" scale="0.001 0.001 0.001" />
      </geometry>
    </visual>
  </link>
  <link name="leg_right">
    <inertial>
      <mass value="5.741522183296334" />
      <origin rpy="0 0 0" xyz="-0.35225 -0.204   -0.38711" />
      <inertia ixx="0.6337458051838858" ixy="-0.43107317072067103" ixz="-0.2993369937343584" iyy="1.046634426174878" iyz="-0.46606762221676656" izz="0.9662986162769234" />
    </inertial>
    <collision name="leg_right_collision">
      <origin rpy="0 0 0" xyz="-0.35225 -0.204   -0.38711" />
      <geometry>
        <mesh filename="package://robots/rikshaw/meshes/collisions/leg_right.stl" scale="0.001 0.001 0.001" />
      </geometry>
    </collision>
    <visual name="leg_right_visual">
      <origin rpy="0 0 0" xyz="-0.35225 -0.204   -0.38711" />
      <geometry>
        <mesh filename="package://robots/rikshaw/meshes/visuals/leg_right.stl" scale="0.001 0.001 0.001" />
      </geometry>
    </visual>
  </link>
  <link name="leg_left">
    <inertial>
      <mass value="5.7426173662328575" />
      <origin rpy="0 0 0" xyz="-0.35275  0.14365 -0.38712" />
      <inertia ixx="0.5427884169781724" ixy="0.3499498433914676" ixz="0.24468683550206866" iyy="1.0437222226233074" iyz="-0.4657299321823802" izz="0.8715411400437341" />
    </inertial>
    <collision name="leg_left_collision">
      <origin rpy="0 0 0" xyz="-0.35275  0.14365 -0.38712" />
      <geometry>
        <mesh filename="package://robots/rikshaw/meshes/collisions/leg_left.stl" scale="0.001 0.001 0.001" />
      </geometry>
    </collision>
    <visual name="leg_left_visual">
      <origin rpy="0 0 0" xyz="-0.35275  0.14365 -0.38712" />
      <geometry>
        <mesh filename="package://robots/rikshaw/meshes/visuals/leg_left.stl" scale="0.001 0.001 0.001" />
      </geometry>
    </visual>
  </link>
  <link name="wheel_back">
    <inertial>
      <mass value="13.340163929098479" />
      <origin rpy="0 0 0" xyz="-0.6486   0.03107 -0.25624" />
      <inertia ixx="1.4043208422760698" ixy="-0.32812134268378185" ixz="-0.1296324865039446" iyy="7.504381180421911" iyz="-2.217204307894474" izz="6.140471373352847" />
    </inertial>
    <collision name="wheel_back_collision">
      <origin rpy="0 0 0" xyz="-0.6486   0.03107 -0.25624" />
      <geometry>
        <mesh filename="package://robots/rikshaw/meshes/collisions/wheel_back.stl" scale="0.001 0.001 0.001" />
      </geometry>
    </collision>
    <visual name="wheel_back_visual">
      <origin rpy="0 0 0" xyz="-0.6486   0.03107 -0.25624" />
      <geometry>
        <mesh filename="package://robots/rikshaw/meshes/visuals/wheel_back.stl" scale="0.001 0.001 0.001" />
      </geometry>
    </visual>
  </link>
  <link name="elbow_left">
    <inertial>
      <mass value="0.15681540300170926" />
      <origin rpy="0 0 0" xyz="-0.33623  0.48671 -1.20934" />
      <inertia ixx="0.256864953120857" ixy="0.02715659840956128" ixz="0.09321889691014267" iyy="0.23510542876452983" iyz="-0.0630978624555684" izz="0.05862599276052077" />
    </inertial>
    <collision name="elbow_left_collision">
      <origin rpy="0 0 0" xyz="-0.33623  0.48671 -1.20934" />
      <geometry>
        <mesh filename="package://robots/rikshaw/meshes/collisions/elbow_left.stl" scale="0.001 0.001 0.001" />
      </geometry>
    </collision>
    <visual name="elbow_left_visual">
      <origin rpy="0 0 0" xyz="-0.33623  0.48671 -1.20934" />
      <geometry>
        <mesh filename="package://robots/rikshaw/meshes/visuals/elbow_left.stl" scale="0.001 0.001 0.001" />
      </geometry>
    </visual>
  </link>
  <link name="elbow_right">
    <inertial>
      <mass value="0.17350645370716086" />
      <origin rpy="0 0 0" xyz="-0.33625 -0.52775 -1.20836" />
      <inertia ixx="0.29092134642236867" ixy="-0.03256614172841492" ixz="-0.11152852379310105" iyy="0.25911527550455765" iyz="-0.06967799853294211" izz="0.07260155373740665" />
    </inertial>
    <collision name="elbow_right_collision">
      <origin rpy="0 0 0" xyz="-0.33625 -0.52775 -1.20836" />
      <geometry>
        <mesh filename="package://robots/rikshaw/meshes/collisions/elbow_right.stl" scale="0.001 0.001 0.001" />
      </geometry>
    </collision>
    <visual name="elbow_right_visual">
      <origin rpy="0 0 0" xyz="-0.33625 -0.52775 -1.20836" />
      <geometry>
        <mesh filename="package://robots/rikshaw/meshes/visuals/elbow_right.stl" scale="0.001 0.001 0.001" />
      </geometry>
    </visual>
  </link>
  <link name="left_shoulder_link1">
    <inertial>
      <mass value="0.04675353024257252" />
      <origin rpy="0 0 0" xyz="0 0 0" />
      <inertia ixx="0.09124311009121511" ixy="0.004209482376385915" ixz="0.017439008752899925" iyy="0.09289236823462671" iyz="-0.021186744952191985" izz="0.0085849609954555" />
    </inertial>
    <collision name="left_shoulder_link1_collision">
      <origin rpy="0 0 0" xyz="0 0 0" />
      <geometry>
        <mesh filename="package://robots/rikshaw/meshes/collisions/left_shoulder_link1.stl" scale="0.001 0.001 0.001" />
      </geometry>
    </collision>
    <visual name="left_shoulder_link1_visual">
      <origin rpy="0 0 0" xyz="0 0 0" />
      <geometry>
        <mesh filename="package://robots/rikshaw/meshes/visuals/left_shoulder_link1.stl" scale="0.001 0.001 0.001" />
      </geometry>
    </visual>
  </link>
  <link name="left_shoulder_link2">
    <inertial>
      <mass value="0.031337303847437374" />
      <origin rpy="0 0 0" xyz="0 0 0" />
      <inertia ixx="0.06115583425429413" ixy="0.002821460465335818" ixz="0.011688728604804268" iyy="0.06226129181848564" iyz="-0.014200749103179578" izz="0.00575288014481582" />
    </inertial>
    <collision name="left_shoulder_link2_collision">
      <origin rpy="0 0 0" xyz="0 0 0" />
      <geometry>
        <mesh filename="package://robots/rikshaw/meshes/collisions/left_shoulder_link2.stl" scale="0.001 0.001 0.001" />
      </geometry>
    </collision>
    <visual name="left_shoulder_link2_visual">
      <origin rpy="0 0 0" xyz="0 0 0" />
      <geometry>
        <mesh filename="package://robots/rikshaw/meshes/visuals/left_shoulder_link2.stl" scale="0.001 0.001 0.001" />
      </geometry>
    </visual>
  </link>
  <link name="wrist_left_1">
    <inertial>
      <mass value="0.012762217633342583" />
      <origin rpy="0 0 0" xyz="-0.35218  0.71637 -0.97306" />
      <inertia ixx="0.018970691396491133" ixy="0.003248339947130892" ixz="0.009052108796479035" iyy="0.013906693497415518" iyz="-0.004420385057485256" izz="0.008241479604974272" />
    </inertial>
    <collision name="wrist_left_1_collision">
      <origin rpy="0 0 0" xyz="-0.35218  0.71637 -0.97306" />
      <geometry>
        <mesh filename="package://robots/rikshaw/meshes/collisions/wrist_left_1.stl" scale="0.001 0.001 0.001" />
      </geometry>
    </collision>
    <visual name="wrist_left_1_visual">
      <origin rpy="0 0 0" xyz="-0.35218  0.71637 -0.97306" />
      <geometry>
        <mesh filename="package://robots/rikshaw/meshes/visuals/wrist_left_1.stl" scale="0.001 0.001 0.001" />
      </geometry>
    </visual>
  </link>
  <link name="left_hand">
    <inertial>
      <mass value="0.08391816593127362" />
      <origin rpy="0 0 0" xyz="-0.3352   0.72441 -0.98105" />
      <inertia ixx="0.12315663152243422" ixy="0.02351379836528688" ixz="0.06051648116403934" iyy="0.08285072728366757" iyz="-0.027866103240523472" izz="0.062041662036345445" />
    </inertial>
    <collision name="left_hand_collision">
      <origin rpy="0 0 0" xyz="-0.3352   0.72441 -0.98105" />
      <geometry>
        <mesh filename="package://robots/rikshaw/meshes/collisions/left_hand.stl" scale="0.001 0.001 0.001" />
      </geometry>
    </collision>
    <visual name="left_hand_visual">
      <origin rpy="0 0 0" xyz="-0.3352   0.72441 -0.98105" />
      <geometry>
        <mesh filename="package://robots/rikshaw/meshes/visuals/left_hand.stl" scale="0.001 0.001 0.001" />
      </geometry>
    </visual>
  </link>
  <link name="wrist_right_1">
    <inertial>
      <mass value="0.012761782896867226" />
      <origin rpy="0 0 0" xyz="-0.35259 -0.76042 -0.97175" />
      <inertia ixx="0.01981192653797364" ixy="-0.0034501178168721454" ixz="-0.00960805204659084" iyy="0.013906055128874585" iyz="-0.004422361782762946" izz="0.00908685911865395" />
    </inertial>
    <collision name="wrist_right_1_collision">
      <origin rpy="0 0 0" xyz="-0.35259 -0.76042 -0.97175" />
      <geometry>
        <mesh filename="package://robots/rikshaw/meshes/collisions/wrist_right_1.stl" scale="0.001 0.001 0.001" />
      </geometry>
    </collision>
    <visual name="wrist_right_1_visual">
      <origin rpy="0 0 0" xyz="-0.35259 -0.76042 -0.97175" />
      <geometry>
        <mesh filename="package://robots/rikshaw/meshes/visuals/wrist_right_1.stl" scale="0.001 0.001 0.001" />
      </geometry>
    </visual>
  </link>
  <link name="right_hand">
    <inertial>
      <mass value="0.08391622142376684" />
      <origin rpy="0 0 0" xyz="-0.37032 -0.76629 -0.97998" />
      <inertia ixx="0.13019843505363257" ixy="-0.02490104700630209" ixz="-0.06449950190353403" iyy="0.08332891545792796" iyz="-0.027909412829306077" izz="0.06849264168180677" />
    </inertial>
    <collision name="right_hand_collision">
      <origin rpy="0 0 0" xyz="-0.37032 -0.76629 -0.97998" />
      <geometry>
        <mesh filename="package://robots/rikshaw/meshes/collisions/right_hand.stl" scale="0.001 0.001 0.001" />
      </geometry>
    </collision>
    <visual name="right_hand_visual">
      <origin rpy="0 0 0" xyz="-0.37032 -0.76629 -0.97998" />
      <geometry>
        <mesh filename="package://robots/rikshaw/meshes/visuals/right_hand.stl" scale="0.001 0.001 0.001" />
      </geometry>
    </visual>
  </link>
  <link name="upper_arm_left">
    <inertial>
      <mass value="1.1803838170765448" />
      <origin rpy="0 0 0" xyz="-0.33073  0.27223 -1.37016" />
      <inertia ixx="2.1298878606900375" ixy="0.15731396320754892" ixz="0.5963000881547096" iyy="2.078345545756509" iyz="-0.5098935199657852" izz="0.3233187846841082" />
    </inertial>
    <collision name="upper_arm_left_collision">
      <origin rpy="0 0 0" xyz="-0.33073  0.27223 -1.37016" />
      <geometry>
        <mesh filename="package://robots/rikshaw/meshes/collisions/upper_arm_left.stl" scale="0.001 0.001 0.001" />
      </geometry>
    </collision>
    <visual name="upper_arm_left_visual">
      <origin rpy="0 0 0" xyz="-0.33073  0.27223 -1.37016" />
      <geometry>
        <mesh filename="package://robots/rikshaw/meshes/visuals/upper_arm_left.stl" scale="0.001 0.001 0.001" />
      </geometry>
    </visual>
  </link>
  <link name="lower_arm_left">
    <inertial>
      <mass value="1.4159186820902159" />
      <origin rpy="0 0 0" xyz="-0.34303  0.52508 -1.15266" />
      <inertia ixx="2.1811131919385804" ixy="0.3032071609440758" ixz="0.9349772174239721" iyy="1.8114839178439186" iyz="-0.5288085786732152" izz="0.7127903112759242" />
    </inertial>
    <collision name="lower_arm_left_collision">
      <origin rpy="0 0 0" xyz="-0.34303  0.52508 -1.15266" />
      <geometry>
        <mesh filename="package://robots/rikshaw/meshes/collisions/lower_arm_left.stl" scale="0.001 0.001 0.001" />
      </geometry>
    </collision>
    <visual name="lower_arm_left_visual">
      <origin rpy="0 0 0" xyz="-0.34303  0.52508 -1.15266" />
      <geometry>
        <mesh filename="package://robots/rikshaw/meshes/visuals/lower_arm_left.stl" scale="0.001 0.001 0.001" />
      </geometry>
    </visual>
  </link>
  <link name="lower_arm_right">
    <inertial>
      <mass value="1.3992272098428602" />
      <origin rpy="0 0 0" xyz="-0.34306 -0.56612 -1.15169" />
      <inertia ixx="2.224056987713926" ixy="-0.32109609612110884" ixz="-0.9871381806426893" iyy="1.7807932691131367" iyz="-0.5212987529954032" izz="0.7827088740676036" />
    </inertial>
    <collision name="lower_arm_right_collision">
      <origin rpy="0 0 0" xyz="-0.34306 -0.56612 -1.15169" />
      <geometry>
        <mesh filename="package://robots/rikshaw/meshes/collisions/lower_arm_right.stl" scale="0.001 0.001 0.001" />
      </geometry>
    </collision>
    <visual name="lower_arm_right_visual">
      <origin rpy="0 0 0" xyz="-0.34306 -0.56612 -1.15169" />
      <geometry>
        <mesh filename="package://robots/rikshaw/meshes/visuals/lower_arm_right.stl" scale="0.001 0.001 0.001" />
      </geometry>
    </visual>
  </link>
  <link name="right_shoulder_link1">
    <inertial>
      <mass value="0.04674900288659637" />
      <origin rpy="0 0 0" xyz="0 0 0" />
      <inertia ixx="0.09232437526869294" ixy="-0.004825593285278366" ixz="-0.019993263390362594" iyy="0.0928824466151441" iyz="-0.021182751147620086" izz="0.0096732810387272" />
    </inertial>
    <collision name="right_shoulder_link1_collision">
      <origin rpy="0 0 0" xyz="0 0 0" />
      <geometry>
        <mesh filename="package://robots/rikshaw/meshes/collisions/right_shoulder_link1.stl" scale="0.001 0.001 0.001" />
      </geometry>
    </collision>
    <visual name="right_shoulder_link1_visual">
      <origin rpy="0 0 0" xyz="0 0 0" />
      <geometry>
        <mesh filename="package://robots/rikshaw/meshes/visuals/right_shoulder_link1.stl" scale="0.001 0.001 0.001" />
      </geometry>
    </visual>
  </link>
  <link name="right_shoulder_link2">
    <inertial>
      <mass value="0.03133730384711679" />
      <origin rpy="0 0 0" xyz="0 0 0" />
      <inertia ixx="0.06188657465774138" ixy="-0.003234741031616726" ixz="-0.013402089121146524" iyy="0.06226067322485201" iyz="-0.014199453462168308" izz="0.006482987366217103" />
    </inertial>
    <collision name="right_shoulder_link2_collision">
      <origin rpy="0 0 0" xyz="0 0 0" />
      <geometry>
        <mesh filename="package://robots/rikshaw/meshes/collisions/right_shoulder_link2.stl" scale="0.001 0.001 0.001" />
      </geometry>
    </collision>
    <visual name="right_shoulder_link2_visual">
      <origin rpy="0 0 0" xyz="0 0 0" />
      <geometry>
        <mesh filename="package://robots/rikshaw/meshes/visuals/right_shoulder_link2.stl" scale="0.001 0.001 0.001" />
      </geometry>
    </visual>
  </link>
</robot>