<?xml version="1.0" ?>
<sdf version="1.6">
	<model name="rikshaw">
		<link name="bike">
			<self_collide>false</self_collide>
			<pose frame="">-0.08857855461656707 0.03232678669767529 0.1146025606045478 0.0 -0.0 0.0</pose>
			<inertial>
				<pose frame="">0.0 0.0 0.0 0 0 0</pose>
				<mass>9.123374541674044</mass>
				<inertia>
					<ixx>0.2676110458247469</ixx>
					<ixy>0.022504055650875893</ixy>
					<ixz>-0.033766151670108296</ixz>
					<iyy>2.9838143890229882</iyy>
					<iyz>-0.22182970031409888</iyz>
					<izz>2.7445539890238853</izz>
				</inertia>
			</inertial>
			<collision name="bike_collision">
				<geometry>
					<mesh>
						<uri>model://rikshaw/meshes/CAD/bike.stl</uri>
						<scale>0.001 0.001 0.001</scale>
					</mesh>
				</geometry>
			</collision>
			<visual name="bike_visual">
				<geometry>
					<mesh>
						<uri>model://rikshaw/meshes/CAD/bike.stl</uri>
						<scale>0.001 0.001 0.001</scale>
					</mesh>
				</geometry>
			</visual>
		</link>
		<link name="pedal_left">
			<self_collide>false</self_collide>
			<pose frame="">0.2444488071691209 -0.06998001899389801 0.09625710324688459 0.0 -0.0 0.0</pose>
			<inertial>
				<pose frame="">0.0 0.0 0.0 0 0 0</pose>
				<mass>1.4041650832964538</mass>
				<inertia>
					<ixx>0.02744479218908917</ixx>
					<ixy>0.023992648630360568</ixy>
					<ixz>0.007267871424477564</ixz>
					<iyy>0.10288660231176043</iyy>
					<iyz>-0.03310858577936466</iyz>
					<izz>0.09264313094014832</izz>
				</inertia>
			</inertial>
			<collision name="pedal_left_collision">
				<geometry>
					<mesh>
						<uri>model://rikshaw/meshes/CAD/pedal_left.stl</uri>
						<scale>0.001 0.001 0.001</scale>
					</mesh>
				</geometry>
			</collision>
			<visual name="pedal_left_visual">
				<geometry>
					<mesh>
						<uri>model://rikshaw/meshes/CAD/pedal_left.stl</uri>
						<scale>0.001 0.001 0.001</scale>
					</mesh>
				</geometry>
			</visual>
		</link>
		<link name="pedal_right">
			<self_collide>false</self_collide>
			<pose frame="">0.22936974881958036 0.13265525635124195 0.18699204441983652 0.0 -0.0 0.0</pose>
			<inertial>
				<pose frame="">0.0 0.0 0.0 0 0 0</pose>
				<mass>1.3791057548146732</mass>
				<inertia>
					<ixx>0.0792588266121774</ixx>
					<ixy>-0.041239315608420014</ixy>
					<ixz>-0.036247382164239415</ixz>
					<iyy>0.12658985919785845</iyy>
					<iyz>-0.05738482595103527</iyz>
					<izz>0.09929970693471371</izz>
				</inertia>
			</inertial>
			<collision name="pedal_right_collision">
				<geometry>
					<mesh>
						<uri>model://rikshaw/meshes/CAD/pedal_right.stl</uri>
						<scale>0.001 0.001 0.001</scale>
					</mesh>
				</geometry>
			</collision>
			<visual name="pedal_right_visual">
				<geometry>
					<mesh>
						<uri>model://rikshaw/meshes/CAD/pedal_right.stl</uri>
						<scale>0.001 0.001 0.001</scale>
					</mesh>
				</geometry>
			</visual>
		</link>
		<link name="thigh_right">
			<self_collide>false</self_collide>
			<pose frame="">0.2130676220272979 0.23075804961914492 0.6636155811866733 0.0 -0.0 0.0</pose>
			<inertial>
				<pose frame="">0.0 0.0 0.0 0 0 0</pose>
				<mass>5.563551531361345</mass>
				<inertia>
					<ixx>2.7587103141393774</ixx>
					<ixy>-0.27653691454319923</ixy>
					<ixz>-0.8525725925194048</ixz>
					<iyy>2.7338304215308424</iyy>
					<iyz>-0.7886856442807302</iyz>
					<izz>0.5768546331244859</izz>
				</inertia>
			</inertial>
			<collision name="thigh_right_collision">
				<geometry>
					<mesh>
						<uri>model://rikshaw/meshes/CAD/thigh_right.stl</uri>
						<scale>0.001 0.001 0.001</scale>
					</mesh>
				</geometry>
			</collision>
			<visual name="thigh_right_visual">
				<geometry>
					<mesh>
						<uri>model://rikshaw/meshes/CAD/thigh_right.stl</uri>
						<scale>0.001 0.001 0.001</scale>
					</mesh>
				</geometry>
			</visual>
		</link>
		<link name="thigh_left">
			<self_collide>false</self_collide>
			<pose frame="">0.33596172751211206 -0.165705685121125 0.5768343943578617 0.0 -0.0 0.0</pose>
			<inertial>
				<pose frame="">0.0 0.0 0.0 0 0 0</pose>
				<mass>5.563586550484201</mass>
				<inertia>
					<ixx>2.032298455269805</ixx>
					<ixy>0.30885145604075287</ixy>
					<ixz>0.5347695724937122</ixz>
					<iyy>2.5103291140248376</iyy>
					<iyz>-1.0778482754769985</iyz>
					<izz>0.7927908850236612</izz>
				</inertia>
			</inertial>
			<collision name="thigh_left_collision">
				<geometry>
					<mesh>
						<uri>model://rikshaw/meshes/CAD/thigh_left.stl</uri>
						<scale>0.001 0.001 0.001</scale>
					</mesh>
				</geometry>
			</collision>
			<visual name="thigh_left_visual">
				<geometry>
					<mesh>
						<uri>model://rikshaw/meshes/CAD/thigh_left.stl</uri>
						<scale>0.001 0.001 0.001</scale>
					</mesh>
				</geometry>
			</visual>
		</link>
		<link name="leg_right">
			<self_collide>false</self_collide>
			<pose frame="">0.13073111293726639 0.23018790159214506 0.5152814010211896 0.0 -0.0 0.0</pose>
			<inertial>
				<pose frame="">0.0 0.0 0.0 0 0 0</pose>
				<mass>5.7416066293880625</mass>
				<inertia>
					<ixx>1.8500195908173283</ixx>
					<ixy>-0.17043594464017472</ixy>
					<ixz>-0.6835654057960041</ixz>
					<iyy>1.6653849427476624</iyy>
					<iyz>-0.37372738986267745</iyz>
					<izz>0.4333240399601409</izz>
				</inertia>
			</inertial>
			<collision name="leg_right_collision">
				<geometry>
					<mesh>
						<uri>model://rikshaw/meshes/CAD/leg_right.stl</uri>
						<scale>0.001 0.001 0.001</scale>
					</mesh>
				</geometry>
			</collision>
			<visual name="leg_right_visual">
				<geometry>
					<mesh>
						<uri>model://rikshaw/meshes/CAD/leg_right.stl</uri>
						<scale>0.001 0.001 0.001</scale>
					</mesh>
				</geometry>
			</visual>
		</link>
		<link name="leg_left">
			<self_collide>false</self_collide>
			<pose frame="">0.35460216180609017 -0.16476933592867768 0.2307814775788578 0.0 -0.0 0.0</pose>
			<inertial>
				<pose frame="">0.0 0.0 0.0 0 0 0</pose>
				<mass>5.742615089607888</mass>
				<inertia>
					<ixx>0.5016738260717913</ixx>
					<ixy>0.3354589885668807</ixy>
					<ixz>0.22180598001631352</ixz>
					<iyy>1.070741512212526</iyy>
					<iyz>-0.4681515967886399</iyz>
					<izz>0.8903661507239246</izz>
				</inertia>
			</inertial>
			<collision name="leg_left_collision">
				<geometry>
					<mesh>
						<uri>model://rikshaw/meshes/CAD/leg_left.stl</uri>
						<scale>0.001 0.001 0.001</scale>
					</mesh>
				</geometry>
			</collision>
			<visual name="leg_left_visual">
				<geometry>
					<mesh>
						<uri>model://rikshaw/meshes/CAD/leg_left.stl</uri>
						<scale>0.001 0.001 0.001</scale>
					</mesh>
				</geometry>
			</visual>
		</link>
		<link name="hip">
			<self_collide>false</self_collide>
			<pose frame="">0.3188054114712725 0.03259725162001076 0.8199215837346147 0.0 -0.0 0.0</pose>
			<inertial>
				<pose frame="">0.0 0.0 0.0 0 0 0</pose>
				<mass>13.796358839496321</mass>
				<inertia>
					<ixx>9.622766189285441</ixx>
					<ixy>-0.14380494608466368</ixy>
					<ixz>-0.36878952400805726</ixz>
					<iyy>10.7532784485541</iyy>
					<iyz>-3.6058239375753556</iyz>
					<izz>1.7419388881373217</izz>
				</inertia>
			</inertial>
			<collision name="hip_collision">
				<geometry>
					<mesh>
						<uri>model://rikshaw/meshes/CAD/hip.stl</uri>
						<scale>0.001 0.001 0.001</scale>
					</mesh>
				</geometry>
			</collision>
			<visual name="hip_visual">
				<geometry>
					<mesh>
						<uri>model://rikshaw/meshes/CAD/hip.stl</uri>
						<scale>0.001 0.001 0.001</scale>
					</mesh>
				</geometry>
			</visual>
		</link>
		<link name="foot_right">
			<self_collide>false</self_collide>
			<pose frame="">0.23078034023968821 0.21050360507473392 0.3301538298419227 0.0 -0.0 0.0</pose>
			<inertial>
				<pose frame="">0.0 0.0 0.0 0 0 0</pose>
				<mass>1.9533512343981427</mass>
				<inertia>
					<ixx>0.3025600513950909</ixx>
					<ixy>-0.09457237923285203</ixy>
					<ixz>-0.13554099111341522</ixz>
					<iyy>0.3246916605138675</iyy>
					<iyz>-0.15191511975860528</iyz>
					<izz>0.1971286762725725</izz>
				</inertia>
			</inertial>
			<collision name="foot_right_collision">
				<geometry>
					<mesh>
						<uri>model://rikshaw/meshes/CAD/foot_right.stl</uri>
						<scale>0.001 0.001 0.001</scale>
					</mesh>
				</geometry>
			</collision>
			<visual name="foot_right_visual">
				<geometry>
					<mesh>
						<uri>model://rikshaw/meshes/CAD/foot_right.stl</uri>
						<scale>0.001 0.001 0.001</scale>
					</mesh>
				</geometry>
			</visual>
		</link>
		<link name="foot_left">
			<self_collide>false</self_collide>
			<pose frame="">0.28746026033547045 -0.1464978271419891 -0.011512207248022328 0.0 -0.0 0.0</pose>
			<inertial>
				<pose frame="">0.0 0.0 0.0 0 0 0</pose>
				<mass>1.9533510268194152</mass>
				<inertia>
					<ixx>0.04386356442023626</ixx>
					<ixy>0.08182852386066176</ixy>
					<ixz>-0.003436930655597172</ixz>
					<iyy>0.16902388320136888</iyy>
					<iyz>0.004970750201399241</iyz>
					<izz>0.21092671026717796</izz>
				</inertia>
			</inertial>
			<collision name="foot_left_collision">
				<geometry>
					<mesh>
						<uri>model://rikshaw/meshes/CAD/foot_left.stl</uri>
						<scale>0.001 0.001 0.001</scale>
					</mesh>
				</geometry>
			</collision>
			<visual name="foot_left_visual">
				<geometry>
					<mesh>
						<uri>model://rikshaw/meshes/CAD/foot_left.stl</uri>
						<scale>0.001 0.001 0.001</scale>
					</mesh>
				</geometry>
			</visual>
		</link>
		<joint name="joint_pedal_right" type="revolute">
			<parent>foot_right</parent>
			<child>pedal_right</child>
			<pose frame="">-0.03989180963305358 0.1244618503468464 0.11647434794801739 0 0 0</pose>
			<axis>
				<xyz>-1.0474289204478013e-10 0.9999999999999999 2.7515982639923474e-10</xyz>
				<limit>
					<lower>-3.141592653589793</lower>
					<upper>3.141592653589793</upper>
				</limit>
				<use_parent_model_frame>0</use_parent_model_frame>
			</axis>
		</joint>
		<joint name="joint_bike_left" type="revolute">
			<parent>pedal_left</parent>
			<child>bike</child>
			<pose frame="">0.33358131896486654 -0.03582698698179355 0.028993015421412752 0 0 0</pose>
			<axis>
				<xyz>1.4238488985885442e-10 -0.9999999999999999 -2.7441464235583507e-10</xyz>
				<limit>
					<lower>-3.141592653589793</lower>
					<upper>3.141592653589793</upper>
				</limit>
				<use_parent_model_frame>0</use_parent_model_frame>
			</axis>
		</joint>
		<joint name="joint_bike_right" type="revolute">
			<parent>pedal_right</parent>
			<child>bike</child>
			<pose frame="">0.3335813189575388 0.034173320050219065 0.02899301544067585 0 0 0</pose>
			<axis>
				<xyz>1.0474358406622928e-10 -1.0000000000000004 -2.7516404609824913e-10</xyz>
				<limit>
					<lower>-3.141592653589793</lower>
					<upper>3.141592653589793</upper>
				</limit>
				<use_parent_model_frame>0</use_parent_model_frame>
			</axis>
		</joint>
		<joint name="joint_pedal_left" type="revolute">
			<parent>foot_left</parent>
			<child>pedal_left</child>
			<pose frame="">-0.001814332799598688 -0.12413718074049786 -0.12182445371959495 0 0 0</pose>
			<axis>
				<xyz>1.4230742896098652e-10 -1.0 -2.7440939389598657e-10</xyz>
				<limit>
					<lower>-3.141592653589793</lower>
					<upper>3.141592653589793</upper>
				</limit>
				<use_parent_model_frame>0</use_parent_model_frame>
			</axis>
		</joint>
		<joint name="joint_hip_left" type="revolute">
			<parent>hip</parent>
			<child>thigh_left</child>
			<pose frame="">-0.014198391986819488 0.010555659221835115 0.11031310191475584 0 0 0</pose>
			<axis>
				<xyz>4.714220161252588e-12 -0.9999999999999999 -4.747072576310608e-10</xyz>
				<limit>
					<lower>-3.141592653589793</lower>
					<upper>3.141592653589793</upper>
				</limit>
				<use_parent_model_frame>0</use_parent_model_frame>
			</axis>
		</joint>
		<joint name="joint_hip_right" type="revolute">
			<parent>hip</parent>
			<child>thigh_right</child>
			<pose frame="">0.10869571349630182 -0.02190807552891389 0.023531915258738254 0 0 0</pose>
			<axis>
				<xyz>4.714117194135765e-12 -0.9999999999999999 -4.747078088732916e-10</xyz>
				<limit>
					<lower>-3.141592653589793</lower>
					<upper>3.141592653589793</upper>
				</limit>
				<use_parent_model_frame>0</use_parent_model_frame>
			</axis>
		</joint>
		<joint name="joint_foot_left" type="revolute">
			<parent>leg_left</parent>
			<child>foot_left</child>
			<pose frame="">0.07180290654911549 0.020897801482261044 0.04334149852288286 0 0 0</pose>
			<axis>
				<xyz>1.7379113579511293e-10 0.9999999999999997 1.5163702627450592e-10</xyz>
				<limit>
					<lower>-3.141592653589793</lower>
					<upper>3.141592653589793</upper>
				</limit>
				<use_parent_model_frame>0</use_parent_model_frame>
			</axis>
		</joint>
		<joint name="joint_knee_right" type="revolute">
			<parent>thigh_right</parent>
			<child>leg_right</child>
			<pose frame="">-0.1102385124091251 -0.013637927463249823 0.10246188711047716 0 0 0</pose>
			<axis>
				<xyz>3.8751886398178056e-11 1.000000000000023 4.832504674201488e-10</xyz>
				<limit>
					<lower>-3.141592653589793</lower>
					<upper>3.141592653589793</upper>
				</limit>
				<use_parent_model_frame>0</use_parent_model_frame>
			</axis>
		</joint>
		<joint name="joint_knee_left" type="revolute">
			<parent>thigh_left</parent>
			<child>leg_left</child>
			<pose frame="">0.009873151240645512 0.033669310169744816 0.15015214413791014 0 0 0</pose>
			<axis>
				<xyz>-2.3658644533201752e-11 -1.0000000000000242 -2.741036256664899e-10</xyz>
				<limit>
					<lower>-3.141592653589793</lower>
					<upper>3.141592653589793</upper>
				</limit>
				<use_parent_model_frame>0</use_parent_model_frame>
			</axis>
		</joint>
		<joint name="joint_foot_right" type="revolute">
			<parent>leg_right</parent>
			<child>foot_right</child>
			<pose frame="">0.05717343818275868 0.011546369209471977 0.06316682467872305 0 0 0</pose>
			<axis>
				<xyz>-8.733427660066444e-11 -1.0000000000000018 -6.907090334408558e-10</xyz>
				<limit>
					<lower>-3.141592653589793</lower>
					<upper>3.141592653589793</upper>
				</limit>
				<use_parent_model_frame>0</use_parent_model_frame>
			</axis>
		</joint>
		<plugin filename="libmusc_plugin.so" name="musc_plugin">
			<myoMuscle name="motor0">
				<link name="hip">
					<viaPoint type="FIXPOINT">4.327833399547235 0.6404851581959281 -0.6761715836734256</viaPoint>
				</link>
				<link name="thigh_left">
					<viaPoint type="FIXPOINT">4.332675041209032 0.7845331012654819 -0.4330843943152818</viaPoint>
					<viaPoint type="FIXPOINT">4.301275449347968 0.7036215233807748 -0.4330843943413848</viaPoint>
				</link>
			</myoMuscle>
			<myoMuscle name="motor1">
				<link name="hip">
					<viaPoint type="FIXPOINT">4.225377970596348 0.6403713949650874 -0.6787715836787723</viaPoint>
				</link>
				<link name="thigh_left">
					<viaPoint type="FIXPOINT">4.232943071558577 0.6847267094780795 -0.43483439433990706</viaPoint>
				</link>
			</myoMuscle>
			<myoMuscle name="motor2">
				<link name="hip">
					<viaPoint type="FIXPOINT">4.222600893598315 0.640371395049156 -1.0271715836795368</viaPoint>
				</link>
				<link name="thigh_right">
					<viaPoint type="FIXPOINT">4.281086263073728 0.4111069712970447 -0.8691155811286033</viaPoint>
				</link>
			</myoMuscle>
			<myoMuscle name="motor3">
				<link name="hip">
					<viaPoint type="FIXPOINT">4.3234080563570885 0.6403713950491444 -1.0271715836690196</viaPoint>
				</link>
				<link name="thigh_right">
					<viaPoint type="FIXPOINT">4.4017504626147215 0.3058244699736617 -0.8701155811540077</viaPoint>
					<viaPoint type="FIXPOINT">4.2929653102866645 0.3172916550200051 -0.8673655811314003</viaPoint>
				</link>
			</myoMuscle>
			<myoMuscle name="motor4">
				<link name="thigh_right">
					<viaPoint type="FIXPOINT">4.194268177665284 0.3854660019166881 -0.864469599358566</viaPoint>
				</link>
				<link name="leg_right">
					<viaPoint type="FIXPOINT">4.093621595700019 0.2514920865964622 -0.7162814015515123</viaPoint>
					<viaPoint type="FIXPOINT">4.239103653436476 0.1850528493718759 -0.7171761384248815</viaPoint>
				</link>
			</myoMuscle>
			<myoMuscle name="motor5">
				<link name="thigh_right">
					<viaPoint type="FIXPOINT">4.205259111977764 0.31126984332122226 -0.8691684780447413</viaPoint>
				</link>
				<link name="leg_right">
					<viaPoint type="FIXPOINT">4.2683722168217235 0.2567824543999967 -0.717281401546244</viaPoint>
				</link>
			</myoMuscle>
			<myoMuscle name="motor6">
				<link name="thigh_left">
					<viaPoint type="FIXPOINT">4.225798473718114 0.5953431127785443 -0.43606425243522334</viaPoint>
				</link>
				<link name="leg_left">
					<viaPoint type="FIXPOINT">4.1854091785355925 0.46782672876668896 -0.08403147751508039</viaPoint>
					<viaPoint type="FIXPOINT">4.234867788423367 0.3446177513202678 -0.0850314775538838</viaPoint>
				</link>
			</myoMuscle>
			<myoMuscle name="motor7">
				<link name="thigh_left">
					<viaPoint type="FIXPOINT">4.327733083658931 0.594995650282452 -0.43611450900673676</viaPoint>
				</link>
				<link name="leg_left">
					<viaPoint type="FIXPOINT">4.286669765952606 0.3388085066413993 -0.08903147756444628</viaPoint>
				</link>
			</myoMuscle>
			<myoMuscle name="motor8">
				<link name="leg_left">
					<viaPoint type="FIXPOINT">4.313970639383619 0.24916873309390866 -0.09031159024997232</viaPoint>
				</link>
				<link name="foot_left">
					<viaPoint type="FIXPOINT">4.3970965730178175 0.0665035696689139 0.15326220728736792</viaPoint>
				</link>
			</myoMuscle>
			<myoMuscle name="motor9">
				<link name="leg_left">
					<viaPoint type="FIXPOINT">4.229134080776311 0.24880135463795192 -0.08948191279141118</viaPoint>
				</link>
				<link name="foot_left">
					<viaPoint type="FIXPOINT">4.229703770422645 0.06623182171348745 0.1532622072423362</viaPoint>
				</link>
			</myoMuscle>
			<myoMuscle name="motor10">
				<link name="leg_right">
					<viaPoint type="FIXPOINT">4.2841889681279826 0.1324478856026151 -0.7176467365314096</viaPoint>
				</link>
				<link name="foot_right">
					<viaPoint type="FIXPOINT">4.261351961497274 0.060167787166551606 -0.5341538305478616</viaPoint>
				</link>
			</myoMuscle>
			<myoMuscle name="motor11">
				<link name="leg_right">
					<viaPoint type="FIXPOINT">4.338681420099781 0.1865283572376562 -0.7212476959244845</viaPoint>
				</link>
				<link name="foot_right">
					<viaPoint type="FIXPOINT">4.390745631389317 0.08764896055465514 -0.5341538305155951</viaPoint>
				</link>
			</myoMuscle>
		</plugin>
	</model>
</sdf>
