<sdf version="1.6">
	<model name="rikshaw">
		<link name="bike">
			<self_collide>false</self_collide>
			<pose frame="">1.310899896367346e-07 -2.442664557200658e-07 1.774980865576481e-07 0.0 -0.0 0.0</pose>
			<inertial>
				<pose frame="">0.0 0.0 0.0 0 0 0</pose>
				<mass>21.81947805717533</mass>
				<inertia>
					<ixx>5.886482099704385</ixx>
					<ixy>0.05246604407007407</ixy>
					<ixz>-0.14605334861846847</ixz>
					<iyy>9.145464405182723</iyy>
					<iyz>2.3093169469685275</iyz>
					<izz>3.8627096944427937</izz>
				</inertia>
			</inertial>
			<collision name="bike_collision">
				<geometry>
					<mesh>
						<uri>model://rikshaw/meshes/collisions/bike.stl</uri>
						<scale>0.001 0.001 0.001</scale>
					</mesh>
				</geometry>
			</collision>
			<visual name="bike_visual">
				<geometry>
					<mesh>
						<uri>model://rikshaw/meshes/visuals/bike.stl</uri>
						<scale>0.001 0.001 0.001</scale>
					</mesh>
				</geometry>
			</visual>
		</link>
		<link name="upper_arm_right">
			<self_collide>false</self_collide>
			<pose frame="">-0.22287861737836615 -0.4003629869395849 1.073812604810606 0.0 -0.0 0.0</pose>
			<inertial>
				<pose frame="">0.0 0.0 0.0 0 0 0</pose>
				<mass>1.0945525999991552</mass>
				<inertia>
					<ixx>1.4421148034784848</ixx>
					<ixy>-0.0977475801484251</ixy>
					<ixz>0.4688762159986468</ixz>
					<iyy>1.3199753951468367</iyy>
					<iyz>0.26189149622628766</iyz>
					<izz>0.2343257965627362</izz>
				</inertia>
			</inertial>
			<collision name="upper_arm_right_collision">
				<geometry>
					<mesh>
						<uri>model://rikshaw/meshes/collisions/upper_arm_right.stl</uri>
						<scale>0.001 0.001 0.001</scale>
					</mesh>
				</geometry>
			</collision>
			<visual name="upper_arm_right_visual">
				<geometry>
					<mesh>
						<uri>model://rikshaw/meshes/visuals/upper_arm_right.stl</uri>
						<scale>0.001 0.001 0.001</scale>
					</mesh>
				</geometry>
			</visual>
		</link>
		<link name="torso">
			<self_collide>false</self_collide>
			<pose frame="">0.0 0.0 0.0 0.0 -0.0 0.0</pose>
			<inertial>
				<pose frame="">0.0 0.0 0.0 0 0 0</pose>
				<mass>12.829194596051684</mass>
				<inertia>
					<ixx>17.25655500920537</ixx>
					<ixy>0.04357283427721384</ixy>
					<ixz>-0.2404715577566944</ixz>
					<iyy>17.518149027040117</iyy>
					<iyz>2.95154696517872</iyz>
					<izz>0.8597492821307174</izz>
				</inertia>
			</inertial>
			<collision name="torso_collision">
				<geometry>
					<mesh>
						<uri>model://rikshaw/meshes/collisions/torso.stl</uri>
						<scale>0.001 0.001 0.001</scale>
					</mesh>
				</geometry>
			</collision>
			<visual name="torso_visual">
				<geometry>
					<mesh>
						<uri>model://rikshaw/meshes/visuals/torso.stl</uri>
						<scale>0.001 0.001 0.001</scale>
					</mesh>
				</geometry>
			</visual>
		</link>
		<link name="front_part">
			<self_collide>false</self_collide>
			<pose frame="">0.7163902600571725 -0.010388552466272516 0.2164376942146126 0.0 -0.0 0.0</pose>
			<inertial>
				<pose frame="">0.0 0.0 0.0 0 0 0</pose>
				<mass>16.810672465638184</mass>
				<inertia>
					<ixx>3.2092296528945967</ixx>
					<ixy>0.18113615628275678</ixy>
					<ixz>0.006723073533121614</ixz>
					<iyy>14.66296026711583</iyy>
					<iyz>-1.241970673631743</iyz>
					<izz>13.91291969418297</izz>
				</inertia>
			</inertial>
			<collision name="front_part_collision">
				<geometry>
					<mesh>
						<uri>model://rikshaw/meshes/collisions/front_part.stl</uri>
						<scale>0.001 0.001 0.001</scale>
					</mesh>
				</geometry>
			</collision>
			<visual name="front_part_visual">
				<geometry>
					<mesh>
						<uri>model://rikshaw/meshes/visuals/front_part.stl</uri>
						<scale>0.001 0.001 0.001</scale>
					</mesh>
				</geometry>
			</visual>
		</link>
		<link name="left_wheel">
			<self_collide>false</self_collide>
			<pose frame="">0.9984258521253293 0.3500004088111501 0.04566700000000771 0.0 -0.0 0.0</pose>
			<inertial>
				<pose frame="">0.0 0.0 0.0 0 0 0</pose>
				<mass>13.34016392909787</mass>
				<inertia>
					<ixx>2.171169531427472</ixx>
					<ixy>-4.661713033463371</ixy>
					<ixz>-0.21322209220250452</ixz>
					<iyy>14.34232616188963</iyy>
					<iyz>-0.608246286975269</iyz>
					<izz>15.441547158388817</izz>
				</inertia>
			</inertial>
			<collision name="left_wheel_collision">
				<geometry>
					<mesh>
						<uri>model://rikshaw/meshes/collisions/left_wheel.stl</uri>
						<scale>0.001 0.001 0.001</scale>
					</mesh>
				</geometry>
			</collision>
			<visual name="left_wheel_visual">
				<geometry>
					<mesh>
						<uri>model://rikshaw/meshes/visuals/left_wheel.stl</uri>
						<scale>0.001 0.001 0.001</scale>
					</mesh>
				</geometry>
			</visual>
		</link>
		<link name="right_wheel">
			<self_collide>false</self_collide>
			<pose frame="">0.9984258521253289 -0.3420002694171169 0.04566700000003821 0.0 -0.0 0.0</pose>
			<inertial>
				<pose frame="">0.0 0.0 0.0 0 0 0</pose>
				<mass>13.34016392909787</mass>
				<inertia>
					<ixx>2.097317024732184</ixx>
					<ixy>4.55515786054409</ixy>
					<ixz>0.2083483651538148</ixz>
					<iyy>14.342326161889634</iyy>
					<iyz>-0.6082462869756708</iyz>
					<izz>15.367694651693467</izz>
				</inertia>
			</inertial>
			<collision name="right_wheel_collision">
				<geometry>
					<mesh>
						<uri>model://rikshaw/meshes/collisions/right_wheel.stl</uri>
						<scale>0.001 0.001 0.001</scale>
					</mesh>
				</geometry>
			</collision>
			<visual name="right_wheel_visual">
				<geometry>
					<mesh>
						<uri>model://rikshaw/meshes/visuals/right_wheel.stl</uri>
						<scale>0.001 0.001 0.001</scale>
					</mesh>
				</geometry>
			</visual>
		</link>
		<link name="pedal_right">
			<self_collide>false</self_collide>
			<pose frame="">-0.07786651206439894 -0.14798929042854508 0.17187503593715864 0.0 -0.0 0.0</pose>
			<inertial>
				<pose frame="">0.0 0.0 0.0 0 0 0</pose>
				<mass>0.9460025886020137</mass>
				<inertia>
					<ixx>0.049584952858416534</ixx>
					<ixy>-0.01090117556517612</ixy>
					<ixz>0.024062204564554542</ixz>
					<iyy>0.03409659621084031</iyy>
					<iyz>0.012633073677194193</iyz>
					<izz>0.027060626295967245</izz>
				</inertia>
			</inertial>
			<collision name="pedal_right_collision">
				<geometry>
					<mesh>
						<uri>model://rikshaw/meshes/collisions/pedal_right.stl</uri>
						<scale>0.001 0.001 0.001</scale>
					</mesh>
				</geometry>
			</collision>
			<visual name="pedal_right_visual">
				<geometry>
					<mesh>
						<uri>model://rikshaw/meshes/visuals/pedal_right.stl</uri>
						<scale>0.001 0.001 0.001</scale>
					</mesh>
				</geometry>
			</visual>
		</link>
		<link name="kurbel">
			<self_collide>false</self_collide>
			<pose frame="">-0.09222872619138844 -0.0001317180120880801 0.004277283496540975 0.0 -0.0 0.0</pose>
			<inertial>
				<pose frame="">0.0 0.0 0.0 0 0 0</pose>
				<mass>2.7832708381107603</mass>
				<inertia>
					<ixx>0.0332152555656024</ixx>
					<ixy>0.001021810155673795</ixy>
					<ixz>0.012937192477663303</ixz>
					<iyy>0.041586881852696926</iyy>
					<iyz>-0.0003014363494414667</iyz>
					<izz>0.039731070916128416</izz>
				</inertia>
			</inertial>
			<collision name="kurbel_collision">
				<geometry>
					<mesh>
						<uri>model://rikshaw/meshes/collisions/kurbel.stl</uri>
						<scale>0.001 0.001 0.001</scale>
					</mesh>
				</geometry>
			</collision>
			<visual name="kurbel_visual">
				<geometry>
					<mesh>
						<uri>model://rikshaw/meshes/visuals/kurbel.stl</uri>
						<scale>0.001 0.001 0.001</scale>
					</mesh>
				</geometry>
			</visual>
		</link>
		<link name="pedal_left">
			<self_collide>false</self_collide>
			<pose frame="">-0.10738103245690382 0.14924470957145564 -0.16537796258198204 0.0 -0.0 0.0</pose>
			<inertial>
				<pose frame="">0.0 0.0 0.0 0 0 0</pose>
				<mass>0.9460025886020093</mass>
				<inertia>
					<ixx>0.047865070945934965</ixx>
					<ixy>0.01516068573344577</ixy>
					<ixz>0.023349033442654262</ixz>
					<iyy>0.037196017563941204</iyy>
					<iyz>-0.016827373941817634</iyz>
					<izz>0.03258593744910717</izz>
				</inertia>
			</inertial>
			<collision name="pedal_left_collision">
				<geometry>
					<mesh>
						<uri>model://rikshaw/meshes/collisions/pedal_left.stl</uri>
						<scale>0.001 0.001 0.001</scale>
					</mesh>
				</geometry>
			</collision>
			<visual name="pedal_left_visual">
				<geometry>
					<mesh>
						<uri>model://rikshaw/meshes/visuals/pedal_left.stl</uri>
						<scale>0.001 0.001 0.001</scale>
					</mesh>
				</geometry>
			</visual>
		</link>
		<link name="foot_left">
			<self_collide>false</self_collide>
			<pose frame="">-0.17583358320217474 0.18852199978740125 -0.20648446058656983 0.0 -0.0 0.0</pose>
			<inertial>
				<pose frame="">0.0 0.0 0.0 0 0 0</pose>
				<mass>0.7294147785294234</mass>
				<inertia>
					<ixx>0.05407216953667249</ixx>
					<ixy>0.03251612036702484</ixy>
					<ixz>0.026761208182578378</ixz>
					<iyy>0.06910783811131357</iyy>
					<iyz>-0.03357311404413584</iyz>
					<izz>0.06737097284992735</izz>
				</inertia>
			</inertial>
			<collision name="foot_left_collision">
				<geometry>
					<mesh>
						<uri>model://rikshaw/meshes/collisions/foot_left.stl</uri>
						<scale>0.001 0.001 0.001</scale>
					</mesh>
				</geometry>
			</collision>
			<visual name="foot_left_visual">
				<geometry>
					<mesh>
						<uri>model://rikshaw/meshes/visuals/foot_left.stl</uri>
						<scale>0.001 0.001 0.001</scale>
					</mesh>
				</geometry>
			</visual>
		</link>
		<link name="foot_left_tip">
			<self_collide>false</self_collide>
			<pose frame="">-0.13523838377491149 0.18735459670162263 -0.21215746469145746 0.0 -0.0 0.0</pose>
			<inertial>
				<pose frame="">0.0 0.0 0.0 0 0 0</pose>
				<mass>0.27796086995260727</mass>
				<inertia>
					<ixx>0.022352432140757796</ixx>
					<ixy>0.007051209655856457</ixy>
					<ixz>0.01104791819788336</ixz>
					<iyy>0.017709776432757476</iyy>
					<iyz>-0.007965691482024362</iyz>
					<izz>0.01503260538749266</izz>
				</inertia>
			</inertial>
			<collision name="foot_left_tip_collision">
				<geometry>
					<mesh>
						<uri>model://rikshaw/meshes/collisions/foot_left_tip.stl</uri>
						<scale>0.001 0.001 0.001</scale>
					</mesh>
				</geometry>
			</collision>
			<visual name="foot_left_tip_visual">
				<geometry>
					<mesh>
						<uri>model://rikshaw/meshes/visuals/foot_left_tip.stl</uri>
						<scale>0.001 0.001 0.001</scale>
					</mesh>
				</geometry>
			</visual>
		</link>
		<link name="foot_right">
			<self_collide>false</self_collide>
			<pose frame="">-0.17755692904068934 -0.15962800036486463 -0.2048798081230718 0.0 -0.0 0.0</pose>
			<inertial>
				<pose frame="">0.0 0.0 0.0 0 0 0</pose>
				<mass>0.7293884039293155</mass>
				<inertia>
					<ixx>0.046628493153724276</ixx>
					<ixy>-0.027737105196730626</ixy>
					<ixz>-0.02258940931322784</ixz>
					<iyy>0.06999759190491005</iyy>
					<iyz>-0.033939836746644796</iyz>
					<izz>0.06080277396500069</izz>
				</inertia>
			</inertial>
			<collision name="foot_right_collision">
				<geometry>
					<mesh>
						<uri>model://rikshaw/meshes/collisions/foot_right.stl</uri>
						<scale>0.001 0.001 0.001</scale>
					</mesh>
				</geometry>
			</collision>
			<visual name="foot_right_visual">
				<geometry>
					<mesh>
						<uri>model://rikshaw/meshes/visuals/foot_right.stl</uri>
						<scale>0.001 0.001 0.001</scale>
					</mesh>
				</geometry>
			</visual>
		</link>
		<link name="foot_right_tip">
			<self_collide>false</self_collide>
			<pose frame="">-0.1374757584185959 -0.15796062268710265 -0.2111101488022362 0.0 -0.0 0.0</pose>
			<inertial>
				<pose frame="">0.0 0.0 0.0 0 0 0</pose>
				<mass>0.27795073699924977</mass>
				<inertia>
					<ixx>0.01940696459090878</ixx>
					<ixy>-0.006044281399509699</ixy>
					<ixz>-0.009268276323839846</ixz>
					<iyy>0.017755497306462847</iyy>
					<iyz>-0.008058438745184075</iyz>
					<izz>0.012380586242452746</izz>
				</inertia>
			</inertial>
			<collision name="foot_right_tip_collision">
				<geometry>
					<mesh>
						<uri>model://rikshaw/meshes/collisions/foot_right_tip.stl</uri>
						<scale>0.001 0.001 0.001</scale>
					</mesh>
				</geometry>
			</collision>
			<visual name="foot_right_tip_visual">
				<geometry>
					<mesh>
						<uri>model://rikshaw/meshes/visuals/foot_right_tip.stl</uri>
						<scale>0.001 0.001 0.001</scale>
					</mesh>
				</geometry>
			</visual>
		</link>
		<link name="thigh_right">
			<self_collide>false</self_collide>
			<pose frame="">-0.2288097432546992 -0.18383580219063253 0.3778972700415497 0.0 -0.0 0.0</pose>
			<inertial>
				<pose frame="">0.0 0.0 0.0 0 0 0</pose>
				<mass>5.563544538495218</mass>
				<inertia>
					<ixx>1.0107794337760492</ixx>
					<ixy>-0.23394874645676036</ixy>
					<ixz>0.3895573298264988</ixz>
					<iyy>1.116934262404504</iyy>
					<iyz>0.4818341397585977</iyz>
					<izz>0.49142600627784244</izz>
				</inertia>
			</inertial>
			<collision name="thigh_right_collision">
				<geometry>
					<mesh>
						<uri>model://rikshaw/meshes/collisions/thigh_right.stl</uri>
						<scale>0.001 0.001 0.001</scale>
					</mesh>
				</geometry>
			</collision>
			<visual name="thigh_right_visual">
				<geometry>
					<mesh>
						<uri>model://rikshaw/meshes/visuals/thigh_right.stl</uri>
						<scale>0.001 0.001 0.001</scale>
					</mesh>
				</geometry>
			</visual>
		</link>
		<link name="thigh_left">
			<self_collide>false</self_collide>
			<pose frame="">-0.2292807025616207 0.2126278059044757 0.37790682144510335 0.0 -0.0 0.0</pose>
			<inertial>
				<pose frame="">0.0 0.0 0.0 0 0 0</pose>
				<mass>5.563607010025899</mass>
				<inertia>
					<ixx>1.0743502428394167</ixx>
					<ixy>0.27061255753829405</ixy>
					<ixz>-0.4500948529131707</ixz>
					<iyy>1.1181878375700518</iyy>
					<iyz>0.4831083644344466</iyz>
					<izz>0.5561313234967189</izz>
				</inertia>
			</inertial>
			<collision name="thigh_left_collision">
				<geometry>
					<mesh>
						<uri>model://rikshaw/meshes/collisions/thigh_left.stl</uri>
						<scale>0.001 0.001 0.001</scale>
					</mesh>
				</geometry>
			</collision>
			<visual name="thigh_left_visual">
				<geometry>
					<mesh>
						<uri>model://rikshaw/meshes/visuals/thigh_left.stl</uri>
						<scale>0.001 0.001 0.001</scale>
					</mesh>
				</geometry>
			</visual>
		</link>
		<link name="leg_right">
			<self_collide>false</self_collide>
			<pose frame="">-0.23291239341706327 -0.18326551525220983 0.029972767090955945 0.0 -0.0 0.0</pose>
			<inertial>
				<pose frame="">0.0 0.0 0.0 0 0 0</pose>
				<mass>5.741539074839567</mass>
				<inertia>
					<ixx>0.23782026670704295</ixx>
					<ixy>-0.2455186518053473</ixy>
					<ixz>0.03496971541512629</ixz>
					<iyy>0.35940035869454817</iyy>
					<iyz>0.03759088986317208</iyz>
					<izz>0.5167570394584527</izz>
				</inertia>
			</inertial>
			<collision name="leg_right_collision">
				<geometry>
					<mesh>
						<uri>model://rikshaw/meshes/collisions/leg_right.stl</uri>
						<scale>0.001 0.001 0.001</scale>
					</mesh>
				</geometry>
			</collision>
			<visual name="leg_right_visual">
				<geometry>
					<mesh>
						<uri>model://rikshaw/meshes/visuals/leg_right.stl</uri>
						<scale>0.001 0.001 0.001</scale>
					</mesh>
				</geometry>
			</visual>
		</link>
		<link name="leg_left">
			<self_collide>false</self_collide>
			<pose frame="">-0.23204406711003875 0.21169140263300495 0.03008521594900539 0.0 -0.0 0.0</pose>
			<inertial>
				<pose frame="">0.0 0.0 0.0 0 0 0</pose>
				<mass>5.742633907090983</mass>
				<inertia>
					<ixx>0.3024377123250296</ixx>
					<ixy>0.28200011187752894</ixy>
					<ixz>-0.04001203273953342</ixz>
					<iyy>0.3572039205308176</iyy>
					<iyz>0.0381306989371113</iyz>
					<izz>0.5789452561844931</izz>
				</inertia>
			</inertial>
			<collision name="leg_left_collision">
				<geometry>
					<mesh>
						<uri>model://rikshaw/meshes/collisions/leg_left.stl</uri>
						<scale>0.001 0.001 0.001</scale>
					</mesh>
				</geometry>
			</collision>
			<visual name="leg_left_visual">
				<geometry>
					<mesh>
						<uri>model://rikshaw/meshes/visuals/leg_left.stl</uri>
						<scale>0.001 0.001 0.001</scale>
					</mesh>
				</geometry>
			</visual>
		</link>
		<link name="wheel_back">
			<self_collide>false</self_collide>
			<pose frame="">-0.5368974286036897 -0.0035499556212921935 0.0494158702490248 0.0 -0.0 0.0</pose>
			<inertial>
				<pose frame="">0.0 0.0 0.0 0 0 0</pose>
				<mass>13.340163929098493</mass>
				<inertia>
					<ixx>0.5419188938328757</ixx>
					<ixy>-0.025425846119324413</ixy>
					<ixz>0.0023401868697195947</ixz>
					<iyy>4.894303401629517</iyy>
					<iyz>0.35393127318782075</iyz>
					<izz>4.354763468464214</izz>
				</inertia>
			</inertial>
			<collision name="wheel_back_collision">
				<geometry>
					<mesh>
						<uri>model://rikshaw/meshes/collisions/wheel_back.stl</uri>
						<scale>0.001 0.001 0.001</scale>
					</mesh>
				</geometry>
			</collision>
			<visual name="wheel_back_visual">
				<geometry>
					<mesh>
						<uri>model://rikshaw/meshes/visuals/wheel_back.stl</uri>
						<scale>0.001 0.001 0.001</scale>
					</mesh>
				</geometry>
			</visual>
		</link>
		<link name="elbow_left">
			<self_collide>false</self_collide>
			<pose frame="">-0.23066409509999589 0.5401171716105586 0.9674697426308526 0.0 -0.0 0.0</pose>
			<inertial>
				<pose frame="">0.0 0.0 0.0 0 0 0</pose>
				<mass>0.15681540300967223</mass>
				<inertia>
					<ixx>0.19266629450625464</ixx>
					<ixy>0.019541794174774592</ixy>
					<ixz>-0.08195067996592703</ixz>
					<iyy>0.1552331043974446</iyy>
					<iyz>0.034994843981859466</iyz>
					<izz>0.05422684654213822</izz>
				</inertia>
			</inertial>
			<collision name="elbow_left_collision">
				<geometry>
					<mesh>
						<uri>model://rikshaw/meshes/collisions/elbow_left.stl</uri>
						<scale>0.001 0.001 0.001</scale>
					</mesh>
				</geometry>
			</collision>
			<visual name="elbow_left_visual">
				<geometry>
					<mesh>
						<uri>model://rikshaw/meshes/visuals/elbow_left.stl</uri>
						<scale>0.001 0.001 0.001</scale>
					</mesh>
				</geometry>
			</visual>
		</link>
		<link name="elbow_right">
			<self_collide>false</self_collide>
			<pose frame="">-0.23072494665910095 -0.5136902854210897 0.9649761410858565 0.0 -0.0 0.0</pose>
			<inertial>
				<pose frame="">0.0 0.0 0.0 0 0 0</pose>
				<mass>0.1735064537201356</mass>
				<inertia>
					<ixx>0.2075000206797995</ixx>
					<ixy>-0.02056914602319384</ixy>
					<ixz>0.08601030782639262</ixz>
					<iyy>0.17091898467001698</iyy>
					<iyz>0.03862988659000414</iyz>
					<izz>0.055162486401777906</izz>
				</inertia>
			</inertial>
			<collision name="elbow_right_collision">
				<geometry>
					<mesh>
						<uri>model://rikshaw/meshes/collisions/elbow_right.stl</uri>
						<scale>0.001 0.001 0.001</scale>
					</mesh>
				</geometry>
			</collision>
			<visual name="elbow_right_visual">
				<geometry>
					<mesh>
						<uri>model://rikshaw/meshes/visuals/elbow_right.stl</uri>
						<scale>0.001 0.001 0.001</scale>
					</mesh>
				</geometry>
			</visual>
		</link>
		<link name="left_shoulder_link1">
			<self_collide>false</self_collide>
			<pose frame="">-0.21902257250894014 0.30660205307510063 1.1633275713285138 0.0 -0.0 0.0</pose>
			<inertial>
				<pose frame="">0.0 0.0 0.0 0 0 0</pose>
				<mass>0.046753849896631366</mass>
				<inertia>
					<ixx>0.06767449740992429</ixx>
					<ixy>0.00313965054739232</ixy>
					<ixz>-0.01667609874350618</ixz>
					<iyy>0.06552223385053244</iyy>
					<iyz>0.0119126470601849</iyz>
					<izz>0.006643884826415351</izz>
				</inertia>
			</inertial>
			<collision name="left_shoulder_link1_collision">
				<geometry>
					<mesh>
						<uri>model://rikshaw/meshes/collisions/left_shoulder_link1.stl</uri>
						<scale>0.001 0.001 0.001</scale>
					</mesh>
				</geometry>
			</collision>
			<visual name="left_shoulder_link1_visual">
				<geometry>
					<mesh>
						<uri>model://rikshaw/meshes/visuals/left_shoulder_link1.stl</uri>
						<scale>0.001 0.001 0.001</scale>
					</mesh>
				</geometry>
			</visual>
		</link>
		<link name="left_shoulder_link2">
			<self_collide>false</self_collide>
			<pose frame="">-0.21902251991402213 0.30660324302695735 1.1633275703688477 0.0 -0.0 0.0</pose>
			<inertial>
				<pose frame="">0.0 0.0 0.0 0 0 0</pose>
				<mass>0.031337295884972576</mass>
				<inertia>
					<ixx>0.045358313011474534</ixx>
					<ixy>0.0021043939017770154</ixy>
					<ixz>-0.011177386877311443</ixz>
					<iyy>0.04391571091145054</iyy>
					<iyz>0.007984584297783932</iyz>
					<izz>0.004451855074852757</izz>
				</inertia>
			</inertial>
			<collision name="left_shoulder_link2_collision">
				<geometry>
					<mesh>
						<uri>model://rikshaw/meshes/collisions/left_shoulder_link2.stl</uri>
						<scale>0.001 0.001 0.001</scale>
					</mesh>
				</geometry>
			</collision>
			<visual name="left_shoulder_link2_visual">
				<geometry>
					<mesh>
						<uri>model://rikshaw/meshes/visuals/left_shoulder_link2.stl</uri>
						<scale>0.001 0.001 0.001</scale>
					</mesh>
				</geometry>
			</visual>
		</link>
		<link name="wrist_left_1">
			<self_collide>false</self_collide>
			<pose frame="">-0.24088719522801216 0.7562832464364361 0.7745298640433302 0.0 -0.0 0.0</pose>
			<inertial>
				<pose frame="">0.0 0.0 0.0 0 0 0</pose>
				<mass>0.01276210274228386</mass>
				<inertia>
					<ixx>0.014958953395600197</ixx>
					<ixy>0.0023249649587372334</ixy>
					<ixz>-0.0074769785070066775</ixz>
					<iyy>0.008400668033256913</iyy>
					<iyz>0.002381158490744941</iyz>
					<izz>0.008043893530445803</izz>
				</inertia>
			</inertial>
			<collision name="wrist_left_1_collision">
				<geometry>
					<mesh>
						<uri>model://rikshaw/meshes/collisions/wrist_left_1.stl</uri>
						<scale>0.001 0.001 0.001</scale>
					</mesh>
				</geometry>
			</collision>
			<visual name="wrist_left_1_visual">
				<geometry>
					<mesh>
						<uri>model://rikshaw/meshes/visuals/wrist_left_1.stl</uri>
						<scale>0.001 0.001 0.001</scale>
					</mesh>
				</geometry>
			</visual>
		</link>
		<link name="left_hand">
			<self_collide>false</self_collide>
			<pose frame="">-0.2472829707751968 0.8144879664655759 0.717797943440462 0.0 -0.0 0.0</pose>
			<inertial>
				<pose frame="">0.0 0.0 0.0 0 0 0</pose>
				<mass>0.08391854013243093</mass>
				<inertia>
					<ixx>0.0990936807995511</ixx>
					<ixy>0.016915179144618795</ixy>
					<ixz>-0.04898119948040993</ixz>
					<iyy>0.04850556851408662</iyy>
					<iyz>0.014877442754935744</iyz>
					<izz>0.06095909720368022</izz>
				</inertia>
			</inertial>
			<collision name="left_hand_collision">
				<geometry>
					<mesh>
						<uri>model://rikshaw/meshes/collisions/left_hand.stl</uri>
						<scale>0.001 0.001 0.001</scale>
					</mesh>
				</geometry>
			</collision>
			<visual name="left_hand_visual">
				<geometry>
					<mesh>
						<uri>model://rikshaw/meshes/visuals/left_hand.stl</uri>
						<scale>0.001 0.001 0.001</scale>
					</mesh>
				</geometry>
			</visual>
		</link>
		<link name="wrist_right_1">
			<self_collide>false</self_collide>
			<pose frame="">-0.2410890221186818 -0.7319772164849917 0.7744475046092366 0.0 -0.0 0.0</pose>
			<inertial>
				<pose frame="">0.0 0.0 0.0 0 0 0</pose>
				<mass>0.012761742618737516</mass>
				<inertia>
					<ixx>0.014495265462586292</ixx>
					<ixy>-0.002252044804095112</ixy>
					<ixz>0.007235730703507522</ixz>
					<iyy>0.008400166661985523</iyy>
					<iyz>0.002382816635337103</iyz>
					<izz>0.007583144518463848</izz>
				</inertia>
			</inertial>
			<collision name="wrist_right_1_collision">
				<geometry>
					<mesh>
						<uri>model://rikshaw/meshes/collisions/wrist_right_1.stl</uri>
						<scale>0.001 0.001 0.001</scale>
					</mesh>
				</geometry>
			</collision>
			<visual name="wrist_right_1_visual">
				<geometry>
					<mesh>
						<uri>model://rikshaw/meshes/visuals/wrist_right_1.stl</uri>
						<scale>0.001 0.001 0.001</scale>
					</mesh>
				</geometry>
			</visual>
		</link>
		<link name="right_hand">
			<self_collide>false</self_collide>
			<pose frame="">-0.24630211259917092 -0.793844358067563 0.7213589039660698 0.0 -0.0 0.0</pose>
			<inertial>
				<pose frame="">0.0 0.0 0.0 0 0 0</pose>
				<mass>0.08391560474704363</mass>
				<inertia>
					<ixx>0.09673260828008547</ixx>
					<ixy>-0.01642785532035098</ixy>
					<ixz>0.04797394115153065</ixz>
					<iyy>0.0488781699072868</iyy>
					<iyz>0.014904604866633244</iyz>
					<izz>0.058149691796935264</izz>
				</inertia>
			</inertial>
			<collision name="right_hand_collision">
				<geometry>
					<mesh>
						<uri>model://rikshaw/meshes/collisions/right_hand.stl</uri>
						<scale>0.001 0.001 0.001</scale>
					</mesh>
				</geometry>
			</collision>
			<visual name="right_hand_visual">
				<geometry>
					<mesh>
						<uri>model://rikshaw/meshes/visuals/right_hand.stl</uri>
						<scale>0.001 0.001 0.001</scale>
					</mesh>
				</geometry>
			</visual>
		</link>
		<link name="upper_arm_left">
			<self_collide>false</self_collide>
			<pose frame="">-0.2252960596449966 0.42958897523062484 1.0743437474386435 0.0 -0.0 0.0</pose>
			<inertial>
				<pose frame="">0.0 0.0 0.0 0 0 0</pose>
				<mass>1.1803819781445266</mass>
				<inertia>
					<ixx>1.585242002687883</ixx>
					<ixy>0.11434969923035074</ixy>
					<ixz>-0.5429322961403309</ixz>
					<iyy>1.4261049013852967</iyy>
					<iyz>0.28558236377926466</iyz>
					<izz>0.2826519290728222</izz>
				</inertia>
			</inertial>
			<collision name="upper_arm_left_collision">
				<geometry>
					<mesh>
						<uri>model://rikshaw/meshes/collisions/upper_arm_left.stl</uri>
						<scale>0.001 0.001 0.001</scale>
					</mesh>
				</geometry>
			</collision>
			<visual name="upper_arm_left_visual">
				<geometry>
					<mesh>
						<uri>model://rikshaw/meshes/visuals/upper_arm_left.stl</uri>
						<scale>0.001 0.001 0.001</scale>
					</mesh>
				</geometry>
			</visual>
		</link>
		<link name="lower_arm_left">
			<self_collide>false</self_collide>
			<pose frame="">-0.235755404130434 0.6503756188584698 0.8673556347512142 0.0 -0.0 0.0</pose>
			<inertial>
				<pose frame="">0.0 0.0 0.0 0 0 0</pose>
				<mass>1.4159186820905578</mass>
				<inertia>
					<ixx>1.6711043719939074</ixx>
					<ixy>0.21726236763332382</ixy>
					<ixz>-0.7959155751086089</ixz>
					<iyy>1.1476118832810638</iyy>
					<iyz>0.28939502409604073</iyz>
					<izz>0.6821912770719468</izz>
				</inertia>
			</inertial>
			<collision name="lower_arm_left_collision">
				<geometry>
					<mesh>
						<uri>model://rikshaw/meshes/collisions/lower_arm_left.stl</uri>
						<scale>0.001 0.001 0.001</scale>
					</mesh>
				</geometry>
			</collision>
			<visual name="lower_arm_left_visual">
				<geometry>
					<mesh>
						<uri>model://rikshaw/meshes/visuals/lower_arm_left.stl</uri>
						<scale>0.001 0.001 0.001</scale>
					</mesh>
				</geometry>
			</visual>
		</link>
		<link name="lower_arm_right">
			<self_collide>false</self_collide>
			<pose frame="">-0.23591830318609724 -0.6254849907380644 0.864217720299911 0.0 -0.0 0.0</pose>
			<inertial>
				<pose frame="">0.0 0.0 0.0 0 0 0</pose>
				<mass>1.3992272098428604</mass>
				<inertia>
					<ixx>1.5991623337794942</ixx>
					<ixy>-0.20662618938024316</ixy>
					<ixz>0.753684363768859</ixz>
					<iyy>1.1265213782471069</iyy>
					<iyz>0.2851505374909441</iyz>
					<izz>0.6296965516830374</izz>
				</inertia>
			</inertial>
			<collision name="lower_arm_right_collision">
				<geometry>
					<mesh>
						<uri>model://rikshaw/meshes/collisions/lower_arm_right.stl</uri>
						<scale>0.001 0.001 0.001</scale>
					</mesh>
				</geometry>
			</collision>
			<visual name="lower_arm_right_visual">
				<geometry>
					<mesh>
						<uri>model://rikshaw/meshes/visuals/lower_arm_right.stl</uri>
						<scale>0.001 0.001 0.001</scale>
					</mesh>
				</geometry>
			</visual>
		</link>
		<link name="right_shoulder_link1">
			<self_collide>false</self_collide>
			<pose frame="">-0.21899230781246104 -0.27775808395347434 1.1633276553145095 0.0 -0.0 0.0</pose>
			<inertial>
				<pose frame="">0.0 0.0 0.0 0 0 0</pose>
				<mass>0.04674901102976101</mass>
				<inertia>
					<ixx>0.06687953509128483</ixx>
					<ixy>-0.0028435966522462296</ixy>
					<ixz>0.015105711571040226</ixz>
					<iyy>0.06551484259180702</iyy>
					<iyz>0.011909769073168024</iyz>
					<izz>0.005854610150255846</izz>
				</inertia>
			</inertial>
			<collision name="right_shoulder_link1_collision">
				<geometry>
					<mesh>
						<uri>model://rikshaw/meshes/collisions/right_shoulder_link1.stl</uri>
						<scale>0.001 0.001 0.001</scale>
					</mesh>
				</geometry>
			</collision>
			<visual name="right_shoulder_link1_visual">
				<geometry>
					<mesh>
						<uri>model://rikshaw/meshes/visuals/right_shoulder_link1.stl</uri>
						<scale>0.001 0.001 0.001</scale>
					</mesh>
				</geometry>
			</visual>
		</link>
		<link name="right_shoulder_link2">
			<self_collide>false</self_collide>
			<pose frame="">-0.2189923241146676 -0.2777584163912652 1.1633276553163918 0.0 -0.0 0.0</pose>
			<inertial>
				<pose frame="">0.0 0.0 0.0 0 0 0</pose>
				<mass>0.03133729588511852</mass>
				<inertia>
					<ixx>0.04483010367618182</ixx>
					<ixy>-0.0019061524746546135</ixy>
					<ixz>0.010125833877362215</ixz>
					<iyy>0.04391530263166799</iyy>
					<iyz>0.007983484076604644</iyz>
					<izz>0.003923225072147937</izz>
				</inertia>
			</inertial>
			<collision name="right_shoulder_link2_collision">
				<geometry>
					<mesh>
						<uri>model://rikshaw/meshes/collisions/right_shoulder_link2.stl</uri>
						<scale>0.001 0.001 0.001</scale>
					</mesh>
				</geometry>
			</collision>
			<visual name="right_shoulder_link2_visual">
				<geometry>
					<mesh>
						<uri>model://rikshaw/meshes/visuals/right_shoulder_link2.stl</uri>
						<scale>0.001 0.001 0.001</scale>
					</mesh>
				</geometry>
			</visual>
		</link>
		<link name="zed_camera_left_lense">
			<self_collide>false</self_collide>
			<pose frame="">-0.09050894989898309 0.0744237259007461 1.5155224302330115 0.0 -0.0 0.0</pose>
			<inertial>
				<pose frame="">0.0 0.0 0.0 0 0 0</pose>
				<mass>0.005755421733357211</mass>
				<inertia>
					<ixx>0.013251176636323792</ixx>
					<ixy>3.876858906286288e-05</ixy>
					<ixz>-0.0006491587708028636</ixz>
					<iyy>0.013266636305534263</iyy>
					<iyz>0.0007894656332276956</iyz>
					<izz>7.942719232827483e-05</izz>
				</inertia>
			</inertial>
			<collision name="zed_camera_left_lense_collision">
				<geometry>
					<mesh>
						<uri>model://rikshaw/meshes/collisions/zed_camera_left_lense.stl</uri>
						<scale>0.001 0.001 0.001</scale>
					</mesh>
				</geometry>
			</collision>
			<visual name="zed_camera_left_lense_visual">
				<geometry>
					<mesh>
						<uri>model://rikshaw/meshes/visuals/zed_camera_left_lense.stl</uri>
						<scale>0.001 0.001 0.001</scale>
					</mesh>
				</geometry>
			</visual>
		</link>
		<link name="zed_camera_right_lense">
			<self_collide>false</self_collide>
			<pose frame="">-0.09050894989872259 -0.04557835229204655 1.5155224302743826 0.0 -0.0 0.0</pose>
			<inertial>
				<pose frame="">0.0 0.0 0.0 0 0 0</pose>
				<mass>0.005755421733357103</mass>
				<inertia>
					<ixx>0.01323125421744619</ixx>
					<ixy>-2.374254662672125e-05</ixy>
					<ixz>0.00039755584390753414</ixz>
					<iyy>0.01326663630625537</iyy>
					<iyz>0.0007894656332470204</iyz>
					<izz>5.9504772729015e-05</izz>
				</inertia>
			</inertial>
			<collision name="zed_camera_right_lense_collision">
				<geometry>
					<mesh>
						<uri>model://rikshaw/meshes/collisions/zed_camera_right_lense.stl</uri>
						<scale>0.001 0.001 0.001</scale>
					</mesh>
				</geometry>
			</collision>
			<visual name="zed_camera_right_lense_visual">
				<geometry>
					<mesh>
						<uri>model://rikshaw/meshes/visuals/zed_camera_right_lense.stl</uri>
						<scale>0.001 0.001 0.001</scale>
					</mesh>
				</geometry>
			</visual>
		</link>
		<link name="zed_camera">
			<self_collide>false</self_collide>
			<pose frame="">-0.10218003663925548 0.018479663903051526 1.5155933282605707 0.0 -0.0 0.0</pose>
			<inertial>
				<pose frame="">0.0 0.0 0.0 0 0 0</pose>
				<mass>0.009633908101969985</mass>
				<inertia>
					<ixx>0.02214757863539191</ixx>
					<ixy>1.807639468020231e-05</ixy>
					<ixz>-0.00026981613792170637</ixz>
					<iyy>0.02223019298553637</iyy>
					<iyz>0.0014919337341406241</iyz>
					<izz>0.0001186047881965815</izz>
				</inertia>
			</inertial>
			<collision name="zed_camera_collision">
				<geometry>
					<mesh>
						<uri>model://rikshaw/meshes/collisions/zed_camera.stl</uri>
						<scale>0.001 0.001 0.001</scale>
					</mesh>
				</geometry>
			</collision>
			<visual name="zed_camera_visual">
				<geometry>
					<mesh>
						<uri>model://rikshaw/meshes/visuals/zed_camera.stl</uri>
						<scale>0.001 0.001 0.001</scale>
					</mesh>
				</geometry>
			</visual>
		</link>
		<link name="sphere_head_link1">
			<self_collide>false</self_collide>
			<pose frame="">-0.20830602314000823 0.014422000441736565 1.31823153913462 0.0 -0.0 0.0</pose>
			<inertial>
				<pose frame="">0.0 0.0 0.0 0 0 0</pose>
				<mass>0.02393810080236979</mass>
				<inertia>
					<ixx>0.04160499755559101</ixx>
					<ixy>7.19145924626448e-05</ixy>
					<ixz>-0.00045510006133885777</ixz>
					<iyy>0.0426387262617714</iyy>
					<iyz>0.006573296422452212</iyz>
					<izz>0.0010456442314470164</izz>
				</inertia>
			</inertial>
			<collision name="sphere_head_link1_collision">
				<geometry>
					<mesh>
						<uri>model://rikshaw/meshes/collisions/sphere_head_link1.stl</uri>
						<scale>0.001 0.001 0.001</scale>
					</mesh>
				</geometry>
			</collision>
			<visual name="sphere_head_link1_visual">
				<geometry>
					<mesh>
						<uri>model://rikshaw/meshes/visuals/sphere_head_link1.stl</uri>
						<scale>0.001 0.001 0.001</scale>
					</mesh>
				</geometry>
			</visual>
		</link>
		<link name="sphere_head_link2">
			<self_collide>false</self_collide>
			<pose frame="">-0.2083060231400081 0.014422000441736575 1.318231539134621 0.0 -0.0 0.0</pose>
			<inertial>
				<pose frame="">0.0 0.0 0.0 0 0 0</pose>
				<mass>0.016046417516495715</mass>
				<inertia>
					<ixx>0.02788863341630688</ixx>
					<ixy>4.8206479942218094e-05</ixy>
					<ixz>-0.000305067041713818</ixz>
					<iyy>0.028581572365603776</iyy>
					<iyz>0.0044062751562945176</iyz>
					<izz>0.0007004983586646253</izz>
				</inertia>
			</inertial>
			<collision name="sphere_head_link2_collision">
				<geometry>
					<mesh>
						<uri>model://rikshaw/meshes/collisions/sphere_head_link2.stl</uri>
						<scale>0.001 0.001 0.001</scale>
					</mesh>
				</geometry>
			</collision>
			<visual name="sphere_head_link2_visual">
				<geometry>
					<mesh>
						<uri>model://rikshaw/meshes/visuals/sphere_head_link2.stl</uri>
						<scale>0.001 0.001 0.001</scale>
					</mesh>
				</geometry>
			</visual>
		</link>
		<link name="head">
			<self_collide>false</self_collide>
			<pose frame="">-0.21879121675166882 0.015071175760851966 1.4738508471242002 0.0 -0.0 0.0</pose>
			<inertial>
				<pose frame="">0.0 0.0 0.0 0 0 0</pose>
				<mass>2.0664370230195903</mass>
				<inertia>
					<ixx>4.516784822650517</ixx>
					<ixy>0.00682015432548133</ixy>
					<ixz>-0.04602734647260561</ixz>
					<iyy>4.620379896985018</iyy>
					<iyz>0.6688122473703546</iyz>
					<izz>0.12437460828210316</izz>
				</inertia>
			</inertial>
			<collision name="head_collision">
				<geometry>
					<mesh>
						<uri>model://rikshaw/meshes/collisions/head.stl</uri>
						<scale>0.001 0.001 0.001</scale>
					</mesh>
				</geometry>
			</collision>
			<visual name="head_visual">
				<geometry>
					<mesh>
						<uri>model://rikshaw/meshes/visuals/head.stl</uri>
						<scale>0.001 0.001 0.001</scale>
					</mesh>
				</geometry>
			</visual>
		</link>
		<joint name="joint_hip_left" type="revolute">
			<parent>bike</parent>
			<child>thigh_left</child>
			<pose frame="">0.004772342500965045 -0.010555805861684569 0.1111212772234638 0 0 0</pose>
			<axis>
				<xyz>-4.713373484460976e-12 0.9999999999999994 -4.747094644637576e-10</xyz>
				<limit>
					<lower>-3.141592653589793</lower>
					<upper>3.141592653589793</upper>
				</limit>
				<use_parent_model_frame>0</use_parent_model_frame>
			</axis>
		</joint>
		<joint name="joint_hip_right" type="revolute">
			<parent>bike</parent>
			<child>thigh_right</child>
			<pose frame="">0.00430138319573679 0.02190780224390359 0.11113082879981172 0 0 0</pose>
			<axis>
				<xyz>-4.713259055962439e-12 0.9999999999999997 -4.747100165437955e-10</xyz>
				<limit>
					<lower>-3.141592653589793</lower>
					<upper>3.141592653589793</upper>
				</limit>
				<use_parent_model_frame>0</use_parent_model_frame>
			</axis>
		</joint>
		<joint name="joint_knee_left" type="revolute">
			<parent>thigh_left</parent>
			<child>leg_left</child>
			<pose frame="">-0.008998885657996851 -0.03366940273164467 0.15020698063130739 0 0 0</pose>
			<axis>
				<xyz>6.509053341793854e-12 1.000000000000024 -2.72420312161297e-10</xyz>
				<limit>
					<lower>-3.141592653589793</lower>
					<upper>3.141592653589793</upper>
				</limit>
				<use_parent_model_frame>0</use_parent_model_frame>
			</axis>
		</joint>
		<joint name="joint_knee_right" type="revolute">
			<parent>thigh_right</parent>
			<child>leg_right</child>
			<pose frame="">-0.007630654968175854 0.013637515151702289 0.1503096618781518 0 0 0</pose>
			<axis>
				<xyz>5.578038031472943e-12 -1.0000000000000226 5.189987478333383e-10</xyz>
				<limit>
					<lower>-3.141592653589793</lower>
					<upper>3.141592653589793</upper>
				</limit>
				<use_parent_model_frame>0</use_parent_model_frame>
			</axis>
		</joint>
		<joint name="joint_foot_left" type="revolute">
			<parent>leg_left</parent>
			<child>foot_left</child>
			<pose frame="">-0.0620293110271249 -0.02399999998456089 0.037647902653943216 0 0 0</pose>
			<axis>
				<xyz>-9.646261322484993e-12 -0.999999999999999 1.1192843361396554e-10</xyz>
				<limit>
					<lower>-3.141592653589793</lower>
					<upper>3.141592653589793</upper>
				</limit>
				<use_parent_model_frame>0</use_parent_model_frame>
			</axis>
		</joint>
		<joint name="joint_foot_left_tip" type="fixed">
			<parent>foot_left</parent>
			<child>foot_left_tip</child>
			<pose frame="">-0.04103985138514272 0.0011674030872309516 0.005886567336367854 0 0 0</pose>
		</joint>
		<joint name="joint_foot_right" type="revolute">
			<parent>leg_right</parent>
			<child>foot_right</child>
			<pose frame="">-0.06298913863233675 -0.023499999970076253 0.03601900003503332 0 0 0</pose>
			<axis>
				<xyz>1.1247724973628692e-11 -0.9999999999999986 7.168120661733697e-10</xyz>
				<limit>
					<lower>-3.141592653589793</lower>
					<upper>3.141592653589793</upper>
				</limit>
				<use_parent_model_frame>0</use_parent_model_frame>
			</axis>
		</joint>
		<joint name="joint_foot_right_tip" type="fixed">
			<parent>foot_right</parent>
			<child>foot_right_tip</child>
			<pose frame="">-0.04109892725086624 -0.0011673776796484248 0.005458746616041097 0 0 0</pose>
		</joint>
		<joint name="joint_pedal_right" type="revolute">
			<parent>kurbel</parent>
			<child>pedal_right</child>
			<pose frame="">4.2209831345401125e-05 -0.042000000000000634 -6.592456775027956e-05 0 0 0</pose>
			<axis>
				<xyz>4.2643962886166735e-16 -1.0000000000000004 -1.5799660158833406e-15</xyz>
				<limit>
					<lower>-3.141592653589793</lower>
					<upper>3.141592653589793</upper>
				</limit>
				<use_parent_model_frame>0</use_parent_model_frame>
			</axis>
		</joint>
		<joint name="joint_pedal_left" type="revolute">
			<parent>kurbel</parent>
			<child>pedal_left</child>
			<pose frame="">5.3016250217616804e-05 0.041999999999999336 5.759336515414049e-05 0 0 0</pose>
			<axis>
				<xyz>-4.264396288616295e-16 0.9999999999999998 1.5799660158833545e-15</xyz>
				<limit>
					<lower>-3.141592653589793</lower>
					<upper>3.141592653589793</upper>
				</limit>
				<use_parent_model_frame>0</use_parent_model_frame>
			</axis>
		</joint>
		<joint name="elbow_right_rot1" type="revolute">
			<parent>elbow_right</parent>
			<child>lower_arm_right</child>
			<pose frame="">0.004565493587210305 0.09373552648455152 0.08064039788483157 0 0 0</pose>
			<axis>
				<xyz>0.036880022280742775 0.7578073504191255 0.6514352489751488</xyz>
				<limit>
					<lower>-1.5707963267948966</lower>
					<upper>1.5707963267948966</upper>
				</limit>
				<use_parent_model_frame>0</use_parent_model_frame>
			</axis>
		</joint>
		<joint name="left_shoulder_axis0" type="revolute">
			<parent>torso</parent>
			<child>left_shoulder_link1</child>
			<pose frame="">5.8246084471136326e-08 3.4487377575942446e-09 -9.64847828299753e-10 0 0 0</pose>
			<axis>
				<xyz>-0.05097567905860326 0.9986354432779869 -0.011345993720010035</xyz>
				<limit>
					<lower>-3.141592653589793</lower>
					<upper>3.141592653589793</upper>
				</limit>
				<use_parent_model_frame>0</use_parent_model_frame>
			</axis>
		</joint>
		<joint name="left_shoulder_axis1" type="revolute">
			<parent>left_shoulder_link1</parent>
			<child>left_shoulder_link2</child>
			<pose frame="">5.6511660062597005e-09 -1.1865031193991628e-06 -5.183125040275627e-12 0 0 0</pose>
			<axis>
				<xyz>-0.9986941911138322 -0.05101049432270813 -0.0028003757679576683</xyz>
				<limit>
					<lower>-3.141592653589793</lower>
					<upper>3.141592653589793</upper>
				</limit>
				<use_parent_model_frame>0</use_parent_model_frame>
			</axis>
		</joint>
		<joint name="left_shoulder_axis2" type="revolute">
			<parent>left_shoulder_link2</parent>
			<child>upper_arm_left</child>
			<pose frame="">0.0062735464982675996 -0.12298691864977655 0.08898382292815342 0 0 0</pose>
			<axis>
				<xyz>-0.03688002228788198 0.7578073498002895 -0.6514352496946403</xyz>
				<limit>
					<lower>-3.141592653589793</lower>
					<upper>3.141592653589793</upper>
				</limit>
				<use_parent_model_frame>0</use_parent_model_frame>
			</axis>
		</joint>
		<joint name="elbow_left_rot1" type="revolute">
			<parent>elbow_left</parent>
			<child>lower_arm_left</child>
			<pose frame="">0.004427718763257076 -0.09092040741737371 0.07847955111938205 0 0 0</pose>
			<axis>
				<xyz>-0.03688002228788115 0.7578073498002851 -0.6514352496946373</xyz>
				<limit>
					<lower>-1.5707963267948966</lower>
					<upper>1.5707963267948966</upper>
				</limit>
				<use_parent_model_frame>0</use_parent_model_frame>
			</axis>
		</joint>
		<joint name="elbow_left_rot0" type="revolute">
			<parent>upper_arm_left</parent>
			<child>elbow_left</child>
			<pose frame="">0.006143913370833012 -0.01903307709343487 0.03504187379271258 0 0 0</pose>
			<axis>
				<xyz>0.03535217944531835 -0.6504813218360856 -0.7586990663964501</xyz>
				<limit>
					<lower>0.0</lower>
					<upper>1.5707963267948966</upper>
				</limit>
				<use_parent_model_frame>0</use_parent_model_frame>
			</axis>
		</joint>
		<joint name="left_wrist_0" type="revolute">
			<parent>lower_arm_left</parent>
			<child>wrist_left_1</child>
			<pose frame="">0.0004155964834064818 -0.0055336094632906455 -0.008293621144653826 0 0 0</pose>
			<axis>
				<xyz>0.047216894784735314 -0.6683646979703974 -0.7423336145924063</xyz>
				<limit>
					<lower>-0.5235987755982988</lower>
					<upper>0.5235987755982988</upper>
				</limit>
				<use_parent_model_frame>0</use_parent_model_frame>
			</axis>
		</joint>
		<joint name="left_wrist_1" type="revolute">
			<parent>wrist_left_1</parent>
			<child>left_hand</child>
			<pose frame="">0.02378489150686079 -0.05570281027054207 0.05642767184566111 0 0 0</pose>
			<axis>
				<xyz>-0.9982455359929415 -0.05815370141400403 -0.011135388723325142</xyz>
				<limit>
					<lower>-0.5235987755982988</lower>
					<upper>0.5235987755982988</upper>
				</limit>
				<use_parent_model_frame>0</use_parent_model_frame>
			</axis>
		</joint>
		<joint name="elbow_right_rot0" type="revolute">
			<parent>upper_arm_right</parent>
			<child>elbow_right</child>
			<pose frame="">0.006179640697866802 0.020311938145424053 0.036558407615423935 0 0 0</pose>
			<axis>
				<xyz>-0.03535217943919214 -0.6504813211160859 0.7586990670140391</xyz>
				<limit>
					<lower>0.0</lower>
					<upper>1.5707963267948966</upper>
				</limit>
				<use_parent_model_frame>0</use_parent_model_frame>
			</axis>
		</joint>
		<joint name="right_wrist_0" type="revolute">
			<parent>lower_arm_right</parent>
			<child>wrist_right_1</child>
			<pose frame="">0.00020839823297386318 0.005920092789905454 -0.009526132469630539 0 0 0</pose>
			<axis>
				<xyz>0.02346171305541958 0.6321241248586624 -0.7745118713048712</xyz>
				<limit>
					<lower>-0.5235987755982988</lower>
					<upper>0.5235987755982988</upper>
				</limit>
				<use_parent_model_frame>0</use_parent_model_frame>
			</axis>
		</joint>
		<joint name="right_wrist_1" type="revolute">
			<parent>wrist_right_1</parent>
			<child>right_hand</child>
			<pose frame="">-0.012307749605959586 0.06191750084179191 0.05179170488733917 0 0 0</pose>
			<axis>
				<xyz>-0.999022304705215 0.04386113030445887 0.005534975148719516</xyz>
				<limit>
					<lower>-0.5235987755982988</lower>
					<upper>0.5235987755982988</upper>
				</limit>
				<use_parent_model_frame>0</use_parent_model_frame>
			</axis>
		</joint>
		<joint name="right_shoulder_axis0" type="revolute">
			<parent>torso</parent>
			<child>right_shoulder_link1</child>
			<pose frame="">-9.534940730304698e-09 -1.5142075481833218e-06 -1.6783019418653567e-13 0 0 0</pose>
			<axis>
				<xyz>-0.998694191114313 0.05101049431064217 -0.002800375816389378</xyz>
				<limit>
					<lower>-3.141592653589793</lower>
					<upper>3.141592653589793</upper>
				</limit>
				<use_parent_model_frame>0</use_parent_model_frame>
			</axis>
		</joint>
		<joint name="right_shoulder_axis2" type="revolute">
			<parent>right_shoulder_link2</parent>
			<child>upper_arm_right</child>
			<pose frame="">0.0038863000309653727 0.12260338877856182 0.08951505050373712 0 0 0</pose>
			<axis>
				<xyz>-0.03688002228074311 -0.7578073504191246 -0.6514352489751519</xyz>
				<limit>
					<lower>-3.141592653589793</lower>
					<upper>3.141592653589793</upper>
				</limit>
				<use_parent_model_frame>0</use_parent_model_frame>
			</axis>
		</joint>
		<joint name="right_shoulder_axis1" type="revolute">
			<parent>right_shoulder_link1</parent>
			<child>right_shoulder_link2</child>
			<pose frame="">6.767266427232244e-09 -1.1817697557958695e-06 -2.0477841644606087e-12 0 0 0</pose>
			<axis>
				<xyz>-0.03535217943919361 -0.6504813211160873 0.7586990670140364</xyz>
				<limit>
					<lower>-3.141592653589793</lower>
					<upper>3.141592653589793</upper>
				</limit>
				<use_parent_model_frame>0</use_parent_model_frame>
			</axis>
		</joint>
		<joint name="zed_camera_mount" type="fixed">
			<parent>head</parent>
			<child>zed_camera</child>
			<pose frame="">0.0005121610921336206 0.017441984839815707 0.008148669928157801 0 0 0</pose>
		</joint>
		<joint name="zed_camera_right" type="fixed">
			<parent>zed_camera</parent>
			<child>zed_camera_right_lense</child>
			<pose frame="">-0.01131521292843841 7.371603771844093e-11 0.00022109518862095 0 0 0</pose>
		</joint>
		<joint name="zed_camera_left" type="fixed">
			<parent>zed_camera</parent>
			<child>zed_camera_left_lense</child>
			<pose frame="">-0.011315212931356004 -1.988862324734164e-05 0.00022109503931460494 0 0 0</pose>
		</joint>
		<joint name="head_axis0" type="revolute">
			<parent>torso</parent>
			<child>sphere_head_link1</child>
			<pose frame="">-2.842170943040401e-16 8.881784197001253e-18 2.842170943040401e-15 0 0 0</pose>
			<axis>
				<xyz>0.999809155875435 -4.562156208365309e-12 -0.019535911231678183</xyz>
				<limit>
					<lower>-0.5235987755982988</lower>
					<upper>0.5235987755982988</upper>
				</limit>
				<use_parent_model_frame>0</use_parent_model_frame>
			</axis>
		</joint>
		<joint name="head_axis2" type="revolute">
			<parent>sphere_head_link2</parent>
			<child>head</child>
			<pose frame="">0.01048519361166008 -0.000649175319115396 -0.15561930798957888 0 0 0</pose>
			<axis>
				<xyz>0.019535911231678155 4.747127404711171e-10 0.9998091558754341</xyz>
				<limit>
					<lower>-0.5235987755982988</lower>
					<upper>0.5235987755982988</upper>
				</limit>
				<use_parent_model_frame>0</use_parent_model_frame>
			</axis>
		</joint>
		<joint name="head_axis1" type="revolute">
			<parent>sphere_head_link1</parent>
			<child>sphere_head_link2</child>
			<pose frame="">-4.973799150320702e-16 -1.1102230246251566e-17 -2.842170943040401e-16 0 0 0</pose>
			<axis>
				<xyz>4.7126746949288645e-12 -1.0000000000000007 4.747112713885635e-10</xyz>
				<limit>
					<lower>-0.5235987755982988</lower>
					<upper>0.5235987755982988</upper>
				</limit>
				<use_parent_model_frame>0</use_parent_model_frame>
			</axis>
		</joint>
		<joint name="joint_wheel_right" type="revolute">
			<parent>front_part</parent>
			<child>right_wheel</child>
			<pose frame="">-1.8474111129762605e-15 0.003999653375196743 7.167599846980011e-15 0 0 0</pose>
			<axis>
				<xyz>-1.942890293094024e-16 -0.9999999999999996 4.3170595303689904e-14</xyz>
				<limit>
					<lower>-3.141592653589793</lower>
					<upper>3.141592653589793</upper>
				</limit>
				<use_parent_model_frame>0</use_parent_model_frame>
			</axis>
		</joint>
		<joint name="joint_wheel_back" type="revolute">
			<parent>bike</parent>
			<child>wheel_back</child>
			<pose frame="">-2.1316282072803005e-16 0.06899965337519753 8.881784197001253e-17 0 0 0</pose>
			<axis>
				<xyz>1.3877787807814457e-16 0.9999999999999998 1.2767564783189294e-15</xyz>
				<limit>
					<lower>-3.141592653589793</lower>
					<upper>3.141592653589793</upper>
				</limit>
				<use_parent_model_frame>0</use_parent_model_frame>
			</axis>
		</joint>
		<joint name="joint_pedal" type="revolute">
			<parent>bike</parent>
			<child>kurbel</child>
			<pose frame="">-0.0002782913867367753 0.03513164955581838 -0.0010093313481013915 0 0 0</pose>
			<axis>
				<xyz>-1.3877787807814457e-16 -0.9999999999999998 -1.2767564783189294e-15</xyz>
				<limit>
					<lower>-3.141592653589793</lower>
					<upper>3.141592653589793</upper>
				</limit>
				<use_parent_model_frame>0</use_parent_model_frame>
			</axis>
		</joint>
		<joint name="spine_joint" type="revolute">
			<parent>bike</parent>
			<child>torso</child>
			<pose frame="">-0.22048396235129444 0.014422000145820898 0.6949887848680888 0 0 0</pose>
			<axis>
				<xyz>-0.019535911231678107 -4.747112459513404e-10 -0.9998091558754337</xyz>
				<limit>
					<lower>-0.5235987755982988</lower>
					<upper>0.5235987755982988</upper>
				</limit>
				<use_parent_model_frame>0</use_parent_model_frame>
			</axis>
		</joint>
		<joint name="joint_wheel_left" type="revolute">
			<parent>front_part</parent>
			<child>left_wheel</child>
			<pose frame="">-2.2737367544323206e-15 -0.04600034662480333 9.459100169806334e-15 0 0 0</pose>
			<axis>
				<xyz>1.942890293094024e-16 0.9999999999999996 -4.3170595303689904e-14</xyz>
				<limit>
					<lower>-3.141592653589793</lower>
					<upper>3.141592653589793</upper>
				</limit>
				<use_parent_model_frame>0</use_parent_model_frame>
			</axis>
		</joint>
		<joint name="joint_front" type="revolute">
			<parent>bike</parent>
			<child>front_part</child>
			<pose frame="">0.23003546879794612 0.010388308199859624 -0.20527069599791542 0 0 0</pose>
			<axis>
				<xyz>-5.34564260914393e-16 4.0843979107500514e-14 1.0</xyz>
				<limit>
					<lower>-0.5235987755982988</lower>
					<upper>0.5235987755982988</upper>
				</limit>
				<use_parent_model_frame>0</use_parent_model_frame>
			</axis>
		</joint>
		<plugin filename="libcardsflow_gazebo_plugin.so" name="cardsflow_gazebo_plugin" />
	</model>
</sdf>
