<?xml version="1.0" ?>
<sdf version="1.6">
	<model name="rikshaw">
		<link name="bike">
			<self_collide>false</self_collide>
			<pose frame="">0.11407161388991904 0.03170624505765542 0.5831929199333695 0.0 -0.0 0.0</pose>
			<inertial>
				<pose frame="">0.0 0.0 0.0 0 0 0</pose>
				<mass>21.81331498933295</mass>
				<inertia>
					<ixx>10.083898654031916</ixx>
					<ixy>-0.06607369188353159</ixy>
					<ixz>-0.3883753822995066</ixz>
					<iyy>13.522231324250988</iyy>
					<iyz>-3.5907666395614837</iyz>
					<izz>4.078177458509554</izz>
				</inertia>
			</inertial>
			<collision name="bike_collision">
				<geometry>
					<mesh>
						<uri>model://rikshaw/meshes/CAD/bike.stl</uri>
						<scale>0.001 0.001 0.001</scale>
					</mesh>
				</geometry>
			</collision>
			<visual name="bike_visual">
				<geometry>
					<mesh>
						<uri>model://rikshaw/meshes/CAD/bike.stl</uri>
						<scale>0.001 0.001 0.001</scale>
					</mesh>
				</geometry>
			</visual>
		</link>
		<link name="foot_left">
			<self_collide>false</self_collide>
			<pose frame="">0.32953037112482525 -0.14122043737664075 0.0016945492770594505 0.0 -0.0 0.0</pose>
			<inertial>
				<pose frame="">0.0 0.0 0.0 0 0 0</pose>
				<mass>1.0073570813716561</mass>
				<inertia>
					<ixx>0.020750513605191527</ixx>
					<ixy>0.04690908383866695</ixy>
					<ixz>0.00024345371490371603</ixz>
					<iyy>0.11228597885468367</iyy>
					<iyz>-0.0009047423260076533</iyz>
					<izz>0.13240932064928215</izz>
				</inertia>
			</inertial>
			<collision name="foot_left_collision">
				<geometry>
					<mesh>
						<uri>model://rikshaw/meshes/CAD/foot_left.stl</uri>
						<scale>0.001 0.001 0.001</scale>
					</mesh>
				</geometry>
			</collision>
			<visual name="foot_left_visual">
				<geometry>
					<mesh>
						<uri>model://rikshaw/meshes/CAD/foot_left.stl</uri>
						<scale>0.001 0.001 0.001</scale>
					</mesh>
				</geometry>
			</visual>
		</link>
		<link name="foot_right">
			<self_collide>false</self_collide>
			<pose frame="">0.2695456664829376 0.20617071215293895 0.355200304611504 0.0 -0.0 0.0</pose>
			<inertial>
				<pose frame="">0.0 0.0 0.0 0 0 0</pose>
				<mass>1.0073526294372792</mass>
				<inertia>
					<ixx>0.1710169135614256</ixx>
					<ixy>-0.056008864515654636</ixy>
					<ixz>-0.07378206564558545</ixz>
					<iyy>0.20317739089550094</iyy>
					<iyz>-0.09741171616210452</iyz>
					<izz>0.11849200847169264</izz>
				</inertia>
			</inertial>
			<collision name="foot_right_collision">
				<geometry>
					<mesh>
						<uri>model://rikshaw/meshes/CAD/foot_right.stl</uri>
						<scale>0.001 0.001 0.001</scale>
					</mesh>
				</geometry>
			</collision>
			<visual name="foot_right_visual">
				<geometry>
					<mesh>
						<uri>model://rikshaw/meshes/CAD/foot_right.stl</uri>
						<scale>0.001 0.001 0.001</scale>
					</mesh>
				</geometry>
			</visual>
		</link>
		<link name="thigh_right">
			<self_collide>false</self_collide>
			<pose frame="">0.21306762202729806 0.2307580496191449 0.6636155811866741 0.0 -0.0 0.0</pose>
			<inertial>
				<pose frame="">0.0 0.0 0.0 0 0 0</pose>
				<mass>5.563551531361356</mass>
				<inertia>
					<ixx>2.758710314139378</ixx>
					<ixy>-0.27653691454319923</ixy>
					<ixz>-0.8525725925194048</ixz>
					<iyy>2.733830421530841</iyy>
					<iyz>-0.7886856442807304</iyz>
					<izz>0.5768546331244858</izz>
				</inertia>
			</inertial>
			<collision name="thigh_right_collision">
				<geometry>
					<mesh>
						<uri>model://rikshaw/meshes/CAD/thigh_right.stl</uri>
						<scale>0.001 0.001 0.001</scale>
					</mesh>
				</geometry>
			</collision>
			<visual name="thigh_right_visual">
				<geometry>
					<mesh>
						<uri>model://rikshaw/meshes/CAD/thigh_right.stl</uri>
						<scale>0.001 0.001 0.001</scale>
					</mesh>
				</geometry>
			</visual>
		</link>
		<link name="thigh_left">
			<self_collide>false</self_collide>
			<pose frame="">0.33596172751211173 -0.16570568512112502 0.5768343943578618 0.0 -0.0 0.0</pose>
			<inertial>
				<pose frame="">0.0 0.0 0.0 0 0 0</pose>
				<mass>5.56358655048423</mass>
				<inertia>
					<ixx>2.032298455269805</ixx>
					<ixy>0.30885145604075287</ixy>
					<ixz>0.5347695724937122</ixz>
					<iyy>2.5103291140248367</iyy>
					<iyz>-1.0778482754769985</iyz>
					<izz>0.7927908850236616</izz>
				</inertia>
			</inertial>
			<collision name="thigh_left_collision">
				<geometry>
					<mesh>
						<uri>model://rikshaw/meshes/CAD/thigh_left.stl</uri>
						<scale>0.001 0.001 0.001</scale>
					</mesh>
				</geometry>
			</collision>
			<visual name="thigh_left_visual">
				<geometry>
					<mesh>
						<uri>model://rikshaw/meshes/CAD/thigh_left.stl</uri>
						<scale>0.001 0.001 0.001</scale>
					</mesh>
				</geometry>
			</visual>
		</link>
		<link name="leg_left">
			<self_collide>false</self_collide>
			<pose frame="">0.35424937385620825 -0.16607206397334248 0.23807825743848945 0.0 -0.0 0.0</pose>
			<inertial>
				<pose frame="">0.0 0.0 0.0 0 0 0</pose>
				<mass>5.524287867603195</mass>
				<inertia>
					<ixx>0.4973493200849545</ixx>
					<ixy>0.3249892870144498</ixy>
					<ixz>0.22046728182220332</ixz>
					<iyy>1.0413469586966366</iyy>
					<iyz>-0.4644797348689091</iyz>
					<izz>0.8576839534608591</izz>
				</inertia>
			</inertial>
			<collision name="leg_left_collision">
				<geometry>
					<mesh>
						<uri>model://rikshaw/meshes/CAD/leg_left.stl</uri>
						<scale>0.001 0.001 0.001</scale>
					</mesh>
				</geometry>
			</collision>
			<visual name="leg_left_visual">
				<geometry>
					<mesh>
						<uri>model://rikshaw/meshes/CAD/leg_left.stl</uri>
						<scale>0.001 0.001 0.001</scale>
					</mesh>
				</geometry>
			</visual>
		</link>
		<link name="leg_right">
			<self_collide>false</self_collide>
			<pose frame="">0.12562784413945566 0.233693069857624 0.5187514348723183 0.0 -0.0 0.0</pose>
			<inertial>
				<pose frame="">0.0 0.0 0.0 0 0 0</pose>
				<mass>5.07490752025796</mass>
				<inertia>
					<ixx>1.6604884872903782</ixx>
					<ixy>-0.147654085828189</ixy>
					<ixz>-0.6170549679009609</ixz>
					<iyy>1.4802781244120977</iyy>
					<iyz>-0.3212866014165562</iyz>
					<izz>0.3823636748069988</izz>
				</inertia>
			</inertial>
			<collision name="leg_right_collision">
				<geometry>
					<mesh>
						<uri>model://rikshaw/meshes/CAD/leg_right.stl</uri>
						<scale>0.001 0.001 0.001</scale>
					</mesh>
				</geometry>
			</collision>
			<visual name="leg_right_visual">
				<geometry>
					<mesh>
						<uri>model://rikshaw/meshes/CAD/leg_right.stl</uri>
						<scale>0.001 0.001 0.001</scale>
					</mesh>
				</geometry>
			</visual>
		</link>
		<link name="back_wheel">
			<self_collide>false</self_collide>
			<pose frame="">0.6486084286036901 0.03492264887089664 0.25624887024902543 0.0 -0.0 0.0</pose>
			<inertial>
				<pose frame="">0.0 0.0 0.0 0 0 0</pose>
				<mass>13.340163929098477</mass>
				<inertia>
					<ixx>1.4014062390517636</ixx>
					<ixy>-0.3021697127655251</ixy>
					<ixz>-0.11937965050242952</ixz>
					<iyy>7.504381180421915</iyy>
					<iyz>-2.2172043078944803</iyz>
					<izz>6.137556770128537</izz>
				</inertia>
			</inertial>
			<collision name="back_wheel_collision">
				<geometry>
					<mesh>
						<uri>model://rikshaw/meshes/CAD/back_wheel.stl</uri>
						<scale>0.001 0.001 0.001</scale>
					</mesh>
				</geometry>
			</collision>
			<visual name="back_wheel_visual">
				<geometry>
					<mesh>
						<uri>model://rikshaw/meshes/CAD/back_wheel.stl</uri>
						<scale>0.001 0.001 0.001</scale>
					</mesh>
				</geometry>
			</visual>
		</link>
		<link name="front_part">
			<self_collide>false</self_collide>
			<pose frame="">-0.6046185937738633 0.04475872331475461 0.4232366755238699 0.0 -0.0 0.0</pose>
			<inertial>
				<pose frame="">0.0 0.0 0.0 0 0 0</pose>
				<mass>16.813631847058485</mass>
				<inertia>
					<ixx>5.46577888962775</ixx>
					<ixy>0.511047160266088</ixy>
					<ixz>-0.28744018766830076</ixz>
					<iyy>14.406698608958099</iyy>
					<iyz>2.9381621443324253</iyz>
					<izz>11.46435998130477</izz>
				</inertia>
			</inertial>
			<collision name="front_part_collision">
				<geometry>
					<mesh>
						<uri>model://rikshaw/meshes/CAD/front_part.stl</uri>
						<scale>0.001 0.001 0.001</scale>
					</mesh>
				</geometry>
			</collision>
			<visual name="front_part_visual">
				<geometry>
					<mesh>
						<uri>model://rikshaw/meshes/CAD/front_part.stl</uri>
						<scale>0.001 0.001 0.001</scale>
					</mesh>
				</geometry>
			</visual>
		</link>
		<link name="left_wheel">
			<self_collide>false</self_collide>
			<pose frame="">-0.8867148521253287 -0.3156284088111488 0.25250000000001 0.0 -0.0 0.0</pose>
			<inertial>
				<pose frame="">0.0 0.0 0.0 0 0 0</pose>
				<mass>13.340163929097853</mass>
				<inertia>
					<ixx>2.6886582542943342</ixx>
					<ixy>-3.73354366648907</ixy>
					<ixz>1.0631600153408742</ixz>
					<iyy>12.355706573664577</iyy>
					<iyz>2.986802675143824</iyz>
					<izz>12.327019793799982</izz>
				</inertia>
			</inertial>
			<collision name="left_wheel_collision">
				<geometry>
					<mesh>
						<uri>model://rikshaw/meshes/CAD/left_wheel.stl</uri>
						<scale>0.001 0.001 0.001</scale>
					</mesh>
				</geometry>
			</collision>
			<visual name="left_wheel_visual">
				<geometry>
					<mesh>
						<uri>model://rikshaw/meshes/CAD/left_wheel.stl</uri>
						<scale>0.001 0.001 0.001</scale>
					</mesh>
				</geometry>
			</visual>
		</link>
		<link name="right_wheel">
			<self_collide>false</self_collide>
			<pose frame="">-0.8867148521253283 0.37637226941711827 0.25250000000004 0.0 -0.0 0.0</pose>
			<inertial>
				<pose frame="">0.0 0.0 0.0 0 0 0</pose>
				<mass>13.340163929097853</mass>
				<inertia>
					<ixx>3.24940928013889</ixx>
					<ixy>4.452078024336449</ixy>
					<ixz>-1.2677691125288901</ixz>
					<iyy>12.35570657366474</iyy>
					<iyz>2.98680267514417</iyz>
					<izz>12.8877708196443</izz>
				</inertia>
			</inertial>
			<collision name="right_wheel_collision">
				<geometry>
					<mesh>
						<uri>model://rikshaw/meshes/CAD/right_wheel.stl</uri>
						<scale>0.001 0.001 0.001</scale>
					</mesh>
				</geometry>
			</collision>
			<visual name="right_wheel_visual">
				<geometry>
					<mesh>
						<uri>model://rikshaw/meshes/CAD/right_wheel.stl</uri>
						<scale>0.001 0.001 0.001</scale>
					</mesh>
				</geometry>
			</visual>
		</link>
		<link name="pedal_right">
			<self_collide>false</self_collide>
			<pose frame="">0.37345950464140776 0.18236129042854465 0.20999067049847114 0.0 -0.0 0.0</pose>
			<inertial>
				<pose frame="">0.0 0.0 0.0 0 0 0</pose>
				<mass>0.9460025886020094</mass>
				<inertia>
					<ixx>0.07377911577090149</ixx>
					<ixy>-0.06442708739658828</ixy>
					<ixz>-0.03622638361731796</ixz>
					<iyy>0.1740707923266257</iyy>
					<iyz>-0.07418824195613966</iyz>
					<izz>0.16432401911803204</izz>
				</inertia>
			</inertial>
			<collision name="pedal_right_collision">
				<geometry>
					<mesh>
						<uri>model://rikshaw/meshes/CAD/pedal_right.stl</uri>
						<scale>0.001 0.001 0.001</scale>
					</mesh>
				</geometry>
			</collision>
			<visual name="pedal_right_visual">
				<geometry>
					<mesh>
						<uri>model://rikshaw/meshes/CAD/pedal_right.stl</uri>
						<scale>0.001 0.001 0.001</scale>
					</mesh>
				</geometry>
			</visual>
		</link>
		<link name="kurbel">
			<self_collide>false</self_collide>
			<pose frame="">0.20524776280826626 0.034503718012087355 0.21029021552905797 0.0 -0.0 0.0</pose>
			<inertial>
				<pose frame="">0.0 0.0 0.0 0 0 0</pose>
				<mass>2.7832708381107576</mass>
				<inertia>
					<ixx>0.1423383234578622</ixx>
					<ixy>-0.032689001789628226</ixy>
					<ixz>-0.02011903160634835</ixz>
					<iyy>0.25819266867802115</iyy>
					<iyz>-0.12002315705190886</iyz>
					<izz>0.15384069763517777</izz>
				</inertia>
			</inertial>
			<collision name="kurbel_collision">
				<geometry>
					<mesh>
						<uri>model://rikshaw/meshes/CAD/kurbel.stl</uri>
						<scale>0.001 0.001 0.001</scale>
					</mesh>
				</geometry>
			</collision>
			<visual name="kurbel_visual">
				<geometry>
					<mesh>
						<uri>model://rikshaw/meshes/CAD/kurbel.stl</uri>
						<scale>0.001 0.001 0.001</scale>
					</mesh>
				</geometry>
			</visual>
		</link>
		<link name="pedal_left">
			<self_collide>false</self_collide>
			<pose frame="">0.03491749565445945 -0.11487270957145626 0.20998199734654882 0.0 -0.0 0.0</pose>
			<inertial>
				<pose frame="">0.0 0.0 0.0 0 0 0</pose>
				<mass>0.9460025886020111</mass>
				<inertia>
					<ixx>0.054798951844923956</ixx>
					<ixy>0.0037944800841213187</ixy>
					<ixz>0.022818718582806888</ixz>
					<iyy>0.04327986812473328</iyy>
					<iyz>-0.006936264200881655</iyz>
					<izz>0.01455982259395355</izz>
				</inertia>
			</inertial>
			<collision name="pedal_left_collision">
				<geometry>
					<mesh>
						<uri>model://rikshaw/meshes/CAD/pedal_left.stl</uri>
						<scale>0.001 0.001 0.001</scale>
					</mesh>
				</geometry>
			</collision>
			<visual name="pedal_left_visual">
				<geometry>
					<mesh>
						<uri>model://rikshaw/meshes/CAD/pedal_left.stl</uri>
						<scale>0.001 0.001 0.001</scale>
					</mesh>
				</geometry>
			</visual>
		</link>
		<joint name="joint_pedal_right" type="revolute">
			<parent>kurbel</parent>
			<child>pedal_right</child>
			<pose frame="">-6.199487566426853e-05 0.041999999999999885 4.779491486118559e-05 0 0 0</pose>
			<axis>
				<xyz>-2.5713482822523515e-16 1.0000000000000007 4.56357540647104e-17</xyz>
				<limit>
					<lower>-3.141592653589793</lower>
					<upper>3.141592653589793</upper>
				</limit>
				<use_parent_model_frame>0</use_parent_model_frame>
			</axis>
		</joint>
		<joint name="joint_pedal_left" type="revolute">
			<parent>kurbel</parent>
			<child>pedal_left</child>
			<pose frame="">6.199487566573846e-05 -0.04199999999999953 4.779491486139875e-05 0 0 0</pose>
			<axis>
				<xyz>2.5713482822524407e-16 -1.0 -4.563575406471198e-17</xyz>
				<limit>
					<lower>-3.141592653589793</lower>
					<upper>3.141592653589793</upper>
				</limit>
				<use_parent_model_frame>0</use_parent_model_frame>
			</axis>
		</joint>
		<joint name="joint_wheel_left" type="revolute">
			<parent>front_part</parent>
			<child>left_wheel</child>
			<pose frame="">1.4210854715202005e-15 0.04600034662480176 7.283063041541026e-15 0 0 0</pose>
			<axis>
				<xyz>3.1662288285729275e-30 -0.9999999999999998 -4.317059530368993e-14</xyz>
				<limit>
					<lower>-3.141592653589793</lower>
					<upper>3.141592653589793</upper>
				</limit>
				<use_parent_model_frame>0</use_parent_model_frame>
			</axis>
		</joint>
		<joint name="joint_wheel_right" type="revolute">
			<parent>front_part</parent>
			<child>right_wheel</child>
			<pose frame="">9.947598300641404e-16 -0.003999653375198448 5.4711790653527716e-15 0 0 0</pose>
			<axis>
				<xyz>-3.1662288285729275e-30 0.9999999999999998 4.317059530368993e-14</xyz>
				<limit>
					<lower>-3.141592653589793</lower>
					<upper>3.141592653589793</upper>
				</limit>
				<use_parent_model_frame>0</use_parent_model_frame>
			</axis>
		</joint>
		<joint name="joint_front" type="revolute">
			<parent>bike</parent>
			<child>front_part</child>
			<pose frame="">-0.23009613508125626 -0.01038647904833784 -0.20523667730717202 0 0 0</pose>
			<axis>
				<xyz>6.603440870084913e-16 -4.31170590847569e-14 1.0</xyz>
				<limit>
					<lower>-0.3490658503988659</lower>
					<upper>0.3490658503988659</upper>
				</limit>
				<use_parent_model_frame>0</use_parent_model_frame>
			</axis>
		</joint>
		<joint name="joint_pedal" type="revolute">
			<parent>bike</parent>
			<child>kurbel</child>
			<pose frame="">-0.0010297452301407971 -0.03513164955581818 -0.00018926338061788783 0 0 0</pose>
			<axis>
				<xyz>0.0 1.0 -5.551115123125783e-16</xyz>
				<limit>
					<lower>-3.141592653589793</lower>
					<upper>3.141592653589793</upper>
				</limit>
				<use_parent_model_frame>0</use_parent_model_frame>
			</axis>
		</joint>
		<joint name="joint_knee_right" type="revolute">
			<parent>thigh_right</parent>
			<child>leg_right</child>
			<pose frame="">-0.10513524361131438 -0.017143095728728783 0.09899185325934845 0 0 0</pose>
			<axis>
				<xyz>3.8751886398178056e-11 1.000000000000023 4.832504674201488e-10</xyz>
				<limit>
					<lower>-3.141592653589793</lower>
					<upper>3.141592653589793</upper>
				</limit>
				<use_parent_model_frame>0</use_parent_model_frame>
			</axis>
		</joint>
		<joint name="joint_foot_right" type="revolute">
			<parent>leg_right</parent>
			<child>foot_right</child>
			<pose frame="">0.01840811193950934 0.015879262131266964 0.03812034990914178 0 0 0</pose>
			<axis>
				<xyz>-8.733427660066444e-11 -1.0000000000000018 -6.907090334408558e-10</xyz>
				<limit>
					<lower>-3.141592653589793</lower>
					<upper>3.141592653589793</upper>
				</limit>
				<use_parent_model_frame>0</use_parent_model_frame>
			</axis>
		</joint>
		<joint name="joint_hip_right" type="revolute">
			<parent>bike</parent>
			<child>thigh_right</child>
			<pose frame="">0.10869571349630164 -0.021908075528913856 0.023531915258737542 0 0 0</pose>
			<axis>
				<xyz>4.714117194135765e-12 -0.9999999999999999 -4.747078088732916e-10</xyz>
				<limit>
					<lower>-3.141592653589793</lower>
					<upper>3.141592653589793</upper>
				</limit>
				<use_parent_model_frame>0</use_parent_model_frame>
			</axis>
		</joint>
		<joint name="joint_knee_left" type="revolute">
			<parent>thigh_left</parent>
			<child>leg_left</child>
			<pose frame="">0.010225939190527457 0.03497203821440964 0.1428553642782785 0 0 0</pose>
			<axis>
				<xyz>-2.3658644533201752e-11 -1.0000000000000242 -2.741036256664899e-10</xyz>
				<limit>
					<lower>-3.141592653589793</lower>
					<upper>3.141592653589793</upper>
				</limit>
				<use_parent_model_frame>0</use_parent_model_frame>
			</axis>
		</joint>
		<joint name="joint_hip_left" type="revolute">
			<parent>bike</parent>
			<child>thigh_left</child>
			<pose frame="">-0.014198391986819133 0.01055565922183515 0.11031310191475577 0 0 0</pose>
			<axis>
				<xyz>4.714220161252588e-12 -0.9999999999999999 -4.747072576310608e-10</xyz>
				<limit>
					<lower>-3.141592653589793</lower>
					<upper>3.141592653589793</upper>
				</limit>
				<use_parent_model_frame>0</use_parent_model_frame>
			</axis>
		</joint>
		<joint name="back_wheel" type="revolute">
			<parent>bike</parent>
			<child>back_wheel</child>
			<pose frame="">1.4210854715202004e-16 -0.06600034662480248 -1.0658141036401502e-16 0 0 0</pose>
			<axis>
				<xyz>0.0 -1.0 5.551115123125783e-16</xyz>
				<limit>
					<lower>-3.141592653589793</lower>
					<upper>3.141592653589793</upper>
				</limit>
				<use_parent_model_frame>0</use_parent_model_frame>
			</axis>
		</joint>
		<plugin filename="libmusc_plugin.so" name="musc_plugin">
			<myoMuscle name="motor0">
				<link name="bike">
					<viaPoint type="FIXPOINT">0.16124863756624933 -0.17135627098845546 0.1660591206662997</viaPoint>
				</link>
				<link name="thigh_left">
					<viaPoint type="FIXPOINT">-0.03476482623118624 0.024405659262930878 0.02369167395760371</viaPoint>
				</link>
			</myoMuscle>
			<myoMuscle name="motor1">
				<link name="bike">
					<viaPoint type="FIXPOINT">0.2503752159599816 -0.17183479404110635 0.16781063760549145</viaPoint>
				</link>
				<link name="thigh_left">
					<viaPoint type="FIXPOINT">0.06115303680091181 0.027405659213073114 0.12721572664247255</viaPoint>
					<viaPoint type="FIXPOINT">0.024907097509502235 0.02440565925980126 0.029957575096739363</viaPoint>
				</link>
			</myoMuscle>
			<myoMuscle name="motor2">
				<link name="thigh_left">
					<viaPoint type="FIXPOINT">-0.030354214925165126 0.025990069111764776 -0.07370533423730947</viaPoint>
				</link>
				<link name="leg_left">
					<viaPoint type="FIXPOINT">-0.08186955922180268 0.0279720381225877 0.14388297922042526</viaPoint>
					<viaPoint type="FIXPOINT">-0.02812436798002139 0.024972038189440653 0.022318009288644233</viaPoint>
				</link>
			</myoMuscle>
			<myoMuscle name="motor3">
				<link name="thigh_left">
					<viaPoint type="FIXPOINT">0.041160911222953164 0.02290301768345598 -0.069438502059595</viaPoint>
				</link>
				<link name="leg_left">
					<viaPoint type="FIXPOINT">0.03186998782611077 0.02497203819357818 0.02314097429836675</viaPoint>
				</link>
			</myoMuscle>
			<myoMuscle name="motor4">
				<link name="leg_left">
					<viaPoint type="FIXPOINT">-0.03257374460532624 0.026556448043235117 -0.07507723569182495</viaPoint>
				</link>
				<link name="foot_left">
					<viaPoint type="FIXPOINT">-0.04773733783515251 -0.0003795882655907157 0.0035381557253801265</viaPoint>
				</link>
			</myoMuscle>
			<myoMuscle name="motor5">
				<link name="leg_left">
					<viaPoint type="FIXPOINT">0.037697920555514346 0.02618728300230771 -0.07460284636626295</viaPoint>
				</link>
				<link name="foot_left">
					<viaPoint type="FIXPOINT">0.07944124446674793 -0.0003795882865726874 -0.0038515806487142115</viaPoint>
				</link>
			</myoMuscle>
			<myoMuscle name="motor6">
				<link name="bike">
					<viaPoint type="FIXPOINT">0.1612035153205899 0.17606151015139543 0.16605823915880621</viaPoint>
				</link>
				<link name="thigh_left">
					<viaPoint type="FIXPOINT">-0.10240712057358288 0.3720556592046569 0.12355017352290666</viaPoint>
				</link>
			</myoMuscle>
			<myoMuscle name="motor7">
				<link name="bike">
					<viaPoint type="FIXPOINT">0.25049327088358964 0.17302594786442807 0.16780292885972103</viaPoint>
				</link>
				<link name="thigh_left">
					<viaPoint type="FIXPOINT">0.009271256113598057 0.3750556592461445 0.03726340679182563</viaPoint>
				</link>
				<link name="leg_left">
					<viaPoint type="FIXPOINT">-0.10912351768733018 0.3724220380848767 0.4034326644599796</viaPoint>
				</link>
			</myoMuscle>
			<myoMuscle name="motor9">
				<link name="thigh_left">
					<viaPoint type="FIXPOINT">-0.18175060293719228 0.3699180131335132 0.02695236672700169</viaPoint>
				</link>
				<link name="leg_left">
					<viaPoint type="FIXPOINT">-0.22724772896922193 0.3726220381265188 0.3208787783120888</viaPoint>
				</link>
			</myoMuscle>
			<myoMuscle name="motor8">
				<link name="thigh_left">
					<viaPoint type="FIXPOINT">-0.19925223182579616 0.3708468529946282 0.10908013286330423</viaPoint>
				</link>
				<link name="leg_left">
					<viaPoint type="FIXPOINT">-0.39269119509478567 0.3696220381387239 0.30888812231377566</viaPoint>
					<viaPoint type="FIXPOINT">-0.26448231479455575 0.37262203815069794 0.27383002042821014</viaPoint>
				</link>
			</myoMuscle>
			<myoMuscle name="motor10">
				<link name="leg_left">
					<viaPoint type="FIXPOINT">-0.19029753724969417 0.373758654398553 0.20774262587939318</viaPoint>
				</link>
				<link name="foot_left">
					<viaPoint type="FIXPOINT">-0.10630697885596291 0.34777041168919165 0.3414366929209973</viaPoint>
				</link>
			</myoMuscle>
			<myoMuscle name="motor11">
				<link name="leg_left">
					<viaPoint type="FIXPOINT">-0.14734074484823395 0.371037628346569 0.26501730154961306</viaPoint>
				</link>
				<link name="foot_left">
					<viaPoint type="FIXPOINT">0.016443913141224797 0.3477704116799007 0.37551334935755093</viaPoint>
				</link>
			</myoMuscle>
		</plugin>
	</model>
</sdf>
