<?xml version="1.0" ?>
<sdf version="1.6">
	<model name="biking_legs4">
		<link name="shin_right">
			<self_collide>false</self_collide>
			<pose frame="">0.013239504119270827 0.18783982741459382 0.559810014386865 0.0 -0.0 0.0</pose>
			<inertial>
				<pose frame="">0.0 0.0 0.0 0 0 0</pose>
				<mass>5.431396911763333</mass>
				<inertia>
					<ixx>1.919255861324501</ixx>
					<ixy>-0.013353600475323444</ixy>
					<ixz>-0.035611323004641426</ixz>
					<iyy>1.7329590158795576</iyy>
					<iyz>-0.5744301612895817</iyz>
					<izz>0.20602697576109233</izz>
				</inertia>
			</inertial>
			<collision name="shin_right_collision">
				<geometry>
					<mesh>
						<uri>model://biking_legs4/meshes/CAD/shin_right.stl</uri>
						<scale>0.001 0.001 0.001</scale>
					</mesh>
				</geometry>
			</collision>
			<visual name="shin_right_visual">
				<geometry>
					<mesh>
						<uri>model://biking_legs4/meshes/CAD/shin_right.stl</uri>
						<scale>0.001 0.001 0.001</scale>
					</mesh>
				</geometry>
			</visual>
		</link>
		<link name="shin_left">
			<self_collide>false</self_collide>
			<pose frame="">0.13919565223261118 -0.2107954372690158 0.4576228597650435 0.0 -0.0 0.0</pose>
			<inertial>
				<pose frame="">0.0 0.0 0.0 0 0 0</pose>
				<mass>5.431469125207291</mass>
				<inertia>
					<ixx>1.3987368906965336</ixx>
					<ixy>0.15734692678092663</ixy>
					<ixz>-0.33837858810796395</ixz>
					<iyy>1.2727113363929952</iyy>
					<iyz>0.5265221067083151</iyz>
					<izz>0.3656985507158622</izz>
				</inertia>
			</inertial>
			<collision name="shin_left_collision">
				<geometry>
					<mesh>
						<uri>model://biking_legs4/meshes/CAD/shin_left.stl</uri>
						<scale>0.001 0.001 0.001</scale>
					</mesh>
				</geometry>
			</collision>
			<visual name="shin_left_visual">
				<geometry>
					<mesh>
						<uri>model://biking_legs4/meshes/CAD/shin_left.stl</uri>
						<scale>0.001 0.001 0.001</scale>
					</mesh>
				</geometry>
			</visual>
		</link>
		<link name="bike">
			<self_collide>false</self_collide>
			<pose frame="">-1.3108998963673458e-07 2.442664557200658e-07 0.2700101774980866 0.0 -0.0 0.0</pose>
			<inertial>
				<pose frame="">0.0 0.0 0.0 0 0 0</pose>
				<mass>22.15788384251764</mass>
				<inertia>
					<ixx>13.53485267415266</ixx>
					<ixy>0.06502882891143595</ixy>
					<ixz>-3.9251147189684885</ixz>
					<iyy>17.567371829556876</iyy>
					<iyz>0.19195807841229648</iyz>
					<izz>4.647222970934148</izz>
				</inertia>
			</inertial>
			<collision name="bike_collision">
				<geometry>
					<mesh>
						<uri>model://biking_legs4/meshes/CAD/bike.stl</uri>
						<scale>0.001 0.001 0.001</scale>
					</mesh>
				</geometry>
			</collision>
			<visual name="bike_visual">
				<geometry>
					<mesh>
						<uri>model://biking_legs4/meshes/CAD/bike.stl</uri>
						<scale>0.001 0.001 0.001</scale>
					</mesh>
				</geometry>
			</visual>
		</link>
		<link name="thigh_right">
			<self_collide>false</self_collide>
			<pose frame="">0.2112120604302505 0.1880762822456904 0.7871150621346408 0.0 -0.0 0.0</pose>
			<inertial>
				<pose frame="">0.0 0.0 0.0 0 0 0</pose>
				<mass>5.375787339713349</mass>
				<inertia>
					<ixx>3.532780779758347</ixx>
					<ixy>-0.21578873691393144</ixy>
					<ixz>-0.895056574988743</ixz>
					<iyy>3.5966589981715678</iyy>
					<iyz>-0.7963161846061885</iyz>
					<izz>0.4531489356227194</izz>
				</inertia>
			</inertial>
			<collision name="thigh_right_collision">
				<geometry>
					<mesh>
						<uri>model://biking_legs4/meshes/CAD/thigh_right.stl</uri>
						<scale>0.001 0.001 0.001</scale>
					</mesh>
				</geometry>
			</collision>
			<visual name="thigh_right_visual">
				<geometry>
					<mesh>
						<uri>model://biking_legs4/meshes/CAD/thigh_right.stl</uri>
						<scale>0.001 0.001 0.001</scale>
					</mesh>
				</geometry>
			</visual>
		</link>
		<link name="thigh_left">
			<self_collide>false</self_collide>
			<pose frame="">0.21677227112529426 -0.21045055121708778 0.7489194230052839 0.0 -0.0 0.0</pose>
			<inertial>
				<pose frame="">0.0 0.0 0.0 0 0 0</pose>
				<mass>5.3758378001356215</mass>
				<inertia>
					<ixx>3.2682553686700095</ixx>
					<ixy>0.24671208503699205</ixy>
					<ixz>-0.8778642916028623</ixz>
					<iyy>3.2940751013867486</iyy>
					<iyz>0.8491474856449776</iyz>
					<izz>0.5109683209106501</izz>
				</inertia>
			</inertial>
			<collision name="thigh_left_collision">
				<geometry>
					<mesh>
						<uri>model://biking_legs4/meshes/CAD/thigh_left.stl</uri>
						<scale>0.001 0.001 0.001</scale>
					</mesh>
				</geometry>
			</collision>
			<visual name="thigh_left_visual">
				<geometry>
					<mesh>
						<uri>model://biking_legs4/meshes/CAD/thigh_left.stl</uri>
						<scale>0.001 0.001 0.001</scale>
					</mesh>
				</geometry>
			</visual>
		</link>
		<link name="front_part">
			<self_collide>false</self_collide>
			<pose frame="">-0.7163902611040208 0.010388551714715331 0.48643769332085723 0.0 -0.0 0.0</pose>
			<inertial>
				<pose frame="">0.0 0.0 0.0 0 0 0</pose>
				<mass>16.81067246604605</mass>
				<inertia>
					<ixx>6.39949781835294</ixx>
					<ixy>0.1811361598743797</ixy>
					<ixz>4.493581221870604</ixz>
					<iyy>17.853228424407295</iyy>
					<iyz>-0.05387549209623626</iyz>
					<izz>13.91291969470344</izz>
				</inertia>
			</inertial>
			<collision name="front_part_collision">
				<geometry>
					<mesh>
						<uri>model://biking_legs4/meshes/CAD/front_part.stl</uri>
						<scale>0.001 0.001 0.001</scale>
					</mesh>
				</geometry>
			</collision>
			<visual name="front_part_visual">
				<geometry>
					<mesh>
						<uri>model://biking_legs4/meshes/CAD/front_part.stl</uri>
						<scale>0.001 0.001 0.001</scale>
					</mesh>
				</geometry>
			</visual>
		</link>
		<link name="left_wheel">
			<self_collide>false</self_collide>
			<pose frame="">-0.9984258521253281 -0.3500004088111488 0.3156670000000095 0.0 -0.0 0.0</pose>
			<inertial>
				<pose frame="">0.0 0.0 0.0 0 0 0</pose>
				<mass>13.340163929097853</mass>
				<inertia>
					<ixx>3.472638325579821</ixx>
					<ixy>-4.661713033463341</ixy>
					<ixz>4.204420712343591</ixz>
					<iyy>15.643794956041955</iyy>
					<iyz>1.4738690559763468</iyz>
					<izz>15.441547158388762</izz>
				</inertia>
			</inertial>
			<collision name="left_wheel_collision">
				<geometry>
					<mesh>
						<uri>model://biking_legs4/meshes/CAD/left_wheel.stl</uri>
						<scale>0.001 0.001 0.001</scale>
					</mesh>
				</geometry>
			</collision>
			<visual name="left_wheel_visual">
				<geometry>
					<mesh>
						<uri>model://biking_legs4/meshes/CAD/left_wheel.stl</uri>
						<scale>0.001 0.001 0.001</scale>
					</mesh>
				</geometry>
			</visual>
		</link>
		<link name="right_wheel">
			<self_collide>false</self_collide>
			<pose frame="">-0.998425852125328 0.34200026941711825 0.31566700000003983 0.0 -0.0 0.0</pose>
			<inertial>
				<pose frame="">0.0 0.0 0.0 0 0 0</pose>
				<mass>13.340163929097852</mass>
				<inertia>
					<ixx>3.398785818884781</ixx>
					<ixy>4.555157860544104</ixy>
					<ixz>4.204420712343995</ixz>
					<iyy>15.643794956042209</iyy>
					<iyz>-1.4401800727652248</iyz>
					<izz>15.367694651693462</izz>
				</inertia>
			</inertial>
			<collision name="right_wheel_collision">
				<geometry>
					<mesh>
						<uri>model://biking_legs4/meshes/CAD/right_wheel.stl</uri>
						<scale>0.001 0.001 0.001</scale>
					</mesh>
				</geometry>
			</collision>
			<visual name="right_wheel_visual">
				<geometry>
					<mesh>
						<uri>model://biking_legs4/meshes/CAD/right_wheel.stl</uri>
						<scale>0.001 0.001 0.001</scale>
					</mesh>
				</geometry>
			</visual>
		</link>
		<link name="pedal_right">
			<self_collide>false</self_collide>
			<pose frame="">-0.060871485326468085 0.14778929036047628 0.33599902559519357 0.0 -0.0 0.0</pose>
			<inertial>
				<pose frame="">0.0 0.0 0.0 0 0 0</pose>
				<mass>0.9460025886020165</mass>
				<inertia>
					<ixx>0.12808184295787928</ixx>
					<ixy>0.008510384611564501</ixy>
					<ixz>0.019278552558843656</ixz>
					<iyy>0.11071945821838482</iyy>
					<iyz>-0.04697570498887458</iyz>
					<izz>0.02507467524472505</izz>
				</inertia>
			</inertial>
			<collision name="pedal_right_collision">
				<geometry>
					<mesh>
						<uri>model://biking_legs4/meshes/CAD/pedal_right.stl</uri>
						<scale>0.001 0.001 0.001</scale>
					</mesh>
				</geometry>
			</collision>
			<visual name="pedal_right_visual">
				<geometry>
					<mesh>
						<uri>model://biking_legs4/meshes/CAD/pedal_right.stl</uri>
						<scale>0.001 0.001 0.001</scale>
					</mesh>
				</geometry>
			</visual>
		</link>
		<link name="kurbel">
			<self_collide>false</self_collide>
			<pose frame="">0.09148135511675057 0.00013171801208982688 0.2734782195505036 0.0 -0.0 0.0</pose>
			<inertial>
				<pose frame="">0.0 0.0 0.0 0 0 0</pose>
				<mass>2.783270838110804</mass>
				<inertia>
					<ixx>0.22661192188560456</ixx>
					<ixy>0.011971430323317213</ixy>
					<ixz>-0.06353446718403094</ixz>
					<iyy>0.24931558226077652</iyy>
					<iyz>-0.005032343637373379</iyz>
					<izz>0.05406310500420523</izz>
				</inertia>
			</inertial>
			<collision name="kurbel_collision">
				<geometry>
					<mesh>
						<uri>model://biking_legs4/meshes/CAD/kurbel.stl</uri>
						<scale>0.001 0.001 0.001</scale>
					</mesh>
				</geometry>
			</collision>
			<visual name="kurbel_visual">
				<geometry>
					<mesh>
						<uri>model://biking_legs4/meshes/CAD/kurbel.stl</uri>
						<scale>0.001 0.001 0.001</scale>
					</mesh>
				</geometry>
			</visual>
		</link>
		<link name="pedal_left">
			<self_collide>false</self_collide>
			<pose frame="">0.25357665637062593 -0.14999470952001814 0.21798160797408994 0.0 -0.0 0.0</pose>
			<inertial>
				<pose frame="">0.0 0.0 0.0 0 0 0</pose>
				<mass>0.9460025886020155</mass>
				<inertia>
					<ixx>0.06713285096084799</ixx>
					<ixy>0.03598135689787884</ixy>
					<ixz>-0.05237475913761826</ixz>
					<iyy>0.10619417834611186</iyy>
					<iyz>0.030930583855591488</iyz>
					<izz>0.08274094008485167</izz>
				</inertia>
			</inertial>
			<collision name="pedal_left_collision">
				<geometry>
					<mesh>
						<uri>model://biking_legs4/meshes/CAD/pedal_left.stl</uri>
						<scale>0.001 0.001 0.001</scale>
					</mesh>
				</geometry>
			</collision>
			<visual name="pedal_left_visual">
				<geometry>
					<mesh>
						<uri>model://biking_legs4/meshes/CAD/pedal_left.stl</uri>
						<scale>0.001 0.001 0.001</scale>
					</mesh>
				</geometry>
			</visual>
		</link>
		<link name="foot_left">
			<self_collide>false</self_collide>
			<pose frame="">0.25562998919843105 -0.18618470225503764 0.3344885657960112 0.0 -0.0 0.0</pose>
			<inertial>
				<pose frame="">0.0 0.0 0.0 0 0 0</pose>
				<mass>0.7294027700323572</mass>
				<inertia>
					<ixx>0.10754473756929009</ixx>
					<ixy>0.03471787390427102</ixy>
					<ixz>-0.06239216537766689</ixz>
					<iyy>0.12991912414239987</iyy>
					<iyz>0.045426227332565114</iyz>
					<izz>0.07347575406267802</izz>
				</inertia>
			</inertial>
			<collision name="foot_left_collision">
				<geometry>
					<mesh>
						<uri>model://biking_legs4/meshes/CAD/foot_left.stl</uri>
						<scale>0.001 0.001 0.001</scale>
					</mesh>
				</geometry>
			</collision>
			<visual name="foot_left_visual">
				<geometry>
					<mesh>
						<uri>model://biking_legs4/meshes/CAD/foot_left.stl</uri>
						<scale>0.001 0.001 0.001</scale>
					</mesh>
				</geometry>
			</visual>
		</link>
		<link name="foot_left_tip">
			<self_collide>false</self_collide>
			<pose frame="">0.24052106963595002 -0.18509933645724233 0.23280083969708076 0.0 -0.0 0.0</pose>
			<inertial>
				<pose frame="">0.0 0.0 0.0 0 0 0</pose>
				<mass>0.2779398624199501</mass>
				<inertia>
					<ixx>0.02477295096745797</ixx>
					<ixy>0.012375918471231174</ixy>
					<ixz>-0.015587106868354284</ixz>
					<iyy>0.03125687402131169</iyy>
					<iyz>0.011984880492352296</iyz>
					<izz>0.0256907367419953</izz>
				</inertia>
			</inertial>
			<collision name="foot_left_tip_collision">
				<geometry>
					<mesh>
						<uri>model://biking_legs4/meshes/CAD/foot_left_tip.stl</uri>
						<scale>0.001 0.001 0.001</scale>
					</mesh>
				</geometry>
			</collision>
			<visual name="foot_left_tip_visual">
				<geometry>
					<mesh>
						<uri>model://biking_legs4/meshes/CAD/foot_left_tip.stl</uri>
						<scale>0.001 0.001 0.001</scale>
					</mesh>
				</geometry>
			</visual>
		</link>
		<link name="foot_right">
			<self_collide>false</self_collide>
			<pose frame="">0.05086576585988212 0.16225003091814402 0.3927044556316463 0.0 -0.0 0.0</pose>
			<inertial>
				<pose frame="">0.0 0.0 0.0 0 0 0</pose>
				<mass>0.7293879878869814</mass>
				<inertia>
					<ixx>0.13222157853584213</ixx>
					<ixy>-0.0060198298563743854</ixy>
					<ixz>-0.014610214465146527</ixz>
					<iyy>0.1150181707573252</iyy>
					<iyz>-0.04647242720704975</iyz>
					<izz>0.02173122153039112</izz>
				</inertia>
			</inertial>
			<collision name="foot_right_collision">
				<geometry>
					<mesh>
						<uri>model://biking_legs4/meshes/CAD/foot_right.stl</uri>
						<scale>0.001 0.001 0.001</scale>
					</mesh>
				</geometry>
			</collision>
			<visual name="foot_right_visual">
				<geometry>
					<mesh>
						<uri>model://biking_legs4/meshes/CAD/foot_right.stl</uri>
						<scale>0.001 0.001 0.001</scale>
					</mesh>
				</geometry>
			</visual>
		</link>
		<link name="foot_right_tip">
			<self_collide>false</self_collide>
			<pose frame="">-0.0455368764597267 0.1611660686115268 0.356620555707392 0.0 -0.0 0.0</pose>
			<inertial>
				<pose frame="">0.0 0.0 0.0 0 0 0</pose>
				<mass>0.277958485575208</mass>
				<inertia>
					<ixx>0.04265993481242803</ixx>
					<ixy>0.002031737159125534</ixy>
					<ixz>0.004485110875947303</ixz>
					<iyy>0.03603999846404039</iyy>
					<iyz>-0.015977233690499845</iyz>
					<izz>0.007980633153164171</izz>
				</inertia>
			</inertial>
			<collision name="foot_right_tip_collision">
				<geometry>
					<mesh>
						<uri>model://biking_legs4/meshes/CAD/foot_right_tip.stl</uri>
						<scale>0.001 0.001 0.001</scale>
					</mesh>
				</geometry>
			</collision>
			<visual name="foot_right_tip_visual">
				<geometry>
					<mesh>
						<uri>model://biking_legs4/meshes/CAD/foot_right_tip.stl</uri>
						<scale>0.001 0.001 0.001</scale>
					</mesh>
				</geometry>
			</visual>
		</link>
		<link name="wheel_back">
			<self_collide>false</self_collide>
			<pose frame="">0.5368974286036902 0.003549955621292267 0.31941587024902457 0.0 -0.0 0.0</pose>
			<inertial>
				<pose frame="">0.0 0.0 0.0 0 0 0</pose>
				<mass>13.34016392909848</mass>
				<inertia>
					<ixx>1.8703933815675218</ixx>
					<ixy>-0.025425846119325014</ixy>
					<ixz>-2.2877521950726827</ixz>
					<iyy>6.2227778893641625</iyy>
					<iyz>-0.015126574150566754</iyz>
					<izz>4.3547634684642125</izz>
				</inertia>
			</inertial>
			<collision name="wheel_back_collision">
				<geometry>
					<mesh>
						<uri>model://biking_legs4/meshes/CAD/wheel_back.stl</uri>
						<scale>0.001 0.001 0.001</scale>
					</mesh>
				</geometry>
			</collision>
			<visual name="wheel_back_visual">
				<geometry>
					<mesh>
						<uri>model://biking_legs4/meshes/CAD/wheel_back.stl</uri>
						<scale>0.001 0.001 0.001</scale>
					</mesh>
				</geometry>
			</visual>
		</link>
		<joint name="joint_pedal_right" type="revolute">
			<parent>kurbel</parent>
			<child>pedal_right</child>
			<pose frame="">-0.0034585828325984294 0.04220000006806959 0.0007026164893949983 0 0 0</pose>
			<axis>
				<xyz>-2.0192365920660242e-17 1.0000000000000016 -1.9344833188838944e-15</xyz>
				<limit>
					<lower>-3.141592653589793</lower>
					<upper>3.141592653589793</upper>
				</limit>
				<use_parent_model_frame>0</use_parent_model_frame>
			</axis>
		</joint>
		<joint name="joint_pedal_left" type="revolute">
			<parent>kurbel</parent>
			<child>pedal_left</child>
			<pose frame="">-0.00412775198006198 -0.04125000005143699 -0.008045545619484892 0 0 0</pose>
			<axis>
				<xyz>2.0192365920646832e-17 -1.0 1.9344833188838944e-15</xyz>
				<limit>
					<lower>-3.141592653589793</lower>
					<upper>3.141592653589793</upper>
				</limit>
				<use_parent_model_frame>0</use_parent_model_frame>
			</axis>
		</joint>
		<joint name="joint_foot_left" type="revolute">
			<parent>shin_left</parent>
			<child>foot_left</child>
			<pose frame="">-0.024136002440165713 0.023919428475442466 0.00933722988776779 0 0 0</pose>
			<axis>
				<xyz>1.4918101988658006e-10 1.0000000000000002 2.154268320473693e-10</xyz>
				<limit>
					<lower>-1.2217304763960306</lower>
					<upper>1.2217304763960306</upper>
				</limit>
				<use_parent_model_frame>0</use_parent_model_frame>
			</axis>
		</joint>
		<joint name="joint_foot_left_tip" type="fixed">
			<parent>foot_left</parent>
			<child>foot_left_tip</child>
			<pose frame="">0.007251923061045993 -0.0011659373094430236 0.040818161683961095 0 0 0</pose>
		</joint>
		<joint name="joint_foot_right" type="revolute">
			<parent>shin_right</parent>
			<child>foot_right</child>
			<pose frame="">-0.003671644529884537 0.02408038791411233 0.025628846993465047 0 0 0</pose>
			<axis>
				<xyz>8.624347119539928e-11 0.999999999999997 -1.2386997847600487e-10</xyz>
				<limit>
					<lower>-1.2217304763960306</lower>
					<upper>1.2217304763960306</upper>
				</limit>
				<use_parent_model_frame>0</use_parent_model_frame>
			</axis>
		</joint>
		<joint name="joint_foot_right_tip" type="fixed">
			<parent>foot_right</parent>
			<child>foot_right_tip</child>
			<pose frame="">0.039218970260477014 0.0011643502193648915 0.013437878615012977 0 0 0</pose>
		</joint>
		<joint name="joint_wheel_right" type="revolute">
			<parent>front_part</parent>
			<child>right_wheel</child>
			<pose frame="">4.263256414560601e-16 -0.003999653375198307 5.5067062021407766e-15 0 0 0</pose>
			<axis>
				<xyz>-3.1662288285727846e-30 0.9999999999999998 4.317059530368991e-14</xyz>
				<limit>
					<lower>-3.141592653589793</lower>
					<upper>3.141592653589793</upper>
				</limit>
				<use_parent_model_frame>0</use_parent_model_frame>
			</axis>
		</joint>
		<joint name="joint_wheel_back" type="revolute">
			<parent>bike</parent>
			<child>wheel_back</child>
			<pose frame="">-2.1316282072803005e-16 -0.0689996533751975 3.552713678800501e-16 0 0 0</pose>
			<axis>
				<xyz>6.938893903907228e-17 -1.0 1.27675647831893e-15</xyz>
				<limit>
					<lower>-3.141592653589793</lower>
					<upper>3.141592653589793</upper>
				</limit>
				<use_parent_model_frame>0</use_parent_model_frame>
			</axis>
		</joint>
		<joint name="joint_pedal" type="revolute">
			<parent>bike</parent>
			<child>kurbel</child>
			<pose frame="">0.0010256624613746545 -0.03513164955582013 -0.0002102674020640194 0 0 0</pose>
			<axis>
				<xyz>-6.938893903907228e-17 1.0 -1.27675647831893e-15</xyz>
				<limit>
					<lower>-3.141592653589793</lower>
					<upper>3.141592653589793</upper>
				</limit>
				<use_parent_model_frame>0</use_parent_model_frame>
			</axis>
		</joint>
		<joint name="joint_wheel_left" type="revolute">
			<parent>front_part</parent>
			<child>left_wheel</child>
			<pose frame="">5.684341886080802e-16 0.04600034662480176 7.567280135845067e-15 0 0 0</pose>
			<axis>
				<xyz>3.1662288285727846e-30 -0.9999999999999998 -4.317059530368991e-14</xyz>
				<limit>
					<lower>-3.141592653589793</lower>
					<upper>3.141592653589793</upper>
				</limit>
				<use_parent_model_frame>0</use_parent_model_frame>
			</axis>
		</joint>
		<joint name="joint_front" type="revolute">
			<parent>bike</parent>
			<child>front_part</child>
			<pose frame="">-0.23003546775109895 -0.010388307448302651 -0.2052706951041601 0 0 0</pose>
			<axis>
				<xyz>5.345642609144017e-16 -4.084397910750052e-14 1.0</xyz>
				<limit>
					<lower>-0.5235987755982988</lower>
					<upper>0.5235987755982988</upper>
				</limit>
				<use_parent_model_frame>0</use_parent_model_frame>
			</axis>
		</joint>
		<joint name="joint_foot_pedal_left" type="prismatic">
			<parent>pedal_left</parent>
			<child>foot_left_tip</child>
			<pose frame="">0.0016098871523151815 -0.006895373061816521 -0.0115095533441934 0 0 0</pose>
			<axis>
				<xyz>0.27563735580589704 -2.483424453883159e-10 0.9612616959415018</xyz>
				<limit>
					<lower>0.0</lower>
					<upper>0.0</upper>
				</limit>
				<use_parent_model_frame>0</use_parent_model_frame>
			</axis>
		</joint>
		<joint name="joint_foot_pedal_right" type="prismatic">
			<parent>pedal_right</parent>
			<child>foot_right_tip</child>
			<pose frame="">-0.0020755620785581907 0.028623221749667457 -0.005332452014808524 0 0 0</pose>
			<axis>
				<xyz>-0.9743700664056434 5.616845250501422e-11 -0.22495104732509433</xyz>
				<limit>
					<lower>0.0</lower>
					<upper>0.0</upper>
				</limit>
				<use_parent_model_frame>0</use_parent_model_frame>
			</axis>
		</joint>
		<joint name="joint_knee_right" type="revolute">
			<parent>thigh_left</parent>
			<child>shin_left</child>
			<pose frame="">-0.09504128100450046 0.02908016339027043 0.12455325869175496 0 0 0</pose>
			<axis>
				<xyz>3.881963529614987e-11 0.9999999999999999 3.572896691602e-10</xyz>
				<limit>
					<lower>0.0</lower>
					<upper>0.0</upper>
				</limit>
				<use_parent_model_frame>0</use_parent_model_frame>
			</axis>
		</joint>
		<joint name="joint_hip_right" type="revolute">
			<parent>bike</parent>
			<child>thigh_right</child>
			<pose frame="">0.10289157007831527 -0.022745863356888912 0.02411536605529065 0 0 0</pose>
			<axis>
				<xyz>-7.079316341703668e-11 -0.999999999999999 1.6436684458284362e-10</xyz>
				<limit>
					<lower>0.0</lower>
					<upper>3.141592653589793</upper>
				</limit>
				<use_parent_model_frame>0</use_parent_model_frame>
			</axis>
		</joint>
		<joint name="joint_hip_left" type="revolute">
			<parent>bike</parent>
			<child>thigh_left</child>
			<pose frame="">0.08175586676778082 0.011385277244846287 0.06697799584544172 0 0 0</pose>
			<axis>
				<xyz>-4.0005048569493725e-11 -0.9999999999999992 -3.5821318751520816e-10</xyz>
				<limit>
					<lower>-1.5707963267948966</lower>
					<upper>1.5707963267948966</upper>
				</limit>
				<use_parent_model_frame>0</use_parent_model_frame>
			</axis>
		</joint>
		<joint name="joint_knee_left" type="revolute">
			<parent>thigh_right</parent>
			<child>shin_right</child>
			<pose frame="">-0.030120033401146384 -0.021509408511104233 0.15266257289284255 0 0 0</pose>
			<axis>
				<xyz>9.38114342148869e-11 0.9999999999999992 -1.5947454821937694e-10</xyz>
				<limit>
					<lower>0.0</lower>
					<upper>0.0</upper>
				</limit>
				<use_parent_model_frame>0</use_parent_model_frame>
			</axis>
		</joint>
	</model>
</sdf>
