<?xml version="1.0" ?>
<sdf version="1.6">
	<model name="biking_legs4">
		<link name="shin_right">
			<self_collide>false</self_collide>
			<pose frame="">0.013058272137911553 0.18772005548325768 0.5606793547108082 0.0 -0.0 0.0</pose>
			<inertial>
				<pose frame="">0.0 0.0 0.0 0 0 0</pose>
				<mass>5.457533583852904</mass>
				<inertia>
					<ixx>1.9343175776037151</ixx>
					<ixy>-0.01324889341372523</ixy>
					<ixz>-0.035134662836648595</ixz>
					<iyy>1.7473435884602033</iyy>
					<iyz>-0.5775851701254785</iyz>
					<izz>0.20674034532295446</izz>
				</inertia>
			</inertial>
			<collision name="shin_right_collision">
				<geometry>
					<mesh>
						<uri>model://biking_legs4/meshes/CAD/shin_right.stl</uri>
						<scale>0.001 0.001 0.001</scale>
					</mesh>
				</geometry>
			</collision>
			<visual name="shin_right_visual">
				<geometry>
					<mesh>
						<uri>model://biking_legs4/meshes/CAD/shin_right.stl</uri>
						<scale>0.001 0.001 0.001</scale>
					</mesh>
				</geometry>
			</visual>
		</link>
		<link name="shin_left">
			<self_collide>false</self_collide>
			<pose frame="">0.13864687549215313 -0.21067292980418575 0.4583275839410171 0.0 -0.0 0.0</pose>
			<inertial>
				<pose frame="">0.0 0.0 0.0 0 0 0</pose>
				<mass>5.457606455829215</mass>
				<inertia>
					<ixx>1.409197899698929</ixx>
					<ixy>0.1574660562076355</ixy>
					<ixz>-0.33876758849355515</ixz>
					<iyy>1.2822915268968085</iyy>
					<iyz>0.5294498316866111</iyz>
					<izz>0.3666155474883879</izz>
				</inertia>
			</inertial>
			<collision name="shin_left_collision">
				<geometry>
					<mesh>
						<uri>model://biking_legs4/meshes/CAD/shin_left.stl</uri>
						<scale>0.001 0.001 0.001</scale>
					</mesh>
				</geometry>
			</collision>
			<visual name="shin_left_visual">
				<geometry>
					<mesh>
						<uri>model://biking_legs4/meshes/CAD/shin_left.stl</uri>
						<scale>0.001 0.001 0.001</scale>
					</mesh>
				</geometry>
			</visual>
		</link>
		<link name="bike">
			<self_collide>false</self_collide>
			<pose frame="">-1.3108998963673458e-07 2.442664557200658e-07 0.2700101774980866 0.0 -0.0 0.0</pose>
			<inertial>
				<pose frame="">0.0 0.0 0.0 0 0 0</pose>
				<mass>22.15788384251764</mass>
				<inertia>
					<ixx>13.53485267415266</ixx>
					<ixy>0.06502882891143595</ixy>
					<ixz>-3.9251147189684885</ixz>
					<iyy>17.567371829556876</iyy>
					<iyz>0.19195807841229648</iyz>
					<izz>4.647222970934148</izz>
				</inertia>
			</inertial>
			<collision name="bike_collision">
				<geometry>
					<mesh>
						<uri>model://biking_legs4/meshes/CAD/bike.stl</uri>
						<scale>0.001 0.001 0.001</scale>
					</mesh>
				</geometry>
			</collision>
			<visual name="bike_visual">
				<geometry>
					<mesh>
						<uri>model://biking_legs4/meshes/CAD/bike.stl</uri>
						<scale>0.001 0.001 0.001</scale>
					</mesh>
				</geometry>
			</visual>
		</link>
		<link name="thigh_right">
			<self_collide>false</self_collide>
			<pose frame="">0.21236417741961713 0.18819962478275165 0.7873387297192743 0.0 -0.0 0.0</pose>
			<inertial>
				<pose frame="">0.0 0.0 0.0 0 0 0</pose>
				<mass>5.3496506676238305</mass>
				<inertia>
					<ixx>3.517719061701914</ixx>
					<ixy>-0.21589344212188052</ixy>
					<ixz>-0.8955332279369601</ixz>
					<iyy>3.5822744205778334</iyy>
					<iyz>-0.7931611748573322</iyz>
					<izz>0.4524355620187984</izz>
				</inertia>
			</inertial>
			<collision name="thigh_right_collision">
				<geometry>
					<mesh>
						<uri>model://biking_legs4/meshes/CAD/thigh_right.stl</uri>
						<scale>0.001 0.001 0.001</scale>
					</mesh>
				</geometry>
			</collision>
			<visual name="thigh_right_visual">
				<geometry>
					<mesh>
						<uri>model://biking_legs4/meshes/CAD/thigh_right.stl</uri>
						<scale>0.001 0.001 0.001</scale>
					</mesh>
				</geometry>
			</visual>
		</link>
		<link name="thigh_left">
			<self_collide>false</self_collide>
			<pose frame="">0.21771113738008815 -0.21057384468739415 0.7496236881053824 0.0 -0.0 0.0</pose>
			<inertial>
				<pose frame="">0.0 0.0 0.0 0 0 0</pose>
				<mass>5.349700469513711</mass>
				<inertia>
					<ixx>3.2577943403973926</ixx>
					<ixy>0.24659295147818844</ixy>
					<ixz>-0.8774752757639681</ixz>
					<iyy>3.2844948851559583</iyy>
					<iyz>0.8462197564460474</iyz>
					<izz>0.510051315732403</izz>
				</inertia>
			</inertial>
			<collision name="thigh_left_collision">
				<geometry>
					<mesh>
						<uri>model://biking_legs4/meshes/CAD/thigh_left.stl</uri>
						<scale>0.001 0.001 0.001</scale>
					</mesh>
				</geometry>
			</collision>
			<visual name="thigh_left_visual">
				<geometry>
					<mesh>
						<uri>model://biking_legs4/meshes/CAD/thigh_left.stl</uri>
						<scale>0.001 0.001 0.001</scale>
					</mesh>
				</geometry>
			</visual>
		</link>
		<link name="front_part">
			<self_collide>false</self_collide>
			<pose frame="">-0.7163902611040208 0.010388551714715331 0.48643769332085723 0.0 -0.0 0.0</pose>
			<inertial>
				<pose frame="">0.0 0.0 0.0 0 0 0</pose>
				<mass>16.81067246604605</mass>
				<inertia>
					<ixx>6.39949781835294</ixx>
					<ixy>0.1811361598743797</ixy>
					<ixz>4.493581221870604</ixz>
					<iyy>17.853228424407295</iyy>
					<iyz>-0.05387549209623626</iyz>
					<izz>13.91291969470344</izz>
				</inertia>
			</inertial>
			<collision name="front_part_collision">
				<geometry>
					<mesh>
						<uri>model://biking_legs4/meshes/CAD/front_part.stl</uri>
						<scale>0.001 0.001 0.001</scale>
					</mesh>
				</geometry>
			</collision>
			<visual name="front_part_visual">
				<geometry>
					<mesh>
						<uri>model://biking_legs4/meshes/CAD/front_part.stl</uri>
						<scale>0.001 0.001 0.001</scale>
					</mesh>
				</geometry>
			</visual>
		</link>
		<link name="left_wheel">
			<self_collide>false</self_collide>
			<pose frame="">-0.9984258521253281 -0.3500004088111488 0.3156670000000095 0.0 -0.0 0.0</pose>
			<inertial>
				<pose frame="">0.0 0.0 0.0 0 0 0</pose>
				<mass>13.340163929097853</mass>
				<inertia>
					<ixx>3.472638325579821</ixx>
					<ixy>-4.661713033463341</ixy>
					<ixz>4.204420712343591</ixz>
					<iyy>15.643794956041955</iyy>
					<iyz>1.4738690559763468</iyz>
					<izz>15.441547158388762</izz>
				</inertia>
			</inertial>
			<collision name="left_wheel_collision">
				<geometry>
					<mesh>
						<uri>model://biking_legs4/meshes/CAD/left_wheel.stl</uri>
						<scale>0.001 0.001 0.001</scale>
					</mesh>
				</geometry>
			</collision>
			<visual name="left_wheel_visual">
				<geometry>
					<mesh>
						<uri>model://biking_legs4/meshes/CAD/left_wheel.stl</uri>
						<scale>0.001 0.001 0.001</scale>
					</mesh>
				</geometry>
			</visual>
		</link>
		<link name="right_wheel">
			<self_collide>false</self_collide>
			<pose frame="">-0.998425852125328 0.34200026941711825 0.31566700000003983 0.0 -0.0 0.0</pose>
			<inertial>
				<pose frame="">0.0 0.0 0.0 0 0 0</pose>
				<mass>13.340163929097852</mass>
				<inertia>
					<ixx>3.398785818884781</ixx>
					<ixy>4.555157860544104</ixy>
					<ixz>4.204420712343995</ixz>
					<iyy>15.643794956042209</iyy>
					<iyz>-1.4401800727652248</iyz>
					<izz>15.367694651693462</izz>
				</inertia>
			</inertial>
			<collision name="right_wheel_collision">
				<geometry>
					<mesh>
						<uri>model://biking_legs4/meshes/CAD/right_wheel.stl</uri>
						<scale>0.001 0.001 0.001</scale>
					</mesh>
				</geometry>
			</collision>
			<visual name="right_wheel_visual">
				<geometry>
					<mesh>
						<uri>model://biking_legs4/meshes/CAD/right_wheel.stl</uri>
						<scale>0.001 0.001 0.001</scale>
					</mesh>
				</geometry>
			</visual>
		</link>
		<link name="pedal_right">
			<self_collide>false</self_collide>
			<pose frame="">-0.060871485326468085 0.14778929036047628 0.33599902559519357 0.0 -0.0 0.0</pose>
			<inertial>
				<pose frame="">0.0 0.0 0.0 0 0 0</pose>
				<mass>0.9460025886020165</mass>
				<inertia>
					<ixx>0.12808184295787928</ixx>
					<ixy>0.008510384611564501</ixy>
					<ixz>0.019278552558843656</ixz>
					<iyy>0.11071945821838482</iyy>
					<iyz>-0.04697570498887458</iyz>
					<izz>0.02507467524472505</izz>
				</inertia>
			</inertial>
			<collision name="pedal_right_collision">
				<geometry>
					<mesh>
						<uri>model://biking_legs4/meshes/CAD/pedal_right.stl</uri>
						<scale>0.001 0.001 0.001</scale>
					</mesh>
				</geometry>
			</collision>
			<visual name="pedal_right_visual">
				<geometry>
					<mesh>
						<uri>model://biking_legs4/meshes/CAD/pedal_right.stl</uri>
						<scale>0.001 0.001 0.001</scale>
					</mesh>
				</geometry>
			</visual>
		</link>
		<link name="kurbel">
			<self_collide>false</self_collide>
			<pose frame="">0.09148135511675057 0.00013171801208982688 0.2734782195505036 0.0 -0.0 0.0</pose>
			<inertial>
				<pose frame="">0.0 0.0 0.0 0 0 0</pose>
				<mass>2.783270838110804</mass>
				<inertia>
					<ixx>0.22661192188560456</ixx>
					<ixy>0.011971430323317213</ixy>
					<ixz>-0.06353446718403094</ixz>
					<iyy>0.24931558226077652</iyy>
					<iyz>-0.005032343637373379</iyz>
					<izz>0.05406310500420523</izz>
				</inertia>
			</inertial>
			<collision name="kurbel_collision">
				<geometry>
					<mesh>
						<uri>model://biking_legs4/meshes/CAD/kurbel.stl</uri>
						<scale>0.001 0.001 0.001</scale>
					</mesh>
				</geometry>
			</collision>
			<visual name="kurbel_visual">
				<geometry>
					<mesh>
						<uri>model://biking_legs4/meshes/CAD/kurbel.stl</uri>
						<scale>0.001 0.001 0.001</scale>
					</mesh>
				</geometry>
			</visual>
		</link>
		<link name="pedal_left">
			<self_collide>false</self_collide>
			<pose frame="">0.25357665637062593 -0.14999470952001814 0.21798160797408994 0.0 -0.0 0.0</pose>
			<inertial>
				<pose frame="">0.0 0.0 0.0 0 0 0</pose>
				<mass>0.9460025886020155</mass>
				<inertia>
					<ixx>0.06713285096084799</ixx>
					<ixy>0.03598135689787884</ixy>
					<ixz>-0.05237475913761826</ixz>
					<iyy>0.10619417834611186</iyy>
					<iyz>0.030930583855591488</iyz>
					<izz>0.08274094008485167</izz>
				</inertia>
			</inertial>
			<collision name="pedal_left_collision">
				<geometry>
					<mesh>
						<uri>model://biking_legs4/meshes/CAD/pedal_left.stl</uri>
						<scale>0.001 0.001 0.001</scale>
					</mesh>
				</geometry>
			</collision>
			<visual name="pedal_left_visual">
				<geometry>
					<mesh>
						<uri>model://biking_legs4/meshes/CAD/pedal_left.stl</uri>
						<scale>0.001 0.001 0.001</scale>
					</mesh>
				</geometry>
			</visual>
		</link>
		<link name="foot_left">
			<self_collide>false</self_collide>
			<pose frame="">0.25562998919843105 -0.18618470225503764 0.3344885657960112 0.0 -0.0 0.0</pose>
			<inertial>
				<pose frame="">0.0 0.0 0.0 0 0 0</pose>
				<mass>0.7294027700323572</mass>
				<inertia>
					<ixx>0.10754473756929009</ixx>
					<ixy>0.03471787390427102</ixy>
					<ixz>-0.06239216537766689</ixz>
					<iyy>0.12991912414239987</iyy>
					<iyz>0.045426227332565114</iyz>
					<izz>0.07347575406267802</izz>
				</inertia>
			</inertial>
			<collision name="foot_left_collision">
				<geometry>
					<mesh>
						<uri>model://biking_legs4/meshes/CAD/foot_left.stl</uri>
						<scale>0.001 0.001 0.001</scale>
					</mesh>
				</geometry>
			</collision>
			<visual name="foot_left_visual">
				<geometry>
					<mesh>
						<uri>model://biking_legs4/meshes/CAD/foot_left.stl</uri>
						<scale>0.001 0.001 0.001</scale>
					</mesh>
				</geometry>
			</visual>
		</link>
		<link name="foot_left_tip">
			<self_collide>false</self_collide>
			<pose frame="">0.24052106963595002 -0.18509933645724233 0.23280083969708076 0.0 -0.0 0.0</pose>
			<inertial>
				<pose frame="">0.0 0.0 0.0 0 0 0</pose>
				<mass>0.2779398624199501</mass>
				<inertia>
					<ixx>0.02477295096745797</ixx>
					<ixy>0.012375918471231174</ixy>
					<ixz>-0.015587106868354284</ixz>
					<iyy>0.03125687402131169</iyy>
					<iyz>0.011984880492352296</iyz>
					<izz>0.0256907367419953</izz>
				</inertia>
			</inertial>
			<collision name="foot_left_tip_collision">
				<geometry>
					<mesh>
						<uri>model://biking_legs4/meshes/CAD/foot_left_tip.stl</uri>
						<scale>0.001 0.001 0.001</scale>
					</mesh>
				</geometry>
			</collision>
			<visual name="foot_left_tip_visual">
				<geometry>
					<mesh>
						<uri>model://biking_legs4/meshes/CAD/foot_left_tip.stl</uri>
						<scale>0.001 0.001 0.001</scale>
					</mesh>
				</geometry>
			</visual>
		</link>
		<link name="foot_right">
			<self_collide>false</self_collide>
			<pose frame="">0.05086576585988212 0.16225003091814402 0.3927044556316463 0.0 -0.0 0.0</pose>
			<inertial>
				<pose frame="">0.0 0.0 0.0 0 0 0</pose>
				<mass>0.7293879878869814</mass>
				<inertia>
					<ixx>0.13222157853584213</ixx>
					<ixy>-0.0060198298563743854</ixy>
					<ixz>-0.014610214465146527</ixz>
					<iyy>0.1150181707573252</iyy>
					<iyz>-0.04647242720704975</iyz>
					<izz>0.02173122153039112</izz>
				</inertia>
			</inertial>
			<collision name="foot_right_collision">
				<geometry>
					<mesh>
						<uri>model://biking_legs4/meshes/CAD/foot_right.stl</uri>
						<scale>0.001 0.001 0.001</scale>
					</mesh>
				</geometry>
			</collision>
			<visual name="foot_right_visual">
				<geometry>
					<mesh>
						<uri>model://biking_legs4/meshes/CAD/foot_right.stl</uri>
						<scale>0.001 0.001 0.001</scale>
					</mesh>
				</geometry>
			</visual>
		</link>
		<link name="foot_right_tip">
			<self_collide>false</self_collide>
			<pose frame="">-0.0455368764597267 0.1611660686115268 0.356620555707392 0.0 -0.0 0.0</pose>
			<inertial>
				<pose frame="">0.0 0.0 0.0 0 0 0</pose>
				<mass>0.277958485575208</mass>
				<inertia>
					<ixx>0.04265993481242803</ixx>
					<ixy>0.002031737159125534</ixy>
					<ixz>0.004485110875947303</ixz>
					<iyy>0.03603999846404039</iyy>
					<iyz>-0.015977233690499845</iyz>
					<izz>0.007980633153164171</izz>
				</inertia>
			</inertial>
			<collision name="foot_right_tip_collision">
				<geometry>
					<mesh>
						<uri>model://biking_legs4/meshes/CAD/foot_right_tip.stl</uri>
						<scale>0.001 0.001 0.001</scale>
					</mesh>
				</geometry>
			</collision>
			<visual name="foot_right_tip_visual">
				<geometry>
					<mesh>
						<uri>model://biking_legs4/meshes/CAD/foot_right_tip.stl</uri>
						<scale>0.001 0.001 0.001</scale>
					</mesh>
				</geometry>
			</visual>
		</link>
		<link name="wheel_back">
			<self_collide>false</self_collide>
			<pose frame="">0.5368974286036902 0.003549955621292267 0.31941587024902457 0.0 -0.0 0.0</pose>
			<inertial>
				<pose frame="">0.0 0.0 0.0 0 0 0</pose>
				<mass>13.34016392909848</mass>
				<inertia>
					<ixx>1.8703933815675218</ixx>
					<ixy>-0.025425846119325014</ixy>
					<ixz>-2.2877521950726827</ixz>
					<iyy>6.2227778893641625</iyy>
					<iyz>-0.015126574150566754</iyz>
					<izz>4.3547634684642125</izz>
				</inertia>
			</inertial>
			<collision name="wheel_back_collision">
				<geometry>
					<mesh>
						<uri>model://biking_legs4/meshes/CAD/wheel_back.stl</uri>
						<scale>0.001 0.001 0.001</scale>
					</mesh>
				</geometry>
			</collision>
			<visual name="wheel_back_visual">
				<geometry>
					<mesh>
						<uri>model://biking_legs4/meshes/CAD/wheel_back.stl</uri>
						<scale>0.001 0.001 0.001</scale>
					</mesh>
				</geometry>
			</visual>
		</link>
		<joint name="joint_pedal_right" type="revolute">
			<parent>kurbel</parent>
			<child>pedal_right</child>
			<pose frame="">-0.06433006815906651 0.18998929042854587 0.3367016420845886 0 0 0</pose>
			<axis>
				<xyz>-2.0192365920660242e-17 1.0000000000000016 -1.9344833188838944e-15</xyz>
				<limit>
					<lower>-3.141592653589793</lower>
					<upper>3.141592653589793</upper>
				</limit>
				<use_parent_model_frame>0</use_parent_model_frame>
			</axis>
		</joint>
		<joint name="joint_pedal_left" type="revolute">
			<parent>kurbel</parent>
			<child>pedal_left</child>
			<pose frame="">0.24944890439056394 -0.19124470957145512 0.20993606235460505 0 0 0</pose>
			<axis>
				<xyz>2.0192365920646832e-17 -1.0 1.9344833188838944e-15</xyz>
				<limit>
					<lower>-3.141592653589793</lower>
					<upper>3.141592653589793</upper>
				</limit>
				<use_parent_model_frame>0</use_parent_model_frame>
			</axis>
		</joint>
		<joint name="joint_foot_left" type="revolute">
			<parent>shin_left</parent>
			<child>foot_left</child>
			<pose frame="">0.23149398675826532 -0.16226527377959518 0.343825795683779 0 0 0</pose>
			<axis>
				<xyz>1.4918101988658006e-10 1.0000000000000002 2.154268320473693e-10</xyz>
				<limit>
					<lower>-1.2217304763960306</lower>
					<upper>1.2217304763960306</upper>
				</limit>
				<use_parent_model_frame>0</use_parent_model_frame>
			</axis>
		</joint>
		<joint name="joint_foot_left_tip" type="fixed">
			<parent>foot_left</parent>
			<child>foot_left_tip</child>
			<pose frame="">0.24777299269699601 -0.18626527376668534 0.2736190013810419 0 0 0</pose>
		</joint>
		<joint name="joint_foot_right" type="revolute">
			<parent>shin_right</parent>
			<child>foot_right</child>
			<pose frame="">0.04719412132999758 0.18633041883225634 0.4183333026251113 0 0 0</pose>
			<axis>
				<xyz>8.624347119539928e-11 0.999999999999997 -1.2386997847600487e-10</xyz>
				<limit>
					<lower>-1.2217304763960306</lower>
					<upper>1.2217304763960306</upper>
				</limit>
				<use_parent_model_frame>0</use_parent_model_frame>
			</axis>
		</joint>
		<joint name="joint_foot_right_tip" type="fixed">
			<parent>foot_right</parent>
			<child>foot_right_tip</child>
			<pose frame="">-0.006317906199249688 0.1623304188308917 0.370058434322405 0 0 0</pose>
		</joint>
		<joint name="joint_wheel_right" type="revolute">
			<parent>front_part</parent>
			<child>right_wheel</child>
			<pose frame="">-0.9984258521253275 0.33800061604191994 0.31566700000004533 0 0 0</pose>
			<axis>
				<xyz>-3.1662288285727846e-30 0.9999999999999998 4.317059530368991e-14</xyz>
				<limit>
					<lower>-3.141592653589793</lower>
					<upper>3.141592653589793</upper>
				</limit>
				<use_parent_model_frame>0</use_parent_model_frame>
			</axis>
		</joint>
		<joint name="joint_wheel_back" type="revolute">
			<parent>bike</parent>
			<child>wheel_back</child>
			<pose frame="">0.5368974286036899 -0.06544969775390523 0.3194158702490249 0 0 0</pose>
			<axis>
				<xyz>6.938893903907228e-17 -1.0 1.27675647831893e-15</xyz>
				<limit>
					<lower>-3.141592653589793</lower>
					<upper>3.141592653589793</upper>
				</limit>
				<use_parent_model_frame>0</use_parent_model_frame>
			</axis>
		</joint>
		<joint name="joint_pedal" type="revolute">
			<parent>bike</parent>
			<child>kurbel</child>
			<pose frame="">0.09250701757812521 -0.0349999315437303 0.2732679521484396 0 0 0</pose>
			<axis>
				<xyz>-6.938893903907228e-17 1.0 -1.27675647831893e-15</xyz>
				<limit>
					<lower>-3.141592653589793</lower>
					<upper>3.141592653589793</upper>
				</limit>
				<use_parent_model_frame>0</use_parent_model_frame>
			</axis>
		</joint>
		<joint name="joint_wheel_left" type="revolute">
			<parent>front_part</parent>
			<child>left_wheel</child>
			<pose frame="">-0.9984258521253275 -0.304000062186347 0.31566700000001713 0 0 0</pose>
			<axis>
				<xyz>3.1662288285727846e-30 -0.9999999999999998 -4.317059530368991e-14</xyz>
				<limit>
					<lower>-3.141592653589793</lower>
					<upper>3.141592653589793</upper>
				</limit>
				<use_parent_model_frame>0</use_parent_model_frame>
			</axis>
		</joint>
		<joint name="joint_front" type="revolute">
			<parent>bike</parent>
			<child>front_part</child>
			<pose frame="">-0.9464257288551199 2.442664126789396e-07 0.28116699821669716 0 0 0</pose>
			<axis>
				<xyz>5.345642609144017e-16 -4.084397910750052e-14 1.0</xyz>
				<limit>
					<lower>-0.5235987755982988</lower>
					<upper>0.5235987755982988</upper>
				</limit>
				<use_parent_model_frame>0</use_parent_model_frame>
			</axis>
		</joint>
		<joint name="joint_foot_pedal_left" type="prismatic">
			<parent>pedal_left</parent>
			<child>foot_left_tip</child>
			<pose frame="">0.2421309567882652 -0.19199470951905884 0.22129128635288736 0 0 0</pose>
			<axis>
				<xyz>0.27563735580589704 -2.483424453883159e-10 0.9612616959415018</xyz>
				<limit>
					<lower>0.0</lower>
					<upper>0.0</upper>
				</limit>
				<use_parent_model_frame>0</use_parent_model_frame>
			</axis>
		</joint>
		<joint name="joint_foot_pedal_right" type="prismatic">
			<parent>pedal_right</parent>
			<child>foot_right_tip</child>
			<pose frame="">-0.047612438538284896 0.18978929036119424 0.35128810369258345 0 0 0</pose>
			<axis>
				<xyz>-0.9743700664056434 5.616845250501422e-11 -0.22495104732509433</xyz>
				<limit>
					<lower>0.0</lower>
					<upper>0.0</upper>
				</limit>
				<use_parent_model_frame>0</use_parent_model_frame>
			</axis>
		</joint>
		<joint name="joint_knee_left" type="revolute">
			<parent>thigh_left</parent>
			<child>shin_left</child>
			<pose frame="">0.049111867471422474 -0.1817152738931193 0.6218677199739652 0 0 0</pose>
			<axis>
				<xyz>-3.881963529614969e-11 -0.9999999999999997 -3.572896691601996e-10</xyz>
				<limit>
					<lower>0.0</lower>
					<upper>1.5707963267948966</upper>
				</limit>
				<use_parent_model_frame>0</use_parent_model_frame>
			</axis>
		</joint>
		<joint name="joint_hip_right" type="revolute">
			<parent>bike</parent>
			<child>thigh_right</child>
			<pose frame="">0.31410363050856577 0.16533041888880148 0.8112304281899314 0 0 0</pose>
			<axis>
				<xyz>-7.079316341703668e-11 -0.999999999999999 1.6436684458284362e-10</xyz>
				<limit>
					<lower>0.0</lower>
					<upper>3.141592653589793</upper>
				</limit>
				<use_parent_model_frame>0</use_parent_model_frame>
			</axis>
		</joint>
		<joint name="joint_hip_left" type="revolute">
			<parent>bike</parent>
			<child>thigh_left</child>
			<pose frame="">0.2985281378930751 -0.1990652739722415 0.8158974188507255 0 0 0</pose>
			<axis>
				<xyz>-4.0005048569493725e-11 -0.9999999999999992 -3.5821318751520816e-10</xyz>
				<limit>
					<lower>-1.5707963267948966</lower>
					<upper>1.5707963267948966</upper>
				</limit>
				<use_parent_model_frame>0</use_parent_model_frame>
			</axis>
		</joint>
		<joint name="joint_knee_right" type="revolute">
			<parent>thigh_right</parent>
			<child>shin_right</child>
			<pose frame="">0.004905032360376229 0.16633041890679576 0.7460194098405947 0 0 0</pose>
			<axis>
				<xyz>-9.381143421488636e-11 -0.9999999999999992 1.5947454821937697e-10</xyz>
				<limit>
					<lower>0.0</lower>
					<upper>1.5707963267948966</upper>
				</limit>
				<use_parent_model_frame>0</use_parent_model_frame>
			</axis>
		</joint>
	</model>
</sdf>
