<sdf version="1.6">
	<model name="biking_legs4">
		<link name="bike">
			<self_collide>false</self_collide>
			<pose frame="">-1.3108998963673458e-07 2.442664557200658e-07 0.2700101774980866 0.0 -0.0 0.0</pose>
			<inertial>
				<pose frame="">0.0 0.0 0.0 0 0 0</pose>
				<mass>210.72189156161177</mass>
				<inertia>
					<ixx>13.210732611947313</ixx>
					<ixy>0.06448842844444229</ixy>
					<ixz>-3.8148480022010607</ixz>
					<iyy>17.21745042738023</iyy>
					<iyz>0.18787381325742142</iyz>
					<izz>4.594819100094859</izz>
				</inertia>
			</inertial>
			<collision name="bike_collision">
				<geometry>
					<mesh>
						<uri>model://biking_legs4/meshes/CAD/bike.stl</uri>
						<scale>0.001 0.001 0.001</scale>
					</mesh>
				</geometry>
			</collision>
			<visual name="bike_visual">
				<geometry>
					<mesh>
						<uri>model://biking_legs4/meshes/CAD/bike.stl</uri>
						<scale>0.001 0.001 0.001</scale>
					</mesh>
				</geometry>
			</visual>
		</link>
		<link name="shin_right">
			<self_collide>false</self_collide>
			<pose frame="">-0.0063256371104604605 0.18421764204933005 0.568858834969024 0.0 -0.0 0.0</pose>
			<inertial>
				<pose frame="">0.0 0.0 0.0 0 0 0</pose>
				<mass>5.457514487708465</mass>
				<inertia>
					<ixx>1.9770694176698544</ixx>
					<ixy>0.006663404849912148</ixy>
					<ixz>0.02511819475419638</ixz>
					<iyy>1.7970480130741293</iyy>
					<iyz>-0.5750770999851212</iyz>
					<izz>0.1994726840423078</izz>
				</inertia>
			</inertial>
			<collision name="shin_right_collision">
				<geometry>
					<mesh>
						<uri>model://biking_legs4/meshes/collisions/shin_right.stl</uri>
						<scale>0.001 0.001 0.001</scale>
					</mesh>
				</geometry>
			</collision>
			<visual name="shin_right_visual">
				<geometry>
					<mesh>
						<uri>model://biking_legs4/meshes/visuals/shin_right.stl</uri>
						<scale>0.001 0.001 0.001</scale>
					</mesh>
				</geometry>
			</visual>
		</link>
		<link name="thigh_right">
			<self_collide>false</self_collide>
			<pose frame="">0.1862595860003447 0.18587398019020937 0.7685760508755936 0.0 -0.0 0.0</pose>
			<inertial>
				<pose frame="">0.0 0.0 0.0 0 0 0</pose>
				<mass>5.12210094946444</mass>
				<inertia>
					<ixx>3.214312035063571</ixx>
					<ixy>-0.17990981821610683</ixy>
					<ixz>-0.7330825662113737</ixz>
					<iyy>3.2269620103084056</iyy>
					<iyz>-0.7319872100948264</iyz>
					<izz>0.3750945787467279</izz>
				</inertia>
			</inertial>
			<collision name="thigh_right_collision">
				<geometry>
					<mesh>
						<uri>model://biking_legs4/meshes/collisions/thigh_right.stl</uri>
						<scale>0.001 0.001 0.001</scale>
					</mesh>
				</geometry>
			</collision>
			<visual name="thigh_right_visual">
				<geometry>
					<mesh>
						<uri>model://biking_legs4/meshes/visuals/thigh_right.stl</uri>
						<scale>0.001 0.001 0.001</scale>
					</mesh>
				</geometry>
			</visual>
		</link>
		<link name="thigh_left">
			<self_collide>false</self_collide>
			<pose frame="">0.21151373553713007 -0.21418953444290212 0.7150406378526917 0.0 -0.0 0.0</pose>
			<inertial>
				<pose frame="">0.0 0.0 0.0 0 0 0</pose>
				<mass>5.122037076913526</mass>
				<inertia>
					<ixx>2.866790934327865</ixx>
					<ixy>0.23396782548277809</ixy>
					<ixz>-0.7778947075196168</ixz>
					<iyy>2.8715922556414553</iyy>
					<iyz>0.7862847607155022</iyz>
					<izz>0.4833017473156511</izz>
				</inertia>
			</inertial>
			<collision name="thigh_left_collision">
				<geometry>
					<mesh>
						<uri>model://biking_legs4/meshes/collisions/thigh_left.stl</uri>
						<scale>0.001 0.001 0.001</scale>
					</mesh>
				</geometry>
			</collision>
			<visual name="thigh_left_visual">
				<geometry>
					<mesh>
						<uri>model://biking_legs4/meshes/visuals/thigh_left.stl</uri>
						<scale>0.001 0.001 0.001</scale>
					</mesh>
				</geometry>
			</visual>
		</link>
		<link name="shin_left">
			<self_collide>false</self_collide>
			<pose frame="">0.12625765613172962 -0.21258870028769153 0.4525219675242461 0.0 -0.0 0.0</pose>
			<inertial>
				<pose frame="">0.0 0.0 0.0 0 0 0</pose>
				<mass>5.457551238583219</mass>
				<inertia>
					<ixx>1.3838320047025119</ixx>
					<ixy>0.14439486091111498</ixy>
					<ixz>-0.30378265161641</ixz>
					<iyy>1.235478002951661</iyy>
					<iyz>0.5273938022603756</iyz>
					<izz>0.3540082593095712</izz>
				</inertia>
			</inertial>
			<collision name="shin_left_collision">
				<geometry>
					<mesh>
						<uri>model://biking_legs4/meshes/collisions/shin_left.stl</uri>
						<scale>0.001 0.001 0.001</scale>
					</mesh>
				</geometry>
			</collision>
			<visual name="shin_left_visual">
				<geometry>
					<mesh>
						<uri>model://biking_legs4/meshes/visuals/shin_left.stl</uri>
						<scale>0.001 0.001 0.001</scale>
					</mesh>
				</geometry>
			</visual>
		</link>
		<link name="front_part">
			<self_collide>false</self_collide>
			<pose frame="">-0.7163902611040208 0.010388551714715331 0.48643769332085723 0.0 -0.0 0.0</pose>
			<inertial>
				<pose frame="">0.0 0.0 0.0 0 0 0</pose>
				<mass>16.81067246604605</mass>
				<inertia>
					<ixx>6.39949781835294</ixx>
					<ixy>0.18113615987438006</ixy>
					<ixz>4.493581221870604</ixz>
					<iyy>17.853228424407295</iyy>
					<iyz>-0.05387549209623633</iyz>
					<izz>13.91291969470344</izz>
				</inertia>
			</inertial>
			<collision name="front_part_collision">
				<geometry>
					<mesh>
						<uri>model://biking_legs4/meshes/CAD/front_part.stl</uri>
						<scale>0.001 0.001 0.001</scale>
					</mesh>
				</geometry>
			</collision>
			<visual name="front_part_visual">
				<geometry>
					<mesh>
						<uri>model://biking_legs4/meshes/CAD/front_part.stl</uri>
						<scale>0.001 0.001 0.001</scale>
					</mesh>
				</geometry>
			</visual>
		</link>
		<link name="left_wheel">
			<self_collide>false</self_collide>
			<pose frame="">-0.9984258521253283 -0.3500004088111488 0.3156670000000095 0.0 -0.0 0.0</pose>
			<inertial>
				<pose frame="">0.0 0.0 0.0 0 0 0</pose>
				<mass>13.340163929097853</mass>
				<inertia>
					<ixx>3.472638325579821</ixx>
					<ixy>-4.661713033463341</ixy>
					<ixz>4.20442071234359</ixz>
					<iyy>15.643794956041955</iyy>
					<iyz>1.4738690559763468</iyz>
					<izz>15.441547158388762</izz>
				</inertia>
			</inertial>
			<collision name="left_wheel_collision">
				<geometry>
					<mesh>
						<uri>model://biking_legs4/meshes/CAD/left_wheel.stl</uri>
						<scale>0.001 0.001 0.001</scale>
					</mesh>
				</geometry>
			</collision>
			<visual name="left_wheel_visual">
				<geometry>
					<mesh>
						<uri>model://biking_legs4/meshes/CAD/left_wheel.stl</uri>
						<scale>0.001 0.001 0.001</scale>
					</mesh>
				</geometry>
			</visual>
		</link>
		<link name="right_wheel">
			<self_collide>false</self_collide>
			<pose frame="">-0.998425852125328 0.34200026941711825 0.31566700000003983 0.0 -0.0 0.0</pose>
			<inertial>
				<pose frame="">0.0 0.0 0.0 0 0 0</pose>
				<mass>13.340163929097852</mass>
				<inertia>
					<ixx>3.39878581888478</ixx>
					<ixy>4.555157860544104</ixy>
					<ixz>4.204420712343995</ixz>
					<iyy>15.643794956042205</iyy>
					<iyz>-1.4401800727652248</iyz>
					<izz>15.367694651693462</izz>
				</inertia>
			</inertial>
			<collision name="right_wheel_collision">
				<geometry>
					<mesh>
						<uri>model://biking_legs4/meshes/CAD/right_wheel.stl</uri>
						<scale>0.001 0.001 0.001</scale>
					</mesh>
				</geometry>
			</collision>
			<visual name="right_wheel_visual">
				<geometry>
					<mesh>
						<uri>model://biking_legs4/meshes/CAD/right_wheel.stl</uri>
						<scale>0.001 0.001 0.001</scale>
					</mesh>
				</geometry>
			</visual>
		</link>
		<link name="pedal_right">
			<self_collide>false</self_collide>
			<pose frame="">-0.06793487380186891 0.14428687168043655 0.3404839688900156 0.0 -0.0 0.0</pose>
			<inertial>
				<pose frame="">0.0 0.0 0.0 0 0 0</pose>
				<mass>0.9460025886020129</mass>
				<inertia>
					<ixx>0.12999270422407352</ixx>
					<ixy>0.009272821830067078</ixy>
					<ixz>0.021796750954987426</ixz>
					<iyy>0.1144503006000773</iyy>
					<iyz>-0.046474616096591176</iyz>
					<izz>0.024959186136870388</izz>
				</inertia>
			</inertial>
			<collision name="pedal_right_collision">
				<geometry>
					<mesh>
						<uri>model://biking_legs4/meshes/CAD/pedal_right.stl</uri>
						<scale>0.001 0.001 0.001</scale>
					</mesh>
				</geometry>
			</collision>
			<visual name="pedal_right_visual">
				<geometry>
					<mesh>
						<uri>model://biking_legs4/meshes/CAD/pedal_right.stl</uri>
						<scale>0.001 0.001 0.001</scale>
					</mesh>
				</geometry>
			</visual>
		</link>
		<link name="kurbel">
			<self_collide>false</self_collide>
			<pose frame="">0.09148135511675057 0.00013171801208982688 0.2734782195505036 0.0 -0.0 0.0</pose>
			<inertial>
				<pose frame="">0.0 0.0 0.0 0 0 0</pose>
				<mass>2.783270838110804</mass>
				<inertia>
					<ixx>0.22661192188560456</ixx>
					<ixy>0.011971430323317213</ixy>
					<ixz>-0.06353446718403094</ixz>
					<iyy>0.24931558226077652</iyy>
					<iyz>-0.005032343637373379</iyz>
					<izz>0.05406310500420523</izz>
				</inertia>
			</inertial>
			<collision name="kurbel_collision">
				<geometry>
					<mesh>
						<uri>model://biking_legs4/meshes/CAD/kurbel.stl</uri>
						<scale>0.001 0.001 0.001</scale>
					</mesh>
				</geometry>
			</collision>
			<visual name="kurbel_visual">
				<geometry>
					<mesh>
						<uri>model://biking_legs4/meshes/CAD/kurbel.stl</uri>
						<scale>0.001 0.001 0.001</scale>
					</mesh>
				</geometry>
			</visual>
		</link>
		<link name="pedal_left">
			<self_collide>false</self_collide>
			<pose frame="">0.2545609840138157 -0.15190143553656446 0.21905801526330557 0.0 -0.0 0.0</pose>
			<inertial>
				<pose frame="">0.0 0.0 0.0 0 0 0</pose>
				<mass>0.9460025886020054</mass>
				<inertia>
					<ixx>0.06813109187802759</ixx>
					<ixy>0.03658019733901501</ixy>
					<ixz>-0.052821145723480165</ixz>
					<iyy>0.10711237466637509</iyy>
					<iyz>0.031478450863392446</iyz>
					<izz>0.08374999654697406</izz>
				</inertia>
			</inertial>
			<collision name="pedal_left_collision">
				<geometry>
					<mesh>
						<uri>model://biking_legs4/meshes/CAD/pedal_left.stl</uri>
						<scale>0.001 0.001 0.001</scale>
					</mesh>
				</geometry>
			</collision>
			<visual name="pedal_left_visual">
				<geometry>
					<mesh>
						<uri>model://biking_legs4/meshes/CAD/pedal_left.stl</uri>
						<scale>0.001 0.001 0.001</scale>
					</mesh>
				</geometry>
			</visual>
		</link>
		<link name="foot_left">
			<self_collide>false</self_collide>
			<pose frame="">0.25002870852211506 -0.18809137813494958 0.3354950534254786 0.0 -0.0 0.0</pose>
			<inertial>
				<pose frame="">0.0 0.0 0.0 0 0 0</pose>
				<mass>0.7294059937701884</mass>
				<inertia>
					<ixx>0.10855994490388648</ixx>
					<ixy>0.03430498812805772</ixy>
					<ixz>-0.06120217086529731</ixz>
					<iyy>0.12834563926097742</iyy>
					<iyz>0.046029831467702675</iyz>
					<izz>0.07192832826739815</izz>
				</inertia>
			</inertial>
			<collision name="foot_left_collision">
				<geometry>
					<mesh>
						<uri>model://biking_legs4/meshes/collisions/foot_left.stl</uri>
						<scale>0.001 0.001 0.001</scale>
					</mesh>
				</geometry>
			</collision>
			<visual name="foot_left_visual">
				<geometry>
					<mesh>
						<uri>model://biking_legs4/meshes/visuals/foot_left.stl</uri>
						<scale>0.001 0.001 0.001</scale>
					</mesh>
				</geometry>
			</visual>
		</link>
		<link name="foot_left_tip">
			<self_collide>false</self_collide>
			<pose frame="">0.24068824548388532 -0.1870052467613751 0.23311615508005568 0.0 -0.0 0.0</pose>
			<inertial>
				<pose frame="">0.0 0.0 0.0 0 0 0</pose>
				<mass>0.2779428253746731</mass>
				<inertia>
					<ixx>0.02501358836859939</ixx>
					<ixy>0.012511689013770925</ixy>
					<ixz>-0.015613506066510543</ixz>
					<iyy>0.03132039768625456</iyy>
					<iyz>0.012124820982790076</iyz>
					<izz>0.02590805210984201</izz>
				</inertia>
			</inertial>
			<collision name="foot_left_tip_collision">
				<geometry>
					<mesh>
						<uri>model://biking_legs4/meshes/collisions/foot_left_tip.stl</uri>
						<scale>0.001 0.001 0.001</scale>
					</mesh>
				</geometry>
			</collision>
			<visual name="foot_left_tip_visual">
				<geometry>
					<mesh>
						<uri>model://biking_legs4/meshes/visuals/foot_left_tip.stl</uri>
						<scale>0.001 0.001 0.001</scale>
					</mesh>
				</geometry>
			</visual>
		</link>
		<link name="foot_right">
			<self_collide>false</self_collide>
			<pose frame="">0.04055101337216876 0.15874760369419658 0.40318575410605273 0.0 -0.0 0.0</pose>
			<inertial>
				<pose frame="">0.0 0.0 0.0 0 0 0</pose>
				<mass>0.7293897554334206</mass>
				<inertia>
					<ixx>0.13749112907007022</ixx>
					<ixy>-0.004695647696561905</ixy>
					<ixz>-0.011971297797307915</ixz>
					<iyy>0.12041522046985925</iyy>
					<iyz>-0.04668295464505837</iyz>
					<izz>0.020218750886861314</izz>
				</inertia>
			</inertial>
			<collision name="foot_right_collision">
				<geometry>
					<mesh>
						<uri>model://biking_legs4/meshes/collisions/foot_right.stl</uri>
						<scale>0.001 0.001 0.001</scale>
					</mesh>
				</geometry>
			</collision>
			<visual name="foot_right_visual">
				<geometry>
					<mesh>
						<uri>model://biking_legs4/meshes/visuals/foot_right.stl</uri>
						<scale>0.001 0.001 0.001</scale>
					</mesh>
				</geometry>
			</visual>
		</link>
		<link name="foot_right_tip">
			<self_collide>false</self_collide>
			<pose frame="">-0.053745018929418686 0.15766354239033187 0.36190967760481796 0.0 -0.0 0.0</pose>
			<inertial>
				<pose frame="">0.0 0.0 0.0 0 0 0</pose>
				<mass>0.2779557942466614</mass>
				<inertia>
					<ixx>0.04340883040025374</ixx>
					<ixy>0.0023472133230831847</ixy>
					<ixz>0.005372781400575525</ixz>
					<iyy>0.037322458611376154</iyy>
					<iyz>-0.015862126757666375</iyz>
					<izz>0.00789329505457447</izz>
				</inertia>
			</inertial>
			<collision name="foot_right_tip_collision">
				<geometry>
					<mesh>
						<uri>model://biking_legs4/meshes/collisions/foot_right_tip.stl</uri>
						<scale>0.001 0.001 0.001</scale>
					</mesh>
				</geometry>
			</collision>
			<visual name="foot_right_tip_visual">
				<geometry>
					<mesh>
						<uri>model://biking_legs4/meshes/visuals/foot_right_tip.stl</uri>
						<scale>0.001 0.001 0.001</scale>
					</mesh>
				</geometry>
			</visual>
		</link>
		<link name="wheel_back">
			<self_collide>false</self_collide>
			<pose frame="">0.5368974286036902 0.003549955621292267 0.31941587024902457 0.0 -0.0 0.0</pose>
			<inertial>
				<pose frame="">0.0 0.0 0.0 0 0 0</pose>
				<mass>13.34016392909848</mass>
				<inertia>
					<ixx>1.8703933815675218</ixx>
					<ixy>-0.025425846119325014</ixy>
					<ixz>-2.2877521950726827</ixz>
					<iyy>6.2227778893641625</iyy>
					<iyz>-0.015126574150566754</iyz>
					<izz>4.3547634684642125</izz>
				</inertia>
			</inertial>
			<collision name="wheel_back_collision">
				<geometry>
					<mesh>
						<uri>model://biking_legs4/meshes/CAD/wheel_back.stl</uri>
						<scale>0.001 0.001 0.001</scale>
					</mesh>
				</geometry>
			</collision>
			<visual name="wheel_back_visual">
				<geometry>
					<mesh>
						<uri>model://biking_legs4/meshes/CAD/wheel_back.stl</uri>
						<scale>0.001 0.001 0.001</scale>
					</mesh>
				</geometry>
			</visual>
		</link>
		<joint name="joint_pedal_right" type="revolute">
			<parent>kurbel</parent>
			<child>pedal_right</child>
			<pose frame="">0.0036048056428024024 0.04570241874810934 -0.003782326805427019 0 0 0</pose>
			<axis>
				<xyz>-2.0192365920660242e-17 1.0000000000000016 -1.9344833188838944e-15</xyz>
				<limit>
					<lower>-3141592653589793</lower>
					<upper>3141592653589793</upper>
				</limit>
				<use_parent_model_frame>0</use_parent_model_frame>
			</axis>
		</joint>
		<joint name="joint_pedal_left" type="revolute">
			<parent>kurbel</parent>
			<child>pedal_left</child>
			<pose frame="">-0.0051120796232517664 -0.03934327403489066 -0.009121952908700522 0 0 0</pose>
			<axis>
				<xyz>2.0192365920646832e-17 -1.0 1.9344833188838944e-15</xyz>
				<limit>
					<lower>-3141592653589793</lower>
					<upper>3141592653589793</upper>
				</limit>
				<use_parent_model_frame>0</use_parent_model_frame>
			</axis>
		</joint>
		<joint name="joint_wheel_right" type="revolute">
			<parent>front_part</parent>
			<child>right_wheel</child>
			<pose frame="">4.263256414560601e-16 -0.003999653375198307 5.5067062021407766e-15 0 0 0</pose>
			<axis>
				<xyz>-3.1662288285727846e-30 0.9999999999999998 4.317059530368991e-14</xyz>
				<limit>
					<lower>-3141592653589793</lower>
					<upper>3141592653589793</upper>
				</limit>
				<use_parent_model_frame>0</use_parent_model_frame>
			</axis>
		</joint>
		<joint name="joint_wheel_back" type="revolute">
			<parent>bike</parent>
			<child>wheel_back</child>
			<pose frame="">-2.1316282072803005e-16 -0.0689996533751975 3.552713678800501e-16 0 0 0</pose>
			<axis>
				<xyz>6.938893903907228e-17 1.0 1.27675647831893e-15</xyz>
				<limit>
					<lower>-3141592653589793</lower>
					<upper>3141592653589793</upper>
				</limit>
				<use_parent_model_frame>0</use_parent_model_frame>
			</axis>
		</joint>
		<joint name="joint_pedal" type="revolute">
			<parent>bike</parent>
			<child>kurbel</child>
			<pose frame="">0.0010256624613746545 -0.03513164955582013 -0.0002102674020640194 0 0 0</pose>
			<axis>
				<xyz>-6.938893903907228e-17 1.0 -1.27675647831893e-15</xyz>
				<limit>
					<lower>-3141592653589793</lower>
					<upper>3141592653589793</upper>
				</limit>
				<use_parent_model_frame>0</use_parent_model_frame>
			</axis>
		</joint>
		<joint name="joint_wheel_left" type="revolute">
			<parent>front_part</parent>
			<child>left_wheel</child>
			<pose frame="">7.105427357601002e-16 0.04600034662480176 7.567280135845067e-15 0 0 0</pose>
			<axis>
				<xyz>3.1662288285727846e-30 0.9999999999999998 -4.317059530368991e-14</xyz>
				<limit>
					<lower>-3141592653589793</lower>
					<upper>3141592653589793</upper>
				</limit>
				<use_parent_model_frame>0</use_parent_model_frame>
			</axis>
		</joint>
		<joint name="joint_front" type="fixed">
			<parent>bike</parent>
			<child>front_part</child>
			<pose frame="">-0.23003546775109895 -0.010388307448302651 -0.2052706951041601 0 0 0</pose>
			<axis>
				<xyz>5.345642609144017e-16 -4.084397910750052e-14 1.0</xyz>
				<limit>
					<lower>-0.5235987755982988</lower>
					<upper>0.5235987755982988</upper>
				</limit>
				<use_parent_model_frame>0</use_parent_model_frame>
			</axis>
		</joint>
		<joint name="joint_foot_pedal_left" type="prismatic">
			<parent>pedal_left</parent>
			<child>foot_left_tip</child>
			<pose frame="">0.0022583321423718774 -0.006896188774807932 -0.011400401282428519 0 0 0</pose>
			<axis>
				<xyz>0.2208882077273956 -3.56136801142622e-10 0.9752991334390587</xyz>
				<limit>
					<lower>0.0</lower>
					<upper>0.0</upper>
				</limit>
				<use_parent_model_frame>0</use_parent_model_frame>
			</axis>
		</joint>
		<joint name="joint_foot_pedal_right" type="prismatic">
			<parent>pedal_right</parent>
			<child>foot_right_tip</child>
			<pose frame="">-0.0017824374790778208 0.028623329282097033 -0.005437768723704792 0 0 0</pose>
			<axis>
				<xyz>-0.9606852191301636 1.2790581221833604e-10 -0.2776398922071984</xyz>
				<limit>
					<lower>0.0</lower>
					<upper>0.0</upper>
				</limit>
				<use_parent_model_frame>0</use_parent_model_frame>
			</axis>
		</joint>
		<joint name="joint_foot_left" type="revolute">
			<parent>shin_left</parent>
			<child>foot_left</child>
			<pose frame="">-0.0246250044999935 0.02391937832372481 0.007958528079696877 0 0 0</pose>
			<axis>
				<xyz>1.1348637627011487e-10 1.0000000000000002 3.3930920877038484e-10</xyz>
				<limit>
					<lower>-1.2217304763960306</lower>
					<upper>1.2217304763960306</upper>
				</limit>
				<use_parent_model_frame>0</use_parent_model_frame>
			</axis>
		</joint>
		<joint name="joint_foot_left_tip" type="fixed">
			<parent>foot_left</parent>
			<child>foot_left_tip</child>
			<pose frame="">0.004934971119184866 -0.0011667530284586647 0.04116249373981916 0 0 0</pose>
		</joint>
		<joint name="joint_foot_right" type="revolute">
			<parent>shin_right</parent>
			<child>foot_right</child>
			<pose frame="">-0.005060773092868853 0.024080396413696425 0.025391087916722697 0 0 0</pose>
			<axis>
				<xyz>-1.4207596386472318e-11 0.9999999999999973 5.098502300992556e-10</xyz>
				<limit>
					<lower>-1.2217304763960306</lower>
					<upper>1.2217304763960306</upper>
				</limit>
				<use_parent_model_frame>0</use_parent_model_frame>
			</axis>
		</joint>
		<joint name="joint_foot_right_tip" type="fixed">
			<parent>foot_right</parent>
			<child>foot_right_tip</child>
			<pose frame="">0.03842948663111095 0.0011644577429004244 0.015551868527111523 0 0 0</pose>
		</joint>
		<joint name="joint_knee_right" type="revolute">
			<parent>thigh_right</parent>
			<child>shin_right</child>
			<pose frame="">-0.015102164074851017 -0.02138964207676139 0.1828007131827338 0 0 0</pose>
			<axis>
				<xyz>4.7132319394947356e-12 0.9999999999999989 -4.747102699329492e-10</xyz>
				<limit>
					<lower>-6.28</lower>
					<upper>6.28</upper>
				</limit>
				<use_parent_model_frame>0</use_parent_model_frame>
			</axis>
		</joint>
		<joint name="joint_hip_left" type="revolute">
			<parent>bike</parent>
			<child>thigh_left</child>
			<pose frame="">0.11348498690040117 0.030017534389402557 0.09497402434167526 0 0 0</pose>
			<axis>
				<xyz>4.713515162669238e-12 -0.9999999999999984 -4.747101598323789e-10</xyz>
				<limit>
					<lower>-6.14</lower>
					<upper>6.14</upper>
				</limit>
				<use_parent_model_frame>0</use_parent_model_frame>
			</axis>
		</joint>
		<joint name="joint_knee_left" type="revolute">
			<parent>thigh_left</parent>
			<child>shin_left</child>
			<pose frame="">-0.09452786813394166 0.02841670032794614 0.1570841558563722 0 0 0</pose>
			<axis>
				<xyz>4.713573455708269e-12 -0.9999999999999983 -4.747102669537604e-10</xyz>
				<limit>
					<lower>-6.28</lower>
					<upper>6.28</upper>
				</limit>
				<use_parent_model_frame>0</use_parent_model_frame>
			</axis>
		</joint>
		<joint name="joint_hip_right" type="revolute">
			<parent>bike</parent>
			<child>thigh_right</child>
			<pose frame="">0.13773932727967567 -0.02304598024370531 0.04141907557226745 0 0 0</pose>
			<axis>
				<xyz>4.713392143410444e-12 -0.9999999999999977 -4.747101326464687e-10</xyz>
				<limit>
					<lower>-6.14</lower>
					<upper>6.14</upper>
				</limit>
				<use_parent_model_frame>0</use_parent_model_frame>
			</axis>
		</joint>
		<plugin filename="libcardsflow_gazebo_plugin.so" name="cardsflow_gazebo_plugin" />
	</model>
</sdf>