<robot name="biking_legs4">
  <joint name="joint_pedal_right" type="revolute">
    <parent link="kurbel" />
    <child link="pedal_right" />
    <origin rpy="0 0 0" xyz="-0.15683  0.22498  0.06343" />
    <axis xyz="0 1 0" />
    <limit effort="0.0" lower="-3.14159265359e+15" upper="3.14159265359e+15" velocity="0.0" />
  </joint>
  <joint name="joint_pedal_left" type="revolute">
    <parent link="kurbel" />
    <child link="pedal_left" />
    <origin rpy="0 0 0" xyz="0.15694 -0.15624 -0.06333" />
    <axis xyz="0 -1  0" />
    <limit effort="0.0" lower="-3.14159265359e+15" upper="3.14159265359e+15" velocity="0.0" />
  </joint>
  <joint name="joint_wheel_right" type="revolute">
    <parent link="front_part" />
    <child link="right_wheel" />
    <origin rpy="0 0 0" xyz="-0.052   0.338   0.0345" />
    <axis xyz="0 1 0" />
    <limit effort="0.0" lower="-3.14159265359e+15" upper="3.14159265359e+15" velocity="0.0" />
  </joint>
  <joint name="joint_wheel_back" type="revolute">
    <parent link="bike" />
    <child link="wheel_back" />
    <origin rpy="0 0 0" xyz="0.53689 -0.06544  0.31941" />
    <axis xyz="0 1 0" />
    <limit effort="0.0" lower="-3.14159265359e+15" upper="3.14159265359e+15" velocity="0.0" />
  </joint>
  <joint name="joint_pedal" type="revolute">
    <parent link="bike" />
    <child link="kurbel" />
    <origin rpy="0 0 0" xyz="0.0925  -0.035    0.27326" />
    <axis xyz="0 1 0" />
    <limit effort="0.0" lower="-3.14159265359e+15" upper="3.14159265359e+15" velocity="0.0" />
  </joint>
  <joint name="joint_wheel_left" type="revolute">
    <parent link="front_part" />
    <child link="left_wheel" />
    <origin rpy="0 0 0" xyz="-0.052  -0.304   0.0345" />
    <axis xyz="0 1 0" />
    <limit effort="0.0" lower="-3.14159265359e+15" upper="3.14159265359e+15" velocity="0.0" />
  </joint>
  <joint name="joint_front" type="fixed">
    <parent link="bike" />
    <child link="front_part" />
    <origin rpy="0 0 0" xyz="-0.94642  0       0.28116" />
    <axis xyz="0 0 1" />
    <limit effort="0.0" lower="-0.523598775598" upper="0.523598775598" velocity="0.0" />
  </joint>
  <joint name="joint_foot_pedal_left" type="prismatic">
    <parent link="pedal_left" />
    <child link="foot_left_tip" />
    <origin rpy="0 0 0" xyz="-0.0065  -0.00265  0.01178" />
    <axis xyz="0.22088 0      0.97529" />
    <limit effort="0.0" lower="0.0" upper="0.0" velocity="0.0" />
  </joint>
  <joint name="joint_foot_pedal_right" type="prismatic">
    <parent link="pedal_right" />
    <child link="foot_right_tip" />
    <origin rpy="0 0 0" xyz="0.0088  -0.0037   0.01977" />
    <axis xyz="-0.96068  0      -0.27764" />
    <limit effort="0.0" lower="0.0" upper="0.0" velocity="0.0" />
  </joint>
  <joint name="joint_foot_left" type="revolute">
    <parent link="shin_left" />
    <child link="foot_left" />
    <origin rpy="0 0 0" xyz="0.19367  0.02    -0.26615" />
    <axis xyz="0 1 0" />
    <limit effort="0.0" lower="-1.2217304764" upper="1.2217304764" velocity="0.0" />
  </joint>
  <joint name="joint_foot_left_tip" type="fixed">
    <parent link="foot_left" />
    <child link="foot_left_tip" />
    <origin rpy="0 0 0" xyz="0.02021 -0.024   -0.06917" />
    <axis xyz="0 0 0" />
    <limit effort="0" lower="0" upper="0" velocity="0" />
  </joint>
  <joint name="joint_foot_right" type="revolute">
    <parent link="shin_right" />
    <child link="foot_right" />
    <origin rpy="0 0 0" xyz="0.05691  0.02    -0.32308" />
    <axis xyz="0 1 0" />
    <limit effort="0.0" lower="-1.2217304764" upper="1.2217304764" velocity="0.0" />
  </joint>
  <joint name="joint_foot_right_tip" type="fixed">
    <parent link="foot_right" />
    <child link="foot_right_tip" />
    <origin rpy="0 0 0" xyz="-0.0508  -0.024   -0.05111" />
    <axis xyz="0 0 0" />
    <limit effort="0" lower="0" upper="0" velocity="0" />
  </joint>
  <joint name="joint_knee_right" type="revolute">
    <parent link="thigh_right" />
    <child link="shin_right" />
    <origin rpy="0 0 0" xyz="-0.34542  0      -0.05833" />
    <axis xyz="0 1 0" />
    <limit effort="0.0" lower="-6.28" upper="6.28" velocity="0.0" />
  </joint>
  <joint name="joint_hip_left" type="revolute">
    <parent link="bike" />
    <child link="thigh_left" />
    <origin rpy="0 0 0" xyz="0.32499 -0.18417  0.81001" />
    <axis xyz="0 -1  0" />
    <limit effort="0.0" lower="-6.14" upper="6.14" velocity="0.0" />
  </joint>
  <joint name="joint_knee_left" type="revolute">
    <parent link="thigh_left" />
    <child link="shin_left" />
    <origin rpy="0 0 0" xyz="-0.29326  0      -0.2004" />
    <axis xyz="0 -1  0" />
    <limit effort="0.0" lower="-6.28" upper="6.28" velocity="0.0" />
  </joint>
  <joint name="joint_hip_right" type="revolute">
    <parent link="bike" />
    <child link="thigh_right" />
    <origin rpy="0 0 0" xyz="0.32399 0.16282 0.80999" />
    <axis xyz="0 -1  0" />
    <limit effort="0.0" lower="-6.14" upper="6.14" velocity="0.0" />
  </joint>
  <link name="bike">
    <inertial>
      <mass value="210.72189156161177" />
      <origin rpy="0 0 0" xyz="0   0   0.27" />
      <inertia ixx="13.210732611947313" ixy="0.06448842844444229" ixz="-3.8148480022010607" iyy="17.21745042738023" iyz="0.18787381325742142" izz="4.594819100094859" />
    </inertial>
    <collision name="bike_collision">
      <origin rpy="0 0 0" xyz="0   0   0.27" />
      <geometry>
        <mesh filename="package://robots/biking_legs4/meshes/collisions/bike.stl" scale="0.001 0.001 0.001" />
      </geometry>
    </collision>
    <visual name="bike_visual">
      <origin rpy="0 0 0" xyz="0   0   0.27" />
      <geometry>
        <mesh filename="package://robots/biking_legs4/meshes/visuals/bike.stl" scale="0.001 0.001 0.001" />
      </geometry>
    </visual>
  </link>
  <link name="shin_right">
    <inertial>
      <mass value="5.457514487708465" />
      <origin rpy="0 0 0" xyz="0.0151   0.02139 -0.1828" />
      <inertia ixx="1.9770694176698544" ixy="0.006663404849912148" ixz="0.02511819475419638" iyy="1.7970480130741293" iyz="-0.5750770999851212" izz="0.1994726840423078" />
    </inertial>
    <collision name="shin_right_collision">
      <origin rpy="0 0 0" xyz="0.0151   0.02139 -0.1828" />
      <geometry>
        <mesh filename="package://robots/biking_legs4/meshes/collisions/shin_right.stl" scale="0.001 0.001 0.001" />
      </geometry>
    </collision>
    <visual name="shin_right_visual">
      <origin rpy="0 0 0" xyz="0.0151   0.02139 -0.1828" />
      <geometry>
        <mesh filename="package://robots/biking_legs4/meshes/visuals/shin_right.stl" scale="0.001 0.001 0.001" />
      </geometry>
    </visual>
  </link>
  <link name="thigh_right">
    <inertial>
      <mass value="5.12210094946444" />
      <origin rpy="0 0 0" xyz="-0.13773  0.02304 -0.04141" />
      <inertia ixx="3.214312035063571" ixy="-0.17990981821610683" ixz="-0.7330825662113737" iyy="3.2269620103084056" iyz="-0.7319872100948264" izz="0.3750945787467279" />
    </inertial>
    <collision name="thigh_right_collision">
      <origin rpy="0 0 0" xyz="-0.13773  0.02304 -0.04141" />
      <geometry>
        <mesh filename="package://robots/biking_legs4/meshes/collisions/thigh_right.stl" scale="0.001 0.001 0.001" />
      </geometry>
    </collision>
    <visual name="thigh_right_visual">
      <origin rpy="0 0 0" xyz="-0.13773  0.02304 -0.04141" />
      <geometry>
        <mesh filename="package://robots/biking_legs4/meshes/visuals/thigh_right.stl" scale="0.001 0.001 0.001" />
      </geometry>
    </visual>
  </link>
  <link name="thigh_left">
    <inertial>
      <mass value="5.122037076913526" />
      <origin rpy="0 0 0" xyz="-0.11348 -0.03001 -0.09497" />
      <inertia ixx="2.866790934327865" ixy="0.23396782548277809" ixz="-0.7778947075196168" iyy="2.8715922556414553" iyz="0.7862847607155022" izz="0.4833017473156511" />
    </inertial>
    <collision name="thigh_left_collision">
      <origin rpy="0 0 0" xyz="-0.11348 -0.03001 -0.09497" />
      <geometry>
        <mesh filename="package://robots/biking_legs4/meshes/collisions/thigh_left.stl" scale="0.001 0.001 0.001" />
      </geometry>
    </collision>
    <visual name="thigh_left_visual">
      <origin rpy="0 0 0" xyz="-0.11348 -0.03001 -0.09497" />
      <geometry>
        <mesh filename="package://robots/biking_legs4/meshes/visuals/thigh_left.stl" scale="0.001 0.001 0.001" />
      </geometry>
    </visual>
  </link>
  <link name="shin_left">
    <inertial>
      <mass value="5.457551238583219" />
      <origin rpy="0 0 0" xyz="0.09452 -0.02841 -0.15708" />
      <inertia ixx="1.3838320047025119" ixy="0.14439486091111498" ixz="-0.30378265161641" iyy="1.235478002951661" iyz="0.5273938022603756" izz="0.3540082593095712" />
    </inertial>
    <collision name="shin_left_collision">
      <origin rpy="0 0 0" xyz="0.09452 -0.02841 -0.15708" />
      <geometry>
        <mesh filename="package://robots/biking_legs4/meshes/collisions/shin_left.stl" scale="0.001 0.001 0.001" />
      </geometry>
    </collision>
    <visual name="shin_left_visual">
      <origin rpy="0 0 0" xyz="0.09452 -0.02841 -0.15708" />
      <geometry>
        <mesh filename="package://robots/biking_legs4/meshes/visuals/shin_left.stl" scale="0.001 0.001 0.001" />
      </geometry>
    </visual>
  </link>
  <link name="front_part">
    <inertial>
      <mass value="16.81067246604605" />
      <origin rpy="0 0 0" xyz="0.23003 0.01038 0.20527" />
      <inertia ixx="6.39949781835294" ixy="0.18113615987438006" ixz="4.493581221870604" iyy="17.853228424407295" iyz="-0.05387549209623633" izz="13.91291969470344" />
    </inertial>
    <collision name="front_part_collision">
      <origin rpy="0 0 0" xyz="0.23003 0.01038 0.20527" />
      <geometry>
        <mesh filename="package://robots/biking_legs4/meshes/collisions/front_part.stl" scale="0.001 0.001 0.001" />
      </geometry>
    </collision>
    <visual name="front_part_visual">
      <origin rpy="0 0 0" xyz="0.23003 0.01038 0.20527" />
      <geometry>
        <mesh filename="package://robots/biking_legs4/meshes/visuals/front_part.stl" scale="0.001 0.001 0.001" />
      </geometry>
    </visual>
  </link>
  <link name="left_wheel">
    <inertial>
      <mass value="13.340163929097853" />
      <origin rpy="0 0 0" xyz="0    -0.046  0" />
      <inertia ixx="3.472638325579821" ixy="-4.661713033463341" ixz="4.20442071234359" iyy="15.643794956041955" iyz="1.4738690559763468" izz="15.441547158388762" />
    </inertial>
    <collision name="left_wheel_collision">
      <origin rpy="0 0 0" xyz="0    -0.046  0" />
      <geometry>
        <mesh filename="package://robots/biking_legs4/meshes/collisions/left_wheel.stl" scale="0.001 0.001 0.001" />
      </geometry>
    </collision>
    <visual name="left_wheel_visual">
      <origin rpy="0 0 0" xyz="0    -0.046  0" />
      <geometry>
        <mesh filename="package://robots/biking_legs4/meshes/visuals/left_wheel.stl" scale="0.001 0.001 0.001" />
      </geometry>
    </visual>
  </link>
  <link name="right_wheel">
    <inertial>
      <mass value="13.340163929097852" />
      <origin rpy="0 0 0" xyz="0    0.004 0" />
      <inertia ixx="3.39878581888478" ixy="4.555157860544104" ixz="4.204420712343995" iyy="15.643794956042205" iyz="-1.4401800727652248" izz="15.367694651693462" />
    </inertial>
    <collision name="right_wheel_collision">
      <origin rpy="0 0 0" xyz="0    0.004 0" />
      <geometry>
        <mesh filename="package://robots/biking_legs4/meshes/collisions/right_wheel.stl" scale="0.001 0.001 0.001" />
      </geometry>
    </collision>
    <visual name="right_wheel_visual">
      <origin rpy="0 0 0" xyz="0    0.004 0" />
      <geometry>
        <mesh filename="package://robots/biking_legs4/meshes/visuals/right_wheel.stl" scale="0.001 0.001 0.001" />
      </geometry>
    </visual>
  </link>
  <link name="pedal_right">
    <inertial>
      <mass value="0.9460025886020129" />
      <origin rpy="0 0 0" xyz="-0.0036  -0.0457   0.00378" />
      <inertia ixx="0.12999270422407352" ixy="0.009272821830067078" ixz="0.021796750954987426" iyy="0.1144503006000773" iyz="-0.046474616096591176" izz="0.024959186136870388" />
    </inertial>
    <collision name="pedal_right_collision">
      <origin rpy="0 0 0" xyz="-0.0036  -0.0457   0.00378" />
      <geometry>
        <mesh filename="package://robots/biking_legs4/meshes/collisions/pedal_right.stl" scale="0.001 0.001 0.001" />
      </geometry>
    </collision>
    <visual name="pedal_right_visual">
      <origin rpy="0 0 0" xyz="-0.0036  -0.0457   0.00378" />
      <geometry>
        <mesh filename="package://robots/biking_legs4/meshes/visuals/pedal_right.stl" scale="0.001 0.001 0.001" />
      </geometry>
    </visual>
  </link>
  <link name="kurbel">
    <inertial>
      <mass value="2.783270838110804" />
      <origin rpy="0 0 0" xyz="-0.00102  0.03513  0.00021" />
      <inertia ixx="0.22661192188560456" ixy="0.011971430323317213" ixz="-0.06353446718403094" iyy="0.24931558226077652" iyz="-0.005032343637373379" izz="0.05406310500420523" />
    </inertial>
    <collision name="kurbel_collision">
      <origin rpy="0 0 0" xyz="-0.00102  0.03513  0.00021" />
      <geometry>
        <mesh filename="package://robots/biking_legs4/meshes/collisions/kurbel.stl" scale="0.001 0.001 0.001" />
      </geometry>
    </collision>
    <visual name="kurbel_visual">
      <origin rpy="0 0 0" xyz="-0.00102  0.03513  0.00021" />
      <geometry>
        <mesh filename="package://robots/biking_legs4/meshes/visuals/kurbel.stl" scale="0.001 0.001 0.001" />
      </geometry>
    </visual>
  </link>
  <link name="pedal_left">
    <inertial>
      <mass value="0.9460025886020054" />
      <origin rpy="0 0 0" xyz="0.00511 0.03934 0.00912" />
      <inertia ixx="0.06813109187802759" ixy="0.03658019733901501" ixz="-0.052821145723480165" iyy="0.10711237466637509" iyz="0.031478450863392446" izz="0.08374999654697406" />
    </inertial>
    <collision name="pedal_left_collision">
      <origin rpy="0 0 0" xyz="0.00511 0.03934 0.00912" />
      <geometry>
        <mesh filename="package://robots/biking_legs4/meshes/collisions/pedal_left.stl" scale="0.001 0.001 0.001" />
      </geometry>
    </collision>
    <visual name="pedal_left_visual">
      <origin rpy="0 0 0" xyz="0.00511 0.03934 0.00912" />
      <geometry>
        <mesh filename="package://robots/biking_legs4/meshes/visuals/pedal_left.stl" scale="0.001 0.001 0.001" />
      </geometry>
    </visual>
  </link>
  <link name="foot_left">
    <inertial>
      <mass value="0.7294059937701884" />
      <origin rpy="0 0 0" xyz="0.02462 -0.02391 -0.00795" />
      <inertia ixx="0.10855994490388648" ixy="0.03430498812805772" ixz="-0.06120217086529731" iyy="0.12834563926097742" iyz="0.046029831467702675" izz="0.07192832826739815" />
    </inertial>
    <collision name="foot_left_collision">
      <origin rpy="0 0 0" xyz="0.02462 -0.02391 -0.00795" />
      <geometry>
        <mesh filename="package://robots/biking_legs4/meshes/collisions/foot_left.stl" scale="0.001 0.001 0.001" />
      </geometry>
    </collision>
    <visual name="foot_left_visual">
      <origin rpy="0 0 0" xyz="0.02462 -0.02391 -0.00795" />
      <geometry>
        <mesh filename="package://robots/biking_legs4/meshes/visuals/foot_left.stl" scale="0.001 0.001 0.001" />
      </geometry>
    </visual>
  </link>
  <link name="foot_left_tip">
    <inertial>
      <mass value="0.2779428253746731" />
      <origin rpy="0 0 0" xyz="-0.00493  0.00116 -0.04116" />
      <inertia ixx="0.02501358836859939" ixy="0.012511689013770925" ixz="-0.015613506066510543" iyy="0.03132039768625456" iyz="0.012124820982790076" izz="0.02590805210984201" />
    </inertial>
    <collision name="foot_left_tip_collision">
      <origin rpy="0 0 0" xyz="-0.00493  0.00116 -0.04116" />
      <geometry>
        <mesh filename="package://robots/biking_legs4/meshes/collisions/foot_left_tip.stl" scale="0.001 0.001 0.001" />
      </geometry>
    </collision>
    <visual name="foot_left_tip_visual">
      <origin rpy="0 0 0" xyz="-0.00493  0.00116 -0.04116" />
      <geometry>
        <mesh filename="package://robots/biking_legs4/meshes/visuals/foot_left_tip.stl" scale="0.001 0.001 0.001" />
      </geometry>
    </visual>
  </link>
  <link name="foot_right">
    <inertial>
      <mass value="0.7293897554334206" />
      <origin rpy="0 0 0" xyz="0.00506 -0.02408 -0.02539" />
      <inertia ixx="0.13749112907007022" ixy="-0.004695647696561905" ixz="-0.011971297797307915" iyy="0.12041522046985925" iyz="-0.04668295464505837" izz="0.020218750886861314" />
    </inertial>
    <collision name="foot_right_collision">
      <origin rpy="0 0 0" xyz="0.00506 -0.02408 -0.02539" />
      <geometry>
        <mesh filename="package://robots/biking_legs4/meshes/collisions/foot_right.stl" scale="0.001 0.001 0.001" />
      </geometry>
    </collision>
    <visual name="foot_right_visual">
      <origin rpy="0 0 0" xyz="0.00506 -0.02408 -0.02539" />
      <geometry>
        <mesh filename="package://robots/biking_legs4/meshes/visuals/foot_right.stl" scale="0.001 0.001 0.001" />
      </geometry>
    </visual>
  </link>
  <link name="foot_right_tip">
    <inertial>
      <mass value="0.2779557942466614" />
      <origin rpy="0 0 0" xyz="-0.03842 -0.00116 -0.01555" />
      <inertia ixx="0.04340883040025374" ixy="0.0023472133230831847" ixz="0.005372781400575525" iyy="0.037322458611376154" iyz="-0.015862126757666375" izz="0.00789329505457447" />
    </inertial>
    <collision name="foot_right_tip_collision">
      <origin rpy="0 0 0" xyz="-0.03842 -0.00116 -0.01555" />
      <geometry>
        <mesh filename="package://robots/biking_legs4/meshes/collisions/foot_right_tip.stl" scale="0.001 0.001 0.001" />
      </geometry>
    </collision>
    <visual name="foot_right_tip_visual">
      <origin rpy="0 0 0" xyz="-0.03842 -0.00116 -0.01555" />
      <geometry>
        <mesh filename="package://robots/biking_legs4/meshes/visuals/foot_right_tip.stl" scale="0.001 0.001 0.001" />
      </geometry>
    </visual>
  </link>
  <link name="wheel_back">
    <inertial>
      <mass value="13.34016392909848" />
      <origin rpy="0 0 0" xyz="0    0.069 0" />
      <inertia ixx="1.8703933815675218" ixy="-0.025425846119325014" ixz="-2.2877521950726827" iyy="6.2227778893641625" iyz="-0.015126574150566754" izz="4.3547634684642125" />
    </inertial>
    <collision name="wheel_back_collision">
      <origin rpy="0 0 0" xyz="0    0.069 0" />
      <geometry>
        <mesh filename="package://robots/biking_legs4/meshes/collisions/wheel_back.stl" scale="0.001 0.001 0.001" />
      </geometry>
    </collision>
    <visual name="wheel_back_visual">
      <origin rpy="0 0 0" xyz="0    0.069 0" />
      <geometry>
        <mesh filename="package://robots/biking_legs4/meshes/visuals/wheel_back.stl" scale="0.001 0.001 0.001" />
      </geometry>
    </visual>
  </link>
</robot>