<robot name="roboy_head">
  <joint name="zed_camera_mount" type="fixed">
    <parent link="head" />
    <child link="zed_camera" />
    <origin rpy="0  0  0" xyz="0.02168 -0.05805  0.21956" />
    <axis xyz="0  0  0" />
    <limit effort="0" lower="0" upper="0" velocity="0" />
  </joint>
  <joint name="zed_camera_right" type="fixed">
    <parent link="zed_camera" />
    <child link="zed_camera_right_lense" />
    <origin rpy="0  0  0" xyz="-0.08149 -0.00191 -0.00782" />
    <axis xyz="0  0  0" />
    <limit effort="0" lower="0" upper="0" velocity="0" />
  </joint>
  <joint name="zed_camera_left" type="fixed">
    <parent link="zed_camera" />
    <child link="zed_camera_left_lense" />
    <origin rpy="0  0  0" xyz="0.03848 -0.00154 -0.00782" />
    <axis xyz="0  0  0" />
    <limit effort="0" lower="0" upper="0" velocity="0" />
  </joint>
  <joint name="sphere_head_axis0" type="revolute">
    <parent link="neck" />
    <child link="sphere_head_link1" />
    <origin rpy="0  0  0" xyz="0       0       0.06647" />
    <axis xyz="0.12498 -0.99215  0" />
    <limit effort="0.0" lower="-0.523598775598" upper="0.523598775598" velocity="0.0" />
  </joint>
  <joint name="sphere_head_axis2" type="revolute">
    <parent link="sphere_head_link2" />
    <child link="head" />
    <origin rpy="0  0  0" xyz="0  0  0" />
    <axis xyz="0  0  1" />
    <limit effort="0.0" lower="-0.523598775598" upper="0.523598775598" velocity="0.0" />
  </joint>
  <joint name="sphere_head_axis1" type="revolute">
    <parent link="sphere_head_link1" />
    <child link="sphere_head_link2" />
    <origin rpy="0  0  0" xyz="0  0  0" />
    <axis xyz="-0.99215 -0.12498  0" />
    <limit effort="0.0" lower="-0.523598775598" upper="0.523598775598" velocity="0.0" />
  </joint>
  <link name="neck">
    <inertial>
      <mass value="2.047509117555703" />
      <origin rpy="0  0  0" xyz="0      -0.00917 -0.00389" />
      <inertia ixx="0.004341677472901745" ixy="-1.6639129121508378e-05" ixz="-1.7498428368479703e-06" iyy="0.018826278313584643" iyz="-0.0008482806294713261" izz="0.02114004054636476" />
    </inertial>
    <collision name="neck_collision">
      <origin rpy="0  0  0" xyz="0      -0.00917 -0.00389" />
      <geometry>
        <mesh filename="package://robots/roboy_head/meshes/collisions/neck.stl" scale="0.001 0.001 0.001" />
      </geometry>
    </collision>
    <visual name="neck_visual">
      <origin rpy="0  0  0" xyz="0      -0.00917 -0.00389" />
      <geometry>
        <mesh filename="package://robots/roboy_head/meshes/visuals/neck.stl" scale="0.001 0.001 0.001" />
      </geometry>
    </visual>
  </link>
  <link name="head">
    <inertial>
      <mass value="2.0495737293465486" />
      <origin rpy="0  0  0" xyz="0.00051  0.04492  0.1455" />
      <inertia ixx="0.12852178148572738" ixy="-6.154350123814713e-05" ixz="-0.0003330693074768604" iyy="0.11804794413419654" iyz="-0.022204394459719144" izz="0.030242672185104257" />
    </inertial>
    <collision name="head_collision">
      <origin rpy="0  0  0" xyz="0.00051  0.04492  0.1455" />
      <geometry>
        <mesh filename="package://roboy_models/roboy_head_n1/meshes/collisions/head.stl OR roboy_models/roboy_head/meshes/collisions/head.stl OR robots/roboy_head/meshes/collisions/head.stl" scale="0.001 0.001 0.001" />
      </geometry>
    </collision>
    <visual name="head_visual">
      <origin rpy="0  0  0" xyz="0.00051  0.04492  0.1455" />
      <geometry>
        <mesh filename="package://roboy_models/roboy_head_n1/meshes/visuals/head.stl OR roboy_models/roboy_head/meshes/visuals/head.stl OR robots/roboy_head/meshes/visuals/head.stl" scale="0.001 0.001 0.001" />
      </geometry>
    </visual>
  </link>
  <link name="zed_camera_left_lense">
    <inertial>
      <mass value="0.005755421856391891" />
      <origin rpy="0  0  0" xyz="5.00000000e-05  -1.10700000e-02   2.35000000e-03" />
      <inertia ixx="0.00048221143494491534" ixy="2.449485115264801e-05" ixz="-9.725164857961536e-05" iyy="0.00047416232876470397" iyz="0.0001141566698388886" izz="5.0008392870139496e-05" />
    </inertial>
    <collision name="zed_camera_left_lense_collision">
      <origin rpy="0  0  0" xyz="5.00000000e-05  -1.10700000e-02   2.35000000e-03" />
      <geometry>
        <mesh filename="package://robots/roboy_head/meshes/collisions/zed_camera_left_lense.stl" scale="0.001 0.001 0.001" />
      </geometry>
    </collision>
    <visual name="zed_camera_left_lense_visual">
      <origin rpy="0  0  0" xyz="5.00000000e-05  -1.10700000e-02   2.35000000e-03" />
      <geometry>
        <mesh filename="package://robots/roboy_head/meshes/visuals/zed_camera_left_lense.stl" scale="0.001 0.001 0.001" />
      </geometry>
    </visual>
  </link>
  <link name="zed_camera_right_lense">
    <inertial>
      <mass value="0.005755421855125981" />
      <origin rpy="0  0  0" xyz="3.00000000e-05  -1.10700000e-02   2.35000000e-03" />
      <inertia ixx="0.00048251891666343074" ixy="-2.4441773765426615e-05" ixz="9.653024800471e-05" iyy="0.0004738538988814524" iyz="0.00011476545559992052" izz="5.000744514650461e-05" />
    </inertial>
    <collision name="zed_camera_right_lense_collision">
      <origin rpy="0  0  0" xyz="3.00000000e-05  -1.10700000e-02   2.35000000e-03" />
      <geometry>
        <mesh filename="package://robots/roboy_head/meshes/collisions/zed_camera_right_lense.stl" scale="0.001 0.001 0.001" />
      </geometry>
    </collision>
    <visual name="zed_camera_right_lense_visual">
      <origin rpy="0  0  0" xyz="3.00000000e-05  -1.10700000e-02   2.35000000e-03" />
      <geometry>
        <mesh filename="package://robots/roboy_head/meshes/visuals/zed_camera_right_lense.stl" scale="0.001 0.001 0.001" />
      </geometry>
    </visual>
  </link>
  <link name="zed_camera">
    <inertial>
      <mass value="0.0096339079892267" />
      <origin rpy="0  0  0" xyz="-0.01743 -0.0014  -0.00805" />
      <inertia ixx="0.0007788796926614204" ixy="2.4987610089390115e-06" ixz="-1.1386553970512425e-05" iyy="0.0007596640801931402" iyz="0.0001591957506421817" izz="4.897438830692027e-05" />
    </inertial>
    <collision name="zed_camera_collision">
      <origin rpy="0  0  0" xyz="-0.01743 -0.0014  -0.00805" />
      <geometry>
        <mesh filename="package://robots/roboy_head/meshes/collisions/zed_camera.stl" scale="0.001 0.001 0.001" />
      </geometry>
    </collision>
    <visual name="zed_camera_visual">
      <origin rpy="0  0  0" xyz="-0.01743 -0.0014  -0.00805" />
      <geometry>
        <mesh filename="package://robots/roboy_head/meshes/visuals/zed_camera.stl" scale="0.001 0.001 0.001" />
      </geometry>
    </visual>
  </link>
  <link name="sphere_head_link1">
    <inertial>
      <mass value="0.017038665636260348" />
      <origin rpy="0  0  0" xyz="0  0  0" />
      <inertia ixx="7.641228262717032e-05" ixy="1.1492543028346347e-21" ixz="1.7059836460164845e-13" iyy="7.641228262717034e-05" iyz="1.7060379602085175e-13" izz="1.1107708503000374e-06" />
    </inertial>
    <collision name="sphere_head_link1_collision">
      <origin rpy="0  0  0" xyz="0  0  0" />
      <geometry>
        <mesh filename="package://robots/roboy_head/meshes/collisions/sphere_head_link1.stl" scale="0.001 0.001 0.001" />
      </geometry>
    </collision>
    <visual name="sphere_head_link1_visual">
      <origin rpy="0  0  0" xyz="0  0  0" />
      <geometry>
        <mesh filename="package://robots/roboy_head/meshes/visuals/sphere_head_link1.stl" scale="0.001 0.001 0.001" />
      </geometry>
    </visual>
  </link>
  <link name="sphere_head_link2">
    <inertial>
      <mass value="0.011421521917888844" />
      <origin rpy="0  0  0" xyz="0  0  0" />
      <inertia ixx="5.097860160005369e-05" ixy="-8.456776945386935e-22" ixz="9.69292963167584e-14" iyy="5.097860160005372e-05" iyz="9.69339401281355e-14" izz="5.017693548664116e-07" />
    </inertial>
    <collision name="sphere_head_link2_collision">
      <origin rpy="0  0  0" xyz="0  0  0" />
      <geometry>
        <mesh filename="package://robots/roboy_head/meshes/collisions/sphere_head_link2.stl" scale="0.001 0.001 0.001" />
      </geometry>
    </collision>
    <visual name="sphere_head_link2_visual">
      <origin rpy="0  0  0" xyz="0  0  0" />
      <geometry>
        <mesh filename="package://robots/roboy_head/meshes/visuals/sphere_head_link2.stl" scale="0.001 0.001 0.001" />
      </geometry>
    </visual>
  </link>
</robot>