<sdf version="1.6">
	<model name="roboy_head">
		<link name="neck">
			<self_collide>false</self_collide>
			<pose frame="">-1.8149377975533533e-06 -0.009175044956787616 -0.0038904125653804983 0.0 -0.0 0.0</pose>
			<inertial>
				<pose frame="">0.0 0.0 0.0 0 0 0</pose>
				<mass>2.0475091175557028</mass>
				<inertia>
					<ixx>0.004341677497807102</ixx>
					<ixy>-1.6638576499188376e-05</ixy>
					<ixz>-1.7498429867411458e-06</ixz>
					<iyy>0.01882627831705663</iyy>
					<iyz>-0.0008482805817586748</iyz>
					<izz>0.021140040574742096</izz>
				</inertia>
			</inertial>
			<collision name="neck_collision">
				<geometry>
					<mesh>
						<uri>model://roboy_head/meshes/collisions/neck.stl</uri>
						<scale>0.001 0.001 0.001</scale>
					</mesh>
				</geometry>
			</collision>
			<visual name="neck_visual">
				<geometry>
					<mesh>
						<uri>model://roboy_head/meshes/visuals/neck.stl</uri>
						<scale>0.001 0.001 0.001</scale>
					</mesh>
				</geometry>
			</visual>
		</link>
		<link name="head">
			<self_collide>false</self_collide>
			<pose frame="">0.0005102159779004964 0.044924115008751916 0.211980978747011 0.0 -0.0 0.0</pose>
			<inertial>
				<pose frame="">0.0 0.0 0.0 0 0 0</pose>
				<mass>2.0495737293465406</mass>
				<inertia>
					<ixx>0.1285217814857278</ixx>
					<ixy>-6.15435012381666e-05</ixy>
					<ixz>-0.0003330693074767625</ixz>
					<iyy>0.11804794413419648</iyy>
					<iyz>-0.022204394459719782</iyz>
					<izz>0.030242672185104177</izz>
				</inertia>
			</inertial>
			<collision name="head_collision">
				<geometry>
					<mesh>
						<uri>model://roboy_head/meshes/collisions/head.stl</uri>
						<scale>0.001 0.001 0.001</scale>
					</mesh>
				</geometry>
			</collision>
			<visual name="head_visual">
				<geometry>
					<mesh>
						<uri>model://roboy_head/meshes/visuals/head.stl</uri>
						<scale>0.001 0.001 0.001</scale>
					</mesh>
				</geometry>
			</visual>
		</link>
		<link name="zed_camera_left_lense">
			<self_collide>false</self_collide>
			<pose frame="">0.060224029002960845 -0.07066714719955536 0.2805752876362124 0.0 -0.0 0.0</pose>
			<inertial>
				<pose frame="">0.0 0.0 0.0 0 0 0</pose>
				<mass>0.005755421856391891</mass>
				<inertia>
					<ixx>0.00048221143494491534</ixx>
					<ixy>2.449485115264801e-05</ixy>
					<ixz>-9.725164857961536e-05</ixz>
					<iyy>0.00047416232876470397</iyy>
					<iyz>0.0001141566698388886</iyz>
					<izz>5.0008392870139496e-05</izz>
				</inertia>
			</inertial>
			<collision name="zed_camera_left_lense_collision">
				<geometry>
					<mesh>
						<uri>model://roboy_head/meshes/collisions/zed_camera_left_lense.stl</uri>
						<scale>0.001 0.001 0.001</scale>
					</mesh>
				</geometry>
			</collision>
			<visual name="zed_camera_left_lense_visual">
				<geometry>
					<mesh>
						<uri>model://roboy_head/meshes/visuals/zed_camera_left_lense.stl</uri>
						<scale>0.001 0.001 0.001</scale>
					</mesh>
				</geometry>
			</visual>
		</link>
		<link name="zed_camera_right_lense">
			<self_collide>false</self_collide>
			<pose frame="">-0.05977745584801605 -0.07104414423233865 0.28057528759865397 0.0 -0.0 0.0</pose>
			<inertial>
				<pose frame="">0.0 0.0 0.0 0 0 0</pose>
				<mass>0.005755421855125981</mass>
				<inertia>
					<ixx>0.00048251891666343074</ixx>
					<ixy>-2.4441773765426615e-05</ixy>
					<ixz>9.653024800471e-05</ixz>
					<iyy>0.0004738538988814524</iyy>
					<iyz>0.00011476545559992052</iyz>
					<izz>5.000744514650461e-05</izz>
				</inertia>
			</inertial>
			<collision name="zed_camera_right_lense_collision">
				<geometry>
					<mesh>
						<uri>model://roboy_head/meshes/collisions/zed_camera_right_lense.stl</uri>
						<scale>0.001 0.001 0.001</scale>
					</mesh>
				</geometry>
			</collision>
			<visual name="zed_camera_right_lense_visual">
				<geometry>
					<mesh>
						<uri>model://roboy_head/meshes/visuals/zed_camera_right_lense.stl</uri>
						<scale>0.001 0.001 0.001</scale>
					</mesh>
				</geometry>
			</visual>
		</link>
		<link name="zed_camera">
			<self_collide>false</self_collide>
			<pose frame="">0.0042444847902538396 -0.05946040237166452 0.277995220012499 0.0 -0.0 0.0</pose>
			<inertial>
				<pose frame="">0.0 0.0 0.0 0 0 0</pose>
				<mass>0.0096339079892267</mass>
				<inertia>
					<ixx>0.0007788796926614204</ixx>
					<ixy>2.4987610089390115e-06</ixy>
					<ixz>-1.1386553970512425e-05</ixz>
					<iyy>0.0007596640801931402</iyy>
					<iyz>0.0001591957506421817</iyz>
					<izz>4.897438830692027e-05</izz>
				</inertia>
			</inertial>
			<collision name="zed_camera_collision">
				<geometry>
					<mesh>
						<uri>model://roboy_head/meshes/collisions/zed_camera.stl</uri>
						<scale>0.001 0.001 0.001</scale>
					</mesh>
				</geometry>
			</collision>
			<visual name="zed_camera_visual">
				<geometry>
					<mesh>
						<uri>model://roboy_head/meshes/visuals/zed_camera.stl</uri>
						<scale>0.001 0.001 0.001</scale>
					</mesh>
				</geometry>
			</visual>
		</link>
		<link name="sphere_head_link1">
			<self_collide>false</self_collide>
			<pose frame="">-1.5061049265673543e-10 -1.5061528859084698e-10 0.06647893559374944 0.0 -0.0 0.0</pose>
			<inertial>
				<pose frame="">0.0 0.0 0.0 0 0 0</pose>
				<mass>0.017038665636260344</mass>
				<inertia>
					<ixx>7.641228262717032e-05</ixx>
					<ixy>1.1384122811097797e-21</ixy>
					<ixz>1.7059836425470377e-13</ixz>
					<iyy>7.641228262717034e-05</iyy>
					<iyz>1.706037961943241e-13</iyz>
					<izz>1.1107708503000374e-06</izz>
				</inertia>
			</inertial>
			<collision name="sphere_head_link1_collision">
				<geometry>
					<mesh>
						<uri>model://roboy_head/meshes/collisions/sphere_head_link1.stl</uri>
						<scale>0.001 0.001 0.001</scale>
					</mesh>
				</geometry>
			</collision>
			<visual name="sphere_head_link1_visual">
				<geometry>
					<mesh>
						<uri>model://roboy_head/meshes/visuals/sphere_head_link1.stl</uri>
						<scale>0.001 0.001 0.001</scale>
					</mesh>
				</geometry>
			</visual>
		</link>
		<link name="sphere_head_link2">
			<self_collide>false</self_collide>
			<pose frame="">-1.2765771046916346e-10 -1.276638116636219e-10 0.06647893559374916 0.0 -0.0 0.0</pose>
			<inertial>
				<pose frame="">0.0 0.0 0.0 0 0 0</pose>
				<mass>0.011421521917888844</mass>
				<inertia>
					<ixx>5.097860160005369e-05</ixx>
					<ixy>-8.158621347953421e-22</ixy>
					<ixz>9.692929657696692e-14</ixz>
					<iyy>5.097860160005372e-05</iyy>
					<iyz>9.693393943424612e-14</iyz>
					<izz>5.017693548664116e-07</izz>
				</inertia>
			</inertial>
			<collision name="sphere_head_link2_collision">
				<geometry>
					<mesh>
						<uri>model://roboy_head/meshes/collisions/sphere_head_link2.stl</uri>
						<scale>0.001 0.001 0.001</scale>
					</mesh>
				</geometry>
			</collision>
			<visual name="sphere_head_link2_visual">
				<geometry>
					<mesh>
						<uri>model://roboy_head/meshes/visuals/sphere_head_link2.stl</uri>
						<scale>0.001 0.001 0.001</scale>
					</mesh>
				</geometry>
			</visual>
		</link>
		<joint name="zed_camera_right" type="fixed">
			<parent>zed_camera</parent>
			<child>zed_camera_right_lense</child>
			<pose frame="">-3.4778066172904685e-05 0.011070006217811788 -0.002353014092107415 0 0 0</pose>
		</joint>
		<joint name="zed_camera_left" type="fixed">
			<parent>zed_camera</parent>
			<child>zed_camera_left_lense</child>
			<pose frame="">-5.466550911889634e-05 0.011069943702269418 -0.002353014260491726 0 0 0</pose>
		</joint>
		<joint name="zed_camera_mount" type="fixed">
			<parent>head</parent>
			<child>zed_camera</child>
			<pose frame="">0.017437654685091043 0.0014055889584145653 0.008052233827783866 0 0 0</pose>
		</joint>
		<joint name="sphere_head_axis0" type="revolute">
			<parent>neck</parent>
			<child>sphere_head_link1</child>
			<pose frame="">1.506150534492037e-10 1.5061482676757368e-10 6.217248937900877e-17 0 0 0</pose>
			<axis>
				<xyz>1 0 0</xyz>
				<limit>
					<lower>-0.5235987755982988</lower>
					<upper>0.5235987755982988</upper>
				</limit>
				<use_parent_model_frame>0</use_parent_model_frame>
			</axis>
		</joint>
		<joint name="sphere_head_axis2" type="revolute">
			<parent>sphere_head_link2</parent>
			<child>head</child>
			<pose frame="">-0.0005102159778959368 -0.04492411500875237 -0.14550204315326165 0 0 0</pose>
			<axis>
				<xyz>0 0 1</xyz>
				<limit>
					<lower>-0.5235987755982988</lower>
					<upper>0.5235987755982988</upper>
				</limit>
				<use_parent_model_frame>0</use_parent_model_frame>
			</axis>
		</joint>
		<joint name="sphere_head_axis1" type="revolute">
			<parent>sphere_head_link1</parent>
			<child>sphere_head_link2</child>
			<pose frame="">1.2766226704758196e-10 1.276634094495146e-10 3.375077994860476e-16 0 0 0</pose>
			<axis>
				<xyz>0 1 0</xyz>
				<limit>
					<lower>-0.5235987755982988</lower>
					<upper>0.5235987755982988</upper>
				</limit>
				<use_parent_model_frame>0</use_parent_model_frame>
			</axis>
		</joint>
		<plugin filename="libcardsflow_gazebo_plugin.so" name="cardsflow_gazebo_plugin" />
	</model>
</sdf>