<robot name="roboy_head">
  <joint name="zed_camera_right" type="fixed">
    <parent link="zed_camera" />
    <child link="zed_camera_right_lense" />
    <origin rpy="0  0  0" xyz="-0.08149 -0.00191 -0.00782" />
    <axis xyz="0  0  0" />
    <limit effort="0" lower="0" upper="0" velocity="0" />
  </joint>
  <joint name="zed_camera_left" type="fixed">
    <parent link="zed_camera" />
    <child link="zed_camera_left_lense" />
    <origin rpy="0  0  0" xyz="0.03848 -0.00154 -0.00782" />
    <axis xyz="0  0  0" />
    <limit effort="0" lower="0" upper="0" velocity="0" />
  </joint>
  <joint name="sphere_head_axis0" type="revolute">
    <parent link="neck" />
    <child link="sphere_head_link1" />
    <origin rpy="0  0  0" xyz="0       0       0.06647" />
    <axis xyz="0.12498 -0.99215  0" />
    <limit effort="0.0" lower="-0.523598775598" upper="0.523598775598" velocity="0.0" />
  </joint>
  <joint name="sphere_head_axis2" type="revolute">
    <parent link="sphere_head_link2" />
    <child link="head" />
    <origin rpy="0  0  0" xyz="0  0  0" />
    <axis xyz="0  0  1" />
    <limit effort="0.0" lower="-0.523598775598" upper="0.523598775598" velocity="0.0" />
  </joint>
  <joint name="sphere_head_axis1" type="revolute">
    <parent link="sphere_head_link1" />
    <child link="sphere_head_link2" />
    <origin rpy="0  0  0" xyz="0  0  0" />
    <axis xyz="-0.99215 -0.12498  0" />
    <limit effort="0.0" lower="-0.523598775598" upper="0.523598775598" velocity="0.0" />
  </joint>
  <joint name="zed_camera_mount" type="fixed">
    <parent link="head" />
    <child link="zed_camera" />
    <origin rpy="0  0  0" xyz="0.02168 -0.05805  0.22156" />
    <axis xyz="0  0  0" />
    <limit effort="0" lower="0" upper="0" velocity="0" />
  </joint>
  <link name="neck">
    <inertial>
      <mass value="2.047509117555703" />
      <origin rpy="0  0  0" xyz="0      -0.00917 -0.00389" />
      <inertia ixx="0.00434167785897833" ixy="-1.6639096374405273e-05" ixz="-0.0008482805831220521" iyy="0.01882627831378666" iyz="-1.7498429824597373e-06" izz="0.021140040932643222" />
    </inertial>
    <collision name="neck_collision">
      <origin rpy="0  0  0" xyz="0      -0.00917 -0.00389" />
      <geometry>
        <mesh filename="package://robots/roboy_head/meshes/collisions/neck.stl" scale="0.001 0.001 0.001" />
      </geometry>
    </collision>
    <visual name="neck_visual">
      <origin rpy="0  0  0" xyz="0      -0.00917 -0.00389" />
      <geometry>
        <mesh filename="package://robots/roboy_head/meshes/visuals/neck.stl" scale="0.001 0.001 0.001" />
      </geometry>
    </visual>
  </link>
  <link name="zed_camera_left_lense">
    <inertial>
      <mass value="0.005755421856391892" />
      <origin rpy="0  0  0" xyz="5.00000000e-05  -1.10700000e-02   2.35000000e-03" />
      <inertia ixx="0.0004886937732036396" ixy="2.4494851152647972e-05" ixz="0.0001149701083259307" iyy="0.00048064466702342837" iyz="-9.794487796522248e-05" izz="5.000839287013939e-05" />
    </inertial>
    <collision name="zed_camera_left_lense_collision">
      <origin rpy="0  0  0" xyz="5.00000000e-05  -1.10700000e-02   2.35000000e-03" />
      <geometry>
        <mesh filename="package://robots/roboy_head/meshes/collisions/zed_camera_left_lense.stl" scale="0.001 0.001 0.001" />
      </geometry>
    </collision>
    <visual name="zed_camera_left_lense_visual">
      <origin rpy="0  0  0" xyz="5.00000000e-05  -1.10700000e-02   2.35000000e-03" />
      <geometry>
        <mesh filename="package://robots/roboy_head/meshes/visuals/zed_camera_left_lense.stl" scale="0.001 0.001 0.001" />
      </geometry>
    </visual>
  </link>
  <link name="zed_camera_right_lense">
    <inertial>
      <mass value="0.005755421855125981" />
      <origin rpy="0  0  0" xyz="3.00000000e-05  -1.10700000e-02   2.35000000e-03" />
      <inertia ixx="0.0004890012549198648" ixy="-2.4441773765426554e-05" ixz="0.0001155832336407073" iyy="0.00048033623713788647" iyz="9.721833695637285e-05" izz="5.0007445146504473e-05" />
    </inertial>
    <collision name="zed_camera_right_lense_collision">
      <origin rpy="0  0  0" xyz="3.00000000e-05  -1.10700000e-02   2.35000000e-03" />
      <geometry>
        <mesh filename="package://robots/roboy_head/meshes/collisions/zed_camera_right_lense.stl" scale="0.001 0.001 0.001" />
      </geometry>
    </collision>
    <visual name="zed_camera_right_lense_visual">
      <origin rpy="0  0  0" xyz="3.00000000e-05  -1.10700000e-02   2.35000000e-03" />
      <geometry>
        <mesh filename="package://robots/roboy_head/meshes/visuals/zed_camera_right_lense.stl" scale="0.001 0.001 0.001" />
      </geometry>
    </visual>
  </link>
  <link name="zed_camera">
    <inertial>
      <mass value="0.009633907989226698" />
      <origin rpy="0  0  0" xyz="-0.01743 -0.0014  -0.00805" />
      <inertia ixx="0.0007896309497775587" ixy="2.498761008939003e-06" ixz="0.00016034142273308372" iyy="0.0007704153373092785" iyz="-1.1468335922374323e-05" izz="4.897438830692025e-05" />
    </inertial>
    <collision name="zed_camera_collision">
      <origin rpy="0  0  0" xyz="-0.01743 -0.0014  -0.00805" />
      <geometry>
        <mesh filename="package://robots/roboy_head/meshes/collisions/zed_camera.stl" scale="0.001 0.001 0.001" />
      </geometry>
    </collision>
    <visual name="zed_camera_visual">
      <origin rpy="0  0  0" xyz="-0.01743 -0.0014  -0.00805" />
      <geometry>
        <mesh filename="package://robots/roboy_head/meshes/visuals/zed_camera.stl" scale="0.001 0.001 0.001" />
      </geometry>
    </visual>
  </link>
  <link name="sphere_head_link1">
    <inertial>
      <mass value="0.017038665636260348" />
      <origin rpy="0  0  0" xyz="0  0  0" />
      <inertia ixx="7.641228262717038e-05" ixy="1.1817803680091998e-21" ixz="1.706037958473794e-13" iyy="7.641228262717038e-05" iyz="1.7059836269345264e-13" izz="1.1107708503000404e-06" />
    </inertial>
    <collision name="sphere_head_link1_collision">
      <origin rpy="0  0  0" xyz="0  0  0" />
      <geometry>
        <mesh filename="package://robots/roboy_head/meshes/collisions/sphere_head_link1.stl" scale="0.001 0.001 0.001" />
      </geometry>
    </collision>
    <visual name="sphere_head_link1_visual">
      <origin rpy="0  0  0" xyz="0  0  0" />
      <geometry>
        <mesh filename="package://robots/roboy_head/meshes/visuals/sphere_head_link1.stl" scale="0.001 0.001 0.001" />
      </geometry>
    </visual>
  </link>
  <link name="sphere_head_link2">
    <inertial>
      <mass value="0.011421521917888844" />
      <origin rpy="0  0  0" xyz="0  0  0" />
      <inertia ixx="5.097860160005361e-05" ixy="-6.369687763352339e-22" ixz="9.693393743931412e-14" iyy="5.097860160005362e-05" iyz="9.692929792137761e-14" izz="5.017693548664096e-07" />
    </inertial>
    <collision name="sphere_head_link2_collision">
      <origin rpy="0  0  0" xyz="0  0  0" />
      <geometry>
        <mesh filename="package://robots/roboy_head/meshes/collisions/sphere_head_link2.stl" scale="0.001 0.001 0.001" />
      </geometry>
    </collision>
    <visual name="sphere_head_link2_visual">
      <origin rpy="0  0  0" xyz="0  0  0" />
      <geometry>
        <mesh filename="package://robots/roboy_head/meshes/visuals/sphere_head_link2.stl" scale="0.001 0.001 0.001" />
      </geometry>
    </visual>
  </link>
  <link name="head">
    <inertial>
      <mass value="2.118815567061463" />
      <origin rpy="0  0  0" xyz="0.0005   0.04351  0.14287" />
      <inertia ixx="0.13064497336933847" ixy="-6.183025580208296e-05" ixz="-0.02239682112141031" iyy="0.12017013288084884" iyz="-0.0003373395051523233" izz="0.030265010402481148" />
    </inertial>
    <collision name="head_collision">
      <origin rpy="0  0  0" xyz="0.0005   0.04351  0.14287" />
      <geometry>
        <mesh filename="package://robots/roboy_head/meshes/collisions/head.stl" scale="0.001 0.001 0.001" />
      </geometry>
    </collision>
    <visual name="head_visual">
      <origin rpy="0  0  0" xyz="0.0005   0.04351  0.14287" />
      <geometry>
        <mesh filename="package://robots/roboy_head/meshes/visuals/head.stl" scale="0.001 0.001 0.001" />
      </geometry>
    </visual>
  </link>
</robot>