<?xml version="1.0" ?>
<sdf version="1.6">
	<model name="VRarm">
		<link name="base">
			<self_collide>false</self_collide>
			<pose frame="">0.6976937429342663 0.05077798240987637 0.7024848262751959 0.0 -0.0 0.0</pose>
			<inertial>
				<pose frame="">0.0 0.0 0.0 0 0 0</pose>
				<mass>16.207323028151656</mass>
				<inertia>
					<ixx>19.446961904388765</ixx>
					<ixy>-0.5734569352671087</ixy>
					<ixz>-7.943648501490726</ixz>
					<iyy>22.8632065284037</iyy>
					<iyz>-0.5781240956627538</iyz>
					<izz>15.789914080100754</izz>
				</inertia>
			</inertial>
			<collision name="base_collision">
				<geometry>
					<mesh>
						<uri>model://VRarm/meshes/CAD/base.stl</uri>
						<scale>0.001 0.001 0.001</scale>
					</mesh>
				</geometry>
			</collision>
			<visual name="base_visual">
				<geometry>
					<mesh>
						<uri>model://VRarm/meshes/CAD/base.stl</uri>
						<scale>0.001 0.001 0.001</scale>
					</mesh>
				</geometry>
			</visual>
		</link>
		<link name="shoulder_left_link1">
			<self_collide>false</self_collide>
			<pose frame="">0.1807790956293054 0.06490793509010379 0.700018904082991 0.0 -0.0 0.0</pose>
			<inertial>
				<pose frame="">0.0 0.0 0.0 0 0 0</pose>
				<mass>0.06979038134801809</mass>
				<inertia>
					<ixx>0.03450481088643034</ixx>
					<ixy>-0.0008189201815306329</ixy>
					<ixz>-0.008831887922651223</ixz>
					<iyy>0.03649160635049412</iyy>
					<iyz>-0.003171050314257621</iyz>
					<izz>0.002586502083462145</izz>
				</inertia>
			</inertial>
			<collision name="shoulder_left_link1_collision">
				<geometry>
					<mesh>
						<uri>model://VRarm/meshes/CAD/shoulder_left_link1.stl</uri>
						<scale>0.001 0.001 0.001</scale>
					</mesh>
				</geometry>
			</collision>
			<visual name="shoulder_left_link1_visual">
				<geometry>
					<mesh>
						<uri>model://VRarm/meshes/CAD/shoulder_left_link1.stl</uri>
						<scale>0.001 0.001 0.001</scale>
					</mesh>
				</geometry>
			</visual>
		</link>
		<link name="shoulder_left_link2">
			<self_collide>false</self_collide>
			<pose frame="">0.18077909562930847 0.06490793509010383 0.7000189040829911 0.0 -0.0 0.0</pose>
			<inertial>
				<pose frame="">0.0 0.0 0.0 0 0 0</pose>
				<mass>0.04678255835713114</mass>
				<inertia>
					<ixx>0.023127049970576203</ixx>
					<ixy>-0.000548946437063391</ixy>
					<ixz>-0.005920275891382745</ixz>
					<iyy>0.02445885777769733</iyy>
					<iyz>-0.0021256488862038438</iyz>
					<izz>0.0017312628234954627</izz>
				</inertia>
			</inertial>
			<collision name="shoulder_left_link2_collision">
				<geometry>
					<mesh>
						<uri>model://VRarm/meshes/CAD/shoulder_left_link2.stl</uri>
						<scale>0.001 0.001 0.001</scale>
					</mesh>
				</geometry>
			</collision>
			<visual name="shoulder_left_link2_visual">
				<geometry>
					<mesh>
						<uri>model://VRarm/meshes/CAD/shoulder_left_link2.stl</uri>
						<scale>0.001 0.001 0.001</scale>
					</mesh>
				</geometry>
			</visual>
		</link>
		<link name="elbow_left_link1">
			<self_collide>false</self_collide>
			<pose frame="">0.22077909562923928 0.09090793509010696 0.437018904082981 0.0 -0.0 0.0</pose>
			<inertial>
				<pose frame="">0.0 0.0 0.0 0 0 0</pose>
				<mass>0.0697903813480181</mass>
				<inertia>
					<ixx>0.013917365071566613</ixx>
					<ixy>-0.0014007328524469267</ixy>
					<ixz>-0.0067336997093007354</ixz>
					<iyy>0.01674242083368397</iyy>
					<iyz>-0.0027726661998714753</iyz>
					<izz>0.003990233729513199</izz>
				</inertia>
			</inertial>
			<collision name="elbow_left_link1_collision">
				<geometry>
					<mesh>
						<uri>model://VRarm/meshes/CAD/elbow_left_link1.stl</uri>
						<scale>0.001 0.001 0.001</scale>
					</mesh>
				</geometry>
			</collision>
			<visual name="elbow_left_link1_visual">
				<geometry>
					<mesh>
						<uri>model://VRarm/meshes/CAD/elbow_left_link1.stl</uri>
						<scale>0.001 0.001 0.001</scale>
					</mesh>
				</geometry>
			</visual>
		</link>
		<link name="elbow_left_link2">
			<self_collide>false</self_collide>
			<pose frame="">0.22077909562924228 0.09090793509010704 0.437018904082981 0.0 -0.0 0.0</pose>
			<inertial>
				<pose frame="">0.0 0.0 0.0 0 0 0</pose>
				<mass>0.04678255835713113</mass>
				<inertia>
					<ixx>0.009326675668917664</ixx>
					<ixy>-0.0009389526915690209</ixy>
					<ixz>-0.004513798227278331</ixz>
					<iyy>0.01122039416565951</iyy>
					<iyz>-0.0018586002224791661</iyz>
					<izz>0.0026722256951792244</izz>
				</inertia>
			</inertial>
			<collision name="elbow_left_link2_collision">
				<geometry>
					<mesh>
						<uri>model://VRarm/meshes/CAD/elbow_left_link2.stl</uri>
						<scale>0.001 0.001 0.001</scale>
					</mesh>
				</geometry>
			</collision>
			<visual name="elbow_left_link2_visual">
				<geometry>
					<mesh>
						<uri>model://VRarm/meshes/CAD/elbow_left_link2.stl</uri>
						<scale>0.001 0.001 0.001</scale>
					</mesh>
				</geometry>
			</visual>
		</link>
		<link name="wrist_left_link1">
			<self_collide>false</self_collide>
			<pose frame="">0.26627909562923885 0.07390793509011037 0.16901890408298126 0.0 -0.0 0.0</pose>
			<inertial>
				<pose frame="">0.0 0.0 0.0 0 0 0</pose>
				<mass>0.06979038134801814</mass>
				<inertia>
					<ixx>0.0023865980990384135</ixx>
					<ixy>-0.0013734843440707217</ixy>
					<ixz>-0.0031409999254738905</ixz>
					<iyy>0.006953832371751661</iyy>
					<iyz>-0.0008718101511550842</iyz>
					<izz>0.0053413251174183485</izz>
				</inertia>
			</inertial>
			<collision name="wrist_left_link1_collision">
				<geometry>
					<mesh>
						<uri>model://VRarm/meshes/CAD/wrist_left_link1.stl</uri>
						<scale>0.001 0.001 0.001</scale>
					</mesh>
				</geometry>
			</collision>
			<visual name="wrist_left_link1_visual">
				<geometry>
					<mesh>
						<uri>model://VRarm/meshes/CAD/wrist_left_link1.stl</uri>
						<scale>0.001 0.001 0.001</scale>
					</mesh>
				</geometry>
			</visual>
		</link>
		<link name="wrist_left_link2">
			<self_collide>false</self_collide>
			<pose frame="">0.2662790956292419 0.07390793509011033 0.169018904082984 0.0 -0.0 0.0</pose>
			<inertial>
				<pose frame="">0.0 0.0 0.0 0 0 0</pose>
				<mass>0.04678255835713115</mass>
				<inertia>
					<ixx>0.0015972612657379286</ixx>
					<ixy>-0.0009206872098703605</ixy>
					<ixz>-0.0021055052211346567</ixz>
					<iyy>0.004658813585224858</iyy>
					<iyz>-0.0005844001492035248</iyz>
					<izz>0.0035779022437181867</izz>
				</inertia>
			</inertial>
			<collision name="wrist_left_link2_collision">
				<geometry>
					<mesh>
						<uri>model://VRarm/meshes/CAD/wrist_left_link2.stl</uri>
						<scale>0.001 0.001 0.001</scale>
					</mesh>
				</geometry>
			</collision>
			<visual name="wrist_left_link2_visual">
				<geometry>
					<mesh>
						<uri>model://VRarm/meshes/CAD/wrist_left_link2.stl</uri>
						<scale>0.001 0.001 0.001</scale>
					</mesh>
				</geometry>
			</visual>
		</link>
		<link name="upper_arm_left">
			<self_collide>false</self_collide>
			<pose frame="">0.2162397825464516 0.08717470687284044 0.474580238551713 0.0 -0.0 0.0</pose>
			<inertial>
				<pose frame="">0.0 0.0 0.0 0 0 0</pose>
				<mass>0.11563830149074948</mass>
				<inertia>
					<ixx>0.02793525054980266</ixx>
					<ixy>-0.0021907104988883944</ixy>
					<ixz>-0.01175768748034964</ixz>
					<iyy>0.03246740586200936</iyy>
					<iyz>-0.0046874002961990405</iyz>
					<izz>0.006331747557804085</izz>
				</inertia>
			</inertial>
			<collision name="upper_arm_left_collision">
				<geometry>
					<mesh>
						<uri>model://VRarm/meshes/CAD/upper_arm_left.stl</uri>
						<scale>0.001 0.001 0.001</scale>
					</mesh>
				</geometry>
			</collision>
			<visual name="upper_arm_left_visual">
				<geometry>
					<mesh>
						<uri>model://VRarm/meshes/CAD/upper_arm_left.stl</uri>
						<scale>0.001 0.001 0.001</scale>
					</mesh>
				</geometry>
			</visual>
		</link>
		<link name="lower_arm_left">
			<self_collide>false</self_collide>
			<pose frame="">0.2609542815299026 0.07631589663805266 0.20729433038488854 0.0 -0.0 0.0</pose>
			<inertial>
				<pose frame="">0.0 0.0 0.0 0 0 0</pose>
				<mass>0.11563830149074954</mass>
				<inertia>
					<ixx>0.0066863792016505115</ixx>
					<ixy>-0.002294562053964195</ixy>
					<ixz>-0.006122953136491078</ixz>
					<iyy>0.013901718009694418</iyy>
					<iyz>-0.0018939654401127915</iyz>
					<izz>0.008593441282457055</izz>
				</inertia>
			</inertial>
			<collision name="lower_arm_left_collision">
				<geometry>
					<mesh>
						<uri>model://VRarm/meshes/CAD/lower_arm_left.stl</uri>
						<scale>0.001 0.001 0.001</scale>
					</mesh>
				</geometry>
			</collision>
			<visual name="lower_arm_left_visual">
				<geometry>
					<mesh>
						<uri>model://VRarm/meshes/CAD/lower_arm_left.stl</uri>
						<scale>0.001 0.001 0.001</scale>
					</mesh>
				</geometry>
			</visual>
		</link>
		<link name="hand_left">
			<self_collide>false</self_collide>
			<pose frame="">0.27653519146500827 0.07390765964322617 0.16901913117660994 0.0 -0.0 0.0</pose>
			<inertial>
				<pose frame="">0.0 0.0 0.0 0 0 0</pose>
				<mass>0.016515273339096418</mass>
				<inertia>
					<ixx>0.0005622818231408339</ixx>
					<ixy>-0.00033754024859741674</ixy>
					<ixz>-0.0007719195821289069</ixz>
					<iyy>0.001735465190983193</iyy>
					<iyz>-0.00020630562661710128</iyz>
					<izz>0.0013538779291615921</izz>
				</inertia>
			</inertial>
			<collision name="hand_left_collision">
				<geometry>
					<mesh>
						<uri>model://VRarm/meshes/CAD/hand_left.stl</uri>
						<scale>0.001 0.001 0.001</scale>
					</mesh>
				</geometry>
			</collision>
			<visual name="hand_left_visual">
				<geometry>
					<mesh>
						<uri>model://VRarm/meshes/CAD/hand_left.stl</uri>
						<scale>0.001 0.001 0.001</scale>
					</mesh>
				</geometry>
			</visual>
		</link>
		<joint name="wrist_left_axis0" type="revolute">
			<parent>lower_arm_left</parent>
			<child>wrist_left_link1</child>
			<pose frame="">2.877698079828406e-15 -4.3520742565306136e-16 1.7053025658242404e-15 0 0 0</pose>
			<axis>
				<xyz>-2.5304758288768547e-13 1.3519781307929614e-14 -1.0000000000000047</xyz>
				<limit>
					<lower>-3.141592653589793</lower>
					<upper>3.141592653589793</upper>
				</limit>
				<use_parent_model_frame>0</use_parent_model_frame>
			</axis>
		</joint>
		<joint name="wrist_left_axis2" type="revolute">
			<parent>wrist_left_link2</parent>
			<child>hand_left</child>
			<pose frame="">-0.010256095835766388 2.7544688399494535e-07 -2.270936258241818e-07 0 0 0</pose>
			<axis>
				<xyz>0.9999999999999983 -3.3283401589037034e-17 -2.507299923237839e-13</xyz>
				<limit>
					<lower>-3.141592653589793</lower>
					<upper>3.141592653589793</upper>
				</limit>
				<use_parent_model_frame>0</use_parent_model_frame>
			</axis>
		</joint>
		<joint name="wrist_left_axis1" type="revolute">
			<parent>wrist_left_link1</parent>
			<child>wrist_left_link2</child>
			<pose frame="">-3.0198066269804257e-15 -1.5987211554602254e-16 -2.948752353404416e-15 0 0 0</pose>
			<axis>
				<xyz>-1.6051516946001187e-17 -1.0 -1.4074892820242177e-14</xyz>
				<limit>
					<lower>-3.141592653589793</lower>
					<upper>3.141592653589793</upper>
				</limit>
				<use_parent_model_frame>0</use_parent_model_frame>
			</axis>
		</joint>
		<joint name="elbow_left_axis0" type="revolute">
			<parent>upper_arm_left</parent>
			<child>elbow_left_link1</child>
			<pose frame="">2.913225216616411e-15 -2.486899575160351e-16 -1.3500311979441904e-15 0 0 0</pose>
			<axis>
				<xyz>-2.530475828876892e-13 1.35059035201217e-14 -1.0000000000000047</xyz>
				<limit>
					<lower>-3.141592653589793</lower>
					<upper>3.141592653589793</upper>
				</limit>
				<use_parent_model_frame>0</use_parent_model_frame>
			</axis>
		</joint>
		<joint name="elbow_left_axis2" type="revolute">
			<parent>elbow_left_link2</parent>
			<child>lower_arm_left</child>
			<pose frame="">-0.04017518590066036 0.014592038452054217 0.22972457369809252 0 0 0</pose>
			<axis>
				<xyz>0.9999999999999983 -8.879455281984364e-17 -2.5072999232378374e-13</xyz>
				<limit>
					<lower>-3.141592653589793</lower>
					<upper>3.141592653589793</upper>
				</limit>
				<use_parent_model_frame>0</use_parent_model_frame>
			</axis>
		</joint>
		<joint name="ankle_right_axis1" type="revolute">
			<parent>elbow_left_link1</parent>
			<child>elbow_left_link2</child>
			<pose frame="">-2.913225216616411e-15 -2.3092638912203257e-16 -1.4210854715202004e-16 0 0 0</pose>
			<axis>
				<xyz>-7.156266817765029e-17 -1.0 -1.403325945681873e-14</xyz>
				<limit>
					<lower>-3.141592653589793</lower>
					<upper>3.141592653589793</upper>
				</limit>
				<use_parent_model_frame>0</use_parent_model_frame>
			</axis>
		</joint>
		<joint name="shoulder_left_axis0" type="revolute">
			<parent>base</parent>
			<child>shoulder_left_link1</child>
			<pose frame="">3.801403636316536e-15 -1.5987211554602254e-16 1.4210854715202005e-15 0 0 0</pose>
			<axis>
				<xyz>-2.530475828876892e-13 1.3512842414025931e-14 -1.0000000000000047</xyz>
				<limit>
					<lower>-3.141592653589793</lower>
					<upper>3.141592653589793</upper>
				</limit>
				<use_parent_model_frame>0</use_parent_model_frame>
			</axis>
		</joint>
		<joint name="shoulder_left_axis2" type="revolute">
			<parent>shoulder_left_link2</parent>
			<child>upper_arm_left</child>
			<pose frame="">-0.035460686917143214 -0.0222667717827368 0.2254386655312782 0 0 0</pose>
			<axis>
				<xyz>0.9999999999999998 -1.0267234056412008e-16 -2.507299923237837e-13</xyz>
				<limit>
					<lower>-3.141592653589793</lower>
					<upper>3.141592653589793</upper>
				</limit>
				<use_parent_model_frame>0</use_parent_model_frame>
			</axis>
		</joint>
		<joint name="shoulder_left_axis1" type="revolute">
			<parent>shoulder_left_link1</parent>
			<child>shoulder_left_link2</child>
			<pose frame="">-3.0198066269804257e-15 -1.7763568394002506e-16 -2.842170943040401e-16 0 0 0</pose>
			<axis>
				<xyz>-8.544045600203712e-17 -1.0000000000000022 -1.4012442775107327e-14</xyz>
				<limit>
					<lower>-3.141592653589793</lower>
					<upper>3.141592653589793</upper>
				</limit>
				<use_parent_model_frame>0</use_parent_model_frame>
			</axis>
		</joint>
		<plugin filename="libcardsflow_gazebo_plugin.so" name="cardsflow_gazebo_plugin"/>
	</model>
</sdf>
