<robot name="VRarm">
  <joint name="wrist_left_axis0" type="revolute">
    <parent link="lower_arm_left" />
    <child link="wrist_left_link1" />
    <origin rpy="0 0 0" xyz="0.0455 -0.017  -0.268" />
    <axis xyz="1 0 0" />
    <limit effort="0.0" lower="-3.14159265359" upper="3.14159265359" velocity="0.0" />
  </joint>
  <joint name="wrist_left_axis1" type="revolute">
    <parent link="wrist_left_link1" />
    <child link="wrist_left_link2" />
    <origin rpy="0 0 0" xyz="0 0 0" />
    <axis xyz="0 1 0" />
    <limit effort="0.0" lower="-3.14159265359" upper="3.14159265359" velocity="0.0" />
  </joint>
  <joint name="wrist_left_axis2" type="revolute">
    <parent link="wrist_left_link2" />
    <child link="hand_left" />
    <origin rpy="0 0 0" xyz="0 0 0" />
    <axis xyz="0 0 1" />
    <limit effort="0.0" lower="-3.14159265359" upper="3.14159265359" velocity="0.0" />
  </joint>
  <joint name="elbow_left_axis0" type="revolute">
    <parent link="upper_arm_left" />
    <child link="elbow_left_link1" />
    <origin rpy="0 0 0" xyz="0.04   0.026 -0.263" />
    <axis xyz="1 0 0" />
    <limit effort="0.0" lower="-3.14159265359" upper="3.14159265359" velocity="0.0" />
  </joint>
  <joint name="elbow_left_axis1" type="revolute">
    <parent link="elbow_left_link1" />
    <child link="elbow_left_link2" />
    <origin rpy="0 0 0" xyz="0 0 0" />
    <axis xyz="0 1 0" />
    <limit effort="0.0" lower="-3.14159265359" upper="3.14159265359" velocity="0.0" />
  </joint>
  <joint name="elbow_left_axis2" type="revolute">
    <parent link="elbow_left_link2" />
    <child link="lower_arm_left" />
    <origin rpy="0 0 0" xyz="0 0 0" />
    <axis xyz="0 0 1" />
    <limit effort="0.0" lower="-3.14159265359" upper="3.14159265359" velocity="0.0" />
  </joint>
  <joint name="shoulder_left_axis0" type="revolute">
    <parent link="base" />
    <child link="shoulder_left_link1" />
    <origin rpy="0 0 0" xyz="0.18077 0.0649  0.70001" />
    <axis xyz="1 0 0" />
    <limit effort="0.0" lower="-3.14159265359" upper="3.14159265359" velocity="0.0" />
  </joint>
  <joint name="shoulder_left_axis1" type="revolute">
    <parent link="shoulder_left_link1" />
    <child link="shoulder_left_link2" />
    <origin rpy="0 0 0" xyz="0 0 0" />
    <axis xyz="0 1 0" />
    <limit effort="0.0" lower="-3.14159265359" upper="3.14159265359" velocity="0.0" />
  </joint>
  <joint name="shoulder_left_axis2" type="revolute">
    <parent link="shoulder_left_link2" />
    <child link="upper_arm_left" />
    <origin rpy="0 0 0" xyz="0 0 0" />
    <axis xyz="0 0 1" />
    <limit effort="0.0" lower="-3.14159265359" upper="3.14159265359" velocity="0.0" />
  </joint>

  <link name="base">
    <inertial>
      <mass value="16.207323028151656" />
      <origin rpy="0 0 0" xyz="0.69769 0.05077 0.70248" />
      <inertia ixx="19.446961904388765" ixy="-0.5734569352671087" ixz="-7.943648501490726" iyy="22.8632065284037" iyz="-0.5781240956627538" izz="15.789914080100754" />
    </inertial>
    <collision name="base_collision">
      <origin rpy="0 0 0" xyz="0.69769 0.05077 0.70248" />
      <geometry>
        <mesh filename="package://robots/VRarm/meshes/collisions/base.stl" scale="0.001 0.001 0.001" />
      </geometry>
    </collision>
    <visual name="base_visual">
      <origin rpy="0 0 0" xyz="0.69769 0.05077 0.70248" />
      <geometry>
        <mesh filename="package://robots/VRarm/meshes/visuals/base.stl" scale="0.001 0.001 0.001" />
      </geometry>
    </visual>
  </link>
  <link name="shoulder_left_link1">
    <inertial>
      <mass value="0.06979038134801809" />
      <origin rpy="0 0 0" xyz="0 0 0" />
      <inertia ixx="0.03450481088643034" ixy="-0.0008189201815306329" ixz="-0.008831887922651223" iyy="0.03649160635049412" iyz="-0.003171050314257621" izz="0.002586502083462145" />
    </inertial>
    <collision name="shoulder_left_link1_collision">
      <origin rpy="0 0 0" xyz="0 0 0" />
      <geometry>
        <mesh filename="package://robots/VRarm/meshes/collisions/shoulder_left_link1.stl" scale="0.001 0.001 0.001" />
      </geometry>
    </collision>
    <visual name="shoulder_left_link1_visual">
      <origin rpy="0 0 0" xyz="0 0 0" />
      <geometry>
        <mesh filename="package://robots/VRarm/meshes/visuals/shoulder_left_link1.stl" scale="0.001 0.001 0.001" />
      </geometry>
    </visual>
  </link>
  <link name="shoulder_left_link2">
    <inertial>
      <mass value="0.04678255835713114" />
      <origin rpy="0 0 0" xyz="0 0 0" />
      <inertia ixx="0.023127049970576203" ixy="-0.000548946437063391" ixz="-0.005920275891382745" iyy="0.02445885777769733" iyz="-0.0021256488862038438" izz="0.0017312628234954627" />
    </inertial>
    <collision name="shoulder_left_link2_collision">
      <origin rpy="0 0 0" xyz="0 0 0" />
      <geometry>
        <mesh filename="package://robots/VRarm/meshes/collisions/shoulder_left_link2.stl" scale="0.001 0.001 0.001" />
      </geometry>
    </collision>
    <visual name="shoulder_left_link2_visual">
      <origin rpy="0 0 0" xyz="0 0 0" />
      <geometry>
        <mesh filename="package://robots/VRarm/meshes/visuals/shoulder_left_link2.stl" scale="0.001 0.001 0.001" />
      </geometry>
    </visual>
  </link>
  <link name="elbow_left_link1">
    <inertial>
      <mass value="0.0697903813480181" />
      <origin rpy="0 0 0" xyz="0 0 0" />
      <inertia ixx="0.013917365071566613" ixy="-0.0014007328524469267" ixz="-0.0067336997093007354" iyy="0.01674242083368397" iyz="-0.0027726661998714753" izz="0.003990233729513199" />
    </inertial>
    <collision name="elbow_left_link1_collision">
      <origin rpy="0 0 0" xyz="0 0 0" />
      <geometry>
        <mesh filename="package://robots/VRarm/meshes/collisions/elbow_left_link1.stl" scale="0.001 0.001 0.001" />
      </geometry>
    </collision>
    <visual name="elbow_left_link1_visual">
      <origin rpy="0 0 0" xyz="0 0 0" />
      <geometry>
        <mesh filename="package://robots/VRarm/meshes/visuals/elbow_left_link1.stl" scale="0.001 0.001 0.001" />
      </geometry>
    </visual>
  </link>
  <link name="elbow_left_link2">
    <inertial>
      <mass value="0.04678255835713113" />
      <origin rpy="0 0 0" xyz="0 0 0" />
      <inertia ixx="0.009326675668917664" ixy="-0.0009389526915690209" ixz="-0.004513798227278331" iyy="0.01122039416565951" iyz="-0.0018586002224791661" izz="0.0026722256951792244" />
    </inertial>
    <collision name="elbow_left_link2_collision">
      <origin rpy="0 0 0" xyz="0 0 0" />
      <geometry>
        <mesh filename="package://robots/VRarm/meshes/collisions/elbow_left_link2.stl" scale="0.001 0.001 0.001" />
      </geometry>
    </collision>
    <visual name="elbow_left_link2_visual">
      <origin rpy="0 0 0" xyz="0 0 0" />
      <geometry>
        <mesh filename="package://robots/VRarm/meshes/visuals/elbow_left_link2.stl" scale="0.001 0.001 0.001" />
      </geometry>
    </visual>
  </link>
  <link name="wrist_left_link1">
    <inertial>
      <mass value="0.06979038134801814" />
      <origin rpy="0 0 0" xyz="0 0 0" />
      <inertia ixx="0.0023865980990384135" ixy="-0.0013734843440707217" ixz="-0.0031409999254738905" iyy="0.006953832371751661" iyz="-0.0008718101511550842" izz="0.0053413251174183485" />
    </inertial>
    <collision name="wrist_left_link1_collision">
      <origin rpy="0 0 0" xyz="0 0 0" />
      <geometry>
        <mesh filename="package://robots/VRarm/meshes/collisions/wrist_left_link1.stl" scale="0.001 0.001 0.001" />
      </geometry>
    </collision>
    <visual name="wrist_left_link1_visual">
      <origin rpy="0 0 0" xyz="0 0 0" />
      <geometry>
        <mesh filename="package://robots/VRarm/meshes/visuals/wrist_left_link1.stl" scale="0.001 0.001 0.001" />
      </geometry>
    </visual>
  </link>
  <link name="wrist_left_link2">
    <inertial>
      <mass value="0.04678255835713115" />
      <origin rpy="0 0 0" xyz="0 0 0" />
      <inertia ixx="0.0015972612657379286" ixy="-0.0009206872098703605" ixz="-0.0021055052211346567" iyy="0.004658813585224858" iyz="-0.0005844001492035248" izz="0.0035779022437181867" />
    </inertial>
    <collision name="wrist_left_link2_collision">
      <origin rpy="0 0 0" xyz="0 0 0" />
      <geometry>
        <mesh filename="package://robots/VRarm/meshes/collisions/wrist_left_link2.stl" scale="0.001 0.001 0.001" />
      </geometry>
    </collision>
    <visual name="wrist_left_link2_visual">
      <origin rpy="0 0 0" xyz="0 0 0" />
      <geometry>
        <mesh filename="package://robots/VRarm/meshes/visuals/wrist_left_link2.stl" scale="0.001 0.001 0.001" />
      </geometry>
    </visual>
  </link>
  <link name="upper_arm_left">
    <inertial>
      <mass value="0.11563830149074948" />
      <origin rpy="0 0 0" xyz="0.03546  0.02226 -0.22543" />
      <inertia ixx="0.02793525054980266" ixy="-0.0021907104988883944" ixz="-0.01175768748034964" iyy="0.03246740586200936" iyz="-0.0046874002961990405" izz="0.006331747557804085" />
    </inertial>
    <collision name="upper_arm_left_collision">
      <origin rpy="0 0 0" xyz="0.03546  0.02226 -0.22543" />
      <geometry>
        <mesh filename="package://robots/VRarm/meshes/collisions/upper_arm_left.stl" scale="0.001 0.001 0.001" />
      </geometry>
    </collision>
    <visual name="upper_arm_left_visual">
      <origin rpy="0 0 0" xyz="0.03546  0.02226 -0.22543" />
      <geometry>
        <mesh filename="package://robots/VRarm/meshes/visuals/upper_arm_left.stl" scale="0.001 0.001 0.001" />
      </geometry>
    </visual>
  </link>
  <link name="lower_arm_left">
    <inertial>
      <mass value="0.11563830149074954" />
      <origin rpy="0 0 0" xyz="0.04017 -0.01459 -0.22972" />
      <inertia ixx="0.0066863792016505115" ixy="-0.002294562053964195" ixz="-0.006122953136491078" iyy="0.013901718009694418" iyz="-0.0018939654401127915" izz="0.008593441282457055" />
    </inertial>
    <collision name="lower_arm_left_collision">
      <origin rpy="0 0 0" xyz="0.04017 -0.01459 -0.22972" />
      <geometry>
        <mesh filename="package://robots/VRarm/meshes/collisions/lower_arm_left.stl" scale="0.001 0.001 0.001" />
      </geometry>
    </collision>
    <visual name="lower_arm_left_visual">
      <origin rpy="0 0 0" xyz="0.04017 -0.01459 -0.22972" />
      <geometry>
        <mesh filename="package://robots/VRarm/meshes/visuals/lower_arm_left.stl" scale="0.001 0.001 0.001" />
      </geometry>
    </visual>
  </link>
  <link name="hand_left">
    <inertial>
      <mass value="0.016515273339096418" />
      <origin rpy="0 0 0" xyz="0.01025 0      0" />
      <inertia ixx="0.0005622818231408339" ixy="-0.00033754024859741674" ixz="-0.0007719195821289069" iyy="0.001735465190983193" iyz="-0.00020630562661710128" izz="0.0013538779291615921" />
    </inertial>
    <collision name="hand_left_collision">
      <origin rpy="0 0 0" xyz="0.01025 0      0" />
      <geometry>
        <mesh filename="package://robots/VRarm/meshes/collisions/hand_left.stl" scale="0.001 0.001 0.001" />
      </geometry>
    </collision>
    <visual name="hand_left_visual">
      <origin rpy="0 0 0" xyz="0.01025 0      0" />
      <geometry>
        <mesh filename="package://robots/VRarm/meshes/visuals/hand_left.stl" scale="0.001 0.001 0.001" />
      </geometry>
    </visual>
  </link>
</robot>